Workbook

Sheet RECAP
B1: Date | C1: Recette | D1: Charges | E1: Salaire | F1: Loyer | G1: Net Profit
A2: Dimanche | B2: 43891 | C2: 20000
A3: Lundi | B3: 43892 | C3: 20000
A4: Mardi | B4: 43893 | C4: 15000
A5: Mercredi | B5: 43894 | C5: 23000
A6: Jeudi | B6: 43895 | C6: 25000
A7: Vendredi | B7: 43896 | C7: 0 | D7: 0 | E7: 0 | F7: 0 | G7: 0
A8: Samedi | B8: 43897 | C8: 20000
A9: Dimanche | B9: 43898 | C9: 19000 | O9: Reda | P9: 50000
A10: Lundi | B10: 43899 | C10: 19000 | O10: Sofiane | P10: 19000
A11: Mardi | B11: 43900 | C11: 20000 | O11: Smid Amel | P11: 6250
A12: Mercredi | B12: 43901 | C12: 19000 | O12: monnaies | P12: 4500
A13: Jeudi | B13: 43902 | C13: 23000 | O13: Saida | P13: 2000
A14: Vendredi | B14: 43903 | C14: 0 | D14: 0 | E14: 0 | F14: 0 | G14: 0
A15: Samedi | B15: 43904 | C15: 19000
A16: Dimanche | B16: 43905 | C16: 17000
A17: Lundi | B17: 43906 | C17: 17000
A18: Mardi | B18: 43907 | C18: 14000
A19: Mercredi | B19: 43908 | C19: 10000
A20: Jeudi | B20: 43909 | C20: 13000
A21: Vendredi | B21: 43910 | C21: 0 | D21: 0 | E21: 0 | F21: 0 | G21: 0
A22: Samedi | B22: 43911 | C22: 14000
A23: Dimanche | B23: 43912 | C23: 0 | K23: Cash Restant | P23: =C33*1 -> 327000 | Q23: =Pointage!D33*1 -> 18 | R23: =P23/Q23 -> 18166.667
A24: Lundi | B24: 43913 | C24: 0 | K24: =C33+Charges!E89+P11-D33-Salaires!I19-P9-P10-P13 -> -10045
A25: Mardi | B25: 43914 | C25: 0 | K25: =K24+Charges!E87 -> -5045
A26: Mercredi | B26: 43915 | C26: 0
A27: Jeudi | B27: 43916 | C27: 0
A28: Vendredi | B28: 43917 | C28: 0 | D28: 0 | E28: 0 | F28: 0 | G28: 0
A29: Samedi | B29: 43918 | C29: 0
A30: Dimanche | B30: 43919 | C30: 0 | K30: =C33+Charges!E89-D33-Salaires!I19 -> 54705
A31: Lundi | B31: 43920 | C31: 0
A32: Mardi | B32: 43921 | C32: 0
A33: TOTAL | C33: =SUM(C2:C32) -> 327000 | D33: =Charges!E88*1 -> 301295 | E33: =Pointage!J35*1 -> 121520 | F33: 0 | G33: =C33-Charges!E88-Pointage!J35-F33 -> -95815
A34: TAUX | C34: 1 | D34: =D33/C33 -> 0.92139144 | E34: =E33/C33 -> 0.3716208 | F34: =F33/C33 -> 0 | G34: =G33/C33 -> -0.29301223

Sheet Charges
C3: Produit | D3: Quantité | E3: Prix | F3: Date d'achat
C4: Boites 36/07 | D4: 2 cartons | E4: 1700 | F4: 43891
C5: Boites 48/10 | D5: 1 carton | E5: 1360 | F5: 43891
C6: sachets 5kg | D6: 2 Fardeaux | E6: 2400 | F6: 43891
C7: sachets en papier 23 | D7: 2 Fardeaux | E7: 2200 | F7: 43891
C8: sachets en papier 14 | D8: 2 fardeaux | E8: 1500 | F8: 43891
C9: sachets en papier 06 | D9: 1 fardeau | E9: 980 | F9: 43891
C10: sachets transparent | D10: 2 fardeaux | E10: 1900 | F10: 43891
C11: IFRUIT | D11: 2 Fardeaux | E11: 1040 | F11: 43891
C12: Coca COLA1/2 litres | D12: 2 fardeaux | E12: 1360 | F12: 43891
C13: eau de rose | D13: 5 bouteiles | E13: 300 | F13: 43891
C14: sel | D14: 2 fardeaux | E14: 660 | F14: 43891
C15: Tomate conserve | D15: 1 fardeau | E15: 2640 | F15: 43891
... C19: semoule moyenne Extra Ben Hamadi | D19: 4 sachets de 10kg | E19: 2400 | F19: 43891
C20: Semoule extra fin | D20: 40 sachets de 25kg | F20: 43891
C21: Huile Fridor 10 litres | D21: 10 | E21: 10700 | F21: 43891
C22: sucre 25kg | D22: 1 sachets | E22: 1625 | F22: 43891
C23: lala khdidja 1 litres | D23: 3 fardeaux | E23: 450 | F23: 43891
C24: lala khedidja 0.33litrees | D24: 3 fardeaux | E24: 435 | F24: 43891
C25: orange mangue jus | D25: 1 | E25: 420 | F25: 43891
C26: orange jus | D26: 1 | E26: 420 | F26: 43891
C27: margarine | D27: 1 carton | E27: 1800 | F27: 43891
C28: semoule Baraka 25kg | D28: 40 sacs | E28: 48500 | F28: 43891
C29: Fromage Gouda | D29: 700g | E29: 1000 | F29: 43891
C30: bessel | D30: 11kg | E30: 750 | F30: 43891
C31: Recheta | D31: 5kg | E31: 500 | F31: 43891
C32: herbes | D32: 7 bouquets | E32: 240 | F32: 43891
C33: bessel | D33: 75kg | E33: 6000 | F33: 43891
C34: transport | D34: 1 | E34: 500 | F34: 43891
C35: Farine d'Orge | D35: 25kg | E35: 3000 | F35: 43892
C36: Fromage Gouda | D36: 2.2kg | E36: 2450 | F36: 43893
C37: Recheta | D37: 10kg | E37: 1000 | F37: 43893
C38: herebes | D38: 5 pouquets | E38: 120 | F38: 43893
C39: Recheta | D39: 15kg | E39: 1500 | F39: 43895
C40: Ghress | D40: 10kg | E40: 1700 | F40: 43895
C41: herbes | D41: 7 bouquets | E41: 200 | F41: 43895
C42: bessel | D42: 52 kg | E42: 3600 | F42: 43895
C43: levure | D43: 1 boite | E43: 400 | F43: 43895
C44: lavette isis 5 litres , javel 5 litre ,2 briquets , dewa des cafards | D44: / | E44: 1360 | F44: 44050
C45: fromage spéciale pizza | D45: 7.7kg | E45: 1925 | F45: 43897
...

Sheet Pointage
B1: Date | C1: Zehor | D1: Zoubida | E1: Karima | F1: Amel | G1: Nouara | H1: Nawel | I1: Zahida | J1: Remarque | K1: Reste à payer
A2: Dimanche | B2: 43891 | C2: 1 | D2: 1 | E2: 2 | F2: 0 | G2: 1 | H2: 1 | I2: 1
A3: Lundi | B3: 43892 | C3: 1 | D3: 1 | E3: 1 | F3: 0 | G3: 1 | H3: 1 | I3: 1
A4: Mardi | B4: 43893 | C4: 0 | D4: 1 | E4: 1 | F4: 0 | G4: 1 | H4: 0 | I4: 1
A5: Mercredi | B5: 43894 | C5: 1 | D5: 1 | E5: 1 | F5: 0 | G5: 1 | H5: 1 | I5: 1
A6: Jeudi | B6: 43895 | C6: 1 | D6: 1 | E6: 1 | F6: 0 | G6: 1 | H6: 1 | I6: 2
A7: Vendredi | B7: 43896 | C7: 0 | D7: 0 | E7: 0 | F7: 0 | G7: 0 | H7: 0 | I7: 0
A8: Samedi | B8: 43897 | C8: 0 | D8: 1 | E8: 1 | F8: 0 | G8: 1 | H8: 1 | I8: 2
A9: Dimanche | B9: 43898 | C9: 1 | D9: 1 | E9: 1 | F9: 0 | G9: 1 | H9: 1 | I9: 1
A10: Lundi | B10: 43899 | C10: 1 | D10: 1 | E10: 1 | F10: 0 | G10: 1 | H10: 0 | I10: 1
A11: Mardi | B11: 43900 | C11: 1 | D11: 1 | E11: 1 | F11: 0 | G11: 1 | H11: 1 | I11: 1
A12: Mercredi | B12: 43901 | C12: 1 | D12: 1 | E12: 1 | F12: 0 | G12: 1 | H12: 1 | I12: 1
A13: Jeudi | B13: 43902 | C13: 1 | D13: 1 | E13: 1 | F13: 1 | G13: 1 | H13: 1 | I13: 1
... A20: Jeudi | B20: 43909 | C20: 1 | D20: 1 | E20: 1 | F20: 1 | G20: 1 | H20: 0 | I20: 1
A21: Vendredi | B21: 43910 | C21: 0 | D21: 0 | E21: 0 | G21: 0 | H21: 0 | I21: 0
A22: Samedi | B22: 43911 | C22: 0 | D22: 1 | E22: 1 | F22: 0 | G22: 1 | H22: 0 | I22: 0
A23: Dimenche | B23: 43912 | C23: 0 | D23: 0 | E23: 0 | F23: 0 | G23: 0 | H23: 0 | I23: 0
A24: Lundi | B24: 43913 | C24: 0 | D24: 0 | E24: 0 | F24: 0 | G24: 0 | H24: 0 | I24: 0
A25: Mardfi | B25: 43914 | C25: 0 | D25: 0 | E25: 0 | F25: 0 | G25: 0 | H25: 0 | I25: 0
A26: Mercredi | B26: 43915 | C26: 0 | D26: 0 | E26: 0 | F26: 0 | G26: 0 | H26: 0 | I26: 0
A27: Jeudi | B27: 43916 | C27: 0 | D27: 0 | E27: 0 | F27: 0 | G27: 0 | H27: 0 | I27: 0
A28: Vendredi | B28: 43917 | C28: 0 | D28: 0 | E28: 0 | F28: 0 | G28: 0 | H28: 0 | I28: 0
A29: Samedi | B29: 43918 | C29: 0 | D29: 0 | E29: 0 | F29: 0 | G29: 0 | H29: 0 | I29: 0
A30: Dimanche | B30: 43919 | C30: 0 | D30: 0 | E30: 0 | F30: 0 | G30: 0 | H30: 0 | I30: 0
A31: Lundi | B31: 43920 | C31: 0 | D31: 0 | E31: 0 | F31: 0 | G31: 0 | H31: 0 | I31: 0
A32: Mardi | B32: 43921 | C32: 0 | D32: 0 | E32: 0 | F32: 0 | G32: 0 | H32: 0 | I32: 0
B33: TOTAL | C33: =SUM(C2:C32) -> 15 | D33: =SUM(D2:D32) -> 18 | E33: =SUM(E2:E32) -> 19 | F33: =SUM(F2:F32) -> 7 | G33: =SUM(G2:G32) -> 18 | H33: =SUM(H2:H32) -> 13 | I33: =SUM(I2:I32) -> 19
B34: Salaire/jour | C34: 2000 | D34: 1200 | E34: 480 | F34: 1000 | G34: 1000 | H34: 1000 | I34: 1200 | J34: =SUM(C34:I34) -> 7880
B35: SALAIRES | C35: =C33*C34 -> 30000 | D35: =D34*D33 -> 21600 | E35: =E34*E33 -> 9120 | F35: =F34*F33 -> 7000 | G35: =G34*G33 -> 18000 | H35: =H34*H33 -> 13000 | I35: =I33*I34 -> 22800 | J35: =SUM(C35:I35) -> 121520

Sheet Salaires
G11: Nom | H11: Salaire | I11: Avance
F12: 1 | G12: Zehor | H12: =Pointage!C35*1 -> 30000
F13: 2 | G13: karima | H13: =Pointage!E35*1 -> 9120 | I13: 10000
F14: 3 | G14: Nawel | H14: =Pointage!H35*1 -> 13000 | I14: 13000
F15: 4 | G15: Nowara | H15: =Pointage!G35*1 -> 18000
F16: 5 | G16: Zoubida | H16: =Pointage!D35*1 -> 21600 | I16: 21000
F17: 6 | G17: Amel | H17: =Pointage!F35*1 -> 7000 | I17: 7000
F18: 7 | G18: Zahida | H18: =Pointage!I35*1 -> 22800
G19: TOTAL | H19: =SUM(H12:H18) -> 121520 | I19: =SUM(I12:I18) -> 51000
H20: =H19-I19 -> 70520
