Workbook

Sheet RECAP
B1: Date | C1: Recette Mars 2023 | D1: Recette | E1: Charges | F1: Salaire | G1: Loyer | H1: Net Profit | I1: Nb de jours | M1: Objectif | N1: Décembre | O1: Bénéfice Moyen par jour | P1: Moyenne | Q1: Moyenne salaire | R1: pourcentage du salaire vis à vis la recettte
A2: Samedi | B2: 45017 | C2: 48000 | D2: 33000 | I2: 1 | N2: 48000 | O2: =I33/J33 -> #DIV/0! | P2: =E33/J33 -> #DIV/0! | R2: =Q2/P2 -> #DIV/0!
A3: dimanche | B3: 45018 | C3: 100000 | D3: 37000 | I3: 1 | N3: 100000
A4: lundi | B4: 45019 | C4: 52000 | D4: 43000 | I4: 1 | N4: 52000 | O4: Moyenne des charges par jour | P4: Objectif
A5: mardi | B5: 45020 | C5: 65000 | D5: 36000 | I5: 1 | N5: 65000 | O5: =F33/J33 -> #DIV/0! | P5: 100000
A6: mercredi | B6: 45021 | C6: 67000 | D6: 49000 | I6: 1 | N6: 67000 | O6: ²
A7: jeudi | B7: 45022 | C7: 53000 | D7: 59000 | I7: 1 | N7: 53000
A8: vendredi | B8: 45023 | C8: 50000 | D8: 41000 | I8: 1 | N8: 50000 | O8: Cash restant | P8: Magasin | Q8: caisse
A9: samedi | B9: 45024 | C9: 72000 | D9: 50000 | I9: 1 | N9: 72000 | O9: =D33-P9-E33-'les salaires '!J28 -> 185993 | P9: =Q9*1 -> 495250 | Q9: 495250
A10: dimanche | B10: 45025 | C10: 63000 | D10: 40000 | I10: 1 | N10: 63000 | O10: 161000 | Q10: Sofiane: 14000+20000+42000+38000-1800-1250+17000-59700+21000+15000+22000+28000+16000-1500+3000+50000-12000+53500+30000-70000+13000+36000+31000 | R10: 259250
A11: lundi | B11: 45026 | C11: 82000 | D11: 22000 | I11: 1 | N11: 82000 | O11: loyer | P11: 26000 | Q11: caisse : 26000+ Brahim 1250+1000+2000
A12: mardi | B12: 45027 | C12: 32000 | D12: 22000 | I12: 1 | N12: 32000 | Q12: 17000
A13: mercredi | B13: 45028 | C13: 43000 | D13: 25000 | I13: 1 | N13: 43000 | P13: charges Mais | Q13: Literie Soummam: 171000
A14: jeudi | B14: 45029 | C14: 30000 | D14: 35000 | I14: 1 | N14: 30000 | P14: 293000
A15: vendredi | B15: 45030 | C15: 58000 | D15: 34000 | I15: 1 | N15: 58000
A16: samedi | B16: 45031 | C16: 48000 | D16: 40000 | I16: 1 | N16: 48000
A17: dimanche | B17: 45032 | C17: 80000 | D17: 21000 | I17: 1 | N17: 80000 | O17: Différence mois de Janvier
A18: lundi | B18: 45033 | C18: 40000 | D18: 46000 | I18: 1 | N18: 40000 | O18: =D33-C33 -> -362000 | Q18: Recette Février | R18: =E33*1 -> 669757
A19: mardi | B19: 45034 | C19: 50000 | D19: 91000 | I19: 1 | N19: 50000 | O19: Différence objectif | Q19: charges | R19: =F33*1 -> 341786
A20: mercredi | B20: 45035 | C20: 55000 | D20: 280000 | I20: 1 | N20: 55000 | O20: =M33-E33 -> -669757
A21: jeudi | B21: 45036 | C21: 44000 | D21: 220000 | I21: 1 | N21: 44000
A22: vendredi | B22: 45037 | C22: 70000 | D22: 0 | I22: 1 | N22: 70000 | Q22: Caisse | R22: =P9*1 -> 495250
A23: samedi | B23: 45038 | C23: 106000 | D23: 0 | I23: 1 | N23: 106000 | O23: Les vendredis | Q23: Avance salaire | R23: ='les salaires'!L33*1 -> #REF!
A24: dimanche | B24: 45039 | C24: 106000 | D24: 0 | I24: 1 | N24: 106000 | O24: =E4+E11+E18+E25 -> 0
A25: lundi | B25: 45040 | C25: 45000 | D25: 20000 | I25: 1 | N25: 45000
A26: mardi | B26: 45041 | C26: 68000 | D26: 37000 | I26: 1 | N26: 68000 | O26: Cash réel | Q26: Cash restant | R26: =R18-R19-R22-R23 -> #REF!
A27: mercredi | B27: 45042 | C27: 59000 | D27: 30000 | I27: 1 | N27: 59000 | O27: =D33-E33-'les salaires '!J28-Q12 -> 664243
A28: jeudi | B28: 45043 | C28: 61000 | D28: 57000 | I28: 1 | N28: 61000 | O28: rest à payer
A29: vendredi | B29: 45044 | C29: 64000 | D29: 23000 | I29: 1 | N29: 64000
A30: samedi | B30: 45045 | C30: 65000 | D30: 48000 | I30: 1 | N30: 65000
A31: dimanche | B31: 45046 | C31: 74000 | D31: 49000 | I31: 1 | N31: 74000
N32: 78000 | O32: =O9-O27 -> -478250
C33: =SUM(C2:C32) -> 1850000 | D33: =SUM(D2:D32) -> 1488000 | E33: ='Les charges '!I244*1 -> 669757 | F33: ='les salaires '!I28*1 -> 341786 | G33: 110000 | H33: =D33-G33-F33-E33 -> 366457 | I33: =SUM(I2:I32) -> 30 | N33: =SUM(N2:N32) -> 1928000
C35: Objectif
C36: Mois de Janvier

Sheet Pointage 
B1: Date | C1: Ndjet | D1: Wahiba | E1: Lynda | F1: Fouzia | G1: Youssera | H1: Hafida | I1: Djamila | J1: Yasmine | K1: Kenza | L1: Samira | M1: Sarah | N1: Vendeuse | O1: Salima | P1: Remarque
A2: Samedi | B2: 45017 | C2: 0 | D2: 1 | E2: 1 | F2: 0 | G2: 1 | H2: 1 | I2: 0 | J2: 0 | K2: 0 | L2: 0 | M2: 0 | N2: 1 | O2: 1
A3: dimanche | B3: 45018 | C3: 0 | D3: 1 | E3: 2 | F3: 0 | G3: 1 | H3: 1 | I3: 1 | J3: 0 | K3: 0 | L3: 1 | M3: 0 | N3: 1 | O3: 1
A4: lundi | B4: 45019 | C4: 0 | D4: 1 | E4: 1 | F4: 0 | G4: 1 | H4: 1 | I4: 1 | J4: 0 | K4: 0 | L4: 1 | M4: 1 | N4: 1 | O4: 1
A5: mardi | B5: 45020 | C5: 0 | D5: 1 | E5: 1 | F5: 0 | G5: 0 | H5: 1 | I5: 1 | J5: 0 | K5: 0 | L5: 0 | M5: 1 | N5: 1 | O5: 1
A6: mercredi | B6: 45021 | C6: 0 | D6: 1 | E6: 1 | F6: 0 | G6: 1 | H6: 1 | I6: 1 | J6: 0 | K6: 0 | L6: 0 | M6: 0 | N6: 1 | O6: 1
A7: jeudi | B7: 45022 | C7: 0 | D7: 1 | E7: 1.5 | F7: 0 | G7: 0 | H7: 1 | I7: 1 | J7: 0 | K7: 0 | L7: 0 | M7: 1 | N7: 1 | O7: 0
A8: vendredi | B8: 45023 | C8: 0 | D8: 1 | E8: 2 | F8: 0 | G8: 0 | H8: 1 | I8: 1 | J8: 0 | K8: 0 | L8: 1 | M8: 0 | N8: 1 | O8: 0
A9: samedi | B9: 45024 | C9: 0 | D9: 0 | E9: 1 | F9: 0 | G9: 1 | H9: 1 | I9: 1 | J9: 0 | K9: 0 | L9: 1 | M9: 0.5 | N9: 1 | O9: 0
A10: dimanche | B10: 45025 | C10: 0 | D10: 1 | E10: 1 | F10: 0 | G10: 1 | H10: 1 | I10: 1 | J10: 0 | K10: 0 | L10: 1 | M10: 0.5 | N10: 1 | O10: 0
A11: lundi | B11: 45026 | C11: 0 | D11: 1 | E11: 1 | F11: 0 | G11: 1 | H11: 1 | I11: 1 | J11: 0 | K11: 0 | L11: 1 | M11: 1 | N11: 1 | O11: 0
A12: mardi | B12: 45027 | C12: 0 | D12: 1 | E12: 1 | F12: 1 | G12: 1 | H12: 1 | I12: 1 | J12: 0 | K12: 0 | L12: 1 | M12: 1 | N12: 1 | O12: 0
A13: mercredi | B13: 45028 | C13: 0 | D13: 1 | E13: 2 | F13: 1 | G13: 1 | H13: 1 | I13: 1 | J13: 1 | K13: 0 | L13: 1 | M13: 0 | N13: 1 | O13: 0
... A31: dimanche | B31: 45046 | C31: 0 | D31: 0 | E31: 1 | F31: 0 | G31: 0 | H31: 1 | I31: 1 | J31: 0 | K31: 0 | L31: 1 | M31: 0 | N31: 1 | O31: 0
C32: =SUM(C2:C31) -> 8 | D32: =SUM(D2:D31) -> 26.5 | E32: =SUM(E2:E31) -> 41 | F32: =SUM(F2:F31) -> 13 | G32: =SUM(G2:G31) -> 17 | H32: =SUM(H2:H31) -> 30 | I32: =SUM(I2:I31) -> 21 | J32: =SUM(J2:J31) -> 12.5 | ... O32: =SUM(O2:O31) -> 5
C33: 1200 | D33: 1180 | E33: 1270 | F33: 1180 | G33: 1180 | H33: 1346 | I33: 1180 | J33: 1038 | K33: 1038 | L33: 1038 | M33: 1000 | N33: 1000 | O33: 900
C34: =C32*C33 -> 9600 | D34: =D33*D32 -> 31270 | E34: =E33*E32 -> 52070 | F34: =F33*F32 -> 15340 | G34: =G33*G32 -> 20060 | H34: =H33*H32 -> 40380 | I34: =I33*I32 -> 24780 | J34: =J33*J32 -> 12975 | K34: =K33*K32 -> 10899 | ... N34: =N33*N32 -> 25000 | O34: =O32*O33 -> 4500 | P34: =SUM(D34:M34) -> 242686

Sheet les salaires 
H12: Nom | I12: Salaire | J12: Avance | K12: Salaire à payer
G13: 1 | H13: Sofiane | I13: 30000 | J13: 30000 | K13: =I13-J13 -> 0 | L13: 1800+1200+2000+11000+10000+14000 | M13: viande + batterie +messerouf
G14: 2 | H14: Amel | I14: 30000 | J14: 30000 | K14: =I14-J14 -> 0 | M14: le reste des 6k je les pris du salaire de Mai
G15: 3 | H15: Nadjet | I15: ='Pointage '!C34*1 -> 9600 | J15: 8000 | K15: =I15-J15 -> 1600 | L15: 6000+2000
G16: 3 | H16: Wahiba | I16: ='Pointage '!D34*1 -> 31270 | K16: =I16-J16 -> 31270
G17: 4 | H17: Lynda | I17: ='Pointage '!E34*1 -> 52070 | J17: 6000 | K17: =I17-J17 -> 46070
G18: 5 | H18: Fouzia | I18: ='Pointage '!F34*1 -> 15340 | K18: =I18-J18 -> 15340
G19: 6 | H19: Youssera | I19: ='Pointage '!G34*1 -> 20060 | J19: 10000 | K19: =I19-J19 -> 10060 | L19: 5000+5000
G20: 7 | H20: Hafida | I20: ='Pointage '!H34*1 -> 40380 | J20: 30000 | K20: =I20-J20 -> 10380
G21: 8 | H21: Djamila | I21: ='Pointage '!I34*1 -> 24780 | K21: =I21-J21 -> 24780
G22: 9 | H22: Yasmine | I22: =12975 -> 12975 | K22: =I22-J22 -> 12975
G23: 10 | H23: Kenza | I23: ='Pointage '!K34*1 -> 10899 | K23: =I23-J23 -> 10899
G24: 11 | H24: Samira | I24: ='Pointage '!L34*1 -> 24912 | J24: 5000 | K24: =I24-J24 -> 19912
G25: 12 | H25: Salima | I25: ='Pointage '!O34*1 -> 4500 | K25: =I25-J25 -> 4500
G26: 13 | H26: Sarah | I26: ='Pointage '!M34*1 -> 10000 | K26: =I26-J26 -> 10000
G27: 14 | H27: Vendeuse | I27: ='Pointage '!N34*1 -> 25000 | J27: 18000 | K27: =I27-J27 -> 7000
H28: TOTAL | I28: =SUM(I13:I27) -> 341786 | J28: =SUM(J13:J27) -> 137000 | K28: =SUM(K13:K27) -> 204786
H29: =I28-J28 -> 204786 | K29: =I29-J29 -> 0

Sheet Les charges 
F2: Produit | G2: Quantité | H2: Prix unitaire | I2: Prix | J2: Date d'achat
F3: levure nouara | G3: 2 | H3: 600 | I3: =H3*G3 -> 1200 | J3: 24/01/203
F4: vanille | G4: 1 | H4: 2350 | I4: =H4*G4 -> 2350 | J4: 21/01/2023
F5: Chocolat wedjedane Noir | G5: 6 | H5: 250 | I5: =G5*H5 -> 1500 | J5: 45006
F6: chocolat wedjedene noisette | G6: 6 | H6: 260 | I6: =H6*G6 -> 1560 | J6: 21/01/2023
F7: chocolat wedjedane blanc | G7: 10 | H7: 250 | I7: =H7*G7 -> 2500 | J7: 44947
F8: chocolat wedjedane au lait | G8: 21 | H8: 250 | I8: 2500
F9: Noix de cajou | G9: 0.5 | H9: 2300 | I9: =H9*G9 -> 1150 | J9: 21/01/2023
F10: chocolat à tartiner | G10: 1 | H10: 3500 | I10: =H10*G10 -> 3500 | J10: 21/01/2023
F11: sachet transparent | G11: 1 | H11: 1320 | I11: =H11*G11 -> 1320 | J11: 45012
F12: fromage bidon Mont d'or | G12: 2 | H12: 750 | I12: =H12*G12 -> 1500 | J12: 270/03/2023
F13: fromage blanc | G13: 1 | H13: 1250 | I13: =H13*G13 -> 1250 | J13: 45012
F14: les assietes | G14: 110 | H14: 7.5 | I14: =H14*G14 -> 825 | J14: 45012
F15: 3assila | G15: 10 | H15: 750 | I15: =H15*G15 -> 7500 | J15: 25/03/2023
F16: sanoudj | G16: 1 | H16: 1200 | I16: =H16*G16 -> 1200 | J16: 45007
F17: djeldjelane | G17: 1 | H17: 800 | I17: =H17*G17 -> 800 | J17: 45007
F18: habet halawa | G18: 2 | H18: 900 | I18: =H18*G18 -> 1800 | J18: 45007
F19: cerise confit | G19: 1 | H19: 2000 | I19: =H19*G19 -> 2000 | J19: 45007
F20: les quissetes argentée | G20: 100 | H20: 40 | I20: =H20*G20 -> 4000 | J20: 45001
F21: Margarine Fleurial 250g 40 boites | G21: 60 | H21: 85 | I21: =H21*G21 -> 5100 | J21: 44999
F22: semen Madina 1,8kg | G22: 10 | H22: 805 | I22: =H22*G22 -> 8050 | J22: 44999
F23: huille elio 5 litres | G23: 10 | H23: 600 | I23: =H23*G23 -> 6000 | J23: 25/03/2023
F24: huile 1 litre | G24: 4 | H24: 1800 | I24: =H24*G24 -> 7200 | J24: 45007
F25: Semoule Fine Safina 25kg | G25: 5 | H25: 1600 | I25: =H25*G25 -> 8000 | J25: 45005
F26: semoule sahel 10kg | G26: 80 | H26: 500 | I26: =H26*G26 -> 40000 | J26: 18/02/2023
F27: semoule Sahel 25kg | G27: 5 | H27: 1000 | I27: =H27*G27 -> 5000 | J27: 17/01/2023
F28: semoule gros Moula 1kg | G28: 5 | H28: 160 | I28: =H28*G28 -> 800 | J28: 44941
F29: semoule Moula Fine 10kg | G29: 3 | H29: 700 | I29: =H29*G29 -> 2100 | J29: 45003
F30: semoule gros Moula 10kg | G30: 3 | H30: 1280 | I30: =H30*G30 -> 3840 | J30: 45004
F31: semoule Mama 1kg | G31: 9 | H31: 130 | I31: =H31*G31 -> 1170 | J31: 44994
F32: Leuvure Boulagère | G32: 10 | H32: 385 | I32: =H32*G32 -> 3850 | J32: 44920
F33: Khel | G33: 3 | H33: 75 | I33: =H33*G33 -> 225 | J33: 14/12/2022
F34: fromage bidonprisident | G34: 3 | H34: 900 | I34: =H34*G34 -> 2700 | J34: 45015
F35: gherss | G35: 7 | H35: 140 | I35: =H35*G35 -> 980 | J35: 45015
F36: cheddar | G36: 1.7 | H36: 1700 | I36: =H36*G36 -> 2890 | J36: 45005
F37: Maa zehar | G37: 14 | H37: 70 | I37: =H37*G37 -> 980 | J37: 45005
F38: boîte demie plateaux | G38: 25 | H38: 90 | I38: =H38*G38 -> 2250 | J38: 44992
F39: lave main | G39: 2 | H39: 150 | I39: =H39*G39 -> 300 | J39: 45013
F40: sucre glace | G40: 24 | H40: 115 | I40: =H40*G40 -> 2760 | J40: 45001
F41: amande efilet | G41: 1 | H41: 1980 | I41: =H41*G41 -> 1980 | J41: 45001
...

Sheet Feuille 5
F4: bénéfice | G4: 520000
F5: Loyer | G5: 110000
F6: Recette Avril | G6: =RECAP!D33*1 -> 1488000
F7: Les Charges Mois d'Avril | G7: ='Les charges '!I244*1 -> 669757
F8: Laiterie Soummam | G8: 171000
F9: Cash chez Sofiane | G9: 303000
F10: Avance salaires | G10: ='les salaires '!J28*1 -> 137000
F11: La caisse | G11: 7000
G12: =G4+G5+G6-G7-G8-G9-G10-G11 -> 830243
K17: Mois de Février | L17: Mois de Mars | M17: Mois d'Avril
J18: Recette | K18: 1400000 | L18: 1928000 | M18: =RECAP!D33*1 -> 1488000
J19: Charges | K19: 597000 | L19: 938000 | M19: 670000
J20: Salaires | K20: 413000 | L20: 360000 | M20: 335000
J21: Loyer | K21: 110000 | L21: 110000 | M21: 110000
J22: Profit Net | K22: 280000 | L22: 520000 | M22: 370000
O23: cash restant
O24: =M18-M19-'les salaires '!J28-RECAP!P11-RECAP!P14 -> 362000

Sheet hhh
B2: Date | C2: Samira | P2: Date | Q2: Yasmine
A3: Samedi | B3: 45017 | C3: 0 | O3: Samedi | P3: 45017 | Q3: 0
A4: dimanche | B4: 45018 | C4: 1 | O4: dimanche | P4: 45018 | Q4: 0
A5: lundi | B5: 45019 | C5: 1 | O5: lundi | P5: 45019 | Q5: 0
A6: mardi | B6: 45020 | C6: 0 | O6: mardi | P6: 45020 | Q6: 0
A7: mercredi | B7: 45021 | C7: 0 | O7: mercredi | P7: 45021 | Q7: 0
A8: jeudi | B8: 45022 | C8: 0 | O8: jeudi | P8: 45022 | Q8: 0
A9: vendredi | B9: 45023 | C9: 1 | O9: vendredi | P9: 45023 | Q9: 0
A10: samedi | B10: 45024 | C10: 1 | O10: samedi | P10: 45024 | Q10: 0
A11: dimanche | B11: 45025 | C11: 1 | O11: dimanche | P11: 45025 | Q11: 0
A12: lundi | B12: 45026 | C12: 1 | O12: lundi | P12: 45026 | Q12: 0
A13: mardi | B13: 45027 | C13: 1 | O13: mardi | P13: 45027 | Q13: 0
A14: mercredi | B14: 45028 | C14: 1 | O14: mercredi | P14: 45028 | Q14: 1
... A32: dimanche | B32: 45046 | C32: 1 | O32: dimanche | P32: 45046 | Q32: 0
C33: =SUM(C3:C32) -> 24 | Q33: =SUM(Q3:Q32) -> 12.5
C34: 1077 | Q34: 1077
C35: =C34*C33 -> 25848 | Q35: =Q34*Q33 -> 13462.5
C36: 24912 | Q36: 12975
G85: Date | H85: Vendeuse
F86: Samedi | G86: 45017 | H86: 1
F87: dimanche | G87: 45018 | H87: 1
F88: lundi | G88: 45019 | H88: 1
F89: mardi | G89: 45020 | H89: 1
F90: mercredi | G90: 45021 | H90: 1
F91: jeudi | G91: 45022 | H91: 1
F92: vendredi | G92: 45023 | H92: 1
F93: samedi | G93: 45024 | H93: 1
F94: dimanche | G94: 45025 | H94: 1
F95: lundi | G95: 45026 | H95: 1
F96: mardi | G96: 45027 | H96: 1
F97: mercredi | G97: 45028 | H97: 1
... F115: dimanche | G115: 45046 | H115: 1
H116: =SUM(H86:H115) -> 25
H117: 1000
H118: =H117*H116 -> 25000
