Workbook

Sheet RECAP
B1: Date | C1: Recette Septembre 2023 | D1: Recette | E1: Charges | F1: Salaire | G1: Loyer | H1: Net Profit | I1: Nb de jours | K1: Objectif | L1: 45170
A2: Vendredi | B2: 45261 | C2: 48000 | D2: 40000 | I2: 1 | L2: 48000
A3: Samedi | B3: 45262 | C3: 36000 | D3: 41000 | I3: 1 | L3: 36000 | M3: Bénéfice Moyen par jour | N3: Moyenne | O3: Moyenne salaire | P3: pourcentage du salaire vis à vis la recettte
A4: Dimanche | B4: 45263 | C4: 48000 | D4: 40000 | I4: 1 | L4: 48000 | M4: =H35/I35 -> #DIV/0! | N4: =D35/I35 -> #DIV/0! | P4: =O4/N4 -> #DIV/0!
A5: Lundi | B5: 45264 | C5: 25000 | D5: 33000 | I5: 1 | L5: 25000
A6: Mardi | B6: 45265 | C6: 34000 | D6: 38000 | I6: 1 | L6: 34000 | M6: Moyenne des charges par jour | N6: Objectif
A7: Mercredi | B7: 45266 | C7: 25000 | D7: 40000 | I7: 1 | L7: 25000 | M7: =E35/I35 -> #DIV/0! | N7: 100000
A8: Jeudi | B8: 45267 | C8: 31000 | D8: 52000 | I8: 1 | L8: 31000 | M8: ²
A9: Vendredi | B9: 45268 | C9: 37000 | D9: 37000 | I9: 1 | L9: 37000
A10: Samedi | B10: 45269 | C10: 40000 | D10: 30000 | I10: 1 | L10: 40000 | M10: Cash restant | N10: Magasin | O10: Cash réel | P10: Mes dettes pour le magasin
A11: Dimanche | B11: 45270 | C11: 44000 | D11: 44000 | I11: 1 | L11: 44000 | M11: =D33-E33-Salaires!L27-N11 -> 811485 | N11: 15000 | O11: 340000 | P11: =M11-O11 -> 471485
A12: Lundi | B12: 45271 | C12: 37000 | D12: 50000 | I12: 1 | L12: 37000 | O12: 310000+30000
A13: Mardi | B13: 45272 | C13: 32000 | D13: 35000 | I13: 1 | L13: 32000 | M13: loyer | O13: idir: 35000 | P13: sofiane: 15000+2000+4000
A14: Mercredi | B14: 45273 | C14: 37000 | D14: 48000 | I14: 1 | L14: 37000 | O14: La caisse : | P14: sifou 1520
A15: Jeudi | B15: 45274 | C15: 37000 | D15: 75000 | I15: 1 | L15: 37000 | P15: sofiane : 12000+2000 poel | S15: Bénéfice Mois de Novembre 2023+ loyer | T15: 440000
A16: Vendredi | B16: 45275 | C16: 42000 | D16: 55000 | I16: 1 | L16: 42000 | S16: recette | T16: =D33 -> 1678000
A17: Samedi | B17: 45276 | C17: 59000 | D17: 35000 | I17: 1 | L17: 59000 | O17: Bénéfice Mois de Novembre | P17: 330000 | S17: charges | T17: =E33 -> 727515
A18: Dimanche | B18: 45277 | C18: 58000 | D18: 60000 | I18: 1 | L18: 58000 | O18: Loyer | P18: 110000 | S18: avances salaires | T18: =Salaires!L27*1 -> 124000
A19: Lundi | B19: 45278 | C19: 25000 | D19: 45000 | I19: 1 | L19: 25000 | M19: Différence mois de Juin | O19: Chèque VMR | P19: 34000 | S19: la caisse | T19: =N11*1 -> 15000 | Y19: 1
A20: Mardi | B20: 45279 | C20: 38000 | D20: 52000 | I20: 1 | L20: 38000 | M20: =D35-C35 -> 0 | O20: Je dois donner à Sofiane | P20: =P17+P18-P19 -> 406000 | S20: chèque | T20: 34000
A21: Mercredi | B21: 45280 | C21: 16000 | D21: 84000 | I21: 1 | L21: 16000 | M21: Différence objectif | O21: Sofiane caisse | P21: 16000 | S21: cache qui doit etre rester | T21: =T15+T16-T17-T18-T19-T20 -> 1217485
A22: Jeudi | B22: 45281 | C22: 50000 | D22: 60000 | I22: 1 | L22: 50000 | M22: =K36-E36 -> 0 | P22: =P20-P21 -> 390000 | S22: cache réel | T22: 370000 | U22: 325000 cache + 20000da ccp+25000 khalida
A23: Vendredi | B23: 45282 | C23: 90000 | D23: 190000 | I23: 1 | L23: 90000 | M23: Différence du Totale | S23: mes dettes pour le magasin | T23: =T21-T22 -> 847485
A24: Samedi | B24: 45283 | C24: 79000 | D24: 50000 | I24: 1 | L24: 79000 | M24: =D33-C33 -> 424000
A25: Dimanche | B25: 45284 | C25: 33000 | D25: 40000 | I25: 1 | L25: 33000 | M25: Les vendredis
A26: Lundi | B26: 45285 | C26: 47000 | D26: 31000 | I26: 1 | L26: 47000 | M26: =D9+D16+D23+D30 -> 316000
A27: Mardi | B27: 45286 | C27: 35000 | D27: 36000 | I27: 1 | L27: 35000
A28: Mercredi | B28: 45287 | C28: 36000 | D28: 43000 | I28: 1 | L28: 36000 | M28: Cash réel
A29: Jeudi | B29: 45288 | C29: 35000 | D29: 60000 | I29: 1 | L29: 35000 | M29: 51000
A30: Vendredi | B30: 45289 | C30: 43000 | D30: 34000 | I30: 1 | L30: 43000 | M30: rest à payer
A31: Samedi | B31: 45290 | C31: 57000 | D31: 50000 | I31: 1 | L31: 57000
A32: Dimanche | B32: 45291 | C32: 0 | D32: 150000 | I32: 1 | L32: 0
C33: =SUM(C2:C32) -> 1254000 | D33: =SUM(D2:D32) -> 1678000 | E33: ='Les charges'!H331*1 -> 727515 | F33: =Salaires!K27*1 -> 386509.5 | G33: 110000 | H33: =D33-E33-F33-G33 -> 453975.5 | I33: =SUM(I2:I32) -> 31 | L33: =SUM(L2:L32) -> 1254000
M35: =M11-M29-M34 -> 760485
D38: -

Sheet Pointage 
B1: Date | C1: Lynda | D1: Hafida | E1: Djamila | F1: Youssera | G1: Yasmine vendeuse | H1: Kenza | I1: Yasmine | J1: Amina | K1: Fouzia | L1: Nadjet | M1: Samia | N1: Alia | O1: Fatiha | P1: Samira | Q1: NadiaFemme de ménage | R1: Nadia | S1: Remarque
A2: Vendredi | B2: 45261 | C2: 1 | D2: 0 | E2: 0 | F2: 0 | G2: 1 | H2: 1 | I2: 1 | J2: 2 | L2: 0 | M2: 0 | N2: 1 | P2: 0 | Q2: 0 | R2: 0
A3: Samedi | B3: 45262 | C3: 0.5 | D3: 0 | E3: 1 | F3: 1 | G3: 1 | H3: 0 | I3: 0 | J3: 1 | K3: 0 | L3: 0 | M3: 1 | N3: 0 | P3: 1 | Q3: 1 | R3: 1
A4: Dimanche | B4: 45263 | C4: 0 | D4: 1 | E4: 1 | F4: 1 | G4: 1 | H4: 0 | I4: 0 | J4: 1 | K4: 0 | L4: 0 | M4: 1 | N4: 0 | P4: 1 | Q4: 1 | R4: 1
A5: Lundi | B5: 45264 | C5: 0 | D5: 1 | E5: 1 | F5: 1 | G5: 0 | H5: 0 | I5: 1 | J5: 1 | K5: 0 | L5: 0 | M5: 0.25 | N5: 0.5 | P5: 1 | Q5: 1 | R5: 1
A6: Mardi | B6: 45265 | C6: 0 | D6: 1 | E6: 1 | F6: 1 | G6: 1 | H6: 0 | I6: 0 | J6: 1 | K6: 0 | L6: 0 | M6: 1 | N6: 0.5 | P6: 0 | Q6: 1 | R6: 1
A7: Mercredi | B7: 45266 | C7: 0.5 | D7: 1 | E7: 1 | F7: 1 | G7: 1 | H7: 0 | I7: 0 | J7: 1 | K7: 0 | L7: 0 | M7: -3 | N7: 0.5 | P7: 1 | Q7: 1 | R7: 0
A8: Jeudi | B8: 45267 | C8: 0 | D8: 1 | E8: 1 | F8: 0.5 | G8: 0 | H8: 0 | I8: 1 | J8: 1 | K8: 0 | L8: 0 | M8: 0 | N8: 0.5 | P8: 1 | Q8: 1 | R8: 0
A9: Vendredi | B9: 45268 | C9: 1 | D9: 0 | E9: 0 | F9: 0 | G9: 1 | H9: 0 | I9: 1 | J9: 1 | K9: 0 | L9: 0 | M9: 0 | N9: 1 | P9: 0 | Q9: 0 | R9: 0
A10: Samedi | B10: 45269 | C10: 0.5 | D10: -1 | E10: 1 | F10: 1 | G10: 1 | H10: 0 | I10: 0 | J10: 1 | K10: 0 | L10: 0 | M10: 0 | N10: 1 | P10: 1 | Q10: 1 | R10: 0
A11: Dimanche | B11: 45270 | C11: 0 | D11: 1 | E11: 1 | F11: 1 | G11: 1 | H11: 1 | I11: 0 | J11: 1 | K11: 1 | L11: 1 | M11: 0 | N11: 0 | P11: 0 | Q11: 1 | R11: 0
A12: Lundi | B12: 45271 | C12: 0 | D12: 1 | E12: 1 | F12: 1 | G12: 0.5 | H12: 0 | I12: 0 | J12: 1 | K12: 1 | L12: 1 | M12: 0 | N12: 1 | P12: 0 | Q12: 1 | R12: 1
A13: Mardi | B13: 45272 | C13: 0 | D13: 0 | E13: 1 | F13: 1 | G13: 1 | H13: 0 | I13: 0 | J13: 1 | K13: 1 | L13: 1 | M13: 0 | N13: 0 | P13: 1 | Q13: 1 | R13: 1 | S13: Hafida s'est absenté pour RDV de médecin
A14: Mercredi | B14: 45273 | C14: 0 | D14: 1 | E14: 1 | F14: 1 | G14: 1 | H14: 0 | I14: 0 | J14: 0 | K14: 1 | L14: 1 | M14: 0 | N14: 1 | P14: 0 | Q14: 1 | R14: 1 | S14: Hafida djate en retard pour les analyses
A15: Jeudi | B15: 45274 | C15: 0 | D15: 1 | E15: 1 | F15: 0,5 | G15: 1 | H15: 0 | I15: 0 | J15: 1 | K15: 1 | L15: 1 | M15: 0 | N15: 1 | P15: 1 | Q15: 1 | R15: 1 | S15: Hafida daret retard à cause du medecin
A16: Vendredi | B16: 45275 | C16: 2 | D16: 1 | E16: 0 | F16: 0 | G16: 1 | H16: 0 | I16: 0.5 | J16: 1 | K16: 0 | L16: 0 | M16: 0 | N16: 0 | P16: 0 | Q16: 0 | R16: 0
A17: Samedi | B17: 45276 | C17: 1 | D17: 1 | E17: 1 | F17: 1 | G17: 1 | H17: 0 | I17: 0 | J17: 1 | K17: 0 | L17: 0 | M17: 0 | N17: 1 | P17: 1 | Q17: 0 | R17: 1 | S17: Nadia + youssera + Amina khalitehom youkhouredjou bekeri
A18: Dimanche | B18: 45277 | C18: 0 | D18: 1 | E18: 1 | F18: 1 | G18: 1 | H18: 0 | I18: 0 | J18: 1 | K18: 1 | L18: 1 | M18: 0 | N18: 0 | P18: 0 | Q18: 1 | R18: 1
A19: Lundi | B19: 45278 | C19: 0 | D19: 1 | E19: 1 | F19: 0 | G19: 0 | H19: 0 | I19: 1 | J19: 1 | K19: 1 | L19: 1 | M19: 0 | N19: 1 | P19: 1 | Q19: 1 | R19: 1
A20: Mardi | B20: 45279 | C20: 0 | D20: 1 | E20: 1 | F20: 1 | G20: 1 | H20: 0 | I20: 0 | J20: 1 | K20: 1 | L20: 0 | M20: 0 | N20: 0 | P20: 0.5 | Q20: 1 | R20: 1
A21: Mercredi | B21: 45280 | C21: 0 | D21: 1 | E21: 1 | F21: 2 | G21: 1 | H21: 0 | I21: 0 | J21: 1 | K21: 2 | L21: 1 | M21: 0 | N21: 0 | P21: 1 | Q21: 1 | R21: 1
A22: Jeudi | B22: 45281 | C22: 1 | D22: 1 | E22: 1 | F22: 0.5 | G22: 1 | H22: 0 | I22: 1 | J22: 1 | K22: 0.5 | L22: 0 | M22: 0 | N22: 1 | O22: 1 | P22: 0 | Q22: 1 | R22: 0.75 | S22: Fatiha
A23: Vendredi | B23: 45282 | C23: 1 | D23: 1 | E23: 0 | F23: 0 | G23: 1 | H23: 1 | I23: 1 | J23: 1 | K23: 0 | L23: 0 | M23: 0 | N23: 1 | O23: 0 | P23: 0 | Q23: 0 | R23: 0
A24: Samedi | B24: 45283 | C24: 1 | D24: 1 | E24: 1 | F24: 0.5 | G24: 1 | H24: 1 | I24: 0 | J24: 1 | K24: 1 | L24: 0 | M24: 0 | N24: 0 | O24: 1 | P24: 0 | Q24: 1 | R24: 1 | S24: Fatiha
A25: Dimanche | B25: 45284 | C25: 0.5 | D25: 1 | E25: 1 | F25: 1 | G25: 1 | H25: 0 | I25: 1 | J25: 1 | K25: 1 | L25: 0 | M25: 0 | N25: 0 | O25: 0 | P25: 1 | Q25: 1 | R25: 0
A26: Lundi | B26: 45285 | C26: 0 | D26: 1 | E26: 1 | F26: 1 | G26: 0 | H26: 0 | I26: 1 | J26: 0 | K26: 1 | L26: 0 | M26: 0 | N26: 0 | O26: 0 | P26: 0 | Q26: 1 | R26: 1 | S26: 0
A27: Mardi | B27: 45286 | C27: 0 | D27: 1 | E27: 1 | F27: 1 | G27: 0 | H27: 0 | I27: 1 | J27: 1 | K27: 0.5 | L27: 0 | M27: 0 | N27: 0 | O27: 1 | P27: 1 | Q27: 1 | R27: 1 | S27: 0
A28: Mercredi | B28: 45287 | C28: 1 | D28: 1 | E28: 1 | F28: 1 | G28: 1 | H28: 1 | I28: 0 | J28: 1 | K28: 1 | L28: 1 | M28: 0 | N28: 0 | O28: 1 | P28: 0 | Q28: 1 | R28: 1
A29: Jeudi | B29: 45288 | C29: 1 | D29: 1 | E29: 1 | F29: 0 | G29: 1 | H29: 0 | I29: 0 | J29: 1 | K29: 0.5 | L29: 1 | M29: 0 | N29: 0 | O29: 1 | P29: 1 | Q29: 1 | R29: 1
A30: Vendredi | B30: 45289 | C30: 1 | D30: 1 | E30: 0 | F30: 0 | G30: 1 | H30: 0 | I30: 0 | J30: 1 | K30: 0 | L30: 0 | M30: 0 | N30: 0 | O30: 0 | P30: 1 | Q30: 0 | R30: 0
A31: Samedi | B31: 45290 | C31: 1 | D31: 1 | E31: 1 | F31: 1 | G31: 1 | H31: 1 | I31: 0 | J31: 1 | K31: 0.5 | L31: 0 | M31: 0 | N31: 0 | O31: 1 | P31: 1 | Q31: 1 | R31: 1
A32: Dimanche | B32: 45291 | C32: 1 | D32: 1 | E32: 1 | F32: 1 | G32: 1 | H32: 1 | I32: 0 | J32: 1 | K32: 1 | L32: 0 | M32: 0 | N32: 0 | O32: 1 | P32: 1 | Q32: 1 | R32: 1
C33: =SUM(C2:C32) -> 15 | D33: =SUM(D2:D32) -> 25 | E33: =SUM(E2:E32) -> 26 | F33: =SUM(F2:F32) -> 22.5 | G33: =SUM(G2:G32) -> 25.5 | H33: =SUM(H2:H32) -> 7 | I33: =SUM(I2:I32) -> 10.5 | J33: =SUM(J2:J32) -> 30 | ... R33: =SUM(R2:R32) -> 20.75
C34: 1300 | D34: 1400 | E34: 1270 | F34: 1270 | G34: 1154 | H34: 1154 | I34: 1154 | J34: 1000 | K34: 1400 | L34: 1500 | M34: 1270 | N34: 1200 | O34: 1100 | P34: 1100 | Q34: 1100 | R34: 1100 | S34: =SUM(D34:I34) -> 7402
C35: =C33*C34 -> 19500 | D35: =D34*D33 -> 35000 | E35: =E34*E33 -> 33020 | F35: =F34*F33 -> 28575 | G35: =G34*G33 -> 29427 | H35: =H34*H33 -> 8078 | I35: =I34*I33 -> 12117 | J35: =J34*J33 -> 30000 | K35: =K33*K34 -> 23800 | L35: =L33*L34 -> 15000 | M35: =M33*M34 -> 317.5 | N35: =N33*N34 -> 14400 | O35: =O33*O34 -> 7700 | P35: =P34*P33 -> 19250 | Q35: =Q34*Q33 -> 27500 | R35: =R33*R34 -> 22825
C36: 33000 | D36: 36000 | E36: 33000 | F36: 33000 | G36: 30000 | H36: 30000 | I36: 30000 | J36: 28000 | K36: 36000 | L36: 36000 | M36: 33000 | P36: 28000 | Q36: 28000 | R36: 28000
D37: 31000

Sheet Les charges
E5: Produit | F5: Quantité | G5: Prix unitaire | H5: Prix | I5: Date d'achat
E6: rechta | F6: 25 | G6: 100 | H6: =F6*G6 -> 2500 | I6: Mois de Novembre
E7: poulet haché + blanc de poulet | F7: 3 | G7: 1000 | H7: =F7*G7 -> 3000
E8: citron | F8: 1.5 | G8: 200 | H8: =F8*G8 -> 300
E9: Bessel | F9: 20 | G9: 60 | H9: =F9*G9 -> 1200
E10: Olive noir+ coupé+vert | F10: 3 | G10: 600 | H10: =F10*G10 -> 1800
E11: rechta | F11: 5 | G11: 100 | H11: =F11*G11 -> 500
E12: épinards+ salade+ ail+ thym | F12: 1 | G12: 600 | H12: =F12*G12 -> 600
E13: tomate fraiche | F13: 5 | G13: 80 | H13: =F13*G13 -> 400
E14: isis | F14: 1 | G14: 300 | H14: =F14*G14 -> 300
E15: fromage | F15: 1 | G15: 450 | H15: =F15*G15 -> 450
E16: détergents | F16: 1 | G16: 1500 | H16: =F16*G16 -> 1500
E17: la colle | F17: 2 | G17: 400 | H17: =F17*G17 -> 800
E18: Maiis | F18: 8 | G18: 245 | H18: =F18*G18 -> 1960
... E38: saray orange | F38: 50 | G38: 21 | H38: =F38*G38 -> 1050
E39: coca -fanta | F39: 4 | G39: 530 | H39: =G39*F39 -> 2120
E40: Eau mineral 0,5 litre | F40: 7 | G40: 200 | H40: =F40*G40 -> 1400
E41: eau mineral 1,5 litre | F41: 15 | G41: 200 | H41: =F41*G41 -> 3000
E42: Soda Slim 33cl | F42: 4 | G42: 420 | H42: =F42*G42 -> 1680
E43: gherss | F43: 7 | G43: 200 | H43: =G43*F43 -> 1400
E44: aluminium | F44: 1 | G44: 950 | H44: =F44*G44 -> 950
E45: papier transparent | F45: 1 | G45: 650 | H45: =F45*G45 -> 650
E46: maa zehar | F46: 10 | G46: 75 | H46: =F46*G46 -> 750
E47: amande effilet | F47: 1 | G47: 900 | H47: =F47*G47 -> 900
E48: confiture | F48: 10 | G48: 245 | H48: =F48*G48 -> 2450
E49: 3akeri | F49: 2 | G49: 1100 | H49: =F49*G49 -> 2200
E50: Amandes | F50: 10 | G50: 1600 | H50: =F50*G50 -> 16000
E51: cheddar | F51: 1.5 | G51: 1800 | H51: =G51*F51 -> 2700
E52: hamissa | F52: 11 | G52: 220 | H52: =F52*G52 -> 2420
E53: colorant | F53: 3 | G53: 150 | H53: =G53*F53 -> 450
E54: djeledjelan | F54: 0.5 | G54: 800 | H54: =G54*F54 -> 400
E55: 3assila | F55: 4 | G55: 800 | H55: =G55*F55 -> 3200
E56: bateur | F56: 1 | G56: 4000 | H56: =G56*F56 -> 4000
E57: gherss | F57: 2 | G57: 250 | H57: =G57*F57 -> 500
E58: Boite 48/10 | F58: 1 | G58: 1900 | H58: =G58*F58 -> 1900
E59: Boite 48/07 | F59: 1 | G59: 1500 | H59: =G59*F59 -> 1500
E60: Boite 36 | F60: 0 | G60: 1200 | H60: =G60*F60 -> 0
E61: Boite 24 | F61: 1 | G61: 1100 | H61: =G61*F61 -> 1100
E62: Boite 18 | F62: 1 | G62: 1550 | H62: =G62*F62 -> 1550
E63: Boite 12 | F63: 1 | G63: 1350 | H63: =G63*F63 -> 1350
...

Sheet Salaires
J8: Nom | K8: Salaire | L8: Avance | M8: Salaire à payer
I9: 1 | J9: Sofiane | K9: 30000 | L9: 30000 | M9: =K9-L9 -> 0
I10: 2 | J10: Amel | K10: 30000 | L10: 30000 | M10: =K10-L10 -> 0
I11: 3 | J11: Lynda | K11: ='Pointage '!C35*1 -> 19500 | L11: 2000 | M11: =K11-L11 -> 17500
I12: 4 | J12: Hafida | K12: ='Pointage '!D35*1 -> 35000 | L12: 5000 | M12: =K12-L12 -> 30000 | N12: 5000+2000+
I13: 5 | J13: Djamila | K13: ='Pointage '!E35*1 -> 33020 | M13: =K13-L13 -> 33020
I14: 6 | J14: Youssera | K14: ='Pointage '!F35*1 -> 28575 | M14: =K14-L14 -> 28575
I15: 7 | J15: Yasmine Vendeuse | K15: ='Pointage '!G35*1 -> 29427 | M15: =K15-L15 -> 29427
I16: 8 | J16: Kenza | K16: ='Pointage '!H35*1 -> 8078 | M16: =K16-L16 -> 8078
I17: 9 | J17: Yesmine | K17: ='Pointage '!I35*1 -> 12117 | M17: =K17-L17 -> 12117
I18: 10 | J18: Nadjet | K18: ='Pointage '!L35*1 -> 15000 | L18: 16000 | M18: =K18-L18 -> -1000
I19: 11 | J19: Amina | K19: ='Pointage '!J35*1 -> 30000 | L19: 30000 | M19: =K19-L19 -> 0
I20: 12 | J20: Samira | K20: ='Pointage '!P35*1 -> 19250 | L20: 1000 | M20: =K20-L20 -> 18250
I21: 13 | J21: Samia | K21: ='Pointage '!M35*1 -> 317.5 | M21: =K21-L21 -> 317.5
I22: 14 | J22: Nadia Femme de ménage | K22: ='Pointage '!Q35*1 -> 27500 | M22: =K22-L22 -> 27500
I23: 15 | J23: Alia | K23: ='Pointage '!N35*1 -> 14400 | L23: 5000 | M23: =K23-L23 -> 9400
I24: 16 | J24: Nadia | K24: ='Pointage '!R35*1 -> 22825 | M24: =K24-L24 -> 22825
I25: 17 | J25: Fatiha | K25: ='Pointage '!O35*1 -> 7700 | M25: =K25-L25 -> 7700
I26: 18 | J26: Fouzia | K26: ='Pointage '!K35*1 -> 23800 | L26: 5000 | M26: =K26-L26 -> 18800
J27: TOTAL | K27: =SUM(K9:K26) -> 386509.5 | L27: =SUM(L9:L26) -> 124000 | M27: =SUM(M9:M26) -> 262509.5
J28: =K27-L27 -> 262509.5 | M28: =K28-L28 -> 0

Sheet Feuille 5
H7: 2023
C18: Mois de Janvier | D18: Mois de Février | E18: Mois de Mars | F18: Mois d'Avril | G18: Mois de Mai | H18: Mois de Jiun | I18: Mois de Juillet | J18: Mois d'Aout | K18: Mois de Septembre | L18: Mois d'Octobre | M18: Mois de Novembre | N18: Mois de Décembre | O18: Totale
B19: Recette | C19: 1441000 | D19: 1400000 | E19: 1928000 | F19: 1488000 | G19: 1540000 | H19: 1577000 | I19: 1880000 | J19: 941000 | K19: 1629000 | L19: 1264000 | M19: 1254000 | N19: 1672000 | O19: =SUM(C19:N19) -> 18014000
B20: Charges | C20: 749000 | D20: 597000 | E20: 938000 | F20: 670000 | G20: 753000 | H20: 716000 | I20: 834000 | J20: 492000 | K20: 692000 | L20: 580000 | M20: 509000 | N20: 727000 | O20: =SUM(C20:N20) -> 8257000
B21: Salaires | C21: 332000 | D21: 413000 | E21: 360000 | F21: 335000 | G21: 347000 | H21: 331000 | I21: 416000 | J21: 239000 | K21: 287000 | L21: 364000 | M21: 305000 | N21: 385000 | O21: =SUM(C21:N21) -> 4114000
B22: Loyer | C22: 110000 | D22: 110000 | E22: 110000 | F22: 110000 | G22: 110000 | H22: 110000 | I22: 110000 | J22: 110000 | K22: 110000 | L22: 110000 | M22: 110000 | N22: 110000 | O22: =SUM(C22:N22) -> 1320000
B23: Profit Net | C23: 250000 | D23: 280000 | E23: 520000 | F23: 370000 | G23: =G19-G20-G21-G22 -> 330000 | H23: =H19-H20-H21-H22 -> 420000 | I23: 520000 | J23: 100000 | K23: 540000 | L23: 210000 | M23: =M19-M20-M21-M22 -> 330000 | N23: 450000 | O23: =SUM(C23:N23) -> 4320000
G37: Mois de Decembre
F38: Recette | G38: 1672000
F39: Charges | G39: 727000
F40: Salaires | G40: 385000
F41: Loyer | G41: 110000
F42: Profit Net | G42: =G38-G39-G40-G41 -> 450000 | U42: Mois de Novembre | V42: Mois de Decembre
T43: Recette | U43: 1254000 | V43: 1672000
T44: Charges | U44: 509000 | V44: 727000
T45: Salaires | U45: 305000 | V45: 385000
T46: Loyer | U46: 110000 | V46: 110000
T47: Profit Net | U47: =U43-U44-U45-U46 -> 330000 | V47: =V43-V44-V45-V46 -> 450000
Y59: Totale 2023
X60: Recette | Y60: =O19 -> 18014000
X61: Charges | Y61: =O20 -> 8257000
X62: Salaires | Y62: =O21 -> 4114000
X63: Loyer | Y63: =O22 -> 1320000
X64: Profit Net | Y64: =O23 -> 4320000
