Workbook

Sheet RECAP
B1: Date | C1: Recette Mars 2025 | D1: Recette | E1: Charges | F1: Salaire | G1: Che7i7a | H1: Loyer | I1: Net Profit | J1: Nb de jours | L1: Objectif | M1: Mois de Mars 2025
A2: Mardi | B2: 45748 | C2: 78000 | D2: 0 | G2: 0 | J2: 0 | M2: 78000
A3: Mercredi | B3: 45749 | C3: 48000 | D3: 0 | G3: 0 | J3: 0 | M3: 48000 | N3: Bénéfice Moyen par jour | O3: Moyenne | P3: Moyenne salaire | Q3: pourcentage du salaire vis à vis la recettte
A4: Jeudi | B4: 45750 | C4: 53000 | D4: 0 | G4: 0 | J4: 0 | M4: 53000 | N4: =I32/J32 -> 1802.12 | O4: =D32/J32 -> 51280 | Q4: =P4/O4 -> 0
A5: Vendredi | B5: 45751 | C5: 40000 | D5: 0 | G5: 0 | J5: 0 | M5: 40000
A6: Samedi | B6: 45752 | C6: 43000 | D6: 15000 | G6: 2000 | J6: 1 | M6: 43000 | N6: Moyenne des charges par jour | O6: Objectif
A7: Dimanche | B7: 45753 | C7: 45000 | D7: 33000 | G7: 2000 | J7: 1 | M7: 45000 | N7: =E32/J32 -> 26763.4 | O7: 100000
A8: Lundi | B8: 45754 | C8: 63000 | D8: 54000 | G8: 2000 | J8: 1 | M8: 63000 | N8: ² | S8: "
A9: Mardi | B9: 45755 | C9: 54000 | D9: 32000 | G9: 2000 | J9: 1 | M9: 54000
A10: Mercredi | B10: 45756 | C10: 52000 | D10: 48000 | G10: 2000 | J10: 1 | M10: 52000 | N10: Cash restant | O10: Magasin | P10: Cash réel | Q10: Mes dettes pour le magasin
A11: Jeudi | B11: 45757 | C11: 45000 | D11: 46000 | G11: 2000 | J11: 1 | M11: 45000 | N11: =N14+D32-G32-E32-O11-'Les Salaires '!M30 -> 507715 | O11: 44000 | P11: 250000 | Q11: =N11-P11 -> 257715
A12: Vendredi | B12: 45758 | C12: 57000 | D12: 78000 | G12: 2000 | J12: 1 | M12: 57000
A13: Samedi | B13: 45759 | C13: 58000 | D13: 56000 | G13: 2000 | J13: 1 | M13: 58000 | N13: Fond de Roulement
A14: Dimanche | B14: 45760 | C14: 55000 | D14: 65000 | G14: 2000 | J14: 1 | K14: 45k+20k de Fateh | M14: 55000 | N14: 330000
A15: Lundi | B15: 45761 | C15: 74000 | D15: 39000 | G15: 2000 | J15: 1 | M15: 74000 | Q15: La caisse :28000Da
A16: Mardi | B16: 45762 | C16: 29000 | D16: 43000 | G16: 2000 | J16: 1 | K16: 1 | M16: 29000 | N16: Bénéfice Mars + loyer | Q16: CCP: 16000Da
A17: Mercredi | B17: 45763 | C17: 56000 | D17: 62000 | G17: 2000 | J17: 1 | K17: 1 | M17: 56000 | N17: 440000
A18: Jeudi | B18: 45764 | C18: 37000 | D18: 91000 | G18: 2000 | J18: 1 | M18: 37000
A19: Vendredi | B19: 45765 | C19: 36000 | D19: 59000 | G19: 2000 | J19: 1 | M19: 36000 | N19: Différence mois de Décembre
A20: Samedi | B20: 45766 | C20: 49000 | D20: 32000 | G20: 2000 | J20: 1 | M20: 49000 | N20: =D32-C32 -> -812000
A21: Dimanche | B21: 45767 | C21: 61000 | D21: 53000 | G21: 2000 | J21: 1 | M21: 61000 | N21: Différence objectif
A22: Lundi | B22: 45768 | C22: 61000 | D22: 37000 | G22: 2000 | J22: 1 | M22: 61000 | N22: =L35-E35 -> 0 | P22: Bénéfice + Loyer | Q22: 440000
A23: Mardi | B23: 45769 | C23: 36000 | D23: 49000 | G23: 2000 | J23: 1 | M23: 36000 | N23: Différence du Totale | P23: cash | Q23: 38000
A24: Mercredi | B24: 45770 | C24: 39000 | D24: 63000 | G24: 2000 | J24: 1 | M24: 39000 | N24: =D32-C32 -> -812000 | P24: les livraisons | Q24: 24000
A25: Jeudi | B25: 45771 | C25: 57000 | D25: 73000 | G25: 2000 | J25: 1 | M25: 57000 | N25: Les vendredis | P25: Dimanche | Q25: 36000
A26: Vendredi | B26: 45772 | C26: 74000 | D26: 53000 | G26: 2000 | J26: 1 | M26: 74000 | N26: =D9+D16+D23+D30 -> 167000 | P26: Lundi | Q26: 42000
A27: Samedi | B27: 45773 | C27: 68000 | D27: 1000 | G27: 0 | J27: 0 | M27: 68000 | P27: cash | Q27: 220000
A28: Dimanche | B28: 45774 | C28: 70000 | D28: 37000 | G28: 2000 | J28: 1 | M28: 70000 | N28: Cash réel
A29: Lundi | B29: 45775 | C29: 226000 | D29: 55000 | G29: 2000 | J29: 1 | M29: 226000 | N29: 51000
A30: Mardi | B30: 45776 | C30: 370000 | D30: 43000 | G30: 2000 | J30: 1 | M30: 370000 | N30: rest à payer
A31: Mercredi | B31: 45777 | C31: 60000 | D31: 65000 | G31: 2000 | J31: 1 | M31: 60000
C32: =SUM(C2:C31) -> 2094000 | D32: =SUM(D2:D31) -> 1282000 | E32: ='Les Charges '!G280 -> 669085 | F32: ='Les Salaires '!L30 -> 337862 | G32: =SUM(G2:G31) -> 50000 | H32: 180000 | I32: =D32-E32-F32-G32-H32 -> 45053 | J32: =SUM(J2:J31) -> 25 | M32: =SUM(M2:M31) -> 2094000 | P32: Reste à donner à Sofiane | Q32: 100000
G33: Loyer Magasin | H33: 55000
G34: Loyer Locale | H34: 40000 | N34: =N11-N29-N33 -> 456715
D35: 200000 | G35: Sofiane Maison | H35: 45000
G36: Dette Papa | H36: 40000 | P36: Papa | Q36: 40000
D37: -
C48: 1

Sheet Les Charges 
D2: Produit | E2: Quantité | F2: Prix unitaire | G2: Prix | H2: Date d'achat
D3: Semoule Fine 25kg | E3: 10 | F3: 1000 | G3: =E3*F3 -> 10000
D4: Semoule Moyenne 25kg | E4: 2 | F4: 1000 | G4: =E4*F4 -> 2000
D5: semoule Moula moyenne 10kg | E5: 3 | F5: 850 | G5: =E5*F5 -> 2550
D6: Semoule Moula moyenne 2 kg | E6: 6 | F6: 250 | G6: =E6*F6 -> 1500
D7: Faine Makam 10kg | E7: 6 | F7: 450 | G7: =E7*F7 -> 2700
D8: Farine 10kg Sousimie | E8: 4 | F8: 580 | G8: =E8*F8 -> 2320
D9: Levure boulangère | E9: 5 | F9: 415 | G9: =E9*F9 -> 2075
D10: huile 5 litre | E10: 17 | F10: 600 | G10: =E10*F10 -> 10200
D11: Chocolat wedjedane au lait | E11: 5 | F11: 280 | G11: =E11*F11 -> 1400
D12: Chocolat wedjedane noir | E12: 5 | F12: 280 | G12: =E12*F12 -> 1400
D13: chocolat wedjedane noisette | E13: 17 | F13: 280 | G13: =E13*F13 -> 4760
D14: couscous | E14: 4 | F14: 180 | G14: =E14*F14 -> 720
... D28: Canette IZEM | E28: 24 | F28: 72 | G28: =E28*F28 -> 1728
D29: canette Pep's | E29: 21 | F29: 50 | G29: =E29*F29 -> 1050 | H29: on les a jeter périmé
D30: Canette Coca 24 | E30: 37 | F30: 57 | G30: =E30*F30 -> 2109
D31: canette Hamoud | E31: 106 | F31: 45 | G31: =E31*F31 -> 4770
D32: hamoud bouteille | E32: 36 | F32: 35 | G32: =E32*F32 -> 1260
D33: jus tchina 33cl | E33: 96 | F33: 43 | G33: =E33*F33 -> 4128
D34: Cheddar | E34: 1.2 | F34: 1650 | G34: =E34*F34 -> 1980
D35: Sucre cristalisé 1kg | E35: 2 | F35: 90 | G35: =E35*F35 -> 180
D36: Sucre glace | E36: 19 | F36: 116 | G36: =E36*F36 -> 2204
D37: Harrissa | E37: 1 | F37: 280 | G37: =E37*F37 -> 280
D38: Thon 1kg | E38: 10 | F38: 950 | G38: =E38*F38 -> 9500
D39: Maiis | E39: 16 | F39: 430 | G39: =E39*F39 -> 6880
D40: fromage bidon | E40: 5 | F40: 1320 | G40: =E40*F40 -> 6600
D41: harrissa 1kg | E41: 12 | F41: 260 | G41: =E41*F41 -> 3120
... D88: Sachets blanc 5kg | E88: 1 | F88: 1200 | G88: =E88*F88 -> 1200
D89: Maa zehar | E89: 5 | F89: 80 | G89: =E89*F89 -> 400 | H89: 45752
D90: Rayan Hospitalisation | E90: 1 | F90: 5500 | G90: =E90*F90 -> 5500
D91: Bessel | E91: 100 | F91: 70 | G91: =E91*F91 -> 7000
D92: Tomate fraiche | E92: 7 | F92: 100 | G92: =E92*F92 -> 700
D93: plateaux oeufs | E93: 5 | F93: 350 | G93: =E93*F93 -> 1750
D94: viande hachée | E94: 1 | F94: 1500 | G94: =E94*F94 -> 1500
D95: clanc de poulet + poulet Haché | E95: 2.5 | F95: 900 | G95: =E95*F95 -> 2250
C96: 120 | D96: Rechta | E96: 10 | F96: 120 | G96: =E96*F96 -> 1200
D97: Nakkache | E97: 250 | F97: 60 | G97: =E97*F97 -> 15000
C98: 150 | D98: Fraise | E98: 1 | F98: 150 | G98: =E98*F98 -> 150 | H98: Sofiane
C99: 280 | D99: Kiwi | E99: 1 | F99: 270 | G99: =E99*F99 -> 270
C100: 450 | D100: pLateaux oeufs | E100: 1 | F100: 450 | G100: =E100*F100 -> 450
...

Sheet Pointage
B1: Date | C1: Saida | D1: Fatiha | E1: Assia | F1: Samira | G1: Nour ElHouda | H1: Yasmine | I1: Zohra | J1: Rayan | K1: Amina | L1: Khalida | M1: Amina Ain Beniane | N1: Ahlem | O1: Houda Oueld Fayet | P1: Selma | Q1: Merieioma | R1: Aicha | S1: Wafa | T1: Backup
A2: Mardi | B2: 45748 | C2: 0 | D2: 0 | E2: 0 | F2: 0 | G2: 0 | H2: 0 | I2: 2 | J2: 0 | K2: 0 | L2: 0 | M2: 0 | N2: 0 | O2: 0 | P2: 0 | Q2: 9 | R2: 5 | S2: 0 | T2: 0 | U2: Mois e Mars
A3: Mercredi | B3: 45749 | C3: 0 | D3: 0 | E3: 0 | F3: 0 | G3: 0 | H3: 0 | I3: 0 | J3: 0 | K3: 0 | L3: 0 | M3: 0 | N3: 0 | O3: 0 | P3: 0 | Q3: 0 | R3: 0 | S3: 0 | T3: 0
A4: Jeudi | B4: 45750 | C4: 0 | D4: 0 | E4: 0 | F4: 0 | G4: 0 | H4: 0 | I4: 0 | J4: 0 | K4: 0 | L4: 0 | M4: 0 | N4: 0 | O4: 0 | P4: 0 | Q4: 0 | R4: 0 | S4: 0 | T4: 0
A5: Vendredi | B5: 45751 | C5: 0 | D5: 0 | E5: 0 | F5: 0 | G5: 0 | H5: 0 | I5: 0 | J5: 0 | K5: 0 | L5: 0 | M5: 0 | N5: 0 | O5: 0 | P5: 0 | Q5: 0 | R5: 0 | S5: 0 | T5: 0
A6: Samedi | B6: 45752 | C6: 0 | D6: 2 | E6: 0 | F6: 0 | G6: 0 | H6: 1 | I6: 0 | J6: 1 | K6: 0 | L6: 0 | M6: 1 | N6: 1 | O6: 0 | P6: 0 | Q6: 0 | R6: 0 | S6: 0 | T6: 0
A7: Dimanche | B7: 45753 | C7: 1 | D7: 1 | E7: 1 | F7: 0 | G7: 0 | H7: 1 | I7: 1 | J7: 1 | K7: 0 | L7: 1 | M7: 1 | N7: 1 | O7: 0 | P7: 0 | Q7: 0 | R7: 0 | S7: 0 | T7: 0
A8: Lundi | B8: 45754 | C8: 1 | D8: 1 | E8: 0 | F8: 0 | G8: 0 | H8: 1 | I8: 0 | J8: 1 | K8: 0 | L8: 1 | M8: 1 | N8: 1 | O8: 0 | P8: 0 | Q8: 0 | R8: 0 | S8: 0 | T8: 0 | U8: Yasmine retard de 35 min
A9: Mardi | B9: 45755 | C9: 1 | D9: 1 | E9: 0 | F9: 1 | G9: 0 | H9: 1 | I9: 1 | J9: 1 | K9: 0 | L9: 1 | M9: 0 | N9: 1 | O9: 0 | P9: 0 | Q9: 0 | R9: 0 | S9: 0 | T9: 0
A10: Mercredi | B10: 45756 | C10: 1 | D10: 0.5 | E10: 0 | F10: 1 | G10: 1 | H10: 0 | I10: 0 | J10: 1 | K10: 0 | L10: 1 | M10: 1 | N10: 1 | O10: 0 | P10: 0 | Q10: 0 | R10: 0 | S10: 0 | T10: 0
A11: Jeudi | B11: 45757 | C11: 1 | D11: 1 | E11: 0.5 | F11: 1 | G11: 0 | H11: 1 | I11: 1 | J11: 0 | K11: 0 | L11: 1 | M11: 1 | N11: 1 | O11: 0 | P11: 0 | Q11: 0 | R11: 0 | S11: 0 | T11: 0
A12: Vendredi | B12: 45758 | C12: 0 | D12: 2 | E12: 0 | F12: 0 | G12: 0 | H12: 1 | I12: 1.5 | J12: 0 | K12: 1 | L12: 0 | M12: 0 | N12: 0 | O12: 0 | P12: 0 | Q12: 1 | R12: 0 | S12: 0 | T12: 1
A13: Samedi | B13: 45759 | C13: 1 | D13: 1 | E13: 0 | F13: 1 | G13: 0 | H13: 1 | I13: 0 | J13: 1 | K13: 0 | L13: 1 | M13: 1 | N13: 1 | O13: 0 | P13: 0 | Q13: 0 | R13: 0 | S13: 0 | T13: 0
A14: Dimanche | B14: 45760 | C14: 1 | D14: 1 | E14: 0 | F14: 1 | G14: 0 | H14: 1 | I14: 1 | J14: 1 | K14: 0 | L14: 1 | M14: 1 | N14: 1 | O14: 0 | P14: 0 | Q14: 0 | R14: 0 | S14: 0 | T14: 0 | U14: Yasmine retard de 50 min
A15: Lundi | B15: 45761 | C15: 1 | D15: 0 | E15: 0 | F15: 1 | G15: 0 | H15: 1 | I15: 0 | J15: 1 | K15: 0 | L15: 0.5 | M15: 1 | N15: 1 | O15: 0 | P15: 0 | Q15: 1 | R15: 0 | S15: 0 | T15: 0 | U15: Yasmine retard 15 min
A16: Mardi | B16: 45762 | C16: 0 | D16: 1 | E16: 0 | F16: 1 | G16: 1 | H16: 0 | I16: 1 | J16: 1 | K16: 0 | L16: 0.5 | M16: 1 | N16: 1 | O16: 0 | P16: 0 | Q16: 1 | R16: 0 | S16: 0 | T16: 0 | U16: Houda djate à 09h30
A17: Mercredi | B17: 45763 | C17: 0 | D17: 1 | E17: 0 | F17: 1 | G17: 0 | H17: 1 | I17: 0 | J17: 1 | K17: 0 | L17: 1 | M17: 0 | N17: 1 | O17: 0 | P17: 0 | Q17: 1 | R17: 0 | S17: 0 | T17: 0
A18: Jeudi | B18: 45764 | C18: 0 | D18: 1 | E18: 0 | F18: 1 | G18: 0 | H18: 1 | I18: 1 | J18: 1 | K18: 0 | L18: 1 | M18: 0 | N18: 1 | O18: 1 | P18: 0 | Q18: 1 | R18: 0 | S18: 1 | T18: 0
A19: Vendredi | B19: 45765 | C19: 0 | D19: 1 | E19: 0 | F19: 1 | G19: 0 | H19: 0 | I19: 0 | J19: 1 | K19: 0 | L19: 0 | M19: 0 | N19: 0 | O19: 0 | P19: 0 | Q19: 1 | R19: 0 | S19: 1 | T19: 1
A20: Samedi | B20: 45766 | C20: 0 | D20: 1 | E20: 0 | F20: 1 | G20: 0 | H20: 0 | I20: 1 | J20: 1 | K20: 0 | L20: 1 | M20: 0 | N20: 2 | O20: 1 | P20: 0 | Q20: 1 | R20: 0 | S20: 0 | T20: 0
A21: Dimanche | B21: 45767 | C21: 0 | D21: 1 | E21: 0 | F21: 1 | G21: 0 | H21: 1 | I21: 0 | J21: 1 | K21: 0 | L21: 1 | M21: 1 | N21: 1 | O21: 1 | P21: 0 | Q21: 1 | R21: 0 | S21: 0 | T21: 0
A22: Lundi | B22: 45768 | C22: 0 | D22: 0 | E22: 0 | F22: 1 | G22: 0 | H22: 1 | I22: 1 | J22: 1 | K22: 0 | L22: 1 | M22: 1 | N22: 1 | O22: 0 | P22: 0 | Q22: 0 | R22: 0 | S22: 0 | T22: 0
A23: Mardi | B23: 45769 | C23: 0 | D23: 1 | E23: 0 | F23: 1 | G23: 1 | H23: 0 | I23: 0 | J23: 1 | K23: 0 | L23: 1 | M23: 1 | N23: 1 | O23: 1 | P23: 0 | Q23: 1 | R23: 0 | S23: 1 | T23: 0
A24: Mercredi | B24: 45770 | C24: 0 | D24: 1 | E24: 0 | F24: 1 | G24: 0 | H24: 1 | I24: 1 | J24: 1 | K24: 0 | L24: 0 | M24: 1 | N24: 1 | O24: 0 | P24: 0 | Q24: 0 | R24: 0 | S24: 0 | T24: 0
A25: Jeudi | B25: 45771 | C25: 1 | D25: 1 | E25: 0 | F25: 1 | G25: 0 | H25: 1 | I25: 0 | J25: 1 | K25: 0 | L25: 1 | M25: 1 | N25: 1 | O25: 0 | P25: 0 | Q25: 0 | R25: 0 | S25: 1 | T25: 0
A26: Vendredi | B26: 45772 | C26: 0 | D26: 1 | E26: 0 | F26: 1 | G26: 0 | H26: 1 | I26: 1 | J26: 1 | K26: 0 | L26: 0 | M26: 0 | N26: 0 | O26: 0 | P26: 0 | Q26: 0 | R26: 0 | S26: 1 | T26: 1
A27: Samedi | B27: 45773 | C27: 0 | D27: 1 | E27: 0 | F27: 0 | G27: 0 | H27: 0 | I27: 1 | J27: 0 | K27: 0 | L27: 0 | M27: 0 | N27: 0 | O27: 0 | P27: 0 | Q27: 0 | R27: 0 | S27: 0 | T27: 0
A28: Dimanche | B28: 45774 | C28: 1 | D28: 1 | E28: 0 | F28: 1 | G28: 0 | H28: 1 | I28: 0 | J28: 1 | K28: 0 | L28: 1 | M28: 1 | N28: 1 | O28: 0 | P28: 0 | Q28: 0 | R28: 0 | S28: 0 | T28: 0
A29: Lundi | B29: 45775 | C29: 1 | D29: 1 | E29: 0 | F29: 1 | G29: 0 | H29: 1 | I29: 1 | J29: 1 | K29: 0 | L29: 1 | M29: 1 | N29: 1 | O29: 1 | P29: 0 | Q29: 0 | R29: 0 | S29: 0 | T29: 0 | U29: yasmine djate en retard 15 mi,4
A30: Mardi | B30: 45776 | C30: 1 | D30: 0 | E30: 0 | F30: 1 | G30: 1 | H30: 0 | I30: 0 | J30: 1 | K30: 0 | L30: 1 | M30: 1 | N30: 1 | O30: 1 | P30: 0 | Q30: 0 | R30: 0 | S30: 1 | T30: 0 | U30: Houda djate à 09h20
A31: Mercredi | B31: 45777 | C31: 1 | D31: 0.5 | E31: 0 | F31: 1 | G31: 0 | H31: 1 | I31: 1 | J31: 1 | K31: 0 | L31: 1 | M31: 1 | N31: 1 | O31: 1 | P31: 0 | Q31: 0 | R31: 0 | S31: 0 | T31: 0
B32: Heures suplémentaires | D32: 3 | L32: 0.5
C34: =SUM(C2:C33) -> 13 | D34: =SUM(D2:D33) -> 27 | E34: =SUM(E2:E33) -> 1.5 | F34: =SUM(F2:F33) -> 21 | G34: =SUM(G2:G33) -> 4 | H34: =SUM(H2:H33) -> 19 | I34: =SUM(I2:I33) -> 16.5 | J34: =SUM(J2:J33) -> 23 | K34: =SUM(K2:K33) -> 1 | L34: 19 | M34: =SUM(M2:M33) -> 18 | N34: =SUM(N2:N33) -> 23 | O34: =SUM(O2:O33) -> 7 | P34: =SUM(P2:P33) -> 0 | Q34: =SUM(Q2:Q33) -> 18 | R34: =SUM(R2:R33) -> 5 | S34: =SUM(S2:S33) -> 6 | T34: =SUM(T2:T33) -> 3
C35: 1200 | D35: 1155 | E35: 1155 | F35: 1155 | G35: 1155 | H35: 1155 | I35: 1155 | J35: 1347 | K35: 1200 | L35: 1400 | M35: 1347 | N35: 1155 | O35: 1000 | P35: 1200 | Q35: 1200 | R35: 1155 | S35: 1000 | T35: 1500
C36: =C34*C35 -> 15600 | D36: =D34*D35 -> 31185 | E36: =E34*E35 -> 1732.5 | F36: =F34*F35 -> 24255 | G36: =G34*G35 -> 4620 | H36: =H34*H35 -> 21945 | I36: =I34*I35 -> 19057.5 | J36: =J34*J35 -> 30981 | ... T36: =T34*T35 -> 4500

Sheet Les Salaires 
K10: Nom | L10: Salaire | M10: Avance | N10: Salaire à payer
K11: Sofiane | L11: 30000 | M11: 30000 | N11: =L11-M11 -> 0 | O11: le 25/04/2025
K12: Amel | L12: 30000 | M12: 30000 | N12: =L12-M12 -> 0
J13: 1 | K13: Saida | L13: =Pointage!C36 -> 15600 | M13: 16000 | N13: =L13-M13 -> -400 | O13: 6000+10000
J14: 2 | K14: Fatiha | L14: =Pointage!D36 -> 31185 | M14: 31500 | N14: =L14-M14 -> -315 | O14: 3000+22000+6500
J15: 3 | K15: Assia | L15: =Pointage!E36 -> 1732.5 | M15: 2000 | N15: =L15-M15 -> -267.5
J16: 4 | K16: Samira | L16: =Pointage!F36 -> 24255 | M16: 24500 | N16: =L16-M16 -> -245 | O16: 3000+1000+20500
J17: 5 | K17: Nour ElHouda | L17: =Pointage!G36 -> 4620 | M17: 5000 | N17: =L17-M17 -> -380
J18: 6 | K18: Yasmine | L18: =Pointage!H36+O18 -> 26945 | M18: 27000 | N18: =L18-M18 -> -55 | O18: 5000
J19: 7 | K19: Zohra | L19: =Pointage!I36 -> 19057.5 | M19: 19000 | N19: =L19-M19 -> 57.5 | O19: 3000+16000
J20: 8 | K20: Rayan | L20: =Pointage!J36 -> 30981 | M20: 31000 | N20: =L20-M20 -> -19
I21: 5000 | J21: 9 | K21: Amina | L21: =Pointage!K36 -> 1200 | M21: 1200 | N21: =L21-M21 -> 0
J22: 10 | K22: Khalida | L22: =Pointage!L36 -> 26600 | M22: 27500 | N22: =L22-M22 -> -900
J23: 11 | K23: Amina Ain Beniane | L23: =Pointage!M36 -> 24246 | M23: 24500 | N23: =L23-M23 -> -254
J24: 12 | K24: Ahlem | L24: =Pointage!N36 -> 26565 | M24: 26500 | N24: =L24-M24 -> 65
J25: 13 | K25: Houda Ouled Fayet | L25: =Pointage!O36 -> 7000 | M25: 7000 | N25: =L25-M25 -> 0
J26: 14 | K26: Merioma | L26: =Pointage!Q36 -> 21600 | M26: 22000 | N26: =L26-M26 -> -400 | O26: 10800+10800
J27: 15 | K27: Aicha | L27: =Pointage!R36 -> 5775 | M27: 6000 | N27: =L27-M27 -> -225
J28: 16 | K28: Backup | L28: =Pointage!T36 -> 4500 | M28: 4500 | N28: =L28-M28 -> 0
J29: 17 | K29: wafa | L29: =Pointage!S36 -> 6000 | M29: 6000 | N29: =L29-M29 -> 0 | O29: 2000+1000+2000+1000
K30: TOTAL | L30: =SUM(L11:L29) -> 337862 | M30: =SUM(M11:M29) -> 341200 | N30: =L30-M30 -> -3338
N31: =L31-M31 -> 0

Sheet Comparaisons entre les Mois
I16: Mois de Janvier 2025 | J16: Mois de Février 2025 | K16: Mois de Mars 2025 | L16: Mois d'Avril 2025
H17: Recette | I17: 2033000 | J17: 1859000 | K17: 2094000 | L17: 1282000
H18: Charges | I18: 854000 | J18: 884000 | K18: 962000 | L18: 669000
H19: Salaires | I19: 427000 | J19: 409000 | K19: 439000 | L19: 338000
H20: Che7i7a | I20: 62000 | J20: 56000 | K20: 60000 | L20: 50000
H21: Loyer+Dettes | I21: 180000 | J21: 180000 | K21: 180000 | L21: 180000
H22: Profit Net | I22: =I17-I18-I19-I20-I21 -> 510000 | J22: =J17-J18-J19-J20-J21 -> 330000 | K22: =K17-K18-K19-K20-K21 -> 453000 | L22: =L17-L18-L19-L20-L21 -> 45000
