Workbook

Sheet RECAP
B1: Date | C1: Recette d'Aout 2022 | D1: Recette | E1: Charges | F1: Salaire | G1: Loyer | H1: Net Profit | I1: Nb de jours | K1: Objectif | L1: Septembre | M1: Bénéfice Moyen par jour | N1: Moyenne
A2: Samedi | B2: 44835 | C2: 0 | D2: 50000 | I2: 1 | K2: 80000 | L2: 0 | M2: =H33/I33 -> 17445.419 | N2: =D33/I33 -> 61967.742
A3: Dimanche | B3: 44836 | C3: 0 | D3: 51000 | I3: 1 | K3: 80000 | L3: 0
A4: Lundi | B4: 44837 | C4: 0 | D4: 90000 | I4: 1 | K4: 80000 | L4: 0 | M4: Moyenne des charges par jour | N4: Objectif
A5: Mardi | B5: 44838 | C5: 55000 | D5: 120000 | I5: 1 | K5: 80000 | L5: 55000 | M5: =E33/I33 -> 29074.403 | N5: 80000
A6: Mercredi | B6: 44839 | C6: 80000 | D6: 140000 | I6: 1 | K6: 80000 | L6: 80000 | M6: ²
A7: Jeudi | B7: 44840 | C7: 40000 | D7: 210000 | I7: 1 | K7: 80000 | L7: 40000
A8: Vendredi | B8: 44841 | C8: 95000 | D8: 60000 | I8: 1 | K8: 80000 | L8: 95000 | M8: Cash restant | N8: Magasin | O8: caisse | P8: cash en attente pour le récupérer =Dettes éxterieurs
A9: Samedi | B9: 44842 | C9: 55000 | D9: 52000 | I9: 1 | K9: 80000 | L9: 55000 | M9: =D33+N11-N9-N12-N14-N15-E33-'Salaires '!K30-N16 -> 348693.5 | N9: =P9+O9 -> 87000 | P9: 87000
A10: Dimanche | B10: 44843 | C10: 55000 | D10: 42000 | I10: 1 | K10: 80000 | L10: 55000 | P10: sofiane
A11: Lundi | B11: 44844 | C11: 100000 | D11: 35000 | I11: 1 | K11: 80000 | L11: 100000 | M11: loyer | N11: 1020000 | P11: Ccp:15000
A12: Mardi | B12: 44845 | C12: 23000 | D12: 32000 | I12: 1 | K12: 80000 | L12: 23000 | M12: pétrin+ four+ Loyer du local | N12: 270000
A13: Mercredi | B13: 44846 | C13: 48000 | D13: 45000 | I13: 1 | K13: 80000 | L13: 48000 | N13: 75000+145000 | P13: Faouzi 25000+23000+23000
A14: Jeudi | B14: 44847 | C14: 26000 | D14: 80000 | I14: 1 | K14: 80000 | L14: 26000 | M14: Mounir | N14: 50000
A15: Vendredi | B15: 44848 | C15: 55000 | D15: 66000 | I15: 1 | K15: 80000 | L15: 55000 | M15: Loyer Local | N15: 442000
A16: Samedi | B16: 44849 | C16: 60000 | D16: 78000 | I16: 1 | K16: 80000 | L16: 60000 | M16: Amel Maison | N16: 470000 | O16: 200000+100000+10000+70000
A17: Dimanche | B17: 44850 | C17: 125000 | D17: 36000 | I17: 1 | K17: 80000 | L17: 125000 | M17: Différence mois de septembre
A18: Lundi | B18: 44851 | C18: 50000 | D18: 30000 | I18: 1 | K18: 80000 | L18: 50000 | M18: =D33-C33 -> 264000
A19: Mardi | B19: 44852 | C19: 46000 | D19: 40000 | I19: 1 | K19: 80000 | L19: 46000 | M19: Différence objectif
A20: Mercredi | B20: 44853 | C20: 55000 | D20: 54000 | I20: 1 | K20: 80000 | L20: 55000 | M20: =D33-K33 -> -559000
A21: Jeudi | B21: 44854 | C21: 90000 | D21: 30000 | I21: 1 | K21: 80000 | L21: 90000
A22: Vendredi | B22: 44855 | C22: 45000 | D22: 45000 | I22: 1 | K22: 80000 | L22: 45000
A23: Samedi | B23: 44856 | C23: 45000 | D23: 60000 | I23: 1 | K23: 80000 | L23: 45000 | M23: Les vendredis | P23: Le loyer de Samedi est payé en Mois d'octobre on a payé 492000Da
A24: Dimanche | B24: 44857 | C24: 47000 | D24: 100000 | I24: 1 | K24: 80000 | L24: 47000 | M24: =D6+D13+D20+D27 -> 294000 | P24: on va plus compter le pétrin et le four 270000Da
A25: Lundi | B25: 44858 | C25: 37000 | D25: 33000 | I25: 1 | K25: 80000 | L25: 37000 | P25: Donc il reste 258000 Da de l'argent du loyer
A26: Mardi | B26: 44859 | C26: 56000 | D26: 25000 | I26: 1 | K26: 80000 | L26: 56000 | M26: Cash réel | P26: Sofiane m'a donné 45000 Da pour compléter les salaires
A27: Mercredi | B27: 44860 | C27: 43000 | D27: 55000 | I27: 1 | K27: 80000 | L27: 43000 | M27: 227500 | P27: le bénifice est 54 millions j'ai pris 47 millions il reste 7 millions on les récupère du chèque du 71k eli rahom 3aned Mr . mokrani
A28: Jeudi | B28: 44861 | C28: 62000 | D28: 50000 | I28: 1 | K28: 80000 | L28: 62000 | M28: rest à payer
A29: Vendredi | B29: 44862 | C29: 72000 | D29: 70000 | I29: 1 | K29: 80000 | L29: 72000 | M29: =M9-M27 -> 121193.5
A30: Samedi | B30: 44863 | C30: 120000 | D30: 68000 | I30: 1 | K30: 80000 | L30: 120000
A31: Dimanche | B31: 44864 | C31: 72000 | D31: 21000 | I31: 1 | K31: 80000 | L31: 72000
A32: Lundi | B32: 44865 | C32: 0 | D32: 53000 | I32: 1 | K32: 80000 | L32: 0
C33: =SUM(C2:C32) -> 1657000 | D33: =SUM(D2:D32) -> 1921000 | E33: ='Les Charges '!H394*1 -> 901306.5 | F33: ='Salaires '!J30*1 -> 368885.5 | G33: 110000 | H33: =D33-E33-F33-G33 -> 540808 | I33: =SUM(I2:I32) -> 31 | K33: =SUM(K2:K32) -> 2480000 | L33: =SUM(L2:L32) -> 1657000
D34: =D33-C33 -> 264000 | E34: =E33-E36 -> 199306.5 | F34: =F33-F36 -> 63885.5
C35: Objectif | D35: 2475000 | E35: 900000 | F35: 465000 | G35: 110000 | H35: 1000000
C36: Mois de Septembre | D36: 1657000 | E36: 702000 | F36: 305000 | G36: 110000 | H36: 540000
C39: La différence | D39: =D33-D36 -> 264000 | E39: =E33-E36 -> 199306.5 | F39: =F33-F36 -> 63885.5 | G39: =G33-G36 -> 0 | H39: =H33-H36 -> 808

Sheet Pointage
B1: Date | C1: Nadjet | D1: Hafida | E1: Wahiba | F1: Zahida | G1: djamila | H1: Farida | I1: Yousera | J1: Lynda | K1: Kenza | L1: Fouzia | M1: SAmira | N1: Karima | O1: Monia | P1: La nouvelle vendeuse | Q1: Yasmine | R1: Extra | S1: Remarque
A2: Samedi | B2: 44835 | C2: 0 | D2: 1 | E2: 1 | F2: 1 | G2: 1 | H2: 1 | I2: 1 | J2: 1 | K2: 0 | L2: 1 | M2: 1 | N2: 0 | O2: 0 | P2: 0 | Q2: 1 | R2: 0 | S2: 1
A3: Dimanche | B3: 44836 | C3: 0 | D3: 1 | E3: 1 | F3: 1 | G3: 1 | H3: 1 | I3: 0 | J3: 1 | K3: 0.5 | L3: 1 | M3: 1 | N3: 0 | O3: 0 | P3: 0 | Q3: 1 | R3: 0
A4: Lundi | B4: 44837 | C4: 1.25 | D4: 1.25 | E4: 1 | F4: 1.5 | G4: 1.25 | H4: 1.25 | I4: 1 | J4: 1.25 | K4: 0 | L4: 1 | M4: 1 | N4: 0 | O4: 0 | P4: 0 | Q4: 0.75 | R4: 0
A5: Mardi | B5: 44838 | C5: 1 | D5: 1 | E5: 1 | F5: 1.5 | G5: 1 | H5: 1 | I5: 1 | J5: 1 | K5: 0 | L5: 1 | M5: 1 | N5: 0 | O5: 0 | P5: 0 | Q5: 0.5 | R5: 0
A6: Mercredi | B6: 44839 | C6: 1.5 | D6: 1.5 | E6: 1 | F6: 2 | G6: 1 | H6: 1.5 | I6: 1 | J6: 1.5 | K6: 0 | L6: 1 | M6: 1 | N6: 0 | O6: 0 | P6: 0 | Q6: 0.5 | R6: 0
A7: Jeudi | B7: 44840 | C7: 2 | D7: 1.5 | E7: 1 | F7: 1.5 | G7: 0 | H7: 2 | I7: 1 | J7: 1.25 | K7: 0 | L7: 0 | M7: 1 | N7: 0 | O7: 0 | P7: 0 | Q7: 1 | R7: 0
A8: Vendredi | B8: 44841 | C8: 2 | D8: 2 | E8: 1 | F8: 2 | G8: 0 | H8: 2 | I8: 1 | J8: 1.5 | K8: 1 | L8: 1 | M8: 1 | N8: 0 | O8: 0 | P8: 0 | Q8: 1 | R8: 4 | S8: mama et hadjer
A9: Samedi | B9: 44842 | C9: 1 | D9: 0 | E9: 1 | F9: 0 | G9: 1 | H9: 1 | I9: 1 | J9: 1 | K9: 0.5 | L9: 1 | M9: 0 | N9: 0 | O9: 0 | P9: 0 | Q9: 0 | R9: 0
A10: Dimanche | B10: 44843 | C10: 1 | D10: 1 | E10: 1 | F10: 1 | G10: 1 | H10: 0.5 | I10: 1 | J10: 1 | K10: 0 | L10: 1 | M10: 1 | N10: 0 | O10: 0 | P10: 0 | Q10: 0 | R10: 0
A11: Lundi | B11: 44844 | C11: 1 | D11: 1 | E11: 1 | F11: 1 | G11: 1 | H11: 1 | I11: 0.5 | J11: 1 | K11: 0 | L11: 0 | M11: 1 | N11: 0 | O11: 0 | P11: 0 | Q11: 0 | R11: 0
A12: Mardi | B12: 44845 | C12: 1 | D12: 1 | E12: 1 | F12: 1 | G12: 1 | H12: 1 | I12: 1 | J12: 1 | K12: 1 | L12: 0 | M12: 1 | N12: 0 | O12: 0 | P12: 0 | Q12: 0.5 | R12: 0
A13: Mercredi | B13: 44846 | C13: 1 | D13: 1 | E13: 1 | F13: 1 | G13: 0 | H13: 1 | I13: 1 | J13: 1 | K13: 1 | L13: 0 | M13: 1 | N13: 0 | O13: 0 | P13: 0 | Q13: 1 | R13: 0
A14: Jeudi | B14: 44847 | C14: 0 | D14: 1 | E14: 1 | F14: 1 | G14: 1 | H14: 1 | I14: 1 | J14: 2 | K14: 0 | L14: 0 | M14: 1 | N14: 0 | O14: 0 | P14: 0 | Q14: 1 | R14: 0
A15: Vendredi | B15: 44848 | C15: 0 | D15: 0 | E15: 1 | F15: 1 | G15: 1 | H15: 1 | I15: 0 | J15: 1 | K15: 1 | L15: 0 | M15: 0 | N15: 0 | O15: 0 | P15: 0 | Q15: 1 | R15: 0
A16: Samedi | B16: 44849 | C16: 0 | D16: 1 | E16: 1 | F16: 1 | G16: 1 | H16: 1 | I16: 1 | J16: 1.5 | K16: 0 | L16: 0 | M16: 0 | N16: 0 | O16: 0 | P16: 0 | Q16: 0 | R16: 0 | S16: Djamila djate à 10h et Farida à 11h, Hafida à 09h
A17: Dimanche | B17: 44850 | C17: 1 | D17: 1 | E17: 1 | F17: 1 | G17: 1 | H17: 0 | I17: 1 | J17: 1 | K17: 1 | L17: 0 | M17: 1 | N17: 0 | O17: 0 | P17: 0 | Q17: 0 | R17: 0
A18: Lundi | B18: 44851 | C18: 0 | D18: 0.5 | E18: 1 | F18: 1 | G18: 1 | H18: 1 | I18: 0.5 | J18: 0.5 | K18: 1 | L18: 0 | M18: 1 | N18: 0 | O18: 0 | P18: 0 | Q18: 0 | R18: 0
A19: Mardi | B19: 44852 | C19: 0 | D19: 1 | E19: 1 | F19: 1 | G19: 1 | H19: 1 | I19: 1 | J19: 1 | K19: 0 | L19: 0 | M19: 1 | N19: 0 | O19: 0 | P19: 0 | Q19: 1 | R19: 0
A20: Mercredi | B20: 44853 | C20: 1 | D20: 1 | E20: 1 | F20: 0.5 | G20: 0 | H20: 1 | I20: 0.5 | J20: 1 | K20: 1 | L20: 0 | M20: 1 | N20: 0 | O20: 0 | P20: 0 | Q20: 1 | R20: 0
A21: Jeudi | B21: 44854 | C21: 1 | D21: 1 | E21: 0 | F21: 1 | G21: 0 | H21: 1 | I21: 1 | J21: 1 | K21: 0 | L21: 0 | M21: 1 | N21: 0 | O21: 0 | P21: 0 | Q21: 1 | R21: 0
A22: Vendredi | B22: 44855 | C22: 0 | D22: 0 | E22: 1 | F22: 1 | G22: 1 | H22: 1 | I22: 0 | J22: 1 | K22: 1 | L22: 0 | M22: 1 | N22: 0 | O22: 1 | P22: 0 | Q22: 1 | R22: 0
A23: Samedi | B23: 44856 | C23: 0 | D23: 1 | E23: 1 | F23: 1 | G23: 1 | H23: 1 | I23: 1 | J23: 0 | K23: 0 | L23: 0 | M23: 1 | N23: 1 | O23: 1 | P23: 0 | Q23: 0 | R23: 0
A24: Dimanche | B24: 44857 | C24: 0 | D24: 1 | E24: 0 | F24: 1 | G24: 1 | H24: 1 | I24: 1 | J24: 1 | K24: 0.5 | L24: 0 | M24: 1 | N24: 1 | O24: 1 | P24: 0 | Q24: 0 | R24: 0
A25: Lundi | B25: 44858 | C25: 0 | D25: 1 | E25: 1 | F25: 1 | G25: 1 | H25: 1 | I25: 0.5 | J25: 1 | K25: 1 | L25: 0 | M25: 1 | N25: 0 | O25: 1 | P25: 0 | Q25: 0.5 | R25: 1
A26: Mardi | B26: 44859 | C26: 0 | D26: 1 | E26: 1 | F26: 1 | G26: 1 | H26: 0 | I26: 1 | J26: 1 | K26: 0 | L26: 0 | M26: 1 | N26: 0 | O26: 1 | P26: 0.5 | Q26: 0 | R26: 0
A27: Mercredi | B27: 44860 | C27: 0 | D27: 1 | E27: 1 | F27: 1 | G27: 0 | H27: 1 | I27: 1 | J27: 1 | K27: 0 | L27: 0 | M27: 1 | N27: 1 | O27: 1 | P27: 1 | Q27: 1 | R27: 1
A28: Jeudi | B28: 44861 | C28: 0 | D28: 0 | E28: 1 | F28: 1 | G28: 0 | H28: 1 | I28: 1 | J28: 1 | K28: 1 | L28: 0 | M28: 0 | N28: 0 | O28: 1 | P28: 1 | Q28: 0 | R28: 0
... A31: Dimanche | B31: 44864 | C31: 0 | D31: 0 | E31: 1 | F31: 1 | G31: 1 | H31: 1 | I31: 0.5 | J31: 1 | K31: 0 | L31: 0 | M31: 0 | N31: 0 | O31: 0 | P31: 1 | Q31: 1 | R31: 0
A32: Lundi | B32: 44865 | C32: 0 | D32: 0 | E32: 1 | F32: 1 | G32: 1 | H32: 1 | I32: 1 | J32: 1 | K32: 1 | L32: 0 | M32: 1 | N32: 1 | O32: 0 | P32: 1 | Q32: 0
C33: =SUM(C2:C32) -> 15.75 | D33: =SUM(D2:D32) -> 24.75 | E33: =SUM(E2:E32) -> 29 | F33: =SUM(F2:F32) -> 33 | G33: =SUM(G2:G32) -> 24.25 | H33: =SUM(H2:H32) -> 30.25 | I33: =SUM(I2:I32) -> 24.5 | J33: =SUM(J2:J32) -> 32.5 | ... R33: =SUM(R2:R32) -> 6
C34: 1200 | D34: 1111 | E34: 1111 | F34: 1111 | G34: 1111 | H34: 1150 | I34: 1111 | J34: 1111 | K34: 1000 | L34: 1200 | M34: 900 | N34: 1000 | O34: 1200 | P34: 1000 | Q34: 1000 | R34: 1000
C35: =C34*C33 -> 18900 | D35: =D34*D33 -> 27497.25 | E35: =E34*E33 -> 32219 | F35: =F34*F33 -> 36663 | G35: =G34*G33 -> 26941.75 | H35: =H34*H33 -> 34787.5 | I35: =I34*I33 -> 27219.5 | J35: =J34*J33 -> 36107.5 | ... R35: =R34*R33 -> 6000 | S35: =SUM(C35:R35) -> 328885.5

Sheet Les Charges 
E2: Produit | F2: Quantité | G2: Prix unitaire | H2: Prix | I2: Date d'achat
E3: Eau Lala khedidja 1,5 litres | F3: 8 | G3: 190 | H3: =G3*F3 -> 1520 | I3: 44805
E4: Eau Lala khedidja 0,5 litres | F4: 12 | G4: 200 | H4: =G4*F4 -> 2400 | I4: 44805
E5: Huile 2 litres | F5: 20 | G5: 1416 | H5: =G5*F5 -> 28320 | I5: 44805
D6: 50+25 | E6: Huile 5 litre | F6: 47 | G6: 596 | H6: =F6*G6 -> 28012
E7: oeuf | F7: 5 | G7: 550 | H7: =G7*F7 -> 2750 | I7: 44830
E8: sac croissant 23 | F8: 1 | G8: 1450 | H8: =G8*F8 -> 1450 | I8: 44830
E9: sac croissant 14 | F9: 1 | G9: 900 | H9: =G9*F9 -> 900 | I9: 44830
E10: extrait Maa Zehar | F10: 1 | G10: 780 | H10: =G10*F10 -> 780 | I10: 44830
E11: amande éfilet | F11: 1 | G11: 1000 | H11: =G11*F11 -> 1000 | I11: 44830
E12: les quissetes | F12: 10 | G12: 45 | H12: =G12*F12 -> 450 | I12: 44830
E13: colorant blanc | F13: 1 | G13: 550 | H13: =G13*F13 -> 550 | I13: 44830
E14: colorant vert | F14: 1 | G14: 120 | H14: =G14*F14 -> 120 | I14: 44830
E15: beure | F15: 1 | G15: 2500 | H15: =G15*F15 -> 2500 | I15: 44830
E16: amandes | F16: 11 | G16: 1630 | H16: =G16*F16 -> 17930 | I16: 44830
E17: levure chimique | F17: 3 | G17: 560 | H17: =G17*F17 -> 1680 | I17: 44830
E18: Miel | F18: 5 | G18: 770 | H18: =G18*F18 -> 3850 | I18: 44830
... E83: Margarine Fleurial 250g 40 boites | F83: 0.5 | G83: 3440 | H83: =G83*F83 -> 1720 | I83: 44805
E84: Semoule Fine sahel10kg | F84: 25 | G84: 650 | H84: =G84*F84 -> 16250 | I84: 01/09/2022/
E85: Semoule Moyenne Amor Ben Amor 5kg | F85: 8 | G85: 350 | H85: =G85*F85 -> 2800 | I85: 44805
E86: levure boulangère | F86: 6 | G86: 385 | H86: =G86*F86 -> 2310 | I86: 44821
E87: Maizina | F87: 15 | G87: 200 | H87: =G87*F87 -> 3000 | I87: 44805
E88: Sel | F88: 1 | G88: 390 | H88: =G88*F88 -> 390 | I88: 44805
E89: Barquette aluminium 1065 | F89: 80 | G89: 24 | H89: =G89*F89 -> 1920 | I89: 44805
E90: Farine Sim 5kg | F90: 5 | G90: 320 | H90: =G90*F90 -> 1600 | I90: 44807
E91: sauce tomate ELA 3.8KG | F91: 3 | G91: 520 | H91: =G91*F91 -> 1560 | I91: 44809
E92: Fromage spécial pizza | F92: 19 | G92: 285 | H92: =G92*F92 -> 5415 | I92: 44809
E93: Gherss | F93: 3 | G93: 140 | H93: =G93*F93 -> 420 | I93: 44811
E94: Sucre glace 700g | F94: 11 | G94: 115 | H94: =G94*F94 -> 1265 | I94: 44812
E95: sachet farine 25kg | F95: 1 | G95: 1050 | H95: =G95*F95 -> 1050 | I95: 44814
E96: plats traditionel | F96: 15 | G96: 250 | H96: =G96*F96 -> 3750 | I96: 44818
... E130: rechta | F130: 100 | G130: 120 | H130: =G130*F130 -> 12000 | I130: 44839
D131: 2400 | E131: cuissess de poulet | F131: 15 | G131: 160 | H131: =G131*F131 -> 2400 | I131: 44839
E132: courgette | F132: 1 | G132: 140 | H132: =G132*F132 -> 140
E133: navet | F133: 2 | G133: 100 | H133: =G133*F133 -> 200
E134: épinard | F134: 5 | G134: 20 | H134: =G134*F134 -> 100 | I134: 05/
E135: semoule mama 2kg | F135: 20 | G135: 310 | H135: =G135*F135 -> 6200 | I135: 44839
E136: les gants | F136: 1 | G136: 1000 | H136: =G136*F136 -> 1000 | I136: 44839
E137: bessel | F137: 100 | G137: 60 | H137: =G137*F137 -> 6000 | I137: 44839
E138: viande morceaux | F138: 4 | G138: 350 | H138: =G138*F138 -> 1400 | I138: 44839
...

Sheet Salaires 
I11: Nom | J11: Salaire | K11: Avance | L11: Salaire à payer
H12: 1 | I12: Sofiane | J12: 20000 | K12: 20000 | L12: =J12-K12 -> 0
H13: 2 | I13: Amel | J13: 20000 | K13: 20000 | L13: =J13-K13 -> 0
H14: 3 | I14: Nadjet | J14: =Pointage!C35*1 -> 18900 | K14: 19000 | L14: =J14-K14 -> -100
H15: 4 | I15: Hafida | J15: =Pointage!D35*1 -> 27497.25 | K15: 27500 | L15: =J15-K15 -> -2.75 | M15: 10000+4000
H16: 5 | I16: Wahiba | J16: =Pointage!E35*1 -> 32219 | K16: 32500 | L16: =J16-K16 -> -281
H17: 6 | I17: Zahida | J17: =Pointage!F35*1 -> 36663 | K17: 37000 | L17: =J17-K17 -> -337
H18: 7 | I18: Djamila | J18: =Pointage!G35*1 -> 26941.75 | K18: 27000 | L18: =J18-K18 -> -58.25
H19: 8 | I19: Farida | J19: =Pointage!H35*1 -> 34787.5 | K19: 35000 | L19: =J19-K19 -> -212.5 | M19: 1000+1000
H20: 9 | I20: Yousera | J20: =Pointage!I35*1 -> 27219.5 | K20: 27500 | L20: =J20-K20 -> -280.5 | M20: 2000+7000+5000
H21: 10 | I21: lynda | J21: =Pointage!J35*1 -> 36107.5 | K21: 36500 | L21: =J21-K21 -> -392.5 | M21: 15000
H22: 11 | I22: Karima | J22: =Pointage!N35*1 -> 4000 | K22: 4000 | L22: =J22-K22 -> 0
H23: 12 | I23: Samira | J23: =Pointage!M35*1 -> 21600 | K23: 22000 | L23: =J23-K23 -> -400
H24: 13 | I24: Fouzia | J24: =Pointage!L35*1 -> 9600 | K24: 10000 | L24: =J24-K24 -> -400
H25: 14 | I25: Monia | J25: =Pointage!O35*1 -> 9600 | K25: 10000 | L25: =J25-K25 -> -400
H26: 15 | I26: nouvelle vendeuse | J26: =Pointage!P35*1 -> 5500 | K26: 5500 | L26: =J26-K26 -> 0
H27: 16 | I27: kenza | J27: =Pointage!K35*1 -> 14500 | K27: 14500
H28: 17 | I28: Yasmine | J28: =Pointage!Q35*1 -> 17750 | K28: 18000 | L28: =J28-K28 -> -250
H29: 18 | I29: Extra | J29: =Pointage!R35*1 -> 6000 | K29: 6000 | L29: =J29-K29 -> 0 | M29: 2000+2000+1000+2000
I30: TOTAL | J30: =SUM(J12:J29) -> 368885.5 | K30: =SUM(K12:K29) -> 372000 | L30: =SUM(L12:L29) -> -3114.5
I31: =J30-K30 -> -3114.5 | L31: =J31-K31 -> 0

Sheet Feuille 5
K13: Mois de Juillet | L13: Mois d'Aout | M13: Mois de Septembre | N13: Mois d'Octobre
J14: Recette | K14: 2230000 | L14: 1332000 | M14: 1657000 | N14: 1921000
J15: Charges | K15: 990000 | L15: 594000 | M15: 702000 | N15: 901000
J16: Salaires | K16: 330000 | L16: 188000 | M16: 305000 | N16: 369000
J17: Loyer | K17: 110000 | L17: 110000 | M17: 110000 | N17: 110000
J18: Profit Net | K18: 800000 | L18: 440000 | M18: 540000 | N18: 540000

Sheet Feuille 6
H9: Date | I9: Farida
G10: Samedi | H10: 44835 | I10: 1
G11: Dimanche | H11: 44836 | I11: 1
G12: Lundi | H12: 44837 | I12: 1.25
G13: Mardi | H13: 44838 | I13: 1
G14: Mercredi | H14: 44839 | I14: 1.5
G15: Jeudi | H15: 44840 | I15: 2
G16: Vendredi | H16: 44841 | I16: 2
G17: Samedi | H17: 44842 | I17: 1
G18: Dimanche | H18: 44843 | I18: 0.5
G19: Lundi | H19: 44844 | I19: 1
G20: Mardi | H20: 44845 | I20: 1
G21: Mercredi | H21: 44846 | I21: 1
... G40: Lundi | H40: 44865 | I40: 1
I41: =SUM(I10:I40) -> 30.25
I42: 1150
I43: =I42*I41 -> 34787.5
