Workbook

Sheet RECAP
B1: Date | C1: Recette d'Aout 2022 | D1: Recette | E1: Charges | F1: Salaire | G1: Loyer | H1: Net Profit | I1: Nb de jours | K1: Objectif | L1: Aout | M1: Bénéfice Moyen par jour | N1: Moyenne
A2: Jeudi | B2: 44805 | C2: 47000 | D2: 0 | I2: 0 | K2: 0 | L2: 47000 | M2: =H32/I32 -> 20004.481 | N2: =D32/I32 -> 61370.37
A3: Vendredi | B3: 44806 | C3: 73000 | D3: 0 | I3: 0 | K3: 0 | L3: 73000
A4: Samedi | B4: 44807 | C4: 52000 | D4: 0 | I4: 0 | K4: 0 | L4: 52000 | M4: Moyenne des charges par jour | N4: Objectif
A5: Dimanche | B5: 44808 | C5: 80000 | D5: 55000 | I5: 1 | K5: 70000 | L5: 80000 | N5: 70000
A6: Lundi | B6: 44809 | C6: 60000 | D6: 80000 | I6: 1 | K6: 70000 | L6: 60000 | M6: ²
A7: Mardi | B7: 44810 | C7: 82000 | D7: 40000 | I7: 1 | K7: 70000 | L7: 82000
A8: Mercredi | B8: 44811 | C8: 70000 | D8: 95000 | I8: 1 | K8: 70000 | L8: 70000 | M8: Cash restant | N8: Magasin | O8: caisse | P8: cash en attente pour le récupérer =Dettes éxterieurs
A9: Jeudi | B9: 44812 | C9: 80000 | D9: 55000 | I9: 1 | K9: 70000 | L9: 80000 | M9: =N11+D32-E32-N9-N12-Salaires!I25 -> 723171 | N9: =P9+O9 -> 507000 | O9: 42000 | P9: 465000
A10: Vendredi | B10: 44813 | C10: 60000 | D10: 55000 | I10: 1 | K10: 70000 | L10: 60000 | P10: Sofiane : 20000Da +10000Da
A11: Samedi | B11: 44814 | C11: 51000 | D11: 100000 | I11: 1 | K11: 70000 | L11: 51000 | M11: loyer | N11: 910000 | P11: CCP: 18000 Da Amel 30000Da
A12: Dimanche | B12: 44815 | C12: 40000 | D12: 23000 | I12: 1 | K12: 70000 | L12: 40000 | M12: pétrin+ four | N12: 270000 | P12: Charges Octobre 447000
A13: Lundi | B13: 44816 | C13: 62000 | D13: 48000 | I13: 1 | K13: 70000 | L13: 62000 | N13: 75000+145000
A14: Mardi | B14: 44817 | C14: 40000 | D14: 26000 | I14: 1 | K14: 70000 | L14: 40000 | M14: Mounir | N14: 50000
A15: Mercredi | B15: 44818 | C15: 85000 | D15: 55000 | I15: 1 | K15: 70000 | L15: 85000
A16: Jeudi | B16: 44819 | C16: 60000 | D16: 60000 | I16: 1 | K16: 70000 | L16: 60000
A17: Vendredi | B17: 44820 | C17: 60000 | D17: 125000 | I17: 1 | K17: 70000 | L17: 60000 | M17: Différence mois de juin
A18: Samedi | B18: 44821 | C18: 60000 | D18: 50000 | I18: 1 | K18: 70000 | L18: 60000 | M18: =D32-C32 -> 325000
A19: Dimanche | B19: 44822 | C19: 90000 | D19: 46000 | I19: 1 | K19: 70000 | L19: 90000 | M19: Différence objectif
A20: Lundi | B20: 44823 | C20: 80000 | D20: 55000 | I20: 1 | K20: 70000 | L20: 80000 | M20: =D32-K32 -> -163000
A21: Mardi | B21: 44824 | C21: 100000 | D21: 90000 | I21: 1 | K21: 70000 | L21: 100000
A22: Mercredi | B22: 44825 | C22: 0 | D22: 45000 | I22: 1 | K22: 70000 | L22: 0
A23: Jeudi | B23: 44826 | C23: 0 | D23: 45000 | I23: 1 | K23: 70000 | L23: 0 | M23: Les vendredis
A24: Vendredi | B24: 44827 | C24: 0 | D24: 47000 | I24: 1 | K24: 70000 | L24: 0 | M24: =D6+D13+D20+D27 -> 226000
A25: Samedi | B25: 44828 | C25: 0 | D25: 37000 | I25: 1 | K25: 70000 | L25: 0
A26: Dimanche | B26: 44829 | C26: 0 | D26: 56000 | I26: 1 | K26: 70000 | L26: 0 | M26: Cash réel
A27: Lundi | B27: 44830 | C27: 0 | D27: 43000 | I27: 1 | K27: 70000 | L27: 0 | M27: 780000
A28: Mardi | B28: 44831 | C28: 0 | D28: 62000 | I28: 1 | K28: 70000 | L28: 0 | M28: rest à payer
A29: Mercredi | B29: 44832 | C29: 0 | D29: 72000 | I29: 1 | K29: 70000 | L29: 0 | M29: =M9-M27 -> -56829
A30: Jeudi | B30: 44833 | C30: 0 | D30: 120000 | I30: 1 | K30: 70000 | L30: 0
A31: Vendredi | B31: 44834 | C31: 0 | D31: 72000 | I31: 1 | L31: 0
C32: =SUM(C2:C31) -> 1332000 | D32: =SUM(D2:D31) -> 1657000 | E32: ='Les chareges '!F346 -> 702079 | F32: =Pointage!P34*1 -> 304800 | G32: 110000 | H32: =D32-G32-F32-E32 -> 540121 | I32: =SUM(I2:I31) -> 27 | K32: =SUM(K2:K31) -> 1820000 | L32: =SUM(L2:L31) -> 1332000
C34: Objectif | D34: 2030000 | E34: 800000 | F34: 380000 | G34: 110000 | H34: =D34-E34-F34-G34 -> 740000
C35: Mois d'Aout | D35: 1332000 | E35: 595000 | F35: 188000 | G35: 110000 | H35: 440000
C38: La différence | D38: =D32-D35 -> 325000 | E38: =E32-E35 -> 107079 | F38: =F32-F35 -> 116800 | G38: =G32-G35 -> 0 | H38: =H32-H35 -> 100121
E40: =E32/D32*100 -> 42.370489 | F40: =F32/D32*100 -> 18.394689 | G40: =G32/D32*100 -> 6.6385033 | H40: =H32/D32*100 -> 32.596319

Sheet Pointage
B1: Date | C1: Nadjet | D1: Hafida | E1: Wahiba | F1: Zahida | G1: djamila | H1: Farida | I1: Yousera | J1: Lynda | K1: Fahima | L1: Fouzia | M1: SAmira | N1: Yasmine | O1: Soumia | P1: Remarque
A2: Jeudi | B2: 44805 | C2: 0 | D2: 0 | E2: 0 | F2: 0 | G2: 0 | H2: 0 | I2: 0 | J2: 0 | K2: 0 | L2: 0 | M2: 0 | N2: 0 | O2: 0
A3: Vendredi | B3: 44806 | C3: 0 | D3: 0 | E3: 0 | F3: 0 | G3: 0 | H3: 0 | I3: 0 | J3: 0 | K3: 0 | L3: 0 | M3: 0 | N3: 0 | O3: 0
A4: Samedi | B4: 44807 | C4: 0 | D4: 1.5 | E4: 1 | F4: 0 | G4: 1.5 | H4: 1.5 | I4: 1 | J4: 1 | K4: 0 | L4: 1 | M4: 0 | N4: 1.5 | O4: 0
A5: Dimanche | B5: 44808 | C5: 0 | D5: 1 | E5: 1 | F5: 0 | G5: 1 | H5: 1 | I5: 1 | J5: 1 | K5: 0 | L5: 1 | M5: 0 | N5: 1 | O5: 0
A6: Lundi | B6: 44809 | C6: 1.25 | D6: 1 | E6: 1 | F6: 0 | G6: 1 | H6: 1.5 | I6: 1 | J6: 1 | K6: 0 | L6: 1 | M6: 0 | N6: 1 | O6: 1 | P6: Soumia djate à 09h et kharedjet à 15h40 me3a les autres
A7: Mardi | B7: 44810 | C7: 1.25 | D7: 1 | E7: 1 | F7: 0 | G7: 1 | H7: 1 | I7: 1 | J7: 1 | K7: 0 | L7: 1 | M7: 0 | N7: 1 | O7: 1 | P7: Yousera et Fouzia djaw en retardx et j'ai autorisé à fouzia tekhredj à 15h
A8: Mercredi | B8: 44811 | C8: 1.25 | D8: 1 | E8: 1 | F8: 0 | G8: 1 | H8: 1 | I8: 1 | J8: 1 | K8: 0 | L8: 1 | M8: 0 | N8: 1 | O8: 1
A9: Jeudi | B9: 44812 | C9: 1.25 | D9: 1 | E9: 1 | F9: 0 | G9: 1 | H9: 1 | I9: 0.5 | J9: 1 | K9: 0 | L9: 0 | M9: 0 | N9: 1 | O9: 0
A10: Vendredi | B10: 44813 | C10: 1.25 | D10: 1 | E10: 0 | F10: 0 | G10: 1 | H10: 1 | I10: 0 | J10: 1 | K10: 0 | L10: 1 | M10: 1 | N10: 1 | O10: 0
A11: Samedi | B11: 44814 | C11: 1.25 | D11: 1 | E11: 1 | F11: 0 | G11: 1 | H11: 1 | I11: 1 | J11: 1 | K11: 0 | L11: 1 | M11: 1 | N11: 0 | O11: 0
A12: Dimanche | B12: 44815 | C12: 0 | D12: 1 | E12: 1 | F12: 1 | G12: 0 | H12: 1 | I12: 1 | J12: 1 | K12: 0 | L12: 0 | M12: 1 | N12: 1 | O12: 1
A13: Lundi | B13: 44816 | C13: 0 | D13: 1 | E13: 1 | F13: 1 | G13: 1 | H13: 1 | I13: 0 | J13: 1 | K13: 0 | L13: 0 | M13: 1 | N13: 1 | O13: 1
A14: Mardi | B14: 44817 | C14: 0 | D14: 1 | E14: 1 | F14: 1 | G14: 1 | H14: 1 | I14: 0 | J14: 1 | K14: 0 | L14: 1 | M14: 1 | N14: 0.5 | O14: 1 | P14: Soumia retard 09h05
A15: Mercredi | B15: 44818 | C15: 0 | D15: 1 | E15: 1 | F15: 1 | G15: 1 | H15: 1 | I15: 0 | J15: 1 | K15: 0 | L15: 0 | M15: 1 | N15: 1 | O15: 1 | P15: Soumia reyard 09h
A16: Jeudi | B16: 44819 | C16: 1 | D16: 1.5 | E16: 1 | F16: 0.5 | G16: 0 | H16: 1.5 | I16: 0 | J16: 1.5 | K16: 0 | L16: 1 | M16: 1 | N16: 1 | O16: 1 | P16: soumia retard 09h05 et Fouzia retard 09h
A17: Vendredi | B17: 44820 | C17: 0 | D17: 0 | E17: 0 | F17: 1 | G17: 1 | H17: 1 | I17: 0 | J17: 1.5 | K17: 0 | L17: 1 | M17: 0 | N17: 1 | O17: 0.5
A18: Samedi | B18: 44821 | C18: 0 | D18: 1 | E18: 1 | F18: 0.5 | G18: 1 | H18: 1 | I18: 0 | J18: 1 | K18: 0 | L18: 1 | M18: 1 | N18: 1 | O18: 1
A19: Dimanche | B19: 44822 | C19: 0 | D19: 1 | E19: 1 | F19: 1 | G19: 1 | H19: 1 | I19: 1 | J19: 1 | K19: 0 | L19: 1 | M19: 1 | N19: 0.5 | O19: 1
A20: Lundi | B20: 44823 | C20: 0 | D20: 1 | E20: 1 | F20: 1 | G20: 1 | H20: 0 | I20: 1 | J20: 1 | K20: 0 | L20: 0.5 | M20: 1 | N20: 0.5 | O20: 1
A21: Mardi | B21: 44824 | C21: 0 | D21: 1 | E21: 1 | F21: 1 | G21: 1 | H21: 1 | I21: 1 | J21: 1 | K21: 0 | L21: 0 | M21: 0 | N21: 1 | O21: 1
A22: Mercredi | B22: 44825 | C22: 0 | D22: 1 | E22: 1 | F22: 1 | G22: 1 | H22: 0 | I22: 1 | J22: 1 | K22: 0 | L22: 1 | M22: 1 | N22: 1 | O22: 1
A23: Jeudi | B23: 44826 | C23: 0 | D23: 1 | E23: 1 | F23: 1 | G23: 1 | H23: 1 | I23: 1 | J23: 1 | K23: 0 | L23: 1 | M23: 1 | N23: 0.5 | O23: 1
A24: Vendredi | B24: 44827 | C24: 0 | D24: 0 | E24: 0 | F24: 1.5 | G24: 2 | H24: 2 | I24: 0 | J24: 2 | K24: 0 | L24: 0 | M24: 1 | N24: 2 | O24: 0
A25: Samedi | B25: 44828 | C25: 0 | D25: 1 | E25: 1.5 | F25: 1 | G25: 1 | H25: 1 | I25: 1 | J25: 1 | K25: 0 | L25: 1 | M25: 1 | N25: 0 | O25: 0
A26: Dimanche | B26: 44829 | C26: 0 | D26: 1 | E26: 1 | F26: 0 | G26: 1 | H26: 1 | I26: 1 | J26: 1 | K26: 0 | L26: 0 | M26: 1 | N26: 0.5 | O26: 1
A27: Lundi | B27: 44830 | C27: 0 | D27: 1 | E27: 1 | F27: 1 | G27: 1 | H27: 1 | I27: 1 | J27: 1 | K27: 0 | L27: 1 | M27: 1 | N27: 1 | O27: 1
A28: Mardi | B28: 44831 | C28: 0 | D28: 1 | E28: 1 | F28: 1 | G28: 1 | H28: 1 | I28: 1 | J28: 1 | K28: 0 | L28: 1 | M28: 0 | N28: 1 | O28: 1
... A31: Vendredi | B31: 44834 | C31: 0 | D31: 0 | E31: 1 | F31: 1 | G31: 1 | H31: 1 | I31: 0 | J31: 1 | K31: 0 | L31: 1 | M31: 1 | N31: 1 | O31: 0
C32: =SUM(C2:C31) -> 8.5 | D32: =SUM(D2:D31) -> 26 | E32: =SUM(E2:E31) -> 26.5 | F32: =SUM(F2:F31) -> 18.5 | G32: =SUM(G2:G31) -> 25.5 | H32: =SUM(H2:H31) -> 29.5 | I32: =SUM(I2:I31) -> 18.5 | J32: =SUM(J2:J31) -> 30 | ... O32: =SUM(O2:O31) -> 19.5
C33: 1200 | D33: 1200 | E33: 1200 | F33: 1200 | G33: 1100 | H33: 1200 | I33: 1100 | J33: 1200 | K33: 1000 | L33: 1200 | M33: 900 | N33: 1000 | O33: 1200
C34: =C33*C32 -> 10200 | D34: =D33*D32 -> 31200 | E34: =E33*E32 -> 31800 | F34: =F33*F32 -> 22200 | G34: =G33*G32 -> 28050 | H34: =H33*H32 -> 35400 | I34: =I33*I32 -> 20350 | J34: =J33*J32 -> 36000 | ... O34: =O33*O32 -> 23400 | P34: =SUM(C34:O34) -> 304800

Sheet Les chareges 
C2: Produit | D2: Quantité | E2: Prix unitaire | F2: Prix | G2: Date d'achat
C3: ka3ek Nakach | D3: 400 | E3: 50 | F3: =E3*D3 -> 20000 | G3: 44816
C4: Bessel | D4: 130 | E4: 60 | F4: =E4*D4 -> 7800 | G4: 44812
C5: bessel | D5: 42 | E5: 60 | F5: =E5*D5 -> 2520 | G5: 44810
C6: caissettes N12 | D6: 40 | E6: 30 | F6: =E6*D6 -> 1200 | G6: 44809
C7: Caissettes N10 | D7: 40 | E7: 25 | F7: =E7*D7 -> 1000 | G7: 44809
C8: rehta | D8: 30 | E8: 120 | F8: =E8*D8 -> 3600 | G8: 44814
C9: Gherss | D9: 29 | E9: 140 | F9: =E9*D9 -> 4060 | G9: 44811
C10: semoule Sahel 25kg | D10: 24 | E10: 1200 | F10: =E10*D10 -> 28800 | G10: 44805
C11: Harrissa | D11: 24 | E11: 200 | F11: =E11*D11 -> 4800 | G11: 44808
C12: Huile 2 litres | D12: 20 | E12: 1416 | F12: =E12*D12 -> 28320 | G12: 44805
C13: Eau Lala khedidja 0,5 litres | D13: 20 | E13: 200 | F13: =E13*D13 -> 4000 | G13: 44805
C14: rechta | D14: 20 | E14: 120 | F14: =E14*D14 -> 2400 | G14: 44812
... C20: bessel | D20: 16 | E20: 60 | F20: =E20*D20 -> 960 | G20: 44808
C21: Semoule Fine sahel10kg | D21: 15 | E21: 650 | F21: =E21*D21 -> 9750 | G21: 01/09/2022/
C22: bessel | D22: 15 | E22: 60 | F22: =E22*D22 -> 900 | G22: 44811
C23: Maizina | D23: 15 | F23: =E23*D23 -> 0 | G23: 44805
C24: Levure bolangère | D24: 14 | E24: 365 | F24: =E24*D24 -> 5110 | G24: 44805
C25: Tomate conserve | D25: 12 | E25: 210 | F25: =E25*D25 -> 2520 | G25: 44808
C26: Eau Lala khedidja 1,5 litres | D26: 12 | E26: 190 | F26: =E26*D26 -> 2280 | G26: 44805
C27: Maa Zehar | D27: 12 | E27: 62 | F27: =E27*D27 -> 744 | G27: 44807
C28: amandes | D28: 10 | E28: 1630 | F28: =E28*D28 -> 16300 | G28: 44807
C29: miel | D29: 10 | E29: 770 | F29: =E29*D29 -> 7700 | G29: 44805
C30: Mais | D30: 10 | E30: 350 | F30: =E30*D30 -> 3500 | G30: 44805
C31: Tomate conserve | D31: 10 | E31: 210 | F31: =E31*D31 -> 2100 | G31: 44805
C32: vinaigre | D32: 10 | E32: 70 | F32: =E32*D32 -> 700 | G32: 44805
C33: Farine Sim 1kg | D33: 10 | E33: 70 | F33: =E33*D33 -> 700 | G33: 44805
C34: bessel | D34: 10 | E34: 60 | F34: =E34*D34 -> 600 | G34: 44807
C35: les quissetes | D35: 10 | E35: 40 | F35: =E35*D35 -> 400 | G35: 44805
... C115: Margarine Fleurial 250g 40 boites | D115: 1 | E115: 3440 | F115: =E115*D115 -> 3440 | G115: 44805
C116: avocat | D116: 1 | E116: 3200 | F116: 3200 | G116: 44814
C117: Sucre cristaliser 25kg | D117: 1 | E117: 2200 | F117: =E117*D117 -> 2200 | G117: 44805
C118: Vanille Baraka | D118: 1 | E118: 2200 | F118: =E118*D118 -> 2200 | G118: 44805
C119: réparation des cocottes | D119: 1 | E119: 2000 | F119: =E119*D119 -> 2000 | G119: 44805
C120: détergents | D120: 1 | E120: 2000 | F120: =E120*D120 -> 2000 | G120: 44807
C121: Papier aluminium | D121: 1 | E121: 1930 | F121: =E121*D121 -> 1930 | G121: 44805
C122: canette coca | D122: 1 | E122: 1800 | F122: =E122*D122 -> 1800 | G122: 44805
C123: Boites en carton 48/07 | D123: 1 | E123: 1800 | F123: =E123*D123 -> 1800 | G123: 44805
C124: sachets de congelation | D124: 1 | E124: 1800 | F124: =E124*D124 -> 1800 | G124: 44811
C125: sumon | D125: 1 | E125: 1800 | F125: =E125*D125 -> 1800 | G125: 44814
...

Sheet Salaires
G10: Nom | H10: Salaire | I10: Avance | J10: Salaire à payer
F11: 1 | G11: Sofiane | H11: 30000 | I11: 30000 | J11: 0
F12: 2 | G12: Amel | H12: 30000 | I12: 30000 | J12: 0
F13: 3 | G13: Nadjet | H13: =Pointage!C34*1 -> 10200 | I13: 10200 | J13: =H13-I13 -> 0 | K13: 1500+1500+1500+1500+3000
F14: 4 | G14: Hafida | H14: =Pointage!D34*1 -> 31200 | I14: 31200 | J14: =H14-I14 -> 0
F15: 5 | G15: Wahiba | H15: =Pointage!E34*1 -> 31800 | I15: 31800 | J15: =H15-I15 -> 0
F16: 6 | G16: Zahida | H16: =Pointage!F34*1 -> 22200 | I16: 22200 | J16: =H16-I16 -> 0
F17: 7 | G17: Djamila | H17: =Pointage!G34*1 -> 28050 | I17: 28000 | J17: =H17-I17 -> 50
F18: 8 | G18: Farida | H18: =Pointage!H34*1 -> 35400 | I18: 35400 | J18: =H18-I18 -> 0
F19: 9 | G19: Yousera | H19: =Pointage!I34*1 -> 20350 | I19: 20350 | J19: =H19-I19 -> 0 | K19: 8000+2500+2000
F20: 10 | G20: lynda | H20: =Pointage!J34*1 -> 36000 | I20: 36000 | J20: =H20-I20 -> 0
F21: 11 | G21: Samira | H21: =Pointage!M34*1 -> 17100 | I21: 17100 | J21: =H21-I21 -> 0 | K21: 1000
F22: 12 | G22: Fouzia | H22: =Pointage!L34*1 -> 24600 | I22: 24600 | J22: =H22-I22 -> 0
F23: 13 | G23: Yasmine | H23: =Pointage!N34*1 -> 24500 | I23: 24500 | J23: =H23-I23 -> 0
F24: 14 | G24: Soumia | H24: =Pointage!O34*1 -> 23400 | I24: 23400 | J24: =H24-I24 -> 0 | K24: 1000+1000
G25: TOTAL | H25: =SUM(H13:H24) -> 304800 | I25: =SUM(I11:I24) -> 364750 | J25: =SUM(J13:J24) -> 50
G26: =H25-I25 -> -59950 | J26: =H26-I26 -> 0

Sheet Feuille 6
I14: Mois de Juillet | J14: Mois d'Aout | K14: Mois de Septembre
H15: Recette | I15: 2230000 | J15: 1332000 | K15: 1657000
H16: Charges | I16: 990000 | J16: 594000 | K16: 702000
H17: Salaires | I17: 330000 | J17: 188000 | K17: 305000
H18: Loyer | I18: 110000 | J18: 110000 | K18: 110000
H19: Profit Net | I19: 800000 | J19: 440000 | K19: 540000
G24: Mois | H24: CA | I24: Charge % | J24: Salaire % | K24: Loyer % | L24: Bénef %
G25: SEP | H25: 1 657 000 | I25: 42.37 | J25: 18.39 | K25: 6.64 | L25: 32.6
G26: OCT | H26: 1 921 000 | I26: 46.9 | J26: 19.21 | K26: 5.73 | L26: 28.11
G27: NOV | H27: 1 706 000 | I27: 42.03 | J27: 19.82 | K27: 6.45 | L27: 31.69
G29: OBJ | H29: 2 030 000 | I29: 34.48 | J29: 15.27 | K29: 5.42 | L29: 44.83
