Workbook

Sheet RECAP
B2: Date | C2: Recette de Juillet 2022 | D2: Recette | E2: Charges | F2: Salaire | G2: Loyer | H2: Net Profit | I2: Nb de jours | K2: Objectif | L2: Juillet | M2: Bénéfice Moyen par jour | N2: Moyenne
A3: Lundi | B3: 44774 | C3: 32000 | D3: 47000 | I3: 1 | K3: 70000 | L3: 32000 | M3: =H34/I34 -> 22003.9 | N3: =D34/I34 -> 66600
A4: Mardi | B4: 44775 | C4: 44000 | D4: 73000 | I4: 1 | K4: 70000 | L4: 44000
A5: Mercredi | B5: 44776 | C5: 110000 | D5: 52000 | I5: 1 | K5: 70000 | L5: 110000 | M5: Moyenne des charges par jour | N5: Objectif
A6: Jeudi | B6: 44777 | C6: 114000 | D6: 80000 | I6: 1 | K6: 70000 | L6: 114000 | N6: 70000
A7: Vendredi | B7: 44778 | C7: 120000 | D7: 60000 | I7: 1 | K7: 70000 | L7: 120000 | M7: ²
A8: Samedi | B8: 44779 | C8: 100000 | D8: 82000 | I8: 1 | K8: 70000 | L8: 100000
A9: Dimanche | B9: 44780 | C9: 200000 | D9: 70000 | I9: 1 | K9: 70000 | L9: 200000 | M9: Cash restant | N9: Magasin | O9: caisse | P9: cash en attente pour le récupérer =Dettes éxterieurs
A10: Lundi | B10: 44781 | C10: 96000 | D10: 80000 | I10: 1 | K10: 70000 | L10: 96000 | M10: =D34+N12-N10-N13-E34-Salaires!H24 -> 1080090 | N10: =O10+P10 -> 0 | O10: 0
A11: Mardi | B11: 44782 | C11: 0 | D11: 60000 | I11: 1 | K11: 70000 | L11: 0
A12: Mercredi | B12: 44783 | C12: 0 | D12: 51000 | I12: 1 | K12: 70000 | L12: 0 | M12: loyer | N12: 800000
A13: Jeudi | B13: 44784 | C13: 54000 | D13: 40000 | I13: 1 | K13: 70000 | L13: 54000 | M13: pétrin+ four | N13: 270000
A14: Vendredi | B14: 44785 | C14: 65000 | D14: 62000 | I14: 1 | K14: 70000 | L14: 65000 | N14: 75000+145000
A15: Samedi | B15: 44786 | C15: 70000 | D15: 40000 | I15: 1 | K15: 70000 | L15: 70000 | M15: Mounir | N15: 50000
A16: Dimanche | B16: 44787 | C16: 124000 | D16: 85000 | I16: 1 | K16: 70000 | L16: 124000
A17: Lundi | B17: 44788 | C17: 42000 | D17: 60000 | I17: 1 | K17: 70000 | L17: 42000
A18: Mardi | B18: 44789 | C18: 45000 | D18: 60000 | I18: 1 | K18: 70000 | L18: 45000 | M18: Différence mois de juin
A19: Mercredi | B19: 44790 | C19: 44000 | D19: 60000 | I19: 1 | K19: 70000 | L19: 44000 | M19: =D34-C34 -> -898000
A20: Jeudi | B20: 44791 | C20: 41000 | D20: 90000 | I20: 1 | K20: 70000 | L20: 41000 | M20: Différence objectif
A21: Vendredi | B21: 44792 | C21: 94000 | D21: 80000 | I21: 1 | K21: 70000 | L21: 94000 | M21: =D34-K34 -> -68000
A22: Samedi | B22: 44793 | C22: 92000 | D22: 100000 | I22: 1 | K22: 70000 | L22: 92000
A23: Dimanche | B23: 44794 | C23: 70000 | D23: 0 | K23: 0 | L23: 70000
A24: Lundi | B24: 44795 | C24: 40000 | D24: 0 | K24: 0 | L24: 40000 | M24: Les vendredis
A25: Mardi | B25: 44796 | C25: 60000 | D25: 0 | K25: 0 | L25: 60000 | M25: =D7+D14+D21+D28 -> 202000
A26: Mercredi | B26: 44797 | C26: 66000 | D26: 0 | K26: 0 | L26: 66000
A27: Jeudi | B27: 44798 | C27: 80000 | D27: 0 | K27: 0 | L27: 80000 | M27: Cash réel
A28: Vendredi | B28: 44799 | C28: 60000 | D28: 0 | K28: 0 | L28: 60000 | M28: 720000
A29: Samedi | B29: 44800 | C29: 64000 | D29: 0 | K29: 0 | L29: 64000 | M29: rest à payer
A30: Dimanche | B30: 44801 | C30: 83000 | D30: 0 | K30: 0 | L30: 83000 | M30: =M10-M28 -> 360090
A31: Lundi | B31: 44802 | C31: 60000 | D31: 0 | K31: 0 | L31: 60000
A32: Mardi | B32: 44803 | C32: 100000 | D32: 0 | K32: 0 | L32: 100000
A33: Mercredi | B33: 44804 | C33: 60000 | D33: 0 | K33: 0 | L33: 60000
C34: =SUM(C3:C33) -> 2230000 | D34: =SUM(D3:D33) -> 1332000 | E34: ='Les charges '!F359*1 -> 594310 | F34: ='Pointage '!O35*1 -> 187612 | G34: 110000 | H34: =D34-G34-F34-E34 -> 440078 | I34: =SUM(I3:I33) -> 20 | K34: =SUM(K3:K33) -> 1400000
L35: =SUM(L3:L34) -> 2230000
C36: Objectif | D36: 2030000 | E36: 800000 | F36: 380000 | G36: 110000 | H36: =D36-E36-F36-G36 -> 740000
C37: Mois de Juillet | D37: 2230000 | E37: 990000 | F37: 330000 | G37: 110000 | H37: 800000
C40: La différence | D40: =D34-D37 -> -898000 | E40: =E34-E37 -> -395690 | F40: =F34-F37 -> -142388 | G40: =G34-G37 -> 0 | H40: =H34-H37 -> -359922

Sheet Pointage 
B1: Date | C1: Nadjet | D1: Hafida | E1: Wahiba | F1: Zahida | G1: djamila | H1: Farida | I1: Yousera | J1: Lynda | K1: Fahima | L1: Fouzia | M1: Yasmine | N1: Soumia | O1: Remarque
A2: Lundi | B2: 44774 | C2: 1 | D2: 1 | E2: 1 | F2: 13.5 | G2: 1 | H2: 1 | I2: 1 | J2: 1 | K2: 1 | L2: 0 | M2: 1 | N2: 1 | O2: Yousera et soumeya djaw à 09h et youssera ra7et à 16h sans autorisation
A3: Mardi | B3: 44775 | C3: 1 | D3: 1 | E3: 1 | F3: 0 | G3: 1 | H3: 0 | I3: 1 | J3: 1 | K3: 1 | L3: 0.5 | M3: 1 | N3: 0
A4: Mercredi | B4: 44776 | C4: 1 | D4: 1 | E4: 1 | F4: 0 | G4: 1 | H4: 0 | I4: 1 | J4: 1 | K4: 0 | L4: 1 | M4: 1 | N4: 1 | O4: il y'avait pas de gaz donc elles sont sortis tot et on a reporté les commandes
A5: Jeudi | B5: 44777 | C5: 0 | D5: 1 | E5: 1 | F5: 0 | G5: 1 | H5: 0 | I5: 1 | J5: 1 | K5: 0 | L5: 1 | M5: 1 | N5: 1
A6: Vendredi | B6: 44778 | C6: 2 | D6: 1 | E6: 0 | F6: 0 | G6: 1 | H6: 0 | I6: 1 | J6: 1 | K6: 0 | L6: 0 | M6: 1 | N6: 1
A7: Samedi | B7: 44779 | C7: 2 | D7: 1 | E7: 1 | F7: 0 | G7: 1 | H7: 0 | I7: 0.5 | J7: 2 | K7: 0 | L7: 0 | M7: 1 | N7: 0.5
A8: Dimanche | B8: 44780 | C8: 1 | D8: 1 | E8: 2 | F8: 0 | G8: 0 | H8: 1 | I8: 1 | J8: 2 | K8: 0 | L8: 0 | M8: 1 | N8: 1
A9: Lundi | B9: 44781 | C9: 1 | D9: 1 | E9: 1 | F9: 0 | G9: 0 | H9: 1 | I9: 1 | J9: 1 | K9: 1 | L9: 0 | M9: 1 | N9: 0
A10: Mardi | B10: 44782 | C10: 0 | D10: 1 | E10: 1 | F10: 0 | G10: 0 | H10: 1 | I10: 1 | J10: 1 | K10: 1 | L10: 0 | M10: 0 | N10: 0
A11: Mercredi | B11: 44783 | C11: 0 | D11: 1 | E11: 1 | F11: 0 | G11: 1 | H11: 1 | I11: 0.5 | J11: 1 | K11: 1 | L11: 0 | M11: 0.5 | N11: 0
A12: Jeudi | B12: 44784 | C12: 0 | D12: 1 | E12: 1 | F12: 0 | G12: 1 | H12: 1 | I12: 0 | J12: 1 | K12: 1 | L12: 0 | M12: 0.5 | N12: 0
A13: Vendredi | B13: 44785 | C13: 0 | D13: 1 | E13: 1 | F13: 0 | G13: 1 | H13: 1 | I13: 0 | J13: 1 | K13: 0 | L13: 0 | M13: 1 | N13: 0
A14: Samedi | B14: 44786 | C14: 0 | D14: 1 | E14: 1 | F14: 0 | G14: 1 | H14: 1 | I14: 0 | J14: 1 | K14: 1 | L14: 0 | M14: 1 | N14: 0
A15: Dimanche | B15: 44787 | C15: 0 | D15: 1 | E15: 1 | F15: 0 | G15: 1 | H15: 1 | I15: 0 | J15: 1 | K15: 1 | L15: 0 | M15: 1 | N15: 0
A16: Lundi | B16: 44788 | C16: 0 | D16: 1 | E16: 1 | F16: 0 | G16: 1 | H16: 1 | I16: 0 | J16: 1 | K16: 1 | L16: 1 | M16: 1 | N16: 0
A17: Mardi | B17: 44789 | C17: 1 | D17: 1 | E17: 1 | F17: 0 | G17: 1 | H17: 1 | I17: 1 | J17: 1 | K17: 1 | L17: 1 | M17: 1 | N17: 0 | O17: les emplotées du local ont sorti à 15h30 puisque il y'avait pas de travail
A18: Mercredi | B18: 44790 | C18: 0 | D18: 1 | E18: 1 | F18: 0 | G18: 1 | H18: 1 | I18: 0 | J18: 1 | K18: 1 | L18: 1 | M18: 1 | N18: 0
A19: Jeudi | B19: 44791 | C19: 0 | D19: 1 | E19: 1 | F19: 0 | G19: 1 | H19: 1 | I19: 1 | J19: 1 | K19: 1 | L19: 1 | M19: 1 | N19: 0
A20: Vendredi | B20: 44792 | C20: 0 | D20: 1 | E20: 1 | F20: 0 | G20: 1 | H20: 1 | I20: 0 | J20: 1 | K20: 1 | L20: 0 | M20: 1 | N20: 0
A21: Samedi | B21: 44793 | C21: 0 | D21: 1 | E21: 1 | F21: 0 | G21: 1 | H21: 1 | I21: 1 | J21: 1 | K21: 1 | L21: 1 | M21: 1 | N21: 0
A22: Dimanche | B22: 44794 | C22: 0 | D22: 0 | E22: 0 | F22: 0 | G22: 0 | H22: 0 | I22: 0 | J22: 0 | K22: 0 | L22: 0 | M22: 0 | N22: 0
A23: Lundi | B23: 44795 | C23: 0 | D23: 0 | E23: 0 | F23: 0 | G23: 0 | H23: 0 | I23: 0 | J23: 0 | K23: 0 | L23: 0 | M23: 0 | N23: 0
A24: Mardi | B24: 44796 | C24: 0 | D24: 0 | E24: 0 | F24: 0 | G24: 0 | H24: 0 | I24: 0 | J24: 0 | K24: 0 | L24: 0 | M24: 0 | N24: 0
A25: Mercredi | B25: 44797 | C25: 0 | D25: 0 | E25: 0 | F25: 0 | G25: 0 | H25: 0 | I25: 0 | J25: 0 | K25: 0 | L25: 0 | M25: 0 | N25: 0
A26: Jeudi | B26: 44798 | C26: 0 | D26: 0 | E26: 0 | F26: 0 | G26: 0 | H26: 0 | I26: 0 | J26: 0 | K26: 0 | L26: 0 | M26: 0 | N26: 0
A27: Vendredi | B27: 44799 | C27: 0 | D27: 0 | E27: 0 | F27: 0 | G27: 0 | H27: 0 | I27: 0 | J27: 0 | K27: 0 | L27: 0 | M27: 0 | N27: 0
A28: Samedi | B28: 44800 | C28: 0 | D28: 0 | E28: 0 | F28: 0 | G28: 0 | H28: 0 | I28: 0 | J28: 0 | K28: 0 | L28: 0 | M28: 0 | N28: 0
A29: Dimanche | B29: 44801 | C29: 0 | D29: 0 | E29: 0 | F29: 0 | G29: 0 | H29: 0 | I29: 0 | J29: 0 | K29: 0 | L29: 0 | M29: 0 | N29: 0
... A32: Mercredi | B32: 44804 | C32: 0 | D32: 0 | E32: 0 | F32: 0 | G32: 0 | H32: 0 | I32: 0 | J32: 0 | K32: 0 | L32: 0 | M32: 0 | N32: 0
C33: =SUM(C2:C32) -> 10 | D33: =SUM(D2:D32) -> 20 | E33: =SUM(E2:E32) -> 20 | F33: =SUM(F2:F32) -> 13.5 | G33: =SUM(G2:G32) -> 17 | H33: =SUM(H2:H32) -> 15 | I33: =SUM(I2:I32) -> 12 | J33: =SUM(J2:J32) -> 22 | ... N33: =SUM(N2:N32) -> 5.5
C34: 1200 | D34: 1200 | E34: 1000 | F34: 1112 | G34: 1000 | H34: 1200 | I34: 1000 | J34: 1000 | K34: 1000 | L34: 1200 | M34: 1000 | N34: 1200
C35: =C34*C33 -> 12000 | D35: =D34*D33 -> 24000 | E35: =E34*E33 -> 20000 | F35: =F34*F33 -> 15012 | G35: =G34*G33 -> 17000 | H35: =H34*H33 -> 18000 | I35: =I34*I33 -> 12000 | J35: =J34*J33 -> 22000 | ... N35: =N34*N33 -> 6600 | O35: =SUM(C35:N35) -> 187612

Sheet Les charges 
C2: Produit | D2: Quantité | E2: Prix unitaire | F2: Prix | G2: Date d'achat
C3: cuisses de poulet | D3: 45 | E3: 140 | F3: =E3*D3 -> 6300 | G3: 44774
C4: Amandes | D4: 10 | E4: 1830 | F4: =E4*D4 -> 18300 | G4: 44774
C5: plateaux traditionels | D5: 4 | E5: 250 | F5: =E5*D5 -> 1000 | G5: 44774
C6: Boites rondes | D6: 4 | E6: 250 | F6: =E6*D6 -> 1000 | G6: 44774
C7: les barquetts 1185 | D7: 10 | E7: 35 | F7: =E7*D7 -> 350 | G7: 44774
C8: hallal | D8: 2 | E8: 300 | F8: =E8*D8 -> 600 | G8: 44774
C9: fardeaux de 12 | D9: 6 | E9: 505 | F9: =E9*D9 -> 3030 | G9: 44774
C10: Coca canette petites | D10: 1 | E10: 1400 | F10: =E10*D10 -> 1400 | G10: 44774
C11: Coca canette grande | D11: 1 | E11: 1800 | F11: =E11*D11 -> 1800 | G11: 44774
C12: Shweps grenadine | D12: 1 | E12: 1750 | F12: =E12*D12 -> 1750 | G12: 44774
C13: Rouiba boite | D13: 1 | E13: 590 | F13: =E13*D13 -> 590 | G13: 44774
C14: Candia choco | D14: 1 | E14: 880 | F14: =E14*D14 -> 880 | G14: 44774
... C18: semoule fine Sa7el 10kg | D18: 45 | E18: 650 | F18: =E18*D18 -> 29250 | G18: 44672
C19: gherss | D19: 20 | E19: 150 | F19: =D19*E19 -> 3000 | G19: 44636
C20: eau miniral 1.5 litres | D20: 26 | E20: 190 | F20: =D20*E20 -> 4940 | G20: 44735
C21: eau miniral 0.5 litres | D21: 20 | E21: 200 | F21: =D21*E21 -> 4000 | G21: 44735
C22: sucre cristaliser 25kg | D22: 2 | E22: 2200 | F22: 4400 | G22: 44735
C23: noix | D23: 2 | E23: 1380 | F23: =E23*D23 -> 2760 | G23: 44641
C24: semoule blé complet | D24: 25 kg | E24: 175 | F24: 5000 | G24: 44648
C25: margarine fleurial 500g barquette | D25: 9 | E25: 3112 | F25: =E25*D25 -> 28008 | G25: 44700
C26: margarine fleurial 250g | D26: 14 | E26: 3440 | F26: =E26*D26 -> 48160 | G26: 44700
C27: Semen Madina 1,8kg | D27: 18 | E27: 2988 | F27: =E27*D27 -> 53784 | G27: 44700
C28: semoule sahel 25kg | D28: 10 | E28: 1100 | F28: =E28*D28 -> 11000 | G28: 44746
C29: Semoule Fine Sahel 25kg | D29: 27 | E29: 1150 | F29: =E29*D29 -> 31050 | G29: 44761
C30: huile 5 loitrs 36 | D30: 36 | E30: 600 | F30: =E30*D30 -> 21600 | G30: 44768
C31: fourchettes | D31: 10 | E31: 100 | F31: =E31*D31 -> 1000
C32: Eau de fleur | D32: 5 | E32: 630 | F32: =E32*D32 -> 3150
C33: sucre glace Fabbalco | D33: 32 | E33: 100 | F33: =E33*D33 -> 3200
C34: Farine | D34: 10 | E34: 200 | F34: =E34*D34 -> 2000
C35: décapant | D35: 5 | E35: 100 | F35: =E35*D35 -> 500 | G35: 44766
C36: hamissa | D36: 2 | E36: 200 | F36: =E36*D36 -> 400 | G36: 44766
C37: 7abet halawa | D37: 1 | E37: 800 | F37: =E37*D37 -> 800 | G37: 44763
C38: Livreur semoule | D38: 1 | E38: 1500 | F38: =E38*D38 -> 1500 | G38: 44761
C39: Maiis princesse 850g | D39: 24 | E39: 325 | F39: =E39*D39 -> 7800 | G39: 44760
C40: Fromage speciale pizza | D40: 10 | E40: 315 | F40: =E40*D40 -> 3150 | G40: 44760
C41: cheddar | D41: 2 | E41: 2200 | F41: =E41*D41 -> 4400 | G41: 44760
C42: Thon le Gout | D42: 1 | E42: 2000 | F42: 2000 | G42: 44760
C43: Thon le Gout | D43: 5 | E43: 1880 | F43: =E43*D43 -> 9400 | G43: 44760
C44: Fromage Bidon 3.8kg | D44: 3 | E44: 1300 | F44: =E44*D44 -> 3900 | G44: 44760
...

Sheet Salaires
F11: Nom | G11: Salaire | H11: Avance | I11: Salaire à payer
E12: 1 | F12: Nadjet | G12: ='Pointage '!C35*1 -> 12000 | H12: 12000 | I12: =G12-H12 -> 0
E13: 2 | F13: Hafida | G13: ='Pointage '!D35*1 -> 24000 | H13: 24000 | I13: =G13-H13 -> 0
E14: 3 | F14: Wahiba | G14: ='Pointage '!E35*1 -> 20000 | H14: 20000 | I14: =G14-H14 -> 0
E15: 4 | F15: Zahida | G15: ='Pointage '!F35*1 -> 15012 | H15: 15000 | I15: =G15-H15 -> 12
E16: 5 | F16: Djamila | G16: ='Pointage '!G35*1 -> 17000 | H16: 17000 | I16: =G16-H16 -> 0
E17: 6 | F17: Farida | G17: ='Pointage '!H35*1 -> 18000 | H17: 18000 | I17: =G17-H17 -> 0 | J17: 1000+17000
E18: 7 | F18: Yousera | G18: ='Pointage '!I35*1 -> 12000 | H18: 12000 | I18: =G18-H18 -> 0 | J18: 4500+7500
E19: 8 | F19: lynda | G19: ='Pointage '!J35*1 -> 22000 | H19: 22000 | I19: =G19-H19 -> 0
E20: 9 | F20: Rachida /Fahima | G20: ='Pointage '!K35*1 -> 14000 | H20: 14000 | I20: =G20-H20 -> 0 | J20: 1850
E21: 10 | F21: Fouzia | G21: ='Pointage '!L35*1 -> 9000 | H21: 9000 | I21: =G21-H21 -> 0
E22: 11 | F22: Yasmine | G22: ='Pointage '!M35*1 -> 18000 | H22: 18000 | I22: =G22-H22 -> 0
E23: 12 | F23: Soumia | G23: ='Pointage '!N35*1 -> 6600 | H23: 6600 | I23: =G23-H23 -> 0 | J23: 1000+5000
F24: TOTAL | G24: =SUM(G12:G23) -> 187612 | H24: =SUM(H12:H23) -> 187600 | I24: =SUM(I12:I23) -> 12
F25: =G24-H24 -> 12 | I25: =G25-H25 -> 0

Sheet Feuille 5
I14: Mois de Juillet | J14: Mois d'Aout
H15: Recette | I15: 2230000 | J15: 1332000
H16: Charges | I16: 990000 | J16: 594000
H17: Salaires | I17: 330000 | J17: 188000
H18: Loyer | I18: 110000 | J18: 110000
H19: Profit Net | I19: 800000 | J19: 440000

Sheet Feuille 6
H10: Mois de Juin | I10: Mois de Juillet | J10: Mois d'Aout
G11: Recette | H11: 1410000 | I11: 2230000 | J11: 1332000
G12: Charges | H12: 717000 | I12: 990000 | J12: 594000
G13: Salaires | H13: 321000 | I13: 330000 | J13: 188000
G14: Loyer | H14: 110000 | I14: 110000 | J14: 110000
G15: Profit Net | H15: 260000 | I15: 800000 | J15: 440000
