Workbook

Sheet RECAP
B1: Date | C1: Recette Septembre 2025 | D1: Recette | E1: Charges | F1: Salaire | G1: Che7i7a | H1: Loyer | I1: Net Profit | J1: Nb de jours | L1: Objectif | M1: Mois de Septembre 2025
A2: Mercredi | B2: 45931 | C2: 52000 | D2: 30000 | G2: 2000 | J2: 1 | M2: 52000
A3: Jeudi | B3: 45932 | C3: 67000 | D3: 104000 | G3: 2000 | J3: 1 | M3: 67000 | N3: Bénéfice Moyen par jour | O3: Moyenne | P3: Moyenne salaire | Q3: pourcentage du salaire vis à vis la recettte
A4: Vendredi | B4: 45933 | C4: 97000 | D4: 85000 | G4: 2000 | J4: 1 | M4: 97000 | N4: =I33/J33 -> 16462.5 | O4: =D33/J33 -> 61225.806 | Q4: =P4/O4 -> 0
A5: Samedi | B5: 45934 | C5: 187000 | D5: 55000 | G5: 2000 | J5: 1 | M5: 187000
A6: Dimanche | B6: 45935 | C6: 59000 | D6: 38000 | G6: 2000 | J6: 1 | M6: 59000 | N6: Moyenne des charges par jour | O6: Objectif
A7: Lundi | B7: 45936 | C7: 48000 | D7: 40000 | G7: 2000 | J7: 1 | M7: 48000 | N7: =E33/J33 -> 23223.903 | O7: 100000
A8: Mardi | B8: 45937 | C8: 51000 | D8: 55000 | G8: 2000 | J8: 1 | M8: 51000
A9: Mercredi | B9: 45938 | C9: 50000 | D9: 75000 | G9: 2000 | J9: 1 | M9: 50000
A10: Jeudi | B10: 45939 | C10: 54000 | D10: 73000 | G10: 2000 | J10: 1 | M10: 54000 | N10: Cash restant | O10: Magasin | P10: Cash réel | Q10: Mes dettes pour le magasin
A11: Vendredi | B11: 45940 | C11: 47000 | D11: 76000 | G11: 2000 | J11: 1 | M11: 47000 | N11: =N14+D33-E33-'Les Salaires'!K30-O11-G33 -> 268959 | O11: =S14+S15+S16+S17+S18+S20+S21+S19 -> 759100 | P11: 410000 | Q11: =N11-P11 -> -141041
A12: Samedi | B12: 45941 | C12: 90000 | D12: 76000 | G12: 2000 | J12: 1 | M12: 90000
A13: Dimanche | B13: 45942 | C13: 0 | D13: 48000 | G13: 2000 | J13: 1 | M13: 0 | N13: Fond de Roulement
A14: Lundi | B14: 45943 | C14: 53000 | D14: 29000 | G14: 2000 | J14: 1 | M14: 53000 | N14: 330000 | Q14: Dette Chaherazed Bararki | S14: 10100
A15: Mardi | B15: 45944 | C15: 52000 | D15: 33000 | G15: 2000 | J15: 1 | M15: 52000 | Q15: La caisse : | S15: 41000
A16: Mercredi | B16: 45945 | C16: 39000 | D16: 42000 | G16: 2000 | J16: 1 | K16: 1 | M16: 39000 | Q16: CCP: | S16: 68000
A17: Jeudi | B17: 45946 | C17: 48000 | D17: 66000 | G17: 2000 | J17: 1 | K17: 1 | M17: 48000 | Q17: Monnie | S17: 400000
A18: Vendredi | B18: 45947 | C18: 43000 | D18: 30000 | G18: 2000 | J18: 1 | M18: 43000 | Q18: Loyer Mois d'Octobre 2025 | S18: 150000
A19: Samedi | B19: 45948 | C19: 79000 | D19: 49000 | G19: 2000 | J19: 1 | M19: 79000 | N19: Différence mois de Septembre
A20: Dimanche | B20: 45949 | C20: 75000 | D20: 54000 | G20: 2000 | J20: 1 | M20: 75000 | N20: =D33-C33 -> -9000 | Q20: Maroua:30000 | S20: 30000
A21: Lundi | B21: 45950 | C21: 48000 | D21: 62000 | G21: 2000 | J21: 1 | M21: 48000 | N21: Différence objectif | Q21: Cash PorteFeuille : 60000Da | S21: 60000
A22: Mardi | B22: 45951 | C22: 26000 | D22: 40000 | G22: 2000 | J22: 1 | M22: 26000 | N22: =L36-E36 -> 0
A23: Mercredi | B23: 45952 | C23: 66000 | D23: 67000 | G23: 2000 | J23: 1 | M23: 66000 | N23: Différence du Totale
A24: Jeudi | B24: 45953 | C24: 73000 | D24: 81000 | G24: 2000 | J24: 1 | M24: 73000 | N24: =D33-C33 -> -9000
A25: Vendredi | B25: 45954 | C25: 71000 | D25: 103000 | G25: 2000 | J25: 1 | M25: 71000 | N25: Les vendredis
A26: Samedi | B26: 45955 | C26: 116000 | D26: 50000 | G26: 2000 | J26: 1 | M26: 116000 | N26: =D9+D16+D23+D30 -> 259000
A27: Dimanche | B27: 45956 | C27: 74000 | D27: 100000 | G27: 2000 | J27: 1 | M27: 74000
A28: Lundi | B28: 45957 | C28: 59000 | D28: 45000 | G28: 2000 | J28: 1 | M28: 59000 | N28: Cash réel
A29: Mardi | B29: 45958 | C29: 62000 | D29: 52000 | G29: 2000 | J29: 1 | M29: 62000 | N29: 51000
A30: Mercredi | B30: 45959 | C30: 45000 | D30: 75000 | G30: 2000 | J30: 1 | M30: 45000 | N30: rest à payer
A31: Jeudi | B31: 45960 | C31: 76000 | D31: 101000 | G31: 2000 | J31: 1 | M31: 76000
A32: Vendredi | B32: 45961 | C32: 0 | D32: 64000 | G32: 2000 | J32: 1 | M32: 0
C33: =SUM(C2:C32) -> 1907000 | D33: =SUM(D2:D32) -> 1898000 | E33: ='Les Charges '!H407 -> 719941 | F33: ='Les Salaires'!J30 -> 415721.5 | G33: =SUM(G2:G32) -> 62000 | H33: 190000 | I33: =D33-E33-F33-G33-H33 -> 510337.5 | J33: =SUM(J2:J32) -> 31 | M33: =SUM(M2:M32) -> 1907000
G34: Loyer Magasin | H34: 55000
G35: Loyer Locale | H35: 50000 | N35: =N11-N29-N34 -> 217959
D36: 200000 | G36: Sofiane Maison | H36: 45000 | P36: Papa | Q36: 40000
G37: Dette Papa | H37: 40000
D38: -
C49: 1

Sheet Les Charges 
E2: Produit | F2: Quantité | G2: Prix unitaire | H2: Prix
E3: Semoule Fine 25kg | F3: 19 | G3: 1000 | H3: =F3*G3 -> 19000
E4: Semoule Moyenne 25kg | F4: 1 | G4: 1000 | H4: =F4*G4 -> 1000
E5: Semoule Moula Grosse 10Kg | F5: 3 | G5: 850 | H5: =F5*G5 -> 2550
E6: Sucre Cristalisé | F6: 15 | G6: 99 | H6: =F6*G6 -> 1485
E7: Huile Elio 5 litres | F7: 48 | G7: 600 | H7: =F7*G7 -> 28800
E8: Sel | F8: 15 | G8: 30 | H8: =F8*G8 -> 450
E9: Canette Hamoud | F9: 19 | G9: 44 | H9: =F9*G9 -> 836
E10: Canettes IZEM 24cl | F10: 14 | G10: 72 | H10: =F10*G10 -> 1008
E11: Shwepess Canettes 24cl | F11: 15 | G11: 69 | H11: =F11*G11 -> 1035
E12: Shwepess Canettes Gold 24cl | F12: 12 | G12: 73 | H12: =F12*G12 -> 876
E13: Fanta Canettes 33cl | F13: 9 | G13: 75 | H13: =F13*G13 -> 675
E14: Sprite Canettes 33 cl | F14: 7 | G14: 75 | H14: =F14*G14 -> 525
... E66: Semoule Moula Moyenne 2kg | F66: 5 | G66: 300 | H66: =F66*G66 -> 1500
E67: tomate fraiche | F67: 2 | G67: 120 | H67: =F67*G67 -> 240 | I67: 45931
E68: poivre | F68: 0.5 | G68: 200 | H68: =F68*G68 -> 100
E69: carotte | F69: 1 | G69: 160 | H69: =F69*G69 -> 160
E70: cheddar | F70: 1 | G70: 2050 | H70: =F70*G70 -> 2050
E71: poulet haché | F71: 2 | G71: 800 | H71: =F71*G71 -> 1600
E72: semen Madina 1,8kg | F72: 2 | G72: 820 | H72: =F72*G72 -> 1640
E73: rechta | F73: 5 | G73: 100 | H73: =F73*G73 -> 500
E74: sachets blanc 5kg | F74: 1 | G74: 900 | H74: =F74*G74 -> 900
E75: Papier Aluminium | F75: 1 | G75: 1400 | H75: =F75*G75 -> 1400
E76: sachets pain transparent | F76: 1 | G76: 900 | H76: =F76*G76 -> 900
E77: flitox | F77: 1 | G77: 360 | H77: =F77*G77 -> 360
E78: farine blé complet | F78: 1 | G78: 100 | H78: =F78*G78 -> 100
E79: miel | F79: 6 | G79: 790 | H79: =F79*G79 -> 4740
... E82: boites tranparent 500ccl | F82: 50 | G82: 10.9 | H82: =F82*G82 -> 545
E83: Pain Tacos | F83: 3 | G83: 350 | H83: =F83*G83 -> 1050 | I83: 45932
E84: Chiddar | F84: 6.2 | G84: 1780 | H84: =F84*G84 -> 11036
E85: Tomate Conserve | F85: 24 | G85: 320 | H85: =F85*G85 -> 7680
E86: Harrissa | F86: 24 | G86: 265 | H86: =F86*G86 -> 6360
E87: Gherss | F87: 6 | G87: 135 | H87: =F87*G87 -> 810
E88: Confiture 1kg | F88: 6 | G88: 245 | H88: =F88*G88 -> 1470
E89: chocolat wedjedan blanche | F89: 16 | G89: 265 | H89: =F89*G89 -> 4240
E90: Isis | F90: 5 | G90: 295 | H90: =F90*G90 -> 1475
E91: Tofia | F91: 1 | G91: 970 | H91: =F91*G91 -> 970
E92: poulet haché | F92: 4 | G92: 750 | H92: =F92*G92 -> 3000
E93: blanc de poulet | F93: 4 | G93: 750 | H93: =F93*G93 -> 3000
E94: escalope de poulet | F94: 4 | G94: 750 | H94: =F94*G94 -> 3000
...

Sheet Pointage
B1: Date | C1: Akila | D1: Chiraz | E1: Abir | F1: Samira | G1: Fatiha | H1: Samira Sidi Abdullah | I1: Ahlem | J1: Sarah | K1: Yasmine | L1: Zahia | M1: Zohra | N1: Houda | O1: Imene | P1: Fouzia | Q1: Machair
A2: Mercredi | B2: 45931 | C2: 1 | D2: 0.5 | E2: 1 | F2: 1 | G2: 0 | H2: 1 | I2: 1 | J2: 0.5 | K2: 1 | L2: 1 | M2: 0 | N2: 0 | O2: 0 | P2: 0 | Q2: 0
A3: Jeudi | B3: 45932 | C3: 0.5 | D3: 1 | E3: 0 | F3: 1 | G3: 1 | H3: 1 | I3: 1 | J3: 0.5 | K3: 1 | L3: 0 | M3: 1 | N3: 0 | O3: 0 | P3: 0 | Q3: 0
A4: Vendredi | B4: 45933 | C4: 2 | D4: 2 | E4: 0 | F4: 2 | G4: 2 | H4: 2 | I4: 1 | J4: 0 | K4: 2 | L4: 2 | M4: 0 | N4: 0 | O4: 0 | P4: 0 | Q4: 0
A5: Samedi | B5: 45934 | C5: 1 | D5: 1 | E5: 0.5 | F5: 1 | G5: 1 | H5: 1 | I5: 1 | J5: 1 | K5: 1 | L5: 0 | M5: 1 | N5: 0 | O5: 0 | P5: 0 | Q5: 0
A6: Dimanche | B6: 45935 | C6: 1 | D6: 1 | E6: 1 | F6: 1 | G6: 1 | H6: 1 | I6: 1 | J6: 1 | K6: 1 | L6: 0 | M6: 0 | N6: 0 | O6: 0 | P6: 0 | Q6: 0 | S6: Akila djate à 06h30 jusqu'à 18h14 + Chiraz djate à 10h kharedjet à 18h14
A7: Lundi | B7: 45936 | C7: 2 | D7: 1 | E7: 1 | F7: 1 | G7: 1 | H7: 1 | I7: 1 | J7: 1 | K7: 1 | L7: 0 | M7: 1 | N7: 0 | O7: 0 | P7: 0 | Q7: 0
A8: Mardi | B8: 45937 | C8: 1 | D8: 0.75 | E8: 0 | F8: 1 | G8: 1 | H8: 1 | I8: 1 | J8: 1 | K8: 1 | L8: 1 | M8: 0 | N8: 1 | O8: 0 | P8: 0 | Q8: 0
A9: Mercredi | B9: 45938 | C9: 1 | D9: 1 | E9: 0 | F9: 1 | G9: 1 | H9: 1 | I9: 1 | J9: 0.5 | K9: 1 | L9: 0 | M9: 1 | N9: 0 | O9: 0 | P9: 0 | Q9: 0
A10: Jeudi | B10: 45939 | C10: 1 | D10: 1 | E10: 0 | F10: 1 | G10: 1 | H10: 1 | I10: 1 | J10: 0.5 | K10: 1 | L10: 1 | M10: 0 | N10: 0 | O10: 0 | P10: 0 | Q10: 0
A11: Vendredi | B11: 45940 | C11: 2 | D11: 2 | E11: 0 | F11: 2 | G11: 2 | H11: 2 | I11: 1 | J11: 1 | K11: 2 | L11: 0 | M11: 2 | N11: 0 | O11: 0 | P11: 0 | Q11: 0
A12: Samedi | B12: 45941 | C12: 1 | D12: 1 | E12: 0 | F12: 1 | G12: 1 | H12: 1 | I12: 1 | J12: 1 | K12: 1 | L12: 1 | M12: 0 | N12: 0 | O12: 1 | P12: 0 | Q12: 0 | S12: Akila djate à 06h40 et kharedjet à 17h30
A13: Dimanche | B13: 45942 | C13: 1 | D13: 1 | E13: 0 | F13: 1 | G13: 1 | H13: 1 | I13: 1 | J13: 1 | K13: 1 | L13: 0 | M13: 1 | N13: 0 | O13: 1 | P13: 0 | Q13: 0
A14: Lundi | B14: 45943 | C14: 2 | D14: 0 | E14: 0 | F14: 0 | G14: 1 | H14: 0 | I14: 1 | J14: 1 | K14: 1 | L14: 1 | M14: 0 | N14: 1 | O14: 1 | P14: 0 | Q14: 0
A15: Mardi | B15: 45944 | C15: 1 | D15: 1 | E15: 0 | F15: 0 | G15: 1 | H15: 0 | I15: 1 | J15: 1 | K15: 1 | L15: 0 | M15: 1 | N15: 0 | O15: 0 | P15: 0 | Q15: 0
A16: Mercredi | B16: 45945 | C16: 1 | D16: 1 | E16: 0 | F16: 1 | G16: 1 | H16: 0 | I16: 1 | J16: 0 | K16: 1 | L16: 1 | M16: 0 | N16: 0 | O16: 1 | P16: 0 | Q16: 0
A17: Jeudi | B17: 45946 | C17: 1 | D17: 0 | E17: 0 | F17: 1 | G17: 1 | H17: 0 | I17: 1 | J17: 0.5 | K17: 0 | L17: 0 | M17: 1 | N17: 0 | O17: 1 | P17: 0 | Q17: 0
A18: Vendredi | B18: 45947 | C18: 2 | D18: 2 | E18: 0 | F18: 2 | G18: 2 | H18: 2 | I18: 1 | J18: 2 | K18: 2 | L18: 2 | M18: 0 | N18: 0 | O18: 2 | P18: 0 | Q18: 0
A19: Samedi | B19: 45948 | C19: 1 | D19: 1 | E19: 0 | F19: 1 | G19: 1 | H19: 1 | I19: 1 | J19: 1 | K19: 1 | L19: 0 | M19: 1 | N19: 0 | O19: 1 | P19: 1 | Q19: 0
A20: Dimanche | B20: 45949 | C20: 1 | D20: 1 | E20: 0 | F20: 1 | G20: 1 | H20: 0 | I20: 1 | J20: 1 | K20: 1 | L20: 1 | M20: 0 | N20: 0 | O20: 1 | P20: 1 | Q20: 1
A21: Lundi | B21: 45950 | C21: 2 | D21: 1 | E21: 0 | F21: 1 | G21: 1 | H21: 0 | I21: 1 | J21: 1 | K21: 1 | L21: 0 | M21: 1 | N21: 1 | O21: 1 | P21: 1 | Q21: 1
A22: Mardi | B22: 45951 | C22: 0.75 | D22: 1 | E22: 0 | F22: 1 | G22: 1 | H22: 0 | I22: 1 | J22: 1 | K22: 1 | L22: 1 | M22: 0 | N22: 0 | O22: 0 | P22: 1 | Q22: 1
A23: Mercredi | B23: 45952 | C23: 1 | D23: 0.25 | E23: 0 | F23: 1 | G23: 1 | H23: 0 | I23: 1 | J23: 0.5 | K23: 1 | L23: 0 | M23: 1 | N23: 0 | O23: 0 | P23: 1 | Q23: 1
A24: Jeudi | B24: 45953 | C24: 1 | D24: 0 | E24: 0 | F24: 1 | G24: 1 | H24: 0 | I24: 1 | J24: 0.5 | K24: 1 | L24: 1 | M24: 0 | N24: 0 | O24: 0 | P24: 0.75 | Q24: 1
... A32: Vendredi | B32: 45961 | C32: 2 | D32: 2 | E32: 0 | F32: 2 | G32: 2 | H32: 2 | I32: 1 | J32: 2 | K32: 2 | L32: 0 | M32: 0 | N32: 0 | O32: 0 | P32: 0 | Q32: 2
C33: 3 | E33: 0 | F33: 1 | G33: 1 | H33: 0 | J33: 1 | Q33: 0 | S33: akila 2 jours OFF de Septembre +Samira une journée OFF de Septembre + Sara journée de Septembre le 30
C34: =SUM(C2:C33) -> 42.25 | D34: =SUM(D2:D33) -> 31.5 | E34: =SUM(E2:E33) -> 3.5 | F34: =SUM(F2:F33) -> 33 | G34: =SUM(G2:G33) -> 36 | H34: =SUM(H2:H33) -> 22 | I34: =SUM(I2:I33) -> 30 | J34: =SUM(J2:J33) -> 26.5 | ... R34: =SUM(R2:R33) -> 0
C35: 1290 | D35: 1126 | E35: 1000 | F35: 970 | G35: 970 | H35: 1100 | I35: 970 | J35: 970 | K35: 970 | L35: 1000 | M35: 1200 | N35: 1200 | O35: 800 | P35: 1350 | Q35: 970
C36: =C34*C35 -> 54502.5 | D36: =D34*D35 -> 35469 | E36: =E34*E35 -> 3500 | F36: =F34*F35 -> 32010 | G36: =G34*G35 -> 34920 | H36: =H34*H35 -> 24200 | I36: =I34*I35 -> 29100 | J36: =J34*J35 -> 25705 | ... R36: =R34*R35 -> 0
C37: 40000 | D37: 35000 | E37: 30000 | F37: 30000 | G37: 30000 | H37: 33000 | I37: 30000 | J37: 30000 | K37: 30000 | L37: 30000 | M37: / | N37: 30000 | O37: 25000
V38: Date | W38: Fouzia
U39: Mercredi | V39: 45931 | W39: 0
U40: Jeudi | V40: 45932 | W40: 0
U41: Vendredi | V41: 45933 | W41: 0
U42: Samedi | V42: 45934 | W42: 0
U43: Dimanche | V43: 45935 | W43: 0
U44: Lundi | V44: 45936 | W44: 0
U45: Mardi | V45: 45937 | W45: 0
U46: Mercredi | V46: 45938 | W46: 0
U47: Jeudi | V47: 45939 | W47: 0
...

Sheet Les Salaires
I12: Nom | J12: Salaire | K12: Avance | L12: Salaire à payer
I13: Sofiane | J13: 30000 | K13: 30000 | L13: =J13-K13 -> 0 | N13: 45949
I14: Amel | J14: 30000 | K14: 30000 | L14: =J14-K14 -> 0
H15: 1 | I15: Akila | J15: =Pointage!C36 -> 54502.5 | K15: 54500 | L15: =J15-K15 -> 2.5 | N15: 2500Da Mois de Septembre +10000Da
H16: 2 | I16: Chiraz | J16: =Pointage!D36 -> 35469 | K16: 35500 | L16: =J16-K16 -> -31
H17: 3 | I17: Abir | J17: =Pointage!E36 -> 3500 | K17: 3500 | L17: =J17-K17 -> 0
H18: 4 | I18: Samira | J18: =Pointage!F36 -> 32010 | K18: 32000 | L18: =J18-K18 -> 10 | N18: 1000Da Mois de Septembre
H19: 5 | I19: Fatiha | J19: =Pointage!G36 -> 34920 | K19: 35000 | L19: =J19-K19 -> -80 | N19: 5000 DA 2 ème Mois +2000Da +6000+1000+1000+ 4500 9oudeyan+ iande et poisson
H20: 6 | I20: Samira Sidi AbduAllah | J20: =Pointage!H36 -> 24200 | K20: 24500 | L20: =J20-K20 -> -300 | N20: 5000+10500+5000+2000+2000
H21: 7 | I21: Ahlem | J21: =Pointage!I36 -> 29100 | K21: 29500 | L21: =J21-K21 -> -400
H22: 8 | I22: Sarah | J22: =Pointage!J36 -> 25705 | K22: 26000 | L22: =J22-K22 -> -295 | M22: 3000+2000
H23: 9 | I23: Yasmine | J23: =Pointage!K36+M23 -> 37980 | K23: 38000 | L23: =J23-K23 -> -20 | M23: 5000
H24: 10 | I24: Zahia | J24: =Pointage!L36 -> 17000 | K24: 17000 | L24: =J24-K24 -> 0
H25: 11 | I25: Zohra | J25: =Pointage!M36 -> 20400 | K25: 20500 | L25: =J25-K25 -> -100
H26: 12 | I26: Houda | J26: =Pointage!N36 -> 4800 | K26: 5000 | L26: =J26-K26 -> -200 | M26: 1000+4000
H27: 13 | I27: Imene | J27: =Pointage!O36 -> 8000 | K27: 8000 | L27: =J27-K27 -> 0
H28: 14 | I28: Fouzia | J28: =Pointage!P36 -> 15525 | K28: 16000 | L28: =J28-K28 -> -475
H29: 15 | I29: Machair | J29: =Pointage!Q36 -> 12610 | K29: 13000 | L29: =J29-K29 -> -390 | M29: 2000
I30: TOTAL | J30: =SUM(J13:J29) -> 415721.5 | K30: =SUM(K13:K29) -> 418000 | L30: =J30-K30 -> -2278.5
L31: =J31-K31 -> 0

Sheet Feuille 5
E18: Mois de Janvier 2025 | F18: Mois de Février 2025 | G18: Mois de Mars 2025 | H18: Mois d'Avril 2025 | I18: Mois de Mai 2025 | J18: Mois de Juin 2025 | K18: Mois de Juillet 2025 | L18: Mois d'Aout 2025 | M18: Mois de Septembre 2025 | N18: Mois d'Octobre 2025
D19: Recette | E19: 2033000 | F19: 1859000 | G19: 2094000 | H19: 1282000 | I19: 2077000 | J19: 2345000 | K19: 1997000 | L19: 1772000 | M19: 1907000 | N19: 1898000
D20: Charges | E20: 854000 | F20: 884000 | G20: 962000 | H20: 669000 | I20: 800000 | J20: 883000 | K20: 883000 | L20: 664000 | M20: 702000 | N20: 720000
D21: Salaires | E21: 427000 | F21: 409000 | G21: 439000 | H21: 338000 | I21: 385000 | J21: 365000 | K21: 392000 | L21: 370000 | M21: 367000 | N21: 416000
D22: Che7i7a | E22: 62000 | F22: 56000 | G22: 60000 | H22: 50000 | I22: 180000 | J22: 56000 | K22: 62000 | L22: 48000 | M22: 58000 | N22: 62000
D23: Loyer+Dettes | E23: 180000 | F23: 180000 | G23: 180000 | H23: 180000 | I23: 180000 | J23: 180000 | K23: 180000 | L23: 180000 | M23: 180000 | N23: 190000
D24: Profit Net | E24: =E19-E20-E21-E22-E23 -> 510000 | F24: =F19-F20-F21-F22-F23 -> 330000 | G24: =G19-G20-G21-G22-G23 -> 453000 | H24: =H19-H20-H21-H22-H23 -> 45000 | I24: =I19-I20-I21-I22-I23 -> 532000 | J24: =J19-J20-J21-J22-J23 -> 861000 | K24: =K19-K20-K21-K22-K23 -> 480000 | L24: =L19-L20-L21-L22-L23 -> 510000 | ... N24: =N19-N20-N21-N22-N23 -> 510000
H30: Mois d'Octobre e 2025
G31: Recette | H31: 1898000
G32: Charges | H32: 720000
G33: Salaires | H33: 416000
G34: Che7i7a | H34: 62000
G35: Loyer+Dettes | H35: 190000
G36: Profit Net | H36: =H31-H32-H33-H34-H35 -> 510000
