Workbook

Sheet RECAP
B1: Date | C1: Recette de Decembre | D1: Recette | E1: Charges | F1: Salaire | G1: Loyer | H1: Net Profit | I1: Nb de jours | K1: Decembre
A2: Vendredi | B2: 44197 | C2: 26000 | D2: 26000 | I2: 1 | K2: 26000 | L2: Moyenne
A3: Samedi | B3: 44198 | C3: 29000 | D3: 30000 | I3: 1 | K3: 29000 | L3: =D33/I33 -> 41172.414
A4: Dimanche | B4: 44199 | C4: 57000 | D4: 27000 | I4: 1 | K4: 57000
A5: Lundi | B5: 44200 | C5: 40000 | D5: 27000 | I5: 1 | K5: 40000 | L5: 40000
A6: Mardi | B6: 44201 | C6: 30000 | D6: 48000 | I6: 1 | K6: 30000
A7: Mercredi | B7: 44202 | C7: 31000 | D7: 33000 | I7: 1 | K7: 31000
A8: Jeudi | B8: 44203 | C8: 22000 | D8: 63000 | I8: 1 | K8: 22000
A9: Vendredi | B9: 44204 | C9: 38000 | D9: 54000 | I9: 1 | K9: 38000
A10: Samedi | B10: 44205 | C10: 44000 | D10: 46000 | I10: 1 | K10: 44000
A11: Dimanche | B11: 44206 | C11: 49000 | D11: 61000 | I11: 1 | K11: 49000
A12: Lundi | B12: 44207 | C12: 60000 | D12: 92000 | I12: 1 | K12: 60000
A13: Mardi | B13: 44208 | C13: 31000 | D13: 58000 | I13: 1 | K13: 31000
A14: Mercredi | B14: 44209 | C14: 27000 | D14: 39000 | I14: 1 | K14: 27000 | L14: Cash restant | M14: Magasin | O14: Différence mois de Decembre
A15: Jeudi | B15: 44210 | C15: 27000 | D15: 41000 | I15: 1 | K15: 27000 | L15: =D33+'Les charges '!G256-'Les charges '!G255-M15-Salaires!J25 -> 726735 | M15: 12000 | O15: =D33-C33 -> 40000
A16: Vendredi | B16: 44211 | C16: 20000 | D16: 0 | I16: 0 | K16: 20000 | M16: 412000
A17: Samedi | B17: 44212 | C17: 36000 | D17: 0 | I17: 0 | K17: 36000 | L17: Sofiane | M17: 10000 | N17: 0
A18: Dimanche | B18: 44213 | C18: 55000 | D18: 28000 | I18: 1 | K18: 55000 | L18: Magasin | M18: ='Les charges '!M225*1 -> 50600
A19: Lundi | B19: 44214 | C19: 36000 | D19: 28000 | I19: 1 | K19: 36000
A20: Mardi | B20: 44215 | C20: 33000 | D20: 28000 | I20: 1 | K20: 33000
A21: Mercredi | B21: 44216 | C21: 29000 | D21: 39000 | I21: 1 | K21: 29000
A22: Jeudi | B22: 44217 | C22: 26000 | D22: 50000 | I22: 1 | K22: 26000
A23: Vendredi | B23: 44218 | C23: 24000 | D23: 36000 | I23: 1 | K23: 24000
A24: Samedi | B24: 44219 | C24: 60000 | D24: 25000 | I24: 1 | K24: 60000
A25: Dimanche | B25: 44220 | C25: 45000 | D25: 30000 | I25: 1 | K25: 45000
A26: Lundi | B26: 44221 | C26: 42000 | D26: 32000 | I26: 1 | K26: 42000
A27: Mardi | B27: 44222 | C27: 32000 | D27: 40000 | I27: 1 | K27: 32000
A28: Mercredi | B28: 44223 | C28: 29000 | D28: 46000 | I28: 1 | K28: 29000
A29: Jeudi | B29: 44224 | C29: 35000 | D29: 80000 | I29: 1 | K29: 35000
A30: Vendredi | B30: 44225 | C30: 44000 | D30: 34000 | I30: 1 | K30: 44000
A31: Samedi | B31: 44226 | C31: 42000 | D31: 36000 | I31: 1 | K31: 42000 | O31: 473265
A32: Dimanche | B32: 44227 | C32: 55000 | D32: 17000 | I32: 1 | K32: 55000
A33: TOTAL | C33: =SUM(C2:C32) -> 1154000 | D33: =SUM(D2:D32) -> 1194000 | E33: ='Les charges '!G255*1 -> 473265 | F33: =Salaires!I25*1 -> 209446 | G33: 50000 | H33: =D33+'Les charges '!G256-G33-F33-E33 -> 481289 | I33: =SUM(I2:I32) -> 29 | K33: =SUM(K2:K32) -> 1154000
A34: TAUX | D34: 1 | E34: =E33/D33 -> 0.39636935 | F34: =F33/D33 -> 0.17541541 | G34: =G33/D33 -> 0.041876047 | H34: =H33/D33 -> 0.40308961
C36: Objectif | D36: 1160000 | E36: 400000 | F36: 210000 | G36: 50000 | H36: 500000
C37: Mois de Décembre | D37: 1154000 | E37: 398000 | F37: 206700 | G37: 77000 | H37: 512500

Sheet Les charges 
E5: Produit | F5: Quantité | G5: Prix | H5: Date d'achat
E6: chocolat dada 1kg | F6: 3 | G6: 1053 | H6: 44197
E7: 1 boite vanille de 3kg | F7: 1 | G7: 1200 | H7: 44197
E8: goblet de sorbet | F8: 1 | G8: 850 | H8: 44197
E9: sachet en papier 23 | F9: 1 | G9: 700 | H9: 44197
E10: sacs de 5kg | F10: 1 | G10: 1200 | H10: 44197
E11: 1 Tofia | F11: 1 | G11: 850 | H11: 44197
E12: raisins secs | F12: 1 | G12: 850 | H12: 44197
E13: arachides éfilés | F13: 500g | G13: 300 | H13: 44197
E14: Farine Mama | F14: 4 fardeaux | G14: 2800 | H14: 44197
E15: semen Madina | F15: 4 | G15: 1840 | H15: 44197
E16: miel 5kg | F16: 2 | G16: 1180 | H16: 44197
E17: sel | F17: 1 fardeau | G17: 320 | H17: 44197
E18: paprika | F18: 2kg | G18: 1200 | H18: 44197
E19: coca petit | F19: 2 fardeaux | G19: 1000 | H19: 44197
E20: eau petit | F20: 3 fardeaux | G20: 465 | H20: 44197
E21: eau grand | F21: 5 fardeaux | G21: 700 | H21: 44197
E22: rouiba jus | F22: 2 fardeaux | G22: 860 | H22: 44197
E23: hamoud 33ml | F23: 2 fardeaux | G23: 740 | H23: 44197
E24: coca canette | F24: 1 | G24: 1450 | H24: 44197
E25: Margarine Mani 500g | F25: 2 cartons de 24 | G25: 5520 | H25: 44197
E26: miel Mordjan | F26: 4 | G26: 2260 | H26: 44197
E27: Semoule fine Mama 2kg | F27: 10 fardeaux | G27: 12000 | H27: 44197
E28: Tomate CAB | F28: 2 cartons de 12kg | G28: 3552 | H28: 44197
E29: fromage spécial pizza | F29: 14kg | G29: 2814 | H29: 44197
E30: levure de bierre | F30: 1 carton de 20 de 500g | G30: 5360 | H30: 44197
E31: Farine Mama | F31: 5 fardeaux | G31: 3400 | H31: 44197
E32: semoule fine Sim 10kg | F32: 15 sachets | G32: 6150 | H32: 44197
E33: harrissa CAB | F33: 1 carton de 12kg | G33: 2376 | H33: 44197
E34: Semen Madina 1,8kg | F34: 8 | G34: 3520 | H34: 44197
E35: sacs poubelle | F35: 1 fardeau | G35: 1600 | H35: 44197
E36: sachts transparets | F36: 12 | G36: 600 | H36: 44197
E37: Semoule de blé complet | F37: 100kg | G37: 10000 | H37: 44197
E38: support | F38: 2 | G38: 100 | H38: 44197
E39: poulet hachée | F39: 3kg | G39: 1400 | H39: 44197
E40: épices | F40: 2 | G40: 100 | H40: 44197
E41: assièttes | F41: 2 | G41: 240 | H41: 44197
E42: huile | F42: 10 | G42: 5200 | H42: 44197
E43: chocolat blanc | F43: 1.5kg | G43: 600 | H43: 44197
E44: baghrir | F44: 10 jours | G44: 15000 | H44: 44197
...

Sheet Pointage
B1: Date | C1: Zehor | D1: Zoubida | E1: Nadjet | F1: Hadjer | G1: Amel | H1: Soumia | I1: Karima | J1: Nouara | K1: Zahida | L1: Remarque
A2: Vendredi | B2: 44197 | C2: 1 | D2: 0 | E2: 0 | F2: 1 | G2: 1 | H2: 0 | I2: 0 | J2: 1 | K2: 1
A3: Samedi | B3: 44198 | C3: 1 | D3: 1 | E3: 0 | F3: 0 | G3: 1 | H3: 0 | I3: 1 | J3: 1 | K3: 1
A4: Dimanche | B4: 44199 | C4: 0 | D4: 1 | E4: 0 | F4: 0 | G4: 1 | H4: 0 | I4: 1 | J4: 1 | K4: 1
A5: Lundi | B5: 44200 | C5: 1 | D5: 1 | E5: 0 | F5: 0 | G5: 1 | H5: 0 | I5: 1 | J5: 1 | K5: 1
A6: Mardi | B6: 44201 | C6: 1 | D6: 1 | E6: 0 | F6: 0 | G6: 1 | H6: 1 | I6: 1 | J6: 0 | K6: 1
A7: Mercredi | B7: 44202 | C7: 1 | D7: 1 | E7: 0 | F7: 0 | G7: 1 | H7: 1 | I7: 1 | J7: 1 | K7: 1
A8: Jeudi | B8: 44203 | C8: 1 | D8: 1 | E8: 0 | F8: 1 | G8: 1 | H8: 1 | I8: 1 | J8: 1 | K8: 1
A9: Vendredi | B9: 44204 | C9: 1 | D9: 0 | E9: 0 | F9: 1 | G9: 0 | H9: 0 | I9: 1 | J9: 1 | K9: 1
A10: Samedi | B10: 44205 | C10: 1 | D10: 1 | E10: 0 | F10: 1 | G10: 1 | H10: 1 | I10: 1 | J10: 1 | K10: 1
A11: Dimanche | B11: 44206 | C11: 1 | D11: 1 | E11: 0 | F11: 1 | G11: 1 | H11: 1 | I11: 1 | J11: 1 | K11: 1
A12: Lundi | B12: 44207 | C12: 1 | D12: 1 | E12: 0 | F12: 1 | G12: 1 | H12: 1 | I12: 1 | J12: 1 | K12: 2
A13: Mardi | B13: 44208 | C13: 0 | D13: 1 | E13: 0 | F13: 1 | G13: 1 | H13: 1 | I13: 1 | J13: 1 | K13: 2
... A32: Dimanche | B32: 44227 | C32: 1 | D32: 1 | E32: 0 | F32: 0 | G32: 0 | H32: 1 | I32: 1 | J32: 0.5 | K32: 1
A33: TOTAL | C33: =SUM(C2:C32) -> 24 | D33: =SUM(D2:D32) -> 25 | E33: =SUM(E2:E32) -> 0 | F33: =SUM(F2:F32) -> 12 | G33: =SUM(G2:G32) -> 23 | H33: =SUM(H2:H32) -> 22 | I33: =SUM(I2:I32) -> 29 | J33: =SUM(J2:J32) -> 27.5 | K33: =SUM(K2:K32) -> 31.5
A34: TAUX | C34: 1920 | D34: 1200 | E34: 900 | F34: 1000 | G34: 1153 | H34: 800 | I34: 500 | J34: 961 | K34: 1153 | L34: =SUM(C34:K34) -> 9587
C35: =C34*C33 -> 46080 | D35: =D34*D33 -> 30000 | E35: =E34*E33 -> 0 | F35: =F34*F33 -> 12000 | G35: =G34*G33 -> 26519 | H35: =H34*H33 -> 17600 | I35: =I34*I33 -> 14500 | J35: =J34*J33 -> 26427.5 | K35: =K33*K34 -> 36319.5 | L35: =SUM(C35:K35) -> 209446

Sheet Salaires
H15: Nom | I15: Salaire | J15: Avance
G16: 1 | H16: Zehor | I16: =Pointage!C35*1 -> 46080 | K16: 46000
G17: 2 | H17: Amel | I17: =Pointage!G35*1 -> 26519 | J17: 2000 | K17: 25000
G18: 3 | H18: Nowara | I18: =Pointage!J35*1 -> 26427.5 | K18: 26500
G19: 4 | H19: karima | I19: =Pointage!I35*1 -> 14500 | K19: 14500
G20: 5 | H20: Nadjet | I20: =Pointage!E35*1 -> 0
G21: 6 | H21: Hadjer | I21: =Pointage!F35*1 -> 12000 | K21: 12000
G22: 7 | H22: Zoubida | I22: =Pointage!D35*1 -> 30000 | K22: 30000
G23: 8 | H23: Soumia | I23: =Pointage!H35*1 -> 17600 | K23: 18000
G24: 9 | H24: Zahida | I24: =Pointage!K35*1 -> 36319.5 | K24: 36300
H25: TOTAL | I25: =SUM(I16:I24) -> 209446 | J25: =SUM(J16:J24) -> 2000
I26: =I25-J25 -> 207446
