Workbook

Sheet RECAP
B1: Date | C1: Recette Juin 2024 | D1: Recette | E1: Charges | F1: Salaire | G1: Loyer | H1: Net Profit | I1: Nb de jours | K1: Objectif | L1: Mois de Juin 2024
A2: Lundi | B2: 45474 | C2: 70000 | D2: 41000 | I2: 1 | L2: 70000
A3: mardi | B3: 45475 | C3: 38000 | D3: 37000 | I3: 1 | L3: 38000 | M3: Bénéfice Moyen par jour | N3: Moyenne | O3: Moyenne salaire | P3: pourcentage du salaire vis à vis la recettte
A4: mercredi | B4: 45476 | C4: 30000 | D4: 47000 | I4: 1 | L4: 30000 | M4: =H33/I33 -> 24001.848 | N4: =D33/I33 -> 75333.333 | P4: =O4/N4 -> 0
A5: jeudi | B5: 45477 | C5: 50000 | D5: 130000 | I5: 1 | L5: 50000
A6: vendredi | B6: 45478 | C6: 52000 | D6: 40000 | I6: 1 | L6: 52000 | M6: Moyenne des charges par jour | N6: Objectif
A7: samedi | B7: 45479 | C7: 43000 | D7: 117000 | I7: 1 | L7: 43000 | M7: =E33/I33 -> 31922.7 | N7: 100000
A8: dimanche | B8: 45480 | C8: 45000 | D8: 90000 | I8: 1 | L8: 45000 | M8: ²
A9: lundi | B9: 45481 | C9: 46000 | D9: 60000 | I9: 1 | L9: 46000
A10: mardi | B10: 45482 | C10: 45000 | D10: 50000 | I10: 1 | L10: 45000 | M10: Cash restant | N10: Magasin | O10: Cash réel | P10: Mes dettes pour le magasin
A11: mercredi | B11: 45483 | C11: 48000 | D11: 60000 | I11: 1 | L11: 48000 | M11: =M14+D33-E33-'Les Salaires'!K32-N11-P34 -> 923819 | N11: 25000 | O11: 1005000 | P11: =M11-O11 -> -81181
A12: jeudi | B12: 45484 | C12: 26000 | D12: 67000 | I12: 1 | L12: 26000
A13: vendredi | B13: 45485 | C13: 70000 | D13: 65000 | I13: 1 | L13: 70000 | M13: Fond de Roulement
A14: samedi | B14: 45486 | C14: 69000 | D14: 470000 | I14: 1 | L14: 69000 | M14: 330000 | P14: Ccp: 60000Da
A15: dimanche | B15: 45487 | C15: 172000 | D15: 52000 | I15: 1 | L15: 172000
A16: lundi | B16: 45488 | C16: 220000 | D16: 80000 | I16: 1 | L16: 220000
A17: mardi | B17: 45489 | C17: 0 | D17: 70000 | I17: 1 | L17: 0 | P17: cash chez Kamel: 10000Da
A18: mercredi | B18: 45490 | C18: 0 | D18: 60000 | I18: 1 | L18: 0
A19: jeudi | B19: 45491 | C19: 0 | D19: 43000 | I19: 1 | L19: 0 | M19: Différence mois de juin | P19: la vraie caisse:17000Da + 8000Da monnie
A20: vendredi | B20: 45492 | C20: 55000 | D20: 34000 | I20: 1 | L20: 55000 | M20: =D33-C33 -> 500000
A21: samedi | B21: 45493 | C21: 150000 | D21: 100000 | I21: 1 | L21: 150000 | M21: Différence objectif | O21: réparation Tabouna | P21: 1 | Q21: 8800 | R21: =P21*Q21 -> 8800
A22: dimanche | B22: 45494 | C22: 70000 | D22: 28000 | I22: 1 | L22: 70000 | M22: =K36-E36 -> 0 | O22: Torchons | P22: 4 | Q22: 400 | R22: 600
A23: lundi | B23: 45495 | C23: 44000 | D23: 74000 | I23: 1 | L23: 44000 | M23: Différence du Totale | O23: poelle | P23: 1 | Q23: 2800 | R23: =P23*Q23 -> 2800
A24: mardi | B24: 45496 | C24: 57000 | D24: 49000 | I24: 1 | L24: 57000 | M24: =D33-C33 -> 500000 | R24: =SUM(R21:R23) -> 12200
A25: mercredi | B25: 45497 | C25: 49000 | D25: 52000 | I25: 1 | L25: 49000 | M25: Les vendredis | O25: Cash chez Sofiane
A26: jeudi | B26: 45498 | C26: 38000 | D26: 73000 | I26: 1 | L26: 38000 | M26: =D9+D16+D23+D30 -> 248000 | O26: Cash pour Amine | P26: 70000
A27: vendredi | B27: 45499 | C27: 60000 | D27: 24000 | I27: 1 | L27: 60000 | O27: Cash de la caisse | P27: 5000
A28: samedi | B28: 45500 | C28: 70000 | D28: 73000 | I28: 1 | L28: 70000 | M28: Cash réel | O28: Argent de poche | P28: 10000
A29: dimanche | B29: 45501 | C29: 38000 | D29: 35000 | I29: 1 | L29: 38000 | M29: 51000 | O29: Portable pour Houda | P29: 85000
A30: lundi | B30: 45502 | C30: 60000 | D30: 34000 | I30: 1 | L30: 60000 | M30: rest à payer | O30: Cash pour vidange | P30: 20000
A31: mardi | B31: 45503 | C31: 45000 | D31: 50000 | I31: 1 | L31: 45000 | O31: La commande de Mme Farida | P31: 8000
A32: mercredi | B32: 45504 | C32: 0 | D32: 55000 | L32: 0 | O32: Complenet de salaires | P32: 4000
C33: =SUM(C2:C32) -> 1760000 | D33: =SUM(D2:D32) -> 2260000 | E33: ='Les charges '!E479 -> 957681 | F33: ='Les Salaires'!J32 -> 432263.57 | G33: 150000 | H33: =D33-E33-F33-G33 -> 720055.43 | I33: =SUM(I2:I32) -> 30 | L33: =SUM(L2:L32) -> 1760000 | O33: Cash pour Vacances | P33: 45000
P34: =SUM(P26:P33) -> 247000
M35: =M11-M29-M34 -> 872819
D38: -

Sheet Pointage
B1: Date | C1: Lynda | D1: Hafida | E1: Yasmine Sidi Abd Allah | F1: Nawel | G1: Fouzia | H1: Nadjet | I1: Fatiha | J1: Samira | K1: Zohra | L1: Chiraz | M1: Sarah | N1: Saliha | O1: Romayessa | P1: Mouna | Q1: Fatima/Insaf | R1: Nesrine | S1: Kenza | T1: Yasmine
A2: Lundi | B2: 45474 | C2: 1 | D2: 1 | E2: 1 | F2: 1 | G2: 1 | H2: 0 | I2: 1 | J2: 1 | K2: 0 | L2: 1 | M2: 1 | N2: 1 | O2: 0 | P2: 0 | Q2: 0 | R2: 0 | S2: 0 | T2: 0
A3: mardi | B3: 45475 | C3: 1 | D3: 1 | E3: 0 | F3: 0 | G3: 1 | H3: 0 | I3: 1 | J3: 1 | K3: 1 | L3: 0 | M3: 1 | N3: 1 | O3: 1 | P3: 0 | Q3: 0 | R3: 0 | S3: 0 | T3: 1
A4: mercredi | B4: 45476 | C4: 1 | D4: 1 | E4: 1 | F4: 0 | G4: 1 | H4: 0 | I4: 1 | J4: 1 | K4: 0 | L4: 1 | M4: 1 | N4: 1 | O4: 1 | P4: 0 | Q4: 0 | R4: 0 | S4: 0 | T4: 1
A5: jeudi | B5: 45477 | C5: 1 | D5: 1 | E5: 1 | F5: 0 | G5: 0.5 | H5: 0 | I5: 1 | J5: 2 | K5: 0 | L5: 1 | M5: 1 | N5: 1 | O5: 1 | P5: 0 | Q5: 0 | R5: 0 | S5: 0 | T5: 2
A6: vendredi | B6: 45478 | C6: 0.5 | D6: 1 | E6: 1 | F6: 0 | G6: 0 | H6: 0 | I6: 0 | J6: 1 | K6: 1 | L6: 0.5 | M6: 0 | N6: 0 | O6: 1 | P6: 0 | Q6: 0 | R6: 0 | S6: 0 | T6: 1
A7: samedi | B7: 45479 | C7: 1.25 | D7: 1.25 | E7: 1.25 | F7: 1.25 | G7: 1.25 | H7: 1 | I7: 1 | J7: 1.25 | K7: 1 | L7: 1.25 | M7: 1 | N7: 1.25 | O7: 1.25 | P7: 0 | Q7: 0 | R7: 0 | S7: 0 | T7: 1.25
A8: dimanche | B8: 45480 | C8: 1 | D8: 1 | E8: 1 | F8: 1 | G8: 1 | H8: 0 | I8: 1 | J8: 1 | K8: 1 | L8: 1 | M8: 1 | N8: 1 | O8: 0 | P8: 0 | Q8: 0 | R8: 0 | S8: 0 | T8: 1
A9: lundi | B9: 45481 | C9: 1 | D9: 1 | E9: 1 | F9: 1 | G9: 1 | H9: 0 | I9: 1 | J9: 0 | K9: 0 | L9: 1 | M9: 1 | N9: 1 | O9: 0 | P9: 0 | Q9: 0 | R9: 0 | S9: 0 | T9: 1
A10: mardi | B10: 45482 | C10: 1 | D10: 1 | E10: 0 | F10: 1 | G10: 0 | H10: 0 | I10: 1 | J10: 1 | K10: 0 | L10: 0 | M10: 1 | N10: 1 | O10: 1 | P10: 1 | Q10: 0 | R10: 0 | S10: 0 | T10: 1
A11: mercredi | B11: 45483 | C11: 1 | D11: 0 | E11: 0 | F11: 1 | G11: 1 | H11: 0 | I11: 0 | J11: 1 | K11: 0 | L11: 1 | M11: 1 | N11: 1 | O11: 1 | P11: 1 | Q11: 0 | R11: 0 | S11: 0 | T11: 1
A12: jeudi | B12: 45484 | C12: 1 | D12: 1.25 | E12: 1 | F12: 1 | G12: 0 | H12: 0 | I12: 0 | J12: 1 | K12: 1 | L12: 1 | M12: 1 | N12: 1 | O12: 1.25 | P12: 1 | Q12: 0 | R12: 0 | S12: 0 | T12: 0
A13: vendredi | B13: 45485 | C13: 2 | D13: 1 | E13: 1 | F13: 0 | G13: 0 | H13: 0 | I13: 0 | J13: 1 | K13: 0 | L13: 1.5 | M13: 1.25 | N13: 0 | O13: 1 | P13: 1 | Q13: 0 | R13: 0 | S13: 0 | T13: 1
A14: samedi | B14: 45486 | C14: 2 | D14: 1.5 | E14: 1 | F14: 2 | G14: 0 | H14: 0.5 | I14: 0 | J14: 1.5 | K14: 1.25 | L14: 2 | M14: 2 | N14: 0 | O14: 1.5 | P14: 0 | Q14: 0 | R14: 0 | S14: 0 | T14: 2 | U14: La comande de FAP et CNPM
A15: dimanche | B15: 45487 | C15: 1 | D15: 1.25 | E15: 1 | F15: 1 | G15: 0 | H15: 0 | I15: 0 | J15: 1 | K15: 0 | L15: 1 | M15: 0 | N15: 0 | O15: 0.75 | P15: 0 | Q15: 1.2 | R15: 0 | S15: 0 | T15: 1.25
A16: lundi | B16: 45488 | C16: 1.15 | D16: 1.25 | E16: 1.15 | F16: 1 | G16: 0 | H16: 1 | I16: 0 | J16: 1 | K16: 1.25 | L16: 1 | M16: 1 | N16: 0 | O16: 1.25 | P16: 0 | Q16: 1.2 | R16: 0 | S16: 0 | T16: 1.25
A17: mardi | B17: 45489 | C17: 1 | D17: 1.1 | E17: 1 | F17: 1 | G17: 0 | H17: 0 | I17: 0 | J17: 0 | K17: 0 | L17: 1 | M17: 1 | N17: 0 | O17: 1.1 | P17: 0 | Q17: 1.1 | R17: 0 | S17: 0 | T17: 0 | U17: 18h
A18: mercredi | B18: 45490 | C18: 1 | D18: 1.2 | E18: 1 | F18: 1 | G18: 0 | H18: 0 | I18: 0 | J18: 1 | K18: 0 | L18: 1 | M18: 1 | N18: 0 | O18: 1 | P18: 0 | Q18: 0 | R18: 0 | S18: 0 | T18: 0
A19: jeudi | B19: 45491 | C19: 1 | D19: 1 | E19: 0 | F19: 1 | G19: 0 | H19: 0 | I19: 0 | J19: 1 | K19: 1 | L19: 1 | M19: 1 | N19: 0 | O19: 1.1 | P19: 0 | Q19: 0 | R19: 0 | S19: 0 | T19: 0
A20: vendredi | B20: 45492 | C20: 0 | D20: 2 | E20: 1 | F20: 0 | G20: 0 | H20: 0 | I20: 0 | J20: 1 | K20: 0 | L20: 1 | M20: 0 | N20: 0 | O20: 0 | P20: 0 | Q20: 0 | R20: 0 | S20: 0 | T20: 0
A21: samedi | B21: 45493 | C21: 0 | D21: 1.25 | E21: 1 | F21: 1.5 | G21: 0 | H21: 1.5 | I21: 0 | J21: 1.2 | K21: 0 | L21: 0 | M21: 0 | N21: 0 | O21: 1.5 | P21: 0 | Q21: 0 | R21: 1.5 | S21: 0 | T21: 0
A22: dimanche | B22: 45494 | C22: 0 | D22: 1 | E22: 1 | F22: 1 | G22: 0 | H22: 0.75 | I22: 0 | J22: 0 | K22: 1 | L22: 0 | M22: 1 | N22: 0 | O22: 1 | P22: 0 | Q22: 0 | R22: 1 | S22: 0 | T22: 1
A23: lundi | B23: 45495 | C23: 0 | D23: 1 | E23: 1 | F23: 1 | G23: 0 | H23: 0 | I23: 0 | J23: 1.2 | K23: 0 | L23: 0 | M23: 1 | N23: 0 | O23: 0 | P23: 0 | Q23: 0 | R23: 1 | S23: 1 | T23: 1
A24: mardi | B24: 45496 | C24: 0 | D24: 1 | E24: 0 | F24: 1 | G24: 0 | H24: 0 | I24: 0 | J24: 1.2 | K24: 1 | L24: 0 | M24: 1 | N24: 0 | O24: 1 | P24: 0 | Q24: 0 | R24: 1 | S24: 1 | T24: 1
A25: mercredi | B25: 45497 | C25: 0 | D25: 1 | E25: 1 | F25: 1 | G25: 0 | H25: 0 | I25: 0 | J25: 1 | K25: 0 | L25: 0 | M25: 1 | N25: 0 | O25: 1 | P25: 0 | Q25: 0 | R25: 1 | S25: 1 | T25: 0
A26: jeudi | B26: 45498 | C26: 0 | D26: 1.5 | E26: 1.5 | F26: 1.1 | G26: 0 | H26: 0 | I26: 0 | J26: 1.1 | K26: 0 | L26: 0 | M26: 1 | N26: 0 | O26: 1.5 | P26: 0 | Q26: 0 | R26: 1 | S26: 1 | T26: 0
A27: vendredi | B27: 45499 | C27: 0 | D27: 1 | E27: 1 | F27: 0 | G27: 0 | H27: 0 | I27: 0 | J27: 1 | K27: 0 | L27: 0 | M27: 0 | N27: 0 | O27: 1 | P27: 0 | Q27: 0 | R27: 0 | S27: 1 | T27: 0
A28: samedi | B28: 45500 | C28: 0 | D28: 1 | E28: 1 | F28: 1 | G28: 0 | H28: 0 | I28: 0 | J28: 1 | K28: 0 | L28: 0 | M28: 1 | N28: 0 | O28: 1.5 | P28: 0 | Q28: 0 | R28: 1 | S28: 0 | T28: 0
A29: dimanche | B29: 45501 | C29: 0 | D29: 1 | E29: 1 | F29: 1 | G29: 0 | H29: 1.5 | I29: 0 | J29: 1.2 | K29: 1 | L29: 0 | M29: 1 | N29: 0 | O29: 0 | P29: 0 | Q29: 0 | R29: 1 | S29: 1 | T29: 0
... A32: mercredi | B32: 45504 | C32: 0 | D32: 1 | E32: 1 | F32: 1 | G32: 0 | H32: 1.5 | I32: 0 | J32: 1 | K32: 1 | L32: 0 | M32: 1.2 | N32: 0 | O32: 1.5 | P32: 0 | Q32: 0 | R32: 1 | S32: 0.5 | T32: 0
C33: =SUM(C2:C32) -> 19.9 | D33: =SUM(D2:D32) -> 33.55 | E33: =SUM(E2:E32) -> 25.9 | F33: =SUM(F2:F32) -> 25.85 | G33: =SUM(G2:G32) -> 7.75 | H33: =SUM(H2:H32) -> 10.25 | I33: =SUM(I2:I32) -> 8 | J33: =SUM(J2:J32) -> 30.65 | ... T33: =SUM(T2:T32) -> 20.95
C34: 1333.33 | D34: 1481.481 | E34: 1111.11 | F34: 1111.11 | G34: 1333.33 | H34: 1500 | I34: 1037.037 | J34: 1111.11 | K34: 1200 | L34: 1111.11 | M34: 1037.037 | N34: 1111.11 | O34: 1111.11 | P34: 1111.11 | Q34: 1000 | R34: 1111.11 | S34: 1111.11 | T34: 1111.11
C35: =C33*C34 -> 26533.267 | D35: =D34*D33 -> 49703.688 | E35: =E34*E33 -> 28777.749 | F35: =F33*F34 -> 28722.194 | G35: =G33*G34 -> 10333.308 | H35: =H33*H34 -> 15375 | I35: =I33*I34 -> 8296.296 | J35: =J34*J33 -> 34055.522 | K35: =K34*K33 -> 15000 | L35: =L33*L34 -> 20277.757 | M35: =M33*M34 -> 28466.666 | N35: =N33*N34 -> 11388.878 | O35: =O33*O34 -> 31888.857 | P35: =P33*P34 -> 4444.44 | Q35: =Q34*Q33 -> 3500 | R35: =R34*R33 -> 12777.765 | S35: =S33*S34 -> 9444.435 | T35: =T33*T34 -> 23277.754 | U35: =SUM(#REF!) -> #REF!
C36: 36000 | D36: 40000 | E36: 30000 | F36: 30000 | G36: 36000 | I36: 28000 | J36: 30000 | L36: 30000 | M36: 28000 | N36: 30000 | O36: 30000 | P36: 30000 | T36: 30000

Sheet Les charges 
B2: Produit | C2: Quantité | D2: Prix unitaire | E2: Prix | F2: Date d'achat
B3: Semoule Fine 25kg | C3: 27 | D3: 1000 | E3: =C3*D3 -> 27000
B4: Livraison + manutention semoule | C4: 1 | D4: 1500 | E4: =C4*D4 -> 1500
B5: Semoule Moyenne Sahel 25kg | C5: 8 | D5: 1000 | E5: =C5*D5 -> 8000
B6: Khel | C6: 3 | D6: 85 | E6: =C6*D6 -> 255
B7: Maiis | C7: 2 | D7: 250 | E7: =C7*D7 -> 500
B8: Maa zehar zahia | C8: 4 | D8: 65 | E8: =C8*D8 -> 260
B9: sucre cristalisé | C9: 24 | D9: 95 | E9: =C9*D9 -> 2280
B10: Levure Boulongère 750g | C10: 6 | D10: 780 | E10: =C10*D10 -> 4680
B11: Fromage Bidon 4kg | C11: 3 | D11: 1300 | E11: =C11*D11 -> 3900
B12: Sucre Glace | C12: 14 | D12: 115 | E12: =C12*D12 -> 1610
B13: Coca canette | C13: 24 | D13: 70 | E13: =C13*D13 -> 1680
B14: Hamoude canette | C14: 24 | D14: 80 | E14: =C14*D14 -> 1920
... B77: 3akeri | C77: 1 | D77: 1500 | E77: =C77*D77 -> 1500
B78: Hamissa | C78: 1 | D78: 220 | E78: =C78*D78 -> 220 | F78: 45474
B79: viande morceaux | C79: 3 | D79: 400 | E79: =C79*D79 -> 1200
B80: cuisse de poulet | C80: 3 | D80: 150 | E80: =C80*D80 -> 450
B81: rechta | C81: 2 | D81: 100 | E81: =C81*D81 -> 200
B82: barquette | C82: 1 | D82: 80 | E82: =C82*D82 -> 80
B83: boite leben + livraison | C83: 1 | D83: 450 | E83: =C83*D83 -> 450
B84: Salade | C84: 1 | D84: 80 | E84: =C84*D84 -> 80
B85: bessel | C85: 20 | D85: 40 | E85: =C85*D85 -> 800
B86: légumes | C86: 1 | D86: 450 | E86: =C86*D86 -> 450
B87: Tomate conserve | C87: 3 | D87: 400 | E87: =C87*D87 -> 1200
B88: épice | C88: 2 | D88: 60 | E88: =C88*D88 -> 120
B89: isis | C89: 1 | D89: 180 | E89: =C89*D89 -> 180
B90: néttoyage vitres | C90: 1 | D90: 1000 | E90: =C90*D90 -> 1000
B91: réparation vitres | C91: 1 | D91: 3500 | E91: =C91*D91 -> 3500
B92: bessel | C92: 90 | D92: 40 | E92: =C92*D92 -> 3600 | F92: 45475
B93: tomate fraiche | C93: 4 | D93: 50 | E93: =C93*D93 -> 200
B94: légumes | C94: 1 | D94: 500 | E94: =C94*D94 -> 500
B95: rechta | C95: 10 | D95: 100 | E95: =C95*D95 -> 1000
B96: blanc de poulet | C96: 1.5 | D96: 800 | E96: =C96*D96 -> 1200
B97: poulet haché | C97: 4 | D97: 550 | E97: =C97*D97 -> 2200
B98: viande hachée | C98: 1 | D98: 1350 | E98: =C98*D98 -> 1350
B99: deyoul | C99: 2 | D99: 100 | E99: =C99*D99 -> 200
B100: eau de javel | C100: 1 | D100: 250 | E100: =C100*D100 -> 250
B101: omo | C101: 1 | D101: 250 | E101: =C101*D101 -> 250
B102: cuisse de poulet | C102: 14 | D102: 160 | E102: =C102*D102 -> 2240
B103: poulet haché | C103: 2 | D103: 550 | E103: =C103*D103 -> 1100
...

Sheet Les Salaires
I11: Nom | J11: Salaire | K11: Avance | L11: Salaire à payer
I12: Sofiane | J12: 30000 | K12: 30000 | L12: =J12-K12 -> 0 | M12: 13000+17000
I13: Amel | J13: 30000 | K13: 30000 | L13: =J13-K13 -> 0
H14: 1 | I14: Lynda | J14: =Pointage!C35 -> 26533.267 | K14: 27000 | L14: =J14-K14 -> -466.733
H15: 2 | I15: Hafida | J15: =Pointage!D35 -> 49703.688 | K15: 50000 | L15: =J15-K15 -> -296.31245
H16: 3 | I16: Yasmine Sidi Abd Allah | J16: =M16+N16 -> 38777.749 | K16: 39000 | L16: =J16-K16 -> -222.251 | M16: =Pointage!E35 -> 28777.749 | N16: 10000
H17: 4 | I17: Nawel | J17: =Pointage!F35 -> 28722.194 | K17: 29000 | L17: =J17-K17 -> -277.8065
H18: 5 | I18: Fouzia | J18: =Pointage!G35 -> 10333.308 | K18: 11000 | L18: =J18-K18 -> -666.6925
H19: 6 | I19: Nadjet | J19: =Pointage!H35 -> 15375 | K19: 15500 | L19: =J19-K19 -> -125 | M19: 1000+12000
H20: 7 | I20: Fatiha | J20: =Pointage!I35 -> 8296.296 | K20: 8500 | L20: =J20-K20 -> -203.704
H21: 8 | I21: Samira | J21: =Pointage!J35 -> 34055.522 | K21: 34000 | L21: =J21-K21 -> 55.5215 | M21: 1000+1000+1000
H22: 9 | I22: Zohra | J22: =Pointage!K35 -> 15000 | K22: 15000 | L22: =J22-K22 -> 0
H23: 10 | I23: Chiraz | J23: =Pointage!L35 -> 20277.757 | K23: 21000 | L23: =J23-K23 -> -722.2425
H24: 11 | I24: Yasmine | J24: =Pointage!T35 -> 23277.754 | K24: 23500 | L24: =J24-K24 -> -222.2455
H25: 12 | I25: Sarah | J25: =Pointage!M35 -> 28466.666 | K25: 29000 | L25: =J25-K25 -> -533.33435
H26: 13 | I26: Saliha | J26: =Pointage!N35 -> 11388.878 | K26: 11500 | L26: =J26-K26 -> -111.1225
H27: 14 | I27: Kenza | J27: =Pointage!S35 -> 9444.435 | K27: 9500 | L27: =J27-K27 -> -55.565
H28: 15 | I28: Nesrine | J28: =Pointage!R35 -> 12777.765 | K28: 13000 | L28: =J28-K28 -> -222.235
H29: 16 | I29: Fatima/ Insaf | J29: =Pointage!Q35 -> 3500 | K29: 3500 | L29: =J29-K29 -> 0
H30: 17 | I30: Romayessa | J30: =Pointage!O35 -> 31888.857 | K30: 32000 | L30: =J30-K30 -> -111.143
H31: 18 | I31: Mouna | J31: =Pointage!P35 -> 4444.44 | K31: 4500 | L31: =J31-K31 -> -55.56
I32: TOTAL | J32: =SUM(J12:J31) -> 432263.57 | K32: =SUM(K12:K31) -> 436500 | L32: =J32-K32 -> -4236.4258
L33: =J33-K33 -> 0

Sheet Feuille 4
E17: Mois de Janvier | F17: Mois de Février | G17: Mois de Mars | H17: Mois d'Avril | I17: Mois de Mai | J17: Mois de Jiun | K17: Mois de Juillet | N17: Mois de Juillet
D18: Recette | E18: 1756000 | F18: 2274000 | G18: 1984000 | H18: 1910000 | I18: 1342000 | J18: 1760000 | K18: =RECAP!D33 -> 2260000 | M18: Recette | N18: =K18 -> 2260000
D19: Charges | E19: 920000 | F19: 914000 | G19: 928000 | H19: 744000 | I19: 646000 | J19: 804000 | K19: =RECAP!E33 -> 957681 | M19: Charges | N19: 958000
D20: Salaires | E20: 349000 | F20: 410000 | G20: 406000 | H20: 344000 | I20: 436000 | J20: 396000 | K20: =RECAP!F33 -> 432263.57 | M20: Salaires | N20: 432000
D21: Loyer | E21: 140000 | F21: 140000 | G21: 140000 | H21: 140000 | I21: 140000 | J21: 140000 | K21: 150000 | M21: Loyer | N21: 150000
D22: Profit Net | E22: =E18-E19-E20-E21 -> 347000 | F22: =F18-F19-F20-F21 -> 810000 | G22: =G18-G19-G20-G21 -> 510000 | H22: 680000 | I22: =I18-I19-I20-I21 -> 120000 | J22: 420000 | K22: =K18-K19-K20-K21 -> 720055.43 | M22: Profit Net | N22: 720000

Sheet Feuille 5
G7: Date | H7: Nawel
F8: Lundi | G8: 45474 | H8: 1
F9: mardi | G9: 45475 | H9: 0
F10: mercredi | G10: 45476 | H10: 0
F11: jeudi | G11: 45477 | H11: 0
F12: vendredi | G12: 45478 | H12: 0
F13: samedi | G13: 45479 | H13: 1.25
F14: dimanche | G14: 45480 | H14: 1
F15: lundi | G15: 45481 | H15: 1
F16: mardi | G16: 45482 | H16: 1
F17: mercredi | G17: 45483 | H17: 1
F18: jeudi | G18: 45484 | H18: 1
F19: vendredi | G19: 45485 | H19: 0
... F38: mercredi | G38: 45504 | H38: 1
H39: =SUM(H8:H38) -> 25.85
H40: 1111.11
H41: =H39*H40 -> 28722.194
H42: 30000
