Workbook

Sheet RECAP
A1: 56 | B1: Date | C1: Recette de Janvier 2022 | D1: Recette | E1: Charges | F1: Salaire | G1: Loyer | H1: Net Profit | I1: Nb de jours | K1: Objectif | L1: Janvier | O1: Moyenne
A2: Mardi | B2: 44593 | C2: 40000 | D2: 30000 | I2: 1 | K2: 50000 | L2: 40000 | O2: =D30/I30 -> 48148.148
A3: Mercredi | B3: 44594 | C3: 36000 | D3: 50000 | I3: 1 | K3: 50000 | L3: 36000
A4: Jeudi | B4: 44595 | C4: 21000 | D4: 85000 | I4: 1 | K4: 50000 | L4: 21000 | O4: 50000
A5: Vendredi | B5: 44596 | C5: 26000 | D5: 0 | I5: 0 | K5: 0 | L5: 26000
A6: Samedi | B6: 44597 | C6: 60000 | D6: 33000 | I6: 1 | K6: 50000 | L6: 60000 | N6: ²
A7: Dimanche | B7: 44598 | C7: 9000 | D7: 38000 | I7: 1 | K7: 50000 | L7: 9000
A8: Lundi | B8: 44599 | C8: 39000 | D8: 31000 | I8: 1 | K8: 50000 | L8: 39000 | N8: Cash restant | O8: Magasin | P8: Sofane | Q8: Sifou | R8: caisse | S8: Pétrin
A9: Mardi | B9: 44600 | C9: 70000 | D9: 60000 | I9: 1 | K9: 50000 | L9: 70000 | N9: =D30-O9-E30-Salaires!K19 -> 662589 | O9: =P9+Q9+R9+S9 -> 118000 | P9: 35000 | R9: 8000 | S9: 75000 | T9: =SUM(T14) -> 0
A10: Mercredi | B10: 44601 | C10: 80000 | D10: 34000 | I10: 1 | K10: 50000 | L10: 80000
A11: Jeudi | B11: 44602 | C11: 120000 | D11: 103000 | I11: 1 | K11: 50000 | L11: 120000 | N11: Loyer | O11: 180000
A12: Vendredi | B12: 44603 | C12: 40000 | D12: 50000 | I12: 1 | K12: 50000 | L12: 40000 | N12: cash restant réel | O12: =D30+O11-O9-E30-Salaires!K19 -> 842589
A13: Samedi | B13: 44604 | C13: 46000 | D13: 39000 | I13: 1 | K13: 50000 | L13: 46000 | N13: charges Mars | O13: 160000
A14: Dimanche | B14: 44605 | C14: 27000 | D14: 50000 | I14: 1 | K14: 50000 | L14: 27000 | O14: =N9-O13 -> 502589
A15: Lundi | B15: 44606 | C15: 21000 | D15: 44000 | I15: 1 | K15: 50000 | L15: 21000
A16: Mardi | B16: 44607 | C16: 28000 | D16: 53000 | I16: 1 | K16: 50000 | L16: 28000
A17: Mercredi | B17: 44608 | C17: 30000 | D17: 50000 | I17: 1 | K17: 50000 | L17: 30000 | N17: Différence mois de Décembre
A18: Jeudi | B18: 44609 | C18: 24000 | D18: 55000 | I18: 1 | K18: 50000 | L18: 24000 | N18: =D30-C30 -> 249000
A19: Vendredi | B19: 44610 | C19: 50000 | D19: 40000 | I19: 1 | K19: 50000 | L19: 50000 | N19: Différence objectif
A20: Samedi | B20: 44611 | C20: 44000 | D20: 36000 | I20: 1 | K20: 50000 | L20: 44000 | N20: =D30-K30 -> 0
A21: Dimanche | B21: 44612 | C21: 27000 | D21: 25000 | I21: 1 | K21: 50000 | L21: 27000
A22: Lundi | B22: 44613 | C22: 30000 | D22: 50000 | I22: 1 | K22: 50000 | L22: 30000
A23: Mardi | B23: 44614 | C23: 42000 | D23: 45000 | I23: 1 | K23: 50000 | L23: 42000 | N23: Les vendredis
A24: Mercredi | B24: 44615 | C24: 50000 | D24: 58000 | I24: 1 | K24: 50000 | L24: 50000 | N24: =D12+D19+D26 -> 129000
A25: Jeudi | B25: 44616 | C25: 29000 | D25: 70000 | I25: 1 | K25: 50000 | L25: 29000
A26: Vendredi | B26: 44617 | C26: 32000 | D26: 39000 | I26: 1 | K26: 50000 | L26: 32000
A27: Samedi | B27: 44618 | C27: 30000 | D27: 36000 | I27: 1 | K27: 50000 | L27: 30000
A28: Dimanche | B28: 44619 | C28: 0 | D28: 40000 | I28: 1 | K28: 50000 | L28: 0
A29: Lundi | B29: 44620 | C29: 0 | D29: 56000 | I29: 1 | L29: 0
C30: =SUM(C2:C29) -> 1051000 | D30: =SUM(D2:D29) -> 1300000 | E30: ='Les charges'!F297 -> 462411 | F30: =Pointage!N32*1 -> 277581.12 | G30: 90000 | H30: =D30-G30-F30-E30 -> 470007.88 | I30: =SUM(I2:I29) -> 27 | K30: =SUM(K2:K29) -> 1300000 | L30: =SUM(L2:L29) -> 1051000
C32: Objectif | D32: 1350000 | E32: 500000 | F32: 304000 | G32: 90000 | H32: 456000
C33: Mois de Janvier | D33: 1051000 | E33: 435000 | F33: 226000 | G33: 90000 | H33: 300000

Sheet Les charges
C2: Produit | D2: Quantité | E2: Prix unitaire | F2: Prix | G2: Date d'achat
C3: Leuvre de Bièrre 500g la boite | D3: 10 boites de 500g | E3: 270.5 | F3: 2705 | G3: 44593
C4: chocolat à tartiner | D4: 1 bidon de 9kg/2kg | E4: 487 | F4: 974 | G4: 44593
C5: chocolat wedjedane blanc | D5: 3 boites de 250g | E5: 225 | F5: 675 | G5: 44593
C6: chocolat wedjedane noir | D6: 4 boites de 250g | E6: 145 | F6: 580 | G6: 44593
C7: chocolat wedjedane noisette | D7: 3 boites de 250g | E7: 245 | F7: 735 | G7: 44593
C8: Chocolat wedjdane au lait | D8: 7 boites de 250 | E8: 210 | F8: 1470 | G8: 44593
C9: miel Nounours 5kg | D9: 6 | E9: 740 | F9: 4440 | G9: 44593
C10: Fromage slices cheezy | D10: 18 | E10: 130 | F10: 2340 | G10: 44593
C11: boites demie plateau | D11: 5 | E11: / | F11: 700 | G11: 44593
C12: Bessel | D12: 60kg | E12: 45 | F12: 2700 | G12: 44593
C13: transport marchandise | D13: 1 | E13: 800 | F13: 800 | G13: 44593
C14: Semoule Safina 10kg | D14: 12 | E14: 425 | F14: 5100 | G14: 44593
C15: Semoule Moyenne SIM 2kg*6/Fardeau | D15: 7 | E15: 145 | F15: 1015 | G15: 44562
C16: Semen Madina 1,8kg | D16: 8 boites | E16: 643 | F16: 5144 | G16: 44562
C17: Levure Chimique 100 Sachets /Boite | D17: 2 boites | E17: 375 | F17: 750 | G17: 44562
C18: Semoule SIM myenne 25kg | D18: 3 sachets | E18: 1000 | F18: 3000 | G18: 44562
C19: semoule Amor Ben Amor 25kg | D19: 23 | E19: 1350 | F19: 31050 | G19: 44593
C20: Harrissa SIM 1kg 12kg/carton | D20: 23 | E20: 175 | F20: 4025 | G20: 44593
C21: Tomate conserve Dahra 1kg | D21: 3 fardeaux de 12 boites | E21: 175 | F21: 6300 | G21: 44593
C22: semoule Mama Fine 2 kg | D22: 14 fardeaux | E22: 1200 | F22: 16800 | G22: 44593
C23: semoule Mama Fine 2 kg | D23: 2 | E23: 1500 | F23: 3000 | G23: 44593
C24: Huile Elio 5 litres | D24: 55 bidons | E24: 580 | F24: 31900 | G24: 44593
C25: huile elio 2 litres | D25: 2 fardeaux | E25: 1416 | F25: 2832 | G25: 44593
C26: Jus Rouiba 33cl | D26: 5 fardeaux de 12 | E26: 430 | F26: 2150 | G26: 44593
C27: Slim Hamoud 33cl | D27: 9 fardeaux de 12 | E27: 450 | F27: 4050 | G27: 6692006
C28: Coca 33cl | D28: 1 fardeau | E28: 540 | F28: 540 | G28: 44593
C29: Jus Rouiba 20cl | D29: 2 fardeaux de 24 | E29: 530 | F29: 1060 | G29: 44593
C30: Merinda 33cl | D30: 1 fardeau de 12 | E30: 390 | F30: 390 | G30: 44593
C31: Candia twist | D31: 1 | E31: 570 | F31: 570 | G31: 44593
C32: Farine SIM 1kg | D32: 3 fardeaux de 9kg | E32: 620 | F32: 2160 | G32: 44593
C33: Maa zehar | D33: 40 | E33: 55 | F33: 2200 | G33: 44593
C34: Sac croissant 24 | D34: 1 fardeaux de 500 | E34: 650 | F34: 650 | G34: 44593
C35: sac croissant 14 | D35: 1 fardeaux de 1000 | E35: 850 | F35: 850 | G35: 44593
C36: boites 48/10 | D36: 1 carton de 50 | E36: 2350 | F36: 2350 | G36: 44593
C37: Boite 36/10 | D37: 1 carton de 50 | E37: 1700 | F37: 1700 | G37: 44593
C38: Boite 36/07 | D38: 1 carton de 50 | E38: 1550 | F38: 1550 | G38: 44593
C39: sachets croissant 23 | D39: 2 | E39: 170 | F39: 340 | G39: 44593
C40: oeufs | D40: 2 plateaux | E40: 450 | F40: 900 | G40: 44593
C41: curdent | D41: 1 fardeau | E41: 300 | F41: 300 | G41: 44593
...

Sheet Pointage
B1: Date | C1: Zehor | D1: Soumia | E1: Nadjet | F1: Hadjer | G1: Amel | H1: Marwa | I1: djamila | J1: Houda | K1: Faiza | L1: Hafidha | M1: Zahida
A2: Mardi | B2: 44593 | C2: 1 | D2: 1 | E2: 1 | F2: 0 | G2: 1 | H2: 1 | I2: 1 | J2: 1 | K2: 1 | L2: 1 | M2: 1 | N2: elyoum il y'avait pas de travaille donc 9a3edou yeguesserou
A3: Mercredi | B3: 44594 | C3: 1 | D3: 1 | E3: 0 | F3: 1 | G3: 1 | H3: 0 | I3: 1 | J3: 1 | K3: 1 | L3: 0 | M3: 0 | N3: Houda et Soumia dakhelou à 09h les autres khademou normal
A4: Jeudi | B4: 44595 | C4: 0 | D4: 1 | E4: 1 | F4: 0 | G4: 0 | H4: 1 | I4: 0 | J4: 1 | K4: 1 | L4: 1.5 | M4: 1.0625 | N4: Hafida et zahida kharedjou à 18h
A5: Vendredi | B5: 44596 | C5: 0 | D5: 0 | E5: 0 | F5: 0 | G5: 0 | H5: 0 | I5: 0 | J5: 0 | K5: 0 | L5: 0 | M5: 0
A6: Samedi | B6: 44597 | C6: 1 | D6: 1 | E6: 0 | F6: 1 | G6: 1 | H6: 1 | I6: 0 | J6: 1 | K6: 1 | L6: 0 | M6: 0
A7: Dimanche | B7: 44598 | C7: 0 | D7: 1 | E7: 1 | F7: 0 | G7: 1 | H7: 0 | I7: 1 | J7: 1 | K7: 1 | L7: 1 | M7: 1 | N7: le matin il y'avait pas elkhadema aprés l'après-midi djate une commade de 8200da et mechate el7ala chewia
A8: Lundi | B8: 44599 | C8: 1 | D8: 1 | E8: 0 | F8: 1 | G8: 1 | H8: 0 | I8: 1 | J8: 1 | K8: 1 | L8: 0 | M8: 0.5 | N8: zahida a remplacé Faiza puisque 3anedeha dentiste
A9: Mardi | B9: 44600 | C9: 0 | D9: 1 | E9: 1 | F9: 0 | G9: 1 | H9: 1 | I9: 0 | J9: 1 | K9: 1 | L9: 1 | M9: 1 | N9: Hafida 3adjenet elyoum be yedeha , zahida khaliteha tekhredj à 16h
A10: Mercredi | B10: 44601 | C10: 1 | D10: 1 | E10: 0 | F10: 1 | G10: 1 | H10: 1 | I10: 0 | J10: 1 | K10: 1 | L10: 0 | M10: 1 | N10: Hadjer djate en retard autorisée
A11: Jeudi | B11: 44602 | C11: 1 | D11: 1 | E11: 1 | F11: 0 | G11: 1 | H11: 0 | I11: 1 | J11: 1 | K11: 1 | L11: 1 | M11: 1 | N11: Houda kharedjet à 14h30 , hadjer djate 3awenetena chewia à la fin
A12: Vendredi | B12: 44603 | C12: 1 | D12: 0 | E12: 0 | F12: 1 | G12: 1.5 | H12: 0 | I12: 0 | J12: 0 | K12: 1 | L12: 0 | M12: 1 | N12: djaw we ra7ou bekeri vers 15h30
A13: Samedi | B13: 44604 | C13: 1 | D13: 1 | E13: 0 | F13: 1 | G13: 1 | H13: 0 | I13: 1 | J13: 0 | K13: 1 | L13: 1 | M13: 1
A14: Dimanche | B14: 44605 | C14: 0 | D14: 1 | E14: 0 | F14: 1 | G14: 1 | H14: 0 | I14: 1 | J14: 1 | K14: 1 | L14: 1 | M14: 1
A15: Lundi | B15: 44606 | C15: 1 | D15: 1 | E15: 0 | F15: 1 | G15: 1 | H15: 0 | I15: 1 | J15: 1 | K15: 1 | L15: 1 | M15: 0
A16: Mardi | B16: 44607 | C16: 1 | D16: 1 | E16: 1 | F16: 0 | G16: 1 | H16: 1 | I16: 0 | J16: 1 | K16: 1 | L16: 1 | M16: 1
A17: Mercredi | B17: 44608 | C17: 1 | D17: 0 | E17: 1 | F17: 1 | G17: 1 | H17: 1 | I17: 0 | J17: 1 | K17: 1 | L17: 1 | M17: 0
A18: Jeudi | B18: 44609 | C18: 1 | D18: 0 | E18: 1 | F18: 1 | G18: 1 | H18: 1 | I18: 0 | J18: 1 | K18: 1 | L18: 1 | M18: 1
A19: Vendredi | B19: 44610 | C19: 1 | D19: 0 | E19: 0 | F19: 0 | G19: 0 | H19: 0 | I19: 0 | J19: 0 | K19: 1 | L19: 1 | M19: 1 | N19: Hafida a lavé la vaissel la veille 7assebetehaleha 1 journée
A20: Samedi | B20: 44611 | C20: 1 | D20: 0 | E20: 1 | F20: 0 | G20: 1 | H20: 1 | I20: 0 | J20: 1 | K20: 0 | L20: 1.5 | M20: 1
A21: Dimanche | B21: 44612 | C21: 1 | D21: 1 | E21: 1 | F21: 1 | G21: 0 | H21: 0 | I21: 0 | J21: 1 | K21: 1 | L21: 1 | M21: 1
A22: Lundi | B22: 44613 | C22: 0 | D22: 1 | E22: 1 | F22: 1 | G22: 1 | H22: 1 | I22: 0 | J22: 1 | K22: 1 | L22: 1.5 | M22: 1 | N22: zahida djate à 10h kharedjet à 16h
A23: Mardi | B23: 44614 | C23: 1 | D23: 1 | E23: 1 | F23: 1 | G23: 1 | H23: 1 | I23: 0 | J23: 1 | K23: 1 | L23: 1 | M23: 1 | N23: Hadjer khademet me3a houda et Soumeya . ces 2 derniers kharedjou à 17h. zehor kharedjet à 15h pr abderrahmane
A24: Mercredi | B24: 44615 | C24: 1 | D24: 1 | E24: 1 | F24: 1 | G24: 1 | H24: 0 | I24: 1 | J24: 1 | K24: 1 | L24: 1 | M24: 1
A25: Jeudi | B25: 44616 | C25: 1 | D25: 1 | E25: 1 | F25: 1 | G25: 1 | H25: 0 | I25: 1 | J25: 1 | K25: 1 | L25: 1 | M25: 1
A26: Vendredi | B26: 44617 | C26: 1 | D26: 0 | E26: 0 | F26: 1 | G26: 1.5 | H26: 0 | I26: 0 | J26: 0 | K26: 1 | L26: 0 | M26: 1
A27: Samedi | B27: 44618 | C27: 1 | D27: 1 | E27: 1 | F27: 1 | G27: 1 | H27: 0 | I27: 1 | J27: 1 | K27: 1 | L27: 1 | M27: 1 | N27: Zehor djate men rasseha malgré 9ouletelha ma tedjich+ il y'avait pas beacoup de travail
A28: Dimanche | B28: 44619 | C28: 1 | D28: 1 | E28: 1 | F28: 1 | G28: 1 | H28: 0 | I28: 1 | J28: 1 | K28: 1 | L28: 1 | M28: 1 | N28: zehor kharedjet à 15h30 puisque kanet chetaa et makach khadema
A29: Lundi | B29: 44620 | C29: 1 | D29: 1 | E29: 1 | F29: 0 | G29: 1 | H29: 0 | I29: 1 | J29: 1 | K29: 1 | L29: 1 | M29: 0 | N29: zahida et hadjer sont absente
C30: =SUM(C2:C29) -> 22 | D30: =SUM(D2:D29) -> 21 | E30: =SUM(E2:E29) -> 17 | F30: =SUM(F2:F29) -> 18 | G30: =SUM(G2:G29) -> 25 | H30: =SUM(H2:H29) -> 11 | I30: =SUM(I2:I29) -> 13 | J30: =SUM(J2:J29) -> 23 | ... M30: =SUM(M2:M29) -> 21.5625
C31: 2083 | D31: 1041 | E31: 1250 | F31: 1250 | G31: 1250 | H31: 1000 | I31: 1000 | J31: 1250 | K31: 1041 | L31: 1250 | M31: 1250
C32: =C31*C30 -> 45826 | D32: =D31*D30 -> 21861 | E32: =E31*E30 -> 21250 | F32: =F31*F30 -> 22500 | G32: =G31*G30 -> 31250 | H32: =H31*H30 -> 11000 | I32: =I31*I30 -> 13000 | J32: =J31*J30 -> 28750 | ... L32: =L31*L30 -> 28125 | M32: =M30*M31 -> 26953.125 | N32: =SUM(C32:M32) -> 277581.12

Sheet Salaires
I7: Nom | J7: Salaire | K7: Avance | L7: Salaire à payer
H8: 1 | I8: Zehor | J8: =Pointage!C32*1 -> 45826 | K8: 4000 | L8: =J8-K8 -> 41826 | M8: 2000+2000
H9: 3 | I9: Soumia | J9: =Pointage!D32*1 -> 21861 | K9: 2000 | L9: =J9-K9 -> 19861
H10: 4 | I10: Amel | J10: =Pointage!G32*1 -> 31250 | K10: 27000 | L10: =J10-K10 -> 4250 | M10: 1000+9000+1000+8000+8000
H11: 5 | I11: Marwa | J11: =Pointage!H32*1 -> 11000 | L11: =J11-K11 -> 11000
H12: 6 | I12: Djamila | J12: =Pointage!I32*1 -> 13000 | L12: =J12-K12 -> 13000
H13: 7 | I13: Nadjet | J13: =Pointage!E32*1 -> 21250 | L13: =J13-K13 -> 21250
H14: 8 | I14: Hadjer | J14: =Pointage!F32*1 -> 22500 | L14: =J14-K14 -> 22500
H15: 9 | I15: Houda | J15: =Pointage!J32*1 -> 28750 | L15: =J15-K15 -> 28750
H16: 10 | I16: Faiza | J16: =Pointage!K32*1 -> 27066 | L16: =J16-K16 -> 27066
H17: 11 | I17: Hafida | J17: =Pointage!L32*1 -> 28125 | K17: 24000 | L17: =J17-K17 -> 4125 | M17: 10000+2000+5000+1000+6000
H18: 12 | I18: Zahida | J18: =Pointage!M32*1 -> 26953.125 | L18: =J18-K18 -> 26953.125
I19: TOTAL | J19: =SUM(J8:J18) -> 277581.12 | K19: =SUM(K8:K18) -> 57000 | L19: =SUM(L8:L18) -> 220581.12
I20: =J19-K19 -> 220581.12 | L20: =J20-K20 -> 0

Sheet Amel
A1: Date | B1: Messemen | C1: Messemen petit | D1: Mehadjeb | E1: Metakba | F1: Bradj makela | G1: Bradj | H1: chakhechoukha | I1: Plat chakhechoukha | J1: Plat rechta demie cuisse | K1: Plat rechta | L1: Galletes farcies F | M1: Galletes Farcies S | N1: Galletes simple | O1: Galletes grains | P1: Galletes aux herebes | Q1: Makrout | R1: Mekirets | S1: Hamiss | T1: Zeviti
A2: 44593 | B2: 0 | C2: 0 | D2: 14 | E2: 0 | F2: 0 | G2: 85 | H2: 0 | I2: 0 | J2: 0 | K2: 0 | L2: 4 | M2: 3 | N2: 9 | O2: 6 | P2: 0 | Q2: 35 | R2: 0 | S2: 0 | T2: 0
A3: 44594 | B3: 5 | C3: 0 | D3: 40 | E3: 0 | F3: 0 | G3: 0 | H3: 4 | I3: 5 | J3: 0 | K3: 4 | L3: 0 | M3: 0 | N3: 7 | O3: 6 | P3: 0 | Q3: 0 | R3: 0 | S3: 0 | T3: 0
A4: 44595 | B4: 0 | C4: 0 | D4: 0 | E4: 0 | F4: 0 | G4: 0 | H4: 0 | I4: 0 | J4: 0 | K4: 0 | L4: 0 | M4: 0 | N4: 0 | O4: 0 | P4: 0 | Q4: 0 | R4: 0 | S4: 0 | T4: 0
A5: 44596 | B5: 0 | C5: 0 | D5: 0 | E5: 0 | F5: 0 | G5: 0 | H5: 0 | I5: 0 | J5: 0 | K5: 0 | L5: 0 | M5: 0 | N5: 0 | O5: 0 | P5: 0 | Q5: 0 | R5: 0 | S5: 0 | T5: 0
A6: 44597 | B6: 0 | C6: 0 | D6: 20 | E6: 0 | F6: 0 | G6: 89 | H6: 3 | I6: 0 | J6: 0 | K6: 0 | L6: 3 | M6: 2 | N6: 7 | O6: 11 | P6: 5 | Q6: 0 | R6: 0 | S6: 0 | T6: 0
A7: 44598 | B7: 0 | C7: 25 | D7: 38 | E7: 0 | F7: 0 | G7: 0 | H7: 0 | I7: 0 | J7: 0 | K7: 0 | L7: 0 | M7: 0 | N7: 7 | O7: 7 | P7: 0 | Q7: 55 | R7: 0 | S7: 0 | T7: 0
A8: 44599 | B8: 0 | C8: 0 | D8: 38 | E8: 0 | F8: 0 | G8: 0 | H8: 0.5 | I8: 0 | J8: 0 | K8: 0 | L8: 2 | M8: 2 | N8: 7 | O8: 7 | P8: 5 | Q8: 0 | R8: 0 | S8: 0 | T8: 0
A9: 44600 | B9: 0 | C9: 0 | D9: 0 | E9: 0 | F9: 35 | G9: 90 | H9: 0 | I9: 0 | J9: 0 | K9: 0 | L9: 5 | M9: 0 | N9: 4 | O9: 4 | P9: 0 | Q9: 0 | R9: 0 | S9: 0 | T9: 0
A10: 44601 | B10: 0 | C10: 0 | D10: 25 | E10: 0 | F10: 0 | G10: 97 | H10: 4.5 | I10: 0 | J10: 0 | K10: 0 | L10: 4 | M10: 0 | N10: 4 | O10: 5 | P10: 4 | Q10: 0 | R10: 0 | S10: 0 | T10: 0
A11: 44602
A12: 44603 | B12: 0 | C12: 0 | D12: 0 | E12: 0 | F12: 0 | G12: 100 | H12: 0 | I12: 12 | J12: 4 | K12: 0 | L12: 0 | M12: 0 | N12: 0 | O12: 0 | P12: 0 | Q12: 0 | R12: 0 | S12: 0 | T12: 0
A13: 44604 | B13: 0 | C13: 0 | D13: 0 | E13: 0 | F13: 0 | G13: 96 | H13: 0 | I13: 0 | J13: 0 | K13: 0 | L13: 0 | M13: 0 | N13: 6 | O13: 6 | P13: 0 | Q13: 0 | R13: 5 | S13: 0 | T13: 0
A14: 44605 | B14: 20 | C14: 0 | D14: 45 | E14: 0 | F14: 0 | G14: 0 | H14: 2.5 | I14: 0 | J14: 0 | K14: 0 | L14: 0 | M14: 8 | N14: 7 | O14: 5 | P14: 0 | Q14: 0 | R14: 0 | S14: 0 | T14: 0
A15: 44606
A16: 44607
A17: 44608
A18: 44609
A19: 44610
A20: 44611
A21: 44612
A22: 44613
A23: 44614
A24: 44615
A25: 44616
A26: 44617
... A29: 44620
B30: =SUM(B2:B29) -> 25 | C30: =SUM(C2:C29) -> 25 | D30: =SUM(D2:D29) -> 220 | E30: =SUM(E2:E29) -> 0 | F30: =SUM(F2:F29) -> 35 | G30: =SUM(G2:G29) -> 557 | H30: =SUM(H2:H29) -> 14.5 | I30: 2 | J30: =SUM(J2:J29) -> 4 | K30: =SUM(K2:K29) -> 4 | L30: =SUM(L2:L29) -> 18 | M30: =SUM(M2:M29) -> 15 | N30: =SUM(N2:N29) -> 58 | O30: =SUM(O2:O29) -> 57 | P30: =SUM(P2:P29) -> 14 | Q30: =SUM(Q2:Q29) -> 90 | ... T30: =SUM(T2:T29) -> 0
B31: 70 | C31: 50 | D31: 100 | E31: 50 | F31: 70 | G31: 60 | H31: 400 | I31: 1100 | J31: 800 | K31: 1100 | L31: 250 | M31: 200 | N31: 80 | O31: 100 | P31: 150 | Q31: 150 | R31: 500 | S31: 500 | T31: 500
B32: =B31*B30 -> 1750 | C32: =C31*C30 -> 1250 | D32: =D31*D30 -> 22000 | E32: =E31*E30 -> 0 | F32: =F31*F30 -> 2450 | G32: =G31*G30 -> 33420 | H32: =H31*H30 -> 5800 | I32: =I31*I30 -> 2200 | K32: =K31*K30 -> 4400 | L32: =L31*L30 -> 4500 | M32: =M31*M30 -> 3000 | N32: =N31*N30 -> 4640 | O32: =O31*O30 -> 5700 | P32: =P31*P30 -> 2100 | Q32: =Q31*Q30 -> 13500 | R32: =R31*R30 -> 2500 | ... T32: =T31*T30 -> 0 | U32: =SUM(B32:T32) -> 109210

Sheet Zehor
A1: Date | B1: Messemen | C1: Mehadjeb | D1: khefaf | E1: kefaf petit | F1: chakhechoukha | G1: la pate
A2: 44593 | B2: 30 | C2: 14 | D2: 112 | E2: 0 | F2: 0 | G2: 0
A3: 44594 | B3: 30 | C3: 0 | D3: 120 | E3: 0 | F3: 0 | G3: 3
A4: 44595 | B4: 0 | C4: 0 | D4: 0 | E4: 0 | F4: 0 | G4: 0
A5: 44596 | B5: 0 | C5: 0 | D5: 0 | E5: 0 | F5: 0 | G5: 0
A6: 44597 | B6: 10 | C6: 10 | D6: 84 | E6: 20 | F6: 2 | G6: 3
A7: 44598 | B7: 0 | C7: 0 | D7: 0 | E7: 0 | F7: 0 | G7: 0
A8: 44599 | B8: 25 | C8: 20 | D8: 44 | E8: 12 | F8: 0.5 | G8: 4
A9: 44600 | B9: 0 | C9: 0 | D9: 0 | E9: 0 | F9: 0 | G9: 0
A10: 44601 | B10: 55 | C10: 0 | D10: 98 | E10: 20 | F10: 0 | G10: 3
A11: 44602 | B11: 0 | C11: 0 | D11: 88 | E11: 20 | F11: 0 | G11: 4
A12: 44603 | B12: 0 | C12: 0 | D12: 80 | E12: 15 | F12: 0 | G12: 4
A13: 44604 | B13: 0 | C13: 0 | D13: 101 | E13: 0 | F13: 0 | G13: 4
A14: 44605 | B14: 0 | C14: 0 | D14: 0 | E14: 0 | F14: 0 | G14: 0
A15: 44606
A16: 44607
A17: 44608
A18: 44609
A19: 44610
A20: 44611
A21: 44612
A22: 44613
A23: 44614
A24: 44615
A25: 44616
A26: 44617
... A29: 44620
A30: Totale | B30: =SUM(B2:B29) -> 150 | C30: =SUM(C2:C29) -> 44 | D30: =SUM(D2:D29) -> 727 | E30: =SUM(E2:E29) -> 87 | F30: =SUM(F2:F29) -> 2.5 | G30: =SUM(G2:G29) -> 25
B31: 70 | C31: 100 | D31: 50 | E31: 40 | F31: 400
B32: =B30*B31 -> 10500 | C32: =C30*C31 -> 4400 | D32: =D30*D31 -> 36350 | E32: =E30*E31 -> 3480 | F32: =F30*F31 -> 1000 | H32: =SUM(B32:G32) -> 55730

Sheet Zahida
A1: Date | B1: Messemen | C1: Messemen Petit | D1: Mehadjeb | E1: Mehadjeb p | F1: Bradj petit | G1: Bradj | H1: chakhechoukha | I1: Les Boules G | J1: Les Boules P
A2: 44593 | B2: 0 | C2: 0 | D2: 0 | E2: 0 | F2: 0 | G2: 0 | H2: 0 | I2: 0 | J2: 0
A3: 44594 | B3: 0 | C3: 0 | D3: 0 | E3: 0 | F3: 0 | G3: 0 | H3: 0 | I3: 0 | J3: 0
A4: 44595 | B4: 4 | C4: 0 | D4: 75 | E4: 0 | F4: 120 | G4: 45 | H4: 25 | I4: 25 | J4: 90
A5: 44596 | B5: 0 | C5: 0 | D5: 0 | E5: 0 | F5: 0 | G5: 0 | H5: 0 | I5: 0 | J5: 0
A6: 44597 | B6: 0 | C6: 0 | D6: 0 | E6: 0 | F6: 0 | G6: 0 | H6: 0 | I6: 0 | J6: 0
A7: 44598 | B7: 20 | C7: 0 | D7: 90 | E7: 0 | F7: 0 | G7: 0 | H7: 3 | I7: 157 | J7: 0
A8: 44599 | B8: 0 | C8: 0 | D8: 0 | E8: 0 | F8: 0 | G8: 0 | H8: 0 | I8: 0 | J8: 0
A9: 44600 | B9: 0 | C9: 20 | D9: 95 | E9: 0 | F9: 0 | G9: 0 | H9: 3.5 | I9: 94 | J9: 0
A10: 44601 | B10: 0 | C10: 0 | D10: 0 | E10: 0 | F10: 0 | G10: 0 | H10: 0 | I10: 0 | J10: 0
A11: 44602 | E11: 0
A12: 44603 | B12: 0 | C12: 150 | D12: 22 | E12: 15 | F12: 0 | G12: 0 | H12: 8.5 | I12: 60 | J12: 198
A13: 44604 | B13: 5 | C13: 0 | D13: 47 | E13: 0 | F13: 0 | G13: 0 | H13: 12 | I13: 0 | J13: 128
A14: 44605 | B14: 45 | C14: 0 | D14: 104 | E14: 0 | F14: 0 | G14: 0 | H14: 2.5 | I14: 0 | J14: 0 | K14: kan kayen messemen ta3 la veille elle les a rajoter
A15: 44606
A16: 44607
A17: 44608
A18: 44609
A19: 44610
A20: 44611
A21: 44612
A22: 44613
A23: 44614
A24: 44615
A25: 44616
A26: 44617
... A29: 44620
B30: =SUM(B2:B29) -> 74 | C30: =SUM(C2:C29) -> 170 | D30: =SUM(D2:D29) -> 433 | F30: =SUM(F2:F29) -> 120 | G30: =SUM(G2:G29) -> 45 | H30: =SUM(H2:H29) -> 54.5 | I30: =SUM(I2:I29) -> 336 | J30: =SUM(J2:J29) -> 416
B31: 70 | C31: 50 | D31: 100 | F31: 30 | G31: 60 | H31: 400
B32: =B31*B29 -> 0 | C32: =C31*C30 -> 8500 | D32: =D31*D30 -> 43300 | F32: =F31*F30 -> 3600 | G32: =G31*G30 -> 2700 | H32: =H31*H30 -> 21800 | K32: =SUM(B32:J32) -> 79900

Sheet Hafida
A1: Date | B1: Messemen | C1: Mehadjeb | D1: khefaf | E1: khefaf petit | F1: Metelou3 | G1: chakhechoukha | H1: Chewat | I1: la pate | J1: Galettes simple | K1: Galletes aux grains | L1: Galletes Farcies F | M1: Galletes Farcies S | N1: Galletes aux herbes | O1: Zeviti
A2: 44593 | B2: 10 | C2: 10 | D2: 0 | E2: 0 | F2: 0 | G2: 5 | H2: 0 | I2: 3 | J2: 0 | K2: 0 | L2: 0 | M2: 0 | N2: 0 | O2: 0
A3: 44594 | B3: 0 | C3: 0 | D3: 0 | E3: 0 | F3: 0 | G3: 0 | H3: 0 | I3: 0 | J3: 0 | K3: 0 | L3: 0 | M3: 0 | N3: 0 | O3: 0
A4: 44595 | B4: 20 | C4: 0 | D4: 80 | E4: 0 | F4: 3 | G4: 5 | H4: 0 | I4: 5 | J4: 5 | K4: 4 | L4: 0 | M4: 0 | N4: 0 | O4: 0
A5: 44596 | B5: 0 | C5: 0 | D5: 0 | E5: 0 | F5: 0 | G5: 0 | H5: 0 | I5: 0 | J5: 0 | K5: 0 | L5: 0 | M5: 0 | N5: 0 | O5: 0
A6: 44597 | B6: 0 | C6: 0 | D6: 0 | E6: 0 | F6: 0 | G6: 0 | H6: 0 | I6: 0 | J6: 0 | K6: 0 | L6: 0 | M6: 0 | N6: 0 | O6: 0
A7: 44598 | B7: 25 | C7: 0 | D7: 43 | E7: 0 | F7: 0 | G7: 0 | H7: 2 | I7: 3 | J7: 0 | K7: 0 | L7: 0 | M7: 0 | N7: 0 | O7: 0
A8: 44599 | B8: 0 | C8: 0 | D8: 0 | E8: 0 | F8: 0 | G8: 0 | H8: 0 | I8: 0 | J8: 0 | K8: 0 | L8: 0 | M8: 0 | N8: 0 | O8: 0
A9: 44600 | B9: 0 | C9: 0 | D9: 50 | E9: 35 | F9: 0 | G9: 0 | H9: 0 | I9: 4 | J9: 0 | K9: 0 | L9: 0 | M9: 0 | N9: 0 | O9: 0
A10: 44601 | B10: 0 | C10: 0 | D10: 0 | E10: 0 | F10: 0 | G10: 0 | H10: 0 | I10: 0 | J10: 0 | K10: 0 | L10: 0 | M10: 0 | N10: 0 | O10: 0
A11: 44602
A12: 44603 | B12: 0 | C12: 0 | D12: 0 | E12: 0 | F12: 0 | G12: 0 | H12: 0 | I12: 0 | J12: 0 | K12: 0 | L12: 0 | M12: 0 | N12: 0 | O12: 0
A13: 44604 | B13: 0 | C13: 0 | D13: 0 | E13: 0 | F13: 0 | G13: 0 | H13: 0 | I13: 0 | J13: 0 | K13: 0 | L13: 0 | M13: 0 | N13: 0 | O13: 0
A14: 44605 | B14: 62 | C14: 10 | D14: 70 | E14: 0 | F14: 0 | G14: 0 | H14: 0 | I14: 4 | J14: 0 | K14: 0 | L14: 0 | M14: 0 | N14: 0 | O14: 0
A15: 44606
A16: 44607
A17: 44608
A18: 44609
A19: 44610
A20: 44611
A21: 44612
A22: 44613
A23: 44614
A24: 44615
A25: 44616
A26: 44617
... A29: 44620
B30: =SUM(B2:B29) -> 117 | C30: =SUM(C2:C29) -> 20 | D30: =SUM(D2:D29) -> 243 | E30: =SUM(E2:E29) -> 35 | F30: =SUM(F2:F29) -> 3 | G30: =SUM(G2:G29) -> 10 | H30: =SUM(H2:H29) -> 2 | I30: =SUM(I2:I29) -> 19 | ... O30: =SUM(O2:O29) -> 0
B31: 70 | C31: 100 | D31: 70 | E31: 40 | F31: 120 | G31: 400 | H31: 600 | J31: 80 | K31: 100 | L31: 250 | M31: 200 | N31: 150 | O31: 500
B32: =B31*B30 -> 8190 | C32: =C31*C30 -> 2000 | D32: =D31*D30 -> 17010 | E32: =E31*E30 -> 1400 | F32: =F31*F30 -> 360 | G32: =G31*G30 -> 4000 | H32: =H31*H30 -> 1200 | I32: =I31*I30 -> 0 | ... O32: =O31*O30 -> 0 | P32: =SUM(B32:O32) -> 34960

Sheet Nadjet
A1: Date | B1: Messemen | C1: Messemen P | D1: Mehadjeb | E1: chakhechoukha | F1: Les boules G | G1: Les boules p
A2: 44593 | B2: 0 | C2: 0 | D2: 65 | E2: 0 | F2: 0 | G2: 0
A3: 44594 | B3: 0 | C3: 0 | D3: 0 | E3: 0 | F3: 0 | G3: 0
A4: 44595 | B4: 110 | C4: 40 | D4: 4 | E4: 15 | F4: 0 | G4: 90
A5: 44596 | B5: 0 | C5: 0 | D5: 0 | E5: 0 | F5: 0 | G5: 0
A6: 44597 | B6: 0 | C6: 0 | D6: 0 | E6: 0 | F6: 0 | G6: 0
A7: 44598 | B7: 40 | C7: 0 | D7: 0 | E7: 1 | F7: 0 | G7: 0
A8: 44599 | B8: 0 | C8: 0 | D8: 0 | E8: 0 | F8: 0 | G8: 0
A9: 44600 | B9: 40 | C9: 0 | D9: 37 | E9: 3.5 | F9: 0 | G9: 0
A10: 44601 | B10: 0 | C10: 0 | D10: 0 | E10: 0 | F10: 0 | G10: 0
A11: 44602
A12: 44603 | B12: 0 | C12: 0 | D12: 0 | E12: 0 | F12: 0 | G12: 0
A13: 44604 | B13: 0 | C13: 0 | D13: 0 | E13: 0 | F13: 0 | G13: 0
A14: 44605 | B14: 0 | C14: 0 | D14: 0 | E14: 0 | F14: 0 | G14: 0
A15: 44606
A16: 44607
A17: 44608
A18: 44609
A19: 44610
A20: 44611
A21: 44612
A22: 44613
A23: 44614
A24: 44615
A25: 44616
A26: 44617
... A29: 44620
B30: =SUM(B2:B29) -> 190 | C30: =SUM(C2:C29) -> 40 | D30: =SUM(D2:D29) -> 106 | E30: =SUM(E2:E29) -> 19.5 | G30: =SUM(G2:G29) -> 90
B31: 70 | C31: 50 | D31: 100 | E31: 400
B32: =B30*B31 -> 13300 | C32: =C31*C30 -> 2000 | D32: =D30*D31 -> 10600 | E32: =E30*E31 -> 7800 | H32: =SUM(B32:G32) -> 33700

Sheet Hadjer
A1: Date | B1: Messemen | C1: Messemen petit | D1: Mehadjeb | E1: khefaf | F1: Melewi petit | G1: chakhechoukha | H1: Les Boules
A2: 44593 | B2: 0 | C2: 0 | D2: 0 | E2: 0 | F2: 0 | G2: 0 | H2: 0
A3: 44594 | B3: 35 | C3: 0 | D3: 35 | E3: 0 | F3: 0 | G3: 6 | H3: 0
A4: 44595 | B4: 0 | C4: 0 | D4: 0 | E4: 0 | F4: 0 | G4: 0 | H4: 0
A5: 44596 | B5: 0 | C5: 0 | D5: 0 | E5: 0 | F5: 0 | G5: 0 | H5: 0
A6: 44597 | B6: 70 | C6: 20 | D6: 40 | E6: 0 | F6: 0 | G6: 3 | H6: 0
A7: 44598 | B7: 0 | C7: 0 | D7: 0 | E7: 0 | F7: 0 | G7: 0 | H7: 0
A8: 44599 | B8: 60 | C8: 0 | D8: 40 | E8: 0 | F8: 12 | G8: 0 | H8: 0
A9: 44600 | B9: 0 | C9: 0 | D9: 0 | E9: 0 | F9: 0 | G9: 0 | H9: 0
A10: 44601 | B10: 85 | C10: 0 | D10: 10 | E10: 0 | F10: 0 | G10: 3.5 | H10: 0
A11: 44602
A12: 44603 | B12: 24 | C12: 0 | D12: 10 | E12: 0 | F12: 0 | G12: 1 | H12: 0
A13: 44604 | B13: 40 | C13: 0 | D13: 25 | E13: 0 | F13: 0 | G13: 4 | H13: 0
A14: 44605 | B14: 0 | C14: 0 | D14: 0 | E14: 0 | F14: 0 | G14: 0 | H14: 0
A15: 44606
A16: 44607
A17: 44608
A18: 44609
A19: 44610
A20: 44611
A21: 44612
A22: 44613
A23: 44614
A24: 44615
A25: 44616
A26: 44617
... A29: 44620
B30: =SUM(B2:B29) -> 314 | C30: =SUM(C2:C29) -> 20 | D30: =SUM(D2:D29) -> 160 | E30: =SUM(E2:E29) -> 0 | F30: =SUM(F2:F29) -> 12 | G30: =SUM(G2:G29) -> 17.5 | H30: =SUM(H2:H29) -> 0
B31: 70 | C31: 50 | D31: 100 | E31: 70 | F31: 100 | G31: 400
B32: =B31*B30 -> 21980 | C32: =C31*C30 -> 1000 | D32: =D31*D30 -> 16000 | E32: =E31*E30 -> 0 | F32: =F31*F30 -> 1200 | G32: =G31*G30 -> 7000 | H32: =H31*H30 -> 0 | I32: =SUM(B32:H32) -> 47180

Sheet Houda 
A1: 0 | B1: Burger | C1: Batbout | D1: Tacos | E1: croissant F | F1: Croissant P | G1: Croissant V | H1: Croissant T | I1: Mini Pizza | J1: Souflet F | K1: Souflet P | L1: Souflet V | M1: Souflet T | N1: Frcacées | O1: Begneit | P1: Les russes | Q1: Sablés chocolat | R1: Sablés confiture | S1: Sablés étoiles | T1: Tcharak El3aryan | U1: Tcharak messeker | V1: Griwech | W1: Taba3 | X1: Cigares | Y1: Mehancha | Z1: Les amandines | AA1: Ka3ek Nakach | AB1: Les ésquimeaux | AC1: Bourak Poulet | AD1: Bourak VIande Hachée | AE1: Bessetila | AF1: 3arayech | AG1: ke3ike3at messekerine | AH1: Samsa
A2: 44593 | B2: 0 | C2: 30 | D2: 0 | E2: 0 | F2: 0 | G2: 0 | H2: 0 | I2: 0 | J2: 0 | K2: 0 | L2: 0 | M2: 0 | N2: 0 | O2: 0 | P2: 0 | Q2: 0 | R2: 0 | S2: 0 | T2: 23 | U2: 19 | V2: 0 | W2: 0 | X2: 0 | Y2: 36 | Z2: 0 | AA2: 0 | AB2: 0 | AC2: 0 | AD2: 0 | AE2: 0 | AF2: 0 | AG2: 0 | AH2: 0
A3: 44594 | B3: 0 | C3: 30 | D3: 10 | E3: 0 | F3: 0 | G3: 0 | H3: 0 | I3: 0 | J3: 0 | K3: 0 | L3: 0 | M3: 0 | N3: 0 | O3: 0 | P3: 0 | Q3: 0 | R3: 0 | S3: 0 | T3: 0 | U3: 0 | V3: 0 | W3: 0 | X3: 0 | Y3: 0 | Z3: 0 | AA3: 0 | AB3: 0 | AC3: 0 | AD3: 0 | AE3: 0 | AF3: 0 | AG3: 0 | AH3: 0
A4: 44595 | B4: 0 | C4: 21 | D4: 0 | E4: 0 | F4: 0 | G4: 0 | H4: 0 | I4: 0 | J4: 0 | K4: 0 | L4: 0 | M4: 0 | N4: 0 | O4: 0 | P4: 0 | Q4: 0 | R4: 0 | S4: 0 | T4: 29 | U4: 0 | V4: 0 | W4: 57 | X4: 0 | Y4: 0 | Z4: 0 | AA4: 24 | AB4: 0 | AC4: 0 | AD4: 0 | AE4: 0 | AF4: 21 | AG4: 0 | AH4: 0
A5: 44596 | B5: 0 | C5: 0 | D5: 0 | E5: 0 | F5: 0 | G5: 0 | H5: 0 | I5: 0 | J5: 0 | K5: 0 | L5: 0 | M5: 0 | N5: 0 | O5: 0 | P5: 0 | Q5: 0 | R5: 0 | S5: 0 | T5: 0 | U5: 0 | V5: 0 | W5: 0 | X5: 0 | Y5: 0 | Z5: 0 | AA5: 0 | AB5: 0 | AC5: 0 | AD5: 0 | AE5: 0 | AF5: 0 | AG5: 0 | AH5: 0
A6: 44597 | B6: 0 | C6: 0 | D6: 0 | E6: 0 | F6: 0 | G6: 0 | H6: 0 | I6: 0 | J6: 0 | K6: 0 | L6: 0 | M6: 0 | N6: 0 | O6: 0 | P6: 0 | Q6: 0 | R6: 0 | S6: 0 | T6: 0 | U6: 0 | V6: 0 | W6: 0 | X6: 0 | Y6: 0 | Z6: 0 | AA6: 50 | AB6: 0 | AC6: 0 | AD6: 0 | AE6: 0 | AF6: 0 | AG6: 0 | AH6: 22
A7: 44598 | B7: 0 | C7: 20 | D7: 0 | E7: 0 | F7: 0 | G7: 0 | H7: 0 | I7: 17 | J7: 5 | K7: 6 | L7: 0 | M7: 0 | N7: 0 | O7: 0 | P7: 0 | Q7: 0 | R7: 0 | S7: 0 | T7: 0 | U7: 0 | V7: 0 | W7: 0 | X7: 0 | Y7: 0 | Z7: 0 | AA7: 35 | AB7: 0 | AC7: 0 | AD7: 0 | AE7: 0 | AF7: 0 | AG7: 0 | AH7: 0
A8: 44599 | B8: 0 | C8: 47 | D8: 0 | E8: 0 | F8: 0 | G8: 0 | H8: 0 | I8: 16 | J8: 0 | K8: 0 | L8: 0 | M8: 0 | N8: 10 | O8: 0 | P8: 0 | Q8: 0 | R8: 0 | S8: 0 | T8: 0 | U8: 0 | V8: 0 | W8: 0 | X8: 0 | Y8: 0 | Z8: 0 | AA8: 21 | AB8: 0 | AC8: 0 | AD8: 0 | AE8: 6 | AF8: 0 | AG8: 0 | AH8: 0
A9: 44600 | B9: 0 | C9: 25 | D9: 0 | E9: 0 | F9: 0 | G9: 0 | H9: 0 | I9: 0 | J9: 0 | K9: 0 | L9: 0 | M9: 0 | N9: 0 | O9: 0 | P9: 0 | Q9: 0 | R9: 0 | S9: 0 | T9: 0 | U9: 0 | V9: 0 | W9: 0 | X9: 0 | Y9: 0 | Z9: 0 | AA9: 55 | AB9: 0 | AC9: 0 | AD9: 0 | AE9: 0 | AF9: 0 | AG9: 0 | AH9: 0
A10: 44601 | B10: 0 | C10: 27 | D10: 0 | E10: 0 | F10: 0 | G10: 0 | H10: 0 | I10: 7 | J10: 0 | K10: 0 | L10: 0 | M10: 0 | N10: 0 | O10: 0 | P10: 0 | Q10: 0 | R10: 0 | S10: 0 | T10: 30 | U10: 0 | V10: 0 | W10: 0 | X10: 16 | Y10: 28 | Z10: 0 | AA10: 40 | AB10: 0 | AC10: 0 | AD10: 0 | AE10: 0 | AF10: 0 | AG10: 0 | AH10: 0
A11: 44602 | B11: 0 | C11: 25 | D11: 0 | E11: 0 | F11: 0 | G11: 0 | H11: 0 | I11: 20 | J11: 0 | K11: 0 | L11: 0 | M11: 0 | N11: 0 | O11: 0 | P11: 0 | Q11: 0 | R11: 0 | S11: 0 | T11: 0 | U11: 0 | V11: 0 | W11: 0 | X11: 0 | Y11: 0 | Z11: 0 | AA11: 58 | AB11: 0 | AC11: 0 | AD11: 0 | AE11: 4 | AF11: 0 | AG11: 0 | AH11: 0
A12: 44603 | B12: 0 | C12: 0 | D12: 0 | E12: 0 | F12: 0 | G12: 0 | H12: 0 | I12: 0 | J12: 0 | K12: 0 | L12: 0 | M12: 0 | N12: 0 | O12: 0 | P12: 0 | Q12: 0 | R12: 0 | S12: 0 | T12: 0 | U12: 0 | V12: 0 | W12: 0 | X12: 0 | Y12: 0 | Z12: 0 | AA12: 0 | AB12: 0 | AC12: 0 | AD12: 0 | AE12: 0 | AF12: 0 | AG12: 0 | AH12: 0
A13: 44604 | B13: 0 | C13: 0 | D13: 0 | E13: 0 | F13: 0 | G13: 0 | H13: 0 | I13: 0 | J13: 0 | K13: 0 | L13: 0 | M13: 0 | N13: 0 | O13: 0 | P13: 0 | Q13: 0 | R13: 0 | S13: 0 | T13: 0 | U13: 0 | V13: 0 | W13: 0 | X13: 0 | Y13: 0 | Z13: 0 | AA13: 0 | AB13: 0 | AC13: 0 | AD13: 0 | AE13: 0 | AF13: 0 | AG13: 0 | AH13: 0
A14: 44605 | B14: 0 | C14: 19 | D14: 0 | E14: 0 | F14: 0 | G14: 0 | H14: 0 | I14: 0 | J14: 0 | K14: 0 | L14: 0 | M14: 0 | N14: 0 | O14: 0 | P14: 0 | Q14: 0 | R14: 0 | S14: 0 | T14: 0 | U14: 0 | V14: 0 | W14: 0 | X14: 0 | Y14: 0 | Z14: 0 | AA14: 60 | AB14: 0 | AC14: 0 | AD14: 0 | AE14: 0 | AF14: 0 | AG14: 0 | AH14: 0
A15: 44606
A16: 44607
A17: 44608
A18: 44609
A19: 44610
A20: 44611
A21: 44612
A22: 44613
A23: 44614
A24: 44615
A25: 44616
A26: 44617
... A29: 44620
B30: =SUM(B2:B29) -> 0 | C30: =SUM(C2:C29) -> 244 | D30: =SUM(D2:D29) -> 10 | E30: =SUM(E2:E29) -> 0 | F30: =SUM(F2:F29) -> 0 | G30: =SUM(G2:G29) -> 0 | H30: =SUM(H2:H29) -> 0 | I30: =SUM(I2:I29) -> 60 | ... M30: =SUM(M2:M29) -> 0 | O30: =SUM(O2:O29) -> 0 | P30: =SUM(P2:P29) -> 0 | Q30: =SUM(Q2:Q29) -> 0 | R30: =SUM(R2:R29) -> 0 | S30: =SUM(S2:S29) -> 0 | T30: =SUM(T2:T29) -> 82 | U30: =SUM(U2:U29) -> 19 | V30: =SUM(V2:V29) -> 0 | ... AH30: =SUM(AH2:AH29) -> 22
B31: 100 | C31: 100 | D31: 100 | E31: 70 | F31: 100 | G31: 100 | H31: 100 | I31: 70 | J31: 70 | K31: 100 | L31: 100 | M31: 100 | O31: 60 | P31: 100 | Q31: 100 | R31: 70 | S31: 50 | T31: 150 | U31: 150 | V31: 60 | W31: 50 | X31: 150 | Y31: 200 | Z31: 120 | AA31: 80 | AB31: 100 | AC31: 150 | AD31: 200 | AE31: 250 | AF31: 150 | AH31: 150
B32: =B31*B30 -> 0 | C32: =C31*C30 -> 24400 | D32: =D31*D30 -> 1000 | E32: =E31*E30 -> 0 | F32: =F31*F30 -> 0 | G32: =G31*G30 -> 0 | H32: =H31*H30 -> 0 | I32: =I31*I30 -> 4200 | ... M32: =M31*M30 -> 0 | O32: =O31*O30 -> 0 | P32: =P31*P30 -> 0 | Q32: =Q31*Q30 -> 0 | R32: =R31*R30 -> 0 | S32: =S31*S30 -> 0 | T32: =T31*T30 -> 12300 | U32: =U31*U30 -> 2850 | V32: =V31*V30 -> 0 | ... AH32: =AH31*AH30 -> 3300 | AI32: =SUM(B32:AH32) -> 100140

Sheet Soumia
A1: Date | B1: Burger | C1: Batbout | D1: Tacos | E1: croissant F | F1: Croissant P | G1: Croissant V | H1: Croissant T | I1: Mini Pizza | J1: Souflet F | K1: Souflet P | L1: Souflet V | M1: Souflet T | N1: Begneit | O1: 7alwet taba3 | P1: Les russes | Q1: Sablés chocolat | R1: Sablés confiture | S1: Sablés étoiles | T1: Tcharak El3aryan | U1: Tcharak messeker | V1: Griwech | W1: Cigares | X1: Mehancha | Y1: Les amandines | Z1: Ka3ek Nakach | AA1: Les ésquimeaux | AB1: Bourak Poulet | AC1: Bourak VIande Hachée | AD1: Ke3ike3at messekerine
A2: 44593 | B2: 40 | C2: 0 | D2: 10 | E2: 0 | F2: 0 | G2: 0 | H2: 0 | I2: 0 | J2: 0 | K2: 0 | L2: 0 | M2: 0 | N2: 16 | O2: 0 | P2: 0 | Q2: 0 | R2: 0 | S2: 0 | T2: 0 | U2: 0 | V2: 0 | W2: 13 | X2: 0 | Y2: 0 | Z2: 0 | AA2: 0 | AB2: 0 | AC2: 0 | AD2: 0
A3: 44594 | B3: 40 | C3: 0 | D3: 0 | E3: 5 | F3: 0 | G3: 0 | H3: 5 | I3: 20 | J3: 0 | K3: 0 | L3: 0 | M3: 0 | N3: 22 | O3: 0 | P3: 0 | Q3: 0 | R3: 0 | S3: 0 | T3: 0 | U3: 0 | V3: 0 | W3: 0 | X3: 0 | Y3: 0 | Z3: 0 | AA3: 0 | AB3: 0 | AC3: 0 | AD3: 0
A4: 44595 | B4: 20 | C4: 0 | D4: 0 | E4: 0 | F4: 0 | G4: 10 | H4: 0 | I4: 0 | J4: 0 | K4: 0 | L4: 0 | M4: 0 | N4: 20 | O4: 0 | P4: 0 | Q4: 0 | R4: 0 | S4: 0 | T4: 0 | U4: 0 | V4: 20 | W4: 0 | X4: 0 | Y4: 0 | Z4: 0 | AA4: 0 | AB4: 0 | AC4: 0 | AD4: 0
A5: 44596 | B5: 0 | C5: 0 | D5: 0 | E5: 0 | F5: 0 | G5: 0 | H5: 0 | I5: 0 | J5: 0 | K5: 0 | L5: 0 | M5: 0 | N5: 0 | O5: 0 | P5: 0 | Q5: 0 | R5: 0 | S5: 0 | T5: 0 | U5: 0 | V5: 0 | W5: 0 | X5: 0 | Y5: 0 | Z5: 0 | AA5: 0 | AB5: 0 | AC5: 0 | AD5: 0 | AE5: 0
A6: 44597 | B6: 20 | C6: 14 | D6: 0 | E6: 0 | F6: 0 | G6: 0 | H6: 0 | I6: 0 | J6: 0 | K6: 0 | L6: 0 | M6: 0 | N6: 15 | O6: 0 | P6: 0 | Q6: 0 | R6: 0 | S6: 0 | T6: 0 | U6: 0 | V6: 0 | W6: 23 | X6: 0 | Y6: 0 | Z6: 0 | AA6: 0 | AB6: 0 | AC6: 0 | AD6: 0
A7: 44598 | B7: 15 | C7: 0 | D7: 0 | E7: 0 | F7: 0 | G7: 0 | H7: 0 | I7: 0 | J7: 0 | K7: 0 | L7: 0 | M7: 0 | N7: 18 | O7: 0 | P7: 20 | Q7: 0 | R7: 0 | S7: 0 | T7: 0 | U7: 0 | V7: 0 | W7: 0 | X7: 0 | Y7: 0 | Z7: 0 | AA7: 0 | AB7: 0 | AC7: 0 | AD7: 0
A8: 44599 | B8: 14 | C8: 0 | D8: 12 | E8: 0 | F8: 0 | G8: 0 | H8: 0 | I8: 0 | J8: 0 | K8: 0 | L8: 0 | M8: 0 | N8: 21 | O8: 0 | P8: 0 | Q8: 0 | R8: 23 | S8: 0 | T8: 0 | U8: 0 | V8: 0 | W8: 0 | X8: 0 | Y8: 0 | Z8: 0 | AA8: 0 | AB8: 0 | AC8: 0 | AD8: 0
A9: 44600 | B9: 17 | C9: 0 | D9: 0 | E9: 0 | F9: 0 | G9: 0 | H9: 0 | I9: 14 | J9: 0 | K9: 0 | L9: 0 | M9: 0 | N9: 22 | O9: 44 | P9: 0 | Q9: 0 | R9: 20 | S9: 0 | T9: 0 | U9: 0 | V9: 0 | W9: 0 | X9: 0 | Y9: 0 | Z9: 0 | AA9: 0 | AB9: 0 | AC9: 0 | AD9: 0
A10: 44601 | B10: 23 | C10: 0 | D10: 0 | E10: 3 | F10: 0 | G10: 0 | H10: 3 | I10: 6 | J10: 0 | K10: 3 | L10: 0 | M10: 3 | N10: 20 | O10: 0 | P10: 0 | Q10: 0 | R10: 0 | S10: 0 | T10: 0 | U10: 0 | V10: 0 | W10: 0 | X10: 0 | Y10: 0 | Z10: 0 | AA10: 0 | AB10: 0 | AC10: 0 | AD10: 0 | AE10: 0
A11: 44602 | B11: 40 | C11: 0 | D11: 0 | E11: 0 | F11: 8 | G11: 0 | H11: 5 | I11: 0 | J11: 0 | K11: 0 | L11: 0 | M11: 0 | N11: 0 | O11: 0 | P11: 0 | Q11: 0 | R11: 0 | S11: 0 | T11: 0 | U11: 0 | V11: 0 | W11: 0 | X11: 0 | Y11: 0 | Z11: 0 | AA11: 0 | AB11: 0 | AC11: 0 | AD11: 0 | AE11: 0 | AF11: 0 | AG11: 0
A12: 44603 | B12: 0 | C12: 0 | D12: 0 | E12: 0 | F12: 0 | G12: 0 | H12: 0 | I12: 0 | J12: 0 | K12: 0 | L12: 0 | M12: 0 | N12: 0 | O12: 0 | P12: 0 | Q12: 0 | R12: 0 | S12: 0 | T12: 0 | U12: 0 | V12: 0 | W12: 0 | X12: 0 | Y12: 0 | Z12: 0 | AA12: 0 | AB12: 0 | AC12: 0 | AD12: 0 | AE12: 0 | AF12: 0
A13: 44604 | B13: 19 | C13: 34 | D13: 0 | E13: 0 | F13: 0 | G13: 0 | H13: 0 | I13: 0 | J13: 0 | K13: 0 | L13: 0 | M13: 0 | N13: 22 | O13: 33 | P13: 0 | Q13: 0 | R13: 34 | S13: 0 | T13: 25 | U13: 0 | V13: 0 | W13: 0 | X13: 0 | Y13: 0 | Z13: 0 | AA13: 0 | AB13: 0 | AC13: 0 | AD13: 0 | AE13: 0 | AF13: 0
A14: 44605 | B14: 19 | C14: 0 | D14: 0 | E14: 0 | F14: 0 | G14: 0 | H14: 0 | I14: 0 | J14: 0 | K14: 0 | L14: 0 | M14: 0 | N14: 17 | O14: 0 | P14: 0 | Q14: 0 | R14: 0 | S14: 48 | T14: 0 | U14: 0 | V14: 0 | W14: 0 | X14: 0 | Y14: 0 | Z14: 0 | AA14: 0 | AB14: 0 | AC14: 0 | AD14: 0 | AE14: 0 | AG14: 0
A15: 44606
A16: 44607
A17: 44608
A18: 44609
A19: 44610
A20: 44611
A21: 44612
A22: 44613
A23: 44614
A24: 44615
A25: 44616
A26: 44617
... A29: 44620
B30: =SUM(B2:B29) -> 267 | C30: =SUM(C2:C29) -> 48 | D30: =SUM(D2:D29) -> 22 | E30: =SUM(E2:E29) -> 8 | F30: =SUM(F2:F29) -> 8 | G30: =SUM(G2:G29) -> 10 | H30: =SUM(H2:H29) -> 13 | I30: =SUM(I2:I29) -> 40 | ... AG30: =SUM(AG2:AG29) -> 0
B31: 100 | C31: 100 | D31: 100 | E31: 70 | F31: 100 | G31: 100 | H31: 100 | I31: 70 | J31: 70 | K31: 100 | L31: 100 | M31: 100 | N31: 60 | O31: 50 | P31: 100 | Q31: 100 | R31: 70 | S31: 50 | T31: 150 | U31: 150 | V31: 60 | W31: 150 | X31: 200 | Y31: 120 | Z31: 80 | AA31: 100 | AB31: 150 | AC31: 200
B32: =B31*B30 -> 26700 | C32: =C31*C30 -> 4800 | D32: =D31*D30 -> 2200 | E32: =E31*E30 -> 560 | F32: =F31*F30 -> 800 | G32: =G31*G30 -> 1000 | H32: =H31*H30 -> 1300 | I32: =I31*I30 -> 2800 | ... AG32: =AG31*AG30 -> 0 | AH32: =SUM(B32:AG32) -> 76330

Sheet Djamila
A1: Date | B1: Grandes Boules | C1: Petites Boules | D1: Chakechouka | E1: Gherss | F1: Mehadjeb | G1: Chakhechoukha | H1: Autres
A2: 44593
A3: 44594 | B3: 151 | C3: 0 | D3: 10kg | E3: 0 | F3: 0 | G3: 0 | H3: Kefaf+ Vaissel
A4: 44595 | B4: 0 | C4: 0 | D4: 0 | E4: 0 | F4: 0 | G4: 0
A5: 44596
A6: 44597
A7: 44598
A8: 44599
A9: 44600
A10: 44601
A11: 44602
A12: 44603
A13: 44604
A14: 44605
A15: 44606
A16: 44607
... A29: 44620
B30: =SUM(B2:B29) -> 151 | C30: =SUM(C2:C29) -> 0 | D30: =SUM(D2:D29) -> 0 | E30: =SUM(E2:E29) -> 0 | F30: =SUM(F2:F29) -> 0 | G30: =SUM(G2:G29) -> 0
I32: =SUM(F32:H32) -> 0

Sheet Maroua
A1: Date | B1: Grandes Boules | C1: Petites Boules | D1: Chakechouka | E1: Gherss | F1: Autres
A2: 44593
A3: 44594 | F3: Kefaf+ Vaissel
A4: 44595
A5: 44596
A6: 44597
A7: 44598
A8: 44599
A9: 44600
A10: 44601
A11: 44602
A12: 44603
A13: 44604
A14: 44605
A15: 44606
... A29: 44620
B30: =SUM(B2:B29) -> 0 | C30: =SUM(C2:C29) -> 0 | D30: =SUM(D2:D29) -> 0 | E30: =SUM(E2:E29) -> 0

Sheet Amina 
A1: Date | B1: Baghrir Simple | C1: Baghrir raisins sec | D1: Baghrir petit S | E1: Baghrir petit R s
A2: 44593
A3: 44594
A4: 44595
A5: 44596
A6: 44597
A7: 44598
A8: 44599
A9: 44600
A10: 44601
A11: 44602
A12: 44603
A13: 44604
... A29: 44620
A30: Totale | B30: =SUM(B2:B29) -> 0 | C30: =SUM(C2:C29) -> 0 | D30: =SUM(D2:D29) -> 0 | E30: =SUM(E2:E29) -> 0
B31: 50 | C31: 60 | D31: 30 | E31: 40
B32: =B30*B31 -> 0 | C32: =C30*C31 -> 0 | D32: =D30*D31 -> 0 | E32: =E30*E31 -> 0 | F32: =SUM(B32:E32) -> 0

Sheet Rendement des employées
J8: Nom | K8: Pointage | L8: Salaires | M8: Rendement | N8: Moyenne de Rendement
I9: 1 | J9: Zehor | K9: =Pointage!C30*1 -> 22 | L9: =Pointage!C32*1 -> 45826 | M9: =Zehor!H32*1 -> 55730 | N9: =M9/K9 -> 2533.1818
I10: 2 | J10: Soumia | K10: =Pointage!D30*1 -> 21 | L10: =Pointage!D32*1 -> 21861 | M10: =Soumia!AH32*1 -> 76330 | N10: =M10/K10 -> 3634.7619
I11: 3 | J11: Amel | K11: =Pointage!G30*1 -> 25 | L11: =Pointage!G32*1 -> 31250 | M11: =Amel!U32*1 -> 109210 | N11: =M11/K11 -> 4368.4
I12: 4 | J12: Marwa | K12: =Pointage!H30*1 -> 11 | L12: =Pointage!H32*1 -> 11000 | M12: 0 | N12: =M12/K12 -> 0
I13: 5 | J13: Djamila | K13: =Pointage!I30*1 -> 13 | L13: =Pointage!I32*1 -> 13000 | M13: =Djamila!I32*1 -> 0 | N13: =M13/K13 -> 0
I14: 6 | J14: Nadjet | K14: =Pointage!E30*1 -> 17 | L14: =Pointage!E32*1 -> 21250 | M14: =Nadjet!H32*1 -> 33700 | N14: =M14/K14 -> 1982.3529
I15: 7 | J15: Hadjer | K15: =Pointage!F30*1 -> 18 | L15: =Pointage!F32*1 -> 22500 | M15: =Hadjer!I32*1 -> 47180 | N15: =M15/K15 -> 2621.1111
I16: 8 | J16: Houda | K16: =Pointage!J30*1 -> 23 | L16: =Pointage!J32*1 -> 28750 | M16: ='Houda '!AI32*1 -> 100140 | N16: =M16/K16 -> 4353.913
I17: 9 | J17: Hafida | K17: =Pointage!L30*1 -> 22.5 | L17: =Pointage!L32*1 -> 28125 | M17: =Hafida!P32*1 -> 34960 | N17: =M17/K17 -> 1553.7778
I18: 10 | J18: Zahida | K18: =Pointage!M30*1-E31 -> 20.0625 | L18: =Pointage!M32*1 -> 26953.125 | M18: =Zahida!K32*1 -> 79900 | N18: =M18/K18 -> 3982.5545
J19: Totale | M19: =SUM(M9:M18) -> 537150
E31: 1.5

Sheet Feuille 5
H8: Loyer du Local Octobre , Novembre, Décembre , janvier | I8: 180000
H9: Bénifice Janvier | I9: 300000
H10: recettev février | I10: =RECAP!D30*1 -> 1300000
H11: Cuisine équipée | I11: 30000
H12: Assurance voiture | I12: 20000
H13: Sofiane | I13: 10000
H14: charges février | I14: ='Les charges'!F297*1 -> 462411
H15: caisse | I15: =RECAP!O9*1 -> 118000
H17: cash restant | I17: =I8+I9+I10-I11-I12-I13-I14-I15 -> 1139589
H23: Loyer du Local Octobre , Novembre, Décembre , janvier | I23: 180000
H24: recettev février | I24: =RECAP!D30*1 -> 1300000
H25: charges février | I25: =RECAP!E30*1 -> 462411
H26: caisse | I26: =RECAP!O9*1 -> 118000
H27: Avance Salaires | I27: =Salaires!K19*1 -> 57000
H28: Cash réel | I28: 114000
H31: le magasin me doit | I31: =I23+I24-I25-I26-I27-I28 -> 728589
M43: Mois de Janvier | N43: Mois de Février
L44: Recette | M44: 1051000 | N44: 1300000
L45: Charges | M45: 435000 | N45: 462400
L46: Salaires | M46: 226000 | N46: 277600
L47: Loyer | M47: 90000 | N47: 90000
L48: Profit Net | M48: 300000 | N48: 470000
