Workbook

Sheet RECAP
B1: Date | C1: Recette Décembre 2024 | D1: Recette | E1: Logiciel | F1: Charges | G1: Salaire | H1: Che7i7a | I1: Loyer | J1: Net Profit | K1: Nb de jours | M1: Objectif | N1: Mois de Décembre 2024
A2: Mercredi | B2: 45658 | C2: 57000 | D2: 70000 | E2: 70000 | G2: =Pointage!AF2 -> 0 | H2: 2000 | K2: 1 | N2: 57000
A3: Jeudi | B3: 45659 | C3: 36000 | D3: 47000 | E3: 47000 | G3: =Pointage!AF3 -> 0 | H3: 2000 | K3: 1 | N3: 36000 | O3: Bénéfice Moyen par jour | P3: Moyenne | Q3: Moyenne salaire | R3: pourcentage du salaire vis à vis la recettte
A4: Vendredi | B4: 45660 | C4: 65000 | D4: 71000 | E4: 71000 | G4: =Pointage!AF4 -> 0 | H4: 2000 | K4: 1 | N4: 65000 | O4: =J33/K33 -> 16451.884 | P4: =D33/K33 -> 65580.645 | R4: =Q4/P4 -> 0
A5: Samedi | B5: 45661 | C5: 29000 | D5: 47000 | E5: 47000 | G5: =Pointage!AF5 -> 0 | H5: 2000 | K5: 1 | N5: 29000
A6: Dimanche | B6: 45662 | C6: 65000 | D6: 46000 | E6: 46000 | G6: =Pointage!AF6 -> 0 | H6: 2000 | K6: 1 | N6: 65000 | O6: Moyenne des charges par jour | P6: Objectif
A7: Lundi | B7: 45663 | C7: 71000 | D7: 50000 | E7: 50000 | G7: =Pointage!AF7 -> 0 | H7: 2000 | K7: 1 | N7: 71000 | O7: =F33/K33 -> 27533.31 | P7: 100000
A8: Mardi | B8: 45664 | C8: 69000 | D8: 65000 | E8: 65000 | G8: =Pointage!AF8 -> 0 | H8: 2000 | K8: 1 | N8: 69000 | O8: ² | T8: "
A9: Mercredi | B9: 45665 | C9: 72000 | D9: 112000 | E9: 112000 | G9: =Pointage!AF9 -> 0 | H9: 2000 | K9: 1 | N9: 72000
A10: Jeudi | B10: 45666 | C10: 48000 | D10: 82000 | E10: 82000 | G10: =Pointage!AF10 -> 0 | H10: 2000 | K10: 1 | N10: 48000 | O10: Cash restant | P10: Magasin | Q10: Cash réel | R10: Mes dettes pour le magasin
A11: Vendredi | B11: 45667 | C11: 45000 | D11: 91000 | E11: 91000 | G11: =Pointage!AF11 -> 0 | H11: 2000 | K11: 1 | N11: 45000 | O11: =O14+D33-F33-H33-P11-'Salaires '!M30 -> 861467.4 | P11: 156000 | Q11: 715000 | R11: =O11-Q11 -> 146467.4
A12: Samedi | B12: 45668 | C12: 71000 | D12: 188000 | E12: 188000 | G12: =Pointage!AF12 -> 0 | H12: 2000 | K12: 1 | N12: 71000
A13: Dimanche | B13: 45669 | C13: 72000 | D13: 53000 | E13: 53000 | G13: =Pointage!AF13 -> 0 | H13: 2000 | K13: 1 | N13: 72000 | O13: Fond de Roulement
A14: Lundi | B14: 45670 | C14: 90000 | D14: 45000 | E14: 45000 | G14: =Pointage!AF14 -> 1100 | H14: 2000 | K14: 1 | N14: 90000 | O14: 330000
A15: Mardi | B15: 45671 | C15: 79000 | D15: 58000 | E15: 58000 | G15: =Pointage!AF15 -> 0 | H15: 2000 | K15: 1 | N15: 79000
A16: Mercredi | B16: 45672 | C16: 72000 | D16: 96000 | E16: 96000 | G16: =Pointage!AF16 -> 0 | H16: 2000 | K16: 1 | N16: 72000 | O16: Bénéfice Sept + loyer
A17: Jeudi | B17: 45673 | C17: 55000 | D17: 54000 | E17: 54000 | G17: =Pointage!AF17 -> 0 | H17: 2000 | K17: 1 | N17: 55000 | O17: 0 | R17: Sofiane : 40000 Da +19000Da+22000Da Cnas Sifou + 24000Da Baridi Mob+10000Da
A18: Vendredi | B18: 45674 | C18: 68000 | D18: 59000 | E18: 59000 | G18: =Pointage!AF18 -> 0 | H18: 2000 | K18: 1 | N18: 68000 | R18: Monnie: 23000 Da
A19: Samedi | B19: 45675 | C19: 130000 | D19: 53000 | E19: 53000 | G19: =Pointage!AF19 -> 0 | H19: 2000 | K19: 1 | N19: 130000 | O19: Différence mois de Décembre | R19: la vraie caisse: Da
A20: Dimanche | B20: 45676 | C20: 100000 | D20: 41000 | E20: 41000 | G20: =Pointage!AF20 -> 0 | H20: 2000 | K20: 1 | N20: 100000 | O20: =D33-C33 -> -165000
A21: Lundi | B21: 45677 | C21: 62000 | D21: 43000 | E21: 43000 | G21: =Pointage!AF21 -> 0 | H21: 2000 | K21: 1 | N21: 62000 | O21: Différence objectif | R21: cliente Maha: 4500D a
A22: Mardi | B22: 45678 | C22: 64000 | D22: 46000 | E22: 46000 | G22: =Pointage!AF22 -> 0 | H22: 2000 | K22: 1 | N22: 64000 | O22: =M36-F36 -> 0 | R22: khalida cliente : 7500Da
A23: Mercredi | B23: 45679 | C23: 60000 | D23: 30000 | E23: 30000 | G23: =Pointage!AF23 -> 0 | H23: 2000 | K23: 1 | N23: 60000 | O23: Différence du Totale
A24: Jeudi | B24: 45680 | C24: 44000 | D24: 57000 | E24: 57000 | G24: =Pointage!AF24 -> 0 | H24: 2000 | K24: 1 | N24: 44000 | O24: =D33-C33 -> -165000
A25: Vendredi | B25: 45681 | C25: 47000 | D25: 65000 | E25: 65000 | G25: =Pointage!AF25 -> 0 | H25: 2000 | K25: 1 | N25: 47000 | O25: Les vendredis
A26: Samedi | B26: 45682 | C26: 57000 | D26: 52000 | E26: 52000 | G26: =Pointage!AF26 -> 0 | H26: 2000 | K26: 1 | N26: 57000 | O26: =D9+D16+D23+D30 -> 288000
A27: Dimanche | B27: 45683 | C27: 75000 | D27: 33000 | E27: 33000 | G27: =Pointage!AF27 -> 0 | H27: 2000 | K27: 1 | N27: 75000
A28: Lundi | B28: 45684 | C28: 68000 | D28: 44000 | E28: 44000 | G28: =Pointage!AF28 -> 0 | H28: 2000 | K28: 1 | N28: 68000 | O28: Cash réel
A29: Mardi | B29: 45685 | C29: 68000 | D29: 76000 | E29: 76000 | G29: =Pointage!AF29 -> 0 | H29: 2000 | K29: 1 | N29: 68000 | O29: 51000
A30: Mercredi | B30: 45686 | C30: 66000 | D30: 50000 | E30: 50000 | G30: =Pointage!AF30 -> 0 | H30: 2000 | K30: 1 | N30: 66000 | O30: rest à payer
A31: Jeudi | B31: 45687 | C31: 176000 | D31: 59000 | E31: 59000 | G31: =Pointage!AF31 -> 0 | H31: 2000 | K31: 1 | N31: 176000
A32: Vendredi | B32: 45688 | C32: 117000 | D32: 150000 | E32: 150000 | G32: =Pointage!AF32 -> 0 | H32: 2000 | K32: 1 | L32: 58000Da Recette + 32000Da Box Lunch+ 60000Da commande gateaux | N32: 117000
C33: =SUM(C2:C32) -> 2198000 | D33: =SUM(D2:D32) -> 2033000 | E33: =SUM(E2:E32) -> 2033000 | F33: ='Les Charges'!H381 -> 853532.6 | G33: ='Salaires '!L30 -> 427459 | H33: =SUM(H2:H32) -> 62000 | I33: 180000 | J33: =D33-F33-G33-H33-I33 -> 510008.4 | K33: =SUM(K2:K32) -> 31 | N33: =SUM(N2:N32) -> 2198000
H34: Loyer Magasin | I34: 55000
H35: Loyer Locale | I35: 40000 | O35: =O11-O29-O34 -> 810467.4
H36: Sofiane Maison | I36: 45000
H37: Dette Papa | I37: 40000
D38: -
C49: 1

Sheet Pointage
A1: Colonne 1 | B1: Date | C1: Saida | D1: N/J | E1: Fatiha | F1: Column 18 | G1: Nora | H1: Column 20 | I1: Ikram | J1: Column 21 | K1: Nour ElHouda | L1: Column 22 | M1: Yasmine | N1: Column 23 | O1: Zohra | P1: Column 24 | Q1: Rayan | R1: Column 25 | S1: Amina | T1: Column 26 | U1: Sihem | V1: Column 27 | W1: Karima | X1: Column 28 | Y1: Meriem | Z1: Column 29 | AA1: Ahlem | AB1: Column 30 | AC1: Houda | AD1: Column 31 | AE1: Remarque | AF1: Salaire/Jour
A2: Mercredi | B2: 45658 | AD2: =AC2*1100 -> 0 | AF2: =SUM(AD2,AB2,Z2,X2,V2,T2,R2,P2,N2,L2,J2,H2,F2,D2) -> 0
A3: Jeudi | B3: 45659 | AD3: =AC3*1100 -> 0 | AF3: =SUM(AD3,AB3,Z3,X3,V3,T3,R3,P3,N3,L3,J3,H3,F3,D3) -> 0
A4: Vendredi | B4: 45660 | AD4: =AC4*1100 -> 0 | AF4: =SUM(AD4,AB4,Z4,X4,V4,T4,R4,P4,N4,L4,J4,H4,F4,D4) -> 0
A5: Samedi | B5: 45661 | AD5: =AC5*1100 -> 0 | AF5: =SUM(AD5,AB5,Z5,X5,V5,T5,R5,P5,N5,L5,J5,H5,F5,D5) -> 0
A6: Dimanche | B6: 45662 | AD6: =AC6*1100 -> 0 | AF6: =SUM(AD6,AB6,Z6,X6,V6,T6,R6,P6,N6,L6,J6,H6,F6,D6) -> 0
A7: Lundi | B7: 45663 | AD7: =AC7*1100 -> 0 | AF7: =SUM(AD7,AB7,Z7,X7,V7,T7,R7,P7,N7,L7,J7,H7,F7,D7) -> 0
A8: Mardi | B8: 45664 | AD8: =AC8*1100 -> 0 | AF8: =SUM(AD8,AB8,Z8,X8,V8,T8,R8,P8,N8,L8,J8,H8,F8,D8) -> 0
A9: Mercredi | B9: 45665 | AD9: =AC9*1100 -> 0 | AF9: =SUM(AD9,AB9,Z9,X9,V9,T9,R9,P9,N9,L9,J9,H9,F9,D9) -> 0
A10: Jeudi | B10: 45666 | AD10: =AC10*1100 -> 0 | AF10: =SUM(AD10,AB10,Z10,X10,V10,T10,R10,P10,N10,L10,J10,H10,F10,D10) -> 0
A11: Vendredi | B11: 45667 | AD11: =AC11*1100 -> 0 | AF11: =SUM(AD11,AB11,Z11,X11,V11,T11,R11,P11,N11,L11,J11,H11,F11,D11) -> 0
A12: Samedi | B12: 45668 | AD12: =AC12*1100 -> 0 | AF12: =SUM(AD12,AB12,Z12,X12,V12,T12,R12,P12,N12,L12,J12,H12,F12,D12) -> 0
A13: Dimanche | B13: 45669 | AD13: =AC13*1100 -> 0 | AF13: =SUM(AD13,AB13,Z13,X13,V13,T13,R13,P13,N13,L13,J13,H13,F13,D13) -> 0
A14: Lundi | B14: 45670 | C14: 1 | E14: 1 | G14: 1 | I14: 0 | K14: 0 | M14: 1 | O14: 0 | Q14: 0 | S14: 0 | U14: 0 | W14: 0 | Y14: 1 | AA14: 1 | AC14: 1 | AD14: =AC14*1100 -> 1100 | AF14: =SUM(AD14,AB14,Z14,X14,V14,T14,R14,P14,N14,L14,J14,H14,F14,D14) -> 1100
A15: Mardi | B15: 45671 | AD15: =AC15*1100 -> 0 | AF15: =SUM(AD15,AB15,Z15,X15,V15,T15,R15,P15,N15,L15,J15,H15,F15,D15) -> 0
A16: Mercredi | B16: 45672 | AD16: =AC16*1100 -> 0 | AF16: =SUM(AD16,AB16,Z16,X16,V16,T16,R16,P16,N16,L16,J16,H16,F16,D16) -> 0
A17: Jeudi | B17: 45673 | AD17: =AC17*1100 -> 0 | AF17: =SUM(AD17,AB17,Z17,X17,V17,T17,R17,P17,N17,L17,J17,H17,F17,D17) -> 0
A18: Vendredi | B18: 45674 | AD18: =AC18*1100 -> 0 | AF18: =SUM(AD18,AB18,Z18,X18,V18,T18,R18,P18,N18,L18,J18,H18,F18,D18) -> 0
A19: Samedi | B19: 45675 | AD19: =AC19*1100 -> 0 | AF19: =SUM(AD19,AB19,Z19,X19,V19,T19,R19,P19,N19,L19,J19,H19,F19,D19) -> 0
A20: Dimanche | B20: 45676 | AD20: =AC20*1100 -> 0 | AF20: =SUM(AD20,AB20,Z20,X20,V20,T20,R20,P20,N20,L20,J20,H20,F20,D20) -> 0
A21: Lundi | B21: 45677 | AD21: =AC21*1100 -> 0 | AF21: =SUM(AD21,AB21,Z21,X21,V21,T21,R21,P21,N21,L21,J21,H21,F21,D21) -> 0
A22: Mardi | B22: 45678 | AD22: =AC22*1100 -> 0 | AF22: =SUM(AD22,AB22,Z22,X22,V22,T22,R22,P22,N22,L22,J22,H22,F22,D22) -> 0
A23: Mercredi | B23: 45679 | AD23: =AC23*1100 -> 0 | AF23: =SUM(AD23,AB23,Z23,X23,V23,T23,R23,P23,N23,L23,J23,H23,F23,D23) -> 0
A24: Jeudi | B24: 45680 | AD24: =AC24*1100 -> 0 | AF24: =SUM(AD24,AB24,Z24,X24,V24,T24,R24,P24,N24,L24,J24,H24,F24,D24) -> 0
A25: Vendredi | B25: 45681 | AD25: =AC25*1100 -> 0 | AF25: =SUM(AD25,AB25,Z25,X25,V25,T25,R25,P25,N25,L25,J25,H25,F25,D25) -> 0
A26: Samedi | B26: 45682 | AD26: =AC26*1100 -> 0 | AF26: =SUM(AD26,AB26,Z26,X26,V26,T26,R26,P26,N26,L26,J26,H26,F26,D26) -> 0
... A31: Jeudi | B31: 45687 | AD31: =AC31*1100 -> 0 | AF31: =SUM(AD31,AB31,Z31,X31,V31,T31,R31,P31,N31,L31,J31,H31,F31,D31) -> 0
A32: Over Time | AD32: =AC32*1100 -> 0 | AF32: =SUM(AD32,AB32,Z32,X32,V32,T32,R32,P32,N32,L32,J32,H32,F32,D32) -> 0
AF33: =SUM(AD33,AB33,Z33,X33,V33,T33,R33,P33,N33,L33,J33,H33,F33,D33) -> 0
C34: 1500 | E34: 1112 | G34: 1112 | I34: 1112 | K34: 1112 | M34: 1112 | O34: 1112 | Q34: 1200 | S34: 1112 | U34: 1112 | W34: 1200 | Y34: 1112 | AA34: 1100 | AC34: 1112 | AF34: =SUM(AD34,AB34,Z34,X34,V34,T34,R34,P34,N34,L34,J34,H34,F34,D34) -> 0
C35: =C34*C33 -> 0 | E35: =E34*E33 -> 0 | G35: =G34*G33 -> 0 | I35: =I34*I33 -> 0 | K35: =K34*K33 -> 0 | M35: =M34*M33 -> 0 | O35: =O34*O33 -> 0 | Q35: =Q34*Q33 -> 0 | S35: =S34*S33 -> 0 | U35: =U34*U33 -> 0 | W35: =W34*W33 -> 0 | Y35: =Y34*Y33 -> 0 | AA35: =AA33*AA34 -> 0 | AC35: =AC34*AC33 -> 0 | AF35: =SUM(AD35,AB35,Z35,X35,V35,T35,R35,P35,N35,L35,J35,H35,F35,D35) -> 0
D36: =C36*1500 -> 0 | E36: 30000 | F36: =E36*E65 -> 0 | G36: 30000 | I36: 30000 | K36: 30000 | M36: 30000 | O36: 30000 | S36: 30000 | U36: 30000 | X36: =W36*1200 -> 0 | Z36: =Y36*1112 -> 0 | AB36: =AA36*1100 -> 0 | AD36: =AC36*1100 -> 0 | AF36: =SUM(AD36,AB36,Z36,X36,V36,T36,R36,P36,N36,L36,J36,H36,F36,D36) -> 0

Sheet Les Charges
E1: 45
E2: Produit | F2: Quantité | G2: Prix unitaire | H2: Prix | I2: Date d'achat
E3: Semoule Fine 25kg | F3: 31 | G3: 1000 | H3: =F3*G3 -> 31000
E4: Semoule Moyenne 25kg | F4: 11 | G4: 1000 | H4: =F4*G4 -> 11000
E5: manutention semoule | F5: 1 | G5: 2500 | H5: =F5*G5 -> 2500
E6: semoule Moula moyenne 10kg | F6: 8 | G6: 550 | H6: =F6*G6 -> 4400
E7: Semoule Moula Gross 10 kg | F7: 2 | G7: 850 | H7: =F7*G7 -> 1700
E8: Semoule Moula Gross 10 kg | F8: 2 | G8: 950 | H8: =F8*G8 -> 1900
E9: Semoule Fine Sosimie 10kg | F9: 2 | G9: 400 | H9: =F9*G9 -> 800
E10: Semoule Moula moyenne 2 kg | F10: 6 | G10: 250 | H10: =F10*G10 -> 1500
E11: Semoule Grosse moula 2kg | F11: 6 | G11: 270 | H11: =F11*G11 -> 1620
E12: Faine 10kg | F12: 7 | G12: 580 | H12: =F12*G12 -> 4060
E13: Levure boulangère | F13: 4 | G13: 415 | H13: =F13*G13 -> 1660
E14: Levure Chimiques | F14: 100 | G14: 6.3 | H14: =F14*G14 -> 630
E15: Crème Liquide 1 litre | F15: 5 | G15: 430 | H15: =F15*G15 -> 2150
E16: huile 5 litre | F16: 30 | G16: 600 | H16: =F16*G16 -> 18000 | I16: Déc+ 31/12
E17: Margarine Dima 500g | F17: 6 | G17: 170 | H17: =F17*G17 -> 1020
E18: sel | F18: 20 | G18: 30 | H18: =F18*G18 -> 600
E19: Chocolat wedjedane au lait | F19: 5 | G19: 230 | H19: =F19*G19 -> 1150
E20: Chocolat wedjedane noir | F20: 12 | G20: 230 | H20: =F20*G20 -> 2760
E21: chocolat wedjedane noisette | F21: 5 | G21: 230 | H21: =F21*G21 -> 1150
E22: chocolat wedjdane Blanc | F22: 12 | G22: 230 | H22: =F22*G22 -> 2760
E23: Feuilletine | F23: 0 | G23: 1350 | H23: =F23*G23 -> 0
E24: orgonza | F24: 6 | G24: 150 | H24: =F24*G24 -> 900
E25: fleur de décoration | F25: 1 | G25: 150 | H25: =F25*G25 -> 150
E26: quissetes doré | F26: 5 | G26: 100 | H26: =F26*G26 -> 500
E27: dentelle célophane | F27: 5 | G27: 150 | H27: =F27*G27 -> 750
E28: curdent | F28: 5 | G28: 55 | H28: =F28*G28 -> 275
... E59: sucre glace | F59: 12 | G59: 115 | H59: =F59*G59 -> 1380
E60: Semen Madina 1,8kg | F60: 7 | G60: 800 | H60: =F60*G60 -> 5600 | I60: 31/12
E61: Maa zehar | F61: 10 | G61: 62 | H61: =F61*G61 -> 620
E62: Tofia 2kg | F62: 0 | G62: 970 | H62: =F62*G62 -> 0
E63: Gherss 1kg Reda | F63: 12 | G63: 120 | H63: =F63*G63 -> 1440
E64: Farine SIM 1kg | F64: 6 | G64: 84 | H64: =F64*G64 -> 504
E65: pain tacos 10 pièces dans chaque | F65: 10 | G65: 330 | H65: =F65*G65 -> 3300
E66: Deyoul | F66: 3 | G66: 100 | H66: =F66*G66 -> 300
E67: Fleurial margarine 500g | F67: 22 | G67: 180 | H67: =F67*G67 -> 3960 | I67: 31/12
E68: Lait en poudre 1kg | F68: 5 | G68: 500 | H68: =F68*G68 -> 2500
E69: Pate d'arome citron | F69: 0.2 | G69: 780 | H69: =F69*G69 -> 156
E70: Pate d'arome vanille | F70: 0.2 | G70: 950 | H70: =F70*G70 -> 190
...

Sheet Salaires 
K8: Nom | L8: Salaire | M8: Avance | N8: Salaire à payer
K9: Sofiane | L9: 30000 | M9: 30000 | N9: =L9-M9 -> 0
K10: Amel | L10: 30000 | M10: 30000 | N10: =L10-M10 -> 0
J11: 1 | K11: Saida | L11: ='Pointage Bis'!C36 -> 29221.5 | M11: 29500 | N11: =L11-M11 -> -278.5
J12: 2 | K12: Fatiha | L12: ='Pointage Bis'!D36 -> 34650 | M12: 35000 | N12: =L12-M12 -> -350 | O12: 6000+3000+30000=39000
J13: 3 | K13: Nora | L13: ='Pointage Bis'!E36 -> 34650 | M13: 35000 | N13: =L13-M13 -> -350 | O13: 2500+32500
J14: 4 | K14: Ikram | L14: 34000 | M14: 34000 | N14: =L14-M14 -> 0 | O14: 2500+31500
J15: 5 | K15: Nour ElHouda | L15: ='Pointage Bis'!G36 -> 9240 | M15: 9500 | N15: =L15-M15 -> -260
J16: 6 | K16: Yasmine | L16: ='Pointage Bis'!H36+O16 -> 31500 | M16: 31500 | N16: =L16-M16 -> 0 | O16: 5000
J17: 7 | K17: Zohra | L17: ='Pointage Bis'!I36 -> 18480 | M17: 18500 | N17: =L17-M17 -> -20
J18: 8 | K18: Rayan | L18: ='Pointage Bis'!J36 -> 10800 | M18: 11000 | N18: =L18-M18 -> -200
J19: 9 | K19: Amina | L19: ='Pointage Bis'!K36 -> 12000 | M19: 12000 | N19: =L19-M19 -> 0
J20: 10 | K20: Sihem | L20: ='Pointage Bis'!L36 -> 5400 | M20: 5500 | N20: =L20-M20 -> -100 | O20: 3000+2500
J21: 11 | K21: Karima | L21: 26500 | M21: 26500 | N21: =L21-M21 -> 0
J22: 12 | K22: Meriem | L22: ='Pointage Bis'!N36 -> 32917.5 | M22: 33000 | N22: =L22-M22 -> -82.5
J23: 13 | K23: Ahlem | L23: 30000 | M23: 30000 | N23: =L23-M23 -> 0
J24: 14 | K24: Houda | L24: ='Pointage Bis'!P36 -> 18700 | M24: 19000 | N24: =L24-M24 -> -300
J25: 15 | K25: Selma | L25: ='Pointage Bis'!Q36 -> 4800 | M25: 5000 | N25: =L25-M25 -> -200
J26: 16 | K26: Aicha | L26: ='Pointage Bis'!R36 -> 6000 | M26: 6000 | N26: =L26-M26 -> 0
J27: 17 | K27: Rania | L27: ='Pointage Bis'!T36 -> 19000 | M27: 19000 | N27: =L27-M27 -> 0 | O27: Rania 3500+ Douaa 2500+Sara 8000Da+5000Da
J28: 18 | K28: Amina Ain Beniane | L28: ='Pointage Bis'!S36 -> 9600 | M28: 10000 | N28: =L28-M28 -> -400
J29: 19 | N29: =L29-M29 -> 0
K30: TOTAL | L30: =SUM(L9:L29) -> 427459 | M30: =SUM(M9:M29) -> 430000 | N30: =L30-M30 -> -2541
N31: =L31-M31 -> 0

Sheet Pointage détailé
B1: Date | C1: Saida | E1: Fatiha | G1: Nora | I1: Ikram | K1: Nour ElHouda | M1: Yasmine | O1: Zohra | Q1: Date | R1: Rayan | T1: Amina | V1: Sihem | X1: Karima | Z1: Meriem | AB1: Ahlem | AD1: Houda | AF1: Selma | AH1: Aicha | AJ1: Hanane | AL1: Sarah
B2: Heure | C2: Entrée | D2: Sortie | E2: Entrée | F2: Sortie | G2: Entrée | H2: Sortie | I2: Entrée | J2: Sortie | K2: Entrée | L2: Sortie | M2: Entrée | N2: Sortie | O2: Entrée | P2: Sortie | Q2: Heure | R2: Entrée | S2: Sortie | T2: Entrée | U2: Sortie | V2: Entrée | W2: Sortie | X2: Entrée | Y2: Sortie | Z2: Entrée | AA2: Sortie | AB2: Entrée | AC2: Sortie | AD2: Entrée | AE2: Sortie | AF2: Entrée | AG2: Sortie | AH2: Entrée | AI2: Sortie | AJ2: Entrée | AK2: Sortie | AL2: Entrée | AM2: Sortie | AN2: Entrée | AO2: Sortie | AP2: Entrée | AQ2: Sortie | AR2: Entrée | AS2: Sortie
A3: Mercredi | B3: 45658 | C3: 08h36 | D3: 15h45 | E3: 08h05 | F3: 17h00 | G3: 06h34 | H3: 16h45 | I3: 06h34 | J3: 16h45 | K3: / | L3: / | M3: 09h28 | N3: 14h06 | O3: 09h30 | P3: 17h30 | Q3: 45658 | R3: 08h43 | S3: 16h45 | T3: / | U3: / | X3: 08h00 | Y3: 16h40 | Z3: 08h30 | AA3: 16h30 | AB3: 07h35 | AC3: 15h44 | AD3: / | AE3: / | AF3: // | AG3: / | AH3: / | AI3: / | AJ3: / | AK3: / | AL3: / | AM3: /
A4: Jeudi | B4: 45659 | C4: 08h36 | D4: 15h50 | E4: 08h20 | F4: 14h06 | G4: 06h24 | H4: 15h55 | I4: 06h24 | J4: 15h55 | K4: / | L4: / | M4: 09h56 | N4: 13h24 | O4: / | P4: / | Q4: 45659 | R4: / | S4: / | T4: / | U4: / | X4: 08h05 | Y4: 16h30 | Z4: 08h20 | AA4: 16h30 | AB4: 08h05 | AC4: 15h30 | AD4: / | AE4: / | AF4: // | AG4: / | AH4: / | AI4: / | AJ4: / | AK4: / | AL4: / | AM4: /
A5: Vendredi | B5: 45660 | C5: / | D5: / | E5: 08h15 | F5: 15h30 | G5: 06h37 | H5: 16h10 | I5: 06h37 | J5: 16h10 | K5: / | L5: / | M5: 10h04 | N5: 17h37 | Q5: 45660 | R5: 09h05 | S5: 15h45 | T5: / | U5: / | V5: / | W5: / | X5: / | Y5: / | Z5: / | AA5: / | AB5: / | AC5: / | AD5: / | AE5: / | AF5: // | AG5: / | AH5: 09h05 | AI5: 15h45 | AJ5: / | AK5: / | AL5: / | AM5: /
A6: Samedi | B6: 45661 | C6: / | D6: / | E6: 08h25 | F6: 17h05 | G6: 06h37 | H6: 17h05 | I6: 06h37 | J6: 17h05 | K6: / | L6: / | M6: 10h01 | N6: 17h37 | O6: / | P6: / | Q6: 45661 | R6: 08h30 | S6: 16h40 | T6: / | U6: / | V6: / | W6: / | X6: / | Y6: / | Z6: / | AA6: / | AB6: 08h30 | AC6: 15h20 | AD6: / | AE6: / | AF6: 13h | AG6: 16h40 | AH6: 09h10 | AI6: 16h40 | AJ6: / | AK6: /// | AL6: / | AM6: /
A7: Dimanche | B7: 45662 | C7: 08h54 | D7: 16h30 | E7: 08h02 | F7: 16h45 | G7: / | H7: / | I7: 06h36 | J7: 16h46 | K7: / | L7: / | M7: 10h00 | N7: 17h30 | Q7: 45662 | R7: 11h20 | S7: 15h40 | T7: / | U7: / | V7: / | W7: / | X7: 08h20 | Y7: 13h45 | Z7: 08h20 | AA7: 13h45 | AB7: 08h30 | AC7: 15h30 | AD7: / | AE7: / | AF7: // | AG7: / | AH7: / | AI7: / | AJ7: / | AK7: / | AL7: / | AM7: /
A8: Lundi | B8: 45663 | C8: 09h14 | D8: 15h30 | E8: 08h14 | F8: 13h14 | G8: 06h38 | H8: 15h45 | I8: / | J8: / | K8: / | L8: / | M8: 10h13 | N8: 17h30 | O8: / | P8: / | Q8: 45663 | R8: 08h30 | S8: 16h20 | T8: 10h00 | U8: 15h00 | V8: / | W8: / | X8: / | Y8: / | Z8: 08h35 | AA8: 16h20 | AB8: 08h32 | AC8: 15h00 | AD8: / | AE8: / | AF8: // | AG8: / | AH8: / | AI8: / | AJ8: / | AK8: / | AL8: / | AM8: /
A9: Mardi | B9: 45664 | C9: 08h48 | D9: 16h | E9: 08h11 | F9: 17h20 | G9: 07h14 | H9: 16h46 | I9: 07h14 | J9: 16h46 | K9: / | L9: / | M9: 10h45 | N9: 17h49 | Q9: 45664 | R9: / | S9: / | T9: 08h00 | U9: 16h30 | V9: / | W9: / | X9: 08h030 | Y9: 16h33 | Z9: 08h40 | AA9: 16h33 | AB9: 08h32 | AC9: 14h40 | AD9: / | AE9: / | AF9: 09h30 | AG9: 12h00 | AH9: / | AI9: / | AJ9: / | AK9: / | AL9: / | AM9: /
A10: Mercredi | B10: 45665 | C10: 08h19 | D10: 15h50 | E10: 07h06 | F10: 16h34 | G10: 07h39 | H10: 16h42 | I10: 07h39 | J10: 16h42 | K10: 09h10 | L10: 17h35 | M10: / | N10: / | O10: 09h38 | P10: 17h30 | Q10: 45665 | R10: 08h39 | S10: 17h06 | T10: 08h41 | U10: 16h29 | V10: / | W10: / | X10: 07h41 | Y10: 17h19 | Z10: 08h41 | AA10: 16h29 | AB10: 08h26 | AC10: 15h52 | AD10: / | AE10: / | AF10: // | AG10: / | AH10: / | AI10: / | AJ10: / | AK10: / | AL10: / | AM10: /
A11: Jeudi | B11: 45666 | C11: 08h41 | D11: 15h46 | E11: 06h57 | F11: 17h19 | G11: 06h57 | H11: 17h10 | I11: 06h57 | J11: 17h10 | K11: / | L11: / | M11: 10h03 | N11: 17h32 | O11: / | P11: / | Q11: 45666 | R11: 08h27 | S11: 16h19 | T11: / | U11: / | V11: 08h27 | W11: 16h27 | X11: 07h35 | Y11: 16h35 | Z11: 09h30 | AA11: 16h31 | AB11: 06h57 | AC11: 15h20 | AD11: / | AE11: / | AF11: // | AG11: / | AH11: / | AI11: / | AJ11: / | AK11: / | AL11: / | AM11: /
A12: Vendredi | B12: 45667 | C12: / | D12: / | E12: 07h42 | F12: 18h00 | G12: 06h42 | H12: 17h45 | I12: 06h42 | J12: 17h45 | K12: / | L12: / | M12: 09h55 | N12: 18h00 | O12: 11h53 | P12: 18h00 | Q12: 45667 | R12: 08h50 | S12: 14h30 | T12: 08h50 | U12: 16h | V12: 08h50 | W12: 15h26 | X12: / | Y12: / | Z12: / | AA12: / | AB12: / | AC12: / | AD12: / | AE12: / | AF12: // | AG12: / | AH12: 08h50 | AI12: 15h26 | AJ12: / | AK12: / | AL12: / | AM12: /
A13: Samedi | B13: 45668 | C13: 08h35 | D13: 17h50 | E13: 08h10 | F13: 18h20 | G13: 06h23 | H13: 18h20 | I13: 06h23 | J13: 18h20 | K13: / | L13: / | M13: 09h58 | N13: 18h30/19h15 | O13: / | P13: / | Q13: 45668 | R13: 08h20 | S13: 17h05 | T13: 08h15 | U13: 18h15 | V13: 08h45 | W13: 17h00 | X13: / | Y13: / | Z13: 08h15 | AA13: 18h15 | AB13: 07h00 | AC13: 15h30 | AD13: / | AE13: / | AF13: // | AG13: / | AH13: / | AI13: / | AJ13: / | AK13: / | AL13: / | AM13: /
A14: Dimanche | B14: 45669 | C14: 08h30 | D14: 15h45 | E14: 07h30 | F14: 17h18 | G14: 12h51 | H14: 16h54 | I14: 06h54 | J14: 16h54 | K14: / | L14: / | M14: 10h13 | N14: 17h35 | O14: 11h20 | P14: 17h18 | Q14: 45669 | R14: / | S14: / | T14: 08h30 | U14: 16h30 | V14: 08h30 | W14: 16h30 | X14: / | Y14: / | Z14: 08h30 | AA14: 16h30 | AB14: 07h30 | AC14: 15h30 | AD14: / | AE14: / | AF14: / | AG14: / | AH14: / | AI14: / | AJ14: / | AK14: / | AL14: / | AM14: /
A15: Lundi | B15: 45670 | C15: 09h | D15: 15h42 | E15: 07h21 | F15: 15h42 | G15: 07h21 | H15: 15h39 | I15: / | J15: / | K15: / | L15: / | M15: 10h29 | N15: 17h27 | O15: / | P15: / | Q15: 45670 | R15: / | S15: / | T15: / | U15: / | V15: / | W15: / | X15: / | Y15: / | Z15: 08h21 | AB15: 07h40 | AD15: 08h21 | AF15: / | AG15: / | AH15: / | AI15: / | AJ15: / | AK15: / | AL15: / | AM15: /
A16: Mardi | B16: 45671 | C16: 09h21 | D16: 15h50 | E16: / | F16: / | G16: 07h19 | H16: 16h00 | I16: 07h19 | J16: 16h00 | K16: 09h45 | L16: 17h30 | M16: / | N16: / | O16: 11h30 | P16: 17h30 | Q16: 45671 | R16: / | S16: / | V16: / | W16: / | AH16: / | AI16: / | AJ16: 09h21 | AK16: 13h21 | AL16: 10h30 | AM16: 16h20
A17: Mercredi | B17: 45672 | C17: 09h30 | D17: 15h44 | E17: 07h55 | F17: 16h20 | G17: 06h47 | H17: 16h45 | I17: 06h47 | J17: 16h45 | K17: / | L17: / | M17: 10h11 | N17: 17h20 | O17: / | P17: / | Q17: 45672 | R17: / | S17: / | T17: / | U17: / | V17: / | W17: / | X17: 08h32 | Y17: 16h14 | Z17: 08h36 | AA17: 16h14 | AB17: 07h10 | AC17: 14h56 | AD17: 08h36 | AE17: 16h14 | AH17: / | AI17: / | AJ17: / | AK17: / | AL17: 09h00 | AM17: 15h55
A18: Jeudi | B18: 45673 | C18: 08h49 | D18: 16h00 | E18: 07h07 | F18: 17h40 | G18: 07h07 | H18: 16h30 | I18: 07h07 | J18: 16h30 | K18: / | L18: / | M18: 10h12 | N18: 17h27 | O18: 10h20 | P18: 17h40 | Q18: 45673 | R18: / | S18: / | T18: / | U18: / | V18: / | W18: / | X18: 08h20 | Z18: 08h25 | AB18: 07h05 | AD18: 08h25 | AH18: / | AI18: / | AJ18: / | AK18: / | AL18: 08h00 | AM18: 16h30
A19: Vendredi | B19: 45674 | C19: / | D19: / | E19: 07h50 | F19: 16h30 | G19: 07h50 | H19: 16h30 | I19: 07h50 | J19: 16h30 | K19: / | L19: / | M19: 09h56 | N19: 17h35 | O19: / | P19: / | Q19: 45674 | R19: / | S19: / | V19: / | W19: / | AJ19: / | AK19: / | AL19: / | AM19: /
A20: Samedi | B20: 45675 | C20: / | D20: / | E20: 07h45 | F20: 17h15 | G20: 07h55 | H20: 14h00 | I20: / | J20: / | K20: / | L20: / | M20: 10h11 | N20: 17h15 | O20: 10h30 | P20: 17h15 | Q20: 45675 | R20: / | S20: / | T20: / | U20: / | V20: / | W20: / | AJ20: / | AK20: / | AL20: / | AM20: /
A21: Dimanche | B21: 45676 | C21: 09h06 | D21: 16h10 | E21: / | F21: / | G21: 07h15 | H21: 16h10 | I21: 07h15 | J21: 16h10 | K21: // | L21: / | M21: 09h26 | N21: 17h36 | O21: / | P21: / | Q21: 45676 | R21: / | S21: / | V21: / | W21: / | AH21: / | AI21: / | AJ21: / | AK21: / | AL21: 08h00 | AM21: 16h10
A22: Lundi | B22: 45677 | E22: / | F22: / | G22: / | H22: / | Q22: 45677 | R22: / | S22: / | V22: / | W22: /
A23: Mardi | B23: 45678 | Q23: 45678 | R23: / | S23: / | V23: / | W23: /
A24: Mercredi | B24: 45679 | Q24: 45679 | R24: / | S24: / | V24: / | W24: /
A25: Jeudi | B25: 45680 | Q25: 45680 | R25: / | S25: /
A26: Vendredi | B26: 45681 | Q26: 45681 | R26: / | S26: /
A27: Samedi | B27: 45682 | Q27: 45682 | R27: / | S27: /
A28: Dimanche | B28: 45683 | Q28: 45683 | R28: / | S28: /
A29: Lundi | B29: 45684 | Q29: 45684 | R29: / | S29: /
A30: Mardi | B30: 45685 | Q30: 45685 | R30: / | S30: /
A31: Mercredi | B31: 45686 | Q31: 45686 | R31: / | S31: /////
A32: Jeudi | B32: 45687 | Q32: 45687 | R32: // | S32: /
A33: Vendredi | B33: 45688 | R33: / | S33: /

Sheet Pointage Bis
B1: Date | C1: Saida | D1: Fatiha | E1: Nora | F1: Ikram | G1: Nour ElHouda | H1: Yasmine | I1: Zohra | J1: Rayan | K1: Amina | L1: Sihem | M1: Karima | N1: Meriem | O1: Ahlem | P1: Houda | Q1: Selma | R1: Aicha | S1: Amina | T1: Rania
A2: Mercredi | B2: 45658 | C2: 1 | D2: 1 | E2: 1 | F2: 1 | G2: 0 | H2: 1 | I2: 1 | J2: 1 | K2: 0 | L2: 0 | M2: 1 | N2: 1 | O2: 1 | P2: 0 | R2: 0 | T2: 3.5 | U2: Rania
A3: Jeudi | B3: 45659 | C3: 1 | D3: 0.5 | E3: 1 | F3: 1 | G3: 0 | H3: 1 | I3: 0 | J3: 0 | K3: 0 | L3: 0 | M3: 1 | N3: 1 | O3: 1 | P3: 0 | R3: 0 | T3: 2.5 | U3: Douaa
A4: Vendredi | B4: 45660 | C4: 0 | D4: 1 | E4: 1 | F4: 1 | G4: 0 | H4: 1 | I4: 1 | J4: 1 | K4: 0 | L4: 0 | M4: 0 | N4: 0 | O4: 0 | P4: 0 | R4: 1 | T4: 8 | U4: Sara
A5: Samedi | B5: 45661 | C5: 0 | D5: 1 | E5: 1 | F5: 1 | G5: 0 | H5: 1 | I5: 0 | J5: 1 | K5: 0 | L5: 0 | M5: 0 | N5: 0 | O5: 1 | P5: 0 | Q5: 0.5 | R5: 1
A6: Dimanche | B6: 45662 | C6: 1 | D6: 1 | E6: 0 | F6: 1 | G6: 0 | H6: 1 | I6: 1 | J6: 0.5 | K6: 0 | L6: 0 | M6: 1 | N6: 1 | O6: 1 | P6: 0 | Q6: 0 | R6: 0
A7: Lundi | B7: 45663 | C7: 1 | D7: 1 | E7: 1 | F7: 0 | G7: 0 | H7: 1 | I7: 0 | J7: 1 | K7: 1 | L7: 0 | M7: 0 | N7: 1 | O7: 1 | P7: 0 | Q7: 0 | R7: 0
A8: Mardi | B8: 45664 | C8: 1 | D8: 1 | E8: 1 | F8: 1 | G8: 0 | H8: 1 | I8: 0 | J8: 0 | K8: 1 | L8: 0 | M8: 1 | N8: 1 | O8: 1 | P8: 0 | Q8: 0.5 | R8: 0
A9: Mercredi | B9: 45665 | C9: 1 | D9: 1 | E9: 1 | F9: 1 | G9: 1 | H9: 0 | I9: 1 | J9: 1 | K9: 1 | L9: 0 | M9: 1 | N9: 1 | O9: 1 | P9: 0 | Q9: 0 | R9: 0
A10: Jeudi | B10: 45666 | C10: 1 | D10: 1 | E10: 1 | F10: 1 | G10: 0 | H10: 1 | I10: 0 | J10: 1 | K10: 0 | L10: 1 | M10: 1 | N10: 1 | O10: 1 | P10: 0 | Q10: 0 | R10: 0
A11: Vendredi | B11: 45667 | C11: 0 | D11: 2 | E11: 2 | F11: 2 | G11: 0 | H11: 1 | I11: 1 | J11: 1 | K11: 1 | L11: 1 | M11: 0 | N11: 0 | O11: 0 | P11: 0 | Q11: 0 | R11: 1
A12: Samedi | B12: 45668 | C12: 2 | D12: 2 | E12: 2 | F12: 2 | G12: 0 | H12: 2 | I12: 0 | J12: 1.5 | K12: 1 | L12: 1.5 | M12: 0 | N12: 1 | O12: 1 | P12: 0 | R12: 0
A13: Dimanche | B13: 45669 | C13: 1.3 | D13: 1.5 | E13: 1 | F13: 1.5 | G13: 0 | H13: 1.5 | I13: 1 | J13: 0 | K13: 1 | L13: 1 | M13: 0 | N13: 1 | O13: 1 | P13: 0 | R13: 0
A14: Lundi | B14: 45670 | C14: 1 | D14: 1 | E14: 1 | F14: 0 | G14: 0 | H14: 1 | I14: 0 | J14: 0 | K14: 0 | L14: 0 | M14: 0 | N14: 1 | O14: 1 | P14: 1 | R14: 0
A15: Mardi | B15: 45671 | C15: 1 | D15: 0 | E15: 1 | F15: 1 | G15: 1 | H15: 0 | I15: 1 | J15: 0 | K15: 0 | L15: 0 | M15: 1 | N15: 1 | O15: 1 | P15: 1 | R15: 0
A16: Mercredi | B16: 45672 | C16: 1 | D16: 1 | E16: 1 | F16: 1 | G16: 0 | H16: 1 | I16: 0 | J16: 0 | K16: 0 | L16: 0 | M16: 1 | N16: 1 | O16: 1 | P16: 1 | R16: 0
A17: Jeudi | B17: 45673 | C17: 1 | D17: 1 | E17: 1 | F17: 1 | G17: 0 | H17: 1 | I17: 1 | J17: 0 | K17: 0 | L17: 0 | M17: 1 | N17: 1 | O17: 1 | P17: 1 | R17: 0
A18: Vendredi | B18: 45674 | C18: 0 | D18: 1 | E18: 1 | F18: 1 | G18: 0 | H18: 1 | I18: 0 | J18: 0 | K18: 1 | L18: 0 | M18: 0 | N18: 0 | O18: 0 | P18: 0 | R18: 1
A19: Samedi | B19: 45675 | C19: 0 | D19: 1 | E19: 1 | F19: 0 | G19: 0 | H19: 1 | I19: 1 | J19: 0 | K19: 0 | L19: 0 | M19: 1 | N19: 1 | O19: 1 | P19: 1 | R19: 1
A20: Dimanche | B20: 45676 | C20: 1 | D20: 0 | E20: 1 | F20: 1 | G20: 0 | H20: 1 | I20: 0 | J20: 0 | K20: 0 | L20: 0 | M20: 1 | N20: 1 | O20: 1 | P20: 1 | R20: 0
A21: Lundi | B21: 45677 | C21: 1 | D21: 0 | E21: 0 | F21: 1 | G21: 0 | H21: 0.5 | I21: 1 | J21: 0 | K21: 0 | L21: 0 | M21: 1 | N21: 1 | O21: 1 | P21: 1 | Q21: 0.5 | R21: 0
A22: Mardi | B22: 45678 | C22: 1 | D22: 0 | E22: 1 | F22: 1 | G22: 1 | H22: 0 | I22: 0 | J22: 0 | K22: 0 | L22: 0 | M22: 1 | N22: 1 | O22: 1 | P22: 1 | Q22: 0.5 | R22: 0
A23: Mercredi | B23: 45679 | C23: 1 | D23: 0 | E23: 1 | F23: 1 | G23: 1 | H23: 0 | I23: 1 | J23: 0 | K23: 1 | L23: 0 | M23: 1 | N23: 1 | O23: 1 | P23: 1 | Q23: 0 | R23: 0
A24: Jeudi | B24: 45680 | C24: 1 | D24: 0 | E24: 1 | F24: 1 | G24: 1 | H24: 0 | I24: 0 | J24: 0 | K24: 0 | L24: 0 | M24: 1 | N24: 1 | O24: 1 | P24: 1 | Q24: 0 | R24: 0
A25: Vendredi | B25: 45681 | C25: 0 | D25: 1 | E25: 1 | F25: 1 | G25: 0 | H25: 1 | I25: 1 | J25: 0 | K25: 1 | L25: 0 | M25: 0 | N25: 0 | O25: 0 | P25: 1 | Q25: 0 | R25: 0 | T25: 0
A26: Samedi | B26: 45682 | C26: 1 | D26: 1 | E26: 1 | F26: 1 | G26: 0 | H26: 1 | I26: 1 | J26: 0 | K26: 0 | L26: 0 | M26: 1 | N26: 1 | O26: 1 | P26: 0 | Q26: 1 | R26: 0 | S26: 1 | U26: Amina
A27: Dimanche | B27: 45683 | C27: 1 | D27: 1 | E27: 0 | F27: 1 | G27: 1 | H27: 0 | I27: 0 | J27: 0 | K27: 0 | L27: 0 | M27: 1 | N27: 1 | O27: 1 | P27: 1 | Q27: 0.5 | R27: 0 | S27: 1 | T27: 1 | U27: Aicha
A28: Lundi | B28: 45684 | C28: 1 | D28: 1 | E28: 1 | F28: 0 | G28: 1 | H28: 0 | I28: 1 | J28: 0 | K28: 0 | L28: 0 | M28: 1 | N28: 1 | O28: 1 | P28: 1 | Q28: 0 | R28: 0 | S28: 1 | T28: 1
A29: Mardi | B29: 45685 | C29: 1 | D29: 1 | E29: 1 | F29: 1 | G29: 0 | H29: 0 | I29: 0 | J29: 0 | K29: 0 | L29: 0 | M29: 1 | N29: 1 | O29: 1 | P29: 1 | Q29: 0.5 | R29: 0 | S29: 1 | T29: 1
A30: Mercredi | B30: 45686 | C30: 1 | D30: 1 | E30: 1 | F30: 1 | G30: 1 | H30: 0 | I30: 1 | J30: 0 | K30: 0 | L30: 0 | M30: 1 | N30: 1 | O30: 1 | P30: 1 | Q30: 0 | R30: 0 | S30: 1 | T30: 1
A31: Jeudi | B31: 45687 | C31: 1 | D31: 1 | E31: 1 | F31: 1 | G31: 0 | H31: 1 | I31: 0 | J31: 0 | K31: 0 | L31: 0 | M31: 1 | N31: 0 | O31: 1 | P31: 1 | Q31: 0 | R31: 0 | S31: 2 | T31: 1
A32: Vendredi | B32: 31/01/2025 | C32: 0 | D32: 1 | E32: 1 | F32: 1 | G32: 0 | H32: 1 | I32: 1 | J32: 0 | K32: 1 | L32: 0 | M32: 0 | N32: 1 | O32: 0 | P32: 1 | Q32: 0 | R32: 0 | S32: 1 | T32: 0
A33: Over Time | D33: 3 | J33: 0 | L33: 0 | M33: 2 | N33: 3.5
C34: =SUM(C2:C33) -> 25.3 | D34: =SUM(D2:D33) -> 30 | E34: =SUM(E2:E33) -> 30 | F34: =SUM(F2:F33) -> 29.5 | G34: =SUM(G2:G33) -> 8 | H34: =SUM(H2:H33) -> 23 | I34: =SUM(I2:I33) -> 16 | J34: =SUM(J2:J33) -> 9 | ... T34: =SUM(T2:T33) -> 19
C35: 1155 | D35: 1155 | E35: 1155 | F35: 1155 | G35: 1155 | H35: 1155 | I35: 1155 | J35: 1200 | K35: 1200 | L35: 1200 | M35: 1155 | N35: 1155 | O35: 1155 | P35: 1100 | Q35: 1200 | R35: 1200 | S35: 1200 | T35: 1000
C36: =C34*C35 -> 29221.5 | D36: =D34*D35 -> 34650 | E36: =E34*E35 -> 34650 | F36: =F34*F35 -> 34072.5 | G36: =G34*G35 -> 9240 | H36: 26500 | I36: =I34*I35 -> 18480 | J36: =J34*J35 -> 10800 | K36: =K34*K35 -> 12000 | L36: =L34*L35 -> 5400 | M36: =M34*M35 -> 26565 | N36: =N34*N35 -> 32917.5 | O36: =O34*O35 -> 30030 | P36: =P34*P35 -> 18700 | ... T36: =T34*T35 -> 19000

Sheet Sheet7
J20: Mois de Janvier 2025
I21: Recette | J21: 2033000
I22: Charges | J22: 854000
I23: Salaires | J23: 427000
I24: Che7i7a | J24: 62000
I25: Loyer+Dettes | J25: 180000
I26: Profit Net | J26: =J21-J22-J23-J24-J25 -> 510000
