Workbook

Sheet RECAP
B1: Date | C1: Recette de JUIN 2022 | D1: Recette | E1: Charges | F1: Salaire | G1: Loyer | H1: Net Profit | I1: Nb de jours | K1: Objectif | L1: Juin | M1: Bénéfice Moyen par jour | N1: Moyenne
A2: Vendredi | B2: 44743 | C2: 70000 | D2: 32000 | I2: 1 | K2: 70000 | L2: 70000 | M2: =H33/I33 -> 27588.572 | N2: =D33/I33 -> 76896.552
A3: Samedi | B3: 44744 | C3: 70000 | D3: 44000 | I3: 1 | K3: 70000 | L3: 70000
A4: Dimanche | B4: 44745 | C4: 20000 | D4: 110000 | I4: 1 | K4: 70000 | L4: 20000 | M4: Moyenne des charges par jour | N4: Objectif
A5: Lundi | B5: 44746 | C5: 60000 | D5: 114000 | I5: 1 | K5: 70000 | L5: 60000 | N5: 70000
A6: Mardi | B6: 44747 | C6: 40000 | D6: 120000 | I6: 1 | K6: 70000 | L6: 40000 | M6: ²
A7: Mercredi | B7: 44748 | C7: 40000 | D7: 100000 | I7: 1 | K7: 70000 | L7: 40000
A8: Jeudi | B8: 44749 | C8: 36000 | D8: 200000 | I8: 1 | K8: 70000 | L8: 36000 | M8: Cash restant | N8: Magasin | O8: caisse | P8: cash en attente pour le récupérer =Dettes éxterieurs
A9: Vendredi | B9: 44750 | C9: 50000 | D9: 96000 | I9: 1 | K9: 70000 | L9: 50000 | M9: =D33+N11-N12-E33-salaires!I29-N9 -> 1414900 | N9: =O9+P9 -> 0
A10: Samedi | B10: 44751 | C10: 65000 | D10: 0 | I10: 0 | K10: 0 | L10: 65000
A11: Dimanche | B11: 44752 | C11: 30000 | D11: 0 | I11: 0 | K11: 0 | L11: 30000 | M11: loyer | N11: 690000
A12: Lundi | B12: 44753 | C12: 30000 | D12: 54000 | I12: 1 | K12: 70000 | L12: 30000 | M12: pétrin+ four | N12: 220000 | P12: Lingoworld 17850+17900+18150+18000+18000 | Q12: 117300
A13: Mardi | B13: 44754 | C13: 70000 | D13: 65000 | I13: 1 | K13: 70000 | L13: 70000 | N13: 75000+145000 | P13: 89900-20000
A14: Mercredi | B14: 44755 | C14: 25000 | D14: 70000 | I14: 1 | K14: 70000 | L14: 25000 | P14: 12200+
A15: Jeudi | B15: 44756 | C15: 25000 | D15: 124000 | I15: 1 | K15: 70000 | L15: 25000
A16: Vendredi | B16: 44757 | C16: 50000 | D16: 42000 | I16: 1 | K16: 70000 | L16: 50000
A17: Samedi | B17: 44758 | C17: 62000 | D17: 45000 | I17: 1 | K17: 70000 | L17: 62000 | M17: Différence mois de juin
A18: Dimanche | B18: 44759 | C18: 55000 | D18: 44000 | I18: 1 | K18: 70000 | L18: 55000 | M18: =D33-C33 -> 820000
A19: Lundi | B19: 44760 | C19: 25000 | D19: 41000 | I19: 1 | K19: 70000 | L19: 25000 | M19: Différence objectif
A20: Mardi | B20: 44761 | C20: 47000 | D20: 94000 | I20: 1 | K20: 70000 | L20: 47000 | M20: =D33-K33 -> 200000
A21: Mercredi | B21: 44762 | C21: 46000 | D21: 92000 | I21: 1 | K21: 70000 | L21: 46000
A22: Jeudi | B22: 44763 | C22: 41000 | D22: 70000 | I22: 1 | K22: 70000 | L22: 41000
A23: Vendredi | B23: 44764 | C23: 55000 | D23: 40000 | I23: 1 | K23: 70000 | L23: 55000 | M23: Les vendredis
A24: Samedi | B24: 44765 | C24: 70000 | D24: 60000 | I24: 1 | K24: 70000 | L24: 70000 | M24: =D2+D9+D16+D23+D30 -> 270000
A25: Dimanche | B25: 44766 | C25: 35000 | D25: 66000 | I25: 1 | K25: 70000 | L25: 35000 | M25: =L9+L16+L23+L30 -> 204000
A26: Lundi | B26: 44767 | C26: 28000 | D26: 80000 | I26: 1 | K26: 70000 | L26: 28000 | M26: Cash réel
A27: Mardi | B27: 44768 | C27: 45000 | D27: 60000 | I27: 1 | K27: 70000 | L27: 45000 | M27: 850000
A28: Mercredi | B28: 44769 | C28: 45000 | D28: 64000 | I28: 1 | K28: 70000 | L28: 45000 | M28: rest à payer
A29: Jeudi | B29: 44770 | C29: 66000 | D29: 83000 | I29: 1 | K29: 70000 | L29: 66000 | M29: =M9-M27 -> 564900
A30: Vendredi | B30: 44771 | C30: 49000 | D30: 60000 | I30: 1 | K30: 70000 | L30: 49000
A31: Samedi | B31: 44772 | C31: 60000 | D31: 100000 | I31: 1 | K31: 70000 | L31: 60000
A32: Dimanche | B32: 44773 | C32: 0 | D32: 60000 | I32: 1 | K32: 70000 | L32: 0
C33: =SUM(C2:C32) -> 1410000 | D33: =SUM(D2:D32) -> 2230000 | E33: ='les Charges '!F471*1 -> 990000 | F33: ='Pointage '!Q35*1 -> 329931.4 | G33: 110000 | H33: =D33-G33-F33-E33 -> 800068.6 | I33: =SUM(I2:I32) -> 29 | K33: =SUM(K2:K32) -> 2030000
L34: =SUM(L2:L33) -> 1410000
C35: Objectif | D35: 2030000 | E35: 800000 | F35: 380000 | G35: 110000 | H35: =D35-E35-F35-G35 -> 740000
C36: Mois de Juin | D36: 1410000 | E36: 717246 | F36: 321402 | G36: 110000 | H36: 260000
C39: La différence | D39: =D33-D36 -> 820000 | E39: =E33-E36 -> 272754 | F39: =F33-F36 -> 8529.4025 | G39: =G33-G36 -> 0 | H39: =H33-H36 -> 540068.6

Sheet les Charges 
B1: -(
C2: Produit | D2: Quantité | E2: Prix unitaire | F2: Prix | G2: Date d'achat
C3: crème fraiche | D3: 6 | E3: 250 | F3: 1500 | G3: 44743
C4: bessel | D4: 25kg | E4: 40 | F4: 1000 | G4: 44743
C5: 3akeri | D5: 1 | E5: 850 | F5: 850 | G5: 44743
C6: Chocolat à tartier Boudjedir | D6: 0.5 | E6: 4800 | F6: =D6*E6 -> 2400 | G6: 44743
C7: Maiizina | D7: 25kg | E7: 4750 | F7: 4750 | G7: 44743
C8: Lait en Poudre | D8: 1 sachet de 25kg/5kg | E8: 565 | F8: 2825 | G8: 44501
C9: Pate d'arome Maa zehar | D9: 1 | E9: 780 | F9: 780 | G9: 44743
C10: Sucre glace | D10: 1 fardeau | E10: 1680 | F10: 1680 | G10: 44743
C11: boites blanches | D11: 1 fardeau | E11: 1650 | F11: 1650 | G11: 44743
C12: Tofia | D12: 3 | E12: 270 | F12: 810 | G12: 44743
C13: Amande | D13: 100g | E13: 1900 | F13: 190 | G13: 44743
C14: pistache | D14: 100g | E14: 4000 | F14: 400 | G14: 44743
C15: Noix de Kajou | D15: 100g | E15: 2500 | F15: 250 | G15: 44743
C16: quissetes | D16: 4 | E16: 520 | F16: 520 | G16: 44743
C17: Margarine Salha | D17: 1 | E17: 210 | F17: 210 | G17: 44743
C18: Fromage Slices | D18: 10 | E18: 210 | F18: 2100 | G18: 44743
C19: rechta | D19: 20kg | E19: 120 | F19: 2400 | G19: 44743
C20: blanc de poulet | D20: 3kg | E20: 700 | F20: 2100 | G20: 44743
C21: pomme de terre | D21: 7.5kg | E21: 80 | F21: 600 | G21: 44743
C22: sel | D22: 4 | E22: 25 | F22: 100 | G22: 44743
C23: poivron noir | D23: / | E23: / | F23: 100 | G23: 44743
C24: poichiche | D24: 1kg | E24: 400 | F24: 400 | G24: 44743
C25: Souad ka3ek nakach | D25: 450 | E25: 50 | F25: 22500 | G25: 44743
C26: Boites 48/10 | D26: 7 | E26: 2700 | F26: =D26*E26 -> 18900 | G26: 44641
C27: semoule fine Sa7el 10kg | D27: 10 | E27: 650 | F27: =E27*D27 -> 6500 | G27: 44672
C28: Quissettes dorée N10 | D28: 1 fardeau de 80 | E28: 30 | F28: 2400 | G28: 44641
C29: Quissettes blanc N12 | D29: 1 fardeau de 40 | E29: 30 | F29: 1200 | G29: 44641
C30: Quissetes blanc N 10 | D30: 1 fardeau de 36 | E30: 25 | F30: 900 | G30: 44641
C31: Quissettes blanc N8 | D31: 1 fardeau de 110 | E31: 44689 | F31: 935 | G31: 44641
C32: fleur artificièlle | D32: 36 | E32: 70 | F32: 2520 | G32: 44629
C33: Mayonnaise 1kg | D33: 5 Bouteille | E33: 160 | F33: 800 | G33: 44593
C34: Vinaigre 1 litre | D34: 6 | E34: 60 | F34: 360 | G34: 44593
C35: Levure Chimique 100 Sachets /Boite | D35: 4 | E35: 375 | F35: =D35*E35 -> 1500 | G35: 44562
C36: gherss | D36: 10 | E36: 150 | F36: =D36*E36 -> 1500 | G36: 44636
C37: pate à filo | D37: 1 | E37: 300 | F37: 300 | G37: 44739
C38: boites raib | D38: 1 | E38: 1100 | F38: 1100 | G38: 44739
C39: fourchette | D39: 6 | E39: 150 | F39: 900 | G39: 44739
C40: barquettes1165 | D40: 10 | E40: 75 | F40: 750 | G40: 44739
...

Sheet Pointage 
B1: Date | C1: Zehor | D1: Soumia | E1: Nadjet | F1: Hadjer | G1: djamila | H1: Farida | I1: Yousera | J1: Lynda | K1: Samira | L1: Hafidha | M1: Yasmine | N1: Fouzia | O1: Wahiba | P1: Zahida | Q1: Remarque
A2: Vendredi | B2: 44743 | C2: 0 | D2: 0 | E2: 0 | F2: 0 | G2: 1 | H2: 0 | I2: 0 | J2: 1 | K2: 0 | L2: 1 | M2: 0 | N2: 1 | O2: 1 | P2: 1
A3: Samedi | B3: 44744 | C3: 0 | D3: 1 | E3: 1 | F3: 0 | G3: 1 | H3: 0 | I3: 1 | J3: 1 | K3: 1 | L3: 1 | M3: 0 | N3: 1 | O3: 0 | P3: 1
A4: Dimanche | B4: 44745 | C4: 1 | D4: 1 | E4: 1 | F4: 0 | G4: 1 | H4: 0 | I4: 1 | J4: 1 | K4: 1 | L4: 1 | M4: 0 | N4: 0.5 | O4: 1 | P4: 1
A5: Lundi | B5: 44746 | C5: 1 | D5: 1 | E5: 1 | F5: 1 | G5: 1 | H5: 1 | I5: 1 | J5: 1 | K5: 1 | L5: 1 | M5: 0 | N5: 1 | O5: 1 | P5: 1
A6: Mardi | B6: 44747 | C6: 1 | D6: 0.5 | E6: 2 | F6: 0 | G6: 1 | H6: 1 | I6: 1 | J6: 1 | K6: 1 | L6: 0 | M6: 0 | N6: 1 | O6: 1 | P6: 0
A7: Mercredi | B7: 44748 | C7: 1 | D7: 1 | E7: 1 | F7: 1 | G7: 1 | H7: 1 | I7: 1 | J7: 1 | K7: 0 | L7: 1 | M7: 0 | N7: 1 | O7: 2 | P7: 2
A8: Jeudi | B8: 44749 | C8: 1 | D8: 2 | E8: 2 | F8: 1 | G8: 1 | H8: 1 | I8: 2 | J8: 2 | K8: 1 | L8: 1 | M8: 0 | N8: 1 | O8: 2 | P8: 2
A9: Vendredi | B9: 44750 | C9: 1 | D9: 0 | E9: 1 | F9: 1 | G9: 1 | H9: 1 | I9: 0 | J9: 1 | K9: 1 | L9: 1 | M9: 0 | N9: 1 | O9: 1 | P9: 2
A10: Samedi | B10: 44751 | C10: 0 | D10: 0 | E10: 0 | F10: 0 | G10: 0 | H10: 0 | I10: 0 | J10: 0 | K10: 0 | L10: 0 | M10: 0 | N10: 0 | O10: 0 | P10: 0
A11: Dimanche | B11: 44752 | C11: 0 | D11: 0 | E11: 0 | F11: 0 | G11: 0 | H11: 0 | I11: 0 | J11: 0 | K11: 0 | L11: 0 | M11: 0 | N11: 0 | O11: 0 | P11: 0
A12: Lundi | B12: 44753 | C12: 1 | D12: 1 | E12: 1 | F12: 1 | G12: 0 | H12: 1 | I12: 0 | J12: 1 | K12: 0 | L12: 1 | M12: 0 | N12: 1 | O12: 1 | P12: 1
A13: Mardi | B13: 44754 | C13: 0 | D13: 1 | E13: 0 | F13: 1 | G13: 0 | H13: 0 | I13: 1 | J13: 1 | K13: 1 | L13: 1 | M13: 0 | N13: 1 | O13: 1 | P13: 1
... A32: Dimanche | B32: 44773 | C32: 1 | D32: 1 | E32: 1 | F32: 0 | G32: 1 | H32: 1 | I32: 0 | J32: 1 | K32: 0 | L32: 1 | M32: 0.5 | N32: 1 | O32: 1 | P32: 0
C33: =SUM(C2:C32) -> 25 | D33: =SUM(D2:D32) -> 21.75 | E33: =SUM(E2:E32) -> 23 | F33: =SUM(F2:F32) -> 12 | G33: =SUM(G2:G32) -> 16 | H33: =SUM(H2:H32) -> 21.5 | I33: =SUM(I2:I32) -> 20.75 | J33: =SUM(J2:J32) -> 31.5 | ... P33: =SUM(P2:P32) -> 22
C34: 1923 | D34: 1153.85 | E34: 1153.85 | F34: 1153.85 | G34: 1000 | H34: 961.54 | I34: 961.54 | J34: 961.54 | K34: 961.54 | L34: 1153.85 | M34: 1000 | N34: 1153.85 | O34: 1000 | P34: 1153.85
C35: =C34*C33 -> 48075 | D35: =D34*D33 -> 25096.237 | E35: =E34*E33 -> 26538.55 | F35: =F34*F33 -> 13846.2 | G35: =G34*G33 -> 16000 | H35: =H34*H33 -> 20673.11 | I35: =I34*I33 -> 19951.955 | J35: =J34*J33 -> 30288.51 | ... O35: =O34*O33 -> 26000 | P35: =P33*P34 -> 25384.7 | Q35: =SUM(C35:P35) -> 329931.4
Y40: Vendredi | Z40: 44743 | AA40: 1 | AZ40: Date
Y41: Samedi | Z41: 44744 | AA41: 1 | AY41: Vendredi | AZ41: 44743
Y42: Dimanche | Z42: 44745 | AA42: 1 | AY42: Samedi | AZ42: 44744
Y43: Lundi | Z43: 44746 | AA43: 1 | AY43: Dimanche | AZ43: 44745
Y44: Mardi | Z44: 44747 | AA44: 0 | AY44: Lundi | AZ44: 44746
Y45: Mercredi | Z45: 44748 | AA45: 2 | AY45: Mardi | AZ45: 44747
Y46: Jeudi | Z46: 44749 | AA46: 2 | AY46: Mercredi | AZ46: 44748
Y47: Vendredi | Z47: 44750 | AA47: 2 | AY47: Jeudi | AZ47: 44749
Y48: Samedi | Z48: 44751 | AA48: 0 | AY48: Vendredi | AZ48: 44750
Y49: Dimanche | Z49: 44752 | AA49: 0 | AY49: Samedi | AZ49: 44751
Y50: Lundi | Z50: 44753 | AA50: 1 | AY50: Dimanche | AZ50: 44752
Y51: Mardi | Z51: 44754 | AA51: 1 | AY51: Lundi | AZ51: 44753
Y52: Mercredi | Z52: 44755 | AA52: 1 | AY52: Mardi | AZ52: 44754
... Y70: Dimanche | Z70: 44773 | AA70: 0 | AY70: Samedi | AZ70: 44772
AA71: =SUM(AA40:AA70) -> 22 | AY71: Dimanche | AZ71: 44773
AZ75: Date | BA75: Fouzia
AY76: Vendredi | AZ76: 44743 | BA76: 1
AY77: Samedi | AZ77: 44744 | BA77: 1
AY78: Dimanche | AZ78: 44745 | BA78: 0.5
AY79: Lundi | AZ79: 44746 | BA79: 1
AY80: Mardi | AZ80: 44747 | BA80: 1
AY81: Mercredi | AZ81: 44748 | BA81: 1
AY82: Jeudi | AZ82: 44749 | BA82: 1
...

Sheet salaires
G16: Nom | H16: Salaire | I16: Avance | J16: Salaire à payer
F17: 1 | G17: Zehor | H17: ='Pointage '!C35*1 -> 48075 | I17: 48000 | J17: =H17-I17 -> 75
F18: 2 | G18: Soumia | H18: ='Pointage '!D35*1 -> 25096.237 | I18: 25000 | J18: =H18-I18 -> 96.2375 | K18: 2000+1000
F19: 3 | G19: Nadjet | H19: ='Pointage '!E35*1 -> 26538.55 | I19: 26600 | J19: =H19-I19 -> -61.45
F20: 4 | G20: Hadjer | H20: ='Pointage '!F35*1 -> 13846.2 | I20: 14000 | J20: =H20-I20 -> -153.8
F21: 5 | G21: Djamila | H21: ='Pointage '!G35*1 -> 16000 | I21: 16000 | J21: =H21-I21 -> 0
F22: 6 | G22: Fouzia | H22: ='Pointage '!N35*1 -> 27692.4 | I22: 28000 | J22: =H22-I22 -> -307.6
F23: 7 | G23: Hafida | H23: ='Pointage '!L35*1 -> 30000.1 | I23: 30000 | J23: =H23-I23 -> 0.1 | K23: 2000+2000+1000+2000
F24: 8 | G24: Samira | H24: ='Pointage '!K35*1 -> 15384.64 | I24: 15500 | J24: =H24-I24 -> -115.36
F25: 9 | G25: Youssera | H25: ='Pointage '!I35*1 -> 19951.955 | I25: 20000 | J25: =H25-I25 -> -48.045 | K25: 1000+2500
F26: 10 | G26: Farida | H26: ='Pointage '!H35*1 -> 20673.11 | I26: 21000 | J26: =H26-I26 -> -326.89
F27: 11 | G27: Wahiba | H27: ='Pointage '!O35*1 -> 26000 | I27: 26000 | J27: =H27-I27 -> 0
F28: 12 | G28: Zahida | H28: ='Pointage '!P35*1 -> 25384.7 | I28: 25000 | J28: =H28-I28 -> 384.7 | K28: 4000+25000+15000
G29: TOTAL | H29: =SUM(H17:H28) -> 294642.89 | I29: =SUM(I17:I28) -> 295100 | J29: =SUM(J17:J28) -> -457.1075
G30: =H29-I29 -> -457.1075 | J30: =H30-I30 -> 0

Sheet Bénéfice de juin
B6: 260000 | C6: Bénéfice Mois de Juin
B7: 40000 | C7: Avocat 2 ème partie
B8: 195000 | C8: Sofiane
B9: 25000 | C9: Chèque Fouzi
B10: =B6-B7-B8-B9 -> 0 | C10: reste du Bénifice du Mois de Juin
D13: Sofiane 14000+4000+ 2000+10000+50000+88000+27000 | E13: messerouf + balance + storm +messserouf+ vetements + chèque+restes du bénéfice
D15: Hotel bay diab 46000+46000+46000-50000-88000
K16: Mois de Janvier | L16: Mois de Février | M16: Mois de Mars | N16: Mois d'Avril | O16: Mois de Mai | P16: Mois de Juin | Q16: Mois de Juillet
J17: Recette | K17: 1051000 | L17: 1300000 | M17: 700000 | N17: 2197000 | O17: 1186000 | P17: 1410000 | Q17: 2230000
J18: Charges | K18: 435000 | L18: 462400 | M18: 690000 | N18: 1033000 | O18: 639000 | P18: 717000 | Q18: 990000
J19: Salaires | K19: 226000 | L19: 277600 | M19: 300000 | N19: 331500 | O19: 257000 | P19: 321000 | Q19: 330000
J20: Loyer | K20: 90000 | L20: 90000 | M20: 110000 | N20: 110000 | O20: 110000 | P20: 110000 | Q20: 110000
J21: Profit Net | K21: 300000 | L21: 470000 | M21: 600000 | N21: 720000 | O21: 180000 | P21: 260000 | Q21: 800000
G25: Mois de Juin | H25: Mois de Juillet
F26: Recette | G26: 1410000 | H26: 2230000
F27: Charges | G27: 717000 | H27: 990000
F28: Salaires | G28: 321000 | H28: 330000
F29: Loyer | G29: 110000 | H29: 110000
F30: Profit Net | G30: 260000 | H30: 800000
