Workbook

Sheet RECAP
B1: Date | C1: Recette | D1: Charges | E1: Salaire | F1: Loyer | G1: Net Profit | H1: Nb de jours
A2: samedi | B2: 44044 | C2: 0 | H2: 0
A3: dimanche | B3: 44045 | C3: 0 | H3: 0
A4: lundi | B4: 44046 | C4: 16000 | H4: 1 | L4: Myenne | Q4: Sofiane | R4: Amel
A5: mardi | B5: 44047 | C5: 10000 | H5: 1 | L5: =C33/H33 -> 19560 | Q5: 43000 | R5: 24000
A6: mercredi | B6: 44048 | C6: 15000 | H6: 1
A7: jeudi | B7: 44049 | C7: 25000 | H7: 1 | Q7: 10000 | R7: 45200
A8: vendredi | B8: 44050 | C8: 0 | D8: 0 | E8: 0 | F8: 0 | G8: 0 | H8: 0
A9: samedi | B9: 44051 | C9: 12000 | H9: 1
A10: dimanche | B10: 44052 | C10: 13000 | H10: 1
A11: lundi | B11: 44053 | C11: 16000 | H11: 1
A12: mardi | B12: 44054 | C12: 12000 | H12: 1
A13: mercredi | B13: 44055 | C13: 17000 | H13: 1
A14: jeudi | B14: 44056 | C14: 31000 | H14: 1
A15: vendredi | B15: 44057 | C15: 0 | D15: 0 | E15: 0 | F15: 0 | G15: 0 | H15: 0
A16: samedi | B16: 44058 | C16: 11000 | H16: 1 | L16: Cash restant | M16: Magasin
A17: dimanche | B17: 44059 | C17: 8000 | H17: 1 | L17: =C33+Charges!H83-Charges!H82-Salaires!K20-M17-Q7-R7 -> 165000 | M17: 4000
A18: lundi | B18: 44060 | C18: 15000 | H18: 1
A19: mardi | B19: 44061 | C19: 15000 | H19: 1
A20: mercredi | B20: 44062 | C20: 41000 | H20: 1
A21: jeudi | B21: 44063 | C21: 33000 | H21: 1
A22: vendredi | B22: 44064 | C22: 0 | D22: 0 | E22: 0 | F22: 0 | G22: 0 | H22: 0
A23: Samedi | B23: 44065 | C23: 23000 | H23: 1
A24: Dimanche | B24: 44066 | C24: 14000 | H24: 1
A25: Lundi | B25: 44067 | C25: 14000 | H25: 1
A26: Mardi | B26: 44068 | C26: 16000 | H26: 1
A27: Mercredi | B27: 44069 | C27: 20000 | H27: 1
A28: Jeudi | B28: 44070 | C28: 43000 | H28: 1
A29: vendredi | B29: 44071 | C29: 4000 | H29: 0
A30: Samedi | B30: 44072 | C30: 24000 | H30: 1
A31: Dimanche | B31: 44073 | C31: 16000 | H31: 1
A32: Lundi | B32: 44074 | C32: 25000 | H32: 1
A33: TOTAL | C33: =SUM(C2:C32) -> 489000 | D33: =Charges!H82*1 -> 198400 | E33: =Salaires!J20*1 -> 122800 | F33: 77000 | G33: =C33-D33-E33-F33 -> 90800 | H33: =SUM(H2:H32) -> 25
A34: TAUX | C34: 1 | D34: =D33/C33 -> 0.40572597 | E34: =E33/C33 -> 0.25112474 | F34: =F33/C33 -> 0.15746421 | G34: =G33/C33 -> 0.18568507

Sheet Pointage
B1: Date | C1: Zehor | D1: Zoubida | E1: Amel | F1: Karima | G1: Nadjet | H1: Louiza | I1: Nouara | J1: Zahida | K1: Remarque
A2: samedi | B2: 44044 | C2: 0 | D2: 0 | E2: 0 | F2: 0 | G2: 0 | H2: 0 | I2: 0 | J2: 0
A3: dimanche | B3: 44045 | C3: 0 | D3: 0 | E3: 0 | F3: 0 | G3: 0 | H3: 0 | I3: 0 | J3: 0
A4: lundi | B4: 44046 | C4: 1 | D4: 0 | E4: 0 | F4: 1 | G4: 0 | H4: 0 | I4: 1 | J4: 0
A5: mardi | B5: 44047 | C5: 1 | D5: 0 | E5: 1 | F5: 1 | G5: 0 | H5: 0 | I5: 0 | J5: 0
A6: mercredi | B6: 44048 | C6: 1 | D6: 1 | E6: 1 | F6: 1 | G6: 0 | H6: 0 | I6: 1 | J6: 0
A7: jeudi | B7: 44049 | C7: 1 | D7: 1 | E7: 1 | F7: 1 | G7: 0 | H7: 0 | I7: 1 | J7: 0
A8: vendredi | B8: 44050 | C8: 0 | D8: 0 | E8: 0 | F8: 0 | G8: 0 | H8: 0 | I8: 0 | J8: 0
A9: samedi | B9: 44051 | C9: 1 | D9: 0 | E9: 1 | F9: 1 | G9: 0 | H9: 0 | I9: 1 | J9: 1
A10: dimanche | B10: 44052 | C10: 1 | D10: 1 | E10: 1 | F10: 1 | G10: 0 | H10: 0 | I10: 1 | J10: 1
A11: lundi | B11: 44053 | C11: 1 | D11: 1 | E11: 1 | F11: 1 | G11: 0 | H11: 0 | I11: 1 | J11: 1
A12: mardi | B12: 44054 | C12: 0 | D12: 1 | E12: 1 | F12: 1 | G12: 0 | H12: 0 | I12: 1 | J12: 1
A13: mercredi | B13: 44055 | C13: 0 | D13: 1 | E13: 1 | F13: 1 | G13: 0 | H13: 0 | I13: 1 | J13: 1
... A30: Samedi | B30: 44072 | C30: 1 | D30: 0 | E30: 1 | F30: 0 | G30: 0 | H30: 1 | I30: 1 | J30: 1
A31: Dimanche | B31: 44073 | C31: 1 | D31: 0 | E31: 1 | F31: 0 | G31: 0 | H31: 1 | I31: 1 | J31: 1 | N31: 44065
A32: Lundi | B32: 44074 | C32: 1 | D32: 0 | E32: 0 | F32: 0 | G32: 1 | H32: 1 | I32: 1 | J32: 0 | N32: 42200
B33: Total | C33: =SUM(C2:C32) -> 11 | D33: =SUM(D2:D32) -> 19 | E33: =SUM(E2:E32) -> 23 | F33: =SUM(F2:F32) -> 21 | G33: =SUM(G2:G32) -> 2 | H33: =SUM(H2:H32) -> 4 | I33: =SUM(I2:I32) -> 14 | J33: =SUM(J2:J32) -> 20
B34: Salaire/jour | C34: 2000 | D34: 1200 | E34: 1000 | F34: 600 | G34: 1000 | H34: 600 | I34: 1000 | J34: 1200 | K34: =SUM(C34:J34) -> 8600 | N34: Economiser
B35: SALAIRES | C35: =C34*C33 -> 22000 | D35: =D34*D33 -> 22800 | E35: =E34*E33 -> 23000 | F35: =F34*F33 -> 12600 | G35: =G34*G33 -> 2000 | H35: =H34*H33 -> 2400 | I35: =I34*I33 -> 14000 | J35: =J33*J34 -> 24000 | K35: =SUM(C35:J35) -> 122800 | N35: 45200

Sheet Charges
F3: Produit | G3: Quantité | H3: Prix | I3: Date d'achat
F4: Semoule Fine Elbaraka | G4: 47 sachets de 10kg | H4: 25850 | I4: 44046
F5: Huile | G5: 10 bidons de 5 litres | H5: 5300 | I5: 44046
F6: Transport | G6: 1 | H6: 450 | I6: 44046
F7: bessel | G7: 15kg | H7: 450 | I7: 44047
F8: Levure chimique | G8: 1 boite | H8: 380 | I8: 44048
F9: margarine Mani | G9: 1 carton | H9: 2760 | I9: 44048
F10: Fromage spéciale pizza | G10: 12.2kg | H10: 2560 | I10: 44048
F11: Harrissa | G11: 1 carton de 24 boites | H11: 2460 | I11: 44048
F12: Maa zehar | G12: 1 carton de 12 B | H12: 660 | I12: 44048
F13: Sucre | G13: 1 Fardeau de 10kg | H13: 700 | I13: 44048
F14: Lait en poudre | G14: 2kg | H14: 1480 | I14: 44048
F15: Fromage Gouda | G15: 2kg | H15: 2600 | I15: 44048
F16: Sel | G16: fardeau | H16: 330 | I16: 44048
F17: Tomate conserve | G17: 5 boites | H17: 500 | I17: 44048
F18: Boites 48/10 | G18: 2 cartons | H18: 2800 | I18: 44048
... F24: chocolat Widjedane | G24: 4 boites | H24: 600 | I24: 44048
C25: f | F25: serviette en papier | G25: 10 paquets | H25: 550 | I25: 44048
F26: papier roulou | G26: 1 | H26: 650 | I26: 44048
F27: prix | G27: 1 sachet | H27: 150 | I27: 44048
F28: papier Aluminium | G28: 1 | H28: 110 | I28: 44048
F29: Baghrir | G29: 44jours | H29: 20000 | I29: 44049
F30: bessel | G30: 77kg | H30: 1700 | I30: 44049
F31: bessel | G31: 10kg | H31: 400 | I31: 44049
F32: poulet haché | G32: 2kg | H32: 1200 | I32: 44049
F33: Viande hachée | G33: / | H33: 500 | I33: 44049
F34: Tomate fraiche | G34: 2.5kg | H34: 100 | I34: 44049
F35: Rechta | G35: 20 | H35: 1600 | I35: 44049
F36: Transport | G36: 1 | H36: 500 | I36: 44049
F37: insecticid ( cafards) | G37: 1 | H37: 200 | I37: 44049
F38: poulet haché | H38: 500
F39: Recheta | G39: 20kg | H39: 2000
F40: huile fridor de 10 litres | G40: 10 | H40: 11000 | I40: 44057
F41: bessel | G41: 35kg | H41: 750
F42: kossber maadenouss na3ena3 | G42: 8 | H42: 200 | I42: 44059
F43: tomate | G43: 5 kg | H43: 200
F44: boissons | H44: 4500
F45: Sofiane achats | H45: 4000
F46: les gants | G46: 1 boite | H46: 1000 | I46: 44060
F47: tomate conserve | G47: 1 carton | H47: 2460 | I47: 44060
...

Sheet Salaires
I11: Nom | J11: Salaire | K11: Avance | L11: Rest à payer
H12: 1 | I12: Zehor | J12: =Pointage!C35*1 -> 22000 | K12: 14000 | L12: =J12-K12 -> 8000
H13: 2 | I13: Karima | J13: =Pointage!F35*1 -> 12600 | K13: 12600 | L13: =J13-K13 -> 0
H14: 3 | I14: Amel | J14: =Pointage!E35*1 -> 23000 | K14: 23000 | L14: =J14-K14 -> 0
H15: 4 | I15: Nowara | J15: =Pointage!I35*1 -> 14000 | K15: 9000 | L15: =J15-K15 -> 5000
H16: 5 | I16: Zoubida | J16: =Pointage!D35*1 -> 22800 | K16: 22800 | L16: =J16-K16 -> 0
H17: 6 | I17: Nadjet | J17: =Pointage!G35*1 -> 2000 | K17: 1000 | L17: =J17-K17 -> 1000
H18: 7 | I18: Louiza | J18: =Pointage!H35*1 -> 2400 | K18: 0 | L18: =J18-K18 -> 2400
H19: 8 | I19: Zahida | J19: =Pointage!J35*1 -> 24000 | K19: 24000 | L19: =J19-K19 -> 0
I20: TOTAL | J20: =SUM(J12:J19) -> 122800 | K20: =SUM(K12:K19) -> 106400
J21: =J20-K20 -> 16400

Sheet Gateaux Souad
H5: Date | I5: Gateau | J5: Quantité | K5: Prix unitaire | L5: Totale
I6: 7alewet taba3 | J6: 28 | K6: 25 | L6: =K6*J6 -> 700
I7: 7alwet taba3 | J7: 29 | K7: 25 | L7: =K7*J7 -> 725
I8: ka3ek na9ach | J8: 46 | K8: 50 | L8: =K8*J8 -> 2300
H9: 44065 | I9: Taba3 | J9: 29 | K9: 25 | L9: =K9*J9 -> 725
H10: 44066 | I10: Na9ack | J10: 46 | K10: 50 | L10: =K10*J10 -> 2300
H20: Totale | L20: =SUM(L6:L19) -> 6750
H21: Versé | L21: 8000
H22: Reste à payer | L22: =L20-L21 -> -1250
