Workbook

Sheet RECAP
B1: Date | C1: Recette Mai 2023 | D1: Recette | E1: Charges | F1: Salaire | G1: Loyer | H1: Net Profit | I1: Nb de jours | K1: Objectif | L1: Mai | M1: Bénéfice Moyen par jour | N1: Moyenne | O1: Moyenne salaire | P1: pourcentage du salaire vis à vis la recettte
A2: Jeudi | B2: 45078 | C2: 40000 | D2: 120000 | I2: 1 | L2: 40000 | M2: =H33/I33 -> 15558.444 | N2: =D33/I33 -> 58407.407 | P2: =O2/N2 -> 0
A3: vendredi | B3: 45079 | C3: 59000 | D3: 85000 | I3: 1 | L3: 59000
A4: samedi | B4: 45080 | C4: 55000 | D4: 42000 | I4: 1 | L4: 55000 | M4: Moyenne des charges par jour | N4: Objectif
A5: dimanche | B5: 45081 | C5: 65000 | D5: 38000 | I5: 1 | L5: 65000 | M5: =E33/I33 -> 26522.556 | N5: 100000
A6: lundi | B6: 45082 | C6: 97000 | D6: 45000 | I6: 1 | L6: 97000 | M6: ²
A7: mardi | B7: 45083 | C7: 114000 | D7: 40000 | I7: 1 | L7: 114000
A8: mercredi | B8: 45084 | C8: 30000 | D8: 30000 | I8: 1 | L8: 30000 | M8: Cash restant | N8: Magasin | O8: caisse
A9: jeudi | B9: 45085 | C9: 39000 | D9: 60000 | I9: 1 | L9: 39000 | M9: =D33-E33-Salaires!L31-O9 -> 567491 | N9: =O9*1 -> 172000 | O9: 172000
A10: vendredi | B10: 45086 | C10: 45000 | D10: 38000 | I10: 1 | L10: 45000
A11: samedi | B11: 45087 | C11: 50000 | D11: 64000 | I11: 1 | L11: 50000 | M11: loyer
A12: dimanche | B12: 45088 | C12: 62000 | D12: 24000 | I12: 1 | L12: 62000 | O12: la caisse : 20000 Da
A13: lundi | B13: 45089 | C13: 34000 | D13: 35000 | I13: 1 | L13: 34000
A14: mardi | B14: 45090 | C14: 31000 | D14: 80000 | I14: 1 | L14: 31000 | O14: che7i7a: 7000Da +7000DA
A15: mercredi | B15: 45091 | C15: 22000 | D15: 43000 | I15: 1 | L15: 22000 | O15: Compte ccp: 75000 Da
A16: jeudi | B16: 45092 | C16: 35000 | D16: 80000 | I16: 1 | L16: 35000 | O16: Moh livreur : 10350 Da
A17: vendredi | B17: 45093 | C17: 40000 | D17: 24000 | I17: 1 | L17: 40000 | M17: Différence mois d'Avril | O17: Brahim; 2000Da
A18: samedi | B18: 45094 | C18: 45000 | D18: 66000 | I18: 1 | L18: 45000 | M18: =D33-C33 -> 37000 | O18: Sofiane: 59000Da
A19: dimanche | B19: 45095 | C19: 70000 | D19: 50000 | I19: 1 | L19: 70000 | M19: Différence objectif
A20: lundi | B20: 45096 | C20: 10000 | D20: 12000 | I20: 1 | L20: 10000 | M20: =K34-E34 -> 0
A21: mardi | B21: 45097 | C21: 62000 | D21: 28000 | I21: 1 | L21: 62000
A22: mercredi | B22: 45098 | C22: 30000 | D22: 48000 | I22: 1 | L22: 30000
A23: jeudi | B23: 45099 | C23: 30000 | D23: 39000 | I23: 1 | L23: 30000 | M23: Les vendredis
A24: vendredi | B24: 45100 | C24: 39000 | D24: 40000 | I24: 1 | L24: 39000 | M24: =E4+E11+E18+E25 -> 0
A25: samedi | B25: 45101 | C25: 45000 | D25: 36000 | I25: 1 | L25: 45000
A26: dimanche | B26: 45102 | C26: 74000 | D26: 50000 | I26: 1 | L26: 74000 | M26: Cash réel
A27: lundi | B27: 45103 | C27: 26000 | D27: 120000 | I27: 1 | L27: 26000 | M27: 440000
A28: mardi | B28: 45104 | C28: 45000 | D28: 240000 | I28: 1 | L28: 45000 | M28: rest à payer
A29: mercredi | B29: 45105 | C29: 35000 | D29: 0 | I29: 0 | L29: 35000
A30: jeudi | B30: 45106 | C30: 30000 | D30: 0 | I30: 0 | L30: 30000
A31: vendredi | B31: 45107 | C31: 81000 | D31: 0 | I31: 0 | L31: 81000
C32: 100000 | I32: 0 | L32: 100000
C33: =SUM(C2:C32) -> 1540000 | D33: =SUM(D2:D32) -> 1577000 | E33: ='Les Charges'!H259*1 -> 716109 | F33: =Salaires!K31*1 -> 330813 | G33: 110000 | H33: =D33-E33-F33-G33 -> 420078 | I33: =SUM(I2:I32) -> 27 | L33: =SUM(L2:L32) -> 1540000 | M33: =M9-M27 -> 127491

Sheet Les Charges
E4: Produit | F4: Quantité | G4: Prix unitaire | H4: Prix | I4: Date d'achat
E5: Cawcaw | F5: 5.5 | G5: 550 | H5: =F5*G5 -> 3025 | I5: 45078
E6: Hamissa | F6: 5 | G6: 200 | H6: =F6*G6 -> 1000 | I6: 45078
E7: cuisses de poulet | F7: 28 | G7: 150 | H7: =F7*G7 -> 4200 | I7: 45078
E8: rechta | F8: 11 | G8: 100 | H8: =F8*G8 -> 1100 | I8: 45078
E9: olive | F9: 2 | G9: 200 | H9: =F9*G9 -> 400 | I9: 45078
E10: Boite salade | F10: 100 | G10: 10 | H10: =F10*G10 -> 1000 | I10: 45078
E11: Boites leben | F11: 100 | G11: 10 | H11: =F11*G11 -> 1000 | I11: 45078
E12: Barquettes aluminium 1185 | F12: 40 | G12: 50 | H12: =F12*G12 -> 2000 | I12: 45078
E13: légumes | F13: 1 | G13: 2000 | H13: =F13*G13 -> 2000 | I13: 45078
E14: Couscous | F14: 3 | G14: 200 | H14: =F14*G14 -> 600 | I14: 45078
E15: fromage gouda | F15: 1 | G15: 700 | H15: =F15*G15 -> 700 | I15: 45078
E16: tomate + salade cerise | F16: 2 | G16: 500 | H16: =F16*G16 -> 1000 | I16: 45078
... E25: concombre | F25: 1 | G25: 100 | H25: =F25*G25 -> 100 | I25: 45078
E26: décapant | F26: 5 | G26: 170 | H26: =G26*F26 -> 850 | I26: 45078
E27: Bali + Frotoir | F27: 2 | G27: 350 | H27: =F27*G27 -> 700 | I27: 45078
E28: détergents | F28: 1 | G28: 500 | H28: =G28*F28 -> 500 | I28: 45078
E29: curdents | F29: 15 | G29: 140 | H29: =G29*F29 -> 2100 | I29: 45078
E30: Motif bébé | F30: 4 | G30: 50 | H30: =G30*F30 -> 200 | I30: 45078
E31: dentelle 4,5 | F31: 6 | G31: 90 | H31: =G31*F31 -> 540 | I31: 45078
E32: éléctricité | F32: 1 | G32: 10500 | H32: =G32*F32 -> 10500 | I32: 45078
E33: semoule Fine Sahel et Bousmail 25kg | F33: 27 | G33: 1000 | H33: =G33*F33 -> 27000 | I33: 45078
E34: Oeuf | F34: 5 | G34: 600 | H34: =G34*F34 -> 3000 | I34: 45078
E35: boites demie plateaux | F35: 25 | G35: 80 | H35: =G35*F35 -> 2000 | I35: 45078
E36: messassek | F36: 3 | G36: 300 | H36: =G36*F36 -> 900 | I36: 45078
E37: les moules mini quiches | F37: 38 | G37: 18 | H37: =G37*F37 -> 684 | I37: 45078
E38: viande morceaux | F38: 14 | G38: 500 | H38: =G38*F38 -> 7000 | I38: 45078
E39: Nectarine | F39: 5 | G39: 450 | H39: =G39*F39 -> 2250 | I39: 45078
... E43: poulet haché+ blanc de poulet | F43: 4 | G43: 950 | H43: =G43*F43 -> 3800 | I43: 45078
D44: 1400 | E44: cheddar | F44: 3 | G44: 1400 | H44: =G44*F44 -> 4200 | I44: 45078
D45: 400 | E45: Tortilla | F45: 5 | G45: 400 | H45: =G45*F45 -> 2000 | I45: 45078
D46: 245 | E46: Maiis | F46: 12 | G46: 245 | H46: =G46*F46 -> 2940 | I46: 45078
D47: 530 | E47: Lait en poudre | F47: 9 | G47: 530 | H47: =G47*F47 -> 4770 | I47: 45078
D48: 1400 | E48: Fromage bidon mont d'Or 3kg | F48: 3 | G48: 1400 | H48: =G48*F48 -> 4200 | I48: 45078
D49: 340 | E49: crème fraiche | F49: 8 | G49: 340 | H49: =G49*F49 -> 2720 | I49: 45078
D50: 85 | E50: sucre glace | F50: 20 | G50: 85 | H50: =G50*F50 -> 1700 | I50: 45078
D51: 250 | E51: sac poubelle | F51: 2 | G51: 250 | H51: =G51*F51 -> 500 | I51: 45078
E52: olive dénoyaute | F52: 5 | G52: 500 | H52: =G52*F52 -> 2500 | I52: 45067
E53: olive effilet | F53: 2.5 | G53: 500 | H53: =G53*F53 -> 1250 | I53: 45066
E54: Boite 36 | F54: 3 | G54: 1200 | H54: =G54*F54 -> 3600 | I54: 45058
...

Sheet Pointage
B1: Date | C1: Lynda | D1: Hafida | E1: Djamila | F1: Samira Malawi | G1: Youssera | H1: Vendeuse | I1: Samira | J1: Dalila | K1: Kenza | L1: Yasmine | M1: Sarah | N1: Femme de ménage | O1: Nadjet | P1: Souad | Q1: Fadhila | R1: Farida | S1: Islem | T1: Fouzia | U1: Remarque
A2: Jeudi | B2: 45078 | C2: 2 | D2: 1.5 | E2: 0 | F2: 1 | G2: 0 | H2: 0 | I2: 1.5 | J2: 1.25 | K2: 0 | L2: 0 | M2: 1.5 | N2: 0 | O2: 1 | P2: 0 | Q2: 1.5 | R2: 0 | S2: 0 | T2: 1.5
A3: vendredi | B3: 45079 | C3: 0 | D3: 0 | E3: 0 | F3: 1 | G3: 0 | H3: 0 | I3: 0 | J3: 1 | K3: 1 | L3: 1 | M3: 0 | N3: 0 | O3: 1 | P3: 0 | Q3: 1 | R3: 0 | S3: 0 | T3: 1
A4: samedi | B4: 45080 | C4: 1 | D4: 1 | E4: 0 | F4: 1 | G4: 1 | H4: 0 | I4: 0 | J4: 1 | K4: 1 | L4: 0 | M4: 1 | N4: 0 | O4: 0 | P4: 0 | Q4: 0 | R4: 0 | S4: 0 | T4: 1
A5: dimanche | B5: 45081 | C5: 1 | D5: 1 | E5: 0 | F5: 0 | G5: 1 | H5: 0 | I5: 0 | J5: 1 | K5: 1.25 | L5: 0 | M5: 1 | N5: 0 | O5: 1 | P5: 0 | Q5: 1 | R5: 0 | S5: 0 | T5: 0.75
A6: lundi | B6: 45082 | C6: 1 | D6: 1 | E6: 0 | F6: 0 | G6: 1 | H6: 1 | I6: 1 | J6: 1 | K6: 1.25 | L6: 0 | M6: 1 | N6: 0 | O6: 1 | P6: 0 | Q6: 1 | R6: 0 | S6: 0 | T6: 0.5 | U6: on avait pas beaucoup de commandes donc elles ont fait de ménage et elles ont sortis à 16h et Fouzia est sorti à 11h30
A7: mardi | B7: 45083 | C7: 1 | D7: 1 | E7: 0 | F7: 0 | G7: 0 | H7: 0 | I7: 1 | J7: 1 | K7: 1 | L7: 0 | M7: 1 | N7: 0 | O7: 1 | P7: 0 | Q7: 1 | R7: 0 | S7: 0 | T7: 0.5
A8: mercredi | B8: 45084 | C8: 1.5 | D8: 0 | E8: 0 | F8: 0 | G8: 1 | H8: 0 | I8: 1 | J8: 1 | K8: 0 | L8: 1 | M8: 1 | N8: 0 | O8: 1 | P8: 0 | Q8: 1 | R8: 0 | S8: 0 | T8: 1.5
A9: jeudi | B9: 45085 | C9: 1.5 | D9: 1.25 | E9: 0 | F9: 0 | G9: 0 | H9: 0 | I9: 0 | J9: 1 | K9: 0 | L9: 1 | M9: 0 | N9: 0 | O9: 0 | P9: 1 | Q9: 1 | R9: 0 | S9: 0 | T9: 0
A10: vendredi | B10: 45086 | C10: 0 | D10: 1 | E10: 0 | F10: 0 | G10: 0 | H10: 0 | I10: 0 | J10: 0 | K10: 0.5 | L10: 1 | M10: 0 | N10: 0 | O10: 0 | P10: 0 | Q10: 0 | R10: 0 | S10: 0 | T10: 0
A11: samedi | B11: 45087 | C11: 2 | D11: 1.25 | E11: 0 | F11: 0 | G11: 1 | H11: 0 | I11: 0 | J11: 0.75 | K11: 0 | L11: 1 | M11: 1 | N11: 0 | O11: 0 | P11: 1 | Q11: 0 | R11: 0 | S11: 1 | T11: 0
A12: dimanche | B12: 45088 | C12: 1 | D12: 1 | E12: 0 | F12: 0 | G12: 1 | H12: 0 | I12: 0 | J12: 1 | K12: 0 | L12: 1 | M12: 1 | N12: 0 | O12: 0 | P12: 1 | Q12: 1 | R12: 0 | S12: 1 | T12: 1
A13: lundi | B13: 45089 | C13: 1 | D13: 0 | E13: 0 | F13: 0 | G13: 1 | H13: 0 | I13: 0 | J13: 0.6 | K13: 0 | L13: 1 | M13: 1 | N13: 0 | O13: 0 | P13: 1 | Q13: 1 | R13: 0 | S13: 0 | T13: 1
A14: mardi | B14: 45090 | C14: 1 | D14: 1 | E14: 0 | F14: 0 | G14: 1 | H14: 0 | I14: 0 | J14: 1 | K14: 0 | L14: 1 | M14: 0.5 | N14: 0 | O14: 0 | P14: 1 | Q14: 1 | R14: 0 | S14: 0 | T14: 1
A15: mercredi | B15: 45091 | C15: 1 | D15: 1 | E15: 0 | F15: 0 | G15: 1 | H15: 0 | I15: 0 | J15: 1 | K15: 0 | L15: 1 | M15: 0 | N15: 0 | O15: 0 | P15: 0.5 | Q15: 1 | R15: 0 | S15: 0 | T15: 1
A16: jeudi | B16: 45092 | C16: 1 | D16: 1 | E16: 0 | F16: 0 | G16: 0 | H16: 1 | I16: 0 | J16: 1 | K16: 0 | L16: 1 | M16: 1 | N16: 0 | O16: 1 | P16: 0 | Q16: 1 | R16: 0 | S16: 0 | T16: 1
A17: vendredi | B17: 45093 | C17: 0 | D17: 1 | E17: 0 | F17: 0 | G17: 0 | H17: 1 | I17: 0 | J17: 0 | K17: 1 | L17: 1 | M17: 0 | N17: 0 | O17: 0 | P17: 0 | Q17: 0 | R17: 0 | S17: 0 | T17: 0
A18: samedi | B18: 45094 | C18: 1 | D18: 1 | E18: 0 | F18: 0 | G18: 1 | H18: 1 | I18: 0 | J18: 0 | K18: 1 | L18: 0 | M18: 0 | N18: 1 | O18: 0 | P18: 0 | Q18: 1 | R18: 0 | S18: 0 | T18: 0
... A28: mardi | B28: 45104 | C28: 1 | D28: 1 | E28: 0 | F28: 1 | G28: 1 | H28: 1 | I28: 0 | J28: 0 | K28: 1 | L28: 1 | M28: 0 | N28: 1 | O28: 2 | P28: 0 | Q28: 1 | R28: 0 | S28: 0 | T28: 1
A29: mercredi | B29: 45105
A30: jeudi | B30: 45106
A31: vendredi | B31: 45107
A32: samedi | B32: 45108
C33: =SUM(C2:C32) -> 30.5 | D33: =SUM(D2:D32) -> 23.75 | E33: =SUM(E2:E32) -> 0 | F33: =SUM(F2:F32) -> 13.25 | G33: =SUM(G2:G32) -> 16 | H33: =SUM(H2:H32) -> 14.25 | I33: =SUM(I2:I32) -> 4.5 | J33: =SUM(J2:J32) -> 17.6 | ... T33: =SUM(T2:T32) -> 20.5
C34: 1223 | D34: 1297 | E34: 1223 | F34: 1037 | G34: 1223 | H34: 1000 | I34: 1000 | J34: 1000 | K34: 1037 | L34: 1037 | M34: 800 | N34: 1000 | O34: 1250 | P34: 1000 | Q34: 1000 | R34: 1300 | S34: 1000 | T34: 1200
C35: =C33*C34 -> 37301.5 | D35: =D34*D33 -> 30803.75 | E35: =E34*E33 -> 0 | F35: =F34*F33 -> 13740.25 | G35: =G34*G33 -> 19568 | H35: =H34*H33 -> 14250 | I35: =I34*I33 -> 4500 | J35: =J34*J33 -> 17600 | K35: =K34*K33 -> 17110.5 | ... Q35: =Q34*Q33 -> 18500 | R35: =R33*R34 -> 9425 | S35: =S33*S34 -> 3000 | T35: =T33*T34 -> 24600 | U35: =SUM(D35:M35) -> 149986.5

Sheet Salaires
J10: Nom | K10: Salaire | L10: Avance | M10: Salaire à payer
I11: 1 | J11: Sofiane | K11: 30000 | L11: 30000 | M11: =K11-L11 -> 0 | N11: 10000Da Matcha+9000+11000
I12: 2 | J12: Amel | K12: 30000 | L12: 30000 | M12: =K12-L12 -> 0 | N12: 5000+15000+10000
I13: 3 | J13: Lynda | K13: =Pointage!C35*1 -> 37301.5 | L13: 5000 | M13: =K13-L13 -> 32301.5
I14: 3 | J14: Hafida | K14: =Pointage!D35*1 -> 30803.75 | M14: =K14-L14 -> 30803.75
I15: 4 | J15: Djamila | K15: =Pointage!E35*1 -> 0 | M15: =K15-L15 -> 0
I16: 5 | J16: Samira Malawi | K16: =Pointage!F35*1 -> 13740.25 | M16: =K16-L16 -> 13740.25
I17: 6 | J17: Youssera | K17: =Pointage!G35*1 -> 19568 | L17: 10000 | M17: =K17-L17 -> 9568 | N17: 6000+4000
I18: 7 | J18: Vendeuse | K18: =Pointage!H35*1 -> 14250 | L18: 1000 | M18: =K18-L18 -> 13250
I19: 8 | J19: Samira | K19: =Pointage!I35*1 -> 4500 | M19: =K19-L19 -> 4500
I20: 9 | J20: Dalila | K20: =Pointage!J35*1 -> 17600 | M20: =K20-L20 -> 17600
I21: 10 | J21: Kenza | K21: =Pointage!K35*1 -> 17110.5 | L21: 4000 | M21: =K21-L21 -> 13110.5
I22: 11 | J22: Yasmine | K22: =Pointage!L35*1 -> 22814 | M22: =K22-L22 -> 22814
I23: 12 | J23: Sarah | K23: =Pointage!M35*1 -> 9600 | M23: =K23-L23 -> 9600
I24: 13 | J24: femme de ménage | K24: =Pointage!N35*1 -> 10000 | M24: =K24-L24 -> 10000
I25: 14 | J25: Nadjet | K25: =Pointage!O35*1 -> 12500 | L25: 12500 | M25: =K25-L25 -> 0
I26: 15 | J26: Souad | K26: =Pointage!P35*1 -> 5500 | L26: 5500 | M26: =K26-L26 -> 0
I27: 16 | J27: Fadhila | K27: =Pointage!Q35*1 -> 18500 | M27: =K27-L27 -> 18500
I28: 17 | J28: Farida | K28: =Pointage!R35*1 -> 9425 | M28: =K28-L28 -> 9425
I29: 18 | J29: Islem | K29: =Pointage!S35*1 -> 3000 | L29: 3000 | M29: =K29-L29 -> 0
I30: 19 | J30: Fouzia | K30: =Pointage!T35*1 -> 24600 | L30: 20400 | M30: =K30-L30 -> 4200 | N30: 5000+16000 | O30: 600
J31: TOTAL | K31: =SUM(K11:K30) -> 330813 | L31: =SUM(L11:L30) -> 121400 | M31: =SUM(M11:M30) -> 209413
J32: =K31-L31 -> 209413 | M32: =K32-L32 -> 0

Sheet Feuille 5
E11: Mois de Février | F11: Mois de Mars | G11: Mois d'Avril | H11: Mois de Mai | I11: Mois de Jiun
D12: Recette | E12: 1400000 | F12: 1928000 | G12: 1488000 | H12: 1540000 | I12: 1577000
D13: Charges | E13: 597000 | F13: 938000 | G13: 670000 | H13: 753000 | I13: 716000
D14: Salaires | E14: 413000 | F14: 360000 | G14: 335000 | H14: 347000 | I14: 331000
D15: Loyer | E15: 110000 | F15: 110000 | G15: 110000 | H15: 110000 | I15: 110000
D16: Profit Net | E16: 280000 | F16: 520000 | G16: 370000 | H16: =H12-H13-H14-H15 -> 330000 | I16: =I12-I13-I14-I15 -> 420000
