Workbook

Sheet RECAP
B1: Date | C1: Recette Juillet 2024 | D1: Recette | E1: Charges | F1: Salaire | G1: Loyer | H1: Net Profit | I1: Nb de jours | K1: Objectif | L1: Mois de Septembre 2024
A2: Mardi | B2: 45566 | C2: 39000 | D2: 85000 | I2: 1 | L2: 39000
A3: mercredi | B3: 45567 | C3: 55000 | D3: 35000 | I3: 1 | L3: 55000 | M3: Bénéfice Moyen par jour | N3: Moyenne | O3: Moyenne salaire | P3: pourcentage du salaire vis à vis la recettte
A4: jeudi | B4: 45568 | C4: 78000 | D4: 60000 | I4: 1 | L4: 78000 | M4: =H33/I33 -> 9212.8194 | N4: =D33/I33 -> 52258.065 | P4: =O4/N4 -> 0
A5: vendredi | B5: 45569 | C5: 93000 | D5: 56000 | I5: 1 | L5: 93000
A6: samedi | B6: 45570 | C6: 40000 | D6: 85000 | I6: 1 | L6: 40000 | M6: Moyenne des charges par jour | N6: Objectif
A7: dimanche | B7: 45571 | C7: 1000 | D7: 26000 | I7: 1 | L7: 1000 | M7: =E33/I33 -> 24086.071 | N7: 100000
A8: lundi | B8: 45572 | C8: 39000 | D8: 32000 | I8: 1 | L8: 39000 | M8: ² | R8: "
A9: mardi | B9: 45573 | C9: 32000 | D9: 26000 | I9: 1 | L9: 32000
A10: mercredi | B10: 45574 | C10: 33000 | D10: 28000 | I10: 1 | L10: 33000 | M10: Cash restant | N10: Magasin | O10: Cash réel | P10: Mes dettes pour le magasin
A11: jeudi | B11: 45575 | C11: 51000 | D11: 52000 | I11: 1 | L11: 51000 | M11: =M14+D33-E33-N11-Q19-Salaires!L39 -> 724331.8 | N11: 8000 | O11: 743000 | P11: =M11-O11 -> -18668.2
A12: vendredi | B12: 45576 | C12: 76000 | D12: 38000 | I12: 1 | L12: 76000
A13: samedi | B13: 45577 | C13: 129000 | D13: 40000 | I13: 1 | L13: 129000 | M13: Fond de Roulement
A14: dimanche | B14: 45578 | C14: 93000 | D14: 24000 | I14: 1 | L14: 93000 | M14: 330000
A15: lundi | B15: 45579 | C15: 107000 | D15: 164000 | I15: 1 | L15: 107000
A16: mardi | B16: 45580 | C16: 129000 | D16: 21000 | I16: 1 | L16: 129000 | M16: Bénéfice Sept + loyer | P16: Cash réel : | Q16: Khalida : 30000Da
A17: mercredi | B17: 45581 | C17: 37000 | D17: 107000 | I17: 1 | L17: 37000 | M17: 0 | P17: Sofiane :
A18: jeudi | B18: 45582 | C18: 54000 | D18: 65000 | I18: 1 | L18: 54000 | Q18: 45582
A19: vendredi | B19: 45583 | C19: 23000 | D19: 60000 | I19: 1 | L19: 23000 | M19: Différence mois d'Aout | P19: la vraie caisse:8000Da | Q19: 30000
A20: samedi | B20: 45584 | C20: 54000 | D20: 23000 | I20: 1 | L20: 54000 | M20: =D33-C33 -> -120000
A21: dimanche | B21: 45585 | C21: 50000 | D21: 28000 | I21: 1 | L21: 50000 | M21: Différence objectif | O21: réparation Tabouna | P21: 1 | Q21: 8800 | R21: =P21*Q21 -> 8800
A22: lundi | B22: 45586 | C22: 46000 | D22: 40000 | I22: 1 | L22: 46000 | M22: =K36-E36 -> 0 | O22: Torchons | P22: 4 | Q22: 400 | R22: 600
A23: mardi | B23: 45587 | C23: 43000 | D23: 37000 | I23: 1 | L23: 43000 | M23: Différence du Totale | O23: poelle | P23: 1 | Q23: 2800 | R23: =P23*Q23 -> 2800
A24: mercredi | B24: 45588 | C24: 40000 | D24: 47000 | I24: 1 | L24: 40000 | M24: =D33-C33 -> -120000 | Q24: Achoire | R24: 1 | S24: 1800 | T24: =R24*S24 -> 1800
A25: jeudi | B25: 45589 | C25: 40000 | D25: 43000 | I25: 1 | L25: 40000 | M25: Les vendredis | O25: Cash chez Sofiane
A26: vendredi | B26: 45590 | C26: 170000 | D26: 104000 | I26: 1 | L26: 170000 | M26: =D9+D16+D23+D30 -> 127000 | Q26: Les étagères pour locale | R26: 1 | S26: 21000 | T26: =R26*S26 -> 21000
A27: samedi | B27: 45591 | C27: 73000 | D27: 59000 | I27: 1 | L27: 73000
A28: dimanche | B28: 45592 | C28: 22000 | D28: 53000 | I28: 1 | L28: 22000 | M28: Cash réel
A29: lundi | B29: 45593 | C29: 24000 | D29: 38000 | I29: 1 | L29: 24000 | M29: 51000
A30: mardi | B30: 45594 | C30: 39000 | D30: 43000 | I30: 1 | L30: 39000 | M30: rest à payer
A31: mercredi | B31: 45595 | C31: 30000 | D31: 49000 | I31: 1 | L31: 30000
A32: jeudi | B32: 45596 | C32: 0 | D32: 52000 | I32: 1 | L32: 0 | P32: =SUM(P26:P31) -> 0
C33: =SUM(C2:C32) -> 1740000 | D33: =SUM(D2:D32) -> 1620000 | E33: ='Les Charges '!J466 -> 746668.2 | F33: =Salaires!K39 -> 437734.4 | G33: 150000 | H33: =D33-E33-F33-G33 -> 285597.4 | I33: =SUM(I2:I32) -> 31 | L33: =SUM(L2:L32) -> 1740000
M35: =M11-M29-M34 -> 673331.8
D38: -

Sheet ¨Pointage
B1: Date | C1: Nadjet | D1: Yasmine | E1: Saida | F1: Israa | G1: Ahlem | H1: Nour ElHouda | I1: Do3aa | J1: Wafa | K1: Amina | L1: Selma | M1: Zohra | N1: Nora | O1: Ikram | P1: Sabiha | Q1: Rayan | R1: Karima | S1: Sihem | T1: Fatiha | U1: Remarque
A2: Mardi | B2: 45566 | C2: 0 | D2: 0 | E2: 1 | F2: 1 | G2: 1 | H2: 1.2 | I2: 1.1 | J2: 0 | K2: 1 | L2: 1.2 | M2: 0 | N2: 1 | O2: 1 | P2: 1 | Q2: 1 | R2: 0 | S2: 0 | T2: 0
A3: mercredi | B3: 45567 | C3: 0 | D3: 1 | E3: 1 | F3: 1 | G3: 1 | H3: 0 | I3: 0 | J3: 1 | K3: 1 | L3: 1 | M3: 1 | N3: 1 | O3: 1 | P3: 1 | Q3: 1 | R3: 0 | S3: 0 | T3: 0
A4: jeudi | B4: 45568 | C4: 0 | D4: 1 | E4: 1 | F4: 1 | G4: 1 | H4: 1 | I4: 1 | J4: 1 | K4: 1 | L4: 0 | M4: 0 | N4: 1 | O4: 1 | P4: 0 | Q4: 1 | R4: 0 | S4: 0 | T4: 0
A5: vendredi | B5: 45569 | C5: 0 | D5: 1 | E5: 0 | F5: 0 | G5: 0 | H5: 0 | I5: 0 | J5: 1 | K5: 1 | L5: 0 | M5: 1 | N5: 1 | O5: 1 | P5: 0 | Q5: 1 | R5: 0 | S5: 0 | T5: 0
A6: samedi | B6: 45570 | C6: 0 | D6: 1 | E6: 1 | F6: 1 | G6: 1 | H6: 0 | I6: 1 | J6: 0 | K6: 1 | L6: 1 | M6: 0 | N6: 1.1 | O6: 1.1 | P6: 1 | Q6: 1 | R6: 0 | S6: 0 | T6: 0
A7: dimanche | B7: 45571 | C7: 0 | D7: 1 | E7: 0 | F7: 0 | G7: 1 | H7: 1 | I7: 1 | J7: 0 | K7: 0 | L7: 1.2 | M7: 1 | N7: 0 | O7: 0 | P7: 0 | Q7: 1 | R7: 0 | S7: 0 | T7: 0
A8: lundi | B8: 45572 | C8: 0 | D8: 1 | E8: 0 | F8: 0 | G8: 1 | H8: 0 | I8: 0 | J8: 0 | K8: 1 | L8: 1.2 | M8: 0 | N8: 1 | O8: 1 | P8: 1 | Q8: 0 | R8: 1 | S8: 0 | T8: 0
A9: mardi | B9: 45573 | C9: 1 | D9: 0 | E9: 0 | F9: 0 | G9: 1 | H9: 1 | I9: 0 | J9: 0 | K9: 1 | L9: 1 | M9: 1 | N9: 1 | O9: 1 | P9: 1 | Q9: 1 | R9: 1 | S9: 0 | T9: 0
A10: mercredi | B10: 45574 | C10: 0 | D10: 1 | E10: 0 | F10: 0 | G10: 1 | H10: 1 | I10: 0 | J10: 0 | K10: 1.1 | L10: 1.1 | M10: 0 | N10: 1 | O10: 1 | P10: 1 | Q10: 1 | R10: 1 | S10: 0 | T10: 1
A11: jeudi | B11: 45575 | C11: 1 | D11: 1 | E11: 1 | F11: 0 | G11: 1 | H11: 1 | I11: 0 | J11: 0 | K11: 0 | L11: 1.2 | M11: 0 | N11: 1 | O11: 1 | P11: 1 | Q11: 0 | R11: 1 | S11: 0 | T11: 1
A12: vendredi | B12: 45576 | C12: 0 | D12: 1 | E12: 0 | F12: 0 | G12: 0 | H12: 1 | I12: 1 | J12: 0 | K12: 1 | L12: 0 | M12: 1 | N12: 0 | O12: 0 | P12: 0 | Q12: 1 | R12: 0 | S12: 0 | T12: 1
A13: samedi | B13: 45577 | C13: 0 | D13: 1 | E13: 1 | F13: 1 | G13: 1 | H13: 0 | I13: 0 | J13: 0 | K13: 1 | L13: 1 | M13: 0 | N13: 1 | O13: 1 | P13: 1 | Q13: 1 | R13: 1 | S13: 1 | T13: 1
... A31: mercredi | B31: 45595 | C31: 0 | D31: 1 | E31: 1 | F31: 0 | G31: 1 | H31: 0 | I31: 0 | J31: 0 | K31: 1 | L31: 1 | M31: 0 | N31: 1.1 | O31: 1.1 | P31: 0 | Q31: 0 | R31: 1 | S31: 1 | T31: 1
A32: jeudi | B32: 45596 | C32: 1 | D32: 1 | E32: 1 | F32: 0 | G32: 1 | H32: 0 | I32: 0 | J32: 0 | K32: 1 | L32: 1 | M32: 0 | N32: 0.5 | O32: 0.5 | P32: 0 | Q32: 1 | R32: 1 | S32: 1 | T32: 0.5 | U32: pénution les boules
C33: =SUM(C2:C32) -> 9 | D33: =SUM(D2:D32) -> 26 | E33: =SUM(E2:E32) -> 21 | F33: =SUM(F2:F32) -> 5 | G33: =SUM(G2:G32) -> 27 | H33: =SUM(H2:H32) -> 11.4 | I33: =SUM(I2:I32) -> 7.1 | J33: =SUM(J2:J32) -> 3 | ... T33: =SUM(T2:T32) -> 21.1
C34: 1500 | D34: 1112 | E34: 1112 | F34: 1112 | G34: 1112 | H34: 1112 | I34: 1112 | J34: 1112 | K34: 1112 | L34: 1112 | M34: 1200 | N34: 1112 | O34: 1112 | P34: 1100 | Q34: 1200 | R34: 1112 | S34: 1000 | T34: 1100
C35: =C34*C33 -> 13500 | D35: =D34*D33 -> 28912 | E35: =E34*E33 -> 23352 | F35: =F34*F33 -> 5560 | G35: =G34*G33 -> 30024 | H35: =H34*H33 -> 12676.8 | I35: =I34*I33 -> 7895.2 | J35: =J34*J33 -> 3336 | ... R35: =R34*R33 -> 24241.6 | S35: =S33*S34 -> 15000 | T35: =T34*T33 -> 23210
D36: 30000 | E36: 30000 | F36: 30000 | G36: 30000 | H36: 30000 | I36: 30000 | J36: 30000 | K36: 30000 | L36: 30000 | N36: 30000 | O36: 30000 | P36: 30000

Sheet Les Charges 
G1: Produit | H1: Quantité | I1: Prix unitaire | J1: Prix | K1: Date d'achat
G2: Semoule Fine 25kg Sahel | H2: 5 | I2: 1000 | J2: =H2*I2 -> 5000
G3: Semoule Moyenne 25kg Sahel | H3: 9 | I3: 1000 | J3: =H3*I3 -> 9000
G4: Semoule Fine Agrodive 25kg | H4: 15 | I4: 1000 | J4: =H4*I4 -> 15000
G5: Semoule Fine Sosimie 10kg | H5: 10 | I5: 370 | J5: =H5*I5 -> 3700
G6: Farine Sim 1kg | H6: 33 | I6: 84 | J6: =H6*I6 -> 2772
G7: Cheddar | H7: 2.4 | I7: 1900 | J7: =H7*I7 -> 4560
G8: Fromage Slices | H8: 14 | I8: 200 | J8: =H8*I8 -> 2800
G9: Fromage blanc | H9: 1 | I9: 1100 | J9: =H9*I9 -> 1100
G10: Fromage Bidon 3,8kg | H10: 3 | I10: 1350 | J10: =H10*I10 -> 4050
G11: Crème Fraiche 1 litre | H11: 16 | I11: 440 | J11: =H11*I11 -> 7040
G12: Harrissa | H12: 14 | I12: 255 | J12: =H12*I12 -> 3570
G13: Tomate conserve | H13: 16 | I13: 325 | J13: =H13*I13 -> 5200
G14: Thon 2kg | H14: 1 | I14: 1900 | J14: 1900
G15: Thon 2kg | H15: 1 | I15: 1850 | J15: =H15*I15 -> 1850
G16: Fromage spéciale pizza | H16: 1 | I16: 650 | J16: =H16*I16 -> 650
G17: Coriandre moulu | H17: 1 | I17: 1000 | J17: =H17*I17 -> 1000
G18: 3akeri | H18: 1 | I18: 1100 | J18: =H18*I18 -> 1100
G19: 3akeri Safi | H19: 1 | I19: 1600 | J19: =H19*I19 -> 1600
G20: Levure boulangère | H20: 5 | I20: 390 | J20: =H20*I20 -> 1950
G21: levure chimique | H21: 146 | I21: 6.2 | J21: =H21*I21 -> 905.2
G22: Gherss | H22: 18 | I22: 200 | J22: =H22*I22 -> 3600
G23: javel + lave sol 5litres | H23: 2 | I23: 400 | J23: =H23*I23 -> 800
G24: Bessel | H24: 160 | I24: 50 | J24: =H24*I24 -> 8000
G25: carottes | H25: 5 | I25: 60 | J25: =H25*I25 -> 300
G26: courgette | H26: 5 | I26: 180 | J26: =H26*I26 -> 900
... G78: Maiis | H78: 18 | I78: 250 | J78: =H78*I78 -> 4500
G79: POISSONS | H79: 2 | I79: 500 | J79: =H79*I79 -> 1000 | K79: 45568
G80: Poulet haché | H80: 1.25 | I80: 800 | J80: =H80*I80 -> 1000
G81: rechta | H81: 10 | I81: 100 | J81: =H81*I81 -> 1000
G82: légumes | H82: 1 | I82: 1000 | J82: =H82*I82 -> 1000
G83: transport personelle | H83: 1 | I83: 1000 | J83: =H83*I83 -> 1000
G84: Huile elio 5 litres | H84: 20 | I84: 600 | J84: =H84*I84 -> 12000 | K84: 45568
G85: sucre glace skor 700g | H85: 14 | I85: 115 | J85: =H85*I85 -> 1610
G86: Semen Madina 1,8kg | H86: 1 | I86: 800 | J86: =H86*I86 -> 800
G87: Sac poubelle | H87: 1 | I87: 220 | J87: =H87*I87 -> 220
G88: isis | H88: 1 | I88: 190 | J88: =H88*I88 -> 190
G89: Farine SIM 1kg | H89: 4 | I89: 100 | J89: =H89*I89 -> 400
G90: yaourt | H90: 60 | I90: 25 | J90: =H90*I90 -> 1500
G91: jus tchina 33cl | H91: 19 | I91: 60 | J91: =H91*I91 -> 1140
...

Sheet Salaires
J18: Nom | K18: Salaire | L18: Avance | M18: Salaire à payer
J19: Sofiane | K19: 30000 | L19: 30000 | M19: =K19-L19 -> 0 | N19: 20000+10000
J20: Amel | K20: 30000 | L20: 30000 | M20: =K20-L20 -> 0
I21: 1 | J21: Nadjet | K21: ='¨Pointage'!C35 -> 13500 | L21: 13500 | M21: =K21-L21 -> 0
I22: 2 | J22: Yasmine | K22: =N22+'¨Pointage'!D35 -> 33912 | L22: 34000 | M22: =K22-L22 -> -88 | N22: 5000
I23: 3 | J23: Saida | K23: ='¨Pointage'!E35 -> 23352 | L23: 23500 | M23: =K23-L23 -> -148
I24: 4 | J24: Israa | K24: ='¨Pointage'!F35 -> 5560 | L24: 6000 | M24: =K24-L24 -> -440
I25: 5 | J25: Ahlem | K25: 30000 | L25: 30000 | M25: =K25-L25 -> 0
I26: 6 | J26: Nour ElHouda | K26: ='¨Pointage'!H35 -> 12676.8 | L26: 13000 | M26: =K26-L26 -> -323.2
I27: 7 | J27: Do3aa | K27: ='¨Pointage'!I35 -> 7895.2 | L27: 8000 | M27: =K27-L27 -> -104.8
I28: 8 | J28: Wafa | K28: ='¨Pointage'!J35 -> 3336 | L28: 3500 | M28: =K28-L28 -> -164
I29: 9 | J29: Amina | K29: ='¨Pointage'!K35 -> 29912.8 | L29: 30000 | M29: =K29-L29 -> -87.2
I30: 10 | J30: Selma | K30: ='¨Pointage'!L35 -> 29245.6 | L30: 29500 | M30: =K30-L30 -> -254.4 | N30: 1000+3000
I31: 11 | J31: Zohra | K31: ='¨Pointage'!M35 -> 9000 | L31: 9000 | M31: =K31-L31 -> 0
I32: 12 | J32: Sabiha | K32: ='¨Pointage'!P35 -> 24310 | L32: 24500 | M32: =K32-L32 -> -190
I33: 13 | J33: Rayan | K33: ='¨Pointage'!Q35 -> 31200 | L33: 31500 | M33: =K33-L33 -> -300 | N33: 5000
I34: 14 | J34: Ikram | K34: ='¨Pointage'!O35 -> 29801.6 | L34: 30000 | M34: =K34-L34 -> -198.4
I35: 15 | J35: Nora | K35: ='¨Pointage'!N35 -> 31580.8 | L35: 32000 | M35: =K35-L35 -> -419.2
I36: 16 | J36: Sihel=m | K36: ='¨Pointage'!S35 -> 15000 | L36: 15000 | M36: =K36-L36 -> 0 | N36: 3000
I37: 17 | J37: Karima | K37: ='¨Pointage'!R35 -> 24241.6 | L37: 24500 | M37: =K37-L37 -> -258.4
I38: 17 | J38: Fatiha | K38: ='¨Pointage'!T35 -> 23210 | L38: 23500 | M38: =K38-L38 -> -290 | N38: 10000
J39: TOTAL | K39: =SUM(K19:K38) -> 437734.4 | L39: =SUM(L19:L38) -> 441000 | M39: =K39-L39 -> -3265.6
M40: =K40-L40 -> 0

Sheet Feuille 5
J26: Mois de Janvier | K26: Mois de Février | L26: Mois de Mars | M26: Mois d'Avril | N26: Mois de Mai | O26: Mois de Jiun | P26: Mois de Juillet | Q26: Mois d'Aout | R26: Mois de Septembre | S26: Mois d'Octobre | V26: Mois d'Octobre
I27: Recette | J27: 1756000 | K27: 2274000 | L27: 1984000 | M27: 1910000 | N27: 1342000 | O27: 1760000 | P27: 2260000 | Q27: 1427000 | R27: 1740000 | S27: =RECAP!D33 -> 1620000 | U27: Recette | V27: =S27 -> 1620000
I28: Charges | J28: 920000 | K28: 914000 | L28: 928000 | M28: 744000 | N28: 646000 | O28: 804000 | P28: 958000 | Q28: 640000 | R28: 716000 | S28: =RECAP!E33 -> 746668.2 | U28: Charges | V28: =S28 -> 746668.2
I29: Salaires | J29: 349000 | K29: 410000 | L29: 406000 | M29: 344000 | N29: 436000 | O29: 396000 | P29: 432000 | Q29: 307000 | R29: 514000 | S29: =RECAP!F33 -> 437734.4 | U29: Salaires | V29: =S29 -> 437734.4
I30: Loyer | J30: 140000 | K30: 140000 | L30: 140000 | M30: 140000 | N30: 140000 | O30: 140000 | P30: 150000 | Q30: 150000 | R30: 150000 | S30: =RECAP!G33 -> 150000 | U30: Loyer | V30: =S30 -> 150000
I31: Profit Net | J31: =J27-J28-J29-J30 -> 347000 | K31: =K27-K28-K29-K30 -> 810000 | L31: =L27-L28-L29-L30 -> 510000 | M31: 680000 | N31: =N27-N28-N29-N30 -> 120000 | O31: 420000 | P31: =P27-P28-P29-P30 -> 720000 | Q31: 330000 | R31: =R27-R28-R29-R30 -> 360000 | S31: =S27-S28-S29-S30 -> 285597.4 | U31: Profit Net | V31: =V27-V28-V29-V30 -> 285597.4
