Workbook

Sheet RECAP
B1: Date | C1: Recette Juillet 2024 | D1: Recette | E1: Charges | F1: Salaire | G1: Loyer | H1: Net Profit | I1: Nb de jours | K1: Objectif | L1: Mois de Juin 2024
A2: Jeudi | B2: 45505 | C2: 41000 | D2: 33000 | I2: 1 | L2: 41000
A3: Vendredi | B3: 45506 | C3: 37000 | D3: 60000 | I3: 1 | L3: 37000 | M3: Bénéfice Moyen par jour | N3: Moyenne | O3: Moyenne salaire | P3: pourcentage du salaire vis à vis la recettte
A4: Samedi | B4: 45507 | C4: 47000 | D4: 0 | I4: 0 | L4: 47000 | M4: =H33/I33 -> 13267.157 | N4: =D33/I33 -> 57080 | P4: =O4/N4 -> 0
A5: Dimanche | B5: 45508 | C5: 130000 | D5: 0 | I5: 0 | L5: 130000
A6: Lundi | B6: 45509 | C6: 40000 | D6: 0 | I6: 0 | L6: 40000 | M6: Moyenne des charges par jour | N6: Objectif
A7: Mardi | B7: 45510 | C7: 117000 | D7: 0 | I7: 0 | L7: 117000 | M7: =E33/I33 -> 25593.16 | N7: 100000
A8: Merdredi | B8: 45511 | C8: 90000 | D8: 4000 | I8: 1 | L8: 90000 | M8: ²
A9: Jeudi | B9: 45512 | C9: 60000 | D9: 0 | I9: 0 | L9: 60000
A10: Vendredi | B10: 45513 | C10: 50000 | D10: 0 | I10: 0 | L10: 50000 | M10: Cash restant | N10: Magasin | O10: Cash réel | P10: Mes dettes pour le magasin
A11: Samedi | B11: 45514 | C11: 60000 | D11: 35000 | I11: 1 | L11: 60000 | M11: =M14+D33-E33-N11-P32-Salaire!L38 -> 802171 | N11: 8000 | O11: 824000 | P11: =M11-O11 -> -21829
A12: Dimanche | B12: 45515 | C12: 67000 | D12: 18000 | I12: 1 | L12: 67000
A13: Lundi | B13: 45516 | C13: 65000 | D13: 21000 | I13: 1 | L13: 65000 | M13: Fond de Roulement
A14: Mardi | B14: 45517 | C14: 470000 | D14: 23000 | I14: 1 | L14: 470000 | M14: 330000 | P14: CCP: 100000Da
A15: Mercredi | B15: 45518 | C15: 52000 | D15: 20000 | I15: 1 | L15: 52000 | P15: sifou : 13850Da
A16: Jeudi | B16: 45519 | C16: 80000 | D16: 40000 | I16: 1 | L16: 80000 | P16: Cash réel : 154000Da
A17: Vendredi | B17: 45520 | C17: 70000 | D17: 45000 | I17: 1 | L17: 70000 | P17: cash chez Brahim: 570000Da
A18: Samedi | B18: 45521 | C18: 60000 | D18: 38000 | I18: 1 | L18: 60000
A19: Dimanche | B19: 45522 | C19: 43000 | D19: 37000 | I19: 1 | L19: 43000 | M19: Différence mois de juin | P19: la vraie caisse:5000Da
A20: Lundi | B20: 45523 | C20: 34000 | D20: 32000 | I20: 1 | L20: 34000 | M20: =D33-C33 -> -833000
A21: Mardi | B21: 45524 | C21: 100000 | D21: 15000 | I21: 1 | L21: 100000 | M21: Différence objectif | O21: réparation Tabouna | P21: 1 | Q21: 8800 | R21: =P21*Q21 -> 8800
A22: Mercredi | B22: 45525 | C22: 28000 | D22: 25000 | I22: 1 | L22: 28000 | M22: =K36-E36 -> 0 | O22: Torchons | P22: 4 | Q22: 400 | R22: 600
A23: Jeudi | B23: 45526 | C23: 74000 | D23: 38000 | I23: 1 | L23: 74000 | M23: Différence du Totale | O23: poelle | P23: 1 | Q23: 2800 | R23: =P23*Q23 -> 2800
A24: Vendredi | B24: 45527 | C24: 49000 | D24: 146000 | I24: 1 | L24: 49000 | M24: =D33-C33 -> -833000 | Q24: Achoire | R24: 1 | S24: 2000 | T24: =R24*S24 -> 2000
A25: Samedi | B25: 45528 | C25: 52000 | D25: 38000 | I25: 1 | L25: 52000 | M25: Les vendredis | O25: Cash chez Sofiane
A26: Dimanche | B26: 45529 | C26: 73000 | D26: 48000 | I26: 1 | L26: 73000 | M26: =D9+D16+D23+D30 -> 540000 | Q26: Les étagères pour locale | R26: 1 | S26: 21000 | T26: =R26*S26 -> 21000
A27: Lundi | B27: 45530 | C27: 24000 | D27: 51000 | I27: 1 | L27: 24000
A28: Mardi | B28: 45531 | C28: 73000 | D28: 39000 | I28: 1 | L28: 73000 | M28: Cash réel
A29: Merdcredi | B29: 45532 | C29: 35000 | D29: 34000 | I29: 1 | L29: 35000 | M29: 51000
A30: Jeudi | B30: 45533 | C30: 34000 | D30: 462000 | I30: 1 | L30: 34000 | M30: rest à payer
A31: Vendredi | B31: 45534 | C31: 50000 | D31: 53000 | I31: 1 | L31: 50000
A32: Samedi | B32: 45535 | C32: 55000 | D32: 72000 | I32: 1 | L32: 55000 | P32: =SUM(P26:P31) -> 0
C33: =SUM(C2:C32) -> 2260000 | D33: =SUM(D2:D32) -> 1427000 | E33: ='Les Charges'!G302 -> 639829 | F33: =Salaire!K38 -> 305492.07 | G33: 150000 | H33: =D33-E33-F33-G33 -> 331678.93 | I33: =SUM(I2:I32) -> 25 | L33: =SUM(L2:L32) -> 2260000
M35: =M11-M29-M34 -> 751171
D38: -

Sheet Pointage
B1: Date | C1: Lynda | D1: Hafida | E1: Yasmine Sidi Abd Allah | F1: Nawel | G1: Saida | H1: Nadjet | I1: Israa | J1: Samira | K1: Zohra | L1: Ahlem | M1: Sarah | N1: Karima | O1: Romayessa | P1: Kahina | Q1: Hadjer+chiraz+ période d'éssaie | R1: Amina | S1: Wafa | T1: Salma | U1: Nesrine | V1: Kenza | W1: Yasmine
A2: Jeudi | B2: 45505 | C2: 0 | D2: 1 | E2: 1 | F2: 1 | G2: 0 | H2: 1.5 | I2: 0 | J2: 1.5 | K2: 0 | L2: 0 | M2: 3 | N2: 0 | O2: 1.5 | P2: 0 | Q2: 0 | R2: 0 | S2: 0 | T2: 0 | U2: 1 | V2: 1 | W2: 1 | X2: Sara les 2 jours denjuillet
A3: Vendredi | B3: 45506 | C3: 0 | D3: 1 | E3: 1 | F3: 0 | G3: 0 | H3: 1 | I3: 0 | J3: 1.5 | K3: 2 | L3: 0 | M3: 1 | N3: 0 | O3: 1 | P3: 0 | Q3: 0 | R3: 0 | S3: 0 | T3: 0 | U3: 0 | V3: 1 | W3: 1
A4: Samedi | B4: 45507 | C4: 0 | D4: 1 | E4: 0 | F4: 0 | G4: 0 | H4: 0 | I4: 0 | J4: 1 | K4: 2 | L4: 0 | M4: 0 | N4: 0 | O4: 0 | P4: 0 | Q4: 0 | R4: 0 | S4: 0 | T4: 0 | U4: 0 | V4: 0 | W4: 0
A5: Dimanche | B5: 45508 | C5: 0 | D5: 1 | E5: 0 | F5: 0 | G5: 0 | H5: 0 | I5: 0 | J5: 1 | K5: 0 | L5: 0 | M5: 0 | N5: 0 | O5: 0 | P5: 0 | Q5: 0 | R5: 0 | S5: 0 | U5: 0 | V5: 0 | W5: 0
A6: Lundi | B6: 45509 | C6: 0 | D6: 1 | E6: 0 | F6: 0 | G6: 0 | H6: 0 | I6: 0 | J6: 1 | K6: 0 | L6: 0 | M6: 0 | N6: 0 | O6: 0 | P6: 0 | Q6: 0 | R6: 0 | S6: 0 | T6: 0 | U6: 0 | V6: 0 | W6: 0
A7: Mardi | B7: 45510 | C7: 0 | D7: 1 | E7: 0 | F7: 0 | G7: 0 | H7: 0 | I7: 0 | J7: 1 | K7: 0 | L7: 0 | M7: 0 | N7: 0 | O7: 0 | P7: 0 | Q7: 0 | R7: 0 | S7: 0 | T7: 0 | U7: 0 | V7: 0 | W7: 0
A8: Merdredi | B8: 45511 | C8: 0 | D8: 1 | E8: 0 | F8: 0 | G8: 0 | H8: 0 | I8: 0 | J8: 1 | K8: 0 | L8: 0 | M8: 0 | N8: 0 | O8: 0 | P8: 0 | Q8: 0 | R8: 0 | S8: 0 | T8: 0 | U8: 0 | V8: 0 | W8: 0
A9: Jeudi | B9: 45512 | C9: 0 | D9: 1 | E9: 0 | F9: 0 | G9: 0 | H9: 0 | I9: 0 | J9: 1 | K9: 0 | L9: 0 | M9: 0 | N9: 0 | O9: 0 | P9: 0 | Q9: 0 | R9: 0 | S9: 0 | T9: 0 | U9: 0 | V9: 0 | W9: 0
A10: Vendredi | B10: 45513 | C10: 0 | D10: 1 | E10: 0 | F10: 0 | G10: 0 | H10: 0 | I10: 0 | J10: 1 | K10: 0 | L10: 0 | M10: 0 | N10: 0 | O10: 0 | P10: 0 | Q10: 0 | R10: 0 | S10: 0 | T10: 0 | U10: 0 | V10: 0 | W10: 0
A11: Samedi | B11: 45514 | C11: 0 | D11: 1 | E11: 1.3 | F11: 0 | G11: 0 | H11: 2 | I11: 0 | J11: 1 | K11: 0 | L11: 0 | M11: 0 | N11: 0 | O11: 0 | P11: 0 | Q11: 0 | S11: 0 | T11: 0 | U11: 1 | V11: 0 | W11: 0
A12: Dimanche | B12: 45515 | C12: 0 | D12: 0 | E12: 1.3 | F12: 0 | G12: 0 | H12: 2 | I12: 0 | J12: 1 | K12: 0 | L12: 0 | M12: 0 | N12: 0 | O12: 0 | P12: 0 | Q12: 1 | R12: 0 | S12: 0 | T12: 0 | U12: 1 | V12: 0 | W12: 0
A13: Lundi | B13: 45516 | C13: 0 | D13: 0 | E13: 1.3 | F13: 0 | G13: 0 | H13: 2 | I13: 0 | J13: 1 | K13: 1 | L13: 0 | M13: 0 | N13: 0 | O13: 0 | P13: 0 | Q13: 1 | R13: 0 | S13: 0 | T13: 0 | U13: 1 | V13: 0 | W13: 0
A14: Mardi | B14: 45517 | C14: 0 | D14: 0 | E14: 2 | F14: 0 | G14: 0 | H14: 2 | I14: 0 | J14: 1 | K14: 0 | L14: 0 | M14: 0 | N14: 0 | O14: 0 | P14: 0 | Q14: 0 | R14: 0 | S14: 0 | T14: 0 | U14: 0 | V14: 0 | W14: 0
A15: Mercredi | B15: 45518 | C15: 0 | D15: 0 | E15: 1.5 | F15: 0 | G15: 0 | H15: 1.5 | I15: 0 | J15: 1 | K15: 1 | L15: 1 | M15: 0 | N15: 0 | O15: 0 | P15: 0 | Q15: 0 | R15: 0 | S15: 0 | T15: 0 | U15: 0 | V15: 0 | W15: 0
A16: Jeudi | B16: 45519 | C16: 0 | D16: 0 | E16: 2 | F16: 0 | G16: 1 | H16: 1 | I16: 1 | J16: 1 | K16: 0 | L16: 1 | M16: 0 | N16: 0 | O16: 0 | P16: 0 | Q16: 1 | R16: 0 | S16: 0 | T16: 0 | U16: 0 | V16: 0 | W16: 0
A17: Vendredi | B17: 45520 | C17: 0 | D17: 0 | E17: 1 | F17: 0 | G17: 0 | H17: 1 | I17: 0 | J17: 1 | K17: 0 | L17: 0 | M17: 0 | N17: 1 | O17: 0 | P17: 1 | Q17: 1 | R17: 0 | S17: 0 | T17: 0 | U17: 0 | V17: 0 | W17: 0
A18: Samedi | B18: 45521 | C18: 0 | D18: 0 | E18: 1.3 | F18: 0 | G18: 1 | H18: 1.3 | I18: 1 | J18: 1 | K18: 0 | L18: 1 | M18: 0 | N18: 0 | O18: 0 | P18: 1 | Q18: 0 | R18: 0 | S18: 0 | T18: 0 | U18: 0 | V18: 0 | W18: 0
A19: Dimanche | B19: 45522 | C19: 0 | D19: 0 | E19: 1.3 | F19: 0 | G19: 1 | H19: 1.3 | I19: 1 | J19: 0 | K19: 0 | L19: 1 | M19: 0 | N19: 0 | O19: 0 | P19: 1 | Q19: 2 | R19: 0 | S19: 0 | T19: 0 | U19: 0 | V19: 0 | W19: 0
A20: Lundi | B20: 45523 | C20: 0 | D20: 0 | E20: 1 | F20: 0 | G20: 1 | H20: 1.3 | I20: 1 | J20: 0 | K20: 0 | L20: 1 | M20: 0 | N20: 0 | O20: 0 | P20: 1 | Q20: 1 | R20: 0 | S20: 0 | T20: 0 | U20: 0 | V20: 0 | W20: 0
A21: Mardi | B21: 45524 | C21: 0 | D21: 0 | E21: 1.3 | F21: 0 | G21: 1 | H21: 1.3 | I21: 1 | J21: 0 | K21: 0 | L21: 1 | M21: 0 | N21: 0 | O21: 0 | P21: 0 | Q21: 1 | R21: 0 | S21: 0 | T21: 0 | U21: 0 | V21: 0 | W21: 1
A22: Mercredi | B22: 45525 | C22: 0 | D22: 0 | E22: 1 | F22: 0 | G22: 1 | H22: 1 | I22: 1 | J22: 0 | K22: 0 | L22: 1 | M22: 0 | N22: 0 | O22: 0 | P22: 0 | Q22: 0 | R22: 0 | S22: 0 | T22: 0 | U22: 0 | V22: 0 | W22: 0
A23: Jeudi | B23: 45526 | C23: 0 | D23: 0 | E23: 1.5 | F23: 0 | G23: 1 | H23: 1.5 | I23: 1 | J23: 0 | K23: 0 | L23: 1 | M23: 0 | N23: 0 | O23: 0 | P23: 0 | Q23: 1 | R23: 0 | S23: 0 | T23: 0 | U23: 0 | V23: 0 | W23: 0
A24: Vendredi | B24: 45527 | C24: 0 | D24: 0 | E24: 0 | F24: 0 | G24: 0 | H24: 0 | I24: 0 | J24: 0 | K24: 0 | L24: 0 | M24: 0 | N24: 0 | O24: 0 | P24: 0 | Q24: 0 | R24: 0 | S24: 0 | T24: 0 | U24: 0 | V24: 0 | W24: 0
A25: Samedi | B25: 45528 | C25: 0 | D25: 0 | E25: 1 | F25: 0 | G25: 1 | H25: 1 | I25: 1 | J25: 0 | K25: 0 | L25: 1 | M25: 0 | N25: 0 | O25: 0 | P25: 0 | Q25: 2 | R25: 1 | S25: 1 | T25: 0 | U25: 0 | V25: 0 | W25: 0 | X25: wafa +Amina
A26: Dimanche | B26: 45529 | C26: 0 | D26: 0 | E26: 1 | F26: 0 | G26: 1 | H26: 1 | I26: 1 | J26: 0 | K26: 0 | L26: 1 | M26: 0 | N26: 0 | O26: 0 | P26: 0 | Q26: 2 | R26: 1 | S26: 1 | T26: 0 | U26: 0 | V26: 0 | W26: 0 | X26: wafa +Amina+Bochra
A27: Lundi | B27: 45530 | C27: 0 | D27: 0 | E27: 1 | F27: 0 | G27: 1 | H27: 1 | I27: 1 | J27: 0 | K27: 1 | L27: 1 | M27: 0 | N27: 0 | O27: 0 | P27: 0 | Q27: 0 | R27: 1 | S27: 1 | T27: 0 | U27: 0 | V27: 0 | W27: 0
A28: Mardi | B28: 45531 | C28: 0 | D28: 0 | E28: 2 | F28: 0 | G28: 1 | H28: 2 | I28: 1 | J28: 0 | K28: 0 | L28: 1 | M28: 0 | N28: 0 | O28: 0 | P28: 0 | Q28: 0 | R28: 1 | S28: 1 | T28: 0.5 | U28: 0 | V28: 0 | W28: 0 | X28: doulble journée du Off
A29: Merdcredi | B29: 45532 | C29: 0 | D29: 0 | E29: 1 | F29: 0 | G29: 1 | H29: 1 | I29: 1 | J29: 0 | K29: 1 | L29: 1 | M29: 0 | N29: 0 | O29: 0 | P29: 0 | Q29: 5 | R29: 1 | S29: 1 | T29: 0 | U29: 0 | V29: 0 | W29: 0 | X29: 3,5 bouchera + 1,5 Allaa
A30: Jeudi | B30: 45533 | C30: 0 | D30: 0 | E30: 1.3 | F30: 0 | G30: 1 | H30: 1 | I30: 1 | J30: 0 | K30: 1 | L30: 1 | M30: 0 | N30: 0 | O30: 0 | P30: 0 | Q30: 0 | R30: 1 | S30: 1 | T30: 1 | U30: 0 | V30: 0 | W30: 0
A31: Vendredi | B31: 45534 | C31: 0 | D31: 0 | E31: 1.5 | F31: 0 | G31: 0 | H31: 1.5 | I31: 0 | J31: 0 | K31: 0 | L31: 0 | M31: 0 | N31: 0 | O31: 0 | P31: 0 | Q31: 0 | R31: 1 | S31: 1 | T31: 0 | U31: 0 | V31: 0 | W31: 0
A32: Samedi | B32: 45535 | C32: 0 | D32: 0 | E32: 2 | F32: 0 | G32: 1 | H32: 2 | I32: 1 | J32: 0 | K32: 1 | L32: 1 | M32: 0 | N32: 0 | O32: 0 | P32: 0 | Q32: 0 | R32: 1 | S32: 1 | T32: 1 | U32: 0 | V32: 0 | W32: 0 | X32: double journée pour la journée off
C33: 0 | D33: =SUM(D2:D32) -> 10 | E33: =SUM(E2:E32) -> 30.6 | F33: =SUM(F2:F32) -> 1 | G33: =SUM(G2:G32) -> 14 | H33: =SUM(H2:H32) -> 32.2 | I33: =SUM(I2:I32) -> 14 | J33: =SUM(J2:J32) -> 18 | K33: =SUM(K2:K32) -> 10 | ... W33: =SUM(W2:W32) -> 3
C34: 1384.61 | D34: 1538.46 | E34: 1153.84 | F34: 1153.84 | G34: 1153.84 | H34: 1500 | I34: 1076.92 | J34: 1000 | K34: 1200 | L34: 1076.92 | M34: 1384.61 | N34: 1384.61 | O34: 1384.61 | P34: 1000 | Q34: 1000 | R34: 1000 | S34: 1000 | T34: 1000 | U34: 1384.61 | V34: 1384.61 | W34: 1384.61
C35: =C33*C34 -> 0 | D35: =D34*D33 -> 15384.6 | E35: =E34*E33 -> 35307.504 | F35: =F33*F34 -> 1153.84 | G35: =G33*G34 -> 16153.76 | H35: =H33*H34 -> 48300 | I35: =I33*I34 -> 15076.88 | J35: =J34*J33 -> 18000 | K35: =K34*K33 -> 12000 | L35: =L33*L34 -> 16153.8 | M35: =M33*M34 -> 5538.44 | N35: =N33*N34 -> 1384.61 | O35: =O33*O34 -> 3461.525 | P35: =P33*P34 -> 4000 | Q35: =Q34*Q33 -> 18000 | R35: =R34*R33 -> 8000 | S35: =S34*S33 -> 8000 | T35: =T33*T34 -> 2500 | U35: =U34*U33 -> 5538.44 | V35: =V33*V34 -> 2769.22 | W35: =W33*W34 -> 4153.83 | X35: =SUM(#REF!) -> #REF!
C36: 36000 | D36: 40000 | E36: 30000 | F36: 30000 | G36: 36000 | I36: 28000 | J36: 30000 | L36: 28000 | M36: 30000 | N36: 30000 | O36: 30000 | P36: 30000 | U36: 30000 | V36: 30000 | W36: 30000

Sheet Les Charges
D1: Produit | E1: Quantité | F1: Prix unitaire | G1: Prix | H1: Date d'achat
D2: poulet Haché + blanc de poulet | E2: 5 | F2: 800 | G2: =E2*F2 -> 4000 | H2: 45505
D3: viande morceaux | E3: 2 | F3: 400 | G3: =E3*F3 -> 800
D4: Légumes pour chakhechoukha | E4: 1 | F4: 300 | G4: =E4*F4 -> 300
D5: Boite en plastique | E5: 2 | F5: 300 | G5: =E5*F5 -> 600
D6: Levure chimique | E6: 320 | F6: 6.5 | G6: =E6*F6 -> 2080
D7: Semoule Fine 25kg | E7: 10 | F7: 1000 | G7: =E7*F7 -> 10000
D8: Livraison + manutention semoule | E8: 1 | F8: 1500 | G8: =E8*F8 -> 1500
D9: Semoule Fine 10kg | E9: 30 | F9: 370 | G9: =E9*F9 -> 11100
D10: farine sousimie 10kg | E10: 5 | F10: 580 | G10: =E10*F10 -> 2900
D11: Levure Boulongère 750g | E11: 3 | F11: 780 | G11: =E11*F11 -> 2340
D12: Semoule grosse moula 2kg | E12: 1 | F12: 280 | G12: =E12*F12 -> 280
D13: Khel | E13: 0 | F13: 85 | G13: =E13*F13 -> 0
D14: Maiis | E14: 9 | F14: 250 | G14: =E14*F14 -> 2250
... D69: légumes rechta | E69: 1 | F69: 300 | G69: =E69*F69 -> 300
D70: poulet haché | E70: 3 | F70: 1000 | G70: =E70*F70 -> 3000 | H70: 45518
D71: blanc de poulet | E71: 3 | F71: 1000 | G71: =E71*F71 -> 3000
D72: bessel | E72: 30 | F72: 50 | G72: =E72*F72 -> 1500
D73: Tomate fraiche | E73: 4 | F73: 100 | G73: =E73*F73 -> 400
D74: salade | E74: 2 | F74: 100 | G74: =E74*F74 -> 200
D75: légumes | E75: 1 | F75: 300 | G75: =E75*F75 -> 300
D76: lahessen | E76: 1 | F76: 15600 | G76: =E76*F76 -> 15600
D77: Plateau oeuf | E77: 3 | F77: 500 | G77: =E77*F77 -> 1500
D78: rechta | E78: 30 | F78: 100 | G78: =E78*F78 -> 3000
D79: viande hachée | E79: 1.5 | F79: 1900 | G79: =E79*F79 -> 2850
D80: cuisses de poulet | E80: 12 | F80: 200 | G80: =E80*F80 -> 2400
D81: viande morceaux | E81: 3 | F81: 600 | G81: =E81*F81 -> 1800
D82: épinards | E82: 3 | F82: 50 | G82: =E82*F82 -> 150
... D92: crème fraiche | E92: 2 | F92: 450 | G92: =E92*F92 -> 900
D93: bingo | E93: 1 | F93: 240 | G93: =E93*F93 -> 240 | H93: 45521
D94: esprit de sel+ naddaf | E94: 6 | F94: 170 | G94: =E94*F94 -> 1020
D95: chiffon | E95: 1 | F95: 150 | G95: =E95*F95 -> 150
D96: pala | E96: 1 | F96: 100 | G96: =E96*F96 -> 100
D97: canette IZEM | E97: 5 | F97: 100 | G97: =E97*F97 -> 500
D98: Canette Coca | E98: 20 | F98: 80 | G98: =E98*F98 -> 1600
D99: Bouteille Hamoud | E99: 30 | F99: 50 | G99: =E99*F99 -> 1500
D100: Hamissa | E100: 1 | F100: 220 | G100: =E100*F100 -> 220
D101: Lavette | E101: 1 | F101: 60 | G101: =E101*F101 -> 60
D102: olive éffilet | E102: 1 | F102: 200 | G102: =E102*F102 -> 200
D103: poulet haché | E103: 1 | F103: 1000 | G103: =E103*F103 -> 1000
...

Sheet Salaire
J14: Nom | K14: Salaire | L14: Avance | M14: Salaire à payer
J15: Sofiane | K15: 30000 | L15: 30000 | M15: =K15-L15 -> 0 | N15: 19000+11000
J16: Amel | K16: 30000 | L16: 30000 | M16: =K16-L16 -> 0
I17: 1 | J17: Lynda | K17: =Pointage!C35 -> 0 | L17: 0 | M17: =K17-L17 -> 0
I18: 2 | J18: Hafida | K18: =Pointage!D35 -> 15384.6 | L18: 15500 | M18: =K18-L18 -> -115.4
I19: 3 | J19: Yasmine Sidi Abd Allah | K19: 40000 | L19: 40000 | M19: =K19-L19 -> 0 | N19: 5000
I20: 4 | J20: Nawel | K20: =Pointage!F35 -> 1153.84 | L20: 1500 | M20: =K20-L20 -> -346.16
I21: 5 | J21: Saida | K21: =Pointage!G35 -> 16153.76 | L21: 16500 | M21: =K21-L21 -> -346.24
I22: 6 | J22: Nadjet | K22: =Pointage!H35 -> 48300 | L22: 48500 | M22: =K22-L22 -> -200
I23: 7 | J23: Israa | K23: 15000 | L23: 15000 | M23: =K23-L23 -> 0
I24: 8 | J24: Samira | K24: =Pointage!J35 -> 18000 | L24: 18000 | M24: =K24-L24 -> 0 | N24: 4500+13500
I25: 9 | J25: Zohra | K25: =Pointage!K35 -> 12000 | L25: 12000 | M25: =K25-L25 -> 0
J26: Ahlem | K26: 16153.8 | L26: 16500 | M26: =K26-L26 -> -346.2
I27: 11 | J27: Yasmine | K27: =Pointage!W35 -> 4153.83 | L27: 4500 | M27: =K27-L27 -> -346.17
I28: 12 | J28: Sarah | K28: =Pointage!M35 -> 5538.44 | L28: 6000 | M28: =K28-L28 -> -461.56
I29: 13 | J29: Karima Batna | K29: =Pointage!N35 -> 1384.61 | M29: =K29-L29 -> 1384.61
I30: 14 | J30: Kenza | K30: =Pointage!V35 -> 2769.22 | L30: 3000 | M30: =K30-L30 -> -230.78
I31: 15 | J31: Nesrine | K31: =Pointage!U35 -> 5538.44 | L31: 6000 | M31: =K31-L31 -> -461.56
I32: 16 | J32: Kahina | K32: =Pointage!P35 -> 4000 | L32: 4000 | M32: =K32-L32 -> 0
I33: 17 | J33: Wafa | K33: =Pointage!S35 -> 8000 | L33: 8000 | M33: =K33-L33 -> 0 | N33: 6000+2000
I34: 18 | J34: Amina | K34: =Pointage!R35 -> 8000 | L34: 8000 | M34: =K34-L34 -> 0 | N34: 2000+6000
I35: 19 | J35: Salma | K35: =Pointage!T35 -> 2500 | L35: 2500 | M35: =K35-L35 -> 0
I36: 20 | J36: Romayessa | K36: =Pointage!O35 -> 3461.525 | L36: 3500 | M36: =K36-L36 -> -38.475
I37: 21 | J37: Hadjer + Chiraz+wafa+Amina | K37: =Pointage!Q35 -> 18000 | L37: 18000 | M37: =K37-L37 -> 0
J38: TOTAL | K38: =SUM(K15:K37) -> 305492.07 | L38: =SUM(L15:L37) -> 307000 | M38: =K38-L38 -> -1507.935
M39: =K39-L39 -> 0

Sheet Feuille 5
D18: Mois de Janvier | E18: Mois de Février | F18: Mois de Mars | G18: Mois d'Avril | H18: Mois de Mai | I18: Mois de Jiun | J18: Mois de Juillet | K18: Mois d'Aout | N18: Mois d'Aout
C19: Recette | D19: 1756000 | E19: 2274000 | F19: 1984000 | G19: 1910000 | H19: 1342000 | I19: 1760000 | J19: 2260000 | K19: =RECAP!D33 -> 1427000 | M19: Recette | N19: =K19 -> 1427000
C20: Charges | D20: 920000 | E20: 914000 | F20: 928000 | G20: 744000 | H20: 646000 | I20: 804000 | J20: 958000 | K20: 640000 | M20: Charges | N20: =K20 -> 640000
C21: Salaires | D21: 349000 | E21: 410000 | F21: 406000 | G21: 344000 | H21: 436000 | I21: 396000 | J21: 432000 | K21: 307000 | M21: Salaires | N21: =K21 -> 307000
C22: Loyer | D22: 140000 | E22: 140000 | F22: 140000 | G22: 140000 | H22: 140000 | I22: 140000 | J22: 150000 | K22: 150000 | M22: Loyer | N22: 150000
C23: Profit Net | D23: =D19-D20-D21-D22 -> 347000 | E23: =E19-E20-E21-E22 -> 810000 | F23: =F19-F20-F21-F22 -> 510000 | G23: 680000 | H23: =H19-H20-H21-H22 -> 120000 | I23: 420000 | J23: =J19-J20-J21-J22 -> 720000 | K23: =K19-K20-K21-K22 -> 330000 | M23: Profit Net | N23: =K23 -> 330000

Sheet Feuille 6
