Workbook

Sheet RECAP
B1: Date | C1: Recette Fevrier 2023 | D1: Recette | E1: Charges | F1: Salaire | G1: Loyer | H1: Net Profit | I1: Nb de jours | L1: Objectif | M1: Décembre | N1: Bénéfice Moyen par jour | O1: Moyenne | P1: Moyenne salaire | Q1: pourcentage du salaire vis à vis la recettte
A2: mercredi | B2: 44986 | C2: 10000 | D2: 48000 | I2: 1 | M2: 10000 | N2: =H33/I33 -> 16795.852 | O2: =D33/I33 -> 62193.548 | P2: =F33/I33 -> 11699.387 | Q2: =P2/O2 -> 0.18811255
A3: jeudi | B3: 44987 | C3: 0 | D3: 100000 | I3: 1 | M3: 0
A4: vendredi | B4: 44988 | C4: 0 | D4: 52000 | I4: 1 | M4: 0 | N4: Moyenne des charges par jour | O4: Objectif
A5: samedi | B5: 44989 | C5: 60000 | D5: 65000 | I5: 1 | M5: 60000 | N5: =E33/I33 -> 30149.923 | O5: 100000
A6: dimanche | B6: 44990 | C6: 50000 | D6: 67000 | I6: 1 | M6: 50000 | N6: ²
A7: lundi | B7: 44991 | C7: 30000 | D7: 53000 | I7: 1 | M7: 30000
A8: mardi | B8: 44992 | C8: 40000 | D8: 50000 | I8: 1 | M8: 40000 | N8: Cash restant | O8: Magasin | P8: caisse
A9: mercredi | B9: 44993 | C9: 60000 | D9: 72000 | I9: 1 | M9: 60000 | N9: =D33-O9-E33-'les salaires'!K33 -> 257102.4 | O9: =P9*1 -> 371250 | P9: 371250
A10: jeudi | B10: 44994 | C10: 100000 | D10: 63000 | I10: 1 | M10: 100000 | N10: 161000 | P10: Sofiane: 23000+14000+20000+42000+38000-1800-1250+17000-59700+21000+15000+22000+28000 | Q10: 177250
A11: vendredi | B11: 44995 | C11: 77000 | D11: 82000 | I11: 1 | M11: 77000 | N11: loyer
A12: samedi | B12: 44996 | C12: 40000 | D12: 32000 | I12: 1 | M12: 40000 | P12: caisse : 23000
A13: dimanche | B13: 44997 | C13: 23000 | D13: 43000 | I13: 1 | M13: 23000 | P13: Literie Soummam: 171000
A14: lundi | B14: 44998 | C14: 37000 | D14: 30000 | I14: 1 | M14: 37000
A15: mardi | B15: 44999 | C15: 34000 | D15: 58000 | I15: 1 | M15: 34000
A16: mercredi | B16: 45000 | C16: 76000 | D16: 48000 | I16: 1 | M16: 76000
A17: jeudi | B17: 45001 | C17: 101000 | D17: 80000 | I17: 1 | M17: 101000 | N17: Différence mois de Janvier
A18: vendredi | B18: 45002 | C18: 76000 | D18: 40000 | I18: 1 | M18: 76000 | N18: =D33-C33 -> 528000 | P18: Recette Février | Q18: =D33*1 -> 1928000
A19: samedi | B19: 45003 | C19: 99000 | D19: 50000 | I19: 1 | M19: 99000 | N19: Différence objectif | P19: charges | Q19: =E33*1 -> 934647.6
A20: dimanche | B20: 45004 | C20: 35000 | D20: 55000 | I20: 1 | M20: 35000 | N20: =L33-D33 -> -1928000
A21: lundi | B21: 45005 | C21: 40000 | D21: 44000 | I21: 1 | M21: 40000
A22: mardi | B22: 45006 | C22: 40000 | D22: 70000 | I22: 1 | M22: 40000 | P22: Caisse | Q22: =O9*1 -> 371250
A23: mercredi | B23: 45007 | C23: 45000 | D23: 106000 | I23: 1 | J23: Date | K23: montant | M23: 45000 | N23: Les vendredis | P23: Avance salaire | Q23: ='les salaires'!K33*1 -> 365000
A24: jeudi | B24: 45008 | C24: 67000 | D24: 106000 | I24: 1 | J24: 45008 | K24: 19800 | M24: 67000 | N24: =D4+D11+D18+D25 -> 219000
A25: vendredi | B25: 45009 | C25: 53000 | D25: 45000 | I25: 1 | J25: 45009 | K25: 18000 | M25: 53000
A26: samedi | B26: 45010 | C26: 40000 | D26: 68000 | I26: 1 | J26: 45010 | K26: 18000 | M26: 40000 | N26: Cash réel | P26: Cash restant | Q26: =Q18-Q19-Q22-Q23 -> 257102.4
A27: dimanche | B27: 45011 | C27: 70000 | D27: 59000 | I27: 1 | J27: 45011 | K27: 19200 | M27: 70000 | N27: 131000
A28: lundi | B28: 45012 | C28: 36000 | D28: 61000 | I28: 1 | J28: 45012 | K28: 19200 | M28: 36000 | N28: rest à payer
A29: Mardi | B29: 45013 | C29: 61000 | D29: 64000 | I29: 1 | J29: 45013 | K29: 19200 | M29: 61000
A30: Mercredi | B30: 45014 | C30: 0 | D30: 65000 | I30: 1 | J30: 45014 | K30: 19200 | M30: 0
A31: Jeudi | B31: 45015 | C31: 0 | D31: 74000 | I31: 1 | J31: 45015 | K31: 19200 | M31: 0
A32: Vendredi | B32: 45016 | C32: 0 | D32: 78000 | I32: 1 | J32: 45016 | K32: 19200 | M32: 0 | N32: =N9-N27 -> 126102.4
C33: =SUM(C2:C32) -> 1400000 | D33: =SUM(D2:D32) -> 1928000 | E33: ='Les charges '!I336*1 -> 934647.6 | F33: ='les salaires'!J33*1 -> 362681 | G33: 110000 | H33: =D33-G33-F33-E33 -> 520671.4 | I33: =SUM(I2:I32) -> 31 | K33: =SUM(K24:K32) -> 171000 | M33: =SUM(M2:M32) -> 1400000
C35: Objectif
C36: Mois de Janvier
C39: La différence | D39: =D33-D36 -> 1928000 | E39: =E33-E36 -> 934647.6 | F39: =F33-F36 -> 362681 | G39: =G33-G36 -> 110000 | H39: =H33-H36 -> 520671.4

Sheet Pointage 
B1: Date | C1: Wahiba | D1: Lynda | E1: Fouzia | F1: Youssera | G1: Hafida | H1: Djamila | I1: Alia | J1: Yasmine | K1: Kenza | L1: Hadjira | M1: Zohra | N1: Samira | O1: Soumia | P1: Sarah | Q1: Vendeuse | R1: Salima | S1: Remarque
A2: mercredi | B2: 44986 | C2: 1 | D2: 1 | E2: 1 | F2: 1 | G2: 1 | H2: 1 | I2: 1 | J2: 1 | K2: 0 | L2: 1 | M2: 1 | N2: 1 | O2: 1 | P2: 0 | Q2: 1 | R2: 0
A3: jeudi | B3: 44987 | C3: 1 | D3: 1 | E3: 1 | F3: 1 | G3: 1 | H3: 1 | I3: 1 | J3: 1 | K3: 1 | L3: 1 | M3: 1 | N3: 1 | O3: 1 | P3: 0 | Q3: 1 | R3: 0 | S3: wahiba khademet la demie journée
A4: vendredi | B4: 44988 | C4: 0 | D4: 1 | E4: 0 | F4: 0 | G4: 0 | H4: 1 | I4: 0 | J4: 1 | K4: 1 | L4: 1 | M4: 1 | N4: 1 | O4: 0 | P4: 0 | Q4: 0 | R4: 0 | S4: Lynda khademet la demie journée
A5: samedi | B5: 44989 | C5: 1 | D5: 1 | E5: 0.5 | F5: 1 | G5: 1 | H5: 1 | I5: 1 | J5: 1 | K5: 0 | L5: 1 | M5: 1 | N5: 1 | O5: 1 | P5: 0 | Q5: 0 | R5: 0 | S5: lynda wahiba et yousra khardjou à14h avec autorisation
A6: dimanche | B6: 44990 | C6: 1 | D6: 1 | E6: 0 | F6: 1 | G6: 1 | H6: 1 | I6: 1 | J6: 0 | K6: 0.5 | L6: 0 | M6: 0 | N6: 0 | O6: 1 | P6: 0 | Q6: 1 | R6: 0 | S6: Anissa
A7: lundi | B7: 44991 | C7: 1 | D7: 1 | E7: 0 | F7: 1 | G7: 1 | H7: 1 | I7: 1 | J7: 1 | K7: 0 | L7: 0 | M7: 1 | N7: 1 | O7: 1 | P7: 0 | Q7: 1 | R7: 0
A8: mardi | B8: 44992 | C8: 1 | D8: 1 | E8: 1 | F8: 1 | G8: 1 | H8: 1 | I8: 1 | J8: 1 | K8: 0.5 | L8: 0 | M8: 1 | N8: 1 | O8: 0 | P8: 1 | Q8: 1 | R8: 0
A9: mercredi | B9: 44993 | C9: 1 | D9: 1 | E9: 1 | F9: 1 | G9: 1 | H9: 1 | I9: 1 | J9: 1 | K9: 0 | L9: 0 | M9: 0 | N9: 1 | O9: 0 | P9: 0 | Q9: 1 | R9: 0
A10: jeudi | B10: 44994 | C10: 1 | D10: 1 | E10: 0 | F10: 0 | G10: 1 | H10: 1 | I10: 1 | J10: 1 | K10: 1 | L10: 0 | M10: 0 | N10: 1 | O10: 0 | P10: 1 | Q10: 1 | R10: 0 | S10: Ahlem
A11: vendredi | B11: 44995 | C11: 1 | D11: 1 | E11: 0 | F11: 0 | G11: 1 | H11: 1 | I11: 1 | J11: 1 | K11: 0 | L11: 0 | M11: 0 | N11: 0 | O11: 0 | P11: 0 | Q11: 0 | R11: 0
A12: samedi | B12: 44996 | C12: 0 | D12: 1 | E12: 0 | F12: 1 | G12: 1 | H12: 0 | I12: 0 | J12: 1 | K12: 1 | L12: 0 | M12: 0 | N12: 0 | O12: 0 | P12: 0 | Q12: 0 | R12: 0
A13: dimanche | B13: 44997 | C13: 0 | D13: 1 | E13: 1 | F13: 1 | G13: 1 | H13: 1 | I13: 1 | J13: 0.5 | K13: 0 | L13: 0 | M13: 0 | N13: 1 | O13: 0 | P13: 0 | Q13: 1 | R13: 0 | S13: Nadjet
A14: lundi | B14: 44998 | C14: 0 | D14: 1 | E14: 0 | F14: 1 | G14: 1 | H14: 1 | I14: 1 | J14: 0 | K14: 1 | L14: 0 | M14: 0 | N14: 1 | O14: 0 | P14: 0 | Q14: 0 | R14: 0
A15: mardi | B15: 44999 | C15: 0 | D15: 1 | E15: 0.5 | F15: 0 | G15: 1 | H15: 0 | I15: 1 | J15: 0 | K15: 0 | L15: 0 | M15: 0 | N15: 1 | O15: 0 | P15: 1 | Q15: 1 | R15: 0
A16: mercredi | B16: 45000 | C16: 1 | D16: 1 | E16: 0.5 | F16: 1 | G16: 1 | H16: 1 | I16: 0 | J16: 0 | K16: 0 | L16: 0 | M16: 0 | N16: 1 | O16: 0 | P16: 0 | Q16: 1 | R16: 0
A17: jeudi | B17: 45001 | C17: 1 | D17: 1 | E17: 1.5 | F17: 1 | G17: 1.5 | H17: 1.5 | I17: 0 | J17: 0 | K17: 0 | L17: 0 | M17: 0 | N17: 1 | O17: 0 | P17: 1 | Q17: 1 | R17: 0
A18: vendredi | B18: 45002 | C18: 0 | D18: 0 | E18: 2 | F18: 0 | G18: 2 | H18: 0 | I18: 0 | J18: 0 | K18: 0 | L18: 0 | M18: 0 | N18: 1.5 | O18: 0 | P18: 0 | Q18: 0 | R18: 0
A19: samedi | B19: 45003 | C19: 1 | D19: 1 | E19: 0 | F19: 1 | G19: 1 | H19: 0 | I19: 0 | J19: 0 | K19: 0 | L19: 0 | M19: 0 | N19: 1.25 | O19: 0 | P19: 0 | Q19: 0 | R19: 0
A20: dimanche | B20: 45004 | C20: 1 | D20: 1 | E20: 0 | F20: 1 | G20: 1 | H20: 0 | I20: 0 | J20: 1 | K20: 0 | L20: 0 | M20: 0 | N20: 1 | O20: 0 | P20: 0 | Q20: 1 | R20: 0
A21: lundi | B21: 45005 | C21: 1 | D21: 1.5 | E21: 0 | F21: 0 | G21: 0 | H21: 1.5 | I21: 0 | J21: 1 | K21: 0 | L21: 0 | M21: 0 | N21: 1.5 | O21: 0 | P21: 0 | Q21: 0 | R21: 0
A22: mardi | B22: 45006 | C22: 1 | D22: 1.5 | E22: 1 | F22: 0 | G22: 1 | H22: 1 | I22: 0 | J22: 1 | K22: 0 | L22: 0 | M22: 0 | N22: 0 | O22: 0 | P22: 0 | Q22: 0 | R22: 0
A23: mercredi | B23: 45007 | C23: 2 | D23: 2 | E23: 0 | F23: 0 | G23: 1 | H23: 0 | I23: 0 | J23: 1 | K23: 0 | L23: 0 | M23: 0 | N23: 1 | O23: 0 | P23: 0 | Q23: 0 | R23: 1 | S23: Salima
A24: jeudi | B24: 45008 | C24: 1 | D24: 1 | E24: 0 | F24: 1 | G24: 1 | H24: 1 | I24: 0 | J24: 1 | K24: 1 | L24: 0 | M24: 0 | N24: 1 | O24: 0 | P24: 0 | Q24: 0 | R24: 1
A25: vendredi | B25: 45009 | C25: 0 | D25: 2 | E25: 0 | F25: 0 | G25: 1 | H25: 1 | I25: 0 | J25: 1 | K25: 0 | L25: 0 | M25: 0 | N25: 1 | O25: 0 | P25: 0 | Q25: 0 | R25: 0
A26: samedi | B26: 45010 | C26: 1 | D26: 1.5 | E26: 0 | F26: 1 | G26: 1 | H26: 1 | I26: 0 | J26: 0 | K26: 1 | L26: 0 | M26: 0 | N26: 1 | O26: 0 | P26: 0 | Q26: 0 | R26: 1
A27: dimanche | B27: 45011 | C27: 1 | D27: 1 | E27: 0 | F27: 1 | G27: 1 | H27: 1 | I27: 0 | J27: 0 | K27: 1 | L27: 0 | M27: 0 | N27: 1 | O27: 0 | P27: 0 | Q27: 0 | R27: 1
A28: lundi | B28: 45012 | C28: 1 | D28: 2 | E28: 0 | F28: 1 | G28: 1 | H28: 1 | I28: 0 | J28: 0 | K28: 0.5 | L28: 0 | M28: 0 | N28: 1 | O28: 0 | P28: 1 | Q28: 1 | R28: 1 | S28: Taous
A29: Mardi | B29: 45013 | C29: 1 | D29: 1 | E29: 0 | F29: 1 | G29: 1 | H29: 1 | I29: 0 | J29: 0 | K29: 0.5 | L29: 0 | M29: 0 | N29: 1 | O29: 0 | P29: 1 | Q29: 1 | R29: 1
A30: mercredi | B30: 45014 | C30: 1 | D30: 1 | E30: 0 | F30: 1 | G30: 1 | H30: 1 | I30: 0 | J30: 0 | K30: 0 | L30: 0 | M30: 0 | N30: 1 | O30: 0 | P30: 0 | Q30: 1 | R30: 1
A31: Jeudi | B31: 45015 | C31: 1 | D31: 1 | E31: 0 | F31: 1 | G31: 1 | H31: 1 | I31: 0 | J31: 0 | K31: 0 | L31: 0 | M31: 0 | N31: 1 | O31: 0 | P31: 1 | Q31: 1 | R31: 1
A32: Vendredi | B32: 45016 | C32: 0 | D32: 1 | E32: 0 | F32: 1 | G32: 1 | H32: 1 | I32: 0 | J32: 0 | K32: 0 | L32: 0 | M32: 0 | N32: 1 | O32: 0 | P32: 0 | Q32: 1 | R32: 0
C33: =SUM(C2:C32) -> 24 | D33: =SUM(D2:D32) -> 34.5 | E33: =SUM(E2:E32) -> 11 | F33: =SUM(F2:F32) -> 22 | G33: =SUM(G2:G32) -> 30.5 | H33: =SUM(H2:H32) -> 26 | I33: =SUM(I2:I32) -> 12 | J33: =SUM(J2:J32) -> 16.5 | ... R33: =SUM(R2:R32) -> 8
C34: 1270 | D34: 1270 | E34: 1270 | F34: 1270 | G34: 1346 | H34: 1270 | I34: 962 | J34: 1077 | K34: 1077 | L34: 1077 | M34: 962 | N34: 962 | O34: 962 | P34: 800 | Q34: 1000 | R34: 962
C35: =C34*C33 -> 30480 | D35: =D34*D33 -> 43815 | E35: =E34*E33 -> 13970 | F35: =F34*F33 -> 27940 | G35: =G34*G33 -> 41053 | H35: =H34*H33 -> 33020 | I35: =I34*I33 -> 11544 | J35: =J34*J33 -> 17770.5 | ... Q35: =Q34*Q33 -> 17000 | R35: =R33*R34 -> 7696 | S35: =SUM(C35:P35) -> 278029

Sheet Feuille 7

Sheet les salaires
I14: Nom | J14: Salaire | K14: Avance | L14: Salaire à payer
H15: 1 | I15: Sofiane | J15: 30000 | K15: 30000 | L15: =J15-K15 -> 0 | M15: 12500+5500+12000
H16: 2 | I16: Amel | J16: 30000 | K16: 30000 | L16: =J16-K16 -> 0 | M16: 10000+5000+15000
H17: 3 | I17: Wahiba | J17: ='Pointage '!C35*1 -> 30480 | K17: 30500 | L17: =J17-K17 -> -20
H18: 4 | I18: Lynda | J18: ='Pointage '!D35*1 -> 43815 | K18: 44000 | L18: =J18-K18 -> -185
H19: 5 | I19: Fouzia | J19: ='Pointage '!E35*1 -> 13970 | K19: 14000 | L19: =J19-K19 -> -30
H20: 6 | I20: Youssera | J20: ='Pointage '!F35*1 -> 27940 | K20: 28000 | L20: =J20-K20 -> -60 | M20: 2000+2000+24000
H21: 7 | I21: Hafida | J21: ='Pointage '!G35*1 -> 41053 | K21: 41000 | L21: 0 | M21: 1000+7000+1000+32000
H22: 8 | I22: Djamila | J22: ='Pointage '!H35*1 -> 33020 | K22: 33000 | L22: 0
H23: 9 | I23: Alia | J23: 11500 | K23: 11500 | L23: =J23-K23 -> 0 | M23: 3000+8500
H24: 10 | I24: Yasmine | J24: ='Pointage '!J35*1 -> 17770.5 | K24: 18000 | L24: =J24-K24 -> -229.5
H25: 11 | I25: Kenza | J25: ='Pointage '!K35*1 -> 10770 | K25: 11000 | L25: =J25-K25 -> -230
H26: 12 | I26: Hadjira | J26: ='Pointage '!L35*1 -> 4308 | K26: 4500 | L26: =J26-K26 -> -192
H27: 13 | I27: Zohra | J27: ='Pointage '!M35*1 -> 5772 | K27: 6000 | L27: =J27-K27 -> -228
H28: 14 | I28: Samira | J28: ='Pointage '!N35*1 -> 27176.5 | K28: 27500 | L28: =J28-K28 -> -323.5 | M28: 1000+1000+1000+24500
H29: 15 | I29: Salima | J29: ='Pointage '!R35*1 -> 7696 | K29: 8000 | L29: =J29-K29 -> -304
H30: 16 | I30: Sarah | J30: ='Pointage '!P35*1 -> 5600 | K30: 6000 | L30: =J30-K30 -> -400
H31: 17 | I31: Vendeuse | J31: ='Pointage '!Q35*1 -> 17000 | K31: 17000 | L31: =J31-K31 -> 0
H32: 18 | I32: Soumia | J32: ='Pointage '!O35*1 -> 4810 | K32: 5000 | L32: =J32-K32 -> -190
I33: TOTAL | J33: =SUM(J15:J32) -> 362681 | K33: =SUM(K15:K32) -> 365000 | L33: =SUM(L15:L32) -> -2392
I34: =J33-K33 -> -2319 | L34: =J34-K34 -> 0

Sheet Les charges 
F1: Produit | G1: Quantité | H1: Prix unitaire | I1: Prix | J1: Date d'achat
F2: semoule Sahel 25kg | G2: 10 | H2: 1000 | I2: =H2*G2 -> 10000 | J2: 17/01/2023
F3: semoule gros Moula 1kg | G3: 10 | H3: 160 | I3: =H3*G3 -> 1600 | J3: 44941
F4: Leuvure Boulagère | G4: 15 | H4: 385 | I4: =H4*G4 -> 5775 | J4: 44920
F5: Khel | G5: 4 | H5: 75 | I5: =H5*G5 -> 300 | J5: 14/12/2022
F6: Margarine Fleurial 250g 40 boites | G6: 45 | H6: 86 | I6: =H6*G6 -> 3870 | J6: 44805
F7: pistache | G7: 1 | H7: 1000 | I7: =H7*G7 -> 1000 | J7: 44963
F8: les gants | G8: 2 | H8: 300 | I8: =H8*G8 -> 600 | J8: 44961
F9: boites transparent 750cc | G9: 100 | H9: 15.5 | I9: =H9*G9 -> 1550 | J9: 44929
F10: olive | G10: 3 | H10: 300 | I10: =H10*G10 -> 900 | J10: 44929
F11: barquettes aluminium 1120 | G11: 50 | H11: 35 | I11: =H11*G11 -> 1750 | J11: 19/11/2022
F12: barquettes aluminium 2 compartiments | G12: 80 | H12: 36 | I12: =H12*G12 -> 2880 | J12: 19/11/2022
F13: djouz | G13: 2 | H13: 1600 | I13: =H13*G13 -> 3200 | J13: 44982
F14: fleurs de décoration | G14: 4 | H14: 150 | I14: =H14*G14 -> 600 | J14: 44982
F15: bessel | G15: 110 | H15: 130 | I15: =H15*G15 -> 14300 | J15: 44982
F16: boites 48/10 | G16: 2 | H16: 2050 | I16: =H16*G16 -> 4100 | J16: 44980
F17: Boites 48/07 | G17: 5 | H17: 1650 | I17: =H17*G17 -> 8250 | J17: 44980
F18: Boites 36/07 | G18: 3 | H18: 1300 | I18: =H18*G18 -> 3900 | J18: 44980
F19: Boite 18/07 | G19: 2 | H19: 1750 | I19: =H19*G19 -> 3500 | J19: 45232
F20: Boites 12/07 | G20: 3 | H20: 1450 | I20: =H20*G20 -> 4350 | J20: 44980
F21: boite 24 | G21: 1 | H21: 1130 | I21: =H21*G21 -> 1130 | J21: 44973
F22: farine SIM 1kg | G22: 3 | H22: 680 | I22: =H22*G22 -> 2040 | J22: 18/02/2023
F23: barquettes 1185 | G23: 40 | H23: 41 | I23: =H23*G23 -> 1640 | J23: 44980
F24: sac poubelle | G24: 2 | H24: 280 | I24: =H24*G24 -> 560 | J24: 18/02/2023
F25: pilles | G25: 5 | H25: 20 | I25: =H25*G25 -> 100 | J25: 18/02/2023
F26: semoule sahel 10kg | G26: 65 | H26: 450 | I26: =H26*G26 -> 29250 | J26: 18/02/2023
F27: fromage slices | G27: 14 | H27: 190 | I27: =H27*G27 -> 2660 | J27: 18/02/2023
F28: Thon 2kg | G28: 4 | H28: 1900 | I28: =H28*G28 -> 7600 | J28: 18/02/2023
F29: sucre glace | G29: 12 | H29: 115 | I29: =H29*G29 -> 1380 | J29: 18/02/2023
F30: miel 5kg | G30: 4 | H30: 760 | I30: =H30*G30 -> 3040 | J30: 18/02/2023
F31: Farine Mama 25kg | G31: 4 | H31: 650 | I31: =H31*G31 -> 2600 | J31: 45232
F32: margarine 500g | G32: 23 | H32: 202 | I32: =H32*G32 -> 4646 | J32: 44980
F33: semen Madina 1,8kg | G33: 10 | H33: 720 | I33: =H33*G33 -> 7200 | J33: 44980
F34: huile 2 litres | G34: 12 | H34: 1500 | I34: =H34*G34 -> 18000 | J34: 44980
F35: fardeau sucre | G35: 1 | H35: 860 | I35: =H35*G35 -> 860 | J35: 44980
F36: huile d'olive | G36: 1 | H36: 950 | I36: =H36*G36 -> 950 | J36: 22/02/2023
F37: djeldjelan | G37: 1 | H37: 850 | I37: =H37*G37 -> 850 | J37: 22/02/2023
F38: les motifs | G38: 5 | H38: 240 | I38: =H38*G38 -> 1200 | J38: 44976
F39: semoule moyenne 10kg | G39: 2 | H39: 980 | I39: =H39*G39 -> 1960 | J39: 20/02/2023
F40: boites size plateau | G40: 20 | H40: 150 | I40: =H40*G40 -> 3000 | J40: 44962
...

Sheet Feuille 5
L10: Mois de Mars
K11: Recette | L11: =RECAP!D33*1 -> 1928000
K12: Charges | L12: =RECAP!E33*1 -> 934647.6
K13: Salaires | L13: =RECAP!F33*1 -> 362681
K14: Loyer | L14: 110000
K15: Profit Net | L15: =RECAP!H33*1 -> 520671.4
Q18: Mois de Février | R18: Mois de Mars
P19: Recette | Q19: 1400000 | R19: 1928000
P20: Charges | Q20: 597000 | R20: 938000 | S20: =R20-Q20 -> 341000
P21: Salaires | Q21: 413000 | R21: 360000
D22: Facture éléctricité | E22: 1 | F22: 39000 | P22: Loyer | Q22: 110000 | R22: 110000
D23: tadjine | E23: 1 | F23: 500 | P23: Profit Net | Q23: 280000 | R23: 520000
D24: tabounate | E24: 2 | F24: 10000
F25: =SUM(F22:F24) -> 49500

Sheet Literie Soumam
B6: Produit | C6: Quantité | D6: Prix unitaire | E6: Totale à payer
B7: salade | C7: 1 | D7: 100 | E7: =C7*D7 -> 100
B8: carrote | C8: 1 | D8: 100 | E8: =C8*D8 -> 100
B9: pomme de terre | C9: 6 | D9: 65 | E9: =C9*D9 -> 390
B10: citron | C10: 1 | D10: 400 | E10: =C10*D10 -> 400
B11: hamissa | C11: 2 | D11: 400 | E11: =C11*D11 -> 800
B12: blanc de poulet | C12: 2 | D12: 800 | E12: =C12*D12 -> 1600
B13: olive noir et vert | C13: 2 | D13: 450 | E13: =C13*D13 -> 900
B14: olive dényauté | C14: 2 | D14: 350 | E14: =C14*D14 -> 700
B15: cuisse de poulet | C15: 20 | D15: 170 | E15: =C15*D15 -> 3400
B16: ferik | C16: 1 | D16: 400 | E16: =C16*D16 -> 400
B17: tomate conserve | C17: 1 | D17: 230 | E17: =C17*D17 -> 230
B18: les épices | C18: 8 | D18: 200 | E18: =C18*D18 -> 1600
E19: =C19*D19 -> 0
E20: =C20*D20 -> 0
E21: =C21*D21 -> 0
E22: =C22*D22 -> 0
E23: =C23*D23 -> 0
E24: =C24*D24 -> 0
E25: =C25*D25 -> 0
E26: =C26*D26 -> 0
E27: =C27*D27 -> 0
E28: =C28*D28 -> 0
E29: =C29*D29 -> 0
E30: =C30*D30 -> 0
... E41: =C41*D41 -> 0
E42: =SUM(E7:E41) -> 10620
