Workbook

Sheet RECAP
B1: Date | C1: Recette d'Avril 2022 | D1: Recette | E1: Charges | F1: Salaire | G1: Loyer | H1: Net Profit | I1: Nb de jours | K1: Objectif | L1: Avril | M1: Bénéfice Moyen par jour | N1: Moyenne
A2: Dimanche | B2: 44682 | C2: 0 | D2: 40000 | I2: 1 | K2: 50000 | L2: 0 | M2: =H33/I33 -> 6430.4286 | N2: =D33/I33 -> 42357.143
A3: Lundi | B3: 44683 | C3: 80000 | D3: 0 | K3: 0 | L3: 80000
A4: Mardi | B4: 44684 | C4: 50000 | D4: 0 | K4: 0 | L4: 50000 | M4: Moyenne des charges par jour | N4: Objectif
A5: Mercredi | B5: 44685 | C5: 55000 | D5: 0 | K5: 0 | L5: 55000 | M5: =E33/I33 -> 22808.714 | N5: 50000
A6: Jeudi | B6: 44686 | C6: 65000 | D6: 15000 | I6: 1 | K6: 50000 | L6: 65000 | M6: ²
A7: Vendredi | B7: 44687 | C7: 50000 | D7: 18000 | I7: 1 | K7: 50000 | L7: 50000
A8: Samedi | B8: 44688 | C8: 55000 | D8: 40000 | I8: 1 | K8: 50000 | L8: 55000 | M8: Cash restant | N8: Magasin | P8: caisse | Q8: Sousou+islem+ hayet | R8: islem | S8: Hayet
A9: Dimanche | B9: 44689 | C9: 55000 | D9: 40000 | I9: 1 | K9: 50000 | L9: 55000 | M9: =N11+N16+D33-N9-N12-E33-Salaire!I23 -> 558456 | N9: =P9+Q9 -> 51600 | P9: =P10+P11 -> 30000 | Q9: =R9+S9 -> 21600 | R9: 16100 | S9: 5500
A10: Lundi | B10: 44690 | C10: 51000 | D10: 50000 | I10: 1 | K10: 50000 | L10: 51000 | P10: 20000 | Q10: cliente | R10: 1000+4000+(12*300)+1000+5000+(3*500)
A11: Mardi | B11: 44691 | C11: 64000 | D11: 94000 | I11: 1 | K11: 50000 | L11: 64000 | M11: loyer | N11: 470000 | P11: 10000 | Q11: caissse réelle
A12: Mercredi | B12: 44692 | C12: 60000 | D12: 25000 | I12: 1 | K12: 50000 | L12: 60000 | M12: pétrin+ four | N12: 220000
A13: Jeudi | B13: 44693 | C13: 74000 | D13: 45000 | I13: 1 | K13: 50000 | L13: 74000 | N13: 75000+145000
A14: Vendredi | B14: 44694 | C14: 85000 | D14: 60000 | I14: 1 | K14: 50000 | L14: 85000
A15: Samedi | B15: 44695 | C15: 100000 | D15: 52000 | I15: 1 | K15: 50000 | L15: 100000
A16: Dimanche | B16: 44696 | C16: 55000 | D16: 30000 | I16: 1 | K16: 50000 | L16: 55000 | N16: 70000 | O16: Rest Bénifice Avril
A17: Lundi | B17: 44697 | C17: 54000 | D17: 36000 | I17: 1 | K17: 50000 | L17: 54000 | M17: Différence mois de Février | N17: 20000 | O17: Sofiane messerouf
A18: Mardi | B18: 44698 | C18: 66000 | D18: 30000 | I18: 1 | K18: 50000 | L18: 66000 | M18: =D33-C33 -> -1011000 | N18: 20000 | O18: Sofiane les pneus
A19: Mercredi | B19: 44699 | C19: 45000 | D19: 30000 | I19: 1 | K19: 50000 | L19: 45000 | M19: Différence objectif | N19: 20000 | O19: Amel analyses et echo
A20: Jeudi | B20: 44700 | C20: 100000 | D20: 35000 | I20: 1 | K20: 50000 | L20: 100000 | M20: =D33-K33 -> -214000 | N20: 100000 | O20: Chèque +cash
A21: Vendredi | B21: 44701 | C21: 60000 | D21: 15000 | I21: 1 | K21: 50000 | L21: 60000 | N21: 70000 | O21: sofiane fare + tolier
A22: Samedi | B22: 44702 | C22: 95000 | D22: 56000 | I22: 1 | K22: 50000 | L22: 95000
A23: Dimanche | B23: 44703 | C23: 50000 | D23: 60000 | I23: 1 | K23: 50000 | L23: 50000 | M23: Les vendredis | N23: =SUM(N16:N22) -> 300000 | O23: Totale bénifice Avril
A24: Lundi | B24: 44704 | C24: 65000 | D24: 30000 | I24: 1 | K24: 50000 | L24: 65000 | M24: =D7+D14+D21+D28 -> 133000
A25: Mardi | B25: 44705 | C25: 53000 | D25: 12000 | I25: 1 | K25: 50000 | L25: 53000 | M25: =L9+L16+L23+L30 -> 260000
A26: Mercredi | B26: 44706 | C26: 60000 | D26: 32000 | I26: 1 | K26: 50000 | L26: 60000 | M26: Cash réel
A27: Jeudi | B27: 44707 | C27: 60000 | D27: 150000 | I27: 1 | K27: 50000 | L27: 60000 | M27: 150000
A28: Vendredi | B28: 44708 | C28: 140000 | D28: 40000 | I28: 1 | K28: 50000 | L28: 140000 | M28: rest à payer
A29: Samedi | B29: 44709 | C29: 100000 | D29: 30000 | I29: 1 | K29: 50000 | L29: 100000 | M29: =M9-M27 -> 408456
A30: Dimanche | B30: 44710 | C30: 100000 | D30: 21000 | I30: 1 | K30: 50000 | L30: 100000
A31: Lundi | B31: 44711 | C31: 250000 | D31: 40000 | I31: 1 | K31: 50000 | L31: 250000
A32: Mardi | B32: 44712 | C32: 0 | D32: 60000 | I32: 1 | K32: 50000
C33: =SUM(C2:C32) -> 2197000 | D33: =SUM(D2:D32) -> 1186000 | E33: ='Les Charges '!F287*1 -> 638644 | F33: =Salaire!H23 -> 257304 | G33: 110000 | H33: =D33-G33-F33-E33 -> 180052 | I33: =SUM(I2:I32) -> 28 | K33: =SUM(K2:K32) -> 1400000
L34: =SUM(L2:L33) -> 2197000
C35: Objectif | D35: 2030000 | E35: 700000 | F35: 320000 | G35: 110000 | H35: =D35-E35-F35-G35 -> 900000
C36: Mois de Mars | D36: 1581000 | E36: 591000 | F36: 300000 | G36: 90000 | H36: 600000

Sheet Les Charges 
C2: Produit | D2: Quantité | E2: Prix unitaire | F2: Prix | G2: Date d'achat
C3: Boites 48/10 | D3: 5 | E3: 2700 | F3: =D3*E3 -> 13500 | G3: 44641
C4: shewepess canette | D4: 1 | E4: 1500 | F4: 1500 | G4: 44613
C5: Coca canette | D5: 1 | E5: 1450 | F5: 1450 | G5: 44613
C6: Coca bouteille | D6: 2 | E6: 520 | F6: 1040 | G6: 44613
C7: Ifruit 33cl | D7: 8 | E7: 520 | F7: 4100 | G7: 44613
C8: Rouiba 33cl | D8: 3 | E8: 430 | F8: 1290 | G8: 44613
C9: Hamoud | D9: 3 | E9: 430 | F9: 1290 | G9: 44613
C10: Pepsi | D10: 4 | E10: 390 | F10: 1560 | G10: 44613
C11: Arome Maa zehar | D11: 5 | E11: 200 | F11: 1000 | G11: 44682
C12: semoule fine Sa7el 10kg | D12: 36 sachets | E12: 650 | F12: 23400 | G12: 44672
C13: Amandes blanc | D13: 20kg | E13: 2000 | F13: 40000 | G13: 44677
C14: miel mordjane | D14: 6 | E14: 750 | F14: 4500 | G14: 44677
C15: ka3ek nakach | D15: 1000 | E15: 50 | F15: 50000 | G15: 44681
C16: 3arayech + mechekela | D16: 64 | E16: 140 | F16: =D16*E16 -> 8960 | G16: 44681
C17: plateaux d'oeuf | D17: 3 | E17: 450 | F17: 1350 | G17: 44681
C18: deyoul | D18: 3 | E18: 100 | F18: 300 | G18: 44681
C19: sucre glace | D19: 1 fardeau | E19: 1300 | F19: 1300 | G19: 44681
C20: maa zehar | D20: 1 carton | E20: 750 | F20: 750 | G20: 44681
C21: rechta | D21: 50 kg | E21: 100 | F21: 5000 | G21: 44682
C22: boites transparents 500cc | D22: 1 fardeau de 100 | E22: 13 | F22: 1300 | G22: 44641
C23: boites transparents 750cc | D23: 1 fardeau de 100 | E23: 44726 | F23: 1460 | G23: 44641
C24: noix | D24: 1 carton de 1kg | E24: 1380 | F24: 1380 | G24: 44641
C25: Lait en Poudre | D25: 1 sachet de 25kg/10kg | E25: 565 | F25: 3125 | G25: 44501
C26: Maizina | D26: 1 sachet de 25kg | E26: 135 | F26: 2000 | G26: 44501
C27: Semoule Fine Mama 2kg | D27: 10 fardeau de 12kg | E27: 1600 | F27: 16000 | G27: 44649
C28: 3akeri | D28: 02 kg | E28: 800 | F28: 1600 | G28: 44607
C29: Leuvre de Bièrre 500g la boite | D29: 2 boites de 500g | E29: 270.5 | F29: 541 | G29: 44593
C30: semoule SIM moyenne 5kg | D30: 07 sachets | E30: 350 | F30: 2450 | G30: 44637
C31: semoule fine SIM 5kg | D31: 15 sachets | E31: 350 | F31: 5250 | G31: 44637
C32: margarine fleurial 500g barquette | D32: 8 | E32: 130 | F32: 1040 | G32: 44637
C33: Semen Madina 1,8kg | D33: 1 cartons | E33: 2988 | F33: 2988 | G33: 44637
C34: Magarine fleurial 250g | D34: 100 | E34: 84 | F34: 8400 | G34: 44637
C35: ELIO 2 litres | D35: 18 fardeaux | E35: 1416 | F35: 25488 | G35: 44637
C36: Sucre 10kg | D36: 2 | E36: 920 | F36: 1840 | G36: 44637
C37: Eau minirale lala khedidja 1.5l | D37: 5 | E37: 190 | F37: 950 | G37: 44637
C38: Eau minirale lala khedidja 0.5l | D38: 5 | E38: 200 | F38: 1000 | G38: 44637
C39: semoule Amor Ben Amor 25kg | D39: 4 | E39: 1300 | F39: 5200 | G39: 44633
C40: Semoule Sosemie moyenne 10kg | D40: 2 | E40: 480 | F40: 960 | G40: 44633
C41: SIM moyenne 10kg | D41: 2 | E41: 600 | F41: 1200 | G41: 44635
...

Sheet Pointage 
B1: Date | C1: Zehor | D1: Soumia | E1: Nadjet | F1: Hadjer | G1: djamila | H1: Mounia | I1: Chiraz | J1: Yousera | K1: Nafissa | L1: Samira | M1: Hafidha | N1: Wahiba | O1: Zahida
A2: Dimanche | B2: 44682 | C2: 0 | D2: 0 | E2: 0 | F2: 0 | G2: 0 | H2: 0 | I2: 0 | J2: 1 | K2: 1 | L2: 0 | M2: 1 | N2: 0 | O2: 1
A3: Lundi | B3: 44683 | C3: 0 | D3: 0 | E3: 0 | F3: 0 | G3: 0 | H3: 0 | I3: 0 | J3: 0 | K3: 0 | L3: 0 | M3: 0 | N3: 0 | O3: 0
A4: Mardi | B4: 44684 | C4: 0 | D4: 0 | E4: 0 | F4: 0 | G4: 0 | H4: 0 | I4: 0 | J4: 0 | K4: 0 | L4: 0 | M4: 0 | N4: 0 | O4: 0
A5: Mercredi | B5: 44685 | C5: 0 | D5: 0.5 | E5: 0 | F5: 0 | G5: 0 | H5: 0.5 | I5: 0 | J5: 0 | K5: 0 | L5: 0 | M5: 0 | N5: 0 | O5: 0
A6: Jeudi | B6: 44686 | C6: 0 | D6: 0 | E6: 0 | F6: 0 | G6: 0 | H6: 0 | I6: 0 | J6: 1 | K6: 0 | L6: 0 | M6: 0 | N6: 0 | O6: 0
A7: Vendredi | B7: 44687 | C7: 0 | D7: 0 | E7: 1.67 | F7: 0 | G7: 0 | H7: 0 | I7: 0 | J7: 0 | K7: 1 | L7: 1 | M7: 0 | N7: 0 | O7: 0
A8: Samedi | B8: 44688 | C8: 1 | D8: 1 | E8: 0 | F8: 1 | G8: 0 | H8: 1 | I8: 0 | J8: 1 | K8: 1 | L8: 0 | M8: 1 | N8: 0 | O8: 1
A9: Dimanche | B9: 44689 | C9: 1 | D9: 1 | E9: 0 | F9: 1 | G9: 0 | H9: 1 | I9: 0 | J9: 1 | K9: 1 | L9: 0 | M9: 1 | N9: 0 | O9: 1
A10: Lundi | B10: 44690 | C10: 1 | D10: 1 | E10: 0 | F10: 1 | G10: 0 | H10: 1 | I10: 0 | J10: 0.5 | K10: 1 | L10: 1 | M10: 1 | N10: 0 | O10: 1
A11: Mardi | B11: 44691 | C11: 1 | D11: 1 | E11: 0 | F11: 1 | G11: 0 | H11: 0 | I11: 0 | J11: 1 | K11: 1 | L11: 1 | M11: 1 | N11: 0 | O11: 1 | P11: youssera djate a 09h les filles khalitehom yokheredjou à 14h30
A12: Mercredi | B12: 44692 | C12: 1 | D12: 0.5 | E12: 0 | F12: 0 | G12: 1 | H12: 1 | I12: 0 | J12: 1 | K12: 1 | L12: 1 | M12: 1 | N12: 1 | O12: 1 | P12: youssera djate à 09h mounia à 10h les filles à 10h30 kharedjou 14h30 sans permission
A13: Jeudi | B13: 44693 | C13: 1 | D13: 0 | E13: 0 | F13: 0.5 | G13: 1 | H13: 1 | I13: 1 | J13: 1 | K13: 1 | L13: 1 | M13: 1 | N13: 1 | O13: 1 | P13: hadjer djate à 09h kharedjet à 09h30 3awedet welate à 15h khardjet à 18h
A14: Vendredi | B14: 44694 | C14: 1 | D14: 0 | E14: 0 | F14: 1 | G14: 1 | H14: 0 | I14: 1 | J14: 1 | K14: 1 | L14: 0 | M14: 0 | N14: 0 | O14: 1
A15: Samedi | B15: 44695 | C15: 1 | D15: 0.5 | E15: 0 | F15: 1 | G15: 0 | H15: 1 | I15: 1 | J15: 1 | K15: 1 | L15: 1 | M15: 1 | N15: 1 | O15: 1 | P15: les filles dakhelou à 09h kharedjou 15h30
A16: Dimanche | B16: 44696 | C16: 1 | D16: 1 | E16: 0 | F16: 0 | G16: 1 | H16: 1 | I16: 1 | J16: 1 | K16: 1 | L16: 1 | M16: 1 | N16: 1 | O16: 1 | P16: les filles dakhelou à 09h et Mounia 09h30 kharedjou à 15h makach khadema
A17: Lundi | B17: 44697 | C17: 0.5 | D17: 1 | E17: 0 | F17: 0 | G17: 1 | H17: 0 | I17: 1 | J17: 1 | K17: 1 | L17: 1 | M17: 1 | N17: 1 | O17: 1 | P17: zehor djate à 11h30, soumeya 08h45, youssera 09h10 et kharedjou à 15h30 autorisées
A18: Mardi | B18: 44698 | C18: 1 | D18: 0.5 | E18: 0 | F18: 0 | G18: 1 | H18: 0.5 | I18: 1 | J18: 0.5 | K18: 1 | L18: 0 | M18: 1 | N18: 1 | O18: 1
A19: Mercredi | B19: 44699 | C19: 1 | D19: 1 | E19: 0 | F19: 1 | G19: 0 | H19: 1 | I19: 0 | J19: 1 | K19: 0.5 | L19: 1 | M19: 1 | N19: 1 | O19: 1
A20: Jeudi | B20: 44700 | C20: 1 | D20: 1 | E20: 0 | F20: 0 | G20: 1 | H20: 1 | I20: 0 | J20: 1 | K20: 1 | L20: 1 | M20: 1 | N20: 1 | O20: 1
A21: Vendredi | B21: 44701 | C21: 1 | D21: 1 | E21: 0 | F21: 0 | G21: 1 | H21: 0 | I21: 0 | J21: 0 | K21: 0 | L21: 0 | M21: 0 | N21: 1 | O21: 1
A22: Samedi | B22: 44702 | C22: 1 | D22: 0.5 | E22: 0 | F22: 1 | G22: 1 | H22: 0.5 | I22: 0 | J22: 1 | K22: 1 | L22: 0 | M22: 1 | N22: 0 | O22: 0 | P22: soumeya et dakhlou à 08h30 et mounia à 13h
A23: Dimanche | B23: 44703 | C23: 1 | D23: 1 | E23: 1 | F23: 1 | G23: 0 | H23: 1 | I23: 0 | J23: 1 | K23: 0 | L23: 1 | M23: 1 | N23: 0 | O23: 1 | P23: soumia djate à08h40 youssera 09h, Mounia 09h15 Mounia avait la télécomande donc dakhelou kaaamel à 09h15
A24: Lundi | B24: 44704 | C24: 1 | D24: 1 | E24: 0 | F24: 0 | G24: 1 | H24: 0.5 | I24: 0 | J24: 1 | K24: 0 | L24: 1 | M24: 1 | N24: 0 | O24: 1
A25: Mardi | B25: 44705 | C25: 1 | D25: 1 | E25: 0 | F25: 0 | G25: 0 | H25: 1 | I25: 0 | J25: 0 | K25: 0 | L25: 1 | M25: 1 | N25: 0 | O25: 1
A26: Mercredi | B26: 44706 | C26: 1 | D26: 1 | E26: 0 | F26: 0 | G26: 1 | H26: 0.5 | I26: 0 | J26: 1 | K26: 0 | L26: 1 | M26: 1 | N26: 0 | O26: 1
A27: Jeudi | B27: 44707 | C27: 1 | D27: 1 | E27: 0 | F27: 1 | G27: 1 | H27: 1 | I27: 0 | J27: 1 | K27: 1 | L27: 1.5 | M27: 0 | N27: 1.5 | O27: 1
A28: Vendredi | B28: 44708 | C28: 1 | D28: 0 | E28: 0 | F28: 1 | G28: 1 | H28: 0 | I28: 0 | J28: 0 | K28: 1 | L28: 0 | M28: 0 | N28: 0 | O28: 1
A29: Samedi | B29: 44709 | C29: 1 | D29: 0.5 | E29: 0 | F29: 0.5 | G29: 0 | H29: 0.5 | I29: 0 | J29: 1 | K29: 1 | L29: 1 | M29: 0 | N29: 1 | O29: 0
A30: Dimanche | B30: 44710 | C30: 1 | D30: 1 | E30: 0 | F30: 1 | G30: 1 | H30: 1 | I30: 0 | J30: 1 | K30: 1 | L30: 0 | M30: 1 | N30: 0 | O30: 1 | P30: les filles djaw à 09h et ma kharedjouch les salés sauf mini pizzas + poulet avarié
A31: Lundi | B31: 44711 | C31: 0.5 | D31: 1 | E31: 0 | F31: 1 | G31: 1 | H31: 1 | I31: 0 | J31: 0 | K31: 1 | L31: 1 | M31: 1 | O31: 1
A32: Mardi | B32: 44712 | C32: 1 | D32: 1 | E32: 0 | F32: 1 | G32: 1 | H32: 0 | I32: 0 | J32: 1 | K32: 1 | L32: 1 | M32: 1 | N32: 0 | O32: 1
B33: Totale | C33: =SUM(C2:C32) -> 24 | D33: =SUM(D2:D32) -> 20 | E33: =SUM(E2:E32) -> 2.67 | F33: =SUM(F2:F32) -> 15 | G33: =SUM(G2:G32) -> 16 | H33: =SUM(H2:H32) -> 17 | I33: =SUM(I2:I32) -> 6 | J33: =SUM(J2:J32) -> 22 | ... O33: =SUM(O2:O32) -> 24
C34: 2000 | D34: 1200 | E34: 1200 | F34: 1200 | G34: 1000 | H34: 1000 | I34: 600 | J34: 1000 | K34: 1000 | L34: 1000 | M34: 1200 | N34: 1000 | O34: 1200
C35: =C34*C33 -> 48000 | D35: =D34*D33 -> 24000 | E35: =E34*E33 -> 3204 | F35: =F34*F33 -> 18000 | G35: =G34*G33 -> 16000 | H35: =H34*H33 -> 17000 | I35: =I34*I33 -> 3600 | J35: =J34*J33 -> 22000 | ... O35: =O34*O33 -> 28800 | P35: =SUM(C35:O35) -> 257304
H43: 257304
H44: 238501
H45: =H43-H44 -> 18803

Sheet Salaire
G9: Nom | H9: Salaire | I9: Avance | J9: Salaire à payer
F10: 1 | G10: Zehor | H10: ='Pointage '!C35*1 -> 48000 | I10: 48000 | J10: =H10-I10 -> 0 | K10: 48000
F11: 2 | G11: Soumia | H11: ='Pointage '!D35*1 -> 24000 | I11: 24000 | J11: =H11-I11 -> 0 | K11: 6000+2000+2400+2000+1000+10400
F12: 3 | G12: Nadjet | H12: ='Pointage '!E35*1 -> 3204 | I12: 3200 | J12: =H12-I12 -> 4 | K12: 2000+1200
F13: 4 | G13: Hadjer | H13: ='Pointage '!F35*1 -> 18000 | I13: 18000 | J13: =H13-I13 -> 0 | K13: 1000+17000
F14: 6 | G14: Djamila | H14: ='Pointage '!G35*1 -> 16000 | I14: 16000 | J14: =H14-I14 -> 0
F15: 7 | G15: Mounia | H15: ='Pointage '!H35*1 -> 17000 | I15: 17000 | J15: =H15-I15 -> 0 | K15: 1500+15500
F16: 8 | G16: Nafissa | H16: ='Pointage '!K35*1 -> 21500 | I16: 21500 | J16: =H16-I16 -> 0 | K16: 1000+1000+19500
F17: 9 | G17: Hafida | H17: ='Pointage '!M35*1 -> 25200 | I17: 25200 | J17: =H17-I17 -> 0 | K17: 7000+2000+5000+11200
F18: 11 | G18: Samira | H18: ='Pointage '!L35*1 -> 18500 | I18: 18500 | J18: =H18-I18 -> 0 | K18: 4000+3000+11500
F19: 12 | G19: Youssera | H19: ='Pointage '!J35*1 -> 22000 | I19: 22000 | J19: =H19-I19 -> 0 | K19: 2000+20000
F20: 13 | G20: Chiraz | H20: ='Pointage '!I35*1 -> 3600 | I20: 3600 | J20: =H20-I20 -> 0
F21: 14 | G21: Wahiba | H21: ='Pointage '!N35*1 -> 11500 | I21: 11500 | J21: =H21-I21 -> 0 | K21: 1500+10000 | L21: 1500da pour souhila
F22: 15 | G22: Zahida | H22: ='Pointage '!O35*1 -> 28800 | I22: 28800 | J22: =H22-I22 -> 0 | K22: 3000+25800
G23: TOTAL | H23: =SUM(H10:H22) -> 257304 | I23: =SUM(I10:I22) -> 257300 | J23: =SUM(J10:J22) -> 4
G24: =H23-I23 -> 4 | J24: =H24-I24 -> 0

Sheet Feuille 5
H10: Mois de Janvier | I10: Mois de Février | J10: Mois de Mars | K10: Mois d'Avril | L10: Mois de Mai | M10: Objectif
G11: Recette | H11: 1051000 | I11: 1300000 | J11: 700000 | K11: 2197000 | L11: 1186000 | M11: 1400000
G12: Charges | H12: 435000 | I12: 462400 | J12: 690000 | K12: 1033000 | L12: 639000
G13: Salaires | H13: 226000 | I13: 277600 | J13: 300000 | K13: 331500 | L13: 257000
G14: Loyer | H14: 90000 | I14: 90000 | J14: 110000 | K14: 110000 | L14: 110000 | M14: 110000
G15: Profit Net | H15: 300000 | I15: 470000 | J15: 600000 | K15: 720000 | L15: 180000
I22: Moyenne / jour
H23: Moyenne réelle | I23: 42000
H24: Objectif | I24: 50000
