Workbook

Sheet RECAP
B1: Date | C1: Recette | D1: Charges | E1: Salaire | F1: Loyer | G1: Net Profit
A2: Samedi | B2: 43862 | C2: 17000
A3: dimanche | B3: 43863 | C3: 20000
A4: lundi | B4: 43864 | C4: 25000
A5: mardi | B5: 43865 | C5: 20000
A6: mercredi | B6: 43866 | C6: 18000
A7: jeudi | B7: 43867 | C7: 25000
A8: vendredi | B8: 43868 | C8: 0 | D8: 0 | E8: 0 | F8: 0 | G8: 0
A9: samedi | B9: 43869 | C9: 23000
A10: dimanche | B10: 43870 | C10: 22000
A11: lundi | B11: 43871 | C11: 19000
A12: mardi | B12: 43872 | C12: 23000
A13: mercredi | B13: 43873 | C13: 21000 | J13: Real Net Profit
A14: jeudi | B14: 43874 | C14: 32000 | J14: =C31-D31-E31-F31 -> 82000
A15: vendredi | B15: 43875 | C15: 0 | D15: 0 | E15: 0 | F15: 0 | G15: 0
A16: samedi | B16: 43876 | C16: 12000
A17: dimanche | B17: 43877 | C17: 17000
A18: lundi | B18: 43878 | C18: 17000
A19: mardi | B19: 43879 | C19: 21000
A20: mercredi | B20: 43880 | C20: 19000
A21: jeudi | B21: 43881 | C21: 23000
A22: vendredi | B22: 43882 | C22: 0 | D22: 0 | E22: 0 | F22: 0 | G22: 0
A23: samedi | B23: 43883 | C23: 17000
A24: dimanche | B24: 43884 | C24: 23000
A25: lundi | B25: 43885 | C25: 14000
A26: mardi | B26: 43886 | C26: 16000
A27: mercredi | B27: 43887 | C27: 21000
A28: jeudi | B28: 43888 | C28: 30000
A29: vendredi | B29: 43889 | C29: 0 | D29: 0 | E29: 0 | F29: 0 | G29: 0 | J29: Cash restant
A30: samedi | B30: 43890 | C30: 26000 | J30: =C31+Charges!E98-Salaires!J19-D31 -> 343400 | R30: =C31*1 -> 521000 | S30: =Pointage!I31*1 -> 25 | T30: =R30/S30 -> 20840
A31: TOTAL | C31: =SUM(C2:C30) -> 521000 | D31: =Charges!E97*1 -> 228600 | E31: =Pointage!J33*1 -> 165400 | F31: 45000 | G31: =C31+Charges!E98-Charges!E97-E31-F31 -> 162000 | J31: =C31+Charges!E98-Salaires!J19-Charbate2020!J17-Charges!E97 -> 249800 | T31: 30000
A32: TAUX | C32: 1 | D32: =D31/C31 -> 0.43877159 | E32: =E31/C31 -> 0.31746641 | F32: =F31/C31 -> 0.086372361 | G32: =G31/C31 -> 0.3109405

Sheet Charges
C2: Produit | D2: Quantité | E2: Prix | F2: Date d'achat
C3: Semoule Extra Fin Habour | D3: 15 Sachets de 25kg | E3: 17250 | F3: 43862
C4: Levure chimique | D4: 2 boite de 100 | E4: 800 | F4: 43862
C5: jus ifruit | D5: 4 Fardeaux | E5: 2000 | F5: 43862
C6: Coca Cola cannette | D6: 1 | E6: 1500 | F6: 43862
C7: Coca Cola | D7: 1 | E7: 700 | F7: 43862
C8: Rouiba | D8: 1 | E8: 600 | F8: 43862
C9: Boites 48/10 | D9: 3 | E9: 4200 | F9: 43862
C10: Boites 36/10 | D10: 3 | E10: 3300 | F10: 43862
C11: Boites 36/07 | D11: 2 | E11: 1560 | F11: 43862
C12: Boites 08/07 | D12: 2 | E12: 1760 | F12: 43862
C13: Boites 08/06 | D13: 1 | E13: 850 | F13: 43862
C14: Sachet en papier 23 | D14: 3 fardeaux | E14: 3300 | F14: 43862
C15: Gants | D15: 1 Boite | E15: 850 | F15: 43862
C16: Aluminium | D16: 3 Boites | E16: 2900 | F16: 43862
C17: Vanille | D17: 400g | E17: 200 | F17: 43862
C18: Sanoudj | D18: 1kg | E18: 400 | F18: 43862
C19: Fromage spéciale Pizza | D19: 12.5kg | E19: 3200 | F19: 43862
C20: Tomate conserve | D20: 1 carton | E20: 2900 | F20: 43862
C21: Levure de bièrre | D21: 1 carton | E21: 4900 | F21: 43862
C22: eau de fleur | D22: 5 Bouteilles | E22: 275 | F22: 43862
C23: eau de javel | D23: 1 bidon de 5 litres | E23: 200 | F23: 43862
C24: isis | D24: 1 bidon de 5 litres | E24: 520 | F24: 43862
C25: Margarine Mani | D25: 4 cartons | E25: 11400 | F25: 43862
... C41: Gheress | D41: 60kg | E41: 10200 | F41: 43862
C42: lait candia | D42: 1 | E42: 55 | F42: 43863
C43: Herbes | D43: 8 pouquets | E43: 200 | F43: 43864
C44: Transport yassir | D44: 1 | E44: 300 | F44: 43864
C45: Recheta | D45: 10kg | E45: 1000 | F45: 43864
C46: Recheta | D46: 20kg | E46: 2000 | F46: 43865
C47: bessel | D47: 120kg | E47: 7200 | F47: 43865
C48: tomate fraiche | D48: 1.5kg | E48: 100 | F48: 43865
C49: felfel guenawa | D49: 200g | E49: 100 | F49: 43865
C50: Farine | D50: 1kg | E50: 80 | F50: 43865
C51: Transport yassir | D51: 1 | E51: 500 | F51: 43865
C52: Recheta | D52: 10kg | E52: 1000 | F52: 43867
C53: Transport Yassir | D53: 1 | E53: 400 | F53: 43867
C54: 3akeri | D54: 1kg | E54: 800 | F54: 43867
C55: Refiss | D55: 40 pièces | E55: 1600 | F55: 43869
C56: Herbes | D56: 7 bouquets | E56: 130 | F56: 43869
...

Sheet Pointage
B1: Date | C1: Zehor | D1: Hadjer | E1: Zoubida | F1: Louiza | G1: Nouara | H1: Nawel | I1: Zahida | J1: Remarque | K1: Reste à payer
A2: Samedi | B2: 43862 | C2: 1 | D2: 1 | E2: 1 | F2: 0 | G2: 0 | H2: 0 | I2: 1
A3: Dimanche | B3: 43863 | C3: 1 | D3: 0 | E3: 1 | F3: 0 | G3: 0 | H3: 0 | I3: 1
A4: Lundi | B4: 43864 | C4: 1 | D4: 1 | E4: 1 | F4: 1 | G4: 0 | H4: 0 | I4: 1
A5: Mardi | B5: 43865 | C5: 1 | D5: 1 | E5: 1 | F5: 1 | G5: 0 | H5: 0 | I5: 1
A6: Mercredi | B6: 43866 | C6: 1 | D6: 1 | E6: 1 | F6: 1 | G6: 1 | H6: 1 | I6: 1
A7: Jeudi | B7: 43867 | C7: 1 | D7: 1 | E7: 1 | F7: 1 | G7: 1 | H7: 1 | I7: 1
A8: Vendredi | B8: 43868 | C8: 0 | D8: 0 | E8: 0 | F8: 0 | G8: 0 | H8: 0 | I8: 0
A9: Samedi | B9: 43869 | C9: 1 | D9: 0 | E9: 1 | F9: 1 | G9: 1 | H9: 1 | I9: 1
A10: Dimanche | B10: 43870 | C10: 1 | D10: 0 | E10: 1 | F10: 1 | G10: 1 | H10: 1 | I10: 1
A11: Lundi | B11: 43871 | C11: 1 | D11: 0 | E11: 1 | F11: 1 | G11: 1 | H11: 1 | I11: 1
A12: Mardi | B12: 43872 | C12: 1 | D12: 0 | E12: 1 | F12: 1 | G12: 1 | H12: 1 | I12: 1
A13: Mercredi | B13: 43873 | C13: 1 | D13: 0 | E13: 1 | F13: 1 | G13: 1 | H13: 1 | I13: 1
... A28: Jeudi | B28: 43888 | C28: 1 | D28: 0 | E28: 1 | F28: 1 | G28: 1 | H28: 1 | I28: 1
A29: Vendredi | B29: 43889 | C29: 0 | F29: 0 | G29: 0 | H29: 0 | I29: 0
A30: Samedi | B30: 43890 | C30: 1 | D30: 0 | E30: 1 | F30: 0 | G30: 1 | H30: 1 | I30: 1
B31: TOTAL | C31: =SUM(C2:C30) -> 23 | D31: =SUM(D2:D30) -> 5 | E31: =SUM(E2:E30) -> 25 | F31: =SUM(F2:F30) -> 24 | G31: =SUM(G2:G30) -> 21 | H31: =SUM(H2:H30) -> 21 | I31: =SUM(I2:I30) -> 25
B32: Salaire/jour | C32: 2000 | D32: 600 | E32: 1200 | F32: 600 | G32: 1000 | H32: 1000 | I32: 1200 | J32: =SUM(C32:I32) -> 7600
B33: SALAIRES | C33: =C31*C32 -> 46000 | D33: =D32*D31 -> 3000 | E33: =E32*E31 -> 30000 | F33: =F32*F31 -> 14400 | G33: =G32*G31 -> 21000 | H33: =H32*H31 -> 21000 | I33: =I31*I32 -> 30000 | J33: =SUM(C33:I33) -> 165400

Sheet Salaires
H11: Nom | I11: Salaire | J11: Avance
G12: 1 | H12: Zehor | I12: =Pointage!C33*1 -> 46000
G13: 2 | H13: Louiza | I13: =Pointage!F33*1 -> 14400 | J13: 14000
G14: 3 | H14: Nawel | I14: =Pointage!H33*1 -> 21000 | J14: 12000
G15: 4 | H15: Nowara | I15: =Pointage!G33*1 -> 21000
G16: 5 | H16: Hadjer | I16: =Pointage!D33*1 -> 3000 | J16: 3000
G17: 6 | H17: Zoubida | I17: =Pointage!E33*1 -> 30000
G18: 7 | H18: Zahida | I18: =Pointage!I33*1 -> 30000
H19: TOTAL | I19: =SUM(I12:I18) -> 165400 | J19: =SUM(J12:J18) -> 29000
I20: =I19-J19 -> 136400

Sheet Magasin

Sheet Objectif
G9: Objectif | H9: Real | I9: Manque | J9: Bénéfice Prévu | K9: Bénéfice réel
G10: =RECAP!T31*RECAP!S30 -> 750000 | H10: =RECAP!C31*1 -> 521000 | I10: =G10-H10 -> 229000 | J10: =G10+Charges!E98-Charges!E97-RECAP!F31-RECAP!E31 -> 391000 | K10: =RECAP!G31*1 -> 162000
G19: =RECAP!C31+Charges!E98-Charges!E97-Salaires!J19-RECAP!F31-RECAP!F31 -> 253400
G20: =Charges!E98+Salaires!I20+RECAP!G31 -> 378400

Sheet Charbate2020
I5: Charbate 2020
I6: 225 kg citron | J6: 31500
I7: 200kg citron | J7: 29000
I8: 4 3assarates | J8: 480
I9: 3 rapeuses | J9: 900
I10: 3 cotaux | J10: 270
I11: 8 bas de 14 litres | J11: 2800
I12: 3 bacs de 22 litres | J12: 1050
I13: 3 plats | J13: 600
I14: 3assara éléctrique | J14: 2400
I15: les filles | J15: 18000
I16: 100kg Sucre | J16: 6600
I17: Totale | J17: =SUM(J6:J16) -> 93600
