Workbook

Sheet RECAP
B1: Date | C1: Recette de Septembre | D1: Recette | E1: Charges | F1: Salaire | G1: Loyer | H1: Net Profit | I1: Nb de jours | K1: Objectif | L1: Septembre | O1: Moyenne
A2: Vendredi | B2: 44470 | C2: 0 | D2: 0 | K2: 0 | L2: 0 | O2: =D33/I33 -> 46692.308
A3: Samedi | B3: 44471 | C3: 0 | D3: 50000 | I3: 1 | K3: 0 | L3: 0
A4: Dimanche | B4: 44472 | C4: 0 | D4: 26000 | I4: 1 | K4: 0 | L4: 0 | O4: 60000
A5: Lundi | B5: 44473 | C5: 50000 | D5: 30000 | I5: 1 | K5: 60000 | L5: 50000
A6: Mardi | B6: 44474 | C6: 42000 | D6: 28000 | I6: 1 | K6: 60000 | L6: 42000
A7: Mercredi | B7: 44475 | C7: 58000 | D7: 25000 | I7: 1 | K7: 60000 | L7: 58000
A8: Jeudi | B8: 44476 | C8: 41000 | D8: 80000 | I8: 1 | K8: 60000 | L8: 41000 | N8: Cash restant | O8: Magasin
A9: Vendredi | B9: 44477 | C9: 38000 | D9: 0 | I9: 0 | K9: 60000 | L9: 38000 | N9: =D33+charges!F267-O9-E33-#REF! -> #REF! | O9: 5000
A10: Samedi | B10: 44478 | C10: 60000 | D10: 25000 | I10: 1 | K10: 60000 | L10: 60000
A11: Dimanche | B11: 44479 | C11: 0 | D11: 25000 | I11: 1 | K11: 0 | L11: 0
A12: Lundi | B12: 44480 | C12: 61000 | D12: 40000 | I12: 1 | K12: 60000 | L12: 61000
A13: Mardi | B13: 44481 | C13: 24000 | D13: 30000 | I13: 1 | K13: 60000 | L13: 24000
A14: Mercredi | B14: 44482 | C14: 38000 | D14: 44000 | I14: 1 | K14: 60000 | L14: 38000
A15: Jeudi | B15: 44483 | C15: 28000 | D15: 70000 | I15: 1 | K15: 60000 | L15: 28000
A16: Vendredi | B16: 44484 | C16: 50000 | D16: 0 | I16: 0 | K16: 60000 | L16: 50000
A17: Samedi | B17: 44485 | C17: 26000 | D17: 77000 | I17: 1 | K17: 60000 | L17: 26000 | N17: Différence mois de Septembre
A18: Dimanche | B18: 44486 | C18: 0 | D18: 90000 | I18: 1 | K18: 0 | L18: 0 | N18: =D33-C33 -> 213000
A19: Lundi | B19: 44487 | C19: 25000 | D19: 100000 | I19: 1 | K19: 60000 | L19: 25000 | N19: Différence objectif
A20: Mardi | B20: 44488 | C20: 26000 | D20: 28000 | I20: 1 | K20: 60000 | L20: 26000 | N20: =D33-K33 -> -286000
A21: Mercredi | B21: 44489 | C21: 36000 | D21: 34000 | I21: 1 | K21: 60000 | L21: 36000
A22: Jeudi | B22: 44490 | C22: 44000 | D22: 80000 | I22: 1 | K22: 60000 | L22: 44000
A23: Vendredi | B23: 44491 | C23: 45000 | D23: 5000 | I23: 0 | K23: 60000 | L23: 45000
A24: Samedi | B24: 44492 | C24: 46000 | D24: 45000 | I24: 1 | K24: 60000 | L24: 46000
A25: Dimanche | B25: 44493 | C25: 1000 | D25: 34000 | I25: 1 | K25: 60000 | L25: 1000 | N25: ciyeux | O25: 25000
A26: Lundi | B26: 44494 | C26: 52000 | D26: 45000 | I26: 1 | K26: 60000 | L26: 52000 | M26: . | N26: amortisseur | O26: 7000
A27: Mardi | B27: 44495 | C27: 30000 | D27: 29000 | I27: 1 | K27: 60000 | L27: 30000 | N27: batterie | O27: 8000
A28: Mercredi | B28: 44496 | C28: 30000 | D28: 52000 | I28: 1 | K28: 60000 | L28: 30000 | N28: Sofiane | O28: 15000
A29: Jeudi | B29: 44497 | C29: 42000 | D29: 60000 | I29: 1 | K29: 60000 | L29: 42000 | O29: 12500
A30: Vendredi | B30: 44498 | C30: 38000 | D30: 0 | I30: 0 | K30: 60000 | L30: 38000
A31: Samedi | B31: 44499 | C31: 70000 | D31: 28000 | I31: 1 | K31: 0 | L31: 70000
A32: Dimanche | B32: 44500 | C32: 0 | D32: 34000 | I32: 1 | K32: 60000 | L32: 0
C33: =SUM(C2:C32) -> 1001000 | D33: =SUM(D2:D32) -> 1214000 | E33: =charges!F266 -> 510753.5 | F33: =Salaires!I29*1 -> 272573 | G33: 90000 | H33: =D33+charges!F267-charges!F266-G33-F33 -> 360673.5 | I33: =SUM(I2:I32) -> 26 | K33: =SUM(K2:K32) -> 1500000 | L33: =SUM(L2:L32) -> 1001000
C35: Objectif | D35: 1750000 | E35: 500000 | F35: 280000 | G35: 90000 | H35: 880000
C36: Mois d'Aout | D36: 1001000 | E36: 460000 | F36: 225300 | G36: 50000 | H36: 286000

Sheet charges
C3: Produit | D3: Quantité | E3: Prix unitaire | F3: Prix | G3: Date d'achat
C4: semoule Moula 10kg | D4: 10 | E4: 480 | F4: 4800 | G4: 44470
C5: Farine Maria 1kg | D5: 100kg | E5: 50 | F5: 5000 | G5: 44470
C6: Transport Semmar | D6: 1 | E6: 700 | F6: 700 | G6: 44470
C7: Tomate conserve 1kg | D7: 7 | E7: 185 | F7: 1295 | G7: 44470
C8: Harrissa | D8: 7 | E8: 180 | F8: 1260 | G8: 44470
C9: cheddar | D9: 2kg | E9: 1330 | F9: 2660 | G9: 44470
C10: margarine | D10: 24 de 500g | E10: 325 | F10: 7800 | G10: 44470
C11: fromage sandwiche | D11: 2 | E11: 670 | F11: 1340 | G11: 44470
C12: boites 12/08 | D12: 2 | E12: 1300 | F12: 2600 | G12: 44470
C13: - | D13: 2 | E13: 1050 | F13: 2100 | G13: 44470
C14: Boites 36/10 | D14: 2 | E14: 1600 | F14: 3200 | G14: 44470
C15: Boites 48/10 | D15: 2 | E15: 1920 | F15: 3840 | G15: 44470
C16: Aluminium | D16: 2 | E16: 1150 | F16: 2300 | G16: 44470
C17: quissetes N10 | D17: 1 | E17: 1670 | F17: 1670 | G17: 44470
C18: sachets transparents | D18: 1 | E18: 1200 | F18: 1200 | G18: 44470
C19: Ton 1kg | D19: 5 | E19: 750 | F19: 3750 | G19: 44470
C20: bessel | D20: 30kg | E20: 35 | F20: 1050 | G20: 44470
C21: gherss | D21: 7kg | E21: 200 | F21: 1400 | G21: 44470
C22: isis+javel moussant | D22: 5litres+ 1.5litres | E22: 400+150 | F22: 550 | G22: 44470
C23: huile fridor 10litres | D23: 10 | E23: 1100 | F23: 11000 | G23: 44470
C24: semoul Moula 25kg | D24: 5 | E24: 1100 | F24: 5500 | G24: 44470
C25: Amor Ben Amor 25kg moyenne | D25: 2 | E25: 1260 | F25: 2520 | G25: 44470
C26: oeufs | D26: 5 plateaux | E26: 400 | F26: 2000 | G26: 44470
C27: serpière | D27: 3 | E27: 110 | F27: 110 | G27: 44470
C28: lavette carée | D28: 4 | E28: 20 | F28: 80 | G28: 44470
C29: eau 1.5 litre | D29: 10 | E29: 160 | F29: 1600 | G29: 44470
C30: Rouiba 33 cl | D30: 3 | E30: 430 | F30: 430 | G30: 44470
C31: Hamoud 33 cl | D31: 3 | E31: 390 | F31: 1170 | G31: 44470
C32: djeldjelane | D32: 3 | E32: 60 | F32: 180 | G32: 44470
C33: crème liquide | D33: 2 | E33: 180 | F33: 360 | G33: 44470
C34: viande hachéée | D34: 1kg | E34: 1500 | F34: 1500 | G34: 44470
C35: olive noir et dénoyauté | D35: 2kg | E35: 400 | F35: 800 | G35: 44470
C36: deyoul | D36: 5 | E36: 80 | F36: 400 | G36: 44470
C37: tomate fraiche | D37: 4kg | E37: 50 | F37: 200 | G37: 44470
C38: fleurial 250g | D38: 5 | E38: 85 | F38: 425 | G38: 44470
C39: cafardcide | D39: 1.5 boite | E39: 20 | F39: 1500 | G39: 44470
C40: serpière | D40: 2 | E40: 110 | F40: 220 | G40: 44470
C41: chiffon | D41: 1 | E41: 200 | F41: 200 | G41: 44470
C42: semen Madina 1.8kg | D42: 4 | E42: 700 | F42: 2800 | G42: 44440
...

Sheet Pointage
B1: Date | C1: Zehor | D1: Yossera | E1: Soumia | F1: Nadjet | G1: Hadjer | H1: Amel | I1: Fatima | J1: Marwa | K1: djamila | L1: Imene | M1: Radia | N1: Wahiba houma | O1: Houda | P1: Hafidha | Q1: Sabah | R1: Zahida | S1: Remarque
A2: Vendredi | B2: 44470 | C2: 0 | D2: 0 | E2: 0 | F2: 0 | G2: 0 | H2: 0 | I2: 0 | J2: 0 | K2: 0 | L2: 0 | M2: 0 | N2: 0 | O2: 0 | P2: 0 | Q2: 0 | R2: 0
A3: Samedi | B3: 44471 | C3: 1 | D3: 0 | E3: 0 | F3: 1 | G3: 0 | H3: 1 | I3: 1 | J3: 0 | K3: 0 | L3: 0 | M3: 0 | N3: 0 | O3: 1 | P3: 0 | Q3: 1 | R3: 1
A4: Dimanche | B4: 44472 | C4: 1 | D4: 1 | E4: 0 | F4: 0.5 | G4: 1 | H4: 0 | I4: 1 | J4: 0 | K4: 0 | L4: 0 | M4: 0 | N4: 1 | O4: 1 | P4: 0 | Q4: 0 | R4: 1 | S4: Nadjet djate à midi
A5: Lundi | B5: 44473 | C5: 1 | D5: 0.5 | E5: 0 | F5: 1 | G5: 1 | H5: 1 | I5: 1 | J5: 0 | K5: 0 | L5: 0 | M5: 0 | N5: 1 | O5: 1 | P5: 0 | Q5: 0 | R5: 1
A6: Mardi | B6: 44474 | C6: 1 | D6: 1 | E6: 0 | F6: 1 | G6: 1 | H6: 0 | I6: 1 | J6: 0 | K6: 0 | L6: 0 | M6: 0 | N6: 1 | O6: 1 | P6: 0 | Q6: 0 | R6: 1
A7: Mercredi | B7: 44475 | C7: 1 | D7: 1 | E7: 0 | F7: 1 | G7: 1 | H7: 1 | I7: 1 | J7: 0 | K7: 0 | L7: 0 | M7: 0 | N7: 1 | O7: 1 | P7: 0 | Q7: 0 | R7: 1
A8: Jeudi | B8: 44476 | C8: 1 | D8: 1 | E8: 1 | F8: 1 | G8: 1 | H8: 1 | I8: 1 | J8: 0 | K8: 0 | L8: 0 | M8: 0 | N8: 1 | O8: 1 | P8: 0 | Q8: 0 | R8: 1
A9: Vendredi | B9: 44477 | C9: 0 | D9: 0 | E9: 0 | F9: 0 | G9: 0 | H9: 0 | I9: 0 | J9: 0 | K9: 0 | L9: 0 | M9: 0 | N9: 0 | O9: 0 | P9: 0 | Q9: 0 | R9: 0
A10: Samedi | B10: 44478 | C10: 1 | D10: 0.5 | E10: 1 | F10: 0 | G10: 0.5 | H10: 1 | I10: 1 | J10: 0 | K10: 0 | L10: 0 | M10: 0 | N10: 0 | O10: 1 | P10: 0 | Q10: 0 | R10: 1
A11: Dimanche | B11: 44479 | C11: 1 | D11: 1 | E11: 1 | F11: 0 | G11: 1 | H11: 0 | I11: 1 | J11: 0 | K11: 0 | L11: 0 | M11: 0 | N11: 1 | O11: 1 | P11: 0 | Q11: 0 | R11: 1
A12: Lundi | B12: 44480 | C12: 1 | D12: 1 | E12: 1 | F12: 0 | G12: 1 | H12: 1 | I12: 1 | J12: 0 | K12: 0 | L12: 0 | M12: 1 | N12: 1 | O12: 1 | P12: 0 | Q12: 0 | R12: 1 | Z12: Date | AA12: Hadjer
A13: Mardi | B13: 44481 | C13: 1 | D13: 0 | E13: 1 | F13: 0 | G13: 1 | H13: 0 | I13: 0 | J13: 0 | K13: 0 | L13: 0 | M13: 1 | N13: 1 | O13: 1 | P13: 0 | Q13: 0 | R13: 1 | Y13: Vendredi | Z13: 44470 | AA13: 0
A14: Mercredi | B14: 44482 | C14: 1 | D14: 1 | E14: 0 | F14: 0 | G14: 0 | H14: 1 | I14: 0 | J14: 0 | K14: 0 | L14: 0 | M14: 1 | N14: 1 | O14: 1 | P14: 0 | Q14: 0 | R14: 1 | Y14: Samedi | Z14: 44471 | AA14: 0
A15: Jeudi | B15: 44483 | C15: 1 | D15: 1 | E15: 1 | F15: 1 | G15: 1 | H15: 0.5 | I15: 0 | J15: 0 | K15: 0 | L15: 0 | M15: 1 | N15: 0 | O15: 1 | P15: 0 | Q15: 0 | R15: 1 | Y15: Dimanche | Z15: 44472 | AA15: 1
A16: Vendredi | B16: 44484 | C16: 1 | D16: 0 | E16: 0 | F16: 0 | G16: 1 | H16: 0 | I16: 0 | J16: 0 | K16: 0 | L16: 0 | M16: 0 | N16: 0 | O16: 2 | P16: 0 | Q16: 0 | R16: 1 | Y16: Lundi | Z16: 44473 | AA16: 1
A17: Samedi | B17: 44485 | C17: 1 | D17: 0.5 | E17: 1 | F17: 0 | G17: 1 | H17: 1 | I17: 1 | J17: 0 | K17: 0 | L17: 0 | M17: 1 | N17: 1 | O17: 1 | P17: 1 | Q17: 0 | R17: 1 | Y17: Mardi | Z17: 44474 | AA17: 1
A18: Dimanche | B18: 44486 | C18: 1 | D18: 1 | E18: 1 | F18: 0 | G18: 1 | H18: 1 | I18: 0 | J18: 0 | K18: 0 | L18: 0 | M18: 1 | N18: 0 | O18: 1 | P18: 1 | Q18: 1 | R18: 1 | Y18: Mercredi | Z18: 44475 | AA18: 1
A19: Lundi | B19: 44487 | C19: 0 | D19: 0.5 | E19: 1 | F19: 1 | G19: 1 | H19: 1 | I19: 0 | J19: 0 | K19: 0.5 | L19: 0.5 | M19: 1 | N19: 0 | O19: 1 | P19: 1 | Q19: 1 | R19: 2 | Y19: Jeudi | Z19: 44476 | AA19: 1
A20: Mardi | B20: 44488 | C20: 1 | D20: 1 | E20: 1 | F20: 0 | G20: 1 | H20: 1.5 | I20: 0 | J20: 0 | K20: 0.5 | L20: 0.5 | M20: 1 | N20: 0 | O20: 0.5 | P20: 1 | Q20: 1 | R20: 1 | S20: Houda retard 12h 30 | Y20: Vendredi | Z20: 44477 | AA20: 0
A21: Mercredi | B21: 44489 | C21: 1 | D21: 1 | E21: 1 | F21: 1 | G21: 0 | H21: 0.5 | I21: 0 | J21: 0 | K21: 1 | L21: 1 | M21: 1 | N21: 0 | O21: 1 | P21: 0 | Q21: 1 | R21: 1 | Y21: Samedi | Z21: 44478 | AA21: 0.5
A22: Jeudi | B22: 44490 | C22: 1 | D22: 1 | E22: 1 | F22: 1 | G22: 1 | H22: 0 | I22: 0 | J22: 0 | K22: 1 | L22: 1 | M22: 0 | N22: 0 | O22: 1 | P22: 1 | Q22: 0.5 | R22: 1 | S22: Radia inscription la fac | Y22: Dimanche | Z22: 44479 | AA22: 1
A23: Vendredi | B23: 44491 | C23: 0 | D23: 0 | E23: 0 | F23: 0 | G23: 0 | H23: 0 | I23: 0 | J23: 0 | K23: 0 | L23: 0 | M23: 0 | N23: 0 | O23: 0 | P23: 0 | Q23: 0 | R23: 0.5 | Y23: Lundi | Z23: 44480 | AA23: 1
A24: Samedi | B24: 44492 | C24: 1 | D24: 1 | E24: 1 | F24: 1 | G24: 0 | H24: 0 | I24: 1 | J24: 1 | K24: 1 | L24: 0 | M24: 1 | N24: 0 | O24: 1 | P24: 1 | Q24: 0 | R24: 0 | Y24: Mardi | Z24: 44481 | AA24: 1
A25: Dimanche | B25: 44493 | C25: 1 | D25: 0 | E25: 1 | F25: 1 | G25: 1 | H25: 0 | I25: 0 | J25: 1 | K25: 1 | L25: 0 | M25: 1 | N25: 0 | O25: 1 | P25: 1 | Q25: 0 | R25: 1 | S25: Hadjer retard 10h30-16h/ Radia la fac | Y25: Mercredi | Z25: 44482 | AA25: 0
A26: Lundi | B26: 44494 | C26: 1 | D26: 0 | E26: 1 | F26: 1 | G26: 1 | H26: 0 | I26: 0 | J26: 1 | K26: 1 | L26: 0 | M26: 0.5 | N26: 0 | O26: 1 | P26: 1 | Q26: 1 | R26: 1 | Y26: Jeudi | Z26: 44483 | AA26: 1
A27: Mardi | B27: 44495 | C27: 1 | D27: 0 | E27: 1 | F27: 1 | G27: 1 | H27: 0 | I27: 0 | J27: 1 | K27: 1 | L27: 0 | M27: 1 | N27: 0 | O27: 1 | P27: 1 | Q27: 0 | R27: 1 | Y27: Vendredi | Z27: 44484 | AA27: 1
A28: Mercredi | B28: 44496 | C28: 1 | D28: 0 | E28: 1 | F28: 1 | G28: 0.5 | H28: 0 | I28: 0 | J28: 1 | K28: 1 | L28: 0 | M28: 1 | N28: 0 | O28: 1 | P28: 1 | Q28: 1 | R28: 1 | S28: hadjer djate à 12h | Y28: Samedi | Z28: 44485 | AA28: 1
A29: Jeudi | B29: 44497 | C29: 1 | D29: 0 | E29: 1 | F29: 1 | G29: 1 | H29: 0 | I29: 0 | J29: 1 | K29: 1 | L29: 0 | M29: 0.5 | N29: 0 | O29: 1 | P29: 1 | Q29: 0 | R29: 1 | S29: Radia djate à 13h | Y29: Dimanche | Z29: 44486 | AA29: 1
A30: Vendredi | B30: 44498 | C30: 0 | D30: 0 | E30: 0 | F30: 0 | G30: 0 | H30: 0 | I30: 0 | J30: 0 | K30: 0 | L30: 0 | M30: 0 | N30: 0 | O30: 0 | P30: 0 | Q30: 0 | R30: 0 | Y30: Lundi | Z30: 44487 | AA30: 1
A31: Samedi | B31: 44499 | C31: 1 | D31: 0 | E31: 1 | F31: 1 | G31: 0 | H31: 0 | I31: 0 | J31: 1 | K31: 1 | L31: 0 | M31: 1 | N31: 0 | O31: 1 | P31: 1 | Q31: 0 | R31: 1 | S31: zahida djate à midi et Zehor et Nadjet kharedjou bekeri | Y31: Mardi | Z31: 44488 | AA31: 1
A32: Dimanche | B32: 44500 | C32: 1 | D32: 0 | E32: 1 | F32: 0.5 | G32: 0 | H32: 0 | I32: 0 | J32: 0 | K32: 0 | L32: 0 | N32: 0 | O32: 1 | P32: 1 | Q32: 0 | R32: 1 | Y32: Mercredi | Z32: 44489 | AA32: 0
C33: =SUM(C1:C32) -> 26 | D33: =SUM(D1:D32) -> 15 | E33: =SUM(E2:E32) -> 20 | F33: =SUM(F1:F32) -> 17 | G33: =SUM(G1:G32) -> 20 | H33: =SUM(H1:H32) -> 12.5 | I33: =SUM(I1:I32) -> 11 | J33: =SUM(J2:J32) -> 7 | K33: =SUM(K2:K32) -> 10 | L33: =SUM(L2:L32) -> 3 | M33: =SUM(M2:M32) -> 15 | N33: =SUM(N1:N32) -> 10 | O33: =SUM(O2:O32) -> 27.5 | P33: =SUM(P2:P32) -> 13 | Q33: =SUM(Q2:Q32) -> 7.5 | R33: =SUM(R1:R32) -> 27.5 | Y33: Jeudi | Z33: 44490 | AA33: 1
C34: 1923 | D34: 1000 | E34: 1000 | F34: 1000 | G34: 1000 | H34: 1200 | I34: 1000 | J34: 800 | K34: 800 | L34: 800 | M34: 1000 | N34: 500 | O34: 1200 | P34: 1200 | Q34: 930 | R34: 1200 | S34: =SUM(C34:R34) -> 16553 | Y34: Vendredi | Z34: 44491 | AA34: 0
C35: =C34*C33 -> 49998 | D35: =D33*D34 -> 15000 | E35: =E34*E33 -> 20000 | F35: =F34*F33 -> 17000 | G35: =G34*G33 -> 20000 | H35: =H34*H33 -> 15000 | I35: =I34*I33 -> 11000 | J35: =J34*J33 -> 5600 | K35: =K34*K33 -> 8000 | L35: =L34*L33 -> 2400 | ... Q35: =Q34*Q33 -> 6975 | R35: =R33*R34 -> 33000 | S35: =SUM(C35:R35) -> 272573 | Y35: Samedi | Z35: 44492 | AA35: 0
Y36: Dimanche | Z36: 44493 | AA36: 1
Y37: Lundi | Z37: 44494 | AA37: 1
Y38: Mardi | Z38: 44495 | AA38: 1
Y39: Mercredi | Z39: 44496 | AA39: 0.5
Y40: Jeudi | Z40: 44497 | AA40: 1
...

Sheet Salaires
H12: Nom | I12: Salaire | J12: Avance | K12: Salaire à payer
G13: 1 | H13: Zehor | I13: =Pointage!C35*1 -> 49998 | J13: 0 | K13: 50000
G14: 2 | H14: Yossera | I14: =Pointage!D35*1 -> 15000 | J14: 15000 | K14: 0
G15: 3 | H15: Soumia | I15: =Pointage!E35*1 -> 20000 | J15: 2000 | K15: 18000
G16: 4 | H16: Amel | I16: =Pointage!H35*1 -> 15000 | J16: 15000 | K16: 0 | L16: 12000+3000
G17: 5 | H17: Marwa | I17: =Pointage!J35*1 -> 5600 | J17: 0 | K17: 5600
G18: 6 | H18: Djamila | I18: =Pointage!K35*1 -> 8000 | J18: 0 | K18: 8000
G19: 7 | H19: Imene | I19: =Pointage!L35*1 -> 2400 | J19: 0 | K19: 2400
G20: 8 | H20: Nadjet | I20: =Pointage!F35*1 -> 17000 | J20: 1000 | K20: 16000
G21: 9 | H21: Hadjer | I21: =Pointage!G35*1 -> 20000 | J21: 0 | K21: 20000
G22: 10 | H22: Fatima | I22: =Pointage!I35*1 -> 11000 | J22: 0 | K22: 11000
G23: 11 | H23: Houda | I23: =Pointage!O35*1 -> 33000 | J23: 0 | K23: 33000
G24: 12 | H24: Whiba | I24: =Pointage!N35*1 -> 5000 | J24: 0 | K24: 5000
G25: 13 | H25: Radia | I25: =Pointage!M35*1 -> 15000 | J25: 0 | K25: 15000
G26: 14 | H26: Sabah | I26: =Pointage!Q35*1 -> 6975 | J26: 0 | K26: 7000
G27: 15 | H27: Hafida | I27: =Pointage!P35*1 -> 15600 | J27: 7000 | K27: 9000 | L27: 2000+5000
G28: 16 | H28: Zahida | I28: =Pointage!R35*1 -> 33000 | J28: 0 | K28: 33000
H29: TOTAL | I29: =SUM(I13:I28) -> 272573 | J29: =SUM(J13:J28) -> 40000
H30: =I29-J29 -> 232573

Sheet Feuille 5
D8: Mois d'Octobre | E8: Mois de Septembre | G8: Produit | H8: quantité | I8: prix unitaire | J8: Somme | L8: Produit | M8: quantité | N8: prix unitaire | O8: Somme
C9: Recette | D9: 1214000 | E9: 1001000 | G9: Ka3ek Nakache | H9: 293 | I9: 80 | J9: =I9*H9 -> 23440 | L9: Batbout | M9: 271 | N9: 100 | O9: =N9*M9 -> 27100
C10: Charges | D10: 510000 | E10: 460000 | G10: Tcharak el3aryan | H10: 387 | I10: 150 | J10: =I10*H10 -> 58050 | L10: Berger | M10: 372 | N10: 100 | O10: =N10*M10 -> 37200
C11: Salaires | D11: 272500 | E11: 225300 | G11: Griweche | H11: 200 | I11: 60 | J11: =I11*H11 -> 12000 | L11: souflet et croissant fromage | M11: 330 | N11: 70 | O11: =N11*M11 -> 23100
C12: Loyer | D12: 90000 | E12: 50000 | G12: Sablés | H12: 89 | I12: 60 | J12: =I12*H12 -> 5340 | L12: Mini pizza | M12: 417 | N12: 70 | O12: =N12*M12 -> 29190
C13: Profit Net | D13: 360000 | E13: 286000 | G13: POP cakes | H13: 25 | I13: 100 | J13: =I13*H13 -> 2500 | L13: Souflet et croissant Thon | M13: 160 | N13: 100 | O13: =N13*M13 -> 16000
G14: cup cakes | H14: 32 | I14: 100 | J14: =I14*H14 -> 3200 | L14: Souflet et croissant poulet | M14: 128 | N14: 100 | O14: =N14*M14 -> 12800
G15: Sablés Chocolat | H15: 79 | I15: 100 | J15: =I15*H15 -> 7900 | L15: Beignets | M15: 430 | N15: 50 | O15: =N15*M15 -> 21500
G16: Amandines | H16: 52 | I16: 150 | J16: =I16*H16 -> 7800 | L16: Quiches | M16: 20 | N16: 150 | O16: =N16*M16 -> 3000
G17: Les Ruses | H17: 83 | I17: 100 | J17: =I17*H17 -> 8300 | L17: Hamiss | M17: 4 | N17: 400 | O17: =N17*M17 -> 1600
G18: Basboussa | H18: 34 | I18: 100 | J18: =I18*H18 -> 3400 | L18: Galette Farcie | M18: 17 | N18: 600 | O18: =N18*M18 -> 10200
G19: Bastila | H19: 17 | I19: 250 | J19: =I19*H19 -> 4250 | L19: pizza couverte | M19: 68 | N19: 100 | O19: =N19*M19 -> 6800
G20: Mini Tarte chocolat | H20: 71 | I20: 100 | J20: =I20*H20 -> 7100 | L20: burgers vides | M20: 30 | N20: 40 | O20: =N20*M20 -> 1200
G21: Dattes fourées | H21: 15 | I21: 500 | J21: =I21*H21 -> 7500
G22: Temina | H22: 11 | I22: 600 | J22: =I22*H22 -> 6600
G23: ésquimaux | H23: 30 | I23: 100 | J23: =I23*H23 -> 3000
G24: Khachkhache | H24: 25 | I24: 70 | J24: =I24*H24 -> 1750
G25: Halwet Taba3 | H25: 70 | I25: 45 | J25: =I25*H25 -> 3150
G26: Bourak | H26: 26 | I26: 150 | J26: =I26*H26 -> 3900
G27: Gherybia | H27: 28 | I27: 40 | J27: =I27*H27 -> 1120
G28: Ke3ike3ate messekerine | H28: 15 | I28: 150 | J28: =I28*H28 -> 2250
G29: Totale | J29: =SUM(J9:J28) -> 172550 | L29: Totale | O29: =SUM(O9:O28) -> 189690
G31: Salaires du 2 ème Locale | H31: =Pointage!D35+Pointage!E35+Pointage!M35+Pointage!O35+Pointage!Q35 -> 89975
G32: Location | H32: 40000
