Workbook

Sheet RECAP
B1: Date | C1: Recette de Mars | D1: Recette | E1: Charges | F1: Salaire | G1: Loyer | H1: Net Profit | I1: Nb de jours | K1: Objectif | L1: Avril | O1: Moyenne
A2: Samedi | B2: 44317 | C2: 48000 | D2: 21000 | I2: 1 | K2: 45000 | L2: 48000 | O2: =D33/I33 -> 31322.581
A3: dimanche | B3: 44318 | C3: 0 | D3: 34000 | I3: 1 | K3: 45000 | L3: 0
A4: lundi | B4: 44319 | C4: 38000 | D4: 35000 | I4: 1 | K4: 45000 | L4: 38000 | O4: =K33/I33 -> 45000
A5: mardi | B5: 44320 | C5: 15000 | D5: 15000 | I5: 1 | K5: 45000 | L5: 15000
A6: mercredi | B6: 44321 | C6: 27000 | D6: 33000 | I6: 1 | K6: 45000 | L6: 27000
A7: jeudi | B7: 44322 | C7: 38000 | D7: 43000 | I7: 1 | K7: 45000 | L7: 38000
A8: vendredi | B8: 44323 | C8: 44000 | D8: 25000 | I8: 1 | K8: 45000 | L8: 44000
A9: samedi | B9: 44324 | C9: 46000 | D9: 45000 | I9: 1 | K9: 45000 | L9: 46000
A10: dimanche | B10: 44325 | C10: 8000 | D10: 46000 | I10: 1 | K10: 45000 | L10: 8000
A11: lundi | B11: 44326 | C11: 46000 | D11: 90000 | I11: 1 | K11: 45000 | L11: 46000 | N11: Cash restant | O11: Magasin | R11: Différence mois de Mars
A12: mardi | B12: 44327 | C12: 30000 | D12: 190000 | I12: 1 | K12: 45000 | L12: 30000 | N12: =D33+Charges!G203-O12-E33-'salaire '!L22 -> 463991 | O12: 17000 | R12: =D33-C33 -> -224000
A13: mercredi | B13: 44328 | C13: 41000 | D13: 40000 | I13: 1 | K13: 45000 | L13: 41000 | R13: Différence objectif
A14: jeudi | B14: 44329 | C14: 50000 | D14: 0 | I14: 1 | K14: 45000 | L14: 50000 | Q14: caisse | R14: =D33-K33 -> -424000
A15: vendredi | B15: 44330 | C15: 142000 | D15: 0 | I15: 1 | K15: 45000 | L15: 142000
A16: samedi | B16: 44331 | C16: 37000 | D16: 0 | I16: 1 | K16: 45000 | L16: 37000
A17: dimanche | B17: 44332 | C17: 36000 | D17: 0 | I17: 1 | K17: 45000 | L17: 36000
A18: lundi | B18: 44333 | C18: 45000 | D18: 15000 | I18: 1 | K18: 45000 | L18: 45000
A19: mardi | B19: 44334 | C19: 40000 | D19: 32000 | I19: 1 | K19: 45000 | L19: 40000
A20: mercredi | B20: 44335 | C20: 34000 | D20: 55000 | I20: 1 | K20: 45000 | L20: 34000
A21: jeudi | B21: 44336 | C21: 50000 | D21: 35000 | I21: 1 | K21: 45000 | L21: 50000
A22: vendredi | B22: 44337 | C22: 33000 | D22: 12000 | I22: 1 | K22: 45000 | L22: 33000
A23: samedi | B23: 44338 | C23: 45000 | D23: 23000 | I23: 1 | K23: 45000 | L23: 45000
A24: dimanche | B24: 44339 | C24: 61000 | D24: 14000 | I24: 1 | K24: 45000 | L24: 61000
A25: lundi | B25: 44340 | C25: 45000 | D25: 19000 | I25: 1 | K25: 45000 | L25: 45000
A26: mardi | B26: 44341 | C26: 34000 | D26: 21000 | I26: 1 | K26: 45000 | L26: 34000
... A28: jeudi | B28: 44343 | C28: 37000 | D28: 28000 | I28: 1 | K28: 45000 | L28: 37000
A29: vendredi | B29: 44344 | C29: 26000 | D29: 27000 | I29: 1 | K29: 45000 | L29: 26000 | M29: .
A30: samedi | B30: 44345 | C30: 49000 | D30: 18000 | I30: 1 | K30: 45000 | L30: 49000
A31: dimanche | B31: 44346 | C31: 28000 | D31: 12000 | I31: 1 | K31: 45000 | L31: 28000
A32: lundi | B32: 44347 | C32: 0 | D32: 12000 | I32: 1 | K32: 45000 | L32: 0
C33: =SUM(C2:C32) -> 1195000 | D33: =SUM(D2:D32) -> 971000 | E33: =Charges!G202*1 -> 461009 | F33: ='salaire '!K22*1 -> 199440 | G33: 50000 | H33: =D33+Charges!G203-E33-F33-G33 -> 280551 | I33: =SUM(I2:I32) -> 31 | K33: =SUM(K2:K32) -> 1395000 | L33: =SUM(L2:L32) -> 1195000
C35: Objectif | D35: 1365000 | E35: 500000 | F35: 215000 | G35: 50000 | H35: 600000
C36: Mois d'Avril | D36: 1195000 | E36: 680000 | F36: 214700 | G36: 50000 | H36: 270000

Sheet Charges
D2: Produit | E2: Quantité | F2: Prix unitaire | G2: Prix | H2: Date d'achat
D3: Amandes | E3: 5kg | F3: 1880 | G3: 9400 | H3: 44317
D4: arachides | E4: 1kg | F4: 440 | G4: 440 | H4: 44317
D5: Arachdes éfilet | E5: 1kg | F5: 650 | G5: 650 | H5: 44317
D6: Amandes éfilet | E6: 500g | F6: 2000 | G6: 1000 | H6: 44317
D7: pistache | E7: 250g | F7: 4000 | G7: 1000 | H7: 44317
D8: les quissetes num 10 | E8: 1 | F8: 2100 | G8: 2100 | H8: 44317
D9: margarine fleurial 500g | E9: 5 cartons | F9: 2000 | G9: 10000 | H9: 44317
D10: ka3ek nakach | E10: 1105 | F10: 50 | G10: 55250 | H10: 44317
D11: boites de sauce | E11: 1 fardeau | F11: 1500 | G11: 1500 | H11: 44317
D12: les quissetes num 10 | E12: 1 | F12: 60 | G12: 60 | H12: 44317
D13: les moules | E13: 3 | F13: 100 | G13: 300 | H13: 44317
D14: torchons | E14: 3m | F14: 300 | G14: 900 | H14: 44317
D15: les gants | E15: 20 | F15: 15 | G15: 300 | H15: 44317
D16: amandes | E16: 1kg | F16: 2000 | G16: 2000 | H16: 44317
D17: storm | E17: 1 | F17: 1000 | G17: 1000 | H17: 44317
D18: 9aleb elouz | E18: 2 | F18: 4500 | G18: 4500 | H18: 44317
D19: barquettes | E19: 2 | F19: 100 | G19: 2200 | H19: 44317
D20: sachets transparets | E20: 10 | F20: 50 | G20: 500 | H20: 44317
D21: pistache | E21: / | F21: 4000 | G21: 500 | H21: 44317
D22: Farine Sim 1kg | E22: 11 fardeaux | F22: 660 | G22: 7260 | H22: 44317
D23: pate feuilltée | E23: 4kg | F23: 250 | G23: 1000 | H23: 44317
D24: yaourt Nature | E24: 48 | F24: 20 | G24: 950 | H24: 44317
D25: Semoule Baraka 10kg | E25: 7 | F25: 700 | G25: 4900 | H25: 44317
D26: Semoule moyenne Sim 2kg | E26: 3 fardeaux | F26: 1040 | G26: 3120 | H26: 44317
D27: sac croissant 23 | E27: 2 | F27: 750 | G27: 1500 | H27: 44317
D28: semoule Mama fine 2kg | E28: 1 | F28: 1180 | G28: 1180 | H28: 44317
D29: Fromage blanc bèrbrre | E29: 3 | F29: 790 | G29: 2370 | H29: 44317
D30: fromage spéciale pizza | E30: 10kg | F30: 240 | G30: 2400 | H30: 44317
D31: Sucre glace | E31: 24kg | F31: 86 | G31: 2064 | H31: 44317
D32: Huile Elio de 5 litres | E32: 52 | F32: 590 | G32: 30680 | H32: 44317
D33: Miel Mordjan 5kg | E33: 06 Bidons | F33: 565 | G33: 3390 | H33: 44317
D34: Semen Madina 1.8kg | E34: 5 boites | F34: 465 | G34: 2325 | H34: 44317
D35: boites 12/07 | E35: 5 fardeaux de 50 | F35: 730 | G35: 3650 | H35: 44317
D36: Maa Zehar cartons de 12 bouteilles | E36: 2*12 | F36: 50 | G36: 1200 | H36: 44317
D37: sucre | E37: 2 sachets de 25kg | F37: 72 | G37: 8400 | H37: 44317
D38: Poulet haché | E38: 2kg | F38: 750 | G38: 1500 | H38: 44317
D39: viande hachée | E39: 1kg | F39: 1500 | G39: 1500 | H39: 44317
D40: deyoul | E40: 14 | F40: 100 | G40: 1400 | H40: 44317
D41: 9etayef | E41: 30 | F41: 50 | G41: 1500 | H41: 44317
...

Sheet Pointage 
A1: . | B1: Date | C1: Zehor | D1: Saida | E1: Nadjet | F1: Hadjer | G1: Amel | H1: Soumia | I1: Hafida | J1: Fatiha | K1: Wahiba | L1: Zahida | M1: Remarque
A2: Samedi | B2: 44317 | C2: 1 | D2: 1 | E2: 1 | F2: 1 | G2: 1 | H2: 1 | I2: 0 | J2: 1 | K2: 1 | L2: 1
A3: dimanche | B3: 44318 | C3: 1 | E3: 1 | F3: 0 | G3: 1 | H3: 1 | I3: 1 | J3: 0 | K3: 1 | L3: 1
A4: lundi | B4: 44319 | C4: 1 | E4: 1 | F4: 0 | G4: 1 | H4: 1 | I4: 1 | J4: 0 | K4: 0 | L4: 0
A5: mardi | B5: 44320 | C5: 1 | E5: 1 | F5: 0 | G5: 1 | H5: 1 | I5: 1 | J5: 0 | K5: 1 | L5: 1
A6: mercredi | B6: 44321 | C6: 1 | E6: 1 | F6: 1 | G6: 1 | H6: 0 | I6: 1 | J6: 0 | K6: 1 | L6: 1
A7: jeudi | B7: 44322 | C7: 1 | E7: 1 | F7: 1 | G7: 1 | H7: 1 | I7: 1 | J7: 0 | K7: 0 | L7: 1
A8: vendredi | B8: 44323 | C8: 1 | E8: 0 | F8: 1 | G8: 2 | H8: 0 | I8: 1 | J8: 0 | K8: 0 | L8: 1
A9: samedi | B9: 44324 | C9: 0 | E9: 1 | F9: 1 | G9: 1 | H9: 1 | I9: 0 | J9: 1 | K9: 0 | L9: 1.5 | M9: 3awenet hadjer fe chakhechoukha
A10: dimanche | B10: 44325 | C10: 1 | E10: 1 | F10: 1 | G10: 1 | H10: 1 | I10: 1 | J10: 0 | K10: 0 | L10: 2 | M10: zahida a bossé la nuit
A11: lundi | B11: 44326 | C11: 1 | E11: 1 | F11: 1 | G11: 1 | H11: 1 | I11: 0.5 | J11: 0 | K11: 0 | L11: 2
A12: mardi | B12: 44327 | C12: 1 | E12: 1 | F12: 1 | G12: 2 | H12: 1 | I12: 1 | J12: 1 | K12: 0 | L12: 2
A13: mercredi | B13: 44328 | C13: 1 | E13: 1 | F13: 0 | G13: 2 | H13: 0 | I13: 1 | J13: 1 | K13: 0 | L13: 1
A14: jeudi | B14: 44329 | C14: 0 | E14: 0 | F14: 0 | G14: 0 | H14: 0 | I14: 0 | J14: 0 | K14: 0 | L14: 0
A15: vendredi | B15: 44330 | C15: 0 | E15: 0 | F15: 0 | G15: 0 | H15: 0 | I15: 0 | J15: 0 | K15: 0 | L15: 0
A16: samedi | B16: 44331 | C16: 0 | E16: 0 | F16: 0 | G16: 0 | H16: 0 | I16: 0 | J16: 0 | K16: 0 | L16: 0
A17: dimanche | B17: 44332 | C17: 0 | E17: 0 | F17: 0 | G17: 0 | H17: 0 | I17: 0 | J17: 0 | K17: 0 | L17: 0
A18: lundi | B18: 44333 | C18: 1 | E18: 0 | F18: 0 | G18: 1 | H18: 0 | I18: 1 | J18: 0 | K18: 0 | L18: 1
A19: mardi | B19: 44334 | C19: 1 | E19: 0 | F19: 0 | G19: 1 | H19: 1 | I19: 1.5 | J19: 0 | K19: 0 | L19: 1
A20: mercredi | B20: 44335 | C20: 1 | E20: 0 | F20: 1 | G20: 1 | H20: 1 | I20: 1.5 | J20: 0 | K20: 0 | L20: 1
A21: jeudi | B21: 44336 | C21: 1 | D21: 0 | E21: 0 | F21: 1 | G21: 1 | H21: 1 | I21: 1.5 | J21: 0 | K21: 0 | L21: 1
A22: vendredi | B22: 44337 | C22: 1 | E22: 0 | F22: 1 | G22: 0 | H22: 0 | I22: 1.5 | J22: 1 | K22: 0 | L22: 1
A23: samedi | B23: 44338 | C23: 0 | D23: 0 | E23: 0 | F23: 1 | G23: 1 | H23: 1 | I23: 1.5 | J23: 1 | K23: 0 | L23: 0
A24: dimanche | B24: 44339 | C24: 1 | D24: 0 | E24: 0 | F24: 1 | G24: 1 | H24: 1 | I24: 0 | J24: 0 | K24: 0 | L24: 1
A25: lundi | B25: 44340 | C25: 1 | D25: 0 | E25: 0 | F25: 1 | G25: 1 | H25: 1 | I25: 1.5 | J25: 0 | K25: 0 | L25: 1
A26: mardi | B26: 44341 | C26: 0.5 | D26: 0 | E26: 0 | F26: 1 | G26: 1 | H26: 1 | I26: 1.5 | J26: 0 | K26: 0 | L26: 1 | M26: -1/2 pour zehor a cause de la commande du père de Amine 36 messemen et 3 paquets chakhechoukha
A27: mercredi | B27: 44342 | C27: 1 | D27: 0 | E27: 0 | F27: 1 | G27: 1 | H27: 1 | I27: 1.5 | J27: 0 | K27: 0 | L27: 1
A28: jeudi | B28: 44343 | C28: 1 | D28: 0 | E28: 0 | F28: 0 | G28: 1 | H28: 1 | I28: 1.5 | J28: 1 | K28: 0 | L28: 1 | M28: -1/2 pour Hafida pour les 2 paquets de chakhechoukha perdus
A29: vendredi | B29: 44344 | C29: 1 | F29: 1 | G29: 0 | H29: 0 | I29: 1 | J29: 1 | K29: 0 | L29: 0
A30: samedi | B30: 44345 | C30: 1 | E30: 0 | F30: 0 | G30: 1 | H30: 1 | I30: 0 | J30: 1 | K30: 0 | L30: 1
A31: dimanche | B31: 44346 | C31: 1 | E31: 0 | F31: 0 | G31: 1 | H31: 1 | I31: 1 | J31: 0 | K31: 0 | L31: 1
A32: Lundi | B32: 44347 | C32: 1 | E32: 0 | F32: 1 | G32: 1 | H32: 0 | I32: 1 | J32: 0 | K32: 0 | L32: 1
C33: =SUM(C2:C32) -> 24.5 | D33: =SUM(D2:D32) -> 1 | E33: =SUM(E2:E32) -> 11 | F33: =SUM(F2:F32) -> 18 | G33: =SUM(G2:G32) -> 28 | H33: =SUM(H2:H32) -> 20 | I33: =SUM(I2:I32) -> 27 | J33: =SUM(J2:J32) -> 9 | ... L33: =SUM(L2:L32) -> 27.5
C34: 1850 | D34: 7000 | E34: 1000 | F34: 1000 | G34: 1110 | H34: 930 | I34: 930 | J34: 1200 | K34: 500 | L34: 1110 | M34: =SUM(C34:L34) -> 16630
C35: =C34*C33 -> 45325 | D35: =D33*D34 -> 7000 | E35: =E34*E33 -> 11000 | F35: =F34*F33 -> 18000 | G35: =G34*G33 -> 31080 | H35: =H34*H33 -> 18600 | I35: =I34*I33 -> 25110 | J35: =J34*J33 -> 10800 | K35: =K34*K33 -> 2000 | L35: =L33*L34 -> 30525 | M35: =SUM(C35:L35) -> 199440
R39: . | S39: Date | T39: Fatiha
R40: Samedi | S40: 44317 | T40: 1
R41: dimanche | S41: 44318 | T41: 0
D42: h | R42: lundi | S42: 44319 | T42: 0
R43: mardi | S43: 44320 | T43: 0
...

Sheet salaire 
J11: Nom | K11: Salaire | L11: Avance
I12: 1 | J12: Zehor | K12: ='Pointage '!C35*1 -> 45325
I13: 2 | J13: Saida | K13: ='Pointage '!D35*1 -> 7000
I14: 3 | J14: Amel | K14: ='Pointage '!G35*1 -> 31080 | L14: 3000
I15: 4 | J15: Nadjet | K15: ='Pointage '!E35*1 -> 11000
I16: 5 | J16: Hadjer | K16: ='Pointage '!F35*1 -> 18000 | L16: 2000
I17: 6 | J17: Hafida | K17: ='Pointage '!I35*1 -> 25110 | L17: 13000 | M17: 5000+2000+1000+5000
I18: 7 | J18: wahiba | K18: ='Pointage '!K35*1 -> 2000
I19: 8 | J19: Soumia | K19: ='Pointage '!H35*1 -> 18600 | L19: 19000
I20: 9 | J20: Fatiha | K20: ='Pointage '!J35*1 -> 10800
I21: 10 | J21: Zahida | K21: ='Pointage '!L35*1 -> 30525 | L21: 12000 | M21: 10000+2000
J22: TOTAL | K22: =SUM(K12:K21) -> 199440 | L22: =SUM(L12:L21) -> 49000
K23: =K22-L22 -> 150440
