Workbook

Sheet RECAP
B1: Date | C1: Recette Juin 2025 | D1: Recette | E1: Charges | F1: Salaire | G1: Che7i7a | H1: Loyer | I1: Net Profit | J1: Nb de jours | L1: Objectif | M1: Mois de Juin 2025
A2: Mardi | B2: 45839 | C2: 36000 | D2: 43000 | G2: 2000 | J2: 1 | M2: 36000
A3: Mercredi | B3: 45840 | C3: 48000 | D3: 66000 | G3: 2000 | J3: 1 | M3: 48000 | N3: Bénéfice Moyen par jour | O3: Moyenne | P3: Moyenne salaire | Q3: pourcentage du salaire vis à vis la recettte
A4: Jeudi | B4: 45841 | C4: 90000 | D4: 82000 | G4: 2000 | J4: 1 | M4: 90000 | N4: =I33/J33 -> 15487.605 | O4: =D33/J33 -> 64419.355 | Q4: =P4/O4 -> 0
A5: Vendredi | B5: 45842 | C5: 126000 | D5: 87000 | G5: 2000 | J5: 1 | M5: 126000
A6: Samedi | B6: 45843 | C6: 270000 | D6: 148000 | G6: 2000 | J6: 1 | M6: 270000 | N6: Moyenne des charges par jour | O6: Objectif
A7: Dimanche | B7: 45844 | C7: 3000 | D7: 63000 | G7: 2000 | J7: 1 | M7: 3000 | N7: =E33/J33 -> 28487.484 | O7: 100000
A8: Lundi | B8: 45845 | C8: 0 | D8: 30000 | G8: 2000 | J8: 1 | M8: 0 | N8: ² | S8: "
A9: Mardi | B9: 45846 | C9: 10000 | D9: 39000 | G9: 2000 | J9: 1 | M9: 10000
A10: Mercredi | B10: 45847 | C10: 32000 | D10: 32000 | G10: 2000 | J10: 1 | M10: 32000 | N10: Cash restant | O10: Magasin | P10: Cash réel | Q10: Mes dettes pour le magasin
A11: Jeudi | B11: 45848 | C11: 60000 | D11: 32000 | G11: 2000 | J11: 1 | M11: 60000 | N11: =D33+N14-O11-E33-G33-Salaires!L31 -> 615388 | O11: 370000 | P11: 562000 | Q11: =N11-P11 -> 53388
A12: Vendredi | B12: 45849 | C12: 56000 | D12: 62000 | G12: 2000 | J12: 1 | M12: 56000
A13: Samedi | B13: 45850 | C13: 70000 | D13: 112000 | G13: 2000 | J13: 1 | M13: 70000 | N13: Fond de Roulement
A14: Dimanche | B14: 45851 | C14: 60000 | D14: 77000 | G14: 2000 | J14: 1 | M14: 60000 | N14: 330000
A15: Lundi | B15: 45852 | C15: 42000 | D15: 43000 | G15: 2000 | J15: 1 | M15: 42000 | Q15: La caisse :16000Da
A16: Mardi | B16: 45853 | C16: 54000 | D16: 53000 | G16: 2000 | J16: 1 | K16: 1 | M16: 54000 | Q16: CCP: 19000Da
A17: Mercredi | B17: 45854 | C17: 53000 | D17: 68000 | G17: 2000 | J17: 1 | K17: 1 | M17: 53000 | Q17: Dus Non payés: 115000Da
A18: Jeudi | B18: 45855 | C18: 78000 | D18: 64000 | G18: 2000 | J18: 1 | M18: 78000 | Q18: Sofiane : 69000Da +34k | R18: 265
A19: Vendredi | B19: 45856 | C19: 97000 | D19: 89000 | G19: 2000 | J19: 1 | M19: 97000 | N19: Différence mois de Décembre
A20: Samedi | B20: 45857 | C20: 74000 | D20: 69000 | G20: 2000 | J20: 1 | M20: 74000 | N20: =D33-C33 -> -348000 | Q20: Toufik Dz Event: 117000Da
A21: Dimanche | B21: 45858 | C21: 57000 | D21: 62000 | G21: 2000 | J21: 1 | M21: 57000 | N21: Différence objectif
A22: Lundi | B22: 45859 | C22: 63000 | D22: 50000 | G22: 2000 | J22: 1 | M22: 63000 | N22: =L36-E36 -> 0
A23: Mardi | B23: 45860 | C23: 213000 | D23: 47000 | G23: 2000 | J23: 1 | M23: 213000 | N23: Différence du Totale
A24: Mercredi | B24: 45861 | C24: 234000 | D24: 48000 | G24: 2000 | J24: 1 | M24: 234000 | N24: =D33-C33 -> -348000
A25: Jeudi | B25: 45862 | C25: 48000 | D25: 68000 | G25: 2000 | J25: 1 | M25: 48000 | N25: Les vendredis
A26: Vendredi | B26: 45863 | C26: 73000 | D26: 29000 | G26: 2000 | J26: 1 | M26: 73000 | N26: =D9+D16+D23+D30 -> 171000
A27: Samedi | B27: 45864 | C27: 79000 | D27: 161000 | G27: 2000 | J27: 1 | M27: 79000
A28: Dimanche | B28: 45865 | C28: 78000 | D28: 57000 | G28: 2000 | J28: 1 | M28: 78000 | N28: Cash réel
A29: Lundi | B29: 45866 | C29: 69000 | D29: 53000 | G29: 2000 | J29: 1 | M29: 69000 | N29: 51000
A30: Mardi | B30: 45867 | C30: 56000 | D30: 32000 | G30: 2000 | J30: 1 | M30: 56000 | N30: rest à payer
A31: Mercredi | B31: 45868 | C31: 100000 | D31: 58000 | G31: 2000 | J31: 1 | M31: 100000
A32: Jeudi | B32: 45869 | C32: 16000 | D32: 73000 | G32: 2000 | J32: 1 | M32: 16000
C33: =SUM(C2:C32) -> 2345000 | D33: =SUM(D2:D32) -> 1997000 | E33: ='Les Charges '!G413 -> 883112 | F33: =Salaires!K31 -> 391772.25 | G33: =SUM(G2:G32) -> 62000 | H33: 180000 | I33: =D33-E33-F33-G33-H33 -> 480115.75 | J33: =SUM(J2:J32) -> 31 | M33: =SUM(M2:M32) -> 2345000
G34: Loyer Magasin | H34: 55000
G35: Loyer Locale | H35: 40000 | N35: =N11-N29-N34 -> 564388
D36: 200000 | G36: Sofiane Maison | H36: 45000 | P36: Papa | Q36: 40000
G37: Dette Papa | H37: 40000
D38: -
C49: 1

Sheet Les Charges 
D2: Produit | E2: Quantité | F2: Prix unitaire | G2: Prix | H2: Date d'achat
D3: Canette Hamoud Annanas | E3: 7 | F3: 44 | G3: =E3*F3 -> 308 | H3: Boissons
D4: Canette Hamoud Orange | E4: 14 | F4: 44 | G4: =E4*F4 -> 616
D5: Canette Hamoud Pomme | E5: 8 | F5: 44 | G5: =E5*F5 -> 352
D6: Canette Hamoud citron | E6: 3 | F6: 44 | G6: =E6*F6 -> 132
D7: Canette Hamoud Litchi | E7: 10 | F7: 44 | G7: =E7*F7 -> 440
D8: Canette Hamoud Blanc | E8: 23 | F8: 44 | G8: =E8*F8 -> 1012
D9: Canette Hamoud Selecto | E9: 11 | F9: 44 | G9: =E9*F9 -> 484
D10: Canette Hamoud Cola | E10: 3 | F10: 44 | G10: =E10*F10 -> 132
D11: Canette Shwepess Grenadine | E11: 11 | F11: 73 | G11: =E11*F11 -> 803
D12: canette Shwepess Citron | E12: 8 | F12: 73 | G12: =E12*F12 -> 584
D13: Canette Shwepes Gold | E13: 14 | F13: 73 | G13: =E13*F13 -> 1022
D14: Canette Coca Cola | E14: 24 | F14: 60 | G14: =E14*F14 -> 1440
D15: Canette Izem Blanc | E15: 3 | F15: 72 | G15: =E15*F15 -> 216
... D84: Sucre cristalisé 25kg | E84: 15 | F84: 99 | G84: =E84*F84 -> 1485
C85: 450 | D85: Levure chimique | E85: 220 | F85: 6 | G85: =E85*F85 -> 1320
D86: Crème liquide Maitre culinaire | E86: 3 | F86: 430 | G86: =E86*F86 -> 1290
D87: plateaux oeufs | E87: 2 | F87: 450 | G87: =E87*F87 -> 900
D88: noix de coco | E88: 1 | F88: 900 | G88: =E88*F88 -> 900
D89: blanc de poulet | E89: 2 | F89: 750 | G89: =E89*F89 -> 1500 | H89: 6693289
D90: poulet haché | E90: 2 | F90: 750 | G90: =E90*F90 -> 1500
D91: escalope | E91: 1 | F91: 750 | G91: =E91*F91 -> 750
D92: amande blanc | E92: 2 | F92: 2250 | G92: =E92*F92 -> 4500
D93: arome citron | E93: 1 | F93: 100 | G93: =E93*F93 -> 100
D94: Tapis | E94: 2 | F94: 250 | G94: =E94*F94 -> 500
D95: Thon princess | E95: 1 | F95: 270 | G95: =E95*F95 -> 270
D96: papier film petit | E96: 3 | F96: 130 | G96: =E96*F96 -> 390
D97: Metelou3 | E97: 4 | F97: 50 | G97: =E97*F97 -> 200
D98: Thé | E98: 1 | F98: 190 | G98: =E98*F98 -> 190
D99: Tomate fraiche | E99: 2 | F99: 100 | G99: =E99*F99 -> 200
D100: viande hachée Slimane | E100: 0.4 | F100: 1900 | G100: =E100*F100 -> 760
D101: poulet haché | E101: 1.4 | F101: 750 | G101: =E101*F101 -> 1050
... D162: escalope | E162: 1 | F162: 750 | G162: =E162*F162 -> 750
D163: cevital | E163: 1 | F163: 15190 | G163: =E163*F163 -> 15190 | H163: Margarine + semen + jus
D164: crème fraiche 4 fromages | E164: 8 | F164: 350 | G164: =E164*F164 -> 2800
D165: dégraissant mojito | E165: 1 | F165: 190 | G165: =E165*F165 -> 190
D166: brilex multisurface | E166: 1 | F166: 165 | G166: =E166*F166 -> 165
D167: inscticide | E167: 1 | F167: 310 | G167: =E167*F167 -> 310
D168: sanoudj | E168: 0.5 | F168: 1300 | G168: =E168*F168 -> 650 | H168: 45846
D169: 7abet 7alawa | E169: 0.5 | F169: 1300 | G169: =E169*F169 -> 650
...

Sheet Pointage
B1: Date | C1: Saida | D1: Fatiha | E1: Samira Z | F1: Rayan | G1: Yasmine | H1: Zohra | I1: Lynda | J1: Amina Ain Beniane | K1: Ahlem | L1: Samira | M1: Zahia | N1: Khalida | O1: israa | P1: Backup
A2: Mardi | B2: 45839 | C2: 1 | D2: 1 | E2: 1 | F2: 0 | G2: 1 | H2: 1 | I2: 1 | J2: 1 | K2: 1 | L2: 1 | M2: 4 | N2: 1 | O2: 4
A3: Mercredi | B3: 45840 | C3: 1 | D3: 1 | E3: 1 | F3: 0 | G3: 1 | H3: 0 | I3: 1 | J3: 1 | K3: 1 | L3: 1 | M3: 1 | N3: 0 | O3: 0
A4: Jeudi | B4: 45841 | C4: 1 | D4: 1 | E4: 1 | F4: 0 | G4: 1 | H4: 1 | I4: 1 | J4: 1 | K4: 1 | L4: 1 | M4: 1 | N4: 0 | O4: 0
A5: Vendredi | B5: 45842 | C5: 0 | D5: 1 | E5: 0 | F5: 0 | G5: 1 | H5: 0 | I5: 1 | J5: 1 | K5: 0 | L5: 1 | M5: 1 | N5: 0 | O5: 0 | P5: 3
A6: Samedi | B6: 45843 | C6: 1 | D6: 1 | E6: 0 | F6: 0 | G6: 1 | H6: 1 | I6: 1 | J6: 1 | K6: 0 | L6: 0 | M6: 1 | N6: 0 | O6: 0
A7: Dimanche | B7: 45844 | C7: 1 | D7: 0 | E7: 1 | F7: 0 | G7: 1 | H7: 0 | I7: 0 | J7: 1 | K7: 1 | L7: 1 | M7: 1 | N7: 0 | O7: 0
A8: Lundi | B8: 45845 | C8: 1 | D8: 1 | E8: 1 | F8: 0 | G8: 0.95 | H8: 0 | I8: 1 | J8: 1 | K8: 1 | L8: 1 | M8: 1 | N8: 0 | O8: 0 | Q8: Les Heures suplémentaires
A9: Mardi | B9: 45846 | C9: 1 | D9: 1 | E9: 1 | F9: 0 | G9: 0.5 | H9: 0 | I9: 1 | J9: 1 | K9: 1 | L9: 1 | M9: 1 | N9: 0 | O9: 0
A10: Mercredi | B10: 45847 | C10: 1 | D10: 1 | E10: 1 | F10: 0 | G10: 1 | H10: 0 | I10: 1 | J10: 0 | K10: 1 | L10: 1 | M10: 1 | N10: 0 | O10: 0
A11: Jeudi | B11: 45848 | C11: 1 | D11: 0.5 | E11: 0 | F11: 0 | G11: 1 | H11: 0 | I11: 1 | J11: 1 | K11: 1 | L11: 1 | M11: 1 | N11: 0 | O11: 0
A12: Vendredi | B12: 45849 | C12: 0 | D12: 1.5 | E12: 0 | F12: 0 | G12: 1 | H12: 0 | I12: 1 | J12: 1 | K12: 0 | L12: 1 | M12: 0 | N12: 0 | O12: 0 | P12: 1 | Q12: Nadjet
A13: Samedi | B13: 45850 | C13: 1 | D13: 1.5 | E13: 1 | F13: 0 | G13: 1 | H13: 0 | I13: 1 | J13: 1 | K13: 1 | L13: 0 | M13: 1.5 | N13: 0 | O13: 0 | Q13: La commande de Amel Akak
A14: Dimanche | B14: 45851 | C14: 1 | D14: 1.5 | E14: 1 | F14: 0 | G14: 1 | H14: 0 | I14: 1 | J14: 1 | K14: 1 | L14: 1 | M14: 1.5 | N14: 0 | O14: 0 | Q14: Fatiha et Zahia djaw à 06h15
A15: Lundi | B15: 45852 | C15: 1 | D15: 1 | E15: 1 | F15: 0 | G15: 1 | H15: 0 | I15: 1 | J15: 1 | K15: 1 | L15: 1 | M15: 1 | N15: 0 | O15: 0
A16: Mardi | B16: 45853 | C16: 1 | D16: 1 | E16: 1 | F16: 0 | G16: 1 | H16: 0 | I16: 1 | J16: 1 | K16: 1 | L16: 1 | M16: 1 | N16: 0 | O16: 0
A17: Mercredi | B17: 45854 | C17: 1 | D17: 1 | E17: 1 | F17: 0 | G17: 1 | H17: 0 | I17: 1 | J17: 1 | K17: 1 | L17: 1 | M17: 1 | N17: 0 | O17: 0
A18: Jeudi | B18: 45855 | C18: 1 | D18: 1 | E18: 1 | F18: 0 | G18: 1 | H18: 0 | I18: 1.5 | J18: 0 | K18: 1 | L18: 0 | M18: 1 | N18: 0 | O18: 0
A19: Vendredi | B19: 45856 | C19: 0 | D19: 1.25 | E19: 1 | F19: 0 | G19: 1 | H19: 0 | I19: 1 | J19: 0 | K19: 0 | L19: 1 | M19: 1.25 | N19: 0 | O19: 0
A20: Samedi | B20: 45857 | C20: 1 | D20: 0 | E20: 0 | F20: 0 | G20: 1 | H20: 0 | I20: 1 | J20: 0 | K20: 1 | L20: 1 | M20: 0 | N20: 0 | O20: 0
A21: Dimanche | B21: 45858 | C21: 1 | D21: 0 | E21: 0 | F21: 0 | G21: 1 | H21: 0 | I21: 0 | J21: 1 | K21: 1 | L21: 1 | M21: 1 | N21: 0 | O21: 1 | P21: 1 | Q21: Houda
A22: Lundi | B22: 45859 | C22: 1 | D22: 1 | E22: 0 | F22: 0 | G22: 0 | H22: 0 | I22: 1 | J22: 0 | K22: 1 | L22: 1 | M22: 1 | N22: 0 | O22: 0 | P22: 0
A23: Mardi | B23: 45860 | C23: 1 | D23: 1 | E23: 1 | F23: 0 | G23: 1 | H23: 1 | I23: 1.5 | J23: 0 | K23: 1 | L23: 1 | M23: 0 | N23: 0 | O23: 1 | P23: 1 | Q23: Houda
A24: Mercredi | B24: 45861 | C24: 1 | D24: 1 | E24: 1 | F24: 0 | G24: 1 | H24: 0 | I24: 1 | J24: 0 | K24: 1 | L24: 1 | M24: 0 | N24: 1 | O24: 0
A25: Jeudi | B25: 45862 | C25: 1 | D25: 1 | E25: 0 | F25: 0 | G25: 1 | H25: 1 | I25: 1 | J25: 1.5 | K25: 1 | L25: 1 | M25: 1 | N25: 1 | O25: 0
A26: Vendredi | B26: 45863 | C26: 0 | D26: 1 | E26: 0 | F26: 1.5 | G26: 1 | H26: 0 | I26: 1 | J26: 0 | K26: 0 | L26: 1 | M26: 1 | N26: 0 | O26: 0 | P26: 2
A27: Samedi | B27: 45864 | C27: 1 | D27: 0 | E27: 0 | F27: 0.75 | G27: 1 | H27: 0 | I27: 1.5 | J27: 1.5 | K27: 1 | L27: 0 | M27: 0 | N27: 1 | O27: 0 | P27: 1.5
A28: Dimanche | B28: 45865 | C28: 1 | D28: 1 | E28: 1 | F28: 0 | G28: 1 | H28: 1 | I28: 1 | J28: 1 | K28: 1 | L28: 1 | M28: 0 | N28: 0 | O28: 0 | P28: 0
A29: Lundi | B29: 45866 | C29: 1 | D29: 1 | E29: 1 | F29: 0 | G29: 1 | H29: 0 | I29: 1 | J29: 1 | K29: 1 | L29: 1 | M29: 1 | N29: 0 | O29: 0 | P29: 0
A30: Mardi | B30: 45867 | C30: 1 | D30: 1 | E30: 1 | F30: 0 | G30: 1 | H30: 1 | I30: 1 | J30: 1 | K30: 1 | L30: 1 | M30: 0 | N30: 0 | O30: 0 | Q30: Yasmine djate à 11h54
A31: Mercredi | B31: 45868 | C31: 1 | D31: 1 | E31: 1 | F31: 0 | G31: 1 | H31: 0 | I31: 1 | J31: 1 | K31: 1 | L31: 1 | M31: 1 | N31: 0 | O31: 0
A32: Jeudi | B32: 45869 | C32: 1 | D32: 1 | E32: 1 | F32: 0 | G32: 1 | H32: 1 | I32: 1 | J32: 0 | K32: 1 | L32: 1 | M32: 0 | N32: 0 | O32: 0
C33: =SUM(C2:C32) -> 27 | D33: =SUM(D2:D32) -> 28.25 | E33: =SUM(E2:E32) -> 21 | F33: =SUM(F2:F32) -> 2.25 | G33: =SUM(G2:G32) -> 29.45 | H33: =SUM(H2:H32) -> 8 | I33: =SUM(I2:I32) -> 30.5 | J33: =SUM(J2:J32) -> 23 | ... P33: =SUM(P2:P32) -> 9.5
C34: 1225 | D34: 1150 | E34: 1270 | F34: 1300 | G34: 1155 | H34: 1155 | I34: 1400 | J34: 1400 | K34: 1120 | L34: 1200 | M34: 1120 | N34: 1300 | O34: 1120 | P34: 1000
C35: =C33*C34 -> 33075 | D35: =D33*D34 -> 32487.5 | E35: =E33*E34 -> 26670 | F35: =F33*F34 -> 2925 | G35: =G33*G34 -> 34014.75 | H35: =H33*H34 -> 9240 | I35: =I33*I34 -> 42700 | J35: =J33*J34 -> 32200 | ... P35: =P33*P34 -> 9500
C37: 1334 | D37: 1250 | E37: 1375 | F37: 1250 | G37: 1250 | H37: 1250 | I37: 1460 | J37: 1460 | K37: 1250 | L37: 1250 | M37: 1250 | N37: 1300 | O37: 1500

Sheet Salaires
J14: Nom | K14: Salaire | L14: Avance | M14: Salaire à payer
J15: Sofiane | K15: 30000 | L15: 30000 | M15: =K15-L15 -> 0
J16: Amel | K16: 30000 | L16: 30000 | M16: =K16-L16 -> 0
I17: 1 | J17: Saida | K17: =Pointage!C35 -> 33075 | L17: 33000 | M17: 0 | N17: 2000+8000
I18: 2 | J18: Fatiha | K18: =Pointage!D35 -> 32487.5 | L18: 32500 | M18: =K18-L18 -> -12.5 | N18: 2000+ 600Da Abats+ 1200Da Sardines + 2000Da vendredi por miel*+4000Da+1000+15000Da vendredi
I19: 4 | J19: Samira z | K19: =Pointage!E35 -> 26670 | L19: 27000 | M19: =K19-L19 -> -330 | N19: Avance sur Salaire +2000
I20: 5 | J20: Rayan | K20: =Pointage!F35 -> 2925 | L20: 3000 | M20: =K20-L20 -> -75
I21: 6 | J21: Yasmine | K21: =N21+Pointage!G35 -> 39014.75 | L21: 39000 | M21: 0 | N21: 5000
I22: 7 | J22: Zohra | K22: =Pointage!H35 -> 9240 | L22: 9500 | M22: =K22-L22 -> -260
I23: 8 | J23: Lynda | K23: =Pointage!I35 -> 42700 | L23: 43000 | M23: =K23-L23 -> -300
I24: 11 | J24: Amina Ain Beniane | K24: =Pointage!J35 -> 32200 | L24: 32500 | M24: =K24-L24 -> -300
I25: 12 | J25: Ahlem | K25: =Pointage!K35 -> 29120 | L25: 29500 | M25: 0
I26: 14 | J26: Samira | K26: =Pointage!L35 -> 32400 | L26: 32500 | M26: =K26-L26 -> -100
I27: 15 | J27: Zahia | K27: =Pointage!M35 -> 30520 | L27: 30500 | M27: 0
I28: 16 | J28: Khalida | K28: =Pointage!N35 -> 5200 | L28: 8000 | M28: =K28-L28 -> -2800
J29: Israa | K29: =Pointage!O35 -> 6720 | L29: 7000 | M29: =K29-L29 -> -280
I30: 17 | J30: Backup | K30: =Pointage!P35 -> 9500 | L30: 9500 | M30: =K30-L30 -> 0 | N30: Nadjet : 1500Da +3000Da les nièces de Samira+3000Da Alia
J31: TOTAL | K31: =SUM(K15:K30) -> 391772.25 | L31: =SUM(L15:L30) -> 396500 | M31: =K31-L31 -> -4727.75
M32: =K32-L32 -> 0

Sheet Feuille 5
E14: Mois de Janvier 2025 | F14: Mois de Février 2025 | G14: Mois de Mars 2025 | H14: Mois d'Avril 2025 | I14: Mois de Mai 2025 | J14: Mois de Juin 2025 | K14: Mois de Juillet 2025
D15: Recette | E15: 2033000 | F15: 1859000 | G15: 2094000 | H15: 1282000 | I15: 2077000 | J15: 2345000 | K15: =RECAP!D33 -> 1997000
D16: Charges | E16: 854000 | F16: 884000 | G16: 962000 | H16: 669000 | I16: 800000 | J16: 883000 | K16: 883000
D17: Salaires | E17: 427000 | F17: 409000 | G17: 439000 | H17: 338000 | I17: 385000 | J17: 365000 | K17: 392000
D18: Che7i7a | E18: 62000 | F18: 56000 | G18: 60000 | H18: 50000 | I18: 180000 | J18: 56000 | K18: 62000
D19: Loyer+Dettes | E19: 180000 | F19: 180000 | G19: 180000 | H19: 180000 | I19: 180000 | J19: 180000 | K19: 180000
D20: Profit Net | E20: =E15-E16-E17-E18-E19 -> 510000 | F20: =F15-F16-F17-F18-F19 -> 330000 | G20: =G15-G16-G17-G18-G19 -> 453000 | H20: =H15-H16-H17-H18-H19 -> 45000 | I20: =I15-I16-I17-I18-I19 -> 532000 | J20: =J15-J16-J17-J18-J19 -> 861000 | K20: =K15-K16-K17-K18-K19 -> 480000
H26: Mois de Juillet 2025
G27: Recette | H27: 1997000
G28: Charges | H28: 883000
G29: Salaires | H29: 392000
G30: Che7i7a | H30: 62000
G31: Loyer+Dettes | H31: 180000
G32: Profit Net | H32: =H27-H28-H29-H30-H31 -> 480000
