Workbook

Sheet RECAP
B1: Date | C1: Recette de Mai | D1: Recette | E1: Charges | F1: Salaire | G1: Loyer | H1: Net Profit | I1: Nb de jours | J1: Objectif | K1: Mai | N1: Moyenne
A2: Mardi | B2: 44348 | C2: 21000 | D2: 27000 | I2: 1 | J2: 50000 | K2: 21000 | N2: =D32/I32 -> 32000
A3: Mercredi | B3: 44349 | C3: 34000 | D3: 18000 | I3: 1 | J3: 50000 | K3: 34000
A4: Jeudi | B4: 44350 | C4: 35000 | D4: 36000 | I4: 1 | J4: 50000 | K4: 35000 | N4: 50000
A5: Vendredi | B5: 44351 | C5: 15000 | D5: 28000 | I5: 1 | J5: 50000 | K5: 15000
A6: Samedi | B6: 44352 | C6: 33000 | D6: 34000 | I6: 1 | J6: 50000 | K6: 33000
A7: Dimanche | B7: 44353 | C7: 43000 | D7: 37000 | I7: 1 | J7: 50000 | K7: 43000
A8: Lundi | B8: 44354 | C8: 25000 | D8: 28000 | I8: 1 | J8: 50000 | K8: 25000
A9: Mardi | B9: 44355 | C9: 45000 | D9: 31000 | I9: 1 | J9: 50000 | K9: 45000
A10: Mercredi | B10: 44356 | C10: 46000 | D10: 42000 | I10: 1 | J10: 50000 | K10: 46000
A11: Jeudi | B11: 44357 | C11: 90000 | D11: 57000 | I11: 1 | J11: 50000 | K11: 90000 | M11: Cash restant | N11: Magasin | Q11: Différence mois d'Avril
A12: Vendredi | B12: 44358 | C12: 190000 | D12: 30000 | I12: 1 | J12: 50000 | K12: 190000 | M12: =D32+'Charges '!G323-N12-'Charges '!G322-Salaires!K27 -> 378720 | N12: 31000 | Q12: =D32-C32 -> -11000
A13: Samedi | B13: 44359 | C13: 40000 | D13: 41000 | I13: 1 | J13: 50000 | K13: 40000 | Q13: Différence objectif
A14: Dimanche | B14: 44360 | C14: 15000 | D14: 15000 | I14: 1 | J14: 50000 | K14: 15000 | P14: caisse | Q14: =D32-J32 -> -540000
A15: Lundi | B15: 44361 | C15: 32000 | D15: 42000 | I15: 1 | J15: 50000 | K15: 32000 | M15: 10000 | N15: Sofiane 06/06/2021
A16: Mardi | B16: 44362 | C16: 55000 | D16: 32000 | I16: 1 | J16: 50000 | K16: 55000 | M16: ='Charges '!K93*1 -> 78800 | N16: Magasin
A17: Mercredi | B17: 44363 | C17: 35000 | D17: 24000 | I17: 1 | J17: 50000 | K17: 35000 | M17: 3200 | N17: Sofiane Storm 18/06/2021
A18: Jeudi | B18: 44364 | C18: 12000 | D18: 45000 | I18: 1 | J18: 50000 | K18: 12000
A19: Vendredi | B19: 44365 | C19: 23000 | D19: 41000 | I19: 1 | J19: 50000 | K19: 23000
A20: Samedi | B20: 44366 | C20: 14000 | D20: 39000 | I20: 1 | J20: 50000 | K20: 14000
A21: Dimanche | B21: 44367 | C21: 19000 | D21: 28000 | I21: 1 | J21: 50000 | K21: 19000
A22: Lundi | B22: 44368 | C22: 21000 | D22: 20000 | I22: 1 | J22: 50000 | K22: 21000
A23: Mardi | B23: 44369 | C23: 31000 | D23: 21000 | I23: 1 | J23: 50000 | K23: 31000 | P23: Cash restant réel | Q23: =M12-M15-M16-M17 -> 286720
A24: Mercredi | B24: 44370 | C24: 28000 | D24: 25000 | I24: 1 | J24: 50000 | K24: 28000 | P24: Ccp | Q24: 32000
A25: Jeudi | B25: 44371 | C25: 27000 | D25: 30000 | I25: 1 | J25: 50000 | K25: 27000 | P25: Cash Disponible | Q25: 270000
A26: Vendredi | B26: 44372 | C26: 18000 | D26: 32000 | I26: 1 | J26: 50000 | K26: 18000 | P26: AGB | Q26: 250000
A27: Samedi | B27: 44373 | C27: 12000 | D27: 29000 | I27: 1 | J27: 50000 | K27: 12000 | Q27: =Q25+Q24-Q23-Q26 -> -234720
A28: Dimanche | B28: 44374 | C28: 12000 | D28: 47000 | I28: 1 | J28: 50000 | K28: 12000
A29: Lundi | B29: 44375 | C29: 0 | D29: 26000 | I29: 1 | J29: 50000 | K29: 0 | L29: .
A30: Mardi | B30: 44376 | C30: 0 | D30: 31000 | I30: 1 | J30: 50000 | K30: 0
A31: Mercredi | B31: 44377 | C31: 0 | D31: 24000 | I31: 1 | J31: 50000 | K31: 0
C32: =SUM(C2:C31) -> 971000 | D32: =SUM(D2:D31) -> 960000 | E32: ='Charges '!G322*1 -> 485380 | F32: =Salaires!J27*1 -> 304537 | G32: 50000 | H32: =D32+'Charges '!G323-E32-F32-G32 -> 140083 | I32: =SUM(I2:I31) -> 30 | J32: =SUM(J2:J31) -> 1500000 | K32: =SUM(K2:K31) -> 971000
C34: Objectif | D34: 1365000 | E34: 500000 | F34: 215000 | G34: 50000 | H34: 600000
C35: Mois de Mai | D35: 971000 | E35: 461000 | F35: 199000 | G35: 50000 | H35: 280000

Sheet Charges 
D3: Produit | E3: Quantité | F3: Prix unitaire | G3: Prix | H3: Date d'achat
D4: vanille | E4: 1 | F4: 1500 | G4: 1500 | H4: 44348
D5: chocolat à tartiné 9kg | E5: 2 | F5: 3400 | G5: 6800 | H5: 44348
D6: goblet sorbé | E6: 2 | F6: 1950 | G6: 1950 | H6: 44348
D7: sac croissant 23 | E7: 1 | F7: 700 | G7: 700 | H7: 44348
D8: sac croissant 18 | E8: 1 | F8: 600 | G8: 600 | H8: 44348
D9: Boite 36/10 | E9: 2 | F9: 1400 | G9: 2800 | H9: 44348
D10: boite 36/07 | E10: 2 | F10: 1000 | G10: 2000 | H10: 44348
D11: aluminium | E11: 1 | F11: 1000 | G11: 1000 | H11: 44348
D12: sac pain | E12: 1 | F12: 600 | G12: 600 | H12: 44348
D13: crème fraiche emprinte | E13: 1 | F13: 250 | G13: 250 | H13: 44348
D14: sel | E14: 2 | F14: 25 | G14: 50 | H14: 44348
D15: charges mohamed | G15: 13700 | H15: 44348
D16: semoule Fine Mama 25kg | E16: 7 | F16: 1400 | G16: 9800 | H16: 44348
D17: Semoule fine SIM 25kg | E17: 4 | F17: 1100 | G17: 4400 | H17: 44348
D18: sucre 25kg | E18: 3 sachets de 25kg | F18: 72 | G18: 5400 | H18: 44348
D19: Semoule Sim Moyenne 10kg | E19: 6 sachets | F19: 450 | G19: 2700 | H19: 44348
D20: Semoule moyenne Sim 2kg | E20: 2 fardeaux | F20: 1040 | G20: 2080 | H20: 44348
D21: levure de bièrre | E21: 10 de 500g | F21: 280 | G21: 2800 | H21: 44348
D22: gheress | E22: 25kg | F22: 200 | G22: 5000 | H22: 44348
D23: boites 12 | E23: 1 carton | F23: 1100 | G23: 1100 | H23: 44348
D24: boites 24 | E24: 1 carton | F24: 1600 | G24: 1600 | H24: 44348
D25: boites 1000cc | E25: 1 fardeau | F25: 1400 | G25: 1400 | H25: 44348
D26: sachet de pain | E26: 1 | F26: 950 | G26: 950 | H26: 44348
D27: maa zehar | E27: 1 | F27: 720 | G27: 720 | H27: 44348
D28: amandes | E28: 5kg | F28: 1670 | G28: 8350 | H28: 44348
D29: semen Madina 1.8kg | E29: 2 | F29: 520 | G29: 1040 | H29: 44348
D30: Harissa | E30: 1 | F30: 2040 | G30: 2040 | H30: 44348
D31: farine | E31: 5 fardeaux | F31: 650 | G31: 3250 | H31: 44348
D32: Tomate conserve | E32: 1 carton | F32: 2040 | G32: 2040 | H32: 44348
D33: chocolat Dada | E33: 4 | F33: 200 | G33: 800 | H33: 44348
D34: noix de coco | E34: 1kg | F34: 700 | G34: 700 | H34: 44348
D35: fromage rapé | E35: 12.80 | F35: 230 | G35: 2940 | H35: 44348
D36: ka3ek nakach | E36: 700 | F36: 50 | G36: 35000 | H36: 44348
D37: transport marchandise | E37: 1 | F37: 1000 | G37: 1000 | H37: 44348
D38: eau petit | E38: 6 | F38: 155 | G38: 930 | H38: 44348
D39: eau grand | E39: 6 | F39: 135 | G39: 810 | H39: 44348
D40: coca canette | E40: 1 | F40: 1450 | G40: 1450 | H40: 44348
D41: coca bouteille + | E41: 4 | F41: 510 | G41: 2040 | H41: 44348
D42: Rouiba | E42: 1 | F42: 520 | G42: 520 | H42: 44348
...

Sheet Pointage
B1: Date | C1: Zehor | D1: Yossera | E1: Nadjet | F1: Hadjer | G1: Amel | H1: Soumia | I1: Hafida | J1: Fatiha | K1: karima | L1: Samira | M1: Dalila | N1: Linda | O1: Katia | P1: Zahida | Q1: Remarque
A2: Mardi | B2: 44348 | C2: 3 | D2: 1 | E2: 0 | F2: 3 | G2: 3 | H2: 3 | I2: 3 | J2: 1 | K2: 1 | L2: 0 | M2: 0 | N2: 0 | O2: 0 | P2: 3
A3: Mercredi | B3: 44349 | C3: 1 | D3: 1 | E3: 0 | F3: 1 | G3: 1 | H3: 1 | I3: 1 | J3: 0 | K3: 1 | L3: 0 | M3: 0 | N3: 0 | O3: 0 | P3: 1
A4: Jeudi | B4: 44350 | C4: 1 | D4: 1 | E4: 0 | F4: 1 | G4: 1 | H4: 1 | I4: 1 | J4: 1 | K4: 1 | L4: 0 | M4: 0 | N4: 0 | O4: 0 | P4: 1
A5: Vendredi | B5: 44351 | C5: 1 | D5: 0 | E5: 0 | F5: 1 | G5: 0 | H5: 0 | I5: 1 | J5: 0 | K5: 0 | L5: 0 | M5: 0 | N5: 0 | O5: 0 | P5: 1
A6: Samedi | B6: 44352 | C6: 1 | D6: 1 | E6: 1 | F6: 1 | G6: 1 | H6: 0.5 | I6: 0 | J6: 1 | K6: 1 | L6: 0 | M6: 0 | N6: 1 | O6: 0 | P6: 1 | Q6: Soumia djate à 13h+ zahida djate à 14h
A7: Dimanche | B7: 44353 | C7: 1 | D7: 1 | E7: 0 | F7: 1 | G7: 1 | H7: 1 | I7: 1 | J7: 0 | K7: 1 | L7: 0 | M7: 0 | N7: 1 | O7: 1 | P7: 1
A8: Lundi | B8: 44354 | C8: 1 | D8: 0 | E8: 0 | F8: 1 | G8: 1 | H8: 1 | I8: 1 | J8: 0 | K8: 1 | L8: 0 | M8: 0 | N8: 1 | O8: 1 | P8: 1
A9: Mardi | B9: 44355 | C9: 0 | D9: 1 | E9: 1 | F9: 1 | G9: 1 | H9: 1 | I9: 1 | J9: 0 | K9: 1 | L9: 0 | M9: 0 | N9: 1 | O9: 1 | P9: 1
A10: Mercredi | B10: 44356 | C10: 1 | D10: 1 | E10: 1 | F10: 1 | G10: 1 | H10: 1 | I10: 1 | J10: 1 | K10: 1 | L10: 0 | M10: 0 | N10: 1 | O10: 1 | P10: 1 | Q10: Fatiha djat sans que je lui dise . Hafida djate en retard 09h
A11: Jeudi | B11: 44357 | C11: 1 | D11: 1 | E11: 0 | F11: 1 | G11: 1 | H11: 1 | I11: 1 | J11: 1 | K11: 1 | L11: 0 | M11: 0 | N11: 1 | O11: 1 | P11: 1
A12: Vendredi | B12: 44358 | C12: 1 | D12: 1 | E12: 0 | F12: 0 | G12: 0 | H12: 0 | I12: 1 | J12: 1 | K12: 0 | L12: 0 | M12: 0 | N12: 1 | O12: 1 | P12: 1
A13: Samedi | B13: 44359 | C13: 1 | D13: 1 | E13: 1 | F13: 1 | G13: 1 | H13: 0.5 | I13: 0 | J13: 1 | K13: 1 | L13: 0 | M13: 1 | N13: 1 | O13: 1 | P13: 0 | Q13: Zehor est tombé malade et elle est sortie à 13h . Soumeya est venue à midi malgré c'était prévu ma tedjich toute la journée
A14: Dimanche | B14: 44360 | C14: 0 | D14: 0 | E14: 1 | F14: 1 | G14: 1 | H14: 1 | I14: 1 | J14: 0 | K14: 1 | L14: 0 | M14: 1 | N14: 1 | O14: 1 | P14: 1
A15: Lundi | B15: 44361 | C15: 1 | D15: 0 | E15: 1 | F15: 0.5 | G15: 1 | H15: 0 | I15: 1 | J15: 0 | K15: 1 | L15: 0 | M15: 1 | N15: 1 | O15: 1 | P15: 1 | Q15: Hafida est venue à 09h, Hadjer est venue à 12h
A16: Mardi | B16: 44362 | C16: 1 | D16: 0 | E16: 1 | F16: 0 | G16: 1 | H16: 1 | I16: 1 | J16: 0 | K16: 1 | L16: 0 | M16: 1 | N16: 1 | O16: 1 | P16: 0 | Q16: zahida ra7et 3ane medecin et ma djatech tt la journéée
A17: Mercredi | B17: 44363 | C17: 1 | D17: 0 | E17: 1 | F17: 0.5 | G17: 1 | H17: 1 | I17: 1 | J17: 0 | K17: 1 | L17: 0 | M17: 1 | N17: 1 | O17: 1 | P17: 1 | Q17: elyoum il y'avait pas de travaille 9a3edou yeguesserou toute l'aprèsmidi
A18: Jeudi | B18: 44364 | C18: 1 | D18: 0 | E18: 1 | F18: 1 | G18: 1 | H18: 1 | I18: 1 | J18: 0 | K18: 1 | L18: 0 | M18: 1 | N18: 1 | O18: 1 | P18: 1 | Q18: hadjer ra7et à 10h30 we wellate à 13h kan 3anedeha examen . djate zehor à 08h25 bach fete7etelhom elbab, zahida est venue à 13hh puisque kanet 3aned medecin
A19: Vendredi | B19: 44365 | C19: 0 | D19: 1 | E19: 0 | F19: 0 | G19: 0 | H19: 0 | I19: 1 | J19: 1 | K19: 0 | L19: 0 | M19: 0 | N19: 1 | O19: 0 | P19: 1
A20: Samedi | B20: 44366 | C20: 1 | D20: 1 | E20: 1 | F20: 1 | G20: 1 | H20: 0 | I20: 0 | J20: 1 | K20: 1 | L20: 0 | M20: 1 | N20: 1 | O20: 1 | P20: 0 | Q20: elyoum kemelou bekeri kharedjetehom à 16h
A21: Dimanche | B21: 44367 | C21: 1 | D21: 0 | E21: 0 | F21: 1 | G21: 1 | H21: 0 | I21: 1 | J21: 0 | K21: 1 | L21: 0 | M21: 1 | N21: 0 | O21: 1 | P21: 1 | Q21: hafida djate en retard
A22: Lundi | B22: 44368 | C22: 1 | D22: 0 | E22: 0 | F22: 1 | G22: 1 | H22: 0 | I22: 1 | J22: 0 | K22: 1 | L22: 0 | M22: 1 | N22: 1 | O22: 1 | P22: 0.5 | Q22: zahida djate à 13h ra7et tedir manicure 3aned Fulla lol
A23: Mardi | B23: 44369 | C23: 1 | D23: 1 | E23: 0 | F23: 1 | G23: 1 | H23: 0 | I23: 1 | J23: 0 | K23: 0 | L23: 1 | M23: 1 | N23: 1 | O23: 0 | P23: 1 | Q23: zehor et hadjer kharedjou à 15h30 we madaretelich bezaf khefaf , samira djate en retard ma 3arefetch teri9 we kharedjet à 16h30
A24: Mercredi | B24: 44370 | C24: 1 | D24: 1 | E24: 0 | F24: 1 | G24: 1 | H24: 0 | I24: 1 | J24: 0 | K24: 1 | L24: 1 | M24: 1 | N24: 1 | O24: 0 | P24: 1 | Q24: samira djate à 10h ra7et à 16h30 karima djate ghasselet la vaissel ra7et a 13h welate à 15h30 mais zadet reweneteha machi elle a netoyer
A25: Jeudi | B25: 44371 | C25: 1 | D25: 1 | E25: 0 | F25: 0.5 | G25: 1 | H25: 0 | I25: 1 | J25: 1 | K25: 1 | L25: 1 | M25: 1 | N25: 1 | O25: 0 | P25: 1 | Q25: hafida djate en retard a 10h15, hadjer kan 3anedeha RDV 3aned gastro | R25: ,
A26: Vendredi | B26: 44372 | C26: 1 | D26: 1 | E26: 0 | F26: 1 | G26: 0 | H26: 0 | I26: 1 | J26: 1 | K26: 0 | L26: 0 | M26: 0 | N26: 1 | O26: 0 | P26: 1
A27: Samedi | B27: 44373 | C27: 1 | D27: 1 | E27: 0 | F27: 1 | G27: 1 | H27: 0 | I27: 0 | J27: 1 | K27: 0 | L27: 1 | M27: 1 | N27: 1 | O27: 0 | P27: 0.5
A28: Dimanche | B28: 44374 | C28: 1 | D28: 1 | E28: 1 | F28: 0 | G28: 1 | H28: 0 | I28: 1 | J28: 0 | K28: 0 | L28: 1 | M28: 1 | N28: 1 | O28: 0 | P28: 1
A29: Lundi | B29: 44375 | C29: 1 | D29: 1 | E29: 1 | F29: 0 | G29: 1 | H29: 0 | I29: 1 | J29: 0 | K29: 0 | L29: 1 | M29: 1 | N29: 1 | O29: 0 | P29: 1
A30: Mardi | B30: 44376 | C30: 1 | D30: 1 | E30: 1 | F30: 0 | G30: 1 | H30: 0 | I30: 1 | J30: 0 | K30: 0 | L30: 1 | M30: 1 | N30: 1 | O30: 0 | P30: 1
A31: Mercredi | B31: 44377 | C31: 1 | D31: 1 | E31: 1 | F31: 0 | G31: 1 | H31: 0 | I31: 1 | J31: 0 | K31: 0 | L31: 1 | M31: 1 | N31: 1 | O31: 0 | P31: 1
C32: =SUM(C1:C31) -> 29 | D32: =SUM(D1:D31) -> 21 | E32: =SUM(E1:E31) -> 14 | F32: =SUM(F1:F31) -> 23.5 | G32: =SUM(G1:G31) -> 28 | H32: =SUM(H1:H31) -> 15 | I32: =SUM(I1:I31) -> 28 | J32: =SUM(J1:J31) -> 12 | K32: =SUM(K1:K31) -> 20 | L32: =SUM(L2:L31) -> 8 | M32: =SUM(M2:M31) -> 17 | N32: =SUM(N2:N31) -> 25 | O32: =SUM(O2:O31) -> 15 | P32: =SUM(P1:P31) -> 28
C33: 1923 | D33: 600 | E33: 1000 | F33: 1000 | G33: 1154 | H33: 962 | I33: 962 | J33: 1200 | K33: 740 | L33: 962 | M33: 962 | N33: 1000 | O33: 962 | P33: 1154 | Q33: =SUM(C33:P33) -> 14581
C34: =C33*C32 -> 55767 | D34: =D32*D33 -> 12600 | E34: =E33*E32 -> 14000 | F34: =F33*F32 -> 23500 | G34: =G33*G32 -> 32312 | H34: =H33*H32 -> 14430 | I34: =I33*I32 -> 26936 | J34: =J33*J32 -> 14400 | K34: =K33*K32 -> 14800 | L34: =L33*L32 -> 7696 | ... O34: =O33*O32 -> 14430 | P34: =P32*P33 -> 32312 | Q34: =SUM(C34:P34) -> 304537
C35: 56000 | D35: 12600 | E35: 14000 | F35: 23500 | G35: 32000 | H35: 15000 | I35: 27000 | J35: 14400 | K35: 15000 | L35: 8000 | M35: 16000 | N35: 25000 | O35: 14500 | P35: 32000 | Q35: =SUM(C35:P35) -> 305000
Q36: 15000 Da prime de l'aid
O50: u

Sheet Feuille 6

Sheet Salaires
I12: Nom | J12: Salaire | K12: Avance
H13: 1 | I13: Zehor | J13: =Pointage!C34*1 -> 55767 | K13: 1000
H14: 2 | I14: Yossera | J14: =Pointage!D34*1 -> 12600 | K14: 8000 | L14: 1000+1000+6000
H15: 3 | I15: Amel | J15: =Pointage!G34*1 -> 32312 | K15: 2000 | L15: 1000+1000
H16: 4 | I16: Nadjet | J16: =Pointage!E34*1 -> 14000
H17: 5 | I17: Hadjer | J17: =Pointage!F34*1 -> 23500
H18: 6 | I18: Hafida | J18: =Pointage!I34*1 -> 26936 | K18: 12000 | L18: 5000+5000+2000
H19: 7 | I19: Linda | J19: =Pointage!N34*1 -> 25000 | K19: 15000
H20: 8 | I20: Katia | J20: =Pointage!O34*1 -> 14430 | K20: 14500
H21: 9 | I21: Soumia | J21: =Pointage!H34*1 -> 14430 | K21: 14000 | L21: 2000+12000
H22: 10 | I22: Fatiha | J22: =Pointage!J34*1 -> 14400 | K22: 14400 | L22: 1200+13200
H23: 11 | I23: Dalila | J23: =Pointage!M34*1 -> 16354 | K23: 2000 | L23: 1000+1000
H24: 12 | I24: karima | J24: =Pointage!K34*1 -> 14800
H25: 13 | I25: Samira | J25: =Pointage!L34*1 -> 7696 | K25: 2000
H26: 14 | I26: Zahida | J26: =Pointage!P34*1 -> 32312
I27: TOTAL | J27: =SUM(J13:J26) -> 304537 | K27: =SUM(K13:K26) -> 84900
J28: =J27-K27 -> 219637

Sheet Feuille 5
I6: Amel Dépenses Mois de juin
J9: vetements | K9: 14000
J10: Auto école | K10: 5000
J11: réparation Pc | K11: 2000
J12: Lunettes | K12: 26000
J13: afficheur Note 8 | K13: 25000
J14: 2 Fanouss | K14: 4000
J15: dentisste +brossses | K15: 6000
J16: storm | K16: 2000
J17: Khalida | K17: 10000
J18: auto école | K18: 10000
J19: Maria vetements | K19: 3000
J20: Islem | K20: 1000
K25: =SUM(K9:K24) -> 108000
