Workbook

Sheet RECAP
B1: Date | C1: Recette Nov 2024 | D1: Recette | E1: Logiciel | F1: Charges | G1: Salaire | H1: Che7i7a | I1: Loyer | J1: Net Profit | K1: Nb de jours | M1: Objectif | N1: Mois de Novembre 2024
A2: dimanche | B2: 45627 | C2: 139000 | D2: 57000 | E2: 57070 | H2: 2000 | K2: 1 | N2: 139000
A3: lundi | B3: 45628 | C3: 48000 | D3: 36000 | E3: 35810 | H3: 2000 | K3: 1 | N3: 48000 | O3: Bénéfice Moyen par jour | P3: Moyenne | Q3: Moyenne salaire | R3: pourcentage du salaire vis à vis la recettte
A4: mardi | B4: 45629 | C4: 60000 | D4: 65000 | E4: 60840 | H4: 2000 | K4: 1 | N4: 60000 | O4: =J33/K33 -> 23238.21 | P4: =D33/K33 -> 70903.226 | R4: =Q4/P4 -> 0
A5: mercredi | B5: 45630 | C5: 50000 | D5: 29000 | E5: 28720 | H5: 2000 | K5: 1 | N5: 50000
A6: jeudi | B6: 45631 | C6: 49000 | D6: 65000 | E6: 64655 | H6: 2000 | K6: 1 | N6: 49000 | O6: Moyenne des charges par jour | P6: Objectif
A7: vendredi | B7: 45632 | C7: 48000 | D7: 71000 | E7: 64800 | H7: 2000 | K7: 1 | N7: 48000 | O7: =F33/K33 -> 28377.771 | P7: 100000
A8: samedi | B8: 45633 | C8: 72000 | D8: 69000 | E8: 67980 | H8: 2000 | K8: 1 | N8: 72000 | O8: ² | T8: "
A9: dimanche | B9: 45634 | C9: 57000 | D9: 72000 | E9: 72280 | H9: 2000 | K9: 1 | N9: 57000
A10: lundi | B10: 45635 | C10: 62000 | D10: 48000 | E10: 48230 | H10: 2000 | K10: 1 | N10: 62000 | O10: Cash restant | P10: Magasin | Q10: Cash réel | R10: Mes dettes pour le magasin
A11: mardi | B11: 45636 | C11: 31000 | D11: 45000 | E11: 45005 | H11: 2000 | K11: 1 | N11: 31000 | O11: =D33+O14-F33-H33-P11-Salaires!I26 -> 1016289.1 | P11: 194000 | Q11: 809000 | R11: =O11-Q11 -> 207289.1
A12: mercredi | B12: 45637 | C12: 62000 | D12: 71000 | E12: 69920 | H12: 2000 | K12: 1 | N12: 62000
A13: jeudi | B13: 45638 | C13: 35000 | D13: 72000 | E13: 71810 | H13: 2000 | K13: 1 | N13: 35000 | O13: Fond de Roulement
A14: vendredi | B14: 45639 | C14: 71000 | D14: 90000 | E14: 89805 | H14: 2000 | K14: 1 | N14: 71000 | O14: 330000
A15: samedi | B15: 45640 | C15: 80000 | D15: 79000 | E15: 79600 | H15: 2000 | K15: 1 | N15: 80000 | R15: Mounir Facture d'éléctrité : 10000 Da
A16: dimanche | B16: 45641 | C16: 82000 | D16: 72000 | E16: 72110 | H16: 2000 | K16: 1 | N16: 82000 | O16: Bénéfice Sept + loyer | R16: Les Charges du mois de Janvier : 140000Da
A17: lundi | B17: 45642 | C17: 11000 | D17: 55000 | E17: 54720 | H17: 2000 | K17: 1 | N17: 11000 | O17: 0 | R17: Sifou : 30000Da
A18: mardi | B18: 45643 | C18: 0 | D18: 68000 | E18: 68420 | H18: 2000 | K18: 1 | N18: 0 | Q18: 90700 | R18: Chahrazed:27500+4200Da+ 42000Da+13000Da + 4000Da Livraison | S18: 45582 | T18: Le reste du paiement CNASet pénalité pour mois de Décembre
A19: mercredi | B19: 45644 | C19: 0 | D19: 130000 | E19: 130680 | H19: 2000 | K19: 1 | N19: 0 | O19: Différence mois d'Aout | R19: la vraie caisse: 9000 Da | T19: 18000
A20: jeudi | B20: 45645 | C20: 0 | D20: 100000 | E20: 100620 | H20: 2000 | K20: 1 | N20: 0 | O20: =D33-C33 -> 870000 | R20: Porte Monnie Magasin: 5000Da
A21: vendredi | B21: 45646 | C21: 0 | D21: 62000 | E21: 62460 | H21: 2000 | K21: 1 | N21: 0 | O21: Différence objectif | Q21: réparation Tabouna | R21: 1 | S21: 8800 | T21: =R21*S21 -> 8800
A22: samedi | B22: 45647 | C22: 0 | D22: 64000 | E22: 63930 | H22: 2000 | K22: 1 | N22: 0 | O22: =M36-F36 -> 0 | Q22: Torchons | R22: 4 | S22: 400 | T22: 600
A23: dimanche | B23: 45648 | C23: 0 | D23: 60000 | E23: 60120 | H23: 2000 | K23: 1 | N23: 0 | O23: Différence du Totale | Q23: poelle | R23: 1 | S23: 2800 | T23: =R23*S23 -> 2800
A24: lundi | B24: 45649 | C24: 45000 | D24: 44000 | E24: 43970 | H24: 2000 | K24: 1 | N24: 45000 | O24: =D33-C33 -> 870000 | S24: Achoire | T24: 1
A25: mardi | B25: 45650 | C25: 55000 | D25: 47000 | E25: 47440 | H25: 2000 | K25: 1 | N25: 55000 | O25: Les vendredis | Q25: Cash chez Sofiane
A26: mercredi | B26: 45651 | C26: 45000 | D26: 57000 | E26: 57500 | H26: 2000 | K26: 1 | N26: 45000 | O26: =D9+D16+D23+D30 -> 270000 | S26: Les étagères pour locale | T26: 1
A27: jeudi | B27: 45652 | C27: 40000 | D27: 75000 | E27: 75210 | H27: 2000 | K27: 1 | N27: 40000
A28: vendredi | B28: 45653 | C28: 36000 | D28: 68000 | E28: 68550 | H28: 2000 | K28: 1 | N28: 36000 | O28: Cash réel
A29: samedi | B29: 45654 | C29: 69000 | D29: 68000 | E29: 68780 | H29: 2000 | K29: 1 | N29: 69000 | O29: 51000
A30: dimanche | B30: 45655 | C30: 40000 | D30: 66000 | E30: 66000 | H30: 2000 | K30: 1 | N30: 40000 | O30: rest à payer
A31: lundi | B31: 45656 | C31: 41000 | D31: 176000 | E31: 176000 | H31: 2000 | K31: 1 | N31: 41000
A32: mardi | B32: 45657 | C32: 0 | D32: 117000 | E32: 117000 | H32: 2000 | K32: 1 | N32: 0 | R32: =SUM(R26:R31) -> 0
C33: =SUM(C2:C32) -> 1328000 | D33: =SUM(D2:D32) -> 2198000 | E33: =SUM(E2:E32) -> 2190035 | F33: ='Les Charges '!G419 -> 879710.9 | G33: =Salaires!H26 -> 405904.6 | H33: =SUM(H2:H32) -> 62000 | I33: 130000 | J33: =D33-F33-G33-H33-I33 -> 720384.5 | K33: =SUM(K2:K32) -> 31 | N33: =SUM(N2:N32) -> 1328000
O35: =O11-O29-O34 -> 965289.1
D38: -

Sheet Pointage
A1: Colonne 1 | B1: Date | C1: Wissem | D1: N/J | E1: Yasmine | F1: Column 18 | G1: Saida | H1: Column 20 | I1: Ahlem | J1: Column 21 | K1: Nour ElHouda | L1: Column 22 | M1: Amina | N1: Column 23 | O1: Selma | P1: Column 24 | Q1: Zohra | R1: Column 25 | S1: Nora | T1: Column 26 | U1: Ikram | V1: Column 27 | W1: Rayan | X1: Column 28 | Y1: Karima | Z1: Column 29 | AA1: Sihem | AB1: Column 30 | AC1: Fatiha | AD1: Column 31 | AE1: Israa | AF1: Salaire Israa | AG1: Remarque | AH1: Salaire/Jour
A2: dimanche | B2: 45627 | C2: 0 | D2: =C2*1500 -> 0 | E2: 1 | F2: =E2*1112 -> 1112 | G2: 1 | H2: =G2*1112 -> 1112 | I2: 1 | J2: =I2*1112 -> 1112 | K2: 0 | L2: =K2*1112 -> 0 | M2: 1 | N2: =M2*1112 -> 1112 | O2: 1 | P2: =O2*1112 -> 1112 | Q2: 0 | R2: =Q2*1200 -> 0 | S2: 1 | T2: =S2*1112 -> 1112 | U2: 1 | V2: =U2*1112 -> 1112 | W2: 1 | X2: =W2*1200 -> 1200 | Y2: 1 | Z2: =Y2*1112 -> 1112 | AA2: 1 | AB2: =AA2*1100 -> 1100 | AC2: 0 | AD2: =AC2*1100 -> 0 | AE2: 0 | AF2: =AE2*1100 -> 0 | AH2: =SUM(AD2,AB2,Z2,X2,V2,T2,R2,P2,N2,L2,J2,H2,F2,D2) -> 11196
A3: lundi | B3: 45628 | C3: 0 | D3: =C3*1500 -> 0 | E3: 1 | F3: =E3*1112 -> 1112 | G3: 1 | H3: =G3*1112 -> 1112 | I3: 1 | J3: =I3*1112 -> 1112 | K3: 0 | L3: =K3*1112 -> 0 | M3: 0 | N3: =M3*1112 -> 0 | O3: 0 | P3: =O3*1112 -> 0 | Q3: 0 | R3: =Q3*1200 -> 0 | S3: 1 | T3: =S3*1112 -> 1112 | U3: 0 | V3: =U3*1112 -> 0 | W3: 0.5 | X3: =W3*1200 -> 600 | Y3: 1 | Z3: =Y3*1112 -> 1112 | AA3: 1 | AB3: =AA3*1100 -> 1100 | AC3: 1 | AD3: =AC3*1100 -> 1100 | AE3: 1 | AF3: =AE3*1100 -> 1100 | AH3: =SUM(AD3,AB3,Z3,X3,V3,T3,R3,P3,N3,L3,J3,H3,F3,D3) -> 8360
A4: mardi | B4: 45629 | C4: 0 | D4: =C4*1500 -> 0 | E4: 0.33 | F4: =E4*1112 -> 366.96 | G4: 1 | H4: =G4*1112 -> 1112 | I4: 1 | J4: =I4*1112 -> 1112 | K4: 1 | L4: =K4*1112 -> 1112 | M4: 1 | N4: =M4*1112 -> 1112 | O4: 1 | P4: =O4*1112 -> 1112 | Q4: 1 | R4: =Q4*1200 -> 1200 | S4: 1 | T4: =S4*1112 -> 1112 | U4: 1 | V4: =U4*1112 -> 1112 | W4: 1 | X4: =W4*1200 -> 1200 | Y4: 1 | Z4: =Y4*1112 -> 1112 | AA4: 1 | AB4: =AA4*1100 -> 1100 | AC4: 1 | AD4: =AC4*1100 -> 1100 | AE4: 0 | AF4: =AE4*1100 -> 0 | AH4: =SUM(AD4,AB4,Z4,X4,V4,T4,R4,P4,N4,L4,J4,H4,F4,D4) -> 13862.96
A5: mercredi | B5: 45630 | C5: 0 | D5: =C5*1500 -> 0 | E5: 1 | F5: =E5*1112 -> 1112 | G5: 1 | H5: =G5*1112 -> 1112 | I5: 1 | J5: =I5*1112 -> 1112 | K5: 0 | L5: =K5*1112 -> 0 | M5: 1 | N5: =M5*1112 -> 1112 | O5: 1 | P5: =O5*1112 -> 1112 | Q5: 0 | R5: =Q5*1200 -> 0 | S5: 1 | T5: =S5*1112 -> 1112 | U5: 1 | V5: =U5*1112 -> 1112 | W5: 1 | X5: =W5*1200 -> 1200 | Y5: 1 | Z5: =Y5*1112 -> 1112 | AA5: 1 | AB5: =AA5*1100 -> 1100 | AC5: 0.75 | AD5: =AC5*1100 -> 825 | AE5: 0 | AF5: =AE5*1100 -> 0 | AG5: Fatiha est sortie puisque elle était malade | AH5: =SUM(AD5,AB5,Z5,X5,V5,T5,R5,P5,N5,L5,J5,H5,F5,D5) -> 12021
A6: jeudi | B6: 45631 | C6: 0 | D6: =C6*1500 -> 0 | E6: 1 | F6: =E6*1112 -> 1112 | G6: 1 | H6: =G6*1112 -> 1112 | I6: 1 | J6: =I6*1112 -> 1112 | K6: 0 | L6: =K6*1112 -> 0 | M6: 0 | N6: =M6*1112 -> 0 | O6: 0 | P6: =O6*1112 -> 0 | Q6: 1 | R6: =Q6*1200 -> 1200 | S6: 1 | T6: =S6*1112 -> 1112 | U6: 1 | V6: =U6*1112 -> 1112 | W6: 1 | X6: =W6*1200 -> 1200 | Y6: 1 | Z6: =Y6*1112 -> 1112 | AA6: 1 | AB6: =AA6*1100 -> 1100 | AC6: 1 | AD6: =AC6*1100 -> 1100 | AE6: 0 | AF6: =AE6*1100 -> 0 | AG6: Rayan est resté jusqu'à 18h Selma s'est absenté sans autorisation | AH6: =SUM(AD6,AB6,Z6,X6,V6,T6,R6,P6,N6,L6,J6,H6,F6,D6) -> 11272
A7: vendredi | B7: 45632 | C7: 0 | D7: =C7*1500 -> 0 | E7: 1 | F7: =E7*1112 -> 1112 | G7: 0 | H7: =G7*1112 -> 0 | I7: 0 | J7: =I7*1112 -> 0 | K7: 0 | L7: =K7*1112 -> 0 | M7: 2 | N7: =M7*1112 -> 2224 | O7: 1 | P7: =O7*1112 -> 1112 | Q7: 0 | R7: =Q7*1200 -> 0 | S7: 1 | T7: =S7*1112 -> 1112 | U7: 1 | V7: =U7*1112 -> 1112 | W7: 1 | X7: =W7*1200 -> 1200 | Y7: 0 | Z7: =Y7*1112 -> 0 | AA7: 0 | AB7: =AA7*1100 -> 0 | AC7: 1 | AD7: =AC7*1100 -> 1100 | AE7: 0 | AF7: =AE7*1100 -> 0 | AG7: Amina + Wafa | AH7: =SUM(AD7,AB7,Z7,X7,V7,T7,R7,P7,N7,L7,J7,H7,F7,D7) -> 8972
A8: samedi | B8: 45633 | C8: 0 | D8: =C8*1500 -> 0 | E8: 1 | F8: =E8*1112 -> 1112 | G8: 1 | H8: =G8*1112 -> 1112 | I8: 1 | J8: =I8*1112 -> 1112 | K8: 0 | L8: =K8*1112 -> 0 | M8: 1 | N8: =M8*1112 -> 1112 | O8: 1 | P8: =O8*1112 -> 1112 | Q8: 1 | R8: =Q8*1200 -> 1200 | S8: 1 | T8: =S8*1112 -> 1112 | U8: 1 | V8: =U8*1112 -> 1112 | W8: 0 | X8: =W8*1200 -> 0 | Y8: 1.5 | Z8: =Y8*1112 -> 1668 | AA8: 0 | AB8: =AA8*1100 -> 0 | AC8: 0 | AD8: =AC8*1100 -> 0 | AE8: 1 | AF8: =AE8*1100 -> 1100 | AG8: demie journnée Rania | AH8: =SUM(AD8,AB8,Z8,X8,V8,T8,R8,P8,N8,L8,J8,H8,F8,D8) -> 10652
A9: dimanche | B9: 45634 | C9: 0 | D9: =C9*1500 -> 0 | E9: 1 | F9: =E9*1112 -> 1112 | G9: 1 | H9: =G9*1112 -> 1112 | I9: 1 | J9: =I9*1112 -> 1112 | K9: 1 | L9: =K9*1112 -> 1112 | M9: 1 | N9: =M9*1112 -> 1112 | O9: 0 | P9: =O9*1112 -> 0 | Q9: 0 | R9: =Q9*1200 -> 0 | S9: 3.5 | T9: =S9*1112 -> 3892 | U9: 1 | V9: =U9*1112 -> 1112 | W9: 1 | X9: =W9*1200 -> 1200 | Y9: 1 | Z9: =Y9*1112 -> 1112 | AA9: 1 | AB9: =AA9*1100 -> 1100 | AC9: 1 | AD9: =AC9*1100 -> 1100 | AE9: 0 | AF9: =AE9*1100 -> 0 | AH9: =SUM(AD9,AB9,Z9,X9,V9,T9,R9,P9,N9,L9,J9,H9,F9,D9) -> 15076
A10: lundi | B10: 45635 | C10: 0 | D10: =C10*1500 -> 0 | E10: 1 | F10: =E10*1112 -> 1112 | G10: 1 | H10: =G10*1112 -> 1112 | I10: 1 | J10: =I10*1112 -> 1112 | K10: 0 | L10: =K10*1112 -> 0 | M10: 0 | N10: =M10*1112 -> 0 | O10: 0 | P10: =O10*1112 -> 0 | Q10: 1 | R10: =Q10*1200 -> 1200 | S10: 1 | T10: =S10*1112 -> 1112 | U10: 3.5 | V10: =U10*1112 -> 3892 | W10: 1 | X10: =W10*1200 -> 1200 | Y10: 1 | Z10: =Y10*1112 -> 1112 | AA10: 1 | AB10: =AA10*1100 -> 1100 | AC10: 1 | AD10: =AC10*1100 -> 1100 | AE10: 1 | AF10: =AE10*1100 -> 1100 | AH10: =SUM(AD10,AB10,Z10,X10,V10,T10,R10,P10,N10,L10,J10,H10,F10,D10) -> 14052
A11: mardi | B11: 45636 | C11: 0 | D11: =C11*1500 -> 0 | E11: 0 | F11: =E11*1112 -> 0 | G11: 1 | H11: =G11*1112 -> 1112 | I11: 1 | J11: =I11*1112 -> 1112 | K11: 1 | L11: =K11*1112 -> 1112 | M11: 1 | N11: =M11*1112 -> 1112 | O11: 1 | P11: =O11*1112 -> 1112 | Q11: 0 | R11: =Q11*1200 -> 0 | S11: 1 | T11: =S11*1112 -> 1112 | U11: 1 | V11: =U11*1112 -> 1112 | W11: 1 | X11: =W11*1200 -> 1200 | Y11: 1 | Z11: =Y11*1112 -> 1112 | AA11: 1 | AB11: =AA11*1100 -> 1100 | AC11: 0.5 | AD11: =AC11*1100 -> 550 | AE11: 0 | AF11: =AE11*1100 -> 0 | AG11: Selma djate à 14h -17h | AH11: =SUM(AD11,AB11,Z11,X11,V11,T11,R11,P11,N11,L11,J11,H11,F11,D11) -> 11746
A12: mercredi | B12: 45637 | C12: 0 | D12: =C12*1500 -> 0 | E12: 0 | F12: =E12*1112 -> 0 | G12: 1 | H12: =G12*1112 -> 1112 | I12: 1 | J12: =I12*1112 -> 1112 | K12: 1 | L12: =K12*1112 -> 1112 | M12: 1 | N12: =M12*1112 -> 1112 | O12: 0.5 | P12: =O12*1112 -> 556 | Q12: 1 | R12: =Q12*1200 -> 1200 | S12: 1 | T12: =S12*1112 -> 1112 | U12: 1 | V12: =U12*1112 -> 1112 | W12: 0 | X12: =W12*1200 -> 0 | Y12: 1 | Z12: =Y12*1112 -> 1112 | AA12: 1 | AB12: =AA12*1100 -> 1100 | AC12: 1 | AD12: =AC12*1100 -> 1100 | AE12: 0 | AF12: =AE12*1100 -> 0 | AH12: =SUM(AD12,AB12,Z12,X12,V12,T12,R12,P12,N12,L12,J12,H12,F12,D12) -> 11740
A13: jeudi | B13: 45638 | C13: 0 | D13: =C13*1500 -> 0 | E13: 1 | F13: =E13*1112 -> 1112 | G13: 0 | H13: =G13*1112 -> 0 | I13: 1 | J13: =I13*1112 -> 1112 | K13: 1 | L13: =K13*1112 -> 1112 | M13: 0 | N13: =M13*1112 -> 0 | O13: 0 | P13: =O13*1112 -> 0 | Q13: 0 | R13: =Q13*1200 -> 0 | S13: 1 | T13: =S13*1112 -> 1112 | U13: 1 | V13: =U13*1112 -> 1112 | W13: 1 | X13: =W13*1200 -> 1200 | Y13: 1 | Z13: =Y13*1112 -> 1112 | AA13: 0.5 | AB13: =AA13*1100 -> 550 | AC13: 1 | AD13: =AC13*1100 -> 1100 | AE13: 0 | AF13: =AE13*1100 -> 0 | AG13: Do3aa+Rania | AH13: =SUM(AD13,AB13,Z13,X13,V13,T13,R13,P13,N13,L13,J13,H13,F13,D13) -> 9522
A14: vendredi | B14: 45639 | C14: 0 | D14: =C14*1500 -> 0 | E14: 1 | F14: =E14*1112 -> 1112 | G14: 0 | H14: =G14*1112 -> 0 | I14: 0 | J14: =I14*1112 -> 0 | K14: 1 | L14: =K14*1112 -> 1112 | M14: 1 | N14: =M14*1112 -> 1112 | O14: 0 | P14: =O14*1112 -> 0 | Q14: 1 | R14: =Q14*1200 -> 1200 | S14: 0 | T14: =S14*1112 -> 0 | U14: 0 | V14: =U14*1112 -> 0 | W14: 1 | X14: =W14*1200 -> 1200 | Y14: 0 | Z14: =Y14*1112 -> 0 | AA14: 0 | AB14: =AA14*1100 -> 0 | AC14: 1 | AD14: =AC14*1100 -> 1100 | AE14: 0 | AF14: =AE14*1100 -> 0 | AG14: Do3aa | AH14: =SUM(AD14,AB14,Z14,X14,V14,T14,R14,P14,N14,L14,J14,H14,F14,D14) -> 6836
A15: samedi | B15: 45640 | C15: 0 | D15: =C15*1500 -> 0 | E15: 1 | F15: =E15*1112 -> 1112 | G15: 1 | H15: =G15*1112 -> 1112 | I15: 1 | J15: =I15*1112 -> 1112 | K15: 0 | L15: =K15*1112 -> 0 | M15: 1 | N15: =M15*1112 -> 1112 | O15: 0 | P15: =O15*1112 -> 0 | Q15: 0 | R15: =Q15*1200 -> 0 | S15: 1 | T15: =S15*1112 -> 1112 | U15: 1 | V15: =U15*1112 -> 1112 | W15: 1 | X15: =W15*1200 -> 1200 | Y15: 1 | Z15: =Y15*1112 -> 1112 | AA15: 0 | AB15: =AA15*1100 -> 0 | AC15: 1 | AD15: =AC15*1100 -> 1100 | AE15: 0 | AF15: =AE15*1100 -> 0 | AH15: =SUM(AD15,AB15,Z15,X15,V15,T15,R15,P15,N15,L15,J15,H15,F15,D15) -> 10084
A16: dimanche | B16: 45641 | C16: 0 | D16: =C16*1500 -> 0 | E16: 1 | F16: =E16*1112 -> 1112 | G16: 1 | H16: =G16*1112 -> 1112 | I16: 1 | J16: =I16*1112 -> 1112 | K16: 0 | L16: =K16*1112 -> 0 | M16: 0 | N16: =M16*1112 -> 0 | O16: 0 | P16: =O16*1112 -> 0 | Q16: 1 | R16: =Q16*1200 -> 1200 | S16: 1 | T16: =S16*1112 -> 1112 | U16: 1 | V16: =U16*1112 -> 1112 | W16: 1 | X16: =W16*1200 -> 1200 | Y16: 1 | Z16: =Y16*1112 -> 1112 | AA16: 1 | AB16: =AA16*1100 -> 1100 | AC16: 0 | AD16: =AC16*1100 -> 0 | AE16: 0 | AF16: =AE16*1100 -> 0 | AH16: =SUM(AD16,AB16,Z16,X16,V16,T16,R16,P16,N16,L16,J16,H16,F16,D16) -> 10172
A17: lundi | B17: 45642 | C17: 0 | D17: =C17*1500 -> 0 | E17: 1 | F17: =E17*1112 -> 1112 | G17: 0 | H17: =G17*1112 -> 0 | I17: 1 | J17: =I17*1112 -> 1112 | K17: 0 | L17: =K17*1112 -> 0 | M17: 2 | N17: =M17*1112 -> 2224 | O17: 0 | P17: =O17*1112 -> 0 | Q17: 0 | R17: =Q17*1200 -> 0 | S17: 1 | T17: =S17*1112 -> 1112 | U17: 1 | V17: =U17*1112 -> 1112 | W17: 1 | X17: =W17*1200 -> 1200 | Y17: 1 | Z17: =Y17*1112 -> 1112 | AA17: 1 | AB17: =AA17*1100 -> 1100 | AC17: 1 | AD17: =AC17*1100 -> 1100 | AE17: 0 | AF17: =AE17*1100 -> 0 | AH17: =SUM(AD17,AB17,Z17,X17,V17,T17,R17,P17,N17,L17,J17,H17,F17,D17) -> 11184
A18: mardi | B18: 45643 | C18: 0 | D18: =C18*1500 -> 0 | E18: 0 | F18: =E18*1112 -> 0 | G18: 1 | H18: =G18*1112 -> 1112 | I18: 1 | J18: =I18*1112 -> 1112 | K18: 1 | L18: =K18*1112 -> 1112 | M18: 1 | N18: =M18*1112 -> 1112 | O18: 0 | P18: =O18*1112 -> 0 | Q18: 1 | R18: =Q18*1200 -> 1200 | S18: 1 | T18: =S18*1112 -> 1112 | U18: 1 | V18: =U18*1112 -> 1112 | W18: 1 | X18: =W18*1200 -> 1200 | Y18: 1 | Z18: =Y18*1112 -> 1112 | AA18: 1 | AB18: =AA18*1100 -> 1100 | AC18: 1 | AD18: =AC18*1100 -> 1100 | AE18: 0 | AF18: =AE18*1100 -> 0 | AH18: =SUM(AD18,AB18,Z18,X18,V18,T18,R18,P18,N18,L18,J18,H18,F18,D18) -> 12384
A19: mercredi | B19: 45644 | C19: 0 | D19: =C19*1500 -> 0 | E19: 1 | F19: =E19*1112 -> 1112 | G19: 1 | H19: =G19*1112 -> 1112 | I19: 1 | J19: =I19*1112 -> 1112 | K19: 0 | L19: =K19*1112 -> 0 | M19: 1 | N19: =M19*1112 -> 1112 | O19: 1 | P19: =O19*1112 -> 1112 | Q19: 0 | R19: =Q19*1200 -> 0 | S19: 1 | T19: =S19*1112 -> 1112 | U19: 1 | V19: =U19*1112 -> 1112 | W19: 1 | X19: =W19*1200 -> 1200 | Y19: 1 | Z19: =Y19*1112 -> 1112 | AA19: 1 | AB19: =AA19*1100 -> 1100 | AC19: 1 | AD19: =AC19*1100 -> 1100 | AE19: 0 | AF19: =AE19*1100 -> 0 | AH19: =SUM(AD19,AB19,Z19,X19,V19,T19,R19,P19,N19,L19,J19,H19,F19,D19) -> 12296
A20: jeudi | B20: 45645 | C20: 0 | D20: =C20*1500 -> 0 | E20: 1 | F20: =E20*1112 -> 1112 | G20: 1 | H20: =G20*1112 -> 1112 | I20: 1 | J20: =I20*1112 -> 1112 | K20: 0 | L20: =K20*1112 -> 0 | M20: 1 | N20: =M20*1112 -> 1112 | O20: 0 | P20: =O20*1112 -> 0 | Q20: 0 | R20: =Q20*1200 -> 0 | S20: 1 | T20: =S20*1112 -> 1112 | U20: 1 | V20: =U20*1112 -> 1112 | W20: 0 | X20: =W20*1200 -> 0 | Y20: 1 | Z20: =Y20*1112 -> 1112 | AA20: 1 | AB20: =AA20*1100 -> 1100 | AC20: 1 | AD20: =AC20*1100 -> 1100 | AE20: 0 | AF20: =AE20*1100 -> 0 | AH20: =SUM(AD20,AB20,Z20,X20,V20,T20,R20,P20,N20,L20,J20,H20,F20,D20) -> 9984
A21: vendredi | B21: 45646 | C21: 0 | D21: =C21*1500 -> 0 | E21: 1 | F21: =E21*1112 -> 1112 | G21: 0 | H21: =G21*1112 -> 0 | I21: 0 | J21: =I21*1112 -> 0 | K21: 0 | L21: =K21*1112 -> 0 | M21: 1 | N21: =M21*1112 -> 1112 | O21: 0 | P21: =O21*1112 -> 0 | Q21: 0 | R21: =Q21*1200 -> 0 | S21: 1 | T21: =S21*1112 -> 1112 | U21: 1 | V21: =U21*1112 -> 1112 | W21: 0 | X21: =W21*1200 -> 0 | Y21: 0 | Z21: =Y21*1112 -> 0 | AA21: 1 | AB21: =AA21*1100 -> 1100 | AC21: 1 | AD21: =AC21*1100 -> 1100 | AE21: 0 | AF21: =AE21*1100 -> 0 | AH21: =SUM(AD21,AB21,Z21,X21,V21,T21,R21,P21,N21,L21,J21,H21,F21,D21) -> 6648
A22: samedi | B22: 45647 | C22: 0 | D22: =C22*1500 -> 0 | E22: 0.5 | F22: =E22*1112 -> 556 | G22: 1 | H22: =G22*1112 -> 1112 | I22: 1 | J22: =I22*1112 -> 1112 | K22: 0 | L22: =K22*1112 -> 0 | M22: 1 | N22: =M22*1112 -> 1112 | O22: 0 | P22: =O22*1112 -> 0 | Q22: 0 | R22: =Q22*1200 -> 0 | S22: 1 | T22: =S22*1112 -> 1112 | U22: 1 | V22: =U22*1112 -> 1112 | W22: 1 | X22: =W22*1200 -> 1200 | Y22: 1 | Z22: =Y22*1112 -> 1112 | AA22: 0.4 | AB22: =AA22*1100 -> 440 | AC22: 0 | AD22: =AC22*1100 -> 0 | AE22: 1 | AF22: =AE22*1100 -> 1100 | AG22: Yasmine djate à 14h40 | AH22: =SUM(AD22,AB22,Z22,X22,V22,T22,R22,P22,N22,L22,J22,H22,F22,D22) -> 8868
A23: dimanche | B23: 45648 | C23: 0 | D23: =C23*1500 -> 0 | E23: 1 | F23: =E23*1112 -> 1112 | G23: 1 | H23: =G23*1112 -> 1112 | I23: 1 | J23: =I23*1112 -> 1112 | K23: 0 | L23: =K23*1112 -> 0 | M23: 1 | N23: =M23*1112 -> 1112 | O23: 0 | P23: =O23*1112 -> 0 | Q23: 0 | R23: =Q23*1200 -> 0 | S23: 0 | T23: =S23*1112 -> 0 | U23: 1 | V23: =U23*1112 -> 1112 | W23: 1 | X23: =W23*1200 -> 1200 | Y23: 1 | Z23: =Y23*1112 -> 1112 | AA23: 0.1 | AB23: =AA23*1100 -> 110 | AC23: 1 | AD23: =AC23*1100 -> 1100 | AE23: 0 | AF23: =AE23*1100 -> 0 | AH23: =SUM(AD23,AB23,Z23,X23,V23,T23,R23,P23,N23,L23,J23,H23,F23,D23) -> 9082
A24: lundi | B24: 45649 | C24: 0 | D24: =C24*1500 -> 0 | E24: 1 | F24: =E24*1112 -> 1112 | G24: 1 | H24: =G24*1112 -> 1112 | I24: 1 | J24: =I24*1112 -> 1112 | K24: 0 | L24: =K24*1112 -> 0 | M24: 0 | N24: =M24*1112 -> 0 | O24: 0 | P24: =O24*1112 -> 0 | Q24: 1 | R24: =Q24*1200 -> 1200 | S24: 0 | T24: =S24*1112 -> 0 | U24: 0 | V24: =U24*1112 -> 0 | W24: 1 | X24: =W24*1200 -> 1200 | Y24: 1 | Z24: =Y24*1112 -> 1112 | AA24: 0 | AB24: =AA24*1100 -> 0 | AC24: 1 | AD24: =AC24*1100 -> 1100 | AE24: 1 | AF24: =AE24*1100 -> 1100 | AH24: =SUM(AD24,AB24,Z24,X24,V24,T24,R24,P24,N24,L24,J24,H24,F24,D24) -> 7948
A25: mardi | B25: 45650 | C25: 0 | D25: =C25*1500 -> 0 | E25: 1 | F25: =E25*1112 -> 1112 | G25: 1 | H25: =G25*1112 -> 1112 | I25: 1 | J25: =I25*1112 -> 1112 | K25: 0 | L25: =K25*1112 -> 0 | M25: 1 | N25: =M25*1112 -> 1112 | O25: 0 | P25: =O25*1112 -> 0 | Q25: 0 | R25: =Q25*1200 -> 0 | S25: 1 | T25: =S25*1112 -> 1112 | U25: 1 | V25: =U25*1112 -> 1112 | W25: 0 | X25: =W25*1200 -> 0 | Y25: 1 | Z25: =Y25*1112 -> 1112 | AA25: 0 | AB25: =AA25*1100 -> 0 | AC25: 1 | AD25: =AC25*1100 -> 1100 | AE25: 0 | AF25: =AE25*1100 -> 0 | AH25: =SUM(AD25,AB25,Z25,X25,V25,T25,R25,P25,N25,L25,J25,H25,F25,D25) -> 8884
A26: mercredi | B26: 45651 | C26: 0 | D26: =C26*1500 -> 0 | E26: 1 | F26: =E26*1112 -> 1112 | G26: 1 | H26: =G26*1112 -> 1112 | I26: 1 | J26: =I26*1112 -> 1112 | K26: 0 | L26: =K26*1112 -> 0 | M26: 0.5 | N26: =M26*1112 -> 556 | O26: 1.5 | P26: =O26*1112 -> 1668 | Q26: 1 | R26: =Q26*1200 -> 1200 | S26: 0 | T26: =S26*1112 -> 0 | U26: 1 | V26: =U26*1112 -> 1112 | W26: 0 | X26: =W26*1200 -> 0 | Y26: 1 | Z26: =Y26*1112 -> 1112 | AA26: 0 | AB26: =AA26*1100 -> 0 | AC26: 0 | AD26: =AC26*1100 -> 0 | AE26: 1 | AF26: =AE26*1100 -> 1100 | AH26: =SUM(AD26,AB26,Z26,X26,V26,T26,R26,P26,N26,L26,J26,H26,F26,D26) -> 8984
A27: jeudi | B27: 45652 | C27: 1 | D27: =C27*1500 -> 1500 | E27: 1 | F27: =E27*1112 -> 1112 | G27: 1 | H27: =G27*1112 -> 1112 | I27: 1 | J27: =I27*1112 -> 1112 | K27: 0 | L27: =K27*1112 -> 0 | M27: 1 | N27: =M27*1112 -> 1112 | O27: 0 | P27: =O27*1112 -> 0 | Q27: 0 | R27: =Q27*1200 -> 0 | S27: 1 | T27: =S27*1112 -> 1112 | U27: 1 | V27: =U27*1112 -> 1112 | W27: 0 | X27: =W27*1200 -> 0 | Y27: 1 | Z27: =Y27*1112 -> 1112 | AA27: 2.5 | AB27: =AA27*1100 -> 2750 | AC27: 1 | AD27: =AC27*1100 -> 1100 | AE27: 0 | AF27: =AE27*1100 -> 0 | AH27: =SUM(AD27,AB27,Z27,X27,V27,T27,R27,P27,N27,L27,J27,H27,F27,D27) -> 13134
A28: vendredi | B28: 45653 | C28: 1 | D28: =C28*1500 -> 1500 | E28: 1 | F28: =E28*1112 -> 1112 | G28: 0 | H28: =G28*1112 -> 0 | I28: 0 | J28: =I28*1112 -> 0 | K28: 0 | L28: =K28*1112 -> 0 | M28: 1 | N28: =M28*1112 -> 1112 | O28: 2 | P28: =O28*1112 -> 2224 | Q28: 0 | R28: =Q28*1200 -> 0 | S28: 1 | T28: =S28*1112 -> 1112 | U28: 1 | V28: =U28*1112 -> 1112 | W28: 0 | X28: =W28*1200 -> 0 | Y28: 0 | Z28: =Y28*1112 -> 0 | AA28: 0 | AB28: =AA28*1100 -> 0 | AC28: 1 | AD28: =AC28*1100 -> 1100 | AE28: 0 | AF28: =AE28*1100 -> 0 | AH28: =SUM(AD28,AB28,Z28,X28,V28,T28,R28,P28,N28,L28,J28,H28,F28,D28) -> 9272
A29: samedi | B29: 45654 | C29: 1 | D29: =C29*1500 -> 1500 | E29: 0.5 | F29: =E29*1112 -> 556 | G29: 1 | H29: =G29*1112 -> 1112 | I29: 1.25 | J29: =I29*1112 -> 1390 | K29: 0 | L29: =K29*1112 -> 0 | M29: 1 | N29: =M29*1112 -> 1112 | O29: 0 | P29: =O29*1112 -> 0 | Q29: 0 | R29: =Q29*1200 -> 0 | S29: 1 | T29: =S29*1112 -> 1112 | U29: 1 | V29: =U29*1112 -> 1112 | W29: 0 | X29: =W29*1200 -> 0 | Y29: 0.75 | Z29: =Y29*1112 -> 834 | AA29: 0 | AB29: =AA29*1100 -> 0 | AC29: 0 | AD29: =AC29*1100 -> 0 | AE29: 1 | AF29: =AE29*1100 -> 1100 | AH29: =SUM(AD29,AB29,Z29,X29,V29,T29,R29,P29,N29,L29,J29,H29,F29,D29) -> 8728
A30: dimanche | B30: 45655 | C30: 1 | D30: =C30*1500 -> 1500 | E30: 1 | F30: =E30*1112 -> 1112 | G30: 1 | H30: =G30*1112 -> 1112 | I30: 1 | J30: =I30*1112 -> 1112 | K30: 0 | L30: =K30*1112 -> 0 | M30: 1 | N30: =M30*1112 -> 1112 | O30: 0 | P30: =O30*1112 -> 0 | Q30: 0 | R30: =Q30*1200 -> 0 | S30: 0 | T30: =S30*1112 -> 0 | U30: 1 | V30: =U30*1112 -> 1112 | W30: 0 | X30: =W30*1200 -> 0 | Y30: 1 | Z30: =Y30*1112 -> 1112 | AA30: 0 | AB30: =AA30*1100 -> 0 | AC30: 1 | AD30: =AC30*1100 -> 1100 | AE30: 0 | AF30: =AE30*1100 -> 0 | AH30: =SUM(AD30,AB30,Z30,X30,V30,T30,R30,P30,N30,L30,J30,H30,F30,D30) -> 9272
A31: lundi | B31: 45656 | C31: 1 | D31: =C31*1500 -> 1500 | E31: 1 | F31: =E31*1112 -> 1112 | G31: 1 | H31: =G31*1112 -> 1112 | I31: 2 | J31: =I31*1112 -> 2224 | K31: 0 | L31: =K31*1112 -> 0 | M31: 0.5 | N31: =M31*1112 -> 556 | O31: 0 | P31: =O31*1112 -> 0 | Q31: 0 | R31: =Q31*1200 -> 0 | S31: 1 | T31: =S31*1112 -> 1112 | U31: 0 | V31: =U31*1112 -> 0 | W31: 0 | X31: =W31*1200 -> 0 | Y31: 1 | Z31: =Y31*1112 -> 1112 | AA31: 0 | AB31: =AA31*1100 -> 0 | AC31: 1 | AD31: =AC31*1100 -> 1100 | AE31: 0 | AF31: =AE31*1100 -> 0 | AH31: =SUM(AD31,AB31,Z31,X31,V31,T31,R31,P31,N31,L31,J31,H31,F31,D31) -> 9828
A32: mardi | B32: 45657 | C32: 2 | D32: =C32*1500 -> 3000 | E32: 1 | F32: =E32*1112 -> 1112 | G32: 1 | H32: =G32*1112 -> 1112 | I32: 1 | J32: =I32*1112 -> 1112 | K32: 0 | L32: =K32*1112 -> 0 | M32: 2 | N32: =M32*1112 -> 2224 | O32: 1.5 | P32: =O32*1112 -> 1668 | Q32: 0 | R32: =Q32*1200 -> 0 | S32: 1.5 | T32: =S32*1112 -> 1668 | U32: 1 | V32: =U32*1112 -> 1112 | W32: 2 | X32: =W32*1200 -> 2400 | Y32: 0 | Z32: =Y32*1112 -> 0 | AA32: 0 | AB32: =AA32*1100 -> 0 | AC32: 1 | AD32: =AC32*1100 -> 1100 | AE32: 1 | AF32: =AE32*1100 -> 1100 | AH32: =SUM(AD32,AB32,Z32,X32,V32,T32,R32,P32,N32,L32,J32,H32,F32,D32) -> 16508
C33: =SUM(C2:C32) -> 7 | E33: =SUM(E2:E32) -> 26.33 | G33: =SUM(G2:G32) -> 25 | I33: =SUM(I2:I32) -> 28.25 | K33: 7 | M33: =SUM(M2:M32) -> 27 | O33: =SUM(O2:O32) -> 12.5 | Q33: =SUM(Q2:Q32) -> 10 | S33: =SUM(S2:S32) -> 29 | U33: =SUM(U2:U32) -> 29.5 | W33: =SUM(W2:W32) -> 20.5 | Y33: =SUM(Y2:Y32) -> 26.25 | AA33: =SUM(AA2:AA32) -> 18.5 | AC33: =SUM(AC2:AC32) -> 24.25 | AE33: =SUM(AE2:AE32) -> 8 | AH33: =SUM(AD33,AB33,Z33,X33,V33,T33,R33,P33,N33,L33,J33,H33,F33,D33) -> 0
C34: 1100 | E34: 1120 | G34: 1120 | I34: 1120 | K34: 1120 | M34: 1200 | O34: 1150 | Q34: 1100 | S34: 1120 | U34: 1120 | W34: 1200 | Y34: 1200 | AA34: 1120 | AC34: 1120 | AE34: 1120 | AH34: =SUM(AD34,AB34,Z34,X34,V34,T34,R34,P34,N34,L34,J34,H34,F34,D34) -> 0
C35: =C34*C33 -> 7700 | E35: =E34*E33 -> 29489.6 | G35: =G34*G33 -> 28000 | I35: =I34*I33 -> 31640 | K35: =K34*K33 -> 7840 | M35: =M34*M33 -> 32400 | O35: =O34*O33 -> 14375 | Q35: =Q34*Q33 -> 11000 | S35: =S34*S33 -> 32480 | U35: =U34*U33 -> 33040 | W35: =W34*W33 -> 24600 | Y35: =Y34*Y33 -> 31500 | AA35: =AA33*AA34 -> 20720 | AC35: =AC34*AC33 -> 27160 | AE35: =AE34*AE33 -> 8960 | AH35: =SUM(AD35,AB35,Z35,X35,V35,T35,R35,P35,N35,L35,J35,H35,F35,D35) -> 0
A36: 0 | D36: =C36*1500 -> 0 | E36: 30000 | F36: =E36*E67 -> 0 | G36: 30000 | I36: 30000 | K36: 30000 | M36: 30000 | O36: 30000 | S36: 30000 | U36: 30000 | X36: =W36*1200 -> 0 | Z36: =Y36*1112 -> 0 | AA36: 30000 | AB36: =AA36*1100 -> 33000000 | AD36: =AC36*1100 -> 0 | AH36: =SUM(AD36,AB36,Z36,X36,V36,T36,R36,P36,N36,L36,J36,H36,F36,D36) -> 33000000

Sheet Les Charges 
D2: Produit | E2: Quantité | F2: Prix unitaire | G2: Prix | H2: Date d'achat
D3: Semoule Moyenne 25kg | E3: 2 | F3: 1000 | G3: =E3*F3 -> 2000
D4: Semoule Fine 25kg | E4: 13 | F4: 1000 | G4: =E4*F4 -> 13000
D5: Levure boulangère | E5: 7 | F5: 390 | G5: =E5*F5 -> 2730
D6: levure chimique | E6: 44 | F6: 6.2 | G6: =E6*F6 -> 272.8
D7: margarine Fleuriel 500g | E7: 36 | F7: 189 | G7: =E7*F7 -> 6804
D8: Harrissa 1kg | E8: 18 | F8: 260 | G8: =E8*F8 -> 4680
D9: Tomate conserve 1kg | E9: 6 | F9: 325 | G9: =E9*F9 -> 1950
D10: huile 5 litre | E10: 20 | F10: 600 | G10: =E10*F10 -> 12000
D11: 3akeri | E11: 0.5 | F11: 1450 | G11: =E11*F11 -> 725
D12: eau minirale 0,5 | E12: 0 | F12: 17 | G12: =E12*F12 -> 0
D13: eau mineral 1,5 litre | E13: 24 | F13: 34 | G13: =E13*F13 -> 816
D14: 7abet halawa | E14: 1 | F14: 1400 | G14: =E14*F14 -> 1400
... D58: Sachets blanc 5kg | E58: 1 | F58: 1100 | G58: =E58*F58 -> 1100
D59: Olives vertes | E59: 2 | F59: 600 | G59: 1200
D60: Olives coupées | E60: 2 | F60: 600 | G60: 1200
D61: Carton d’olives noires | E61: 5 | F61: 400 | G61: 2000
D62: Cheddar | E62: 1.7 | F62: 1850 | G62: =E62*F62 -> 3145
D63: Noix | E63: 1 | F63: 1450 | G63: =E63*F63 -> 1450
D64: Amande blanc | E64: 1 | F64: 1990 | G64: =E64*F64 -> 1990
D65: Coriandre moulu | E65: 0.5 | F65: 1200 | G65: =E65*F65 -> 600
D66: Lait en poudre 1kg | E66: 3 | F66: 500 | G66: =E66*F66 -> 1500
D67: Pate d'arome citron | E67: 0.5 | F67: 780 | G67: =E67*F67 -> 390
D68: Pate d'arome vanille | E68: 0.5 | F68: 950 | G68: =E68*F68 -> 475
D69: sanoudj | E69: 1.5 | F69: 1200 | G69: =E69*F69 -> 1800
D70: Djeldjelan | E70: 1 | F70: 900 | G70: =E70*F70 -> 900
D71: Eau de Fleur d'oranger | E71: 20 | F71: 60 | G71: =E71*F71 -> 1200
D72: Sucre Glace | E72: 10 | F72: 115 | G72: =E72*F72 -> 1150
D73: Sucre cristalisé 25kg | E73: 1 | F73: 2450 | G73: =E73*F73 -> 2450
... D91: Poivre | E91: 2 | F91: 160 | G91: =E91*F91 -> 320
D92: dépense magasin | E92: 1 | F92: 2490 | G92: =E92*F92 -> 2490 | H92: Mois d'octobre
D93: huile 5 litre | E93: 20 | F93: 600 | G93: =E93*F93 -> 12000 | H93: 45629
D94: margarine Fleuriel 500g | E94: 48 | F94: 176 | G94: =E94*F94 -> 8448
D95: miel 5kg | E95: 5 | F95: 795 | G95: =E95*F95 -> 3975
D96: Canette Peps | E96: 12 | F96: 50 | G96: =E96*F96 -> 600
D97: lavette | E97: 1 | F97: 50 | G97: =E97*F97 -> 50
D98: speed Fire | E98: 1 | F98: 850 | G98: =E98*F98 -> 850
D99: isis | E99: 1 | F99: 300 | G99: =E99*F99 -> 300
D100: bingo 1,5kg | E100: 1 | F100: 450 | G100: =E100*F100 -> 450
D101: Crème liquide 1 litre | E101: 12 | F101: 420 | G101: =E101*F101 -> 5040
...

Sheet Salaires
G8: Nom | H8: Salaire | I8: Avance | J8: Salaire à payer
G9: Sofiane | H9: 30000 | I9: 30000 | J9: =H9-I9 -> 0
G10: Amel | H10: 30000 | I10: 30000 | J10: =H10-I10 -> 0
F11: 1 | G11: Wissem | H11: =Pointage!C35 -> 7700 | I11: 8000 | J11: =H11-I11 -> -300
F12: 2 | G12: Yasmine | H12: =K12+Pointage!E35 -> 34489.6 | I12: 34500 | J12: =H12-I12 -> -10.4 | K12: 5000
F13: 3 | G13: Saida | H13: =Pointage!G35 -> 28000 | I13: 28000 | J13: =H13-I13 -> 0
F14: 4 | G14: Ahlem | H14: =Pointage!I35 -> 31640 | I14: 32000 | J14: =H14-I14 -> -360
F15: 5 | G15: Nour ElHouda | H15: =Pointage!K35 -> 7840 | I15: 8000 | J15: =H15-I15 -> -160
F16: 6 | G16: Amina | H16: =Pointage!M35 -> 32400 | J16: =H16-I16 -> 32400
F17: 7 | G17: Selma | H17: =Pointage!O35 -> 14375 | I17: 14500 | J17: =H17-I17 -> -125
F18: 8 | G18: Zohra | H18: =Pointage!Q35 -> 11000 | I18: 11000 | J18: =H18-I18 -> 0
F19: 9 | G19: Rayan | H19: =Pointage!W35 -> 24600 | I19: 25000 | J19: =H19-I19 -> -400
F20: 10 | G20: Ikram | H20: =Pointage!U35 -> 33040 | I20: 33000 | J20: 0 | K20: 6000+2000
F21: 11 | G21: Nora | H21: =Pointage!S35 -> 32480 | I21: 32500 | J21: =H21-I21 -> -20
F22: 12 | G22: Sihem | H22: =Pointage!AA35 -> 20720 | I22: 21000 | J22: =H22-I22 -> -280 | K22: 18000+3000
F23: 13 | G23: Karima | H23: =Pointage!Y35 -> 31500 | I23: 31500 | J23: =H23-I23 -> 0
F24: 14 | G24: Fatiha | H24: =Pointage!AC35 -> 27160 | I24: 28000 | J24: =H24-I24 -> -840 | K24: 4000+1000+2000
F25: 15 | G25: Israa | H25: =Pointage!AE35 -> 8960 | I25: 9000 | J25: =H25-I25 -> -40
G26: TOTAL | H26: =SUM(H9:H25) -> 405904.6 | I26: =SUM(I9:I25) -> 376000 | J26: =H26-I26 -> 29904.6
J27: =H27-I27 -> 0

Sheet Feuille 5
E25: Mois de Janvier | F25: Mois de Février | G25: Mois de Mars | H25: Mois d'Avril | I25: Mois de Mai | J25: Mois de Jiun | K25: Mois de Juillet | L25: Mois d'Aout | M25: Mois de Septembre | N25: Mois d'Octobre | O25: Mois de Novembre | P25: Mois de Décembre | T25: Mois de Décembre
D26: Recette | E26: 1756000 | F26: 2274000 | G26: 1984000 | H26: 1910000 | I26: 1342000 | J26: 1760000 | K26: 2260000 | L26: 1427000 | M26: 1740000 | N26: 1620000 | O26: 1328000 | P26: 2198000 | S26: Recette | T26: 2198000
D27: Charges | E27: 920000 | F27: 914000 | G27: 928000 | H27: 744000 | I27: 646000 | J27: 804000 | K27: 958000 | L27: 640000 | M27: 716000 | N27: 747000 | O27: 645000 | P27: 880000 | S27: Charges | T27: 880000
D28: Salaires | E28: 349000 | F28: 410000 | G28: 406000 | H28: 344000 | I28: 436000 | J28: 396000 | K28: 432000 | L28: 307000 | M28: 514000 | N28: 438000 | O28: 365000 | P28: 406000 | S28: Salaires | T28: 406000
D29: Loyer | E29: 140000 | F29: 140000 | G29: 140000 | H29: 140000 | I29: 140000 | J29: 140000 | K29: 150000 | L29: 150000 | M29: 150000 | N29: 150000 | O29: 150000 | P29: 130000 | S29: Che7i7a | T29: 62000
D30: Profit Net | E30: =E26-E27-E28-E29 -> 347000 | F30: =F26-F27-F28-F29 -> 810000 | G30: =G26-G27-G28-G29 -> 510000 | H30: 680000 | I30: =I26-I27-I28-I29 -> 120000 | J30: 420000 | K30: =K26-K27-K28-K29 -> 720000 | L30: 330000 | M30: =M26-M27-M28-M29 -> 360000 | N30: =N26-N27-N28-N29 -> 285000 | O30: 120000 | P30: 720000 | S30: Loyer | T30: 130000
S31: Profit Net | T31: =T26-T27-T28-T29-T30 -> 720000
