Workbook

Sheet RECAP
B1: Date | C1: Recette Juillet 2024 | D1: Recette | E1: Charges | F1: Salaire | G1: Loyer | H1: Net Profit | I1: Nb de jours | K1: Objectif | L1: Mois de Juin 2024
A2: Dimanche | B2: 45536 | C2: 33000 | D2: 39000 | I2: 1 | L2: 41000
A3: Lundi | B3: 45537 | C3: 60000 | D3: 55000 | I3: 1 | L3: 37000 | M3: Bénéfice Moyen par jour | N3: Moyenne | O3: Moyenne salaire | P3: pourcentage du salaire vis à vis la recettte
A4: Mardi | B4: 45538 | C4: 0 | D4: 78000 | I4: 1 | L4: 47000 | M4: =H33/I33 -> 12005.09 | N4: =D33/I33 -> 58000 | P4: =O4/N4 -> 0
A5: Mercredi | B5: 45539 | C5: 0 | D5: 93000 | I5: 1 | L5: 130000
A6: Jeudi | B6: 45540 | C6: 0 | D6: 40000 | I6: 1 | L6: 40000 | M6: Moyenne des charges par jour | N6: Objectif
A7: Vendredi | B7: 45541 | C7: 0 | D7: 1000 | I7: 1 | L7: 117000 | M7: =E33/I33 -> 23861.577 | N7: 100000
A8: Samedi | B8: 45542 | C8: 4000 | D8: 39000 | I8: 1 | L8: 90000 | M8: ² | R8: "
A9: Dimanche | B9: 45543 | C9: 0 | D9: 32000 | I9: 1 | L9: 60000
A10: Lundi | B10: 45544 | C10: 0 | D10: 33000 | I10: 1 | L10: 50000 | M10: Cash restant | N10: Magasin | O10: Cash réel | P10: Mes dettes pour le magasin
A11: Mardi | B11: 45545 | C11: 35000 | D11: 51000 | I11: 1 | L11: 60000 | M11: =M14+D33-E33-Salaires!J31-N11 -> 827152.7 | N11: 13000 | O11: 699000 | P11: =M11-O11 -> 128152.7
A12: Mercredi | B12: 45546 | C12: 18000 | D12: 76000 | I12: 1 | L12: 67000
A13: Jeudi | B13: 45547 | C13: 21000 | D13: 129000 | I13: 1 | L13: 65000 | M13: Fond de Roulement
A14: Vendredi | B14: 45548 | C14: 23000 | D14: 93000 | I14: 1 | L14: 470000 | M14: 330000
A15: Samedi | B15: 45549 | C15: 20000 | D15: 107000 | I15: 1 | L15: 52000 | Q15: Islem: 27000 D a
A16: Dimanche | B16: 45550 | C16: 40000 | D16: 129000 | I16: 1 | L16: 80000 | P16: Cash réel : 554000Da | Q16: Khalida : 30000Da
A17: Lundi | B17: 45551 | C17: 45000 | D17: 37000 | I17: 1 | L17: 70000 | P17: Cash dans la boite : 34000Da
A18: Mardi | B18: 45552 | C18: 38000 | D18: 54000 | I18: 1 | L18: 60000
A19: Mercredi | B19: 45553 | C19: 37000 | D19: 23000 | I19: 1 | L19: 43000 | M19: Différence mois d'Aout | P19: la vraie caisse:13000Da
A20: Jeudi | B20: 45554 | C20: 32000 | D20: 54000 | I20: 1 | L20: 34000 | M20: =D33-C33 -> 313000
A21: Vendredi | B21: 45555 | C21: 15000 | D21: 50000 | I21: 1 | L21: 100000 | M21: Différence objectif | O21: réparation Tabouna | P21: 1 | Q21: 8800 | R21: =P21*Q21 -> 8800
A22: Samedi | B22: 45556 | C22: 25000 | D22: 46000 | I22: 1 | L22: 28000 | M22: =K36-E36 -> 0 | O22: Torchons | P22: 4 | Q22: 400 | R22: 600
A23: Dimanche | B23: 45557 | C23: 38000 | D23: 43000 | I23: 1 | L23: 74000 | M23: Différence du Totale | O23: poelle | P23: 1 | Q23: 2800 | R23: =P23*Q23 -> 2800
A24: Lundi | B24: 45558 | C24: 146000 | D24: 40000 | I24: 1 | L24: 49000 | M24: =D33-C33 -> 313000 | Q24: Achoire | R24: 1 | S24: 1800 | T24: =R24*S24 -> 1800
A25: Mardi | B25: 45559 | C25: 38000 | D25: 40000 | I25: 1 | L25: 52000 | M25: Les vendredis | O25: Cash chez Sofiane
A26: Mercredi | B26: 45560 | C26: 48000 | D26: 170000 | I26: 1 | L26: 73000 | M26: =D9+D16+D23+D30 -> 243000 | Q26: Les étagères pour locale | R26: 1 | S26: 21000 | T26: =R26*S26 -> 21000
A27: Jeudi | B27: 45561 | C27: 51000 | D27: 73000 | I27: 1 | L27: 24000
A28: Vendredi | B28: 45562 | C28: 39000 | D28: 22000 | I28: 1 | L28: 73000 | M28: Cash réel
A29: Samedi | B29: 45563 | C29: 34000 | D29: 24000 | I29: 1 | L29: 35000 | M29: 51000
A30: Dimanche | B30: 45564 | C30: 462000 | D30: 39000 | I30: 1 | L30: 34000 | M30: rest à payer
A31: Lundi | B31: 45565 | C31: 53000 | D31: 30000 | I31: 1 | L31: 50000
A32: Mardi | B32: 45566 | C32: 72000 | L32: 55000 | P32: =SUM(P26:P31) -> 0
C33: =SUM(C2:C32) -> 1427000 | D33: =SUM(D2:D32) -> 1740000 | E33: ='Les Charges '!G334 -> 715847.3 | F33: =Salaires!J31 -> 514000 | G33: 150000 | H33: =D33-E33-F33-G33 -> 360152.7 | I33: =SUM(I2:I32) -> 30 | L33: =SUM(L2:L32) -> 2260000
M35: =M11-M29-M34 -> 776152.7
D38: -

Sheet Pointage
A1: 0 | B1: 10 | C1: Nadjet | D1: Yasmine | E1: Saida | F1: Israa | G1: Ahlem | H1: Nour ElHouda | I1: Do3aa | J1: Feriel | K1: Wafa | L1: Amina | M1: Selma | N1: Lynda | O1: Zohra | P1: Nora | Q1: Ikram | R1: Sabiha | S1: Ikram Locale | T1: Rayan | U1: Fatima + Insaf | W1: Remarque
A2: Dimanche | B2: 45536 | C2: 1 | D2: 1 | E2: 1 | F2: 1 | G2: 1 | H2: 2 | I2: 3 | J2: 1 | K2: 1 | L2: 1 | M2: 1 | N2: 1 | O2: 0 | P2: 0 | Q2: 0 | R2: 0 | S2: 0 | T2: 0 | U2: 0
A3: Lundi | B3: 45537 | C3: 1 | D3: 1 | E3: 1 | F3: 1 | G3: 1 | H3: 1 | I3: 1 | J3: 1 | K3: 0 | L3: 0 | M3: 1 | N3: 1 | O3: 1 | P3: 0 | Q3: 0 | R3: 0 | S3: 0 | T3: 0 | U3: 0
A4: Mardi | B4: 45538 | C4: 1 | D4: 1 | E4: 1 | F4: 1 | G4: 1 | H4: 1 | I4: 1 | J4: 1 | K4: 1 | L4: 1 | M4: 1 | N4: 1 | O4: 0 | P4: 0 | Q4: 0 | R4: 0 | S4: 0 | T4: 0 | U4: 0
A5: Mercredi | B5: 45539 | C5: 1 | D5: 1 | E5: 1 | F5: 1 | G5: 1 | H5: 1.2 | I5: 1.2 | J5: 1 | K5: 1.2 | L5: 1.2 | M5: 0 | N5: 1 | O5: 1 | P5: 0 | Q5: 0 | R5: 0 | S5: 0 | T5: 0 | U5: 0
A6: Jeudi | B6: 45540 | C6: 1 | D6: 1 | E6: 1 | F6: 1 | G6: 1 | H6: 1 | I6: 1 | J6: 1 | K6: 1.2 | L6: 1.2 | M6: 0 | N6: 1 | O6: 0 | P6: 0 | Q6: 0 | R6: 0 | S6: 0 | T6: 0 | U6: 0
A7: Vendredi | B7: 45541 | C7: 0 | D7: 0 | E7: 0 | F7: 0 | G7: 0 | H7: 0 | I7: 0 | J7: 0 | K7: 0 | L7: 0 | M7: 0 | N7: 0 | O7: 1 | P7: 0 | Q7: 0 | R7: 0 | S7: 0 | T7: 0 | U7: 0
A8: Samedi | B8: 45542 | C8: 0 | D8: 1 | E8: 1 | F8: 1 | G8: 1 | H8: 1 | I8: 1 | J8: 1 | K8: 1.2 | L8: 1.2 | M8: 0 | N8: 0 | O8: 0 | P8: 0 | Q8: 0 | R8: 0 | S8: 0 | T8: 0 | U8: 0
A9: Dimanche | B9: 45543 | C9: 1 | D9: 1 | E9: 0.5 | F9: 0.5 | G9: 1 | H9: 1 | I9: 1 | J9: 0 | K9: 1 | L9: 1 | M9: 0 | N9: 0 | O9: 0 | P9: 1 | Q9: 1 | R9: 0 | S9: 0 | T9: 0 | U9: 0
A10: Lundi | B10: 45544 | C10: 1 | D10: 1 | E10: 1 | F10: 1 | G10: 1 | H10: 1 | I10: 1 | J10: 1 | K10: 1 | L10: 1 | M10: 0 | N10: 1 | O10: 0 | P10: 1 | Q10: 1 | R10: 0 | S10: 0 | T10: 0 | U10: 0
A11: Mardi | B11: 45545 | C11: 0.5 | D11: 0 | E11: 1 | F11: 1 | G11: 1 | H11: 1.2 | I11: 1 | J11: 1 | K11: 1 | L11: 1 | M11: 0 | N11: 1 | O11: 0 | P11: 1 | Q11: 1 | R11: 0 | S11: 0 | T11: 0 | U11: 0
A12: Mercredi | B12: 45546 | C12: 1 | D12: 1 | E12: 1 | F12: 1 | G12: 1 | H12: 1 | I12: 1 | J12: 1 | K12: 0 | L12: 1.1 | M12: 0 | N12: 1 | O12: 1 | P12: 1.2 | Q12: 1.2 | R12: 0 | S12: 0 | T12: 0 | U12: 0
A13: Jeudi | B13: 45547 | C13: 1.5 | D13: 1.2 | E13: 1.5 | F13: 1.5 | G13: 1 | H13: 1.5 | I13: 1.5 | J13: 1.2 | K13: 1.5 | L13: 1.5 | M13: 1.2 | N13: 1.5 | O13: 0 | P13: 1.5 | Q13: 1.5 | R13: 0 | S13: 0 | T13: 0 | U13: 0
... A17: Lundi | B17: 45551 | C17: 0 | D17: 0 | E17: 0 | F17: 0 | G17: 1.5 | H17: 1.2 | I17: 1.2 | J17: 0 | K17: 0 | L17: 0 | M17: 1 | N17: 1 | O17: 0 | P17: 0 | Q17: 0 | R17: 1 | S17: 0 | T17: 0 | U17: 0
A18: Mardi | B18: 45552 | C18: 0 | D18: 0 | E18: 1 | F18: 1 | G18: 1 | H18: 1.2 | I18: 1 | J18: 1.1 | K18: 1.1 | L18: 1.1 | M18: 1.1 | N18: 1 | O18: 1 | P18: 1 | Q18: 1 | R18: 1 | S18: 0 | T18: 0 | U18: 0 | W18: Wafa Amina Selma et Feriel 17h15 Houda vendeuse
A19: Mercredi | B19: 45553 | C19: 0 | D19: 1 | E19: 1 | F19: 1 | G19: 1 | H19: 0 | I19: 0 | J19: 1 | K19: 1 | L19: 1 | M19: 1.1 | N19: 1 | O19: 0 | P19: 1 | Q19: 1 | R19: 1 | S19: 0 | T19: 0 | U19: 0
A20: Jeudi | B20: 45554 | C20: 0 | D20: 1 | E20: 1 | F20: 1 | G20: 1 | H20: 1 | I20: 1 | J20: 1 | K20: 1 | L20: 1 | M20: 0 | N20: 0 | O20: 1 | P20: 1 | Q20: 1 | R20: 1 | S20: 0 | T20: 0 | U20: 0
A21: Vendredi | B21: 45555 | C21: 0 | D21: 1 | E21: 0 | F21: 0 | G21: 0 | H21: 0 | I21: 1 | J21: 0 | K21: 1 | L21: 1 | M21: 0 | N21: 0 | O21: 0 | P21: 1 | Q21: 1 | R21: 0 | S21: 0 | T21: 0 | U21: 0
A22: Samedi | B22: 45556 | C22: 0 | D22: 1 | E22: 1 | F22: 1 | G22: 1 | H22: 1 | I22: 1 | J22: 1 | K22: 1.05 | L22: 1.05 | M22: 1.05 | N22: 0 | O22: 0 | P22: 1 | Q22: 1 | R22: 1 | T22: 0 | U22: 0
A23: Dimanche | B23: 45557 | C23: 0 | D23: 0.5 | E23: 1 | F23: 1 | G23: 1 | H23: 1.5 | I23: 1.2 | J23: 0 | K23: 1 | L23: 1 | M23: 1 | N23: 0 | O23: 0 | P23: 1 | Q23: 1 | R23: 1 | S23: 1 | T23: 0 | U23: 0
A24: Lundi | B24: 45558 | C24: 0 | D24: 1 | E24: 1 | F24: 1 | G24: 1 | H24: 1 | I24: 1 | J24: 0 | K24: 1 | L24: 1 | M24: 1.2 | N24: 0 | O24: 0 | P24: 1 | Q24: 1 | R24: 1 | S24: 1 | T24: 1 | U24: 0
A25: Mardi | B25: 45559 | C25: 0 | D25: 1 | E25: 1 | F25: 1 | G25: 1 | H25: 1 | I25: 1 | J25: 0 | K25: 1 | L25: 1 | M25: 1.2 | N25: 0 | O25: 1 | P25: 1 | Q25: 1 | R25: 1 | S25: 0 | T25: 1 | U25: 0
A26: Mercredi | B26: 45560 | C26: 0 | D26: 1 | E26: 1 | F26: 1 | G26: 1 | H26: 0 | I26: 0 | J26: 0 | K26: 1.2 | L26: 1.2 | M26: 1.3 | N26: 0 | O26: 0 | P26: 1 | Q26: 1 | R26: 1 | S26: 0 | T26: 1.2 | U26: 0
A27: Jeudi | B27: 45561 | C27: 0 | D27: 1 | E27: 1 | F27: 1 | G27: 1 | H27: 1 | I27: 1 | J27: 0 | K27: 1.1 | L27: 1.1 | M27: 1.2 | N27: 0 | O27: 1 | P27: 1 | Q27: 1 | R27: 1 | S27: 0 | T27: 1.3 | U27: 0
A28: Vendredi | B28: 45562 | C28: 0 | D28: 1 | E28: 0 | F28: 0 | G28: 0 | H28: 1 | I28: 1 | J28: 0 | K28: 0 | L28: 0 | M28: 0 | N28: 0 | O28: 0 | P28: 1 | Q28: 1 | R28: 0 | S28: 0 | T28: 0 | U28: 0
A29: Samedi | B29: 45563 | C29: 0 | D29: 1 | E29: 1 | F29: 1 | G29: 1 | H29: 0 | I29: 0 | J29: 0 | K29: 1 | L29: 1 | M29: 1.2 | N29: 0 | O29: 0 | P29: 1 | Q29: 1 | R29: 1 | S29: 0 | T29: 1 | U29: 0
A30: Dimanche | B30: 45564 | C30: 0 | D30: 1 | E30: 1 | F30: 1 | G30: 1 | H30: 1 | I30: 1 | J30: 0 | K30: 1 | L30: 1 | M30: 1.2 | N30: 0 | O30: 0 | P30: 1 | Q30: 1 | R30: 1 | S30: 0 | T30: 1 | U30: 0
A31: Lundi | B31: 45565 | C31: 0 | D31: 1 | E31: 1 | F31: 1 | G31: 1 | H31: 1 | I31: 1 | J31: 0 | K31: 1 | L31: 1 | M31: 1.2 | N31: 0 | O31: 1 | P31: 1 | Q31: 1 | R31: 1 | S31: 0 | T31: 0 | U31: 0
A32: Mardi | B32: 45566 | S32: 0 | U32: 7
C33: =SUM(C2:C32) -> 15 | D33: =SUM(D2:D32) -> 27.4 | E33: =SUM(E2:E32) -> 26.5 | F33: =SUM(F2:F32) -> 26.5 | G33: =SUM(G2:G32) -> 26.7 | H33: =SUM(H2:H32) -> 29.8 | I33: =SUM(I2:I32) -> 31.1 | J33: =SUM(J2:J32) -> 16.5 | ... V33: =SUM(V2:V32) -> 0
C34: 1500 | D34: 1154 | E34: 1154 | F34: 1154 | G34: 1154 | H34: 1154 | I34: 1154 | J34: 1347 | K34: 1154 | L34: 1154 | M34: 1154 | N34: 1154 | O34: 1200 | P34: 1154 | Q34: 1154 | R34: 1154 | S34: 1000 | T34: 1200 | U34: 1000
C35: =C34*C33 -> 22500 | D35: =D34*D33 -> 31619.6 | E35: =E34*E33 -> 30581 | F35: =F34*F33 -> 30581 | G35: =G34*G33 -> 30811.8 | H35: =H34*H33 -> 34389.2 | I35: =I34*I33 -> 35889.4 | J35: =J34*J33 -> 22225.5 | ... V35: =V34*V33 -> 0
D36: 30000 | E36: 30000 | F36: 30000 | G36: 30000 | H36: 30000 | I36: 30000 | J36: 35000 | K36: 30000 | L36: 30000 | M36: 30000 | N36: 30000 | P36: 30000 | Q36: 30000 | R36: 30000
Q386: Selma
O387: Dimanche | P387: 45536 | Q387: 1
O388: Lundi | P388: 45537 | Q388: 1
O389: Mardi | P389: 45538 | Q389: 1
O390: Mercredi | P390: 45539 | Q390: 0
O391: Jeudi | P391: 45540 | Q391: 0
O392: Vendredi | P392: 45541 | Q392: 0
...

Sheet Les Charges 
C1: Produit | E1: Quantité | F1: Prix unitaire | G1: Prix | H1: Date d'achat
C2: Levure Chimique | E2: 210 | F2: 6.5 | H2: Aout
C3: Semoule Fine 25kg | E3: 13 | F3: 1000 | G3: =E3*F3 -> 13000
C4: Semoule Fine 10kg | E4: 14 | F4: 370 | G4: =E4*F4 -> 5180
C5: farine sousimie 10kg | E5: 7 | F5: 580 | G5: =E5*F5 -> 4060
C6: Levure Boulongère 500g | E6: 7 | F6: 780 | G6: =E6*F6 -> 5460
C7: Khel | E7: 5 | F7: 85 | G7: =E7*F7 -> 425
C8: Maiis | E8: 2 | F8: 250 | G8: =E8*F8 -> 500
C9: Curdents | E9: 4 | F9: 120 | G9: =E9*F9 -> 480
C10: Sel | E10: 10 | F10: 25 | G10: =E10*F10 -> 250
C11: 3akeri | E11: 1 | F11: 1100 | G11: =E11*F11 -> 1100
C12: Djeldjelan | E12: 1 | F12: 900 | G12: =E12*F12 -> 900
C13: eau minirale 50 cl | E13: 240 | F13: 17 | G13: =E13*F13 -> 4080
C14: eau minirale 1,5 litres | E14: 60 | F14: 30 | G14: =E14*F14 -> 1800
... C22: chocolat wedjdane Blanc | E22: 3 | F22: 230 | G22: =E22*F22 -> 690
C23: Margarine Fleurial 500g | E23: 92 | F23: 190 | G23: =E23*F23 -> 17480 | H23: Aout + 03 septembre
C24: Huile elio 5 litres | E24: 10 | F24: 600 | G24: =E24*F24 -> 6000
C25: Semen Madina 1,8kg | E25: 4 | F25: 800 | G25: =E25*F25 -> 3200
C26: Maiizina | E26: 5 | F26: 180 | G26: =E26*F26 -> 900
C27: Thon 2kg | E27: 1 | F27: 1900 | G27: =E27*F27 -> 1900
C28: Amande blanc | E28: 10 | F28: 1670 | G28: =E28*F28 -> 16700
C29: Raisins sec | E29: 0.5 | F29: 1100 | G29: =E29*F29 -> 550
C30: canette Hamoud + shwepess | E30: 30 | F30: 80 | G30: =E30*F30 -> 2400
C31: canette IZEM | E31: 7 | F31: 100 | G31: =E31*F31 -> 700
C32: Canette Coca | E32: 10 | F32: 80 | G32: =E32*F32 -> 800
C33: Bouteille Hamoud | E33: 6 | F33: 50 | G33: =E33*F33 -> 300
C34: semoule Moula moyenne 2kg | E34: 2 | F34: 280 | G34: =E34*F34 -> 560
C35: cheddar | E35: 1 | F35: 1850 | G35: =E35*F35 -> 1850
... C51: tofia caramel | E51: 1 | F51: 2000 | G51: =E51*F51 -> 2000
C52: force express | E52: 1 | F52: 360 | G52: 360
C53: olive noir | E53: 0.5 | F53: 400 | G53: =E53*F53 -> 200
C54: olive éffilet | E54: 0.5 | F54: 800 | G54: =E54*F54 -> 400
C55: olive dényauté | E55: 0.5 | F55: 600 | G55: =E55*F55 -> 300
C56: mélange d'olive | E56: 1 | F56: 200 | G56: =E56*F56 -> 200
C57: Fromage spéciale pizza | E57: 4 | F57: 200 | G57: =E57*F57 -> 800
C58: Fromage blanc | E58: 1 | F58: 420 | G58: =E58*F58 -> 420
C59: lave sol | E59: 1 | F59: 175 | G59: =E59*F59 -> 175
C60: bingo | E60: 2 | F60: 500 | G60: =E60*F60 -> 1000
C61: isis 5 litres | E61: 2 | F61: 790 | G61: =E61*F61 -> 1580
C62: Confiture | E62: 6 | F62: 280 | G62: =E62*F62 -> 1680
...

Sheet Salaires
H7: Nom | I7: Salaire | J7: Avance | K7: Salaire à payer
H8: Sofiane | I8: 30000 | J8: 30000 | K8: =I8-J8 -> 0
H9: Amel | I9: 30000 | J9: 30000 | K9: =I9-J9 -> 0
G10: 1 | H10: Nadjet | I10: =Pointage!C35 -> 22500 | J10: 22500 | K10: =I10-J10 -> 0
G11: 2 | H11: Yasmine | I11: =L11+Pointage!D35 -> 36619.6 | J11: 37000 | K11: =I11-J11 -> -380.4 | L11: 5000
G12: 3 | H12: Saida | I12: =Pointage!E35 -> 30581 | J12: 31000 | K12: =I12-J12 -> -419
G13: 4 | H13: Israa | I13: =Pointage!F35 -> 30581 | J13: 31000 | K13: =I13-J13 -> -419
G14: 5 | H14: Ahlem | I14: =Pointage!G35 -> 30811.8 | J14: 31000 | K14: =I14-J14 -> -188.2
G15: 6 | H15: Nour ElHouda | I15: =Pointage!H35 -> 34389.2 | J15: 34500 | K15: =I15-J15 -> -110.8
G16: 7 | H16: Do3aa | I16: =Pointage!I35 -> 35889.4 | J16: 36000 | K16: =I16-J16 -> -110.6
G17: 8 | H17: Feriel | I17: =Pointage!J35 -> 22225.5 | J17: 22500 | K17: =I17-J17 -> -274.5
G18: 9 | H18: Wafa | I18: =Pointage!K35 -> 30869.5 | J18: 31000 | K18: =I18-J18 -> -130.5
G19: 10 | H19: Amina | I19: =Pointage!L35 -> 32138.9 | J19: 32500 | K19: =I19-J19 -> -361.1
G20: 11 | H20: Selma | I20: =Pointage!M35 -> 23253.1 | J20: 23500 | K20: =I20-J20 -> -246.9 | L20: 4000+1000
G21: 12 | H21: Lynda | I21: =Pointage!N35 -> 16963.8 | J21: 17000 | K21: =I21-J21 -> -36.2 | L21: 45545 | M21: 45554 | Q21: 8000+9000+
G22: 13 | H22: Zohra | I22: =Pointage!O35 -> 12000 | J22: 12000 | K22: =I22-J22 -> 0
G23: 14 | H23: Sabiha | I23: =Pointage!R35 -> 18464 | J23: 18500 | K23: =I23-J23 -> -36
G24: 15 | H24: Ikram Local | I24: =Pointage!S35 -> 2000 | J24: 2000 | K24: =I24-J24 -> 0
G25: 16 | H25: Rayan | I25: =Pointage!T35 -> 7800 | J25: 8000 | K25: =I25-J25 -> -200
G26: 17 | H26: Insaf+ Fatima | I26: =Pointage!U35 -> 7000 | J26: 7000 | K26: =I26-J26 -> 0
G27: 18 | H27: Ikram | I27: =Pointage!Q35 -> 28503.8 | J27: 28500 | K27: =I27-J27 -> 3.8
G28: 19 | H28: Nora | I28: =Pointage!P35 -> 28503.8 | J28: 28500 | K28: =I28-J28 -> 3.8
H31: TOTAL | I31: =SUM(I8:I30) -> 511094.4 | J31: =SUM(J8:J30) -> 514000 | K31: =I31-J31 -> -2905.6
K32: =I32-J32 -> 0

Sheet Feuille 5
D18: Mois de Janvier | E18: Mois de Février | F18: Mois de Mars | G18: Mois d'Avril | H18: Mois de Mai | I18: Mois de Jiun | J18: Mois de Juillet | K18: Mois d'Aout | L18: Mois de Septembre | O18: Mois de Septembre
C19: Recette | D19: 1756000 | E19: 2274000 | F19: 1984000 | G19: 1910000 | H19: 1342000 | I19: 1760000 | J19: 2260000 | K19: 1427000 | L19: 1740000 | N19: Recette | O19: 1740000
C20: Charges | D20: 920000 | E20: 914000 | F20: 928000 | G20: 744000 | H20: 646000 | I20: 804000 | J20: 958000 | K20: 640000 | L20: 716000 | N20: Charges | O20: 716000
C21: Salaires | D21: 349000 | E21: 410000 | F21: 406000 | G21: 344000 | H21: 436000 | I21: 396000 | J21: 432000 | K21: 307000 | L21: 514000 | N21: Salaires | O21: 514000
C22: Loyer | D22: 140000 | E22: 140000 | F22: 140000 | G22: 140000 | H22: 140000 | I22: 140000 | J22: 150000 | K22: 150000 | L22: 150000 | N22: Loyer | O22: 150000
C23: Profit Net | D23: =D19-D20-D21-D22 -> 347000 | E23: =E19-E20-E21-E22 -> 810000 | F23: =F19-F20-F21-F22 -> 510000 | G23: 680000 | H23: =H19-H20-H21-H22 -> 120000 | I23: 420000 | J23: =J19-J20-J21-J22 -> 720000 | K23: 330000 | L23: =L19-L20-L21-L22 -> 360000 | N23: Profit Net | O23: 360000

Sheet Feuille 6
