Workbook

Sheet RECAP
A1: 87000 | B1: Date | C1: Recette de juin | D1: Recette | E1: Charges | F1: Salaire | G1: Loyer | H1: Net Profit | I1: Nb de jours | J1: Objectif | K1: Juin | N1: Moyenne
A2: Jeudi | B2: 44378 | C2: 27000 | D2: 47000 | I2: 1 | J2: 50000 | K2: 27000 | N2: =D33/I33 -> 41838.71
A3: Vendredi | B3: 44379 | C3: 18000 | D3: 50000 | I3: 1 | J3: 50000 | K3: 18000
A4: Samedi | B4: 44380 | C4: 36000 | D4: 24000 | I4: 1 | J4: 50000 | K4: 36000 | N4: 50000
A5: Dimanche | B5: 44381 | C5: 28000 | D5: 40000 | I5: 1 | J5: 50000 | K5: 28000
A6: Lundi | B6: 44382 | C6: 34000 | D6: 31000 | I6: 1 | J6: 50000 | K6: 34000
A7: Mardi | B7: 44383 | C7: 37000 | D7: 33000 | I7: 1 | J7: 50000 | K7: 37000
A8: Mercredi | B8: 44384 | C8: 28000 | D8: 44000 | I8: 1 | J8: 50000 | K8: 28000
A9: Jeudi | B9: 44385 | C9: 31000 | D9: 77000 | I9: 1 | J9: 50000 | K9: 31000 | Q9: Différence mois d'Avril
A10: Vendredi | B10: 44386 | C10: 42000 | D10: 52000 | I10: 1 | J10: 50000 | K10: 42000 | Q10: =D33-C33 -> 337000
A11: Samedi | B11: 44387 | C11: 57000 | D11: 87000 | I11: 1 | J11: 50000 | K11: 57000 | M11: Cash restant | N11: Magasin | Q11: Différence objectif
A12: Dimanche | B12: 44388 | C12: 30000 | D12: 36000 | I12: 1 | J12: 50000 | K12: 30000 | M12: =D33+Charges!H362-N12-Charges!H361-Charges!H382-Salaires!K25 -> 516255 | N12: 10000 | Q12: =D33-J33 -> -253000
A13: Lundi | B13: 44389 | C13: 41000 | D13: 22000 | I13: 1 | J13: 50000 | K13: 41000
A14: Mardi | B14: 44390 | C14: 15000 | D14: 40000 | I14: 1 | J14: 50000 | K14: 15000
A15: Mercredi | B15: 44391 | C15: 42000 | D15: 33000 | I15: 1 | J15: 50000 | K15: 42000 | M15: 14000 | N15: Accentis 07/07/2021
A16: Jeudi | B16: 44392 | C16: 32000 | D16: 36000 | I16: 1 | J16: 50000 | K16: 32000 | L16: 1500 | M16: 14000 | N16: Accentis 08/07/2021
A17: Vendredi | B17: 44393 | C17: 24000 | D17: 45000 | I17: 1 | J17: 50000 | K17: 24000 | L17: 1500 | M17: 14000 | N17: Accentis 09/07/2021
A18: Samedi | B18: 44394 | C18: 45000 | D18: 47000 | I18: 1 | J18: 50000 | K18: 45000 | L18: 1500 | M18: 14000 | N18: Accentis 10/07/2021
A19: Dimanche | B19: 44395 | C19: 41000 | D19: 55000 | I19: 1 | J19: 50000 | K19: 41000
A20: Lundi | B20: 44396 | C20: 39000 | D20: 129000 | I20: 1 | J20: 50000 | K20: 39000 | M20: =SUM(M15:M19) -> 56000
A21: Mardi | B21: 44397 | C21: 28000 | D21: 0 | I21: 1 | J21: 50000 | K21: 28000
A22: Mercredi | B22: 44398 | C22: 20000 | D22: 0 | I22: 1 | J22: 50000 | K22: 20000
A23: Jeudi | B23: 44399 | C23: 21000 | D23: 27000 | I23: 1 | J23: 50000 | K23: 21000
A24: Vendredi | B24: 44400 | C24: 25000 | D24: 32000 | I24: 1 | J24: 50000 | K24: 25000 | P24: cash supposé | Q24: =M12-M20 -> 460255
A25: Samedi | B25: 44401 | C25: 30000 | D25: 26000 | I25: 1 | J25: 50000 | K25: 30000 | P25: loyer | Q25: 300000
A26: Dimanche | B26: 44402 | C26: 32000 | D26: 21000 | I26: 1 | J26: 50000 | K26: 32000 | P26: cash réel | Q26: 383000
A27: Lundi | B27: 44403 | C27: 29000 | D27: 42000 | I27: 1 | J27: 50000 | K27: 29000 | P27: Sofiane | Q27: 50000 | R27: 40000+10000
A28: Mardi | B28: 44404 | C28: 47000 | D28: 40000 | I28: 1 | J28: 50000 | K28: 47000 | Q28: =Q24+Q25-Q26-Q27 -> 327255
A29: Mercredi | B29: 44405 | C29: 26000 | D29: 45000 | I29: 1 | J29: 50000 | K29: 26000 | L29: .
A30: Jeudi | B30: 44406 | C30: 31000 | D30: 58000 | I30: 1 | J30: 50000 | K30: 31000
A31: Vendredi | B31: 44407 | C31: 24000 | D31: 34000 | I31: 1 | J31: 50000 | K31: 24000
A32: Samedi | B32: 44408 | C32: 0 | D32: 44000 | I32: 1 | J32: 50000 | K32: 0
C33: =SUM(C2:C32) -> 960000 | D33: =SUM(D2:D32) -> 1297000 | E33: =Charges!H361*1 -> 504845 | F33: =Pointage!P35*1 -> 221758 | G33: 50000 | H33: =D33+Charges!H362-G33-F33-E33 -> 540397 | I33: =SUM(I2:I32) -> 31 | J33: =SUM(J2:J32) -> 1550000 | K33: =SUM(K2:K32) -> 960000
C35: Objectif | D35: 1365000 | E35: 500000 | F35: 280000 | G35: 50000 | H35: 600000
C36: Mois de juin | D36: 960000 | E36: 485000 | F36: 305000 | G36: 50000 | H36: 140000

Sheet Charges
E4: Produit | F4: Quantité | G4: Prix unitaire | H4: Prix | I4: Date d'achat
E5: eau miniral grande bouteille | F5: 10 fardeaux | G5: 150 | H5: 1500 | I5: 44378
E6: eau miniral petite bouteille | F6: 6 fardeaux | G6: 160 | H6: 960
E7: Rouiba 20cl | F7: 1 | G7: 520 | H7: 520
E8: Coca canette | F8: 1 | G8: 1450 | H8: 1450
E9: Rouiba 33cl | F9: 2 | G9: 430 | H9: 860
E10: Hamoud 33cl | F10: 4 | G10: 380 | H10: 1520
E11: Coca 33cl | F11: 1 | G11: 510 | H11: 510
E12: Pepsi | F12: 1 | G12: 400 | H12: 400
E13: Ifruit 33 cl | F13: 2 | G13: 480 | H13: 960
E14: semoule fine 25 kg | F14: 4 | G14: 1450 | H14: 5800 | I14: 44378
E15: margarine 500g | F15: 3 | G15: 2130 | H15: 6390 | I15: 44378
E16: margarine 250 g | F16: 2 | G16: 2600 | H16: 5200
E17: Boites 36/07 | F17: 2 | G17: 1050 | H17: 2100 | I17: 44378
E18: alumnium | F18: 1 | G18: 1450 | H18: 1450
E19: Sorbet | F19: 1 | G19: 900 | H19: 900
E20: barquette 1185 | F20: 1 | G20: 3300 | H20: 3300
E21: chedar | F21: 3.40kg | G21: 1350 | H21: 4550
E22: Fromage bidon | F22: 3 | G22: 600 | H22: 1800
E23: levure de bièrre | F23: 1 | G23: 5600 | H23: 5600
E24: sachet de transparent | F24: 1 | G24: 1200 | H24: 1200
E25: 3o9ach | F25: 2 | G25: 150 | H25: 300
F26: 1 | H26: 250
E27: fromage spéciale pizza | F27: 11.5kg | G27: 230 | H27: 2650 | I27: 44378
E28: Farine Sim 5kg | F28: 10 | G28: 190 | H28: 1900
E29: boite GM | F29: 1 fardeau | G29: 1600 | H29: 1600
E30: Boite PM | F30: 1 fardeau | G30: 1300 | H30: 1300
E31: démarcheur | F31: 1 | G31: 1200 | H31: 1200 | I31: 44378
E32: Huile 5 litres Elio la concorde | F32: 34 | G32: 590 | H32: 20060
E33: Huile 5 litres Elio | F33: 6 | G33: 590 | H33: 3540 | I33: 44378
E34: Semoule fine Boumsail 25kg | F34: 4 | G34: 1100 | H34: 4400 | I34: 44378
E35: semoule fine Sim 25kg | F35: 4 | G35: 1100 | H35: 4400 | I35: 44378
E36: semoule sim moyenne 2kg | F36: 12 | G36: 200 | H36: 2400 | I36: 44378
E37: Semoule fine Mama + Amor Ben Amor | F37: 4 | G37: 1400 | H37: 5600 | I37: 44378
E38: maa zehar | F38: 1 | G38: 720 | H38: 720 | I38: 44378
E39: miel | F39: 4 | G39: 590 | H39: 2360 | I39: 44378
E40: sucre glace | F40: 1 fardeau | G40: 1140 | H40: 1140 | I40: 44378
E41: semen Madina 1.8kg | F41: 6 | G41: 520 | H41: 3120 | I41: 44378
E42: eau miniral 5 litre s | F42: 12 | G42: 175 | H42: 1020 | I42: 44378
E43: épices chawarma et poulet roti | F43: 1kg | G43: 1200 | H43: 1200 | I43: 44378
...

Sheet Pointage
B1: Date | C1: Zehor | D1: Yossera | E1: Soumia | F1: Nadjet | G1: Hadjer | H1: Amel | I1: Hafida | J1: Fatiha | K1: Safia | L1: Samira | M1: Dalila | N1: Linda | O1: Zahida | P1: Remarque
A2: Jeudi | B2: 44378 | C2: 1 | D2: 1 | E2: 0 | F2: 1 | G2: 0 | H2: 1 | I2: 1 | J2: 0 | K2: 0 | L2: 1 | M2: 1 | N2: 1 | O2: 1
A3: Vendredi | B3: 44379 | C3: 1 | D3: 1 | E3: 0 | F3: 0 | G3: 1 | H3: 0 | I3: 1 | J3: 1 | K3: 0 | L3: 0 | M3: 0 | N3: 1 | O3: 1
A4: Samedi | B4: 44380 | C4: 0 | D4: 1 | E4: 0 | F4: 0 | G4: 0 | H4: 1 | I4: 0 | J4: 1 | K4: 0 | L4: 1 | M4: 1 | N4: 1 | O4: 1 | P4: elyoum makach khadema kharedjou bekeri
A5: Dimanche | B5: 44381 | C5: 1 | D5: 1 | E5: 0 | F5: 1 | G5: 0 | H5: 1 | I5: 1 | J5: 0 | K5: 0 | L5: 1 | M5: 0 | N5: 1 | O5: 0 | P5: zahida n'est pas venue 3anedha djanaza de la maman de son amie
A6: Lundi | B6: 44382 | C6: 1 | D6: 1 | E6: 0 | F6: 1 | G6: 0 | H6: 1 | I6: 1 | J6: 0 | K6: 0 | L6: 1 | M6: 0 | N6: 0.5 | O6: 1 | P6: Lynda est tombé malade et elle est sortie à 12h
A7: Mardi | B7: 44383 | C7: 1 | D7: 0 | E7: 0 | F7: 1 | G7: 0 | H7: 1 | I7: 1 | J7: 0 | K7: 0 | L7: 1 | M7: 0 | N7: 0 | O7: 0 | P7: Hafida a laissé 8 boules sans couverture et Amel a laissé 500g de poulet haché au refrigirateur
A8: Mercredi | B8: 44384 | C8: 1 | D8: 1 | E8: 0 | F8: 0 | G8: 0 | H8: 1 | I8: 1 | J8: 0 | K8: 0 | L8: 1 | M8: 0 | N8: 1 | O8: 1
A9: Jeudi | B9: 44385 | C9: 1 | D9: 1 | E9: 1 | F9: 1 | G9: 0 | H9: 1 | I9: 1 | J9: 1 | K9: 0 | L9: 1 | M9: 0 | N9: 0 | O9: 0 | P9: zahida nest pas venu 3anedeha djanaza et linda est malade
A10: Vendredi | B10: 44386 | C10: 1 | D10: 0 | E10: 1 | F10: 0 | G10: 0 | H10: 2 | I10: 1 | J10: 1 | K10: 0 | L10: 1 | M10: 0 | N10: 0 | O10: 0 | P10: zahida nest pas venu 3anedeha djanaza de sa belle soeur
A11: Samedi | B11: 44387 | C11: 1 | D11: 0 | E11: 1 | F11: 1 | G11: 0 | H11: 1 | I11: 0 | J11: 1 | K11: 0 | L11: 1 | M11: 0 | N11: 0 | O11: 1
A12: Dimanche | B12: 44388 | C12: 1 | D12: 0 | E12: 1 | F12: 1 | G12: 0 | H12: 1 | I12: 1 | J12: 0 | K12: 0 | L12: 1 | M12: 0 | N12: 0 | O12: 1
A13: Lundi | B13: 44389 | C13: 0 | D13: 0 | E13: 1 | F13: 1 | G13: 0 | H13: 1 | I13: 1 | J13: 0 | K13: 0 | L13: 1 | M13: 0 | N13: 0 | O13: 1 | P13: zahida est sortie à 17h à cause du teste covide 19
A14: Mardi | B14: 44390 | C14: 1 | D14: 0 | E14: 1 | F14: 1 | G14: 0 | H14: 1 | I14: 1 | J14: 0 | K14: 0 | L14: 1 | M14: 0 | N14: 0 | O14: 1 | P14: Amel khalate 5kg de poulet yefou7ou
A15: Mercredi | B15: 44391 | C15: 1 | D15: 0 | E15: 1 | F15: 1 | G15: 0 | H15: 0 | I15: 1 | J15: 0 | K15: 0 | L15: 1 | M15: 0 | N15: 0 | O15: 0 | P15: samira djate à 13h, zahida n'est pas venu kan 3anedeha cheghoul avec son père après ra7et la plage
A16: Jeudi | B16: 44392 | C16: 1 | D16: 0 | E16: 0.5 | F16: 1 | G16: 0 | H16: 1 | I16: 1 | J16: 0 | K16: 0 | L16: 1 | M16: 0 | N16: 0 | O16: 1
A17: Vendredi | B17: 44393 | C17: 1 | D17: 1.75 | E17: 0 | F17: 0 | G17: 0 | H17: 0 | I17: 1 | J17: 1 | K17: 0 | L17: 1 | M17: 0 | N17: 0 | O17: 1
A18: Samedi | B18: 44394 | C18: 1 | D18: 1.75 | E18: 0 | F18: 1 | G18: 0 | H18: 1 | I18: 0 | J18: 1 | K18: 0 | L18: 1 | M18: 0 | N18: 0 | O18: 1
A19: Dimanche | B19: 44395 | C19: 1 | D19: 1.75 | E19: 0 | F19: 1 | G19: 0 | H19: 1 | I19: 1 | J19: 1 | K19: 0 | L19: 1 | M19: 0 | N19: 0 | O19: 1
A20: Lundi | B20: 44396 | C20: 1 | D20: 1.75 | E20: 0 | F20: 1 | G20: 0 | H20: 1 | I20: 1 | J20: 1 | K20: 0 | L20: 1 | M20: 0 | N20: 0 | O20: 1
A21: Mardi | B21: 44397 | C21: 0 | D21: 0 | E21: 0 | F21: 0 | G21: 0 | H21: 0 | I21: 0 | J21: 0 | K21: 0 | L21: 0 | M21: 0 | N21: 0 | O21: 0
A22: Mercredi | B22: 44398 | C22: 0 | D22: 0 | E22: 0 | F22: 0 | G22: 0 | H22: 0 | I22: 0 | J22: 0 | K22: 0 | L22: 0 | M22: 0 | N22: 0 | O22: 0
A23: Jeudi | B23: 44399 | C23: 1 | D23: 0 | E23: 0 | F23: 1 | G23: 0 | H23: 0 | I23: 1 | J23: 0 | K23: 0 | L23: 0 | M23: 0 | N23: 0 | O23: 13
A24: Vendredi | B24: 44400 | C24: 1 | D24: 0 | E24: 0 | F24: 1 | G24: 0 | H24: 0 | I24: 1 | J24: 0 | K24: 0 | L24: 0 | M24: 0 | N24: 0 | O24: 0
A25: Samedi | B25: 44401 | C25: 1 | D25: 1 | E25: 0 | F25: 1 | G25: 0 | H25: 1 | I25: 0 | J25: 0 | K25: 0 | L25: 1 | M25: 0 | N25: 0 | O25: 0
A26: Dimanche | B26: 44402 | C26: 0 | D26: 1 | E26: 0 | F26: 1 | G26: 0 | H26: 1 | I26: 1 | J26: 0 | K26: 1 | L26: 1 | M26: 0 | N26: 0 | O26: 0
A27: Lundi | B27: 44403 | C27: 1 | D27: 1 | E27: 0 | F27: 1 | G27: 0 | H27: 1 | I27: 1 | J27: 0 | K27: 1 | L27: 1 | M27: 0 | N27: 0 | O27: 0
... A32: Samedi | B32: 44408 | C32: 1 | D32: 0 | E32: 0 | F32: 1 | G32: 0 | H32: 1 | I32: 0 | J32: 0 | K32: 1 | L32: 1 | M32: 0 | N32: 0 | O32: 0
C33: =SUM(C1:C32) -> 26 | D33: =SUM(D1:D32) -> 20 | E33: =SUM(E2:E32) -> 7.5 | F33: =SUM(F1:F32) -> 23 | G33: =SUM(G1:G32) -> 1 | H33: =SUM(H1:H32) -> 24 | I33: =SUM(I1:I32) -> 24 | J33: =SUM(J1:J32) -> 9 | K33: =SUM(K2:K32) -> 4.5 | L33: =SUM(L2:L32) -> 25 | M33: =SUM(M2:M32) -> 2 | N33: =SUM(N2:N32) -> 5.5 | O33: =SUM(O1:O32) -> 27
C34: 1923 | D34: 600 | E34: 962 | F34: 1000 | G34: 1000 | H34: 1154 | I34: 962 | J34: 1200 | K34: 962 | L34: 962 | M34: 962 | N34: 1000 | O34: 1154 | P34: =SUM(C34:O34) -> 13841
C35: =C34*C33 -> 49998 | D35: =D33*D34 -> 12000 | E35: =E34*E33 -> 7215 | F35: =F34*F33 -> 23000 | G35: =G34*G33 -> 1000 | H35: =H34*H33 -> 27696 | I35: =I34*I33 -> 23088 | J35: =J34*J33 -> 10800 | K35: =K34*K33 -> 4329 | L35: =L34*L33 -> 24050 | ... N35: =N34*N33 -> 5500 | O35: =O33*O34 -> 31158 | P35: =SUM(C35:O35) -> 221758
N37: Amel | O37: -600 | P37: khalate 5.5kg de poulet 7ata fa7ou on a pas pu les sauver
N38: Soumia | O38: -500 | P38: 7are9et 10 pièces de tcharak
N39: Hafida | O39: -500 | P39: khalate la pate fel frigidaire 7ata welate verte
N40: Yossera | O40: -300 | P40: e

Sheet Salaires
I11: Nom | J11: Salaire | K11: Avance
H12: 1 | I12: Zehor | J12: =Pointage!C35*1 -> 49998 | K12: 50000
H13: 2 | I13: Yossera | J13: =Pointage!D35*1 -> 12000 | K13: 12000 | L13: 8400+1000+3000
H14: 3 | I14: Soumia | J14: =Pointage!E35*1 -> 7215 | K14: 7000
H15: 4 | I15: Amel | J15: =Pointage!H35*1 -> 27696 | K15: 28000 | L15: 500+500+1000+500+25000
H16: 5 | I16: Nadjet | J16: =Pointage!F35*1 -> 23000 | K16: 23000 | L16: 500+22500
H17: 6 | I17: Hadjer | J17: =Pointage!G35*1 -> 1000 | K17: 1000
H18: 7 | I18: Hafida | J18: =Pointage!I35*1 -> 23088 | K18: 23000 | L18: 10000+3000+10000
H19: 8 | I19: Linda | J19: =Pointage!N35*1 -> 5500 | K19: 5000
H20: 9 | I20: Fatiha | J20: =Pointage!J35*1 -> 10800 | K20: 10800
H21: 10 | I21: Dalila | J21: =Pointage!M35*1 -> 1924 | K21: 1900
H22: 11 | I22: Safia | J22: =Pointage!K35*1 -> 4329 | K22: 4300
H23: 12 | I23: Samira | J23: =Pointage!L35*1 -> 24050 | K23: 24000 | L23: 17300+6700
H24: 13 | I24: Zahida | J24: =Pointage!O35*1 -> 31158 | K24: 31000
I25: TOTAL | J25: =SUM(J12:J24) -> 221758 | K25: =SUM(K12:K24) -> 221000
J26: =J25-K25 -> 758

Sheet Statistiques ADS
G2: Date | H2: Nb de messages | I2: Nb de commandes | J2: La somme
G3: 44379 | H3: 0 | I3: 0 | J3: 0
G4: 44380 | H4: 3 | I4: 0 | J4: 0
G5: 44381 | H5: 4 | I5: 0 | J5: 0
G6: 44382 | H6: 5 | I6: 0 | J6: 0
G7: 44383 | H7: 3 | I7: 0 | J7: 0
G8: 44384 | H8: 6 | I8: 0 | J8: 0
G9: 44385 | H9: 6 | I9: 1 | J9: 800 | K9: 2 parts zeviti
G10: 44386 | H10: 4 | I10: 1 | J10: 2400 | K10: 10 mehadjeb+10khefaf+2kg rechta
G11: 44387
G12: 44388
G13: 44389
G14: 44390
G15: 44391
G16: 44392
G17: 44393
G18: 44394
G19: 44395
G20: 44396
G21: 44397
G22: 44398
... G32: 44408
G33: Totale | H33: =SUM(H3:H32) -> 31 | I33: =SUM(I3:I32) -> 2 | J33: =SUM(J3:J32) -> 3200
