Workbook

Sheet RECAP
B1: Date | C1: Recette de Février 2022 | D1: Recette | E1: Charges | F1: Salaire | G1: Loyer | H1: Net Profit | I1: Nb de jours | K1: Objectif | L1: Février | O1: Moyenne
A2: Mardi | B2: 44621 | C2: 30000 | D2: 36000 | I2: 1 | K2: 50000 | L2: 30000 | O2: =D33/I33 -> 51000
A3: Mercredi | B3: 44622 | C3: 50000 | D3: 18000 | I3: 1 | K3: 50000 | L3: 50000
A4: Jeudi | B4: 44623 | C4: 85000 | D4: 52000 | I4: 1 | K4: 50000 | L4: 85000 | O4: 50000
A5: Vendredi | B5: 44624 | C5: 0 | D5: 40000 | I5: 1 | K5: 50000 | L5: 0
A6: Samedi | B6: 44625 | C6: 33000 | D6: 70000 | I6: 1 | K6: 50000 | L6: 33000 | N6: ²
A7: Dimanche | B7: 44626 | C7: 38000 | D7: 34000 | I7: 1 | K7: 50000 | L7: 38000
A8: Lundi | B8: 44627 | C8: 31000 | D8: 90000 | I8: 1 | K8: 50000 | L8: 31000 | N8: Cash restant | O8: Magasin | P8: Sofiane | Q8: caisse | R8: Hayet+Sousou
A9: Mardi | B9: 44628 | C9: 60000 | D9: 30000 | I9: 1 | K9: 50000 | L9: 60000 | N9: =D33+O11-O9-O12-E33-Salaires!J27 -> 643243.5 | O9: =P9+Q9+R9 -> 94000 | P9: 40000 | Q9: 22000 | R9: 32000
A10: Mercredi | B10: 44629 | C10: 34000 | D10: 32000 | I10: 1 | K10: 50000 | L10: 34000 | P10: 10000+20000
A11: Jeudi | B11: 44630 | C11: 103000 | D11: 92000 | I11: 1 | K11: 50000 | L11: 103000 | N11: loyer | O11: 270000 | P11: 10000 | Q11: Fadhila
A12: Vendredi | B12: 44631 | C12: 50000 | D12: 50000 | I12: 1 | K12: 50000 | L12: 50000 | N12: pétrin+ four | O12: 220000
A13: Samedi | B13: 44632 | C13: 39000 | D13: 70000 | I13: 1 | K13: 50000 | L13: 39000 | O13: 75000+145000
A14: Dimanche | B14: 44633 | C14: 50000 | D14: 36000 | I14: 1 | K14: 50000 | L14: 50000
A15: Lundi | B15: 44634 | C15: 44000 | D15: 38000 | I15: 1 | K15: 50000 | L15: 44000
A16: Mardi | B16: 44635 | C16: 53000 | D16: 39000 | I16: 1 | K16: 50000 | L16: 53000
A17: Mercredi | B17: 44636 | C17: 50000 | D17: 40000 | I17: 1 | K17: 50000 | L17: 50000 | N17: Différence mois de Février
A18: Jeudi | B18: 44637 | C18: 55000 | D18: 57000 | I18: 1 | K18: 50000 | L18: 55000 | N18: =D33-C33 -> 262000
A19: Vendredi | B19: 44638 | C19: 55000 | D19: 74000 | I19: 1 | K19: 50000 | L19: 40000 | N19: Différence objectif
A20: Samedi | B20: 44639 | C20: 40000 | D20: 40000 | I20: 1 | K20: 50000 | L20: 36000 | N20: =D33-K33 -> 31000
A21: Dimanche | B21: 44640 | C21: 25000 | D21: 40000 | I21: 1 | K21: 50000 | L21: 25000
A22: Lundi | B22: 44641 | C22: 50000 | D22: 24000 | I22: 1 | K22: 50000 | L22: 50000
A23: Mardi | B23: 44642 | C23: 45000 | D23: 35000 | I23: 1 | K23: 50000 | L23: 45000 | N23: Les vendredis
A24: Mercredi | B24: 44643 | C24: 58000 | D24: 54000 | I24: 1 | K24: 50000 | L24: 58000 | N24: =D5+D12+D19+D26 -> 220000
A25: Jeudi | B25: 44644 | C25: 70000 | D25: 74000 | I25: 1 | K25: 50000 | L25: 70000
A26: Vendredi | B26: 44645 | C26: 39000 | D26: 56000 | I26: 1 | K26: 50000 | L26: 39000 | N26: Cash réel | P26: CCP
A27: Samedi | B27: 44646 | C27: 36000 | D27: 50000 | I27: 1 | K27: 50000 | L27: 36000 | N27: 133000 | O27: 113000 | P27: 20000
A28: Dimanche | B28: 44647 | C28: 40000 | D28: 42000 | I28: 1 | K28: 50000 | L28: 40000 | N28: diférence à payer
A29: Lundi | B29: 44648 | C29: 56000 | D29: 37000 | I29: 1 | K29: 50000 | L29: 56000 | N29: =N9-N27 -> 510243.5
A30: Mardi | B30: 44649 | C30: 0 | D30: 70000 | I30: 1 | K30: 50000 | L30: 0
A31: Mercredi | B31: 44650 | C31: 0 | D31: 83000 | I31: 1 | K31: 50000 | L31: 0
A32: Jeudi | B32: 44651 | C32: 0 | D32: 78000 | I32: 1 | K32: 50000 | L32: 0
C33: =SUM(C2:C32) -> 1319000 | D33: =SUM(D2:D32) -> 1581000 | E33: ='Les Charges'!F347*1 -> 590756.5 | F33: =Pointage!Q35*1 -> 300000 | G33: 90000 | H33: =D33-G33-F33-E33 -> 600243.5 | I33: =SUM(I2:I32) -> 31 | K33: =SUM(K2:K32) -> 1550000 | L33: =SUM(L2:L32) -> 1300000
C35: Objectif | D35: 1550000 | E35: 500000 | F35: 300000 | G35: 90000 | H35: =D35-E35-F35-G35 -> 660000
C36: Mois de Février | D36: 1300000 | E36: 462400 | F36: 277600 | G36: 90000 | H36: 470000

Sheet Les Charges
A1: :::::
C2: Produit | D2: Quantité | E2: Prix unitaire | F2: Prix | G2: Date d'achat
C3: Cheddar | D3: 6kg | E3: 1870 | F3: 11220 | G3: 44613
C4: thon | D4: 10 boites de 2kg | E4: 1800 | F4: 18000 | G4: 44613
C5: fromage spécial pizza | D5: 11kg | E5: 370 | F5: 4070 | G5: 44613
C6: shewepess canette | D6: 1 | E6: 1500 | F6: 1500 | G6: 44613
A7: pp | C7: Coca canette | D7: 1 | E7: 1450 | F7: 1450 | G7: 44613
C8: Coca bouteille | D8: 2 | E8: 520 | F8: 1040 | G8: 44613
C9: Ifruit 33cl | D9: 8 | E9: 520 | F9: 4160 | G9: 44613
C10: Rouiba 33cl | D10: 3 | E10: 430 | F10: 1290 | G10: 44613
C11: Hamoud | D11: 3 | E11: 430 | F11: 1290 | G11: 44613
C12: Pepsi | D12: 4 | E12: 390 | F12: 1560 | G12: 44613
C13: Rouiba25ml | D13: 2 | E13: 520 | F13: 1040 | G13: 44613
C14: amandes | D14: 20kg | E14: 1580 | F14: 31600 | G14: 44612
C15: tofia 500g | D15: 2 | E15: 240 | F15: 480 | G15: 44612
C16: arome fleur d'oranger | D16: 1 | E16: 850 | F16: 850 | G16: 44612
C17: amandes éfilet | D17: 500g | E17: 2000 | F17: 1000 | G17: 44612
C18: djeldjelan | D18: 500g | E18: 600 | F18: 300 | G18: 44612
C19: pistache | D19: 300g | E19: 3400 | F19: 1000 | G19: 44612
C20: la gelée | D20: 1 | E20: 110 | F20: 110 | G20: 44612
C21: noix | D21: 700g | E21: 1600 | F21: 1000 | G21: 44612
C22: amande noir | D22: 1kg | E22: 1600 | F22: 1600 | G22: 44612
C23: framboise | D23: 1 | E23: 280 | F23: 280 | G23: 44612
C24: Quissettes dorée N10 | D24: 5 | E24: 60 | F24: 300 | G24: 44612
C25: balance | D25: 1 | E25: 700 | F25: 700 | G25: 44612
C26: organza5.5 | D26: 2 | E26: 90 | F26: 180 | G26: 44612
C27: orgonza4.5 | D27: 2 | E27: 85 | F27: 170 | G27: 44612
C28: 3akeri | D28: 02kg | E28: 800 | F28: 1600 | G28: 44607
C29: boites 08/07 | D29: 1 fardeaux de 100 | E29: 1700 | F29: 1700 | G29: 44597
C30: boites 24/07 | D30: 1 fardeaux de50 | E30: 1600 | F30: 1600 | G30: 44597
C31: boites de 36/07 | D31: 1 fardeaux de 50 | E31: 1600 | F31: 1600 | G31: 44597
C32: boites de 48/10 | D32: 2 fardeaux de 50 | E32: 2700 | F32: 5400 | G32: 44597
C33: les gants | D33: 1 boite | E33: 1350 | F33: 1350 | G33: 44616
C34: extincteur | D34: 1 | E34: 1200 | F34: 1200 | G34: 44618
C35: Leuvre de Bièrre 500g la boite | D35: 9 boites de 500g | E35: 270.5 | F35: 2434.5 | G35: 44593
C36: chocolat à tartiner | D36: 1 bidon de 7kg | E36: 486 | F36: 3400 | G36: 44593
C37: chocolat wedjedane blanc | D37: 2 boites de 250g | E37: 225 | F37: 450 | G37: 44593
C38: chocolat wedjedane noisette | D38: 3 boites de 250g | E38: 245 | F38: 735 | G38: 44593
C39: miel Nounours 5kg | D39: 2 | E39: 740 | F39: 1480 | G39: 44593
C40: Fromage slices cheezy | D40: 10 | E40: 130 | F40: 1300 | G40: 44593
...

Sheet Pointage
B1: Date | C1: Zehor | D1: Soumia | E1: Nadjet | F1: Hadjer | G1: Amel | H1: Marwa | I1: djamila | J1: Mounia | K1: Soumeya | L1: Houda | M1: Noura | N1: Samira | O1: Hafidha | P1: Zahida
A2: Mardi | B2: 44621 | C2: 1 | D2: 1 | E2: 1 | F2: 0 | G2: 1 | H2: 0 | I2: 1 | J2: 0 | K2: 0 | L2: 1 | M2: 0 | N2: 0 | O2: 1 | P2: 1 | Q2: elyoum zehor djate à 08h40 Amel 08h50 et Hafida 08h55
A3: Mercredi | B3: 44622 | C3: 1 | D3: 1 | E3: 1 | F3: 0 | G3: 1 | H3: 0 | I3: 1 | J3: 0 | K3: 0 | L3: 1 | M3: 0 | N3: 0 | O3: 1 | P3: 1
A4: Jeudi | B4: 44623 | C4: 1 | D4: 0 | E4: 1 | F4: 0 | G4: 1 | H4: 1 | I4: 1 | J4: 0 | K4: 0 | L4: 1 | M4: 0 | N4: 0 | O4: 1 | P4: 1
A5: Vendredi | B5: 44624 | C5: 1 | D5: 0 | E5: 0 | F5: 1 | G5: 1.5 | H5: 0 | I5: 0 | J5: 0 | K5: 0 | L5: 0 | M5: 0 | N5: 1 | O5: 0 | P5: 1
A6: Samedi | B6: 44625 | C6: 1 | D6: 1 | E6: 1 | F6: 1 | G6: 1 | H6: 1 | I6: 0 | J6: 0 | K6: 0 | L6: 1 | M6: 0 | N6: 0 | O6: 1 | P6: 0
A7: Dimanche | B7: 44626 | C7: 1 | D7: 1 | E7: 1 | F7: 1 | G7: 1 | H7: 1 | I7: 0 | J7: 0 | K7: 0 | L7: 1 | M7: 0 | N7: 0 | O7: 1 | P7: 1 | Q7: zehor et hadjer djaw à 08h50 Hafida à 09h
A8: Lundi | B8: 44627 | C8: 1 | D8: 1 | E8: 1 | F8: 1 | G8: 1 | H8: 0 | I8: 0 | J8: 0 | K8: 0 | L8: 0 | M8: 0 | N8: 0 | O8: 1 | P8: 1 | Q8: Hafida djate à 11h et kharedjet à 18h
A9: Mardi | B9: 44628 | C9: 1 | D9: 1 | E9: 1 | F9: 1 | G9: 1 | H9: 1 | I9: 0 | J9: 0 | K9: 0 | L9: 1 | M9: 0 | N9: 0 | O9: 1 | P9: 1 | Q9: la journnée international des droits des femmes on leurs a donné la demie journée
A10: Mercredi | B10: 44629 | C10: 1 | D10: 1 | E10: 1 | F10: 1 | G10: 1 | H10: 0 | I10: 1 | J10: 0 | K10: 0 | L10: 1 | M10: 0 | N10: 0 | O10: 1 | P10: 1
A11: Jeudi | B11: 44630 | C11: 1 | D11: 1 | E11: 1 | F11: 0 | G11: 1 | H11: 0 | I11: 1 | J11: 0 | K11: 0 | L11: 1 | M11: 0 | N11: 0 | O11: 1 | P11: 1
A12: Vendredi | B12: 44631 | C12: 1.25 | D12: 0 | E12: 0 | F12: 1.25 | G12: 0.75 | H12: 0 | I12: 1 | J12: 0 | K12: 0 | L12: 0 | M12: 0 | N12: 0 | O12: 0 | P12: 0
A13: Samedi | B13: 44632 | C13: 0 | D13: 1 | E13: 1 | F13: 1 | G13: 1 | H13: 0 | I13: 1 | J13: 0 | K13: 0 | L13: 1 | M13: 0 | N13: 0.5 | O13: 1 | P13: 0
A14: Dimanche | B14: 44633 | C14: 1 | D14: 1 | E14: 1 | F14: 0 | G14: 0.25 | H14: 0 | I14: 1 | J14: 0 | K14: 0 | L14: 1 | M14: 0 | N14: 0.75 | O14: 1 | P14: 0
A15: Lundi | B15: 44634 | C15: 1 | D15: 1 | E15: 1 | F15: 0 | G15: 1 | H15: 0 | I15: 1 | J15: 0 | K15: 0 | L15: 1 | M15: 0 | N15: f | O15: 1 | P15: 0
A16: Mardi | B16: 44635 | C16: 1 | D16: 0.5 | E16: 0 | F16: 0 | G16: 1 | H16: 0 | I16: 1 | J16: 0 | K16: 0 | L16: 1 | M16: 0 | N16: 0.75 | O16: 1 | P16: 0
A17: Mercredi | B17: 44636 | C17: 1 | D17: 1 | E17: 1 | F17: 1 | G17: 1 | H17: 0 | I17: 1 | J17: 0 | K17: 0 | L17: 1 | M17: 0 | N17: 0.75 | O17: 1 | P17: 1 | Q17: elyoum ma kanetech 3anedehom khadema bezaaf
A18: Jeudi | B18: 44637 | C18: 1 | D18: 1 | E18: 1 | F18: 1 | G18: 1 | H18: 0 | I18: 1 | J18: 0 | K18: 0 | L18: 1 | M18: 0 | N18: 0.75 | O18: 1 | P18: 1 | Q18: samira djate à 13h + zahida ra7et à 13h30et elate à 16h
A19: Vendredi | B19: 44638 | C19: 1 | D19: 1 | E19: 0 | F19: 1 | G19: 1.5 | H19: 0 | I19: 1 | J19: 0 | K19: 0 | L19: 0 | M19: 0 | N19: 0 | O19: 1 | P19: 1
A20: Samedi | B20: 44639 | C20: 1 | D20: 1 | E20: 1 | F20: 1 | G20: 0 | H20: 0 | I20: 1 | J20: 0.5 | K20: 0 | L20: 1 | M20: 0 | N20: 0.5 | O20: 1 | P20: 1
A21: Dimanche | B21: 44640 | C21: 1 | D21: 1 | E21: 1 | F21: 1 | G21: 1 | H21: 0 | I21: 0 | J21: 1 | K21: 0 | L21: 1 | M21: 0 | N21: 0 | O21: 1 | P21: 1 | Q21: hadjer djate à 09h50 et ma khademetech tt la journnée
A22: Lundi | B22: 44641 | C22: 1 | D22: 1 | E22: 1 | F22: 1 | G22: 1 | H22: 0 | I22: 0 | J22: 0.5 | K22: 1 | L22: 1 | M22: 1 | N22: 0 | O22: 1.25 | P22: 1 | Q22: hadjer kanet merida et maq kanetech khadema donc 9a3edet tediri ménage
A23: Mardi | B23: 44642 | C23: 1 | D23: 0 | E23: 1 | F23: 1 | G23: 1 | H23: 1 | I23: 0 | J23: 1 | K23: 1 | L23: 1 | M23: 1 | N23: 0 | O23: 1 | P23: 1
A24: Mercredi | B24: 44643 | C24: 1 | D24: 1 | E24: 1 | F24: 0.75 | G24: 1 | H24: 1 | I24: 0 | J24: 0.5 | K24: 1 | L24: 1 | M24: 1 | N24: 0 | O24: 1 | P24: 1
A25: Jeudi | B25: 44644 | C25: 1 | D25: 1 | E25: 1 | F25: 1 | G25: 1 | H25: 1 | I25: 0 | J25: 1 | K25: 1 | L25: 1 | M25: 1 | N25: 0 | O25: 1 | P25: 1 | Q25: Houda kharedjet à 14h30
A26: Vendredi | B26: 44645 | C26: 1 | D26: 0 | E26: 0 | F26: 1 | G26: 1.5 | H26: 0 | I26: 0 | J26: 0 | K26: 0 | L26: 0 | M26: 0 | N26: 0 | O26: 0 | P26: 1
A27: Samedi | B27: 44646 | C27: 1 | D27: 1 | E27: 0 | F27: 1 | G27: 1 | H27: 1 | I27: 0 | J27: 1 | K27: 1 | L27: 1 | M27: 0.5 | N27: 0 | O27: 1 | P27: 1
A28: Dimanche | B28: 44647 | C28: 1 | D28: 1 | E28: 0 | F28: 1 | G28: 1 | H28: 0 | I28: 0 | J28: 1 | K28: 1 | L28: 1 | M28: 0 | N28: 0 | O28: 1 | P28: 1 | Q28: Houda ra7et 3aned le médecin we welate
A29: Lundi | B29: 44648 | C29: 1 | D29: 1 | E29: 1 | F29: 0 | G29: 0 | H29: 0 | I29: 1 | J29: 1 | K29: 1 | L29: 1 | M29: 0 | N29: 0 | O29: 1 | P29: 0
A30: Mardi | B30: 44649 | C30: 1 | D30: 1 | E30: 1 | F30: 0 | G30: 1 | H30: 0 | I30: 1 | J30: 1 | K30: 1 | L30: 1 | M30: 0 | N30: 0 | O30: 0 | P30: 1
A31: Mercredi | B31: 44650 | C31: 0 | D31: 1 | E31: 1 | F31: 1 | G31: 1 | H31: 0 | I31: 1 | J31: 1 | K31: 1 | L31: 0.5 | M31: 0 | N31: 0 | O31: 1 | P31: 1
A32: Jeudi | B32: 44651 | C32: 0 | D32: 1 | E32: 1 | F32: 1 | G32: 1 | H32: 0 | I32: 1 | J32: 1 | K32: 1 | L32: 1 | M32: 0 | N32: 1.0648 | O32: 1 | P32: 1
C33: =SUM(C2:C32) -> 28.25 | D33: =SUM(D2:D32) -> 25.5 | E33: =SUM(E2:E32) -> 24 | F33: =SUM(F2:F32) -> 22 | G33: =SUM(G2:G32) -> 29.5 | H33: =SUM(H2:H32) -> 8 | I33: =SUM(I2:I32) -> 18 | J33: =SUM(J2:J32) -> 10.5 | ... P33: =SUM(P2:P32) -> 24
C34: 1852 | D34: 926 | E34: 1112 | F34: 1112 | G34: 1112 | H34: 1000 | I34: 1000 | J34: 926 | K34: 926 | L34: 1112 | M34: 926 | N34: 926 | O34: 1112 | P34: 1112
C35: =C34*C33 -> 52319 | D35: =D34*D33 -> 23613 | E35: =E34*E33 -> 26688 | F35: =F34*F33 -> 24464 | G35: =G34*G33 -> 32804 | H35: =H34*H33 -> 8000 | I35: =I34*I33 -> 18000 | J35: =J34*J33 -> 9723 | ... O35: =O34*O33 -> 30302 | P35: =P33*P34 -> 26688 | Q35: =SUM(C35:P35) -> 300000

Sheet Salaires
H12: Nom | I12: Salaire | J12: Avance | K12: Salaire à payer
G13: 1 | H13: Zehor | I13: =Pointage!C35*1 -> 52319 | J13: 52500 | K13: =I13-J13 -> -181
G14: 2 | H14: Soumia | I14: =Pointage!D35*1 -> 23613 | J14: 24000 | K14: =I14-J14 -> -387 | L14: 1000+ 10000+2000+11000
G15: 3 | H15: Nadjet | I15: =Pointage!E35*1 -> 26688 | J15: 27000 | K15: =I15-J15 -> -312
G16: 4 | H16: Hadjer | I16: =Pointage!F35*1 -> 24464 | J16: 24500 | K16: =I16-J16 -> -36 | L16: 1000+23500
G17: 5 | H17: Amel | I17: =Pointage!G35*1 -> 32804 | J17: 33000 | K17: =I17-J17 -> -196 | L17: 2000+7000+3000+1000+5000+7000+2000
G18: 6 | H18: Marwa | I18: =Pointage!H35*1 -> 8000 | J18: 8000 | K18: =I18-J18 -> 0
G19: 7 | H19: Djamila | I19: =Pointage!I35*1 -> 18000 | J19: 18000 | K19: =I19-J19 -> 0
G20: 8 | H20: Houda | I20: =Pointage!L35*1 -> 28356 | J20: 28500 | K20: =I20-J20 -> -144 | L20: 4000+24500
G21: 9 | H21: Samira | I21: =Pointage!N35*1 -> 5616.0048 | J21: 6000 | K21: =I21-J21 -> -383.9952 | L21: 1000 | M21: Faiza a pris 1000Da
G22: 10 | H22: Hafida | I22: =Pointage!O35*1 -> 30302 | J22: 30500 | K22: =I22-J22 -> -198 | L22: 5000+2000+3000+2000+3000+2000+2000
G23: 11 | H23: Mounia | I23: =Pointage!J35*1 -> 9723 | J23: 10000 | K23: =I23-J23 -> -277
G24: 12 | H24: Soumeya | I24: =Pointage!K35*1 -> 9260 | J24: 9500 | K24: =I24-J24 -> -240
G25: 13 | H25: Noura | I25: =Pointage!M35*1 -> 4167 | J25: 4500 | K25: =I25-J25 -> -333
G26: 14 | H26: Zahida | I26: =Pointage!P35*1 -> 26688 | J26: 27000 | K26: =I26-J26 -> -312
H27: TOTAL | I27: =SUM(I13:I26) -> 300000 | J27: =SUM(J13:J26) -> 303000 | K27: =SUM(K13:K26) -> -2999.9952
H28: =I27-J27 -> -2999.9952 | K28: =I28-J28 -> 0

Sheet Feuille 10

Sheet Feuille 5
G9: Mois de Janvier | H9: Mois de Février | I9: Mois de Mars | J9: Objectif
F10: Recette | G10: 1051000 | H10: 1300000 | I10: =RECAP!D33*1 -> 1581000 | J10: 1550000
F11: Charges | G11: 435000 | H11: 462400 | I11: =RECAP!E33*1 -> 590756.5 | J11: 500000
F12: Salaires | G12: 226000 | H12: 277600 | I12: =RECAP!F33*1 -> 300000 | J12: 300000
F13: Loyer | G13: 90000 | H13: 90000 | I13: =RECAP!G33*1 -> 90000 | J13: 90000
F14: Profit Net | G14: 300000 | H14: 470000 | I14: 600000 | J14: 660000
H21: Moyenne / jour
G22: Moyenne réelle | H22: 51000
G23: Objectif | H23: 50000
