Workbook

Sheet RECAP
B1: Date | C1: Recette Avril 2025 | D1: Recette | E1: Charges | F1: Salaire | G1: Che7i7a | H1: Loyer | I1: Net Profit | J1: Nb de jours | L1: Objectif | M1: Mois d'Avril 2025
A2: Jeudi | B2: 45778 | C2: 0 | D2: 66000 | G2: 2000 | J2: 1 | M2: 0
A3: Vendredi | B3: 45779 | C3: 0 | D3: 40000 | G3: 2000 | J3: 1 | M3: 0 | N3: Bénéfice Moyen par jour | O3: Moyenne | P3: Moyenne salaire | Q3: pourcentage du salaire vis à vis la recettte
A4: Samedi | B4: 45780 | C4: 0 | D4: 57000 | G4: 2000 | J4: 1 | M4: 0 | N4: =I33/J33 -> 20666.342 | O4: =D33/J33 -> 67000 | Q4: =P4/O4 -> 0
A5: Dimanche | B5: 45781 | C5: 0 | D5: 41000 | G5: 2000 | J5: 1 | M5: 0
A6: Lundi | B6: 45782 | C6: 15000 | D6: 43000 | G6: 2000 | J6: 1 | M6: 15000 | N6: Moyenne des charges par jour | O6: Objectif
A7: Mardi | B7: 45783 | C7: 33000 | D7: 28000 | G7: 2000 | J7: 1 | M7: 33000 | N7: =E33/J33 -> 25809.035 | O7: 100000
A8: Mercredi | B8: 45784 | C8: 54000 | D8: 40000 | G8: 2000 | J8: 1 | M8: 54000 | N8: ² | S8: "
A9: Jeudi | B9: 45785 | C9: 32000 | D9: 78000 | G9: 2000 | J9: 1 | M9: 32000
A10: Vendredi | B10: 45786 | C10: 48000 | D10: 53000 | G10: 2000 | J10: 1 | M10: 48000 | N10: Cash restant | O10: Magasin | P10: Cash réel | Q10: Mes dettes pour le magasin
A11: Samedi | B11: 45787 | C11: 46000 | D11: 47000 | G11: 2000 | J11: 1 | M11: 46000 | N11: =D33+N14-E33-O11-'Les Salaires'!J23-G33 -> 1109419.9 | O11: 38000 | P11: 645000 | Q11: =N11-P11 -> 464419.9
A12: Dimanche | B12: 45788 | C12: 78000 | D12: 48000 | G12: 2000 | J12: 1 | M12: 78000
A13: Lundi | B13: 45789 | C13: 56000 | D13: 54000 | G13: 2000 | J13: 1 | M13: 56000 | N13: Fond de Roulement
A14: Mardi | B14: 45790 | C14: 65000 | D14: 71000 | G14: 2000 | J14: 1 | M14: 65000 | N14: 330000
A15: Mercredi | B15: 45791 | C15: 39000 | D15: 59000 | G15: 2000 | J15: 1 | M15: 39000 | Q15: La caisse :
A16: Jeudi | B16: 45792 | C16: 43000 | D16: 60000 | G16: 2000 | J16: 1 | K16: 1 | M16: 43000 | N16: Bénéfice Mars + loyer
A17: Vendredi | B17: 45793 | C17: 62000 | D17: 66000 | G17: 2000 | J17: 1 | K17: 1 | M17: 62000 | N17: 440000 | Q17: Sofiane: 30000Da
A18: Samedi | B18: 45794 | C18: 91000 | D18: 48000 | G18: 2000 | J18: 1 | M18: 91000
A19: Dimanche | B19: 45795 | C19: 59000 | D19: 45000 | G19: 2000 | J19: 1 | M19: 59000 | N19: Différence mois de Décembre
A20: Lundi | B20: 45796 | C20: 32000 | D20: 50000 | G20: 2000 | J20: 1 | M20: 32000 | N20: =D33-C33 -> 795000
A21: Mardi | B21: 45797 | C21: 53000 | D21: 60000 | G21: 2000 | J21: 1 | M21: 53000 | N21: Différence objectif
A22: Mercredi | B22: 45798 | C22: 37000 | D22: 49000 | G22: 2000 | J22: 1 | M22: 37000 | N22: =L36-E36 -> 0
A23: Jeudi | B23: 45799 | C23: 49000 | D23: 79000 | G23: 2000 | J23: 1 | M23: 49000 | N23: Différence du Totale
A24: Vendredi | B24: 45800 | C24: 63000 | D24: 512000 | G24: 2000 | J24: 1 | M24: 63000 | N24: =D33-C33 -> 795000
A25: Samedi | B25: 45801 | C25: 73000 | D25: 64000 | G25: 2000 | J25: 1 | M25: 73000 | N25: Les vendredis
A26: Dimanche | B26: 45802 | C26: 53000 | D26: 33000 | G26: 2000 | J26: 1 | M26: 53000 | N26: =D9+D16+D23+D30 -> 282000
A27: Lundi | B27: 45803 | C27: 1000 | D27: 36000 | G27: 2000 | J27: 1 | M27: 1000
A28: Mardi | B28: 45804 | C28: 37000 | D28: 43000 | G28: 2000 | J28: 1 | M28: 37000 | N28: Cash réel
A29: Mercredi | B29: 45805 | C29: 55000 | D29: 55000 | G29: 2000 | J29: 1 | M29: 55000 | N29: 51000
A30: Jeudi | B30: 45806 | C30: 43000 | D30: 65000 | G30: 2000 | J30: 1 | M30: 43000 | N30: rest à payer
A31: Vendredi | B31: 45807 | C31: 65000 | D31: 44000 | G31: 2000 | J31: 1 | M31: 65000
A32: samedi | B32: 45808 | C32: 0 | D32: 43000 | G32: 2000 | J32: 1 | M32: 0
C33: =SUM(C2:C32) -> 1282000 | D33: =SUM(D2:D32) -> 2077000 | E33: ='Les Charges'!H368 -> 800080.1 | F33: ='Les Salaires'!I23 -> 394263.3 | G33: =SUM(G2:G32) -> 62000 | H33: 180000 | I33: =D33-E33-F33-G33-H33 -> 640656.6 | J33: =SUM(J2:J32) -> 31 | M33: =SUM(M2:M32) -> 1282000
G34: Loyer Magasin | H34: 55000
G35: Loyer Locale | H35: 40000 | N35: =N11-N29-N34 -> 1058419.9
D36: 200000 | G36: Sofiane Maison | H36: 45000 | P36: Papa | Q36: 40000
G37: Dette Papa | H37: 40000
D38: -
C49: 1

Sheet Les Charges
E3: Produit | F3: Quantité | G3: Prix unitaire | H3: Prix | I3: Date d'achat
E4: Semoule Fine 10kg | F4: 5 | G4: 380 | H4: =F4*G4 -> 1900
E5: Semoule Fine 25kg | F5: 11 | G5: 1000 | H5: =F5*G5 -> 11000
E6: Semoule Moyenne 25kg | F6: 3 | G6: 1000 | H6: =F6*G6 -> 3000
E7: Transport et Manutention semoule | F7: 1 | G7: 2000 | H7: =F7*G7 -> 2000
E8: semoule Moula moyenne 10kg | F8: 8 | G8: 850 | H8: =F8*G8 -> 6800
E9: Semoule Moula Gross 10 kg | F9: 3 | G9: 950 | H9: =F9*G9 -> 2850
E10: Faine Makam 10kg | F10: 4 | G10: 450 | H10: =F10*G10 -> 1800
E11: Levure boulangère | F11: 4 | G11: 415 | H11: =F11*G11 -> 1660
E12: huile 5 litre | F12: 48 | G12: 600 | H12: =F12*G12 -> 28800
E13: Chocolat wedjedane au lait | F13: 5 | G13: 255 | H13: =F13*G13 -> 1275
E14: Chocolat wedjedane noir | F14: 15 | G14: 255 | H14: =F14*G14 -> 3825
E15: chocolat wedjedane noisette | F15: 13 | G15: 280 | H15: =F15*G15 -> 3640
... E36: Khel | F36: 2 | G36: 30 | H36: =F36*G36 -> 60
D37: Boissons | E37: Eau minérale 0,5 litre | F37: 174 | G37: 17 | H37: =F37*G37 -> 2958
E38: limonade Slim 33cl | F38: 83 | G38: 35 | H38: =F38*G38 -> 2905
E39: Canette Coca 24 | F39: 54 | G39: 57 | H39: =F39*G39 -> 3078
E40: canette Hamoud | F40: 46 | G40: 45 | H40: =F40*G40 -> 2070
E41: eau mineral 1,5 litre | F41: 30 | G41: 34 | H41: =F41*G41 -> 1020
E42: Cannette Fanta 24cl | F42: 20 | G42: 52 | H42: =F42*G42 -> 1040
E43: Canettes Sprit | F43: 3 | G43: 52 | H43: =F43*G43 -> 156
E44: Canette IZEM | F44: 10 | G44: 72 | H44: =F44*G44 -> 720
E45: Jus Tchina | F45: 85 | G45: 44 | H45: =F45*G45 -> 3740 | I45: 45785
E46: Canette IZEM | F46: 13 | G46: 72 | H46: =F46*G46 -> 936
E47: Canette Fanta 24 cl | F47: 6 | G47: 50 | H47: =F47*G47 -> 300
E48: Canette Schweppes | F48: 6 | G48: 66 | H48: =F48*G48 -> 396
E49: eau mineral 1,5 litre | F49: 20 | G49: 34 | H49: =F49*G49 -> 680
E50: Maiizina 25kg | F50: 0.2 | G50: 900 | H50: =F50*G50 -> 180
E51: fromage spéciale pizza | F51: 1 | G51: 625 | H51: =F51*G51 -> 625
E52: fromage slices | F52: 14 | G52: 195 | H52: =F52*G52 -> 2730
E53: Sucre cristalisé 1kg | F53: 12 | G53: 90 | H53: =F53*G53 -> 1080
E54: Cheddar | F54: 4 | G54: 1700 | H54: =F54*G54 -> 6800
E55: amande éffiléé | F55: 1 | G55: 2150 | H55: =F55*G55 -> 2150
E56: Amande Moulu | F56: 5 | G56: 1800 | H56: =F56*G56 -> 9000
E57: Amande blanc | F57: 11 | G57: 2420 | H57: =F57*G57 -> 26620
... E70: prunes | F70: 1 | G70: 1200 | H70: =F70*G70 -> 1200
E71: Raisins sec | F71: 1 | G71: 1200 | H71: 1200
E72: fromage bidon | F72: 3 | G72: 1320 | H72: =F72*G72 -> 3960
E73: détergents: isis bingo serpielle | F73: 1 | G73: 800 | H73: =F73*G73 -> 800
E74: cuisses | F74: 10 | G74: 180 | H74: =F74*G74 -> 1800
...

Sheet Pointage
B1: Date | C1: Saida | D1: Fatiha | E1: Assia | F1: Samira | G1: Nour ElHouda | H1: Yasmine | I1: Zohra | J1: Rayan | K1: Amina Ain Beniane | L1: Ahlem | M1: Samira | N1: Merieioma | O1: Camilia | P1: Akila | Q1: Backup
A2: Jeudi | B2: 45778 | C2: 0 | D2: 1 | E2: 1 | F2: 1 | G2: 0 | H2: 1 | I2: 8.66 | J2: 0 | K2: 1 | L2: 1 | M2: 0 | N2: 1 | O2: 0 | P2: 1 | Q2: 0
A3: Vendredi | B3: 45779 | C3: 0 | D3: 1 | E3: 1 | F3: 0 | G3: 0 | H3: 1 | I3: 1 | J3: 0 | K3: 0 | L3: 0 | M3: 0 | N3: 1 | O3: 0 | P3: 1 | Q3: 0
A4: Samedi | B4: 45780 | C4: 1 | D4: 1 | E4: 0 | F4: 1 | G4: 0 | H4: 1 | I4: 0 | J4: 1 | K4: 1 | L4: 1 | M4: 0 | N4: 0 | O4: 0 | P4: 1 | Q4: 0
A5: Dimanche | B5: 45781 | C5: 1 | D5: 1 | E5: 1 | F5: 1 | G5: 0 | H5: 1 | I5: 1 | J5: 1 | K5: 1 | L5: 1 | M5: 0 | N5: 0 | O5: 0 | P5: 1 | Q5: 0
A6: Lundi | B6: 45782 | C6: 1 | D6: 1 | E6: 1 | F6: 1 | G6: 0 | H6: 1 | I6: 0 | J6: 1 | K6: 1 | L6: 1 | M6: 0 | N6: 1 | O6: 0 | P6: 1 | Q6: 0
A7: Mardi | B7: 45783 | C7: 1 | D7: 0 | E7: 1 | F7: 1 | G7: 0 | H7: 1 | I7: 1 | J7: 1 | K7: 1 | L7: 1 | M7: 0 | N7: 0 | O7: 0 | P7: 1 | Q7: 0
A8: Mercredi | B8: 45784 | C8: 1 | D8: 1 | E8: 0 | F8: 1 | G8: 1 | H8: 0 | I8: 1 | J8: 0 | K8: 1 | L8: 1 | M8: 0 | N8: 0 | O8: 0 | P8: 1 | Q8: 0
A9: Jeudi | B9: 45785 | C9: 1 | D9: 1 | E9: 1 | F9: 1 | G9: 0 | H9: 1 | I9: 0 | J9: 0 | K9: 1 | L9: 1 | M9: 0 | N9: 0 | O9: 0 | P9: 1 | Q9: 0 | R9: Fatiha est sortie à 19h10, Assia et Akila à 18h
A10: Vendredi | B10: 45786 | C10: 0 | D10: 1.5 | E10: 1.25 | F10: 0 | G10: 0 | H10: 1 | I10: 2 | J10: 0 | K10: 0 | L10: 0 | M10: 0 | N10: 0 | O10: 0 | P10: 1 | Q10: 0 | R10: Zohra a travaillé dans le magasin et locale de 08h à 18h
A11: Samedi | B11: 45787 | C11: 1 | D11: 1 | E11: 0 | F11: 0.75 | G11: 0 | H11: 1 | I11: 0 | J11: 1 | K11: 0 | L11: 1 | M11: 0 | N11: 0 | O11: 0 | P11: 1 | Q11: 0 | R11: Samira est sortie après un conflit avec la vendeuse à 14h30
A12: Dimanche | B12: 45788 | C12: 1 | D12: 1 | E12: 1 | F12: 0 | G12: 0 | H12: 0.7 | I12: 1 | J12: 1 | K12: 0 | L12: 1 | M12: 0 | N12: 0 | O12: 0 | P12: 1 | Q12: 0 | R12: Ysmine est arrivé à 12h30 , Saida est arrivé à 07h et a commencé le travaille à 08h
A13: Lundi | B13: 45789 | C13: 1 | D13: 0 | E13: 0.75 | F13: 1 | G13: 1.25 | H13: 0 | I13: 0 | J13: 1 | K13: 0 | L13: 1 | M13: 0 | N13: 0 | O13: 0 | P13: 1 | Q13: 0 | R13: Assia djate à 11h30 autorisée elle est allé à l'hopitale
A14: Mardi | B14: 45790 | C14: 1 | D14: 1 | E14: 0 | F14: 1 | G14: 0 | H14: 1 | I14: 1 | J14: 0.75 | K14: 1 | L14: 1 | M14: 0 | N14: 1 | O14: 0.5 | P14: 1 | Q14: 0 | R14: Yasmine darete retard de 20 min , akila est arrivée à 09h et Rayane à 11h mais kanet autorisée
A15: Mercredi | B15: 45791 | C15: 1 | D15: 1 | E15: 0 | F15: 1 | G15: 0 | H15: 1 | I15: 0 | J15: 1 | K15: 1 | L15: 1 | M15: 0 | N15: 1 | O15: 1 | P15: 1 | Q15: 0 | R15: Meriem est arrivée à 10h
A16: Jeudi | B16: 45792 | C16: 0 | D16: 1 | E16: 0 | F16: 1 | G16: 0 | H16: 1 | I16: 0 | J16: 1 | K16: 1 | L16: 1.25 | M16: 0 | N16: 1 | O16: 0.5 | P16: 1 | Q16: 1 | R16: Yasmine est venu 10 min en retard sans me prévenir à l'avance /wafa
A17: Vendredi | B17: 45793 | C17: 0 | D17: 1 | E17: 0 | F17: 1 | G17: 0 | H17: 1 | I17: 1 | J17: 1.5 | K17: 0 | L17: 0 | M17: 0 | N17: 0 | O17: 0 | P17: 1.5 | Q17: 0 | R17: Rayan et Akila ont fait le ménage
A18: Samedi | B18: 45794 | C18: 1 | D18: 1 | E18: 0 | F18: 1 | G18: 0 | H18: 1 | I18: 0 | J18: 1 | K18: 0 | L18: 1 | M18: 0 | N18: 0 | O18: 0 | P18: 0 | Q18: 0
A19: Dimanche | B19: 45795 | C19: 1 | D19: 0.5 | E19: 0 | F19: 0 | G19: 0 | H19: 1 | I19: 1 | J19: 1 | K19: 1 | L19: 1 | M19: 0 | N19: 1 | O19: 0 | P19: 0 | Q19: 0 | R19: Yasmine est arrivé 10min en retard sans me prévenir
A20: Lundi | B20: 45796 | C20: 1 | D20: 1 | E20: 0 | F20: 1 | G20: 0 | H20: 1 | I20: 0 | J20: 0.5 | K20: 1 | L20: 1 | M20: 0 | N20: 0 | O20: 0 | P20: 1 | Q20: 0 | R20: Rayan djate à 10h30
A21: Mardi | B21: 45797 | C21: 1 | D21: 1 | E21: 0 | F21: 1 | G21: 1.25 | H21: 0 | I21: 1 | J21: 1 | K21: 1 | L21: 1 | M21: 1 | N21: 1 | O21: 0 | P21: 1 | Q21: 0
A22: Mercredi | B22: 45798 | C22: -1 | D22: 1 | E22: 0 | F22: 1 | G22: 0 | H22: 1 | I22: 0 | J22: 1 | K22: 1 | L22: 1 | M22: 1 | N22: 0 | O22: 0 | P22: 1 | Q22: 0 | R22: Saida s'est absentée sans me prévenir malgré j'ai insisté avec elle
A23: Jeudi | B23: 45799 | C23: 1 | D23: 1 | E23: 0 | F23: 1 | G23: 0 | H23: 1 | I23: 1 | J23: 1 | K23: 1 | L23: 1 | M23: 1 | N23: 1 | O23: 0 | P23: 1 | Q23: 0 | R23: Yasmine djate en retard 10min et elle a menti 9ateli rani 9oudam dar Kamalate we hier kanet be3ida
A24: Vendredi | B24: 45800 | C24: 0 | D24: 1 | E24: 0 | F24: 1 | G24: 0 | H24: 1 | I24: 0 | J24: 1 | K24: 1 | L24: 0 | M24: 1 | N24: 1 | O24: 0 | P24: 1 | Q24: 0 | R24: Akila et Rayan djaw à 07h et Amina djate fel OFF deyaleha et Samira était malade et il y'avait pas de transport we djate
A25: Samedi | B25: 45801 | C25: 1 | D25: 1 | E25: 0 | F25: 1 | G25: 0 | H25: 1 | I25: 1 | J25: 1 | K25: 0 | L25: 1 | M25: 1 | N25: 0 | O25: 0 | P25: 1 | Q25: 0
A26: Dimanche | B26: 45802 | C26: 1 | D26: 1 | E26: 0 | F26: 0 | G26: 1 | H26: 0 | I26: 0 | J26: 1 | K26: 1 | L26: 1 | M26: 1 | N26: 0 | O26: 0 | P26: 1 | Q26: 0 | R26: Houda djate a 08h45 e kharedjet à 18h30
A27: Lundi | B27: 45803 | C27: 1 | D27: 0 | E27: 0 | F27: 1 | G27: 0 | H27: 1 | I27: 1 | J27: 0 | K27: 1 | L27: 1 | M27: 0 | N27: 0 | O27: 0 | P27: 1 | Q27: 0
A28: Mardi | B28: 45804 | C28: 1 | D28: 1 | E28: 0 | F28: 1 | G28: 0 | H28: 1 | I28: 0 | J28: 1 | K28: 1 | L28: 1 | M28: 1 | N28: 1 | O28: 0 | P28: 1 | Q28: 0 | R28: Yasmine djate en retard puisque Houda n'a pas pu la remplacer Meriem a assuer le poste de vendeuse de 09h jusqua 11h30
A29: Mercredi | B29: 45805 | C29: 1 | D29: 1 | E29: 0 | F29: 1 | G29: 1.5 | H29: 0 | I29: 1 | J29: 1 | K29: 0 | L29: 1 | M29: 1 | N29: 0 | O29: 0 | P29: 1 | Q29: 0
A30: Jeudi | B30: 45806 | C30: 1 | D30: 1 | E30: 0 | F30: 1 | G30: 0 | H30: 1 | I30: 0 | J30: 1 | K30: 0 | L30: 1 | M30: 1 | N30: 1 | O30: 0 | P30: 1 | Q30: 0
A31: Vendredi | B31: 45807 | C31: 0 | D31: 1 | E31: 0 | F31: 0 | G31: 0 | H31: 1 | I31: 1 | J31: 0 | K31: 0 | L31: 0 | M31: 1 | N31: 1.25 | O31: 0 | P31: 0 | Q31: 1.5
A32: samedi | B32: 45808 | C32: 1 | D32: 1 | E32: 0 | F32: 1 | G32: 0 | H32: 1 | I32: 1 | J32: 1 | K32: 1 | L32: 1 | M32: 0 | N32: 0 | O32: 0 | P32: 1 | Q32: 1.5
B33: Totale | C33: =SUM(C2:C32) -> 22 | D33: =SUM(D2:D32) -> 28 | E33: =SUM(E2:E32) -> 9 | F33: =SUM(F2:F32) -> 24.75 | G33: =SUM(G2:G32) -> 6 | H33: =SUM(H2:H32) -> 25.7 | I33: =SUM(I2:I32) -> 25.66 | J33: =SUM(J2:J32) -> 23.75 | ... Q33: =SUM(Q2:Q32) -> 4
C34: 1200 | D34: 1155 | E34: 1155 | F34: 1270 | G34: 1155 | H34: 1155 | I34: 1155 | J34: 1347 | K34: 1347 | L34: 1155 | M34: 1200 | N34: 1155 | O34: 1155 | P34: 1400 | Q34: 1000
C35: =C33*C34 -> 26400 | D35: =D33*D34 -> 32340 | E35: =E33*E34 -> 10395 | F35: =F33*F34 -> 31432.5 | G35: =G33*G34 -> 6930 | H35: =H33*H34 -> 29683.5 | I35: =I33*I34 -> 29637.3 | J35: =J33*J34 -> 31991.25 | ... Q35: =Q33*Q34 -> 4000
C37: 1270
C38: =C33*C37 -> 27940

Sheet Les Salaires
H5: Nom | I5: Salaire | J5: Avance | K5: Salaire à payer
H6: Sofiane | I6: 30000 | J6: 30000 | K6: =I6-J6 -> 0
H7: Amel | I7: 30000 | J7: 30000 | K7: =I7-J7 -> 0
G8: 1 | H8: Saida | I8: =Pointage!C35 -> 26400 | J8: 26500 | K8: =I8-J8 -> -100 | L8: 3000+2000
G9: 2 | H9: Fatiha | I9: =Pointage!D35 -> 32340 | J9: 33000 | K9: =I9-J9 -> -660 | L9: 1000+5000+4000+5000+3000+3000+2000
G10: 3 | H10: Assia | I10: =Pointage!E35 -> 10395 | J10: 11000 | K10: =I10-J10 -> -605 | L10: 3000+2000+1000+1000+4000
G11: 4 | H11: Samira | I11: =Pointage!F35 -> 31432.5 | J11: 31500 | K11: =I11-J11 -> -67.5 | L11: 4000+5000+3000+1000+18500
G12: 5 | H12: Nour ElHouda | I12: =Pointage!G35 -> 6930 | J12: 7000 | K12: =I12-J12 -> -70
G13: 6 | H13: Yasmine | I13: =Pointage!H35+L13 -> 34683.5 | J13: 35000 | K13: =I13-J13 -> -316.5 | L13: 5000
G14: 7 | H14: Zohra | I14: =Pointage!I35 -> 29637.3 | J14: 30000 | K14: =I14-J14 -> -362.7 | L14: 10k rapelle
G15: 8 | H15: Rayan | I15: =Pointage!J35 -> 31991.25 | J15: 32000 | K15: =I15-J15 -> -8.75
G16: 11 | H16: Amina Ain Beniane | I16: =Pointage!K35 -> 26940 | J16: 27000 | K16: =I16-J16 -> -60
G17: 12 | H17: Ahlem | I17: 30000 | J17: 30000 | K17: 0
G18: 14 | H18: Samira | I18: =Pointage!M35 -> 12000 | J18: 12000 | K18: =I18-J18 -> 0 | L18: 3000+9000+
G19: 15 | H19: Merioma | I19: =Pointage!N35 -> 15303.75 | J19: 15500 | K19: =I19-J19 -> -196.25 | L19: 3000+2000+10500
G20: 16 | H20: Kamilia | I20: =Pointage!O35 -> 2310 | J20: 3000 | K20: =I20-J20 -> -690
H21: Akila | I21: =Pointage!P35 -> 39900 | J21: 40000 | K21: =I21-J21 -> -100
G22: 17 | H22: Backup | I22: =Pointage!Q35 -> 4000 | J22: 4000 | K22: =I22-J22 -> 0 | L22: wafa+3000Da Alia
H23: TOTAL | I23: =SUM(I6:I22) -> 394263.3 | J23: =SUM(J6:J22) -> 397500 | K23: =I23-J23 -> -3236.7
K24: =I24-J24 -> 0

Sheet Comparaison entre les Mois 
E17: Mois de Janvier 2025 | F17: Mois de Février 2025 | G17: Mois de Mars 2025 | H17: Mois d'Avril 2025 | I17: Mois de Mai 2025 | N17: Mois de Mai 2025
D18: Recette | E18: 2033000 | F18: 1859000 | G18: 2094000 | H18: 1282000 | I18: =RECAP!D33 -> 2077000 | M18: Recette | N18: 2077000
D19: Charges | E19: 854000 | F19: 884000 | G19: 962000 | H19: 669000 | I19: 800000 | M19: Charges | N19: 800000
D20: Salaires | E20: 427000 | F20: 409000 | G20: 439000 | H20: 338000 | I20: 385000 | M20: Salaires | N20: 385000
D21: Che7i7a | E21: 62000 | F21: 56000 | G21: 60000 | H21: 50000 | I21: =RECAP!G33 -> 62000 | M21: Che7i7a | N21: 62000
D22: Loyer+Dettes | E22: 180000 | F22: 180000 | G22: 180000 | H22: 180000 | I22: 180000 | M22: Loyer+Dettes | N22: 180000
D23: Profit Net | E23: =E18-E19-E20-E21-E22 -> 510000 | F23: =F18-F19-F20-F21-F22 -> 330000 | G23: =G18-G19-G20-G21-G22 -> 453000 | H23: =H18-H19-H20-H21-H22 -> 45000 | I23: =I18-I19-I20-I21-I22 -> 650000 | M23: Profit Net | N23: =N18-N19-N20-N21-N22 -> 650000
