Workbook

Sheet RECAP
B1: Date | C1: 45323 | D1: Recette | E1: Charges | F1: Salaire | G1: Loyer | H1: Net Profit | I1: Nb de jours | K1: Objectif | L1: 45323
A2: Vendredi | B2: 45352 | C2: 76000 | D2: 63000 | I2: 1 | L2: 76000
A3: Samedi | B3: 45353 | C3: 70000 | D3: 32000 | I3: 1 | L3: 70000 | M3: Bénéfice Moyen par jour | N3: Moyenne | O3: Moyenne salaire | P3: pourcentage du salaire vis à vis la recettte
A4: Dimanche | B4: 45354 | C4: 33000 | D4: 45000 | I4: 1 | L4: 33000 | M4: =H33/I33 -> 16451.613 | N4: =D33/I33 -> 64000 | P4: =F33/D33 -> 0.2046371
A5: Lundi | B5: 45355 | C5: 45000 | D5: 73000 | I5: 1 | L5: 45000
A6: Mardi | B6: 45356 | C6: 56000 | D6: 65000 | I6: 1 | L6: 56000 | M6: Moyenne des charges par jour | N6: Objectif
A7: Mercredi | B7: 45357 | C7: 35000 | D7: 62000 | I7: 1 | L7: 35000 | M7: =E33/I33 -> 29935.484 | N7: 100000
A8: Jeudi | B8: 45358 | C8: 62000 | D8: 70000 | I8: 1 | L8: 62000 | M8: ²
A9: Vendredi | B9: 45359 | C9: 110000 | D9: 43000 | I9: 1 | L9: 110000
A10: Samedi | B10: 45360 | C10: 45000 | D10: 85000 | I10: 1 | L10: 45000 | M10: Cash restant | N10: Magasin | O10: Cash réel | P10: Mes dettes pour le magasin
A11: Dimanche | B11: 45361 | C11: 55000 | D11: 100000 | I11: 1 | L11: 55000 | M11: =M14+D33-E33-Salaires!K27-N11 -> 693000 | N11: 296000 | O11: 816000 | P11: =M11-O11 -> -123000
A12: Lundi | B12: 45362 | C12: 37000 | D12: 55000 | I12: 1 | L12: 37000
A13: Mardi | B13: 45363 | C13: 72000 | D13: 70000 | I13: 1 | L13: 72000 | M13: Fond de Roulement
A14: Mercredi | B14: 45364 | C14: 50000 | D14: 60000 | I14: 1 | L14: 50000 | M14: 342000 | P14: Demain je prends de la caisse: 18000Da
A15: Jeudi | B15: 45365 | C15: 65000 | D15: 80000 | I15: 1 | L15: 65000
A16: Vendredi | B16: 45366 | C16: 115000 | D16: 52000 | I16: 1 | L16: 115000 | O16: Cash réel: 790000Da | P16: 140000+424000+330000-12000-284000-8000
A17: Samedi | B17: 45367 | C17: 65000 | D17: 54000 | I17: 1 | L17: 65000
A18: Dimanche | B18: 45368 | C18: 162000 | D18: 52000 | I18: 1 | L18: 162000 | O18: Che7i7a: 20000Da | P18: les charges Avril: 284000Da
A19: Lundi | B19: 45369 | C19: 115000 | D19: 50000 | I19: 1 | L19: 115000 | M19: Différence mois de Février | P19: la vraie caisse: 12000Da
A20: Mardi | B20: 45370 | C20: 60000 | D20: 50000 | I20: 1 | L20: 60000 | M20: =D33-C33 -> -290000
A21: Mercredi | B21: 45371 | C21: 85000 | D21: 54000 | I21: 1 | L21: 85000 | M21: Différence objectif | O21: réparation Tabouna | P21: 1 | Q21: 8800 | R21: =P21*Q21 -> 8800
A22: Jeudi | B22: 45372 | C22: 100000 | D22: 70000 | I22: 1 | L22: 100000 | M22: =K36-E36 -> 0 | O22: Torchons | P22: 4 | Q22: 400 | R22: 600
A23: Vendredi | B23: 45373 | C23: 120000 | D23: 76000 | I23: 1 | L23: 120000 | M23: Différence du Totale | O23: poelle | P23: 1 | Q23: 2800 | R23: =P23*Q23 -> 2800
A24: Samedi | B24: 45374 | C24: 190000 | D24: 63000 | I24: 1 | L24: 190000 | M24: =D33-C33 -> -290000 | R24: =SUM(R21:R23) -> 12200
A25: Dimanche | B25: 45375 | C25: 70000 | D25: 90000 | I25: 1 | L25: 70000 | M25: Les vendredis
A26: Lundi | B26: 45376 | C26: 113000 | D26: 66000 | I26: 1 | L26: 113000 | M26: =D2+D9+D16+D23+D30 -> 275000
A27: Mardi | B27: 45377 | C27: 75000 | D27: 83000 | I27: 1 | L27: 75000
A28: Mercredi | B28: 45378 | C28: 65000 | D28: 52000 | I28: 1 | L28: 65000
A29: Jeudi | B29: 45379 | C29: 43000 | D29: 72000 | I29: 1 | L29: 43000
A30: Vendredi | B30: 45380 | C30: 85000 | D30: 41000 | I30: 1 | L30: 85000
A31: Samedi | B31: 45381 | C31: 0 | D31: 70000 | I31: 1 | L31: 0
A32: Dimanche | B32: 45382 | C32: 0 | D32: 86000 | I32: 1 | L32: 0
C33: =SUM(C2:C32) -> 2274000 | D33: =SUM(D2:D32) -> 1984000 | E33: ='Les Charges '!G461 -> 928000 | F33: 406000 | G33: 140000 | H33: =D33-E33-F33-G33 -> 510000 | I33: =SUM(I2:I32) -> 31 | L33: =SUM(L2:L32) -> 2274000
D35: 2274000 | E35: 914000 | F35: 410000 | G35: 140000 | H35: 810000 | M35: =M11-M29-M34 -> 693000

Sheet Pointage
B1: Date | C1: Lynda | D1: Hafida | E1: Dalila | F1: Yasmine Sidi Abd Allah | G1: Kenza | H1: Yasmine Dely Brahim | I1: Fouzia | J1: Nadjet | K1: Alia | L1: Fatiha | M1: Samira | N1: Asma | O1: Zohra | P1: Sarah | Q1: Chiraz | R1: Romaissa
A2: Vendredi | B2: 45352 | C2: 1 | D2: 0 | E2: 1 | F2: 1 | G2: 1 | H2: 1 | I2: 0 | J2: 0 | K2: 0 | L2: 0 | M2: 1 | N2: 1 | O2: 0 | P2: 0 | Q2: 1 | R2: 1
A3: Samedi | B3: 45353 | C3: 1 | D3: 0 | E3: 1 | F3: 1 | G3: 1 | H3: 0 | I3: 0 | J3: 0 | K3: 0 | L3: 1 | M3: 1 | N3: 1 | O3: 0 | P3: 0 | Q3: 0 | R3: 1
A4: Dimanche | B4: 45354 | C4: 0 | D4: 1 | E4: 1 | F4: 0 | G4: 0 | H4: 1 | I4: 1 | J4: 0 | K4: 0.5 | L4: 1 | M4: 1 | N4: 0.5 | O4: 0 | P4: 1 | Q4: 1 | R4: 0 | S4: Asma est sortie sans autorisation + Fatiha est sortie sans terminer son travaille
A5: Lundi | B5: 45355 | C5: 0 | D5: 1 | E5: 1 | F5: 1 | G5: 0 | H5: 0 | I5: 1 | J5: 0 | K5: 0 | L5: 1 | M5: 0 | N5: 0 | O5: 0 | P5: 1 | Q5: 1 | R5: 1 | S5: Hafida djate à 09h comme hier
A6: Mardi | B6: 45356 | C6: 0.5 | D6: 1 | E6: 1 | F6: 1 | G6: 0 | H6: 0 | I6: 0 | J6: 0 | K6: 0 | L6: 1 | M6: 1 | N6: 0 | O6: 0 | P6: 1 | Q6: 1 | R6: 1 | S6: Hadida djate à 09h30 à cause des analyses et Lynda daret chebah sofra
A7: Mercredi | B7: 45357 | C7: 0 | D7: 0 | E7: 0 | F7: 1 | G7: 0 | H7: 0 | I7: 1 | J7: 1 | K7: 0.5 | L7: 1 | M7: 1 | N7: 0 | O7: 0 | P7: 1 | Q7: 1 | R7: 1
A8: Jeudi | B8: 45358 | C8: 0.5 | D8: 1 | E8: 1 | F8: 1 | G8: 0 | H8: 1 | I8: 0.75 | J8: 1 | K8: 1 | L8: 1 | M8: 0 | N8: 0 | O8: 0 | P8: 1 | Q8: 1 | R8: 1
A9: Vendredi | B9: 45359 | C9: 1 | D9: 1 | E9: 0 | F9: 1 | G9: 1 | H9: 1 | I9: 1 | J9: 0 | K9: 1 | L9: 0 | M9: 0 | N9: 0 | O9: 0 | P9: 1 | Q9: 0 | R9: 0 | S9: sarah et Fouzia kharedjou à 14h
A10: Samedi | B10: 45360 | C10: 1 | D10: 0 | E10: 1 | F10: 0.5 | G10: 0 | H10: 0 | I10: 0 | J10: 1 | K10: 0 | L10: 1 | M10: 0 | N10: 0 | O10: 0 | P10: 0 | Q10: 1 | R10: 1 | V10: Date | W10: Samira
A11: Dimanche | B11: 45361 | C11: 0.5 | D11: 1 | E11: 1 | F11: 0 | G11: 0 | H11: 1 | I11: 1 | J11: 0 | K11: 1 | L11: 1 | M11: 0 | N11: 0 | O11: 0 | P11: 0 | Q11: 1 | R11: 0 | U11: Vendredi | V11: 45352 | W11: 1
A12: Lundi | B12: 45362 | C12: 0.5 | D12: 1 | E12: 0 | F12: 1 | G12: 0 | H12: 0.25 | I12: 1 | J12: 0 | K12: 0 | L12: 1 | M12: 1 | N12: 0 | O12: 0 | P12: 1 | Q12: 0.5 | R12: 1 | U12: Samedi | V12: 45353 | W12: 1
A13: Mardi | B13: 45363 | C13: 0 | D13: 1 | E13: 0 | F13: 1 | G13: 0 | H13: 0.25 | I13: 1 | J13: 1 | K13: 0 | L13: 1 | M13: 1 | N13: 0 | O13: 0 | P13: 1 | Q13: 0 | R13: 1 | U13: Dimanche | V13: 45354 | W13: 1
A14: Mercredi | B14: 45364 | C14: 0.5 | D14: 1 | E14: 0 | F14: 1 | G14: 0 | H14: 0.25 | I14: 1 | J14: 1 | K14: 0 | L14: 1 | M14: 1 | N14: 0 | O14: 0 | P14: 1 | Q14: 0 | R14: 1 | U14: Lundi | V14: 45355 | W14: 0
A15: Jeudi | B15: 45365 | C15: 0.5 | D15: 1 | E15: 0 | F15: 1 | G15: 0 | H15: 1 | I15: 1 | J15: 1 | K15: 0 | L15: 1 | M15: 1 | N15: 0 | O15: 0 | P15: 1 | Q15: 1 | R15: 1 | U15: Mardi | V15: 45356 | W15: 1
A16: Vendredi | B16: 45366 | C16: 1 | D16: 1 | E16: 0 | F16: 1 | G16: 1 | H16: 0 | I16: 0 | J16: 0 | K16: 0 | L16: 0 | M16: 1 | N16: 0 | O16: 0 | P16: 0 | Q16: 1 | R16: 0 | U16: Mercredi | V16: 45357 | W16: 1
A17: Samedi | B17: 45367 | C17: 1 | D17: 1 | E17: 0 | F17: 1 | G17: 0 | H17: 0.25 | I17: 0 | J17: 0 | K17: 0 | L17: 1 | M17: 1 | N17: 0 | O17: 0 | P17: 1 | Q17: 1 | R17: 1 | U17: Jeudi | V17: 45358 | W17: 0
A18: Dimanche | B18: 45368 | C18: 0 | D18: 1 | E18: 0 | F18: 1 | G18: 0 | H18: 1 | I18: 1 | J18: 0.5 | K18: 0 | L18: 1 | M18: 0 | N18: 0 | O18: 0 | P18: 1 | Q18: 1 | R18: 1 | U18: Vendredi | V18: 45359 | W18: 0
A19: Lundi | B19: 45369 | C19: 0 | D19: 1 | E19: 0 | F19: 1 | G19: 0 | H19: 0.25 | I19: 1 | J19: 1 | K19: 0 | L19: 1 | M19: 0 | N19: 0 | O19: 0 | P19: 1 | Q19: 0.5 | R19: 1 | U19: Samedi | V19: 45360 | W19: 0
A20: Mardi | B20: 45370 | C20: 0.5 | D20: 1 | E20: 0 | F20: 1 | G20: 0 | H20: 0.25 | I20: 1 | J20: 1 | K20: 0 | L20: 1 | M20: 0 | N20: 0 | O20: 0 | P20: 1 | Q20: 0 | R20: 1 | S20: Fouzia + Sarah djaw à 11h à cause d'une panne de voiture | U20: Dimanche | V20: 45361 | W20: 0
A21: Mercredi | B21: 45371 | C21: 0.5 | D21: 1 | E21: 0 | F21: 1 | G21: 0 | H21: 0.5 | I21: 1 | J21: 1 | K21: 0 | L21: 1 | M21: 0 | N21: 0 | O21: 0 | P21: 1 | Q21: 1 | R21: 1 | U21: Lundi | V21: 45362 | W21: 1
A22: Jeudi | B22: 45372 | C22: 1 | D22: 1 | E22: 0 | F22: 1 | G22: 0 | H22: 1 | I22: 0.75 | J22: 1 | K22: 0 | L22: 0 | M22: 0 | N22: 0 | O22: 1 | P22: 1 | Q22: 1 | R22: 1 | S22: fouzia djate à 12h | U22: Mardi | V22: 45363 | W22: 1
A23: Vendredi | B23: 45373 | C23: 1.5 | D23: 1 | E23: 0 | F23: 1.5 | G23: 1 | H23: 1 | I23: 0 | J23: 0 | K23: 0 | L23: 0 | M23: 1 | N23: 0 | O23: 0 | P23: 0 | Q23: 1.5 | R23: 1 | U23: Mercredi | V23: 45364 | W23: 1
A24: Samedi | B24: 45374 | C24: 1.5 | D24: 1 | E24: 0 | F24: 1 | G24: 1 | H24: 1 | I24: 0 | J24: 1 | K24: 0 | L24: 1 | M24: 1 | N24: 0 | O24: 0 | P24: 0 | Q24: 1 | R24: 1 | U24: Jeudi | V24: 45365 | W24: 1
A25: Dimanche | B25: 45375 | C25: 1 | D25: 1 | E25: 0 | F25: 0 | G25: 1 | H25: 1 | I25: 0 | J25: 1 | K25: 0 | L25: 1 | M25: 1 | N25: 0 | O25: 0 | P25: 0 | Q25: 1 | R25: 0 | U25: Vendredi | V25: 45366 | W25: 1
A26: Lundi | B26: 45376 | C26: 1 | D26: 1 | E26: 0 | F26: 1 | G26: 1 | H26: 0.5 | I26: 0 | J26: 1 | K26: 0 | L26: 1 | M26: 1 | N26: 0 | O26: 1 | P26: 0 | Q26: 1.5 | R26: 1 | U26: Samedi | V26: 45367 | W26: 1
A27: Mardi | B27: 45377 | C27: 1 | D27: 1 | E27: 0 | F27: 1 | G27: 0 | H27: 0 | I27: 0 | J27: 0 | K27: 0 | L27: 1 | M27: 1 | N27: 0 | O27: 0 | P27: 0 | Q27: 1 | R27: 1 | U27: Dimanche | V27: 45368 | W27: 0
A28: Mercredi | B28: 45378 | C28: 1.5 | D28: 1 | E28: 0 | F28: 1 | G28: 0 | H28: 0 | I28: 0 | J28: 1 | K28: 0 | L28: 1 | M28: 1 | N28: 0 | O28: 0 | P28: 1 | Q28: 1 | R28: 1 | U28: Lundi | V28: 45369 | W28: 0
A29: Jeudi | B29: 45379 | C29: 1 | D29: 1 | E29: 0 | F29: 1 | G29: 0 | H29: 0 | I29: 0 | J29: 1 | K29: 0 | L29: 1 | M29: 1 | N29: 0 | O29: 1 | P29: 1 | Q29: 1 | R29: 1 | U29: Mardi | V29: 45370 | W29: 0
A30: Vendredi | B30: 45380 | C30: 1 | D30: 1 | E30: 0 | F30: 1 | G30: 0 | H30: 0 | I30: 0 | J30: 0 | K30: 0 | L30: 0 | M30: 1 | N30: 0 | O30: 0 | P30: 1 | Q30: 1 | R30: 1 | U30: Mercredi | V30: 45371 | W30: 0
A31: Samedi | B31: 45381 | C31: 1 | D31: 1 | E31: 0 | F31: 1 | G31: 0 | H31: 0 | I31: 1 | J31: 1 | K31: 0 | L31: 1 | M31: 1 | N31: 0 | O31: 0 | P31: 1 | Q31: 1 | R31: 1 | U31: Jeudi | V31: 45372 | W31: 0
A32: Dimanche | B32: 45382 | C32: 1 | D32: 1 | E32: 0 | F32: 1 | G32: 0 | H32: 0 | I32: 1 | J32: 1 | K32: 0 | L32: 1 | M32: 1 | N32: 0 | O32: 1 | P32: 1 | Q32: 1 | R32: 1 | U32: Vendredi | V32: 45373 | W32: 1
C33: =SUM(C2:C30) -> 20.5 | D33: =SUM(D2:D32) -> 27 | E33: =SUM(E2:E32) -> 8 | F33: =SUM(F2:F32) -> 28 | G33: =SUM(G2:G32) -> 8 | H33: =SUM(H2:H32) -> 13.5 | I33: =SUM(I2:I32) -> 16.5 | J33: =SUM(J2:J32) -> 17.5 | K33: =SUM(K2:K32) -> 4 | ... R33: =SUM(R2:R32) -> 26 | U33: Samedi | V33: 45374 | W33: 1
C34: 1384.62 | D34: 1384.62 | E34: 1153.85 | F34: 1153.85 | G34: 1153.85 | H34: 1153.85 | I34: 1384.62 | J34: 1500 | K34: 1153.85 | L34: 1076.93 | M34: 1153.85 | N34: 1153.85 | O34: 1076.93 | P34: 1230.77 | Q34: 1153.85 | R34: 1076.93 | U34: Dimanche | V34: 45375 | W34: 1
C35: =C33*C34 -> 28384.71 | D35: =D34*D33 -> 37384.74 | E35: =E34*E33 -> 9230.8 | F35: =F34*F33 -> 32307.8 | G35: =G34*G33 -> 9230.8 | H35: =H34*H33 -> 15576.975 | I35: =I33*I34 -> 22846.23 | J35: =J33*J34 -> 26250 | K35: =K33*K34 -> 4615.4 | L35: =L33*L34 -> 26923.25 | M35: =M34*M33 -> 24230.85 | N35: =N33*N34 -> 2884.625 | O35: =O34*O33 -> 4307.72 | P35: =P33*P34 -> 25846.17 | Q35: =Q33*Q34 -> 30000.1 | R35: =R33*R34 -> 28000.18 | S35: =SUM(C33:P33) -> 216.5 | U35: Lundi | V35: 45376 | W35: 1
C36: 36000 | D36: 36000 | E36: 30000 | F36: 30000 | G36: 30000 | H36: 30000 | I36: 36000 | K36: 30000 | L36: 28000 | M36: 30000 | N36: 30000 | O36: 28000 | P36: 32000 | Q36: 30000 | R36: 28000 | U36: Mardi | V36: 45377 | W36: 1
U37: Mercredi | V37: 45378 | W37: 1
U38: Jeudi | V38: 45379 | W38: 1
U39: Vendredi | V39: 45380 | W39: 1
U40: Samedi | V40: 45381 | W40: 1
...

Sheet Les Charges 
D2: Produit | E2: Quantité | F2: Prix unitaire | G2: Prix | H2: Date d'achat
D3: huile Elio 5 litres | E3: 14 | F3: 600 | G3: =E3*F3 -> 8400
D4: Fleurial 250g | E4: 26 | F4: 85 | G4: =E4*F4 -> 2210
D5: Fleurial 500g | E5: 12 | F5: 195 | G5: =E5*F5 -> 2340
D6: Sucre cristalisé 25kg | E6: 5 | F6: 104 | G6: =E6*F6 -> 520
D7: Semoule Moyenne Moula 2kg | E7: 7 | F7: 250 | G7: =E7*F7 -> 1750
D8: Farine Sim 1kg | E8: 52 | F8: 84 | G8: =E8*F8 -> 4368
D9: Confiture 1 kg | E9: 2 | F9: 240 | G9: =E9*F9 -> 480
D10: Levure Boulangère | E10: 11 | F10: 390 | G10: =E10*F10 -> 4290
D11: Maizina | E11: 5 | F11: 180 | G11: =E11*F11 -> 900
D12: Maiis | E12: 18 | F12: 250 | G12: =E12*F12 -> 4500
D13: chocolat wedjedane Noisette | E13: 1 | F13: 235 | G13: =E13*F13 -> 235
D14: chocolat wedjedane au lait | E14: 0 | F14: 235 | G14: =E14*F14 -> 0
... D119: Bessel | E119: 25 | F119: 80 | G119: =E119*F119 -> 2000
D120: Bessel | E120: 25 | F120: 80 | G120: =E120*F120 -> 2000 | H120: 45358
D121: Blanc de poulet | E121: 1 | F121: 1000 | G121: =E121*F121 -> 1000
D122: rechta | E122: 20 | F122: 100 | G122: =E122*F122 -> 2000
D123: Deyoul grande taille | E123: 35 | F123: 120 | G123: =E123*F123 -> 4200
D124: Deyoul petite taille | E124: 30 | F124: 100 | G124: =E124*F124 -> 3000
D125: ketayef | E125: 12 | F125: 80 | G125: =E125*F125 -> 960
D126: Livraison chebah Sofra | E126: 2 | F126: 500 | G126: =E126*F126 -> 1000
D127: netoyage vitres | E127: 1 | F127: 1000 | G127: =E127*F127 -> 1000
D128: livraison Ka3ek nakkach | E128: 2 | F128: 500 | G128: =E128*F128 -> 1000
D129: Huile Elio 2 litres | E129: 42 | F129: 236 | G129: =E129*F129 -> 9912 | H129: 45358
D130: Sucre cristalisé 25kg | E130: 25 | F130: 104 | G130: =E130*F130 -> 2600
D131: Légumes | E131: 1 | F131: 200 | G131: =E131*F131 -> 200
D132: Tomate fraiche | E132: 2 | F132: 100 | G132: =E132*F132 -> 200
D133: Tomate fraiche dure | E133: 2 | F133: 150 | G133: =E133*F133 -> 300
D134: cuisses de poulet | E134: 4 | F134: 220 | G134: =E134*F134 -> 880
D135: Olive noir | E135: 1 | F135: 400 | G135: =E135*F135 -> 400
D136: olive éfilet | E136: 0.5 | F136: 600 | G136: =E136*F136 -> 300
D137: crème liquide | E137: 2 | F137: 200 | G137: =E137*F137 -> 400
D138: pain tacos | E138: 2 | F138: 280 | G138: =E138*F138 -> 560
D139: bessel | E139: 25 | F139: 80 | G139: =E139*F139 -> 2000
D140: bessel | E140: 20 | F140: 75 | G140: =E140*F140 -> 1500
D141: Amande moulu | E141: 10 | F141: 1300 | G141: =E141*F141 -> 13000
... D156: Maa zehar | E156: 12 | F156: 70 | G156: =E156*F156 -> 840
D157: deyoul | E157: 65 | F157: 100 | G157: =E157*F157 -> 6500 | H157: 45362
D158: Deyoul grande taille | E158: 20 | F158: 120 | G158: =E158*F158 -> 2400
D159: hamissa | E159: 1 | F159: 200 | G159: =E159*F159 -> 200
...

Sheet Salaires
I8: Nom | J8: Salaire | K8: Avance | L8: Salaire à payer
I9: Sofiane | J9: 30000 | K9: 30000 | L9: =J9-K9 -> 0
I10: Amel | J10: 30000 | K10: 30000 | L10: =J10-K10 -> 0
H11: 1 | I11: Lynda | J11: =Pointage!C35 -> 28384.71 | K11: 28500 | L11: =J11-K11 -> -115.29
H12: 2 | I12: Hafida | J12: =Pointage!D35 -> 37384.74 | K12: 37500 | L12: =J12-K12 -> -115.26 | M12: 5000+2000 | N12: Mras | O12: Février
H13: 3 | I13: Romayssa | J13: =N13+O13 -> 41000.18 | K13: 41000 | L13: =J13-K13 -> 0.18 | N13: =Pointage!R35 -> 28000.18 | O13: 13000
H14: 4 | I14: Dalila | J14: =Pointage!E35 -> 9230.8 | K14: 9500 | L14: =J14-K14 -> -269.2
H15: 5 | I15: Yasmine Sidi Abd Allah | J15: =N15+O15 -> 37307.8 | K15: 37500 | L15: =J15-K15 -> -192.2 | N15: =Pointage!F35 -> 32307.8 | O15: 5000
H16: 6 | I16: Kenza | J16: =Pointage!G35 -> 9230.8 | K16: 9500 | L16: =J16-K16 -> -269.2
H17: 7 | I17: Yasmine Dely Brahim | J17: =Pointage!H35 -> 15576.975 | K17: 16000 | L17: =J17-K17 -> -423.025
H18: 8 | I18: Nadjet | J18: =Pointage!J35 -> 26250 | K18: 26500 | L18: =J18-K18 -> -250 | M18: 4500+1000
H19: 9 | I19: Samira | J19: =Pointage!M35 -> 24230.85 | K19: 24500 | L19: =J19-K19 -> -269.15 | M19: 1000+1000
H20: 10 | I20: Alia | J20: =Pointage!K35 -> 4615.4 | K20: 5000 | L20: =J20-K20 -> -384.6
H21: 11 | I21: Asma | J21: =Pointage!N35 -> 2884.625 | K21: 3000 | L21: =J21-K21 -> -115.375
H22: 12 | I22: Fatiha | J22: =Pointage!L35 -> 26923.25 | K22: 27000 | L22: =J22-K22 -> -76.75
H23: 13 | I23: Zohra | J23: =Pointage!O35 -> 4307.72 | K23: 4500 | L23: =J23-K23 -> -192.28
H24: 14 | I24: Sarah | J24: =Pointage!P35 -> 25846.17 | K24: 26000 | L24: =J24-K24 -> -153.83 | M24: 7000+5000+7500
H25: 15 | I25: Chiraz | J25: =Pointage!Q35 -> 30000.1 | K25: 30000 | L25: =J25-K25 -> 0.1
H26: 16 | I26: Fouzia | J26: =Pointage!I35 -> 22846.23 | K26: 23000 | L26: =J26-K26 -> -153.77
I27: TOTAL | J27: =SUM(J9:J26) -> 406020.35 | K27: =SUM(K9:K26) -> 409000 | L27: =SUM(L9:L26) -> -2979.65
I28: =J27-K27 -> -2979.65 | L28: =J28-K28 -> 0

Sheet Feuille 5
I19: Mois de Janvier | J19: Mois de Février | K19: Mois de Mars | N19: Mois de Mars
H20: Recette | I20: 1756000 | J20: 2274000 | K20: =RECAP!D33 -> 1984000 | M20: Recette | N20: =K20 -> 1984000
H21: Charges | I21: 920000 | J21: 914000 | K21: =RECAP!E33 -> 928000 | M21: Charges | N21: =K21 -> 928000
H22: Salaires | I22: 349000 | J22: 410000 | K22: =RECAP!F33 -> 406000 | M22: Salaires | N22: =K22 -> 406000
H23: Loyer | I23: 140000 | J23: 140000 | K23: 140000 | M23: Loyer | N23: 140000
H24: Profit Net | I24: =I20-I21-I22-I23 -> 347000 | J24: =J20-J21-J22-J23 -> 810000 | K24: =RECAP!H33 -> 510000 | M24: Profit Net | N24: =N20-N21-N22-N23 -> 510000
