Workbook

Sheet RECAP
B1: Date | C1: Recette | D1: Charges | E1: Salaire | F1: Loyer | G1: Net Profit
A2: lundi | B2: 43948 | C2: 7500
A3: mardi | B3: 43949 | C3: 8000
A4: mercredi | B4: 43950 | C4: 12000
A5: jeudi | B5: 43951 | C5: 8000
A6: vendredi | B6: 43952 | C6: 0 | D6: 0 | E6: 0 | F6: 0 | G6: 0
A7: samedi | B7: 43953 | C7: 14000
A8: dimanche | B8: 43954 | C8: 14000
A9: lundi | B9: 43955 | C9: 7000
A10: mardi | B10: 43956 | C10: 9000
A11: mercredi | B11: 43957 | C11: 7500
A12: jeudi | B12: 43958 | C12: 11500
A13: vendredi | B13: 43959 | C13: 0 | D13: 0 | E13: 0 | F13: 0 | G13: 0
A14: samedi | B14: 43960 | C14: 13000
A15: dimanche | B15: 43961 | C15: 12000
A16: lundi | B16: 43962 | C16: 11000
A17: mardi | B17: 43963 | C17: 12000
A18: mercredi | B18: 43964 | C18: 11000 | J18: cash restant
A19: jeudi | B19: 43965 | C19: 14000 | J19: =C37-D37-G37-Salaires!J22 -> 44600
A20: vendredi | B20: 43966 | C20: 0 | D20: 0 | E20: 0 | F20: 0 | G20: 0 | J20: 17500
A21: samedi | B21: 43967 | C21: 21000 | J21: =J19-J20 -> 27100
A22: dimanche | B22: 43968 | C22: 22000 | J22: 24000
A23: lundi | B23: 43969 | C23: 33000 | J23: 3000
A24: mardi | B24: 43970 | C24: 20000
A25: mercredi | B25: 43971 | C25: 15000
A26: jeudi | B26: 43972 | C26: 38000
A27: vendredi | B27: 43973 | C27: 35000 | D27: 0 | E27: 0 | F27: 0 | G27: 0
A28: Samedi | B28: 43974 | C28: 0
A29: Dimanche | B29: 43975 | C29: 0
A30: Lundi | B30: 43976 | C30: 0
A31: Mardi | B31: 43977 | C31: 4500
A32: Mercredi | B32: 43978 | C32: 15000
A33: Jeudi | B33: 43979 | C33: 17000
A34: Vendredi | B34: 43980 | C34: 0 | D34: 0 | E34: 0 | F34: 0 | G34: 0
A35: Samedi | B35: 43981 | C35: 0
A36: Dimanche | B36: 43982 | C36: 19000
A37: TOTAL | C37: =SUM(C2:C36) -> 411000 | D37: =Charges!E131*1 -> 94300 | E37: =Salaires!I22*1 -> 169700 | F37: 45000 | G37: =C37-D37-E37-F37 -> 102000
A38: TAUX | C38: 1 | D38: =D37/C37 -> 0.22944039 | E38: =E37/C37 -> 0.41289538 | F38: =F37/C37 -> 0.10948905 | G38: =G37/C37 -> 0.24817518
C66: -
J90: 20.&e

Sheet Charges
C2: Produit | D2: Quantité | E2: Prix | F2: Date d'achat
C3: Herbes | D3: 7 bouquets | E3: 150 | F3: 43948
C4: Bessel | D4: 1kg | E4: 100 | F4: 43948
C5: eau de fleur d'oranger | D5: 4 bouteilles | E5: 240 | F5: 43948
C6: amande | D6: 500g | E6: 950 | F6: 43948
C7: caocao | D7: 500g | E7: 200 | F7: 43948
C8: caocao éfilet | D8: 150g | E8: 100 | F8: 43948
C9: oeufs | D9: 15 | E9: 150 | F9: 43948
C10: farine | D10: 2kg | E10: 160 | F10: 43948
C11: semen | D11: 2.7kg | E11: 700 | F11: 43948
C12: les boules argentées | D12: 2 sachets | E12: 100 | F12: 43948
C13: vanille | D13: / | E13: 200 | F13: 43948
C14: halwet torek | D14: 1 boite | E14: 250 | F14: 43948 | I14: Huile Fridor 10litres | J14: 15 bidons | K14: 15900
C15: 3assila Mordjane | D15: 2kg | E15: 320 | F15: 43948 | I15: 2 cartons | J15: 2 cartons | K15: 5700
C16: rass tabouna | D16: 1 | E16: 380 | F16: 43948 | I16: Semoule baraka 25kg | J16: 23 sachets | K16: 28060
C17: Storme ooredoo | D17: 1 | E17: 1000 | F17: 43948 | I17: Extra Ben Hamadi 25kg | J17: 10 sachets | K17: 12500
C18: gaz | D18: 1 | E18: 300 | F18: 43948 | I18: eau miniral 1.5litres | J18: 4 fardeaux | K18: 600
C19: complément de salaire | E19: 2000 | F19: 43949
C20: lait | D20: 1 | E20: 50 | F20: 43948 | I20: levure de biere | J20: 22 boites | K20: 5500
C21: Farine | D21: 1 fardeau de 9kg | E21: 650 | F21: 43949 | I21: Extra Ben Hamadi 10kg | J21: 2 sachets | K21: 1000
C22: Deyoul | D22: 10 paquets | E22: 700 | F22: 43949
C23: les quissetes blanches | D23: 5 paquets | E23: 650 | F23: 43949
C24: miel mordjane | D24: 5kg | E24: 630 | F24: 43949 | K24: =SUM(K14:K23) -> 69260
C25: les quissetes+ maizina | E25: 300 | F25: 43949
C26: louz | D26: 1kg | E26: 1800 | F26: 43950
C27: les quissetes pr samsa | D27: 2 | E27: 100 | F27: 43950
C28: herebes | D28: 6 pouquets | E28: 120 | F28: 43950
C29: Flexy | D29: 1 | E29: 1500 | F29: 43950
C30: serpiere sanibon serviettes ben papier | D30: 3 | E30: 300 | F30: 43950
C31: sucre | D31: 5kkg | E31: 375 | F31: 43949
C32: salaires complémentaire de Mars | D32: / | E32: 2000 | F32: 43949
C33: Deyoul | D33: 20 paquets | E33: 1200 | F33: 43949
C34: Deyoul | D34: 20paquets | E34: 1200 | F34: 43949
C35: serpilleire | D35: 2 | E35: 200 | F35: 43952
C36: isis | D36: 1 | E36: 150 | F36: 43952
C37: maa ezehar | D37: 2 | E37: 120 | F37: 43952
C38: bessel et tomate | D38: 3kg+500g | E38: 500 | F38: 43952
C39: herebes | D39: 6 paquets | E39: 120 | F39: 43952
C40: herbes | D40: 8 | E40: 160 | F40: 43954
C41: khoubezet tounes | D41: 18 | E41: 1440 | F41: 43955
...

Sheet Pointage
B1: Date | C1: Zehor | D1: Zoubida | E1: Amel | F1: Karima | G1: Nouara | H1: Zahida | I1: Sifou | J1: Nacera | K1: Remarque | L1: Reste à payer
A2: Lundi | B2: 43948 | C2: 1 | D2: 0 | E2: 1 | F2: 0 | G2: 1 | H2: 1 | I2: 0 | J2: 0
A3: Mardi | B3: 43949 | C3: 1 | D3: 0 | E3: 1 | F3: 1 | G3: 1 | H3: 1 | I3: 1 | J3: 0 | M3: 10000
A4: Mercredi | B4: 43950 | C4: 1 | D4: 1 | E4: 1 | F4: 1 | G4: 1 | H4: 1 | I4: 1 | J4: 0
A5: Jeudi | B5: 43951 | C5: 1 | D5: 0 | E5: 1 | F5: 1 | G5: 1 | H5: 1 | I5: 1 | J5: 0
A6: Vendredi | B6: 43952 | C6: 0 | D6: 0 | E6: 0 | F6: 0 | G6: 0 | H6: 0 | I6: 0 | J6: 0
A7: Samedi | B7: 43953 | C7: 1 | D7: 0 | E7: 1 | F7: 1 | G7: 1 | H7: 1 | I7: 0 | J7: 0
A8: Dimanche | B8: 43954 | C8: 1 | D8: 0 | E8: 1 | F8: 1 | G8: 1 | H8: 1 | I8: 0 | J8: 1
A9: Lundi | B9: 43955 | C9: 1 | D9: 0 | E9: 1 | F9: 1 | G9: 1 | H9: 1 | I9: 0 | J9: 1
A10: Mardi | B10: 43956 | C10: 1 | D10: 0 | E10: 1 | F10: 1 | G10: 1 | H10: 1 | I10: 0 | J10: 1
A11: Mercredi | B11: 43957 | C11: 1 | D11: 0 | E11: 1 | F11: 1 | G11: 1 | H11: 1 | I11: 0 | J11: 1
A12: Jeudi | B12: 43958 | C12: 1 | D12: 0 | E12: 1 | F12: 1 | G12: 1 | H12: 1 | I12: 0 | J12: 1
A13: Vendredi | B13: 43959 | C13: 0 | D13: 0 | E13: 0 | F13: 0 | G13: 0 | H13: 0 | I13: 0 | J13: 0
A14: Samedi | B14: 43960 | C14: 1 | D14: 0 | E14: 1 | F14: 1 | G14: 1 | H14: 1 | I14: 0 | J14: 1
A15: Dimanche | B15: 43961 | C15: 1 | D15: 0 | E15: 1 | F15: 1 | G15: 1 | H15: 1 | I15: 0 | J15: 1
... A19: Jeudi | B19: 43965 | C19: 1 | D19: 0 | E19: 1 | F19: 1 | G19: 1 | H19: 1 | I19: 0 | J19: 1
A20: Vendredi | B20: 43966 | C20: 0 | D20: 0 | E20: 0 | F20: 0 | G20: 0 | H20: 0 | I20: 0
A21: Samedi | B21: 43967 | C21: 1 | D21: 0 | E21: 1.5 | F21: 1 | G21: 1 | H21: 1 | I21: 0 | J21: 1
A22: Dimenche | B22: 43968 | C22: 1 | E22: 1 | F22: 1 | G22: 1 | H22: 1 | I22: 0 | J22: 1
A23: Lundi | B23: 43969 | C23: 1 | D23: 1 | E23: 1 | F23: 1 | G23: 1 | H23: 1 | I23: 0 | J23: 1
A24: Mardfi | B24: 43970 | C24: 1 | D24: 1 | E24: 1 | F24: 1 | G24: 1 | H24: 1 | I24: 0 | J24: 1
A25: Mercredi | B25: 43971 | C25: 1 | D25: 1 | E25: 1 | F25: 1 | G25: 1 | H25: 1 | I25: 0 | J25: 1
A26: Jeudi | B26: 43972 | C26: 1 | D26: 1 | E26: 1 | F26: 1 | G26: 1 | H26: 1 | I26: 0 | J26: 1
A27: Vendredi | B27: 43973 | C27: 1 | D27: 1 | E27: 1 | F27: 0 | G27: 1 | H27: 1 | I27: 0 | J27: 0
A28: Samedi | B28: 43974 | C28: 0 | D28: 0 | E28: 0 | F28: 0 | G28: 0 | H28: 0 | I28: 0 | J28: 0
A29: Dimanche | B29: 43975 | C29: 0 | D29: 0 | E29: 0 | F29: 0 | G29: 0 | H29: 0 | I29: 0 | J29: 0
A30: Lundi | B30: 43976 | C30: 0 | D30: 0 | E30: 0 | F30: 0 | G30: 0 | H30: 0 | I30: 0 | J30: 0
A31: Mardi | B31: 43977 | C31: 0 | D31: 1 | E31: 1 | F31: 0 | G31: 1 | H31: 1 | I31: 0 | J31: 0
A32: Mercredi | B32: 43978 | C32: 0 | D32: 1 | E32: 1 | F32: 0 | G32: 1 | H32: 1 | I32: 0 | J32: 0
A33: Jeudi | B33: 43979 | C33: 0 | D33: 1 | E33: 1 | F33: 0 | G33: 1 | H33: 1 | I33: 0 | J33: 0
A34: Vendredi | B34: 43980 | C34: 0 | D34: 0 | E34: 0 | F34: 0 | G34: 0 | H34: 0 | I34: 0 | J34: 0
... A36: Dimanche | B36: 43982 | C36: 0 | D36: 1 | E36: 1 | F36: 1 | G36: 1 | H36: 1 | I36: 0 | J36: 0
B37: TOTAL | C37: =SUM(C2:C36) -> 23 | D37: =SUM(D2:D36) -> 11 | E37: =SUM(E2:E36) -> 28.5 | F37: =SUM(F2:F36) -> 23 | G37: =SUM(G2:G36) -> 28 | H37: =SUM(H2:H36) -> 28 | I37: =SUM(I2:I36) -> 3 | J37: =SUM(J2:J36) -> 17
B38: Salaire/jour | C38: 2000 | D38: 1200 | E38: 1000 | F38: 600 | G38: 1000 | H38: 1200 | I38: 1200 | J38: 1000 | K38: =SUM(C38:H38) -> 7000
B39: SALAIRES | C39: =C40-M3 -> 36000 | D39: =D38*D37 -> 13200 | E39: =E38*E37 -> 28500 | F39: =F38*F37 -> 13800 | G39: =G38*G37 -> 28000 | H39: =H37*H38 -> 33600 | I39: =I38*I37 -> 3600 | J39: =J38*J37 -> 17000 | K39: =SUM(C39:H39) -> 153100
C40: =C38*C37 -> 46000

Sheet Salaires
H12: Nom | I12: Salaire | J12: Avance
G13: 1 | H13: Zehor | I13: =Pointage!C39*1 -> 36000 | J13: 36000
G14: 2 | H14: Karima | I14: =Pointage!F39*1 -> 13800 | J14: 13800
G15: 3 | H15: Amel | I15: =Pointage!E39*1 -> 28500 | J15: 28500
G16: 4 | H16: Nowara | I16: =Pointage!G39*1 -> 28000 | J16: 28000
G17: 5 | H17: Zoubida | I17: =Pointage!D39*1 -> 13200 | J17: 13200
G18: 6 | H18: Sifou | I18: =Pointage!I39*1 -> 3600 | J18: 4000
G19: 7 | H19: Nacera | I19: 7000 | J19: 7000
G20: 8 | H20: Zahida | I20: =Pointage!H39*1 -> 33600 | J20: 33600
G21: 9 | H21: Rafik | I21: 6000 | J21: 6000
H22: TOTAL | I22: =SUM(I13:I21) -> 169700 | J22: =SUM(J13:J21) -> 170100
I23: =I22-J22 -> -400
