Workbook

Sheet RECAP
B1: Date | C1: Recette | D1: Charges | E1: Salaire | F1: Loyer | G1: Net Profit
A2: lundi | B2: 43983 | C2: 20000 | N2: 20000
A3: mardi | B3: 43984 | C3: 20000 | N3: 20000
A4: mercredi | B4: 43985 | C4: 14000 | N4: 14000
A5: jeudi | B5: 43986 | C5: 20000 | N5: 20000
A6: vendredi | B6: 43987 | C6: 0 | D6: 0 | E6: 0 | F6: 0 | G6: 0 | N6: 0
A7: samedi | B7: 43988 | C7: 19000 | K7: Moyenne | N7: 19000
A8: dimanche | B8: 43989 | C8: 19000 | K8: =C32/Pointage!E32 -> 18538.462 | N8: 19000
A9: lundi | B9: 43990 | C9: 25000 | N9: 25000
A10: mardi | B10: 43991 | C10: 24000 | N10: 24000
A11: mercredi | B11: 43992 | C11: 22000 | N11: 22000
A12: jeudi | B12: 43993 | C12: 27000 | N12: 27000
A13: vendredi | B13: 43994 | C13: 0 | D13: 0 | E13: 0 | F13: 0 | G13: 0 | N13: 0
A14: samedi | B14: 43995 | C14: 21000 | N14: 21000
A15: dimanche | B15: 43996 | C15: 17000 | N15: 17000
A16: lundi | B16: 43997 | C16: 15000 | K16: cash restant | N16: 15000
A17: mardi | B17: 43998 | C17: 19000 | K17: =C32+Charges!G154-Charges!G153-Salaires!J20 -> 249000 | N17: 19000
A18: mercredi | B18: 43999 | C18: 21000 | N18: 21000
A19: jeudi | B19: 44000 | C19: 16000 | N19: 16000
A20: vendredi | B20: 44001 | C20: 0 | D20: 0 | E20: 0 | F20: 0 | G20: 0 | N20: 0
A21: samedi | B21: 44002 | C21: 15000 | N21: 15000
A22: dimanche | B22: 44003 | C22: 13000 | N22: 13000
A23: lundi | B23: 44004 | C23: 13000 | N23: 13000
A24: mardi | B24: 44005 | C24: 13000 | N24: 13000
A25: mercredi | B25: 44006 | C25: 27000 | N25: =SUM(N2:N24) -> 373000
A26: jeudi | B26: 44007 | C26: 25000
A27: vendredi | B27: 44008 | C27: 0 | D27: 0 | E27: 0 | F27: 0 | G27: 0
A28: Samedi | B28: 44009 | C28: 21000
A29: Dimanche | B29: 44010 | C29: 8000
A30: Lundi | B30: 44011 | C30: 18000
A31: Mardi | B31: 44012 | C31: 10000
A32: TOTAL | C32: =SUM(C2:C31) -> 482000 | D32: =Charges!G153*1 -> 292000 | E32: =Salaires!I20*1 -> 141000 | F32: 77000 | G32: =C32-D32-E32-F32 -> -28000
A33: TAUX | C33: 1 | D33: =D32/C32 -> 0.60580913 | E33: =E32/C32 -> 0.29253112 | F33: =F32/C32 -> 0.15975104 | G33: =G32/C32 -> -0.058091286

Sheet Pointage
B1: Date | C1: Zehor | D1: Zoubida | E1: Amel | F1: Karima | G1: Nouara | H1: Zahida | I1: Remarque
A2: Lundi | B2: 43983 | C2: 0 | D2: 1 | E2: 1 | F2: 1 | G2: 1 | H2: 1
A3: Mardi | B3: 43984 | C3: 0 | D3: 1 | E3: 1 | F3: 1 | G3: 1 | H3: 1
A4: Mercredi | B4: 43985 | C4: 0 | D4: 1 | E4: 1 | F4: 1 | G4: 1 | H4: 1
A5: Jeudi | B5: 43986 | C5: 0 | D5: 1 | E5: 1 | F5: 1 | G5: 1 | H5: 1.5
A6: Vendredi | B6: 43987 | C6: 0 | D6: 0 | E6: 0 | F6: 0 | G6: 0 | H6: 0
A7: Samedi | B7: 43988 | C7: 0 | D7: 1 | E7: 1 | F7: 1 | G7: 1 | H7: 1.5
A8: Dimanche | B8: 43989 | C8: 0 | D8: 1 | E8: 1 | F8: 1 | G8: 1 | H8: 1.5
A9: Lundi | B9: 43990 | C9: 0 | D9: 1 | E9: 1 | F9: 1 | G9: 1 | H9: 1
A10: Mardi | B10: 43991 | C10: 0 | D10: 1 | E10: 1 | F10: 1 | G10: 1 | H10: 1.5
A11: Mercredi | B11: 43992 | C11: 0 | D11: 1 | E11: 1 | F11: 1 | G11: 1 | H11: 1.5
A12: Jeudi | B12: 43993 | C12: 0 | D12: 1 | E12: 1 | F12: 1 | G12: 1 | H12: 1.5
A13: Vendredi | B13: 43994 | C13: 0 | D13: 0 | E13: 0 | F13: 0 | G13: 0 | H13: 0
... A31: Mardi | B31: 44012 | C31: 1 | D31: 1 | E31: 1 | F31: 1 | G31: 1 | H31: 1
B32: TOTAL | C32: =SUM(C2:C31) -> 7 | D32: =SUM(D2:D31) -> 25 | E32: =SUM(E2:E31) -> 26 | F32: =SUM(F2:F31) -> 26 | G32: =SUM(G2:G31) -> 26 | H32: =SUM(H2:H31) -> 29.5
B33: Salaire/jour | C33: 2000 | D33: 1160 | E33: 962 | F33: 600 | G33: 962 | H33: 1160 | I33: =SUM(C33:H33) -> 6844
B34: SALAIRES | C34: =C33*C32 -> 14000 | D34: =D33*D32 -> 29000 | E34: =E33*E32 -> 25012 | F34: =F33*F32 -> 15600 | G34: =G33*G32 -> 25012 | H34: =H32*H33 -> 34220 | I34: =SUM(C34:H34) -> 142844

Sheet Charges
E2: Produit | F2: Quantité | G2: Prix | H2: Date d'achat
E3: Semoule fine Baraka 25kg | F3: 6 sachets | G3: 7200 | H3: 43983
E4: Semoule Extra Ben Hamadi Moyenne 25kg | F4: 3 sachets | G4: 4050 | H4: 43983
E5: Semoule Extra Ben Hamadi Moyenne 10kg | F5: 1 sachet | G5: 600 | H5: 43983
E6: Semoule Moyenne Amour | F6: 2 | G6: 2400 | H6: 43983
E7: Semoule Baraka Moyenne 10kg | F7: 4 sachets | G7: 2200 | H7: 43983
E8: Margarine Mani | F8: 1 carton | G8: 2900 | H8: 43983
E9: Huile Fridor 10 litres | F9: 8 | G9: 8480 | H9: 43983
E10: Levure de Bièrre | F10: 22 | G10: 5500 | H10: 43983
E11: jus thchina | F11: 2 fardeaux | G11: 880 | H11: 43983
E12: eau miniral petit | F12: 4 fardeaux | G12: 640 | H12: 43983
E13: Coca Cola cannette | F13: 1 fardeau | G13: 1200 | H13: 43983
E14: Gazouz Hamoud | F14: 2 Fardeaux | G14: 800 | H14: 43983
E15: Jus Ifruit | F15: 1 fardeau | G15: 550 | H15: 43983
E16: Jus Rouiba | F16: 1 fardeau | G16: 600 | H16: 43983
E17: Tomate conserve | F17: 11 Boites | G17: 1870 | H17: 43983
E18: Farine Sim | F18: 9 kg | G18: 700 | H18: 43983
E19: Fromage Gouda | F19: 1kg | G19: 1600 | H19: 43983
E20: Sucre | F20: 10kg | G20: 750 | H20: 43983
E21: Sel | F21: 20kg | G21: 350 | H21: 43983
E22: Maa Zehar | F22: 12 | G22: 900 | H22: 43983
E23: Madina | F23: 3 boites | G23: 1290 | H23: 43983
E24: amandes | F24: 1kg | G24: 1700 | H24: 43983
E25: arachide efilet | F25: 500g | G25: 300 | H25: 43983
E26: djeldjelan | F26: 500g | G26: 200 | H26: 43983
E27: arachide efilet | F27: 1kg | G27: 390 | H27: 43983
E28: Maizina | F28: / | G28: 300 | H28: 43983
E29: Vanille | F29: / | G29: 200 | H29: 43983
E30: 7alwet torek | F30: 1 boite | G30: 500 | H30: 43983
E31: Papier Aluminium | F31: 180m | G31: 1300 | H31: 43983
E32: Miel | F32: 10kg | G32: 1200 | H32: 43983
E33: les quissetes | F33: 3 | G33: 300 | H33: 43983
E34: les bavettes | F34: 5 | G34: 350 | H34: 43983
E35: gel désinféctant | F35: 2 | G35: 400 | H35: 43983
E36: Dakin | F36: 1 | G36: 100 | H36: 43983
E37: Eau miniral grande bouteilles | F37: 5 fardeaux | G37: 850 | H37: 43983
E38: bouteilles de charbet | F38: 400 | G38: 5200 | H38: 43983
E39: déteregents | F39: 5 | G39: 600 | H39: 43983
E40: herbes | F40: 7 | G40: 150 | H40: 43983
E41: Flexy modem | F41: 40Go | G41: 1500 | H41: 43983
...

Sheet Salaires
H13: Nom | I13: Salaire | J13: Avance
G14: 1 | H14: Zehor | I14: =Pointage!C34*1 -> 14000
G15: 2 | H15: Karima | I15: 15000
G16: 3 | H16: Amel | I16: 25000 | J16: 3000
G17: 4 | H17: Nowara | I17: 25000
G18: 5 | H18: Zoubida | I18: =Pointage!D34*1 -> 29000
G19: 6 | H19: Zahida | I19: 33000
H20: TOTAL | I20: =SUM(I14:I19) -> 141000 | J20: =SUM(J14:J19) -> 3000
I21: =I20-J20 -> 138000

Sheet Feuille 5
J7: 6900
J8: 7800
J9: 4500
J10: 1200
J11: 10000
J12: 3000
J13: 3000
J14: =SUM(J7:J13) -> 36400
