Workbook

Sheet RECAP
B1: Date | C1: Recette Décembre 2023 | D1: Recette | E1: Charges | F1: Salaire | G1: Loyer | H1: Net Profit | I1: Nb de jours | K1: Objectif | L1: Decembre 2023
A2: Lundi | B2: 45292 | C2: 40000 | D2: 45000 | I2: 1 | L2: 40000
A3: Mardi | B3: 45293 | C3: 41000 | D3: 32000 | I3: 1 | L3: 41000 | M3: Bénéfice Moyen par jour | N3: Moyenne | O3: Moyenne salaire | P3: pourcentage du salaire vis à vis la recettte
A4: Mercredi | B4: 45294 | C4: 40000 | D4: 40000 | I4: 1 | L4: 40000 | M4: =H33/I33 -> 11048.578 | N4: =D33/I33 -> 56483.871 | P4: =O4/N4 -> 0
A5: Jeudi | B5: 45295 | C5: 33000 | D5: 60000 | I5: 1 | L5: 33000
A6: Vendredi | B6: 45296 | C6: 38000 | D6: 30000 | I6: 1 | L6: 38000 | M6: Moyenne des charges par jour | N6: Objectif
A7: Samedi | B7: 45297 | C7: 40000 | D7: 60000 | I7: 1 | L7: 40000 | M7: =E33/I33 -> 29682.097 | N7: 100000
A8: Dimanche | B8: 45298 | C8: 52000 | D8: 57000 | I8: 1 | L8: 52000 | M8: ²
A9: Lundi | B9: 45299 | C9: 37000 | D9: 51000 | I9: 1 | L9: 37000
A10: Mardi | B10: 45300 | C10: 30000 | D10: 70000 | I10: 1 | L10: 30000 | M10: Cash restant | N10: Magasin | O10: Cash réel | P10: Mes dettes pour le magasin
A11: Mercredi | B11: 45301 | C11: 44000 | D11: 140000 | I11: 1 | L11: 44000 | M11: =D33-N11-E33-'les Salaires'!M28 -> 605355 | N11: 104000 | O11: 350000 | P11: =M11-O11 -> 255355
A12: Jeudi | B12: 45302 | C12: 50000 | D12: 210000 | I12: 1 | L12: 50000
A13: Vendredi | B13: 45303 | C13: 35000 | D13: 77000 | I13: 1 | L13: 35000 | M13: loyer
A14: Samedi | B14: 45304 | C14: 48000 | D14: 0 | I14: 1 | L14: 48000
A15: Dimanche | B15: 45305 | C15: 75000 | D15: 0 | I15: 1 | L15: 75000 | O15: éspèce : 280000 | P15: Sofiane: 65000
A16: Lundi | B16: 45306 | C16: 55000 | D16: 44000 | I16: 1 | L16: 55000 | O16: ccp: 50000 | P16: Cliente Baraki: 4100Da
A17: Mardi | B17: 45307 | C17: 35000 | D17: 33000 | I17: 1 | L17: 35000 | O17: chèque: 21000 | P17: zaki: 3600
A18: Mercredi | B18: 45308 | C18: 60000 | D18: 56000 | I18: 1 | L18: 60000 | O18: Sousou: 2000 | P18: mme saihi : 12500
A19: Jeudi | B19: 45309 | C19: 45000 | D19: 50000 | I19: 1 | L19: 45000 | M19: Différence mois de Juin | O19: Bouchaoui:9300 | P19: la vrai caisse: 13000
A20: Vendredi | B20: 45310 | C20: 52000 | D20: 54000 | I20: 1 | L20: 52000 | M20: =D35-C35 -> 0 | P20: Célia: 6500Da
A21: Samedi | B21: 45311 | C21: 84000 | D21: 50000 | I21: 1 | L21: 84000 | M21: Différence objectif
A22: Dimanche | B22: 45312 | C22: 60000 | D22: 30000 | I22: 1 | L22: 60000 | M22: =K36-E36 -> 0
A23: Lundi | B23: 45313 | C23: 190000 | D23: 30000 | I23: 1 | L23: 190000 | M23: Différence du Totale
A24: Mardi | B24: 45314 | C24: 50000 | D24: 35000 | I24: 1 | L24: 50000 | M24: =D33-C33 -> 73000
A25: Mercredi | B25: 45315 | C25: 40000 | D25: 75000 | I25: 1 | L25: 40000 | M25: Les vendredis
A26: Jeudi | B26: 45316 | C26: 31000 | D26: 99000 | I26: 1 | L26: 31000 | M26: =D9+D16+D23+D30 -> 196000
A27: Vendredi | B27: 45317 | C27: 36000 | D27: 50000 | I27: 1 | L27: 36000
A28: Samedi | B28: 45318 | C28: 43000 | D28: 53000 | I28: 1 | L28: 43000 | M28: Cash réel
A29: Dimanche | B29: 45319 | C29: 60000 | D29: 35000 | I29: 1 | L29: 60000 | M29: 51000
A30: Lundi | B30: 45320 | C30: 34000 | D30: 71000 | I30: 1 | L30: 34000 | M30: rest à payer
A31: Mardi | B31: 45321 | C31: 50000 | D31: 42000 | I31: 1 | L31: 50000
A32: Mercredi | B32: 45322 | C32: 150000 | D32: 72000 | I32: 1 | L32: 150000
C33: =SUM(C2:C32) -> 1678000 | D33: =SUM(D2:D32) -> 1751000 | E33: ='Les charges '!F342 -> 920145 | F33: ='les Salaires'!L28 -> 348349.08 | G33: 140000 | H33: =D33-E33-F33-G33 -> 342505.92 | I33: =SUM(I2:I32) -> 31 | L33: =SUM(L2:L32) -> 1678000
M35: =M11-M29-M34 -> 554355
D38: -

Sheet Pointage
B1: Date | C1: Lynda | D1: Hafida | E1: Djamila | F1: Youssera | G1: Yasmine vendeuse | H1: Kenza | I1: Yasmine | J1: Fouzia | K1: Nadjet | L1: Alia | M1: Fatiha | N1: Samira | O1: Nadia | P1: Nadia femme de ménage | Q1: Sarah
A2: Lundi | B2: 45292 | C2: 0.5 | D2: 1 | E2: 1 | F2: 1 | G2: 0 | H2: 0 | I2: 1 | J2: 1 | K2: 1 | L2: 0 | M2: 1 | N2: 1 | O2: 1 | P2: 1 | Q2: 0
A3: Mardi | B3: 45293 | C3: 0 | D3: 1 | E3: 1 | F3: 1 | G3: 1 | H3: 0 | I3: 0 | J3: 1 | K3: 0 | L3: 0 | M3: 1 | N3: 1 | O3: 0 | P3: 1 | Q3: 0
A4: Mercredi | B4: 45294 | C4: 0.5 | D4: 1 | E4: 1 | F4: 1 | G4: 1 | H4: 0 | I4: 0 | J4: 1 | K4: 1 | L4: 0 | M4: 1 | N4: 1 | O4: 1 | P4: 1 | Q4: 0 | R4: 40 baklawa à la maison
A5: Jeudi | B5: 45295 | C5: 0.5 | D5: 1 | E5: 1 | F5: 0.5 | G5: 1 | H5: 0 | I5: 0 | J5: 0.5 | K5: 1 | L5: 0 | M5: 1 | N5: 1 | O5: 1 | P5: 1 | Q5: 0 | R5: parts de rechta + les salés
A6: Vendredi | B6: 45296 | C6: 0 | D6: 0 | E6: 0 | F6: 0 | G6: 1 | H6: 1 | I6: 1 | J6: 0 | K6: 0 | L6: 0 | M6: 0 | N6: 0 | O6: 0 | P6: 0 | Q6: 0
A7: Samedi | B7: 45297 | C7: 0 | D7: 0 | E7: 1 | F7: 1 | G7: 1 | H7: 0 | I7: 0 | J7: 0 | K7: 1 | L7: 1 | M7: 1 | N7: 1 | O7: 1 | P7: 0 | Q7: 0
A8: Dimanche | B8: 45298 | C8: 1 | D8: 1 | E8: 1 | F8: 1 | G8: 1 | H8: 0 | I8: 0 | J8: 1 | K8: 0 | L8: 1 | M8: 1 | N8: 1 | O8: 1 | P8: 0 | Q8: 0 | R8: gateaux au chocolat
A9: Lundi | B9: 45299 | C9: 0 | D9: 1 | E9: 1 | F9: 1 | G9: 0 | H9: 0 | I9: 0 | J9: 1 | K9: 1 | L9: 1 | M9: 1 | N9: 1 | O9: 1 | P9: 0 | Q9: 0
A10: Mardi | B10: 45300 | C10: 0 | D10: 1 | E10: 1 | F10: 1 | G10: 1 | H10: 0 | I10: 0 | J10: 1 | K10: 0 | L10: 1 | M10: 1 | N10: 1 | O10: 1 | P10: 0 | Q10: 0
A11: Mercredi | B11: 45301 | C11: 0 | D11: 1 | E11: 1 | F11: 1 | G11: 2 | H11: 0 | I11: 0 | J11: 1 | K11: 2 | L11: 1 | M11: 1 | N11: 1 | O11: 1 | P11: 0 | Q11: 0
A12: Jeudi | B12: 45302 | C12: 2 | D12: 2 | E12: 2 | F12: 0 | G12: 2 | H12: 0 | I12: 0 | J12: 1.25 | K12: 2 | L12: 2 | M12: 1,5 | N12: 2 | O12: 1 | P12: 0 | Q12: 0
A13: Vendredi | B13: 45303 | C13: 2 | D13: 1 | E13: 1 | F13: 0 | G13: 1 | H13: 0 | I13: 0 | J13: 0 | K13: 1 | L13: 1 | M13: 0 | N13: 1 | O13: 0 | P13: 0 | Q13: 0
A14: Samedi | B14: 45304 | C14: 0 | D14: 0 | E14: 0 | F14: 0 | G14: 0 | H14: 0 | I14: 0 | J14: 0 | K14: 0 | L14: 0 | M14: 0 | N14: 0 | O14: 0 | P14: 0 | Q14: 0
A15: Dimanche | B15: 45305 | C15: 0 | D15: 0 | E15: 0 | F15: 0 | G15: 0 | H15: 0 | I15: 0 | J15: 0 | K15: 0 | L15: 0 | M15: 2 | N15: 0 | O15: 0 | P15: Zohra | Q15: 0
A16: Lundi | B16: 45306 | C16: 0 | D16: 1 | E16: 1 | F16: 0 | G16: 0 | H16: 0 | I16: 0 | J16: 0 | K16: 1 | L16: 1 | M16: 1 | N16: 0 | O16: 1 | P16: 2 | Q16: 0
A17: Mardi | B17: 45307 | C17: 0 | D17: 1 | E17: 1 | F17: 0 | G17: 1 | H17: 0 | I17: 0 | J17: 1 | K17: 0 | L17: 0 | M17: 1 | N17: 0 | O17: 1 | P17: 1 | Q17: 0
A18: Mercredi | B18: 45308 | C18: 0 | D18: 1 | E18: 1 | F18: 0 | G18: 1 | H18: 0 | I18: 0 | J18: 1 | K18: 1 | L18: 1 | M18: 1 | N18: 1 | O18: 1 | P18: 0 | Q18: 0
A19: Jeudi | B19: 45309 | C19: 1 | D19: 1 | E19: 1 | F19: 0 | G19: 1 | H19: 0 | I19: 0 | J19: 1 | K19: 0 | L19: 1 | M19: 1 | N19: 1 | O19: 1 | P19: 0 | Q19: 0
A20: Vendredi | B20: 45310 | C20: 1 | D20: 1 | E20: 0 | F20: 0 | G20: 1 | H20: 0 | I20: 0 | J20: 0 | K20: 0 | L20: 0 | M20: 0 | N20: 1 | O20: 0 | P20: 0 | Q20: 0
A21: Samedi | B21: 45311 | C21: 1.5 | D21: 1 | E21: 1 | F21: 0 | G21: 1 | H21: 0 | I21: 0 | J21: 0.5 | K21: 0 | L21: 1 | M21: 1 | N21: 0 | O21: 0 | P21: 0 | Q21: 0 | R21: Hafida , Djamila , Alia sont sorti à 16h sans autorisation
A22: Dimanche | B22: 45312 | C22: 0 | D22: 1 | E22: 1 | F22: 0 | G22: 1 | H22: 0 | I22: 0 | J22: 1 | K22: 0 | L22: 0 | M22: 1 | N22: 1 | O22: 1 | P22: 0 | Q22: 0
A23: Lundi | B23: 45313 | C23: 0 | D23: 1 | E23: 1 | F23: 0 | G23: 1 | H23: 0 | I23: 0 | J23: 1 | K23: 0 | L23: 1 | M23: 1 | N23: 0 | O23: 1 | P23: 0 | Q23: 0
A24: Mardi | B24: 45314 | C24: 0 | D24: 1 | E24: 1 | F24: 0 | G24: 1 | H24: 0 | I24: 0 | J24: 1 | K24: 0 | L24: 0 | M24: 1 | N24: 1 | O24: 1 | P24: 0 | Q24: 0 | R24: nadia et Fouzia kharedjou à 15h
A25: Mercredi | B25: 45315 | C25: 0 | D25: 1 | E25: 1 | F25: 0 | G25: 1 | H25: 0 | I25: 0 | J25: 1 | K25: 0 | L25: 0 | M25: 1 | N25: 1 | O25: 1 | P25: 0 | Q25: 0
A26: Jeudi | B26: 45316 | C26: 1 | D26: 1.25 | E26: 1 | F26: 0 | G26: 1 | H26: 0 | I26: 0 | J26: 1 | K26: 0 | L26: 1 | M26: 1 | N26: 1 | O26: 0 | P26: 0 | Q26: 0
A27: Vendredi | B27: 45317 | C27: 1 | D27: 1 | E27: 0 | F27: 0 | G27: 1 | H27: 0 | I27: 0 | J27: 0 | K27: 0 | L27: 1 | M27: 0 | N27: 1 | O27: 0 | P27: 0 | Q27: 0
A28: Samedi | B28: 45318 | C28: 1 | D28: 1 | E28: 1 | F28: 0 | G28: 1 | H28: 0 | I28: 0 | J28: 0 | K28: 0 | L28: 1 | M28: 1 | N28: 1 | O28: 0 | P28: 0 | Q28: 0
A29: Dimanche | B29: 45319 | C29: 1 | D29: 1 | E29: 1 | F29: 0 | G29: 1 | H29: 0 | I29: 0 | J29: 1 | K29: 0 | L29: 0 | M29: 1 | N29: 1 | O29: 0 | P29: 0 | Q29: 1
A30: Lundi | B30: 45320 | C30: 0 | D30: 1 | E30: 1 | F30: 0 | G30: 1 | H30: 0 | I30: 0 | J30: 1 | K30: 0 | L30: 1 | M30: 1 | N30: 1 | O30: 0 | P30: 0 | Q30: 1
A31: Mardi | B31: 45321 | C31: 0 | D31: 1 | E31: 1 | F31: 0 | G31: 0 | H31: 0 | I31: 1 | J31: 1 | K31: 0 | L31: 0 | M31: 1 | N31: 1 | O31: 0 | P31: 0 | Q31: 1
A32: Mercredi | B32: 45322 | C32: 0 | D32: 1 | E32: 1 | F32: 0 | G32: 1 | I32: 0 | J32: 1.25 | K32: 1 | L32: 1 | M32: 1 | N32: 0 | O32: 0 | P32: 0 | Q32: 1
C33: =SUM(C2:C32) -> 14 | D33: =SUM(D2:D32) -> 28.25 | E33: =SUM(E2:E32) -> 27 | F33: =SUM(F2:F32) -> 8.5 | G33: =SUM(G2:G32) -> 27 | H33: =SUM(H2:H32) -> 1 | I33: =SUM(I2:I32) -> 3 | J33: =SUM(J2:J32) -> 21.5 | ... Q33: =SUM(Q2:Q32) -> 4
C34: 1296.3 | D34: 1370 | E34: 1222.22 | F34: 1222.22 | G34: 1111.11 | H34: 1111.11 | I34: 1150 | J34: 1370 | K34: 1500 | L34: 1111.11 | M34: 1038 | N34: 1111.11 | O34: 1111.11 | P34: 1150 | Q34: 1000
C35: =C33*C34 -> 18148.2 | D35: =D34*D33 -> 38702.5 | E35: =E34*E33 -> 32999.94 | F35: =F34*F33 -> 10388.87 | G35: =G34*G33 -> 29999.97 | H35: =H34*H33 -> 1111.11 | I35: =I34*I33 -> 3450 | J35: =J33*J34 -> 29455 | K35: =K33*K34 -> 19500 | L35: =L33*L34 -> 19999.98 | M35: =M33*M34 -> 26988 | N35: =N34*N33 -> 26666.64 | O35: =O33*O34 -> 18888.87 | P35: =P34*P33 -> 8050 | Q35: =Q33*Q34 -> 4000
C36: 35000 | D36: 36000 | E36: 33000 | F36: 33000 | G36: 30000 | H36: 30000 | I36: 30000 | J36: 36000 | K36: 36000 | L36: 30000 | M36: 28000 | N36: 30000 | O36: 30000 | P36: 30000

Sheet Les charges 
C2: Produit | D2: Quantité | E2: Prix unitaire | F2: Prix | G2: Date d'achat
C3: huile 5 litres | D3: 34 | E3: 600 | F3: =D3*E3 -> 20400
C4: miel 3 kg | D4: 5 | E4: 480 | F4: =D4*E4 -> 2400
C5: Farine 5kg | D5: 10 | E5: 300 | F5: =D5*E5 -> 3000
C6: Margarine Fleurial 500g | D6: 56 | E6: 190 | F6: =D6*E6 -> 10640
C7: Boite 48/10 | D7: 2 | E7: 1950 | F7: =D7*E7 -> 3900
C8: Boite 48/07 | D8: 1 | E8: 1650 | F8: =D8*E8 -> 1650
C9: Boite 36 | D9: 2 | E9: 1200 | F9: =D9*E9 -> 2400
C10: Boite 24 | D10: 2 | E10: 1100 | F10: =D10*E10 -> 2200
C11: Boite 18 | D11: 2 | E11: 1550 | F11: =D11*E11 -> 3100
C12: Boite 12 | D12: 1 | E12: 1350 | F12: =D12*E12 -> 1350
C13: Boite 08 | D13: 1 | E13: 1150 | F13: =D13*E13 -> 1150
C14: Farine Sim 1kg | D14: 27 | E14: 80 | F14: =D14*E14 -> 2160
... C69: Maiis | D69: 16 | E69: 245 | F69: =D69*E69 -> 3920
C70: sel | D70: 15 | E70: 30 | F70: =E70*D70 -> 450
C71: jus ifruit | D71: 7 | E71: 540 | F71: =D71*E71 -> 3780
C72: Divers | D72: 1 | E72: 6000 | F72: =D72*E72 -> 6000
C73: couscouss | D73: 4 | E73: 200 | F73: =D73*E73 -> 800
C74: pain tacos | D74: 10 | E74: 300 | F74: =D74*E74 -> 3000
C75: viande hachée | D75: 1.5 | E75: 1800 | F75: =D75*E75 -> 2700
C76: poulet haché | D76: 2 | E76: 1000 | F76: =D76*E76 -> 2000
C77: cuisses de poulet | D77: 20 | E77: 200 | F77: =D77*E77 -> 4000
C78: rechta | D78: 10 | E78: 100 | F78: =D78*E78 -> 1000
C79: pate feuilletée | D79: 2 | E79: 400 | F79: =D79*E79 -> 800
C80: fromage blanc | D80: 1 | E80: 620 | F80: =D80*E80 -> 620
C81: Boites demie plateau | D81: 10 | E81: 150 | F81: =D81*E81 -> 1500
C82: viande morceaux | D82: 19 | E82: 400 | F82: =D82*E82 -> 7600
... C160: légumes | D160: 1 | E160: 2300 | F160: =D160*E160 -> 2300
B161: 180 | C161: Cuisses de poulet et blanc de poulet | D161: 20 | E161: 180 | F161: =D161*E161 -> 3600
B162: 300 | C162: viande morceaux | D162: 21 | E162: 300 | F162: =D162*E162 -> 6300
C163: deyoul | D163: 1 | E163: 200 | F163: =D163*E163 -> 200
C164: chakhechoukhate defer | D164: 5 | E164: 250 | F164: =D164*E164 -> 1250
B165: 100 | C165: rechta | D165: 65 | E165: 100 | F165: =D165*E165 -> 6500
C166: couscouss | D166: 5 | E166: 140 | F166: =D166*E166 -> 700
C167: Terida | D167: 5 | E167: 200 | F167: =D167*E167 -> 1000
C168: zebib | D168: 1 | E168: 1600 | F168: =D168*E168 -> 1600
C169: djouz | D169: 1 | E169: 200 | F169: =D169*E169 -> 200
C170: rechta | D170: 2 | E170: 120 | F170: =D170*E170 -> 240
C171: Kabouya | D171: 1 | E171: 100 | F171: =D171*E171 -> 100
C172: sachets de congélation 3kg | D172: 20 | E172: 45 | F172: =D172*E172 -> 900
...

Sheet les Salaires
K10: Nom | L10: Salaire | M10: Avance | N10: Salaire à payer
K11: Sofiane | L11: 30000 | M11: 30000 | N11: =L11-M11 -> 0
K12: Amel | L12: 30000 | M12: 30000 | N12: =L12-M12 -> 0
J13: 1 | K13: Lynda | L13: =Pointage!C35 -> 18148.2 | N13: =L13-M13 -> 18148.2
J14: 2 | K14: Hafida | L14: =Pointage!D35 -> 38702.5 | M14: 7000 | N14: =L14-M14 -> 31702.5 | O14: 5000+2000
J15: 3 | K15: Djamila | L15: =Pointage!E35 -> 32999.94 | N15: =L15-M15 -> 32999.94
J16: 4 | K16: Youssera | L16: =Pointage!F35 -> 10388.87 | M16: 10500 | N16: =L16-M16 -> -111.13
J17: 5 | K17: Yasmine Vendeuse | L17: =Pointage!G35 -> 29999.97 | N17: =L17-M17 -> 29999.97
J18: 6 | K18: Kenza | L18: =Pointage!H35 -> 1111.11 | N18: =L18-M18 -> 1111.11
J19: 7 | K19: Yasmine | L19: =Pointage!I35 -> 3450 | N19: =L19-M19 -> 3450
J20: 8 | K20: Nadjet | L20: =Pointage!K35 -> 19500 | M20: 11000 | N20: =L20-M20 -> 8500
J21: 9 | K21: Samira | L21: =Pointage!N35 -> 26666.64 | M21: 2000 | N21: =L21-M21 -> 24666.64
J22: 10 | K22: Alia | L22: =Pointage!L35 -> 19999.98 | M22: 1000 | N22: =L22-M22 -> 18999.98
J23: 11 | K23: Nadia | L23: =Pointage!O35 -> 18888.87 | M23: 19000 | N23: =L23-M23 -> -111.13
J24: 12 | K24: Fatiha | L24: =Pointage!M35 -> 26988 | N24: =L24-M24 -> 26988
J25: 13 | K25: Nadia femme de ménage | L25: =Pointage!P35*1 -> 8050 | M25: 8000 | N25: 0
J26: 14 | K26: Sarah | L26: =Pointage!Q35*1 -> 4000 | M26: 3000 | N26: =L26-M26 -> 1000 | O26: 1000+2000
J27: 15 | K27: Fouzia | L27: =Pointage!J35 -> 29455 | N27: =L27-M27 -> 29455
K28: TOTAL | L28: =SUM(L11:L27) -> 348349.08 | M28: =SUM(M11:M27) -> 121500 | N28: =SUM(N11:N27) -> 226799.08
K29: =L28-M28 -> 226849.08 | N29: =L29-M29 -> 0
C34: Nom | D34: Jours de Travaille | E34: Salaire | F34: Avance | G34: Salaire à payer
B35: 1 | C35: Lynda | D35: 14 | E35: 18148.2 | F35: 0 | G35: =E35-F35 -> 18148.2
B36: 2 | C36: Hafida | D36: 28.25 | E36: 38702.5 | F36: -7000 | G36: =E36+F36 -> 31702.5
B37: 3 | C37: Djamila | D37: 27 | E37: 33000 | F37: 0 | G37: =E37+F37 -> 33000
B38: 5 | C38: Yasmine Vendeuse | D38: 27 | E38: 30000 | F38: 5000 | G38: =E38+F38 -> 35000
B39: 6 | C39: Kenza | D39: 1 | E39: 1111.11 | F39: 0 | G39: =E39+F39 -> 1111.11
B40: 7 | C40: Yasmine | D40: 3 | E40: =L19 -> 3450 | F40: 0 | G40: =E40+F40 -> 3450
B41: 8 | C41: Nadjet | D41: 13 | E41: 19500 | F41: -11000 | G41: =E41+F41 -> 8500
B42: 9 | C42: Samira | D42: 24 | E42: 26666.64 | F42: -2000 | G42: =E42+F42 -> 24666.64
B43: 10 | C43: Alia | D43: 24 | E43: 20000 | F43: -1000 | G43: =E43+F43 -> 19000
B44: 12 | C44: Fatiha | D44: 26 | E44: 27000 | F44: 0 | G44: =E44+F44 -> 27000
B45: 14 | C45: Sarah | D45: 4 | E45: 4000 | F45: -3000 | G45: =E45+F45 -> 1000
B46: 15 | C46: Fouzia | D46: 21.5 | E46: 29455 | F46: 0 | G46: =E46+F46 -> 29455
C47: TOTAL | E47: =SUM(E30:E46) -> 251033.45 | F47: =SUM(F30:F46) -> -19000 | G47: =SUM(G30:G46) -> 232033.45

Sheet Feuille 5
L16: Mois de Decembre | M16: Mois de Janvier
K17: Recette | L17: 1672000 | M17: =RECAP!D33 -> 1751000
K18: Charges | L18: 727000 | M18: 920000
K19: Salaires | L19: 385000 | M19: 349000
K20: Loyer | L20: 110000 | M20: 140000
K21: Profit Net | L21: =L17-L18-L19-L20 -> 450000 | M21: =M17-M18-M19-M20 -> 342000
