Workbook

Sheet RECAP
B1: Date | C1: Recette juin 2023 | D1: Recette | E1: Charges | F1: Salaire | G1: Loyer | H1: Net Profit | I1: Nb de jours | K1: Objectif | L1: Mai | M1: Bénéfice Moyen par jour | N1: Moyenne | O1: Moyenne salaire | P1: pourcentage du salaire vis à vis la recettte
A2: Samedi | B2: 45108 | C2: 120000 | D2: 20000 | I2: 1 | K2: 100000 | L2: 120000 | M2: =H33/I33 -> 16570.865 | N2: =D33/I33 -> 60645.161 | P2: =O2/N2 -> 0
A3: dimanche | B3: 45109 | C3: 85000 | D3: 30000 | I3: 1 | K3: 100000 | L3: 85000
A4: lundi | B4: 45110 | C4: 42000 | D4: 45000 | I4: 1 | K4: 100000 | L4: 42000 | M4: Moyenne des charges par jour | N4: Objectif
A5: mardi | B5: 45111 | C5: 38000 | D5: 48000 | I5: 1 | K5: 100000 | L5: 38000 | M5: =E33/I33 -> 26907.065 | N5: 100000
A6: mercredi | B6: 45112 | C6: 45000 | D6: 44000 | I6: 1 | K6: 100000 | L6: 45000 | M6: ²
A7: jeudi | B7: 45113 | C7: 40000 | D7: 100000 | I7: 1 | K7: 100000 | L7: 40000
A8: vendredi | B8: 45114 | C8: 30000 | D8: 40000 | I8: 1 | K8: 100000 | L8: 30000 | M8: Cash restant | N8: Magasin
A9: samedi | B9: 45115 | C9: 60000 | D9: 42000 | I9: 1 | J9: 39000 | K9: 100000 | L9: 60000 | M9: =D33-E33-N9-Salaires!J23 -> 571881 | N9: =O9*1 -> 57000 | O9: 57000
A10: dimanche | B10: 45116 | C10: 38000 | D10: 31000 | I10: 1 | K10: 100000 | L10: 38000
A11: lundi | B11: 45117 | C11: 64000 | D11: 30000 | I11: 1 | K11: 100000 | L11: 64000 | M11: loyer
A12: mardi | B12: 45118 | C12: 24000 | D12: 48000 | I12: 1 | K12: 100000 | L12: 24000 | O12: La caisse : 15000 Da
A13: mercredi | B13: 45119 | C13: 35000 | D13: 76000 | I13: 1 | K13: 100000 | L13: 35000 | N13: Sofiane 64000Da | O13: VMR MAGHREB: 24000Da
A14: jeudi | B14: 45120 | C14: 80000 | D14: 100000 | I14: 1 | K14: 100000 | L14: 80000 | O14: che7i7a: 7000Da +11000Da
A15: vendredi | B15: 45121 | C15: 43000 | D15: 75000 | I15: 1 | K15: 100000 | L15: 43000
A16: samedi | B16: 45122 | C16: 80000 | D16: 93000 | I16: 1 | K16: 100000 | L16: 80000
A17: dimanche | B17: 45123 | C17: 24000 | D17: 39000 | I17: 1 | K17: 100000 | L17: 24000 | M17: Différence mois de Juin
A18: lundi | B18: 45124 | C18: 66000 | D18: 50000 | I18: 1 | K18: 100000 | L18: 66000 | M18: =D33-C33 -> 303000
A19: mardi | B19: 45125 | C19: 50000 | D19: 71000 | I19: 1 | K19: 100000 | L19: 50000 | M19: Différence objectif
A20: mercredi | B20: 45126 | C20: 12000 | D20: 120000 | I20: 1 | K20: 100000 | L20: 12000 | M20: =K34-E34 -> 0
A21: jeudi | B21: 45127 | C21: 28000 | D21: 49000 | I21: 1 | K21: 100000 | L21: 28000 | M21: Différence du Totale
A22: vendredi | B22: 45128 | C22: 48000 | D22: 42000 | I22: 1 | K22: 100000 | L22: 48000 | M22: =D33-L33 -> 303000
A23: samedi | B23: 45129 | C23: 39000 | D23: 35000 | I23: 1 | K23: 100000 | L23: 39000 | M23: Les vendredis
A24: dimanche | B24: 45130 | C24: 40000 | D24: 74000 | I24: 1 | K24: 100000 | L24: 40000 | M24: =E4+E11+E18+E25 -> 0
A25: lundi | B25: 45131 | C25: 36000 | D25: 40000 | I25: 1 | K25: 100000 | L25: 36000
A26: mardi | B26: 45132 | C26: 50000 | D26: 40000 | I26: 1 | K26: 100000 | L26: 50000 | M26: Cash réel
A27: mercredi | B27: 45133 | C27: 120000 | D27: 60000 | I27: 1 | K27: 100000 | L27: 120000 | M27: 320000 | N27: AADL / 20000Da
A28: jeudi | B28: 45134 | C28: 240000 | D28: 123000 | I28: 1 | K28: 100000 | L28: 240000 | M28: rest à payer | N28: Sousou: 20000a
A29: vendredi | B29: 45135 | C29: 0 | D29: 115000 | I29: 1 | K29: 100000 | L29: 0 | N29: Nadjet : 30000Da
A30: samedi | B30: 45136 | C30: 0 | D30: 70000 | I30: 1 | K30: 100000 | L30: 0 | N30: Islem : 24000 Da
A31: dimanche | B31: 45137 | C31: 0 | D31: 70000 | I31: 1 | L31: 0 | M31: 94000 | N31: 94000
A32: lundi | B32: 45138 | C32: 0 | D32: 60000 | I32: 1
C33: =SUM(C2:C32) -> 1577000 | D33: =SUM(D2:D32) -> 1880000 | E33: ='Les Charges '!F243*1 -> 834119 | F33: =Salaires!I23*1 -> 422184.2 | G33: 110000 | H33: =D33-E33-F33-G33 -> 513696.8 | I33: =SUM(I2:I32) -> 31 | L33: =SUM(L2:L32) -> 1577000 | M33: =M9-M27-M31 -> 157881

Sheet Les Charges 
C2: Produit | D2: Quantité | E2: Prix unitaire | F2: Prix | G2: Date d'achat
C3: sac croissant 23+18 | D3: 1 | E3: 1500 | F3: =E3*D3 -> 1500 | G3: 45078
C4: Canette Coca et Fanta | D4: 3 | E4: 1680 | F4: =E4*D4 -> 5040 | G4: 45078
C5: nacré | D5: 2 | E5: 550 | F5: =D5*E5 -> 1100 | G5: 45102
C6: feuilltine | D6: 1 | E6: 500 | F6: =D6*E6 -> 500 | G6: 45102
C7: sucre glace Houda | D7: 16 | E7: 110 | F7: =D7*E7 -> 1760 | G7: 45102
C8: les quissetes 08 | D8: 8 | E8: 90 | F8: =D8*E8 -> 720 | G8: 45102
C9: dentelle 4,5 | D9: 20 | E9: 90 | F9: =D9*E9 -> 1800 | G9: 45102
C10: dentelle 5,5 | D10: 20 | E10: 100 | F10: =D10*E10 -> 2000 | G10: 45102
C11: Tomate conserve | D11: 12 | E11: 235 | F11: =D11*E11 -> 2820 | G11: 45102
C12: Maa zehar | D12: 30 | E12: 70 | F12: =D12*E12 -> 2100 | G12: 45108
C13: chocolat a tartiner | D13: 1 | E13: 3450 | F13: =D13*E13 -> 3450 | G13: 14/06/2023
C14: Quissetes blanc 10 | D14: 1 | E14: 1220 | F14: =D14*E14 -> 1220 | G14: 14/06/2023
C15: Quissetes blanc 12 | D15: 1 | E15: 870 | F15: =D15*E15 -> 870 | G15: 14/06/2023
C16: Maiizina | D16: 10 | E16: 180 | F16: =D16*E16 -> 1800 | G16: 13/06/2023
C17: amandes éfilet | D17: 1 | E17: 1950 | F17: =D17*E17 -> 1950 | G17: 13/06/2023
C18: Noix | D18: 1 | E18: 1280 | F18: =D18*E18 -> 1280 | G18: 13/06/2023
C19: Smail arome fleur d'oranger | D19: 1 | E19: 800 | F19: =E19*D19 -> 800 | G19: 45078
C20: Pate d'arome citron | D20: 1 | E20: 740 | F20: =E20*D20 -> 740 | G20: 45078
C21: boites demie plateaux | D21: 25 | E21: 80 | F21: =E21*D21 -> 2000 | G21: 45078
C22: Lait en poudre | D22: 3 | E22: 530 | F22: =E22*D22 -> 1590 | G22: 45078
C23: Boites 48/10 | D23: 4 | E23: 2050 | F23: =E23*D23 -> 8200 | G23: 44999
C24: Boites 48/07 | D24: 2 | E24: 1550 | F24: =D24*E24 -> 3100 | G24: 45108
C25: Boites 36/07 | D25: 3 | E25: 1200 | F25: =D25*E25 -> 3600 | G25: 45108
C26: Boite 08 | D26: 1 | E26: 1150 | F26: =D26*E26 -> 1150 | G26: 018/07/2023
C27: eau mineral 1,5 lire | D27: 12 | E27: 203 | F27: =D27*E27 -> 2436 | G27: 45041
C28: Eau mineral 0,5 litre | D28: 8 | E28: 200 | F28: =D28*E28 -> 1600 | G28: 45041
C29: Semen Madina | D29: 8 | E29: 800 | F29: =E29*D29 -> 6400 | G29: 45069
C30: Margarine Fleurial 500 | D30: 5 | E30: 202 | F30: =D30*E30 -> 1010 | G30: 45069
C31: chocolat wedjedene noisette | D31: 8 | E31: 260 | F31: =E31*D31 -> 2080 | G31: 21/01/2023
C32: chocolat wedjedane blanc ,au lait et noir | D32: 30 | E32: 225 | F32: =E32*D32 -> 6750 | G32: 44947
C33: vitres | D33: 1 | E33: 1000 | F33: =D33*E33 -> 1000 | G33: 45102
C34: oeufs | D34: 2 | E34: 550 | F34: =D34*E34 -> 1100 | G34: 45102
C35: bessel | D35: 40 | E35: 50 | F35: =D35*E35 -> 2000 | G35: 45103
C36: bessel | D36: 40 | E36: 55 | F36: =D36*E36 -> 2200 | G36: 45103
C37: felexy | D37: 1 | E37: 1500 | F37: =D37*E37 -> 1500 | G37: 45103
C38: Coca et Fanta 33cl | D38: 3 | E38: 550 | F38: =E38*D38 -> 1650 | G38: 45083
C39: Soda Slim 33cl | D39: 4 | E39: 420 | F39: =D39*E39 -> 1680 | G39: 14/06/2023
C40: Huile Elio 5 litres | D40: 10 | E40: 600 | F40: =D40*E40 -> 6000 | G40: 45084
C41: miel 5kg | D41: 4 | E41: 780 | F41: =D41*E41 -> 3120 | G41: 45084
...

Sheet Pointage
B1: Date | C1: Lynda | D1: Hafida | E1: Djamila | F1: Samira Malawi | G1: Youssera | H1: Thiziri | I1: Kenza | J1: Yasmine | K1: Nadia | L1: Fadhila | M1: Farida | N1: Samia | O1: Nora | P1: Fouzia | Q1: Remarque
A2: Samedi | B2: 45108 | C2: 1 | D2: 0 | E2: 0 | F2: 1 | G2: 1 | H2: 1 | I2: 0 | J2: 1 | K2: 1 | L2: 1 | M2: 0 | N2: 0 | O2: 0 | P2: 0
A3: dimanche | B3: 45109 | C3: 1 | D3: 1 | E3: 0 | F3: 1 | G3: 1 | H3: 1 | I3: 0 | J3: 0 | K3: 1 | L3: 1 | M3: 0 | N3: 0 | O3: 0 | P3: 1
A4: lundi | B4: 45110 | C4: 1.5 | D4: 1 | E4: 0 | F4: 0 | G4: 1 | H4: 1 | I4: 1 | J4: 1 | K4: 1 | L4: 1 | M4: 0 | N4: 0 | O4: 0 | P4: 1
A5: mardi | B5: 45111 | C5: 1 | D5: 1 | E5: 0 | F5: 1 | G5: 1 | H5: 1 | I5: 1 | J5: 1 | K5: 1 | L5: 1 | M5: 1 | N5: 0 | O5: 0 | P5: 1
A6: mercredi | B6: 45112 | C6: 1 | D6: 1 | E6: 0 | F6: 1 | G6: 1 | H6: 1 | I6: 1 | J6: 1 | K6: 1 | L6: 1 | M6: 1 | N6: 0 | O6: 0 | P6: 1 | Q6: 1
A7: jeudi | B7: 45113 | C7: 2 | D7: 2 | E7: 0 | F7: 2 | G7: 0 | H7: 1 | I7: 1,5 | J7: 1 | K7: 1 | L7: 0 | M7: 2 | N7: 0 | O7: 0 | P7: 2
A8: vendredi | B8: 45114 | C8: 1 | D8: 1 | E8: 0 | F8: 1 | G8: 0 | H8: 1 | I8: 1 | J8: 1 | K8: 0 | L8: 0 | M8: 1 | N8: 0 | O8: 0 | P8: 0
A9: samedi | B9: 45115 | C9: 1 | D9: 0.5 | E9: 0 | F9: 1 | G9: 1 | H9: 0 | I9: 1 | J9: 1 | K9: 1 | L9: 0 | M9: 1 | N9: 0 | O9: 1 | P9: 0 | Q9: il y'avait pas de travaille Hafida ra7et lel dentiste à 12h et les autres kharedjou à 14h30
A10: dimanche | B10: 45116 | C10: 1.5 | D10: 1 | E10: 1 | F10: 1 | G10: 1 | H10: 1 | I10: 1 | J10: 1 | K10: 1 | L10: 0 | M10: 1 | N10: 1 | O10: 1 | P10: 1 | Q10: le magasin: il y'avait pas beaucoup de travaille elles sont sortis à 15h autorisé le locale : youssera kharedjet à 13h 30 et lynda et kenza 9a3edou darou ménage
A11: lundi | B11: 45117 | C11: 1 | D11: 1 | E11: 1 | F11: 0.5 | G11: 1 | H11: 1 | I11: 1 | J11: 0 | K11: 1 | L11: 0 | M11: 0 | N11: 1 | O11: 1 | P11: 0 | Q11: Samira djate en retard + les autres employées khalitehom yekhoredjou bekeri à 16h
A12: mardi | B12: 45118 | C12: 1.5 | D12: 1 | E12: 1 | F12: 1 | G12: 1 | H12: 1 | I12: 1 | J12: 1 | K12: 1 | L12: 0 | M12: 1 | N12: 1 | O12: 1 | P12: 0 | Q12: kharedjou ga3 à 14h30 max
A13: mercredi | B13: 45119 | C13: 2 | D13: 1 | E13: 1 | F13: 0 | G13: 0.4 | H13: 1 | I13: 2 | J13: 1 | K13: 1 | L13: 0 | M13: 1 | N13: 1 | O13: 1 | P13: 0 | Q13: kharedjou entre 14h 30 à 15h30 , youssera kharedjet à 11h sans autorisation normalement tokhredj à 12h
A14: jeudi | B14: 45120 | C14: 2 | D14: 1 | E14: 1 | F14: 1 | G14: 0 | H14: 1 | I14: 2 | J14: 1 | K14: 1 | L14: 0 | M14: 1 | N14: 1 | O14: 1 | P14: 1
A15: vendredi | B15: 45121 | C15: 0 | D15: 1 | E15: 1 | F15: 1 | G15: 0 | H15: 1 | I15: 1 | J15: 1 | K15: 0 | L15: 0 | M15: 1 | N15: 0 | O15: 1 | P15: 0
A16: samedi | B16: 45122 | C16: 1.25 | D16: 1 | E16: 1.25 | F16: 1 | G16: 1 | H16: 1 | I16: 0 | J16: 1 | K16: 1 | L16: 0 | M16: 1.25 | N16: 1 | O16: 0 | P16: 0 | Q16: djaw bekeri et kharedjou à 15h30 max mais on avais une commande de 200 pièces et kharedjouha avant midi
A17: dimanche | B17: 45123 | C17: 0,5 | D17: 1.25 | E17: 1 | F17: 0 | G17: 0 | H17: 1 | I17: 0 | J17: 1 | K17: 1 | L17: 0 | M17: 1 | N17: 1 | O17: 1 | P17: 0 | Q17: Hafida khaliteha toukhredj à 13h30 pour dentiste et les autres vers 15h et Lynda djate darte tchrak et 3arayech we ra7et
A18: lundi | B18: 45124 | C18: 1 | D18: 1 | E18: 1 | F18: 1 | G18: 1 | H18: 0 | I18: 1 | J18: 1 | K18: 1 | L18: 0 | M18: 1 | N18: 1.5 | O18: 1 | P18: 0
A19: mardi | B19: 45125 | C19: 1.5 | D19: 1.5 | E19: 0 | F19: 1.5 | G19: 0.75 | H19: 1 | I19: 1 | J19: 1.5 | K19: 1 | L19: 0 | M19: 1.5 | N19: 1.5 | O19: 1.5 | P19: 0 | Q19: keemlou bekeri mais zedetelhom fe salaire puisque 3ayaw bezaf fe sekhana et wedjedou ga3 les commandes
A20: mercredi | B20: 45126 | C20: 1 | D20: 1 | E20: 0 | F20: 1 | G20: 0 | H20: 1 | I20: 1 | J20: 1 | K20: 1 | L20: 0 | M20: 1 | N20: 1.25 | O20: 1 | P20: 0
A21: jeudi | B21: 45127 | C21: 2 | D21: 1 | E21: 1 | F21: 1 | G21: 0 | H21: 1 | I21: 1.5 | J21: 0 | K21: 1 | L21: 0 | M21: 1 | N21: 1 | O21: 1 | P21: 0
A22: vendredi | B22: 45128 | C22: 1 | D22: 1 | E22: 1 | F22: 1 | G22: 0 | H22: 2 | I22: 2 | J22: 2 | K22: 0 | L22: 0 | M22: 1 | N22: 1 | O22: 1 | P22: 0
A23: samedi | B23: 45129 | C23: 0 | D23: 0.5 | E23: 1 | F23: 1 | G23: 0 | H23: 1 | I23: 1 | J23: 0 | K23: 1 | L23: 0 | M23: 1 | N23: 0 | O23: 1 | P23: 0
A24: dimanche | B24: 45130 | C24: 1 | D24: 1 | E24: 1 | F24: 1 | G24: 0 | H24: 1 | I24: 1 | J24: 1 | K24: 1 | L24: 0 | M24: 1 | N24: 1 | O24: 1 | P24: 0
A25: lundi | B25: 45131 | C25: 1 | D25: 1 | E25: 1 | F25: 0 | G25: 0 | H25: 1 | I25: 1 | J25: 1 | K25: 0 | L25: 0 | M25: 1 | N25: 1 | O25: 1 | P25: 0
A26: mardi | B26: 45132 | C26: 1.5 | D26: 1 | E26: 1 | F26: 1 | G26: 0 | H26: 0 | I26: 1 | J26: 1 | K26: 1 | L26: 0 | M26: 1 | N26: 1 | O26: 1 | P26: 0
A27: mercredi | B27: 45133 | C27: 1 | D27: 1 | E27: 1 | F27: 1 | G27: 0 | H27: 1 | I27: 1 | J27: 1 | K27: 1 | L27: 0 | M27: 1 | N27: 1 | O27: 1 | P27: 0
A28: jeudi | B28: 45134 | C28: 1 | D28: 1 | E28: 1 | F28: 1 | G28: 0 | H28: 1 | I28: 1 | J28: 1 | K28: 1 | L28: 0 | M28: 1 | N28: 1 | O28: 0.5 | P28: 0 | Q28: djate Nora à 11h
A29: vendredi | B29: 45135 | C29: 0 | D29: 1.5 | E29: 1.5 | F29: 1 | G29: 0 | H29: 1 | I29: 1 | J29: 1 | K29: 0 | L29: 0 | M29: 0 | N29: 0 | O29: 0.5 | P29: 0 | Q29: Nora djate à 11h et les autres kharedjou à 17h
A30: samedi | B30: 45136 | C30: 1.5 | D30: 1 | E30: 1 | F30: 1 | G30: 0 | H30: 1 | I30: 1.25 | J30: 1 | K30: 1 | L30: 0 | M30: 1 | N30: 1 | O30: 0 | P30: 0 | Q30: khardjou à 16h
A31: dimanche | B31: 45137 | C31: 1.5 | D31: 1 | E31: 1 | F31: 1 | G31: 0 | H31: 1 | I31: 1 | J31: 1 | K31: 1 | L31: 0 | M31: 1 | N31: 1 | O31: 1 | P31: 0 | Q31: kharedjou à 15h30
A32: lundi | B32: 45138 | C32: 1 | D32: 1 | E32: 1 | F32: 1 | G32: 0 | H32: 1 | I32: 1 | J32: 1 | K32: 1 | L32: 0 | M32: 1 | N32: 1 | O32: 1 | P32: 0 | Q32: kharedjou à 15h30
C33: =SUM(C2:C32) -> 34.75 | D33: =SUM(D2:D32) -> 31.25 | E33: =SUM(E2:E32) -> 21.75 | F33: =SUM(F2:F32) -> 28 | G33: =SUM(G2:G32) -> 12.15 | H33: =SUM(H2:H32) -> 29 | I33: =SUM(I2:I32) -> 29.75 | J33: =SUM(J2:J32) -> 28.5 | ... P33: =SUM(P2:P32) -> 8
C34: 1223 | D34: 1300 | E34: 1223 | F34: 1037 | G34: 1223 | H34: 1000 | I34: 1037 | J34: 1037 | K34: 1000 | L34: 1000 | M34: 1300 | N34: 1100 | O34: 926 | P34: 1100
C35: =C33*C34 -> 42499.25 | D35: =D34*D33 -> 40625 | E35: =E34*E33 -> 26600.25 | F35: =F34*F33 -> 29036 | G35: =G34*G33 -> 14859.45 | H35: =H34*H33 -> 29000 | I35: =I34*I33 -> 30850.75 | J35: =J34*J33 -> 29554.5 | K35: =K34*K33 -> 26000 | L35: =L34*L33 -> 5000 | M35: =M33*M34 -> 36075 | N35: =N33*N34 -> 23375 | O35: =O33*O34 -> 19909 | P35: =P33*P34 -> 8800 | Q35: =SUM(D35:J35) -> 200525.95
E36: 2175

Sheet Salaires
A1: 86000
H6: Nom | I6: Salaire | J6: Avance | K6: Salaire à payer
G7: 1 | H7: Sofiane | I7: 30000 | J7: 30000 | K7: =I7-J7 -> 0 | L7: 10000+17000
G8: 2 | H8: Amel | I8: 30000 | J8: 30000 | K8: =I8-J8 -> 0
G9: 3 | H9: Lynda | I9: =Pointage!C35*1 -> 42499.25 | J9: 41000 | K9: =I9-J9 -> 1499.25
G10: 4 | H10: Hafida | I10: =Pointage!D35*1 -> 40625 | J10: 39000 | K10: =I10-J10 -> 1625
G11: 5 | H11: Djamila | I11: =Pointage!E35*1 -> 26600.25 | J11: 25000 | K11: =I11-J11 -> 1600.25
G12: 6 | H12: Samira Malawi | I12: =Pointage!F35*1 -> 29036 | J12: 29000 | K12: =I12-J12 -> 36 | L12: 1000+28000
G13: 7 | H13: Youssera | I13: =Pointage!G35*1 -> 14859.45 | J13: 15000 | K13: =I13-J13 -> -140.55
G14: 8 | H14: Thiziri | I14: =Pointage!H35*1 -> 29000 | J14: 29000 | K14: =I14-J14 -> 0
G15: 9 | H15: Kenza | I15: =Pointage!I35*1 -> 30850.75 | J15: 31000 | K15: =I15-J15 -> -149.25
G16: 10 | H16: Yasmine | I16: =Pointage!J35*1 -> 29554.5 | J16: 30000 | K16: =I16-J16 -> -445.5
G17: 11 | H17: Nadia | I17: =Pointage!K35*1 -> 26000 | J17: 26000 | K17: =I17-J17 -> 0
G18: 12 | H18: Fadhila | I18: =Pointage!L35*1 -> 5000 | J18: 5000 | K18: =I18-J18 -> 0
G19: 13 | H19: Farida | I19: =Pointage!M35*1 -> 36075 | J19: 34500 | K19: =I19-J19 -> 1575
G20: 14 | H20: Samia | I20: =Pointage!N35*1 -> 23375 | J20: 23500 | K20: =I20-J20 -> -125
G21: 15 | H21: Nora | I21: =Pointage!O35*1 -> 19909 | J21: 20000 | K21: =I21-J21 -> -91
G22: 16 | H22: Fouzia | I22: =Pointage!P35*1 -> 8800 | J22: 9000 | K22: =I22-J22 -> -200
H23: TOTAL | I23: =SUM(I7:I22) -> 422184.2 | J23: =SUM(J7:J22) -> 417000 | K23: =SUM(K7:K22) -> 5184.2
H24: =I23-J23 -> 5184.2 | K24: =I24-J24 -> 0

Sheet RECAP Mentuel
H10: Mois de Février | I10: Mois de Mars | J10: Mois d'Avril | K10: Mois de Mai | L10: Mois de Jiun | M10: Mois de Juillet
G11: Recette | H11: 1400000 | I11: 1928000 | J11: 1488000 | K11: 1540000 | L11: 1577000 | M11: =RECAP!D33 -> 1880000
G12: Charges | H12: 597000 | I12: 938000 | J12: 670000 | K12: 753000 | L12: 716000 | M12: 834000
G13: Salaires | H13: 413000 | I13: 360000 | J13: 335000 | K13: 347000 | L13: 331000 | M13: 416000
G14: Loyer | H14: 110000 | I14: 110000 | J14: 110000 | K14: 110000 | L14: 110000 | M14: 110000
G15: Profit Net | H15: 280000 | I15: 520000 | J15: 370000 | K15: =K11-K12-K13-K14 -> 330000 | L15: =L11-L12-L13-L14 -> 420000 | M15: =M11-M12-M13-M14 -> 520000

Sheet Feuille 6
K6: Bénéfice | L6: 420000
K7: les charges | L7: 154000
K8: CCp | L8: 75000
K9: Cash | L9: 56000
K10: Islem | L10: 31000
K11: Nadjet | L11: 34000
L20: =L6-L7-L8-L9-L10-L11 -> 70000
