Workbook

Sheet RECAP
B1: Date | C1: Mars | D1: Recette | E1: Charges | F1: Salaire | G1: Loyer | H1: Net Profit | I1: Nb de jours | K1: Objectif | L1: 45352
A2: Lundi | B2: 45383 | C2: 63000 | D2: 74000 | I2: 1 | L2: 63000
A3: Mardi | B3: 45384 | C3: 32000 | D3: 37000 | I3: 1 | L3: 32000 | M3: Bénéfice Moyen par jour | N3: Moyenne | O3: Moyenne salaire | P3: pourcentage du salaire vis à vis la recettte
A4: Mercredi | B4: 45385 | C4: 45000 | D4: 62000 | I4: 1 | L4: 45000 | M4: =H32/I32 -> 27210.833 | N4: =D32/I32 -> 76400 | P4: =F32/D32 -> 0.18081789
A5: Jeudi | B5: 45386 | C5: 73000 | D5: 62000 | I5: 1 | L5: 73000
A6: Vendredi | B6: 45387 | C6: 65000 | D6: 21000 | I6: 1 | L6: 65000 | M6: Moyenne des charges par jour | N6: Objectif
A7: Samedi | B7: 45388 | C7: 62000 | D7: 33000 | I7: 1 | L7: 62000 | M7: =E32/I32 -> 29774.68 | N7: 100000
A8: Dimanche | B8: 45389 | C8: 70000 | D8: 500000 | I8: 1 | L8: 70000 | M8: ²
A9: Lundi | B9: 45390 | C9: 43000 | D9: 240000 | I9: 1 | L9: 43000
A10: Mardi | B10: 45391 | C10: 85000 | D10: 0 | I10: 0 | L10: 85000 | M10: Cash restant | N10: Magasin | O10: Cash réel | P10: Mes dettes pour le magasin
A11: Mercredi | B11: 45392 | C11: 100000 | D11: 0 | I11: 0 | L11: 100000 | M11: =M14+D32-E32-N11-Salaires!M31 -> 1097633 | N11: 49000 | O11: 887000 | P11: =M11-O11 -> 210633
A12: Jeudi | B12: 45393 | C12: 55000 | D12: 0 | I12: 0 | L12: 55000
A13: Vendredi | B13: 45394 | C13: 70000 | D13: 0 | I13: 0 | L13: 70000 | M13: Fond de Roulement
A14: Samedi | B14: 45395 | C14: 60000 | D14: 30000 | I14: 0 | L14: 60000 | M14: 330000 | P14: Demain je prends de la caisse: 22000Da
A15: Dimanche | B15: 45396 | C15: 80000 | D15: 40000 | I15: 1 | L15: 80000 | P15: Salim: 7000
A16: Lundi | B16: 45397 | C16: 52000 | D16: 45000 | I16: 1 | L16: 52000 | O16: 853000 | P16: Monnie :
A17: Mardi | B17: 45398 | C17: 54000 | D17: 45000 | I17: 1 | L17: 54000 | P17: ccp:30000Da
A18: Mercredi | B18: 45399 | C18: 52000 | D18: 49000 | I18: 1 | L18: 52000 | O18: Che7i7a: 12000Da
A19: Jeudi | B19: 45400 | C19: 50000 | D19: 85000 | I19: 1 | L19: 50000 | M19: Différence mois de Février | P19: la vraie caisse: 22000 Da
A20: Vendredi | B20: 45401 | C20: 50000 | D20: 40000 | I20: 1 | L20: 50000 | M20: =D32-C32 -> 12000
A21: Samedi | B21: 45402 | C21: 54000 | D21: 42000 | I21: 1 | L21: 54000 | M21: Différence objectif | O21: réparation Tabouna | P21: 1 | Q21: 8800 | R21: =P21*Q21 -> 8800
A22: Dimanche | B22: 45403 | C22: 70000 | D22: 43000 | I22: 1 | L22: 70000 | M22: =K35-E35 -> 0 | O22: Torchons | P22: 4 | Q22: 400 | R22: 600
A23: Lundi | B23: 45404 | C23: 76000 | D23: 60000 | I23: 1 | L23: 76000 | M23: Différence du Totale | O23: poelle | P23: 1 | Q23: 2800 | R23: =P23*Q23 -> 2800
A24: Mardi | B24: 45405 | C24: 63000 | D24: 54000 | I24: 1 | L24: 63000 | M24: =D32-C32 -> 12000 | R24: =SUM(R21:R23) -> 12200
A25: Mercredi | B25: 45406 | C25: 90000 | D25: 65000 | I25: 1 | L25: 90000 | M25: Les vendredis
A26: Jeudi | B26: 45407 | C26: 66000 | D26: 92000 | I26: 1 | L26: 66000 | M26: =D2+D9+D16+D23+D30 -> 459000
A27: Vendredi | B27: 45408 | C27: 83000 | D27: 26000 | I27: 1 | L27: 83000
A28: Samedi | B28: 45409 | C28: 52000 | D28: 41000 | I28: 1 | L28: 52000
A29: Dimanche | B29: 45410 | C29: 72000 | D29: 38000 | I29: 1 | L29: 72000
A30: Lundi | B30: 45411 | C30: 41000 | D30: 40000 | I30: 1 | L30: 41000
A31: Mardi | B31: 45412 | C31: 70000 | D31: 46000 | I31: 1 | L31: 70000
C32: =SUM(C2:C31) -> 1898000 | D32: =SUM(D2:D31) -> 1910000 | E32: ='Les Charges '!G345 -> 744367 | F32: =Salaires!L31 -> 345362.17 | G32: 140000 | H32: =D32-E32-F32-G32 -> 680270.83 | I32: =SUM(I2:I31) -> 25 | L32: =SUM(L2:L31) -> 1898000
D34: 2274000 | E34: 914000 | F34: 410000 | G34: 140000 | H34: 810000 | M34: =M11-M29-M33 -> 1097633

Sheet Pointage
B1: Date | C1: Lynda | D1: Hafida | E1: Yasmine Sidi Abd Allah | F1: Kenza | G1: Yasmine Dely Brahim | H1: Fouzia | I1: Nadjet | J1: Fatiha | K1: Samira | L1: Zohra | M1: Sarah | N1: Nesrine | O1: Nesrine | P1: Ilhem | Q1: Chiraz | R1: Romaissa
A2: Lundi | B2: 45383 | C2: 1 | D2: 1 | E2: 0 | F2: 0 | G2: 0 | H2: 2 | I2: 1 | J2: 1 | K2: 1 | L2: 1 | M2: 1.5 | N2: 0 | O2: 0 | P2: 0 | Q2: 1 | R2: 1 | S2: Fouzia 50 3arayech et Sarah base de sablés
A3: Mardi | B3: 45384 | C3: 2 | D3: 1 | E3: 1 | F3: 0 | G3: 0 | H3: 2 | I3: 1 | J3: 1 | K3: 1 | L3: 0 | M3: 1.5 | N3: 1 | O3: 1 | P3: 0 | Q3: 1 | R3: 1 | S3: Fouzia mechewek elrouz et deziryates et Sarah base des russes
A4: Mercredi | B4: 45385 | C4: 1 | D4: 1 | E4: 1 | F4: 1.5 | G4: 1.5 | H4: 1 | I4: 1 | J4: 1 | K4: 1 | L4: 1 | M4: 1 | N4: 1 | O4: 1 | P4: 0 | Q4: 1.5 | R4: 1 | S4: Lynda ma djatech mais daret bakelawa et makrout elkoucha
A5: Jeudi | B5: 45386 | C5: 2 | D5: 1 | E5: 1 | F5: 1.25 | G5: 1.25 | H5: 1 | I5: 1 | J5: 1 | K5: 1 | L5: 0 | M5: 1 | N5: 1 | O5: 1 | P5: 0 | Q5: 2 | R5: 0
A6: Vendredi | B6: 45387 | C6: 1 | D6: 1 | E6: 2 | F6: 1.25 | G6: 1 | H6: 1 | I6: 1 | J6: 1 | K6: 1 | L6: 0 | M6: 0 | N6: 1 | O6: 1 | P6: 0 | Q6: 1.5 | R6: 1
A7: Samedi | B7: 45388 | C7: 2 | D7: 1 | E7: 1 | F7: 0 | G7: 1 | H7: 2 | I7: 1 | J7: 1 | K7: 1 | L7: 0 | M7: 0 | N7: 1 | O7: 1 | P7: 0 | Q7: 1.5 | R7: 1
A8: Dimanche | B8: 45389 | C8: 2 | D8: 1 | E8: 2 | F8: 0 | G8: 1 | H8: 1 | I8: 1 | J8: 1 | K8: 1 | L8: 0 | M8: 0 | N8: 1 | O8: 1 | P8: 0 | Q8: 1 | R8: 1
A9: Lundi | B9: 45390 | C9: 0 | D9: 0 | E9: 0 | F9: 0 | G9: 0 | H9: 0 | I9: 0 | J9: 1 | K9: 0 | L9: 0 | M9: 0 | N9: 0 | O9: 0 | P9: 0 | Q9: 1 | R9: 0
A10: Mardi | B10: 45391 | C10: 0 | D10: 0 | E10: 0 | F10: 0 | G10: 0 | H10: 0 | I10: 0 | J10: 0 | K10: 0 | L10: 0 | M10: 0 | N10: 0 | O10: 0 | P10: 0 | Q10: 0 | R10: 0
A11: Mercredi | B11: 45392 | C11: 0 | D11: 0 | E11: 0 | F11: 0 | G11: 0 | H11: 0 | I11: 0 | J11: 0 | K11: 0 | L11: 0 | M11: 0 | N11: 0 | O11: 0 | P11: 0 | Q11: 0 | R11: 0
A12: Jeudi | B12: 45393 | C12: 0 | D12: 0 | E12: 0 | F12: 0 | G12: 0 | H12: 0 | I12: 0 | J12: 0 | K12: 0 | L12: 0 | M12: 0 | N12: 0 | O12: 0 | P12: 0 | Q12: 0 | R12: 0
A13: Vendredi | B13: 45394 | C13: 0 | D13: 0 | E13: 0 | F13: 0 | G13: 0 | H13: 0 | I13: 0 | J13: 0 | K13: 0 | L13: 0 | M13: 0 | N13: 0 | O13: 0 | P13: 0 | Q13: 0 | R13: 0
A14: Samedi | B14: 45395 | C14: 0 | D14: 1 | E14: 1 | F14: 0 | G14: 0 | H14: 1 | I14: 0 | J14: 1 | K14: 1 | L14: 1 | M14: 0 | N14: 0.5 | O14: 0.5 | P14: 0 | Q14: 1 | R14: 1
A15: Dimanche | B15: 45396 | C15: 0 | D15: 1 | E15: 1 | F15: 0 | G15: 0 | H15: 1 | I15: 0 | J15: 1 | K15: 1 | L15: 0 | M15: 0 | N15: 0 | O15: 0 | P15: 0 | Q15: 1 | R15: 1
A16: Lundi | B16: 45397 | C16: 0 | D16: 1 | E16: 1 | F16: 0 | G16: 0 | H16: 1 | I16: 0 | J16: 1 | K16: 0 | L16: 1 | M16: 0 | N16: 0 | O16: 0 | P16: 0 | Q16: 0.5 | R16: 1
... A31: Mardi | B31: 45412 | C31: 0 | D31: 1 | E31: 1 | F31: 0 | G31: 0 | H31: 0 | I31: 0 | J31: 1 | K31: 0.5 | L31: 0 | M31: 0 | N31: 0 | O31: 0 | P31: 1 | Q31: 0 | R31: 0
C32: =SUM(C2:C31) -> 13 | D32: =SUM(D2:D31) -> 23.2 | E32: =SUM(E2:E31) -> 25 | F32: =SUM(F2:F31) -> 5 | G32: =SUM(G2:G31) -> 6.75 | H32: =SUM(H2:H31) -> 21 | I32: =SUM(I2:I31) -> 15.4 | J32: =SUM(J2:J31) -> 24.2 | ... R32: =SUM(R2:R31) -> 16.2
C33: 1384.62 | D33: 1384.62 | E33: 1153.85 | F33: 1153.85 | G33: 1153.85 | H33: 1384.62 | I33: 1500 | J33: 1076.93 | K33: 1153.85 | L33: 1200 | M33: 1230.77 | N33: 1000 | O33: 1000 | P33: 1250 | Q33: 1153.85 | R33: 1153.85
C34: =C32*C33 -> 18000.06 | D34: =D33*D32 -> 32123.184 | E34: =E33*E32 -> 28846.25 | F34: =F33*F32 -> 5769.25 | G34: =G33*G32 -> 7788.4875 | H34: =H32*H33 -> 29077.02 | I34: =I32*I33 -> 23100 | J34: =J32*J33 -> 26061.706 | K34: =K33*K32 -> 19615.45 | L34: =L33*L32 -> 8400 | M34: =M32*M33 -> 6153.85 | N34: =N32*N33 -> 6500 | O34: =O33*O32 -> 6500 | P34: =P32*P33 -> 13750 | Q34: =Q32*Q33 -> 28846.25 | R34: =R32*R33 -> 18692.37 | S34: =SUM(C32:M32) -> 162.55
C35: 36000 | D35: 36000 | E35: 30000 | F35: 30000 | G35: 30000 | H35: 36000 | J35: 28000 | K35: 30000 | M35: 32000 | P35: 32000 | Q35: 30000 | R35: 30000
S48: 1111111

Sheet Les Charges 
D3: Produit | E3: Quantité | F3: Prix unitaire | G3: Prix | H3: Date d'achat
D4: levure chimique | E4: 100 | F4: 6.5 | G4: =E4*F4 -> 650 | H4: 45383
D5: quissetes | E5: 5 | F5: 30 | G5: =E5*F5 -> 150
D6: cheddar | E6: 0.75 | F6: 2000 | G6: =E6*F6 -> 1500
D7: Cheddar | E7: 3.6 | F7: 1600 | G7: =E7*F7 -> 5760
D8: Fromage spéciale pizza Napoli | E8: 2 | F8: 350 | G8: =E8*F8 -> 700
D9: Khel | E9: 0 | F9: 85 | G9: =E9*F9 -> 0
D10: Fromage Bidon BV | E10: 4 | F10: 720 | G10: =E10*F10 -> 2880
D11: Fromage Bidon Mont D'Or 3,8kg | E11: 3 | F11: 1360 | G11: =E11*F11 -> 4080
D12: quissettes cigares | E12: 10 | F12: 30 | G12: =E12*F12 -> 300
D13: sachet de congelation 3kg | E13: 3 | F13: 50 | G13: =E13*F13 -> 150
D14: cerise confit | E14: 1 | F14: 1900 | G14: =E14*F14 -> 1900
D15: pistache | E15: 0.25 | F15: 4000 | G15: =E15*F15 -> 1000
D16: Thon 2kg | E16: 3 | F16: 1800 | G16: =E16*F16 -> 5400
... D83: plateaux oeuf | E83: 2 | F83: 450 | G83: =E83*F83 -> 900
G84: =E84*F84 -> 0
D86: 9etayef | E86: 5 | F86: 70 | G86: =E86*F86 -> 350
D87: deyoul | E87: 10 | F87: 100 | G87: =E87*F87 -> 1000
D89: Farine SIM 1Kg | E89: 45 | F89: 90 | G89: =E89*F89 -> 4050
D90: chocolat wedjedane Noisette | E90: 8 | F90: 250 | G90: =E90*F90 -> 2000
D91: chocolat wedjedane au lait | E91: 16 | F91: 235 | G91: =E91*F91 -> 3760
D92: chocolat wedjedane Blanc | E92: 5 | F92: 235 | G92: =E92*F92 -> 1175
D94: miel Mordjane 5kg | E94: 3 | F94: 790 | G94: =E94*F94 -> 2370
D95: Maa zehar zahia | E95: 24 | F95: 60 | G95: =E95*F95 -> 1440
D97: 1 | E97: 0.5 | F97: 4100 | G97: =E97*F97 -> 2050
D98: Noix | E98: 2 | F98: 1200 | G98: =E98*F98 -> 2400
D101: colorant rouge et blanc | E101: 2 | F101: 130 | G101: =E101*F101 -> 260
D102: cacao | E102: 0.5 | F102: 1200 | G102: =E102*F102 -> 600
D103: chocolat à tartiner 10kg | E103: 0.5 | F103: 3450 | G103: =E103*F103 -> 1725
D104: Nacré | E104: 1 | F104: 450 | G104: =E104*F104 -> 450
D105: barquettes carée | E105: 2 | F105: 450 | G105: =E105*F105 -> 900
D106: dentelle célophane | E106: 10 | F106: 110 | G106: =E106*F106 -> 1100
D107: rechta | E107: 10 | F107: 120 | G107: =E107*F107 -> 1200
D108: Deyoul | E108: 45 | F108: 120 | G108: =E108*F108 -> 5400 | H108: 45384
D109: rechta | E109: 25 | F109: 120 | G109: =E109*F109 -> 3000
D110: plateaux oeuf | E110: 13 | F110: 450 | G110: =E110*F110 -> 5850
D111: poivre +ppivron | E111: 2 | F111: 200 | G111: =E111*F111 -> 400
D112: tomate fraiche | E112: 1 | F112: 100 | G112: =E112*F112 -> 100
D113: viande hachée | E113: 1.5 | F113: 1500 | G113: =E113*F113 -> 2250
D114: poulet haché + blanc de poulet | E114: 8 | F114: 1000 | G114: =E114*F114 -> 8000
...

Sheet Salaires
K12: Nom | L12: Salaire | M12: Avance | N12: Salaire à payer
K13: Sofiane | L13: 30000 | M13: 30000 | N13: =L13-M13 -> 0 | O13: 3000Da salaires + 5000Da Fetour +30k
K14: Amel | L14: 30000 | M14: 30000 | N14: =L14-M14 -> 0
J15: 1 | K15: Lynda | L15: =Pointage!C34 -> 18000.06 | M15: 18000 | N15: =L15-M15 -> 0.06
I16: 36000 | J16: 2 | K16: Hafida | L16: =Pointage!D34 -> 32123.184 | M16: 32500 | N16: =L16-M16 -> -376.816 | O16: 5000
J17: 3 | K17: Romayssa | L17: =Pointage!R34 -> 18692.37 | M17: 19000 | N17: =L17-M17 -> -307.63
J18: 4 | K18: Yasmine Sidi Abd Allah | L18: =P18+Q18 -> 33846.25 | M18: 34000 | N18: =L18-M18 -> -153.75 | P18: =Pointage!E34 -> 28846.25 | Q18: 5000
J19: 5 | K19: Kenza | L19: =Pointage!F34 -> 5769.25 | M19: 6000 | N19: =L19-M19 -> -230.75
J20: 6 | K20: Yasmine Dely Brahim | L20: =Pointage!G34*1 -> 7788.4875 | M20: 8000 | N20: =L20-M20 -> -211.5125
J21: 7 | K21: Nadjet | L21: =Pointage!I34 -> 23100 | M21: 23500 | N21: =L21-M21 -> -400 | O21: 1000+10000+3000+6500
J22: 8 | K22: Samira | L22: =Pointage!K34 -> 19615.45 | M22: 20000 | N22: =L22-M22 -> -384.55 | O22: 1000
J23: 9 | K23: Fatiha | L23: 26000 | M23: 26000 | N23: =L23-M23 -> 0
J24: 10 | K24: Zohra | L24: 9600 | M24: 10000 | N24: =L24-M24 -> -400 | O24: 5000+
J25: 11 | K25: Sarah | L25: =Pointage!M34 -> 6153.85 | M25: 6500 | N25: =L25-M25 -> -346.15
J26: 12 | K26: Chiraz | L26: =Pointage!Q34 -> 28846.25 | M26: 29000 | N26: =L26-M26 -> -153.75
J27: 13 | K27: Ilhem | L27: =Pointage!P34 -> 13750 | M27: 14000 | N27: =L27-M27 -> -250
J28: 14 | K28: Nesrine 1 | L28: =Pointage!N34*1 -> 6500 | M28: 6500 | N28: =L28-M28 -> 0
J29: 15 | K29: Nesrine 2 | L29: =Pointage!O34 -> 6500 | M29: 6500 | N29: =L29-M29 -> 0
I30: 34000 | J30: 16 | K30: Fouzia | L30: =Pointage!H34 -> 29077.02 | M30: 29500 | N30: =L30-M30 -> -422.98 | O30: 10000
K31: TOTAL | L31: =SUM(L13:L30) -> 345362.17 | M31: =SUM(M13:M30) -> 349000 | N31: =SUM(N13:N30) -> -3637.8285
K32: =L31-M31 -> -3637.8285 | N32: =L32-M32 -> 0

Sheet Feuille 5
E21: Mois de Janvier | F21: Mois de Février | G21: Mois de Mars | H21: Mois d'Avril | K21: Mois d'Avril
D22: Recette | E22: 1756000 | F22: 2274000 | G22: 1984000 | H22: 1910000 | J22: Recette | K22: 1910000
D23: Charges | E23: 920000 | F23: 914000 | G23: 928000 | H23: 744000 | J23: Charges | K23: 744000
D24: Salaires | E24: 349000 | F24: 410000 | G24: 406000 | H24: 344000 | J24: Salaires | K24: 344000
D25: Loyer | E25: 140000 | F25: 140000 | G25: 140000 | H25: 140000 | J25: Loyer | K25: 140000
D26: Profit Net | E26: =E22-E23-E24-E25 -> 347000 | F26: =F22-F23-F24-F25 -> 810000 | G26: =G22-G23-G24-G25 -> 510000 | H26: 680000 | J26: Profit Net | K26: 680000
