Workbook

Sheet RECAP
B1: Date | C1: Recette Octobre 2025 | D1: Recette | E1: Charges | F1: Salaire | G1: Che7i7a | H1: Loyer | I1: Net Profit | J1: Nb de jours | L1: Objectif | M1: Mois Octobre 2025
A2: Samedi | B2: 45962 | C2: 30000 | D2: 117000 | G2: 2000 | J2: 1 | M2: 30000
A3: dimanche | B3: 45963 | C3: 104000 | D3: 45000 | G3: 2000 | J3: 1 | M3: 104000 | N3: Bénéfice Moyen par jour | O3: Moyenne | P3: Moyenne salaire | Q3: pourcentage du salaire vis à vis la recettte
A4: lundi | B4: 45964 | C4: 85000 | D4: 57000 | G4: 2000 | J4: 1 | M4: 85000 | N4: =I33/J33 -> 2648.7065 | O4: =D33/J33 -> 70588.235 | Q4: =P4/O4 -> 0
A5: mardi | B5: 45965 | C5: 55000 | D5: 35000 | G5: 2000 | J5: 1 | M5: 55000
A6: mercredi | B6: 45966 | C6: 38000 | D6: 45000 | G6: 2000 | J6: 1 | M6: 38000 | N6: Moyenne des charges par jour | O6: Objectif
A7: jeudi | B7: 45967 | C7: 40000 | D7: 78000 | G7: 2000 | J7: 1 | M7: 40000 | N7: =E33/J33 -> 38215.955 | O7: 100000
A8: vendredi | B8: 45968 | C8: 55000 | D8: 49000 | G8: 2000 | J8: 1 | M8: 55000
A9: samedi | B9: 45969 | C9: 75000 | D9: 65000 | G9: 2000 | J9: 1 | M9: 75000
A10: dimanche | B10: 45970 | C10: 73000 | D10: 90000 | G10: 2000 | J10: 1 | M10: 73000 | N10: Cash restant | O10: Magasin | P10: Cash réel | Q10: Mes dettes pour le magasin
A11: lundi | B11: 45971 | C11: 76000 | D11: 54000 | G11: 2000 | J11: 1 | M11: 76000 | N11: =D33+N14-E33-G33-'Les Salaires '!E33-O11 -> 496628.76 | O11: =R14+R15+R16+R17+R18+R19+R20+R21 -> 314000 | P11: 414000 | Q11: =N11-P11 -> 82628.76
A12: mardi | B12: 45972 | C12: 76000 | D12: 73000 | G12: 2000 | J12: 1 | M12: 76000
A13: mercredi | B13: 45973 | C13: 48000 | D13: 58000 | G13: 2000 | J13: 1 | M13: 48000 | N13: Fond de Roulement
A14: jeudi | B14: 45974 | C14: 29000 | D14: 145000 | G14: 2000 | J14: 1 | M14: 29000 | N14: 330000
A15: vendredi | B15: 45975 | C15: 33000 | D15: 99000 | G15: 2000 | J15: 1 | M15: 33000 | Q15: La caisse : | R15: 9000
A16: samedi | B16: 45976 | C16: 42000 | D16: 95000 | G16: 2000 | J16: 1 | K16: 1 | M16: 42000 | Q16: CCP: | R16: 150000
A17: dimanche | B17: 45977 | C17: 66000 | D17: 46000 | G17: 2000 | J17: 1 | K17: 1 | M17: 66000 | Q17: Monnie | R17: 40000
A18: lundi | B18: 45978 | C18: 30000 | D18: 39000 | G18: 2000 | J18: 1 | M18: 30000 | Q18: Voiture | R18: 55000
A19: mardi | B19: 45979 | G19: 2000 | M19: 49000 | N19: Différence mois de Septembre
A20: mercredi | B20: 45980 | M20: 54000 | N20: =D33-C33 -> 205000
A21: jeudi | B21: 45981 | M21: 62000 | N21: Différence objectif | Q21: Cash PorteFeuille : 60000Da | R21: 60000
A22: vendredi | B22: 45982 | C22: 40000 | D22: 10000 | M22: 40000 | N22: =L36-E36 -> 0
A23: samedi | B23: 45983 | M23: 67000 | N23: Différence du Totale
A24: dimanche | B24: 45984 | M24: 81000 | N24: =D33-C33 -> 205000
A25: lundi | B25: 45985 | M25: 103000 | N25: Les vendredis
A26: mardi | B26: 45986 | M26: 50000 | N26: =D9+D16+D23+D30 -> 160000
A27: mercredi | B27: 45987 | M27: 100000
A28: jeudi | B28: 45988 | M28: 45000 | N28: Cash réel
A29: vendredi | B29: 45989 | M29: 52000 | N29: 51000
A30: samedi | B30: 45990 | M30: 75000 | N30: rest à payer
A31: dimanche | B31: 45991 | M31: 101000
A32: lundi | B32: 45992 | M32: 64000
C33: =SUM(C2:C32) -> 995000 | D33: =SUM(D2:D32) -> 1200000 | E33: ='Les Charges '!J386 -> 649671.24 | F33: ='Les Salaires '!D33 -> 279300.75 | G33: =SUM(G2:G32) -> 36000 | H33: 190000 | I33: =D33-E33-F33-G33-H33 -> 45028.01 | J33: =SUM(J2:J32) -> 17 | M33: =SUM(M2:M32) -> 1898000
G34: Loyer Magasin | H34: 55000
G35: Loyer Locale | H35: 50000 | N35: =N11-N29-N34 -> 445628.76
D36: 200000 | G36: Sofiane Maison | H36: 45000 | P36: Papa | Q36: 40000
G37: Dette Papa | H37: 40000
D38: -

Sheet Les Charges 
G3: Produit | H3: Quantité | I3: Prix unitaire | J3: Prix
G4: Margarine Goldmine 10kg | H4: 80 | I4: 280 | J4: =H4*I4 -> 22400
G5: Semoule Moula Moyenne 10kg | H5: 4 | I5: 520 | J5: =H5*I5 -> 2080
G6: Semoule Moula Grosse 10kg | H6: 5 | I6: 850 | J6: =H6*I6 -> 4250
G7: Paprika | H7: 10 | I7: 850 | J7: =H7*I7 -> 8500
G8: Semoule Fine Moula 10kg | H8: 1 | I8: 550 | J8: =H8*I8 -> 550
G9: Semoule Fine 25kg | H9: 15 | I9: 1000 | J9: =H9*I9 -> 15000
G10: Transport Semoule | H10: 1 | I10: 2000 | J10: =H10*I10 -> 2000
G11: Sel | H11: 29 | I11: 30 | J11: =H11*I11 -> 870
G12: Levure Boulangère 500g | H12: 11 | I12: 390 | J12: =H12*I12 -> 4290
G13: Chocolat Wedjedan Noir | H13: 8 | I13: 255 | J13: =H13*I13 -> 2040
G14: Chocolat wedjedane au lait | H14: 21 | I14: 245 | J14: =H14*I14 -> 5145
G15: Chocolat wedjedane Blanc | I15: 245 | J15: =H15*I15 -> 0
G16: Chocolat wedjedane Noisette | H16: 34 | I16: 200 | J16: =H16*I16 -> 6800
G17: Sucre Cristalisé | H17: 40 | I17: 99 | J17: =H17*I17 -> 3960
G18: Huile Elio 5 litres | H18: 55 | I18: 600 | J18: =H18*I18 -> 33000 | K18: octobre +01er novembre
G19: Lait en poudre | H19: 12 | I19: 450 | J19: =H19*I19 -> 5400
G20: Lait en poudre | H20: 6 | I20: 420 | J20: =H20*I20 -> 2520
G21: Semen | H21: 21 | I21: 820 | J21: =H21*I21 -> 17220
G22: Khel | H22: 11 | I22: 30 | J22: =H22*I22 -> 330
G23: Vanille Baraka 4kg | H23: 4 | I23: 800 | J23: =H23*I23 -> 3200
G24: Margarine dE Feuilletage 500g | H24: 10 | I24: 150 | J24: =H24*I24 -> 1500
G25: sucre de datte | H25: 1 | I25: 400 | J25: =H25*I25 -> 400
G26: Pate de Fruits Fraise | H26: 1 | I26: 1900 | J26: =H26*I26 -> 1900
G27: Levure chimique | H27: 500 | I27: 6.8 | J27: =H27*I27 -> 3400
G28: Levure chimique | H28: 100 | I28: 6.3 | J28: =H28*I28 -> 630
G29: Noix | H29: 6 | I29: 1250 | J29: =H29*I29 -> 7500
G30: Sucre Glace | H30: 40 | I30: 125 | J30: =H30*I30 -> 5000
G31: Harrissa | H31: 24 | I31: 270 | J31: =H31*I31 -> 6480
G32: Harrissa | H32: 24 | I32: 265 | J32: =H32*I32 -> 6360 | K32: 45956
G33: Tomate conserve | H33: 24 | I33: 315 | J33: =H33*I33 -> 7560
G34: Tomate conserve | H34: 22 | I34: 320 | J34: =H34*I34 -> 7040
G35: Farine Sim 1kg | H35: 18 | I35: 73 | J35: =H35*I35 -> 1314
G36: Fromage Bidon 3,8kg | H36: 6 | I36: 1350 | J36: =H36*I36 -> 8100
G37: Eau de Fleur d'oranger | H37: 24 | I37: 65 | J37: =H37*I37 -> 1560
G38: Eau de Fleur d'oranger | H38: 36 | I38: 60 | J38: =H38*I38 -> 2160
G39: Amande marron | H39: 1 | I39: 2250 | J39: =H39*I39 -> 2250
G40: amande éffilé | H40: 0.5 | I40: 2500 | J40: =H40*I40 -> 1250
G41: plateaux oeufs | H41: 5 | I41: 560 | J41: =H41*I41 -> 2800
G42: Boite Num 8 | H42: 100 | I42: 9.5 | J42: =H42*I42 -> 950
...

Sheet Pointage 
B1: Date | C1: Akila | D1: Chiraz | E1: Samira | F1: Fatiha | G1: Samira Sidi Abdullah | H1: Ahlem | I1: Sarah | J1: Yasmine | K1: Zahia | L1: Zohra | M1: Houda | N1: Fouzia | O1: Machair
A2: Samedi | B2: 45962 | C2: 1.25 | D2: 1.25 | E2: 1 | F2: 1 | G2: 1 | H2: 0 | I2: 1 | J2: 1 | K2: 0 | L2: 1 | M2: 0 | N2: 0.95 | O2: 1
A3: dimanche | B3: 45963 | C3: 1 | D3: 1 | E3: 1 | F3: 1 | G3: 0 | H3: 1 | I3: 1 | J3: 1 | K3: 1 | L3: 0 | M3: 0 | N3: 1 | O3: 1
A4: lundi | B4: 45964 | C4: 0 | D4: 1 | E4: 1 | F4: 1 | G4: 0 | H4: 1 | I4: 1 | J4: 1 | K4: 0 | L4: 1 | M4: 1 | N4: 1.03 | O4: 1
A5: mardi | B5: 45965 | C5: 1.21 | D5: 1 | E5: 1 | F5: 1 | G5: 0 | H5: 1 | I5: 1 | J5: 0 | K5: 1 | L5: 0 | M5: 0 | N5: 0.94 | O5: 1
A6: mercredi | B6: 45966 | C6: 1.19 | D6: 1.03 | E6: 1 | F6: 1.3 | G6: 0 | H6: 1 | I6: 1 | J6: 1 | K6: 0 | L6: 1 | M6: 0 | N6: 0 | O6: 1
A7: jeudi | B7: 45967 | C7: 1.2 | D7: 1 | E7: 1 | F7: 1.2 | G7: 0 | H7: 1 | I7: 0 | J7: 1 | K7: 0 | L7: 1 | M7: 0 | N7: 0.75 | O7: 1
A8: vendredi | B8: 45968 | C8: 2.4 | D8: 2 | E8: 2 | F8: 2.2 | G8: 2 | H8: 1 | I8: 0 | J8: 2 | K8: 2 | L8: 0 | M8: 0 | N8: 1 | O8: 2
A9: samedi | B9: 45969 | C9: 1.5 | D9: 1.17 | E9: 1 | F9: 1 | G9: 1 | H9: 0 | I9: 1 | J9: 1 | K9: 1 | L9: 1 | M9: 0 | N9: 1 | O9: 1
A10: dimanche | B10: 45970 | C10: 2.2 | D10: 1.1 | E10: 1 | F10: 1.2 | G10: 0 | H10: 1.2 | I10: 1 | J10: 1 | K10: 0 | L10: 0 | M10: 0 | N10: 1.1 | O10: 1.1
A11: lundi | B11: 45971 | C11: 1.25 | D11: 1.12 | E11: 1 | F11: 1 | G11: 0 | H11: 1.2 | I11: 1 | J11: 1 | K11: 0 | L11: 1 | M11: 1.2 | N11: 1.06 | O11: 1
A12: mardi | B12: 45972 | C12: 1.17 | D12: 1 | E12: 1 | F12: 1 | G12: 1 | H12: 1 | I12: 0 | J12: 0 | K12: 1 | L12: 0 | M12: 0 | N12: 0.82 | O12: 1
A13: mercredi | B13: 45973 | C13: 1.25 | D13: 1.11 | E13: 1 | F13: 1 | G13: 1 | H13: 1 | I13: 0.5 | J13: 1 | K13: 0 | L13: 1 | M13: 0 | N13: 1.11 | O13: 1
... A17: dimanche | B17: 45977 | C17: 1.19 | D17: 1.06 | E17: 1 | F17: 1 | G17: 0 | H17: 1.2 | I17: 1 | J17: 0 | K17: 0 | L17: 1 | M17: 0 | N17: 1.1 | O17: 1.1
A18: lundi | B18: 45978 | C18: 1.08 | D18: 1 | E18: 1 | F18: 1.1 | G18: 0 | H18: 1 | I18: 1 | J18: 0 | K18: 0 | L18: 0 | M18: 1.1 | N18: 1
A19: mardi | B19: 45979
A20: mercredi | B20: 45980
A21: jeudi | B21: 45981
A22: vendredi | B22: 45982
A23: samedi | B23: 45983
A24: dimanche | B24: 45984
A25: lundi | B25: 45985
A26: mardi | B26: 45986
A27: mercredi | B27: 45987
A28: jeudi | B28: 45988
A29: vendredi | B29: 45989
A30: samedi | B30: 45990
A31: dimanche | B31: 45991
A32: Heure Suplémentaires | L32: 3.34 | N32: 2 | Q32: Zohra on lui a donner 4000Da du Mois de Septembre + 2 OFF de Fouzia pour Mois d'octobre j'ai oublié de les mentienner
C33: =SUM(C2:C32) -> 22.365 | D33: =SUM(D2:D32) -> 20 | E33: =SUM(E2:E32) -> 19 | F33: =SUM(F2:F32) -> 20.4 | G33: =SUM(G2:G32) -> 9 | H33: =SUM(H2:H32) -> 14.8 | I33: =SUM(I2:I32) -> 14 | J33: =SUM(J2:J32) -> 11 | ... P33: =SUM(P2:P32) -> 0
C34: 1350 | D34: 1170 | E34: 1000 | F34: 1000 | G34: 1100 | H34: 1000 | I34: 1000 | J34: 1000 | K34: 1000 | L34: 1200 | M34: 1200 | N34: 1400 | O34: 1000
C35: =C33*C34 -> 30192.75 | D35: =D33*D34 -> 23400 | E35: =E33*E34 -> 19000 | F35: =F33*F34 -> 20400 | G35: =G33*G34 -> 9900 | H35: =H33*H34 -> 14800 | I35: =I33*I34 -> 14000 | J35: =J33*J34 -> 11000 | ... P35: =P33*P34 -> 0
C36: 40000 | D36: 35000 | E36: 30000 | F36: 30000 | G36: 33000 | H36: 30000 | I36: 30000 | J36: 30000 | K36: 30000 | L36: / | M36: 30000 | N36: 42000 | O36: 30000

Sheet Pointage par heures 
B1: Date | C1: Akila | E1: Chiraz | G1: Fouzia | I1: Fatiha | K1: Samira Sidi Abdullah | L1: Ahlem | M1: Sarah | N1: Yasmine | O1: Zahia | P1: Zohra | Q1: Houda | R1: Fouzia | S1: Machair
A2: Samedi | B2: 45962 | C2: 0.34722222 | D2: 0.76388889 | E2: 0.34722222 | F2: 0.76388889 | G2: 0.38194444 | H2: 0.69791667
A3: dimanche | B3: 45963 | C3: 0 | D3: 0 | E3: 0.375 | F3: 0.70833333 | G3: 0.375 | H3: 0.70833333 | I3: 0 | J3: 0
A4: lundi | B4: 45964 | C4: 0 | D4: 0 | E4: 0.36458333 | F4: 0.69791667 | G4: 0.35416667 | H4: 0.69791667
A5: mardi | B5: 45965 | C5: 0.30555556 | D5: 0.70833333 | E5: 0 | F5: 0 | G5: 0.39583333 | H5: 0.70833333
A6: mercredi | B6: 45966 | C6: 0.30208333 | D6: 0.69791667 | E6: 0.35416667 | F6: 0.69722222 | G6: 0 | H6: 0 | I6: 0.31944444 | J6: 0.73611111
A7: jeudi | B7: 45967 | C7: 0.30208333 | D7: 0.70138889 | E7: 0.36805556 | F7: 0.70486111 | G7: 0.36111111 | H7: 0.63888889 | I7: 0.36111111 | J7: 0.73958333
A8: vendredi | B8: 45968 | C8: 0.30555556 | D8: 0.69444444 | E8: 0.35763889 | F8: 0.69444444 | G8: 0 | H8: 0 | I8: 0.35416667 | J8: 0.72916667
A9: samedi | B9: 45969 | C9: 0.30555556 | D9: 0.76388889 | E9: 0.36458333 | F9: 0.75347222 | G9: 0.40277778 | H9: 0.72916667
A10: dimanche | B10: 45970 | C10: 0.31944444 | D10: 0.70138889 | E10: 0.34375 | F10: 0.70138889 | G10: 0.34375 | H10: 0.67708333 | I10: 0.33333333 | J10: 0.70833333 | S10: 0.41666667 | T10: 0.77777778
A11: lundi | B11: 45971 | C11: 0.3125 | D11: 0.72916667 | E11: 0.37152778 | F11: 0.74652778 | G11: 0.36111111 | H11: 0.70833333
A12: mardi | B12: 45972 | C12: 0.3125 | D12: 0.70138889 | E12: 0 | F12: 0 | G12: 0.34027778 | H12: 0.61111111
A13: mercredi | B13: 45973 | C13: 0.3125 | D13: 0.72916667 | E13: 0.36111111 | F13: 0.72916667 | G13: 0.36111111 | H13: 1730
A14: jeudi | B14: 45974 | C14: 0.31944444 | D14: 0.76388889 | E14: 0.36458333 | F14: 0.75 | G14: 0.34027778 | H14: 0.73263889
A15: vendredi | B15: 45975 | C15: 0.34027778 | D15: 0.70138889 | E15: 0.35763889 | F15: 0.69861111 | G15: 0 | H15: 0
A16: samedi | B16: 45976 | C16: 0.31944444 | D16: 0.69444444 | E16: 0.35069444 | F16: 0.69444444 | G16: 0.34027778 | H16: 0.69444444
A17: dimanche | B17: 45977 | C17: 0.33333333 | D17: 0.72916667 | E17: 0.36458333 | F17: 0.73263889 | G17: 0.34722222 | H17: 0.71875
A18: lundi | B18: 45978 | C18: 0.33333333 | D18: 0.69444444 | E18: 0 | F18: 0 | G18: 0.34027778 | H18: 0.69444444
A19: mardi | B19: 45979
A20: mercredi | B20: 45980
A21: jeudi | B21: 45981
A22: vendredi | B22: 45982
A23: samedi | B23: 45983
A24: dimanche | B24: 45984
A25: lundi | B25: 45985
A26: mardi | B26: 45986
A27: mercredi | B27: 45987
A28: jeudi | B28: 45988
A29: vendredi | B29: 45989
A30: samedi | B30: 45990
A31: dimanche | B31: 45991
A32: Heure Suplémentaires

Sheet Les Salaires 
C16: Nom | D16: Salaire | E16: Avance | F16: Salaire à payer
C17: Sofiane | D17: 30000 | F17: =D17-E17 -> 30000
C18: Amel | D18: 30000 | F18: =D18-E18 -> 30000
B19: 1 | C19: Akila | D19: ='Pointage '!C35 -> 30192.75 | F19: =D19-E19 -> 30192.75
B20: 2 | C20: Chiraz | D20: ='Pointage '!D35 -> 23400 | F20: =D20-E20 -> 23400
B21: 3 | C21: Samira | D21: ='Pointage '!E35 -> 19000 | F21: =D21-E21 -> 19000
B22: 4 | C22: Fatiha | D22: ='Pointage '!F35 -> 20400 | E22: 21700 | F22: =D22-E22 -> -1300 | H22: 10000Da Tv + 4000Da elle les a pris Mois d'Octobre +4000Da+1500Da achats du magasin+200Da mehadjeb+2000
B23: 5 | C23: Samira Sidi AbduAllah | D23: ='Pointage '!G35 -> 9900 | E23: 8000 | F23: =D23-E23 -> 1900 | H23: 5000Da+3000
B24: 6 | C24: Ahlem | D24: ='Pointage '!H35 -> 14800 | F24: =D24-E24 -> 14800
B25: 7 | C25: Sarah | D25: ='Pointage '!I35 -> 14000 | F25: =D25-E25 -> 14000
B26: 8 | C26: Yasmine | D26: ='Pointage '!J35+G26 -> 16000 | F26: =D26-E26 -> 16000 | G26: 5000
B27: 9 | C27: Zahia | D27: ='Pointage '!K35 -> 10400 | F27: =D27-E27 -> 10400
B28: 10 | C28: Zohra | D28: ='Pointage '!L35 -> 13608 | E28: 4000 | F28: =D28-E28 -> 9608 | H28: 4000Da complément salaire de Septembre
B29: 11 | C29: Houda | D29: ='Pointage '!M35 -> 3960 | F29: =D29-E29 -> 3960
B30: 12 | C30: Fouzia | D30: ='Pointage '!N35 -> 25340 | F30: =D30-E30 -> 25340
B31: 13 | C31: Machair | D31: ='Pointage '!O35 -> 18300 | F31: =D31-E31 -> 18300
B32: 14 | D32: ='Pointage '!P35 -> 0 | F32: =D32-E32 -> 0
C33: TOTAL | D33: =SUM(D17:D32) -> 279300.75 | E33: =SUM(E17:E32) -> 33700 | F33: =D33-E33 -> 245600.75
F34: =D34-E34 -> 0

Sheet Feuille 5
