Workbook

Sheet RECAP
B1: Date | C1: Recette Octobre 2024 | D1: Recette | E1: Charges | F1: Salaire | G1: Che7i7a | H1: Loyer | I1: Net Profit | J1: Nb de jours | L1: Objectif | M1: Mois de Septembre 2024
A2: vendredi | B2: 45597 | C2: 85000 | D2: 139000 | F2: =Pointage!AF2 -> 11760 | G2: 2000 | J2: 1 | M2: 85000
A3: samedi | B3: 45598 | C3: 35000 | D3: 48000 | F3: =Pointage!AF3 -> 11196 | G3: 2000 | J3: 1 | M3: 35000 | N3: Bénéfice Moyen par jour | O3: Moyenne | P3: Moyenne salaire | Q3: pourcentage du salaire vis à vis la recettte
A4: dimanche | B4: 45599 | C4: 60000 | D4: 60000 | F4: =Pointage!AF4 -> 11284 | G4: 2000 | J4: 1 | M4: 60000 | N4: =I33/J33 -> 5227.5522 | O4: =D33/J33 -> 57739.13 | Q4: =P4/O4 -> 0
A5: lundi | B5: 45600 | C5: 56000 | D5: 50000 | F5: =Pointage!AF5 -> 12946 | G5: 2000 | J5: 1 | M5: 56000
A6: mardi | B6: 45601 | C6: 85000 | D6: 49000 | F6: =Pointage!AF6 -> 13718.4 | G6: 2000 | J6: 1 | M6: 85000 | N6: Moyenne des charges par jour | O6: Objectif
A7: mercredi | B7: 45602 | C7: 26000 | D7: 48000 | F7: =Pointage!AF7 -> 12945.2 | G7: 2000 | J7: 1 | M7: 26000 | N7: =E33/J33 -> 28048.883 | O7: 100000
A8: jeudi | B8: 45603 | C8: 32000 | D8: 72000 | F8: =Pointage!AF8 -> 12772 | G8: 2000 | J8: 1 | M8: 32000 | N8: ² | S8: "
A9: vendredi | B9: 45604 | C9: 26000 | D9: 57000 | F9: =Pointage!AF9 -> 9448 | G9: 2000 | J9: 1 | M9: 26000
A10: samedi | B10: 45605 | C10: 28000 | D10: 62000 | F10: =Pointage!AF10 -> 11196 | G10: 2000 | J10: 1 | M10: 28000 | N10: Cash restant | O10: Magasin | P10: Cash réel | Q10: Mes dettes pour le magasin
A11: dimanche | B11: 45606 | C11: 52000 | D11: 31000 | F11: =Pointage!AF11 -> 13884 | G11: 2000 | J11: 1 | M11: 52000 | N11: =N14+D33-E33-Salaires!G24-R19-O11-G33 -> 572375.7 | O11: 25000 | P11: 300000 | Q11: =N11-P11 -> 272375.7
A12: lundi | B12: 45607 | C12: 38000 | D12: 62000 | F12: =Pointage!AF12 -> 14996 | G12: 2000 | J12: 1 | M12: 38000
A13: mardi | B13: 45608 | C13: 40000 | D13: 35000 | F13: =Pointage!AF13 -> 13496 | G13: 2000 | J13: 1 | M13: 40000 | N13: Fond de Roulement
A14: mercredi | B14: 45609 | C14: 24000 | D14: 71000 | F14: =Pointage!AF14 -> 13606 | G14: 2000 | J14: 1 | M14: 24000 | N14: 330000
A15: jeudi | B15: 45610 | C15: 164000 | D15: 80000 | F15: =Pointage!AF15 -> 11084 | G15: 2000 | J15: 1 | M15: 164000
A16: vendredi | B16: 45611 | C16: 21000 | D16: 82000 | F16: =Pointage!AF16 -> 9528 | G16: 2000 | J16: 1 | M16: 21000 | N16: Bénéfice Sept + loyer | Q16: Cash réel :
A17: samedi | B17: 45612 | C17: 107000 | D17: 11000 | F17: =Pointage!AF17 -> 0 | G17: 2000 | J17: 0 | M17: 107000 | N17: 0 | Q17: Sofiane : 4300Da
A18: dimanche | B18: 45613 | C18: 65000 | D18: 0 | F18: =Pointage!AF18 -> 0 | G18: 0 | J18: 0 | M18: 65000 | R18: 45582 | S18: Le reste du paiement CNASet pénalité pour mois de Décembre
A19: lundi | B19: 45614 | C19: 60000 | D19: 0 | F19: =Pointage!AF19 -> 0 | G19: 0 | J19: 0 | M19: 60000 | N19: Différence mois d'Aout | Q19: la vraie caisse: 17000DA | S19: 18000
A20: mardi | B20: 45615 | C20: 23000 | D20: 0 | F20: =Pointage!AF20 -> 0 | G20: 0 | J20: 0 | M20: 23000 | N20: =D33-C33 -> -292000 | Q20: Porte Monnie Magasin: 21000
A21: mercredi | B21: 45616 | C21: 28000 | D21: 0 | F21: =Pointage!AF21 -> 4536 | G21: 0 | J21: 0 | M21: 28000 | N21: Différence objectif | P21: réparation Tabouna | Q21: 1 | R21: 8800 | S21: =Q21*R21 -> 8800
A22: jeudi | B22: 45617 | C22: 40000 | D22: 0 | F22: =Pointage!AF22 -> 3424 | G22: 0 | J22: 0 | M22: 40000 | N22: =L36-E36 -> 0 | P22: Torchons | Q22: 4 | R22: 400 | S22: 600
A23: vendredi | B23: 45618 | C23: 37000 | D23: 0 | F23: =Pointage!AF23 -> 5548 | G23: 0 | J23: 0 | M23: 37000 | N23: Différence du Totale | P23: poelle | Q23: 1 | R23: 2800 | S23: =Q23*R23 -> 2800
A24: samedi | B24: 45619 | C24: 47000 | D24: 45000 | F24: =Pointage!AF24 -> 13896 | G24: 2000 | J24: 1 | M24: 47000 | N24: =D33-C33 -> -292000 | R24: Achoire | S24: 1 | T24: 1800 | U24: =S24*T24 -> 1800
A25: dimanche | B25: 45620 | C25: 43000 | D25: 55000 | F25: =Pointage!AF25 -> 11746 | G25: 2000 | J25: 1 | M25: 43000 | N25: Les vendredis | P25: Cash chez Sofiane
A26: lundi | B26: 45621 | C26: 104000 | D26: 45000 | F26: =Pointage!AF26 -> 13134 | G26: 2000 | J26: 1 | M26: 104000 | N26: =D9+D16+D23+D30 -> 179000 | R26: Les étagères pour locale | S26: 1 | T26: 21000 | U26: =S26*T26 -> 21000
A27: mardi | B27: 45622 | C27: 59000 | D27: 40000 | F27: =Pointage!AF27 -> 12852 | G27: 2000 | J27: 1 | M27: 59000
A28: mercredi | B28: 45623 | C28: 53000 | D28: 36000 | F28: =Pointage!AF28 -> 14440 | G28: 2000 | J28: 1 | M28: 53000 | N28: Cash réel
A29: jeudi | B29: 45624 | C29: 38000 | D29: 69000 | F29: =Pointage!AF29 -> 12684 | G29: 2000 | J29: 1 | M29: 38000 | N29: 51000
A30: vendredi | B30: 45625 | C30: 43000 | D30: 40000 | F30: =Pointage!AF30 -> 6748 | G30: 2000 | J30: 1 | M30: 43000 | N30: rest à payer
A31: samedi | B31: 45626 | C31: 49000 | D31: 41000 | F31: =Pointage!AF31 -> 8328 | G31: 2000 | J31: 1 | M31: 49000
C32: 52000 | M32: 52000 | Q32: =SUM(Q26:Q31) -> 0
C33: =SUM(C2:C32) -> 1620000 | D33: =SUM(D2:D32) -> 1328000 | E33: ='Les charges '!F415 -> 645124.3 | F33: =Salaires!F24 -> 364642 | G33: =SUM(G2:G32) -> 48000 | H33: 150000 | I33: =D33-E33-F33-G33-H33 -> 120233.7 | J33: =SUM(J2:J32) -> 23 | M33: =SUM(M2:M32) -> 1620000
N35: =N11-N29-N34 -> 521375.7
D38: -

Sheet Pointage
A1: Colonne 1 | B1: Date | C1: Nadjet | D1: N/J | E1: Yasmine | F1: Column 18 | G1: Saida | H1: Column 20 | I1: Ahlem | J1: Column 21 | K1: Nour ElHouda | L1: Column 22 | M1: Amina | N1: Column 23 | O1: Selma | P1: Column 24 | Q1: Zohra | R1: Column 25 | S1: Nora | T1: Column 26 | U1: Ikram | V1: Column 27 | W1: Rayan | X1: Column 28 | Y1: Karima | Z1: Column 29 | AA1: Sihem | AB1: Column 30 | AC1: Fatiha | AD1: Column 31 | AE1: Remarque | AF1: Salaire/Jour
A2: Dimanche | B2: 45597 | C2: 1 | D2: =C2*1500 -> 1500 | E2: 1 | F2: =E2*1112 -> 1112 | G2: 0 | H2: =G2*1112 -> 0 | I2: 0 | J2: =I2*1112 -> 0 | K2: 0 | L2: =K2*1112 -> 0 | M2: 2 | N2: =M2*1112 -> 2224 | O2: 0 | P2: =O2*1112 -> 0 | Q2: 1 | R2: =Q2*1200 -> 1200 | S2: 1 | T2: =S2*1112 -> 1112 | U2: 1 | V2: =U2*1112 -> 1112 | W2: 2 | X2: =W2*1200 -> 2400 | Y2: 0 | Z2: =Y2*1112 -> 0 | AA2: 0 | AB2: =AA2*1100 -> 0 | AC2: 1 | AD2: =AC2*1100 -> 1100 | AF2: =SUM(AD2,AB2,Z2,X2,V2,T2,R2,P2,N2,L2,J2,H2,F2,D2) -> 11760
A3: Lundi | B3: 45598 | C3: 0 | D3: =C3*1500 -> 0 | E3: 1 | F3: =E3*1112 -> 1112 | G3: 1 | H3: =G3*1112 -> 1112 | I3: 1 | J3: =I3*1112 -> 1112 | K3: 0 | L3: =K3*1112 -> 0 | M3: 1 | N3: =M3*1112 -> 1112 | O3: 1 | P3: =O3*1112 -> 1112 | Q3: 1 | R3: =Q3*1200 -> 1200 | S3: 1 | T3: =S3*1112 -> 1112 | U3: 1 | V3: =U3*1112 -> 1112 | W3: 0 | X3: =W3*1200 -> 0 | Y3: 1 | Z3: =Y3*1112 -> 1112 | AA3: 0 | AB3: =AA3*1100 -> 0 | AC3: 1 | AD3: =AC3*1100 -> 1100 | AF3: =SUM(AD3,AB3,Z3,X3,V3,T3,R3,P3,N3,L3,J3,H3,F3,D3) -> 11196
A4: Mardi | B4: 45599 | C4: 0 | D4: =C4*1500 -> 0 | E4: 1 | F4: =E4*1112 -> 1112 | G4: 1 | H4: =G4*1112 -> 1112 | I4: 1 | J4: =I4*1112 -> 1112 | K4: 0 | L4: =K4*1112 -> 0 | M4: 0 | N4: =M4*1112 -> 0 | O4: 1 | P4: =O4*1112 -> 1112 | Q4: 1 | R4: =Q4*1200 -> 1200 | S4: 1 | T4: =S4*1112 -> 1112 | U4: 1 | V4: =U4*1112 -> 1112 | W4: 1 | X4: =W4*1200 -> 1200 | Y4: 1 | Z4: =Y4*1112 -> 1112 | AA4: 1 | AB4: =AA4*1100 -> 1100 | AC4: 0 | AD4: =AC4*1100 -> 0 | AF4: =SUM(AD4,AB4,Z4,X4,V4,T4,R4,P4,N4,L4,J4,H4,F4,D4) -> 11284
A5: Mercredi | B5: 45600 | C5: 0 | D5: =C5*1500 -> 0 | E5: 1 | F5: =E5*1112 -> 1112 | G5: 1 | H5: =G5*1112 -> 1112 | I5: 1 | J5: =I5*1112 -> 1112 | K5: 0 | L5: =K5*1112 -> 0 | M5: 1 | N5: =M5*1112 -> 1112 | O5: 1 | P5: =O5*1112 -> 1112 | Q5: 1 | R5: =Q5*1200 -> 1200 | S5: 1 | T5: =S5*1112 -> 1112 | U5: 1 | V5: =U5*1112 -> 1112 | W5: 1 | X5: =W5*1200 -> 1200 | Y5: 1 | Z5: =Y5*1112 -> 1112 | AA5: 0.5 | AB5: =AA5*1100 -> 550 | AC5: 1 | AD5: =AC5*1100 -> 1100 | AF5: =SUM(AD5,AB5,Z5,X5,V5,T5,R5,P5,N5,L5,J5,H5,F5,D5) -> 12946
A6: Jeudi | B6: 45601 | C6: 0 | D6: =C6*1500 -> 0 | E6: 0 | F6: =E6*1112 -> 0 | G6: 1 | H6: =G6*1112 -> 1112 | I6: 1 | J6: =I6*1112 -> 1112 | K6: 1.2 | L6: =K6*1112 -> 1334.4 | M6: 1 | N6: =M6*1112 -> 1112 | O6: 1 | P6: =O6*1112 -> 1112 | Q6: 1 | R6: =Q6*1200 -> 1200 | S6: 1 | T6: =S6*1112 -> 1112 | U6: 1 | V6: =U6*1112 -> 1112 | W6: 1 | X6: =W6*1200 -> 1200 | Y6: 1 | Z6: =Y6*1112 -> 1112 | AA6: 1 | AB6: =AA6*1100 -> 1100 | AC6: 1 | AD6: =AC6*1100 -> 1100 | AF6: =SUM(AD6,AB6,Z6,X6,V6,T6,R6,P6,N6,L6,J6,H6,F6,D6) -> 13718.4
A7: Vendredi | B7: 45602 | C7: 1.1 | D7: =C7*1500 -> 1650 | E7: 1.1 | F7: =E7*1112 -> 1223.2 | G7: 1 | H7: =G7*1112 -> 1112 | I7: 1 | J7: =I7*1112 -> 1112 | K7: 0 | L7: =K7*1112 -> 0 | M7: 1 | N7: =M7*1112 -> 1112 | O7: 1 | P7: =O7*1112 -> 1112 | Q7: 1 | R7: =Q7*1200 -> 1200 | S7: 1 | T7: =S7*1112 -> 1112 | U7: 0 | V7: =U7*1112 -> 0 | W7: 0 | X7: =W7*1200 -> 0 | Y7: 1 | Z7: =Y7*1112 -> 1112 | AA7: 1 | AB7: =AA7*1100 -> 1100 | AC7: 1 | AD7: =AC7*1100 -> 1100 | AF7: =SUM(AD7,AB7,Z7,X7,V7,T7,R7,P7,N7,L7,J7,H7,F7,D7) -> 12945.2
A8: Samedi | B8: 45603 | C8: 1 | D8: =C8*1500 -> 1500 | E8: 1 | F8: =E8*1112 -> 1112 | G8: 1 | H8: =G8*1112 -> 1112 | I8: 1 | J8: =I8*1112 -> 1112 | K8: 0 | L8: =K8*1112 -> 0 | M8: 0 | N8: =M8*1112 -> 0 | O8: 0 | P8: =O8*1112 -> 0 | Q8: 1 | R8: =Q8*1200 -> 1200 | S8: 1 | T8: =S8*1112 -> 1112 | U8: 1 | V8: =U8*1112 -> 1112 | W8: 1 | X8: =W8*1200 -> 1200 | Y8: 1 | Z8: =Y8*1112 -> 1112 | AA8: 1 | AB8: =AA8*1100 -> 1100 | AC8: 1 | AD8: =AC8*1100 -> 1100 | AF8: =SUM(AD8,AB8,Z8,X8,V8,T8,R8,P8,N8,L8,J8,H8,F8,D8) -> 12772
A9: Dimanche | B9: 45604 | C9: 1 | D9: =C9*1500 -> 1500 | E9: 1 | F9: =E9*1112 -> 1112 | G9: 0 | H9: =G9*1112 -> 0 | I9: 0 | J9: =I9*1112 -> 0 | K9: 0 | L9: =K9*1112 -> 0 | M9: 1 | N9: =M9*1112 -> 1112 | O9: 0 | P9: =O9*1112 -> 0 | Q9: 1 | R9: =Q9*1200 -> 1200 | S9: 1 | T9: =S9*1112 -> 1112 | U9: 1 | V9: =U9*1112 -> 1112 | W9: 1 | X9: =W9*1200 -> 1200 | Y9: 0 | Z9: =Y9*1112 -> 0 | AA9: 0 | AB9: =AA9*1100 -> 0 | AC9: 1 | AD9: =AC9*1100 -> 1100 | AF9: =SUM(AD9,AB9,Z9,X9,V9,T9,R9,P9,N9,L9,J9,H9,F9,D9) -> 9448
A10: Lundi | B10: 45605 | C10: 0 | D10: =C10*1500 -> 0 | E10: 1 | F10: =E10*1112 -> 1112 | G10: 1 | H10: =G10*1112 -> 1112 | I10: 1 | J10: =I10*1112 -> 1112 | K10: 0 | L10: =K10*1112 -> 0 | M10: 1 | N10: =M10*1112 -> 1112 | O10: 1 | P10: =O10*1112 -> 1112 | Q10: 1 | R10: =Q10*1200 -> 1200 | S10: 1 | T10: =S10*1112 -> 1112 | U10: 1 | V10: =U10*1112 -> 1112 | W10: 0 | X10: =W10*1200 -> 0 | Y10: 1 | Z10: =Y10*1112 -> 1112 | AA10: 0 | AB10: =AA10*1100 -> 0 | AC10: 1 | AD10: =AC10*1100 -> 1100 | AF10: =SUM(AD10,AB10,Z10,X10,V10,T10,R10,P10,N10,L10,J10,H10,F10,D10) -> 11196
A11: Mardi | B11: 45606 | C11: 1 | D11: =C11*1500 -> 1500 | E11: 1 | F11: =E11*1112 -> 1112 | G11: 1 | H11: =G11*1112 -> 1112 | I11: 1 | J11: =I11*1112 -> 1112 | K11: 0 | L11: =K11*1112 -> 0 | M11: 1 | N11: =M11*1112 -> 1112 | O11: 1 | P11: =O11*1112 -> 1112 | Q11: 1 | R11: =Q11*1200 -> 1200 | S11: 0 | T11: =S11*1112 -> 0 | U11: 1 | V11: =U11*1112 -> 1112 | W11: 1 | X11: =W11*1200 -> 1200 | Y11: 1 | Z11: =Y11*1112 -> 1112 | AA11: 1 | AB11: =AA11*1100 -> 1100 | AC11: 1 | AD11: =AC11*1100 -> 1100 | AF11: =SUM(AD11,AB11,Z11,X11,V11,T11,R11,P11,N11,L11,J11,H11,F11,D11) -> 13884
A12: Mercredi | B12: 45607 | C12: 1 | D12: =C12*1500 -> 1500 | E12: 1 | F12: =E12*1112 -> 1112 | G12: 1 | H12: =G12*1112 -> 1112 | I12: 1 | J12: =I12*1112 -> 1112 | K12: 0 | L12: =K12*1112 -> 0 | M12: 1 | N12: =M12*1112 -> 1112 | O12: 1 | P12: =O12*1112 -> 1112 | Q12: 1 | R12: =Q12*1200 -> 1200 | S12: 1 | T12: =S12*1112 -> 1112 | U12: 1 | V12: =U12*1112 -> 1112 | W12: 1 | X12: =W12*1200 -> 1200 | Y12: 1 | Z12: =Y12*1112 -> 1112 | AA12: 1 | AB12: =AA12*1100 -> 1100 | AC12: 1 | AD12: =AC12*1100 -> 1100 | AF12: =SUM(AD12,AB12,Z12,X12,V12,T12,R12,P12,N12,L12,J12,H12,F12,D12) -> 14996
A13: Jeudi | B13: 45608 | C13: 0 | D13: =C13*1500 -> 0 | E13: 0 | F13: =E13*1112 -> 0 | G13: 1 | H13: =G13*1112 -> 1112 | I13: 1 | J13: =I13*1112 -> 1112 | K13: 1 | L13: =K13*1112 -> 1112 | M13: 1 | N13: =M13*1112 -> 1112 | O13: 1 | P13: =O13*1112 -> 1112 | Q13: 1 | R13: =Q13*1200 -> 1200 | S13: 1 | T13: =S13*1112 -> 1112 | U13: 1 | V13: =U13*1112 -> 1112 | W13: 1 | X13: =W13*1200 -> 1200 | Y13: 1 | Z13: =Y13*1112 -> 1112 | AA13: 1 | AB13: =AA13*1100 -> 1100 | AC13: 1 | AD13: =AC13*1100 -> 1100 | AF13: =SUM(AD13,AB13,Z13,X13,V13,T13,R13,P13,N13,L13,J13,H13,F13,D13) -> 13496
A14: Vendredi | B14: 45609 | C14: 1 | D14: =C14*1500 -> 1500 | E14: 0.75 | F14: =E14*1112 -> 834 | G14: 1 | H14: =G14*1112 -> 1112 | I14: 1 | J14: =I14*1112 -> 1112 | K14: 0 | L14: =K14*1112 -> 0 | M14: 0 | N14: =M14*1112 -> 0 | O14: 1 | P14: =O14*1112 -> 1112 | Q14: 0.5 | R14: =Q14*1200 -> 600 | S14: 1 | T14: =S14*1112 -> 1112 | U14: 1 | V14: =U14*1112 -> 1112 | W14: 1.5 | X14: =W14*1200 -> 1800 | Y14: 1 | Z14: =Y14*1112 -> 1112 | AA14: 1 | AB14: =AA14*1100 -> 1100 | AC14: 1 | AD14: =AC14*1100 -> 1100 | AE14: Commande de Dar ElBidha | AF14: =SUM(AD14,AB14,Z14,X14,V14,T14,R14,P14,N14,L14,J14,H14,F14,D14) -> 13606
A15: Samedi | B15: 45610 | C15: 1 | D15: =C15*1500 -> 1500 | E15: 1 | F15: =E15*1112 -> 1112 | G15: 1 | H15: =G15*1112 -> 1112 | I15: 1 | J15: =I15*1112 -> 1112 | K15: 0 | L15: =K15*1112 -> 0 | M15: 0 | N15: =M15*1112 -> 0 | O15: 1 | P15: =O15*1112 -> 1112 | Q15: 0 | R15: =Q15*1200 -> 0 | S15: 1 | T15: =S15*1112 -> 1112 | U15: 1 | V15: =U15*1112 -> 1112 | W15: 1.5 | X15: =W15*1200 -> 1800 | Y15: 1 | Z15: =Y15*1112 -> 1112 | AA15: 0 | AB15: =AA15*1100 -> 0 | AC15: 0 | AD15: =AC15*1100 -> 0 | AE15: m | AF15: =SUM(AD15,AB15,Z15,X15,V15,T15,R15,P15,N15,L15,J15,H15,F15,D15) -> 11084
A16: Dimanche | B16: 45611 | C16: 0 | D16: =C16*1500 -> 0 | E16: 1 | F16: =E16*1112 -> 1112 | G16: 0 | H16: =G16*1112 -> 0 | I16: 0 | J16: =I16*1112 -> 0 | K16: 0 | L16: =K16*1112 -> 0 | M16: 1.5 | N16: =M16*1112 -> 1668 | O16: 0 | P16: =O16*1112 -> 0 | Q16: 1 | R16: =Q16*1200 -> 1200 | S16: 1.5 | T16: =S16*1112 -> 1668 | U16: 1.5 | V16: =U16*1112 -> 1668 | W16: 0 | X16: =W16*1200 -> 0 | Y16: 1 | Z16: =Y16*1112 -> 1112 | AA16: 0 | AB16: =AA16*1100 -> 0 | AC16: 1 | AD16: =AC16*1100 -> 1100 | AF16: =SUM(AD16,AB16,Z16,X16,V16,T16,R16,P16,N16,L16,J16,H16,F16,D16) -> 9528
A17: Lundi | B17: 45612 | C17: 0 | D17: =C17*1500 -> 0 | E17: 0 | F17: =E17*1112 -> 0 | G17: 0 | H17: =G17*1112 -> 0 | I17: 0 | J17: =I17*1112 -> 0 | K17: 0 | L17: =K17*1112 -> 0 | M17: 0 | N17: =M17*1112 -> 0 | O17: 0 | P17: =O17*1112 -> 0 | Q17: 0 | R17: =Q17*1200 -> 0 | S17: 0 | T17: =S17*1112 -> 0 | U17: 0 | V17: =U17*1112 -> 0 | W17: 0 | X17: =W17*1200 -> 0 | Y17: 0 | Z17: =Y17*1112 -> 0 | AA17: 0 | AB17: =AA17*1100 -> 0 | AC17: 0 | AD17: =AC17*1100 -> 0 | AF17: =SUM(AD17,AB17,Z17,X17,V17,T17,R17,P17,N17,L17,J17,H17,F17,D17) -> 0
A18: Mardi | B18: 45613 | C18: 0 | D18: =C18*1500 -> 0 | E18: 0 | F18: =E18*1112 -> 0 | G18: 0 | H18: =G18*1112 -> 0 | I18: 0 | J18: =I18*1112 -> 0 | K18: 0 | L18: =K18*1112 -> 0 | M18: 0 | N18: =M18*1112 -> 0 | O18: 0 | P18: =O18*1112 -> 0 | Q18: 0 | R18: =Q18*1200 -> 0 | S18: 0 | T18: =S18*1112 -> 0 | U18: 0 | V18: =U18*1112 -> 0 | W18: 0 | X18: =W18*1200 -> 0 | Y18: 0 | Z18: =Y18*1112 -> 0 | AA18: 0 | AB18: =AA18*1100 -> 0 | AC18: 0 | AD18: =AC18*1100 -> 0 | AF18: =SUM(AD18,AB18,Z18,X18,V18,T18,R18,P18,N18,L18,J18,H18,F18,D18) -> 0
A19: Mercredi | B19: 45614 | C19: 0 | D19: =C19*1500 -> 0 | E19: 0 | F19: =E19*1112 -> 0 | G19: 0 | H19: =G19*1112 -> 0 | I19: 0 | J19: =I19*1112 -> 0 | K19: 0 | L19: =K19*1112 -> 0 | M19: 0 | N19: =M19*1112 -> 0 | O19: 0 | P19: =O19*1112 -> 0 | Q19: 0 | R19: =Q19*1200 -> 0 | S19: 0 | T19: =S19*1112 -> 0 | U19: 0 | V19: =U19*1112 -> 0 | W19: 0 | X19: =W19*1200 -> 0 | Y19: 0 | Z19: =Y19*1112 -> 0 | AA19: 0 | AB19: =AA19*1100 -> 0 | AC19: 0 | AD19: =AC19*1100 -> 0 | AF19: =SUM(AD19,AB19,Z19,X19,V19,T19,R19,P19,N19,L19,J19,H19,F19,D19) -> 0
A20: Jeudi | B20: 45615 | C20: 0 | D20: =C20*1500 -> 0 | E20: 0 | F20: =E20*1112 -> 0 | G20: 0 | H20: =G20*1112 -> 0 | I20: 0 | J20: =I20*1112 -> 0 | K20: 0 | L20: =K20*1112 -> 0 | M20: 0 | N20: =M20*1112 -> 0 | O20: 0 | P20: =O20*1112 -> 0 | Q20: 0 | R20: =Q20*1200 -> 0 | S20: 0 | T20: =S20*1112 -> 0 | U20: 0 | V20: =U20*1112 -> 0 | W20: 0 | X20: =W20*1200 -> 0 | Y20: 0 | Z20: =Y20*1112 -> 0 | AA20: 0 | AB20: =AA20*1100 -> 0 | AC20: 0 | AD20: =AC20*1100 -> 0 | AF20: =SUM(AD20,AB20,Z20,X20,V20,T20,R20,P20,N20,L20,J20,H20,F20,D20) -> 0
A21: Vendredi | B21: 45616 | C21: 0 | D21: =C21*1500 -> 0 | E21: 0 | F21: =E21*1112 -> 0 | G21: 0 | H21: =G21*1112 -> 0 | I21: 0 | J21: =I21*1112 -> 0 | K21: 0 | L21: =K21*1112 -> 0 | M21: 1 | N21: =M21*1112 -> 1112 | O21: 1 | P21: =O21*1112 -> 1112 | Q21: 0 | R21: =Q21*1200 -> 0 | S21: 0 | T21: =S21*1112 -> 0 | U21: 0 | V21: =U21*1112 -> 0 | W21: 1 | X21: =W21*1200 -> 1200 | Y21: 1 | Z21: =Y21*1112 -> 1112 | AA21: 0 | AB21: =AA21*1100 -> 0 | AC21: 0 | AD21: =AC21*1100 -> 0 | AF21: =SUM(AD21,AB21,Z21,X21,V21,T21,R21,P21,N21,L21,J21,H21,F21,D21) -> 4536
A22: Samedi | B22: 45617 | C22: 0 | D22: =C22*1500 -> 0 | E22: 0 | F22: =E22*1112 -> 0 | G22: 0 | H22: =G22*1112 -> 0 | I22: 0 | J22: =I22*1112 -> 0 | K22: 0 | L22: =K22*1112 -> 0 | M22: 0 | N22: =M22*1112 -> 0 | O22: 1 | P22: =O22*1112 -> 1112 | Q22: 0 | R22: =Q22*1200 -> 0 | S22: 0 | T22: =S22*1112 -> 0 | U22: 0 | V22: =U22*1112 -> 0 | W22: 1 | X22: =W22*1200 -> 1200 | Y22: 1 | Z22: =Y22*1112 -> 1112 | AA22: 0 | AB22: =AA22*1100 -> 0 | AC22: 0 | AD22: =AC22*1100 -> 0 | AF22: =SUM(AD22,AB22,Z22,X22,V22,T22,R22,P22,N22,L22,J22,H22,F22,D22) -> 3424
A23: vendredi | B23: 45618 | C23: 0 | D23: =C23*1500 -> 0 | E23: 1 | F23: =E23*1112 -> 1112 | G23: 0 | H23: =G23*1112 -> 0 | I23: 0 | J23: =I23*1112 -> 0 | K23: 0 | L23: =K23*1112 -> 0 | M23: 0 | N23: =M23*1112 -> 0 | O23: 1 | P23: =O23*1112 -> 1112 | Q23: 0 | R23: =Q23*1200 -> 0 | S23: 1 | T23: =S23*1112 -> 1112 | U23: 1 | V23: =U23*1112 -> 1112 | W23: 0 | X23: =W23*1200 -> 0 | Y23: 0 | Z23: =Y23*1112 -> 0 | AA23: 0 | AB23: =AA23*1100 -> 0 | AC23: 1 | AD23: =AC23*1100 -> 1100 | AF23: =SUM(AD23,AB23,Z23,X23,V23,T23,R23,P23,N23,L23,J23,H23,F23,D23) -> 5548
A24: samedi | B24: 45619 | C24: 1 | D24: =C24*1500 -> 1500 | E24: 1 | F24: =E24*1112 -> 1112 | G24: 1 | H24: =G24*1112 -> 1112 | I24: 1 | J24: =I24*1112 -> 1112 | K24: 0 | L24: =K24*1112 -> 0 | M24: 1 | N24: =M24*1112 -> 1112 | O24: 1 | P24: =O24*1112 -> 1112 | Q24: 1 | R24: =Q24*1200 -> 1200 | S24: 1 | T24: =S24*1112 -> 1112 | U24: 1 | V24: =U24*1112 -> 1112 | W24: 1 | X24: =W24*1200 -> 1200 | Y24: 1 | Z24: =Y24*1112 -> 1112 | AA24: 0 | AB24: =AA24*1100 -> 0 | AC24: 1 | AD24: =AC24*1100 -> 1100 | AF24: =SUM(AD24,AB24,Z24,X24,V24,T24,R24,P24,N24,L24,J24,H24,F24,D24) -> 13896
A25: dimanche | B25: 45620 | C25: 0 | D25: =C25*1500 -> 0 | E25: 1 | F25: =E25*1112 -> 1112 | G25: 1 | H25: =G25*1112 -> 1112 | I25: 1 | J25: =I25*1112 -> 1112 | K25: 0 | L25: =K25*1112 -> 0 | M25: 1 | N25: =M25*1112 -> 1112 | O25: 1 | P25: =O25*1112 -> 1112 | Q25: 0 | R25: =Q25*1200 -> 0 | S25: 1 | T25: =S25*1112 -> 1112 | U25: 1 | V25: =U25*1112 -> 1112 | W25: 1 | X25: =W25*1200 -> 1200 | Y25: 1 | Z25: =Y25*1112 -> 1112 | AA25: 0.5 | AB25: =AA25*1100 -> 550 | AC25: 1 | AD25: =AC25*1100 -> 1100 | AF25: =SUM(AD25,AB25,Z25,X25,V25,T25,R25,P25,N25,L25,J25,H25,F25,D25) -> 11746
A26: lundi | B26: 45621 | C26: 0.5 | D26: =C26*1500 -> 750 | E26: 1 | F26: =E26*1112 -> 1112 | G26: 1 | H26: =G26*1112 -> 1112 | I26: 1 | J26: =I26*1112 -> 1112 | K26: 0 | L26: =K26*1112 -> 0 | M26: 1 | N26: =M26*1112 -> 1112 | O26: 1 | P26: =O26*1112 -> 1112 | Q26: 1 | R26: =Q26*1200 -> 1200 | S26: 1 | T26: =S26*1112 -> 1112 | U26: 0 | V26: =U26*1112 -> 0 | W26: 1 | X26: =W26*1200 -> 1200 | Y26: 1 | Z26: =Y26*1112 -> 1112 | AA26: 1 | AB26: =AA26*1100 -> 1100 | AC26: 1 | AD26: =AC26*1100 -> 1100 | AF26: =SUM(AD26,AB26,Z26,X26,V26,T26,R26,P26,N26,L26,J26,H26,F26,D26) -> 13134
A27: mardi | B27: 45622 | C27: 0 | D27: =C27*1500 -> 0 | E27: 0.5 | F27: =E27*1112 -> 556 | G27: 1 | H27: =G27*1112 -> 1112 | I27: 1 | J27: =I27*1112 -> 1112 | K27: 1 | L27: =K27*1112 -> 1112 | M27: 1 | N27: =M27*1112 -> 1112 | O27: 1 | P27: =O27*1112 -> 1112 | Q27: 0 | R27: =Q27*1200 -> 0 | S27: 1 | T27: =S27*1112 -> 1112 | U27: 1 | V27: =U27*1112 -> 1112 | W27: 1 | X27: =W27*1200 -> 1200 | Y27: 1 | Z27: =Y27*1112 -> 1112 | AA27: 1 | AB27: =AA27*1100 -> 1100 | AC27: 1 | AD27: =AC27*1100 -> 1100 | AF27: =SUM(AD27,AB27,Z27,X27,V27,T27,R27,P27,N27,L27,J27,H27,F27,D27) -> 12852
... A31: samedi | B31: 45626 | C31: 0 | D31: =C31*1500 -> 0 | E31: 1 | F31: =E31*1112 -> 1112 | G31: 1 | H31: =G31*1112 -> 1112 | I31: 1 | J31: =I31*1112 -> 1112 | K31: 0 | L31: =K31*1112 -> 0 | M31: 1 | N31: =M31*1112 -> 1112 | O31: 0.5 | P31: =O31*1112 -> 556 | Q31: 0 | R31: =Q31*1200 -> 0 | S31: 0 | T31: =S31*1112 -> 0 | U31: 1 | V31: =U31*1112 -> 1112 | W31: 0 | X31: =W31*1200 -> 0 | Y31: 1 | Z31: =Y31*1112 -> 1112 | AA31: 0 | AB31: =AA31*1100 -> 0 | AC31: 1 | AD31: =AC31*1100 -> 1100 | AF31: =SUM(AD31,AB31,Z31,X31,V31,T31,R31,P31,N31,L31,J31,H31,F31,D31) -> 8328
A32: Over Time | D32: =C32*1500 -> 0 | E32: 0.4 | F32: =E32*1112 -> 444.8 | H32: =G32*1112 -> 0 | I32: 1.25 | J32: =I32*1112 -> 1390 | L32: =K32*1112 -> 0 | N32: =M32*1112 -> 0 | O32: 1.5 | P32: =O32*1112 -> 1668 | R32: =Q32*1200 -> 0 | T32: =S32*1112 -> 0 | V32: =U32*1112 -> 0 | W32: 1 | X32: =W32*1200 -> 1200 | Y32: 1.95 | Z32: =Y32*1112 -> 2168.4 | AB32: =AA32*1100 -> 0 | AC32: 1.5 | AD32: =AC32*1100 -> 1650 | AF32: =SUM(AD32,AB32,Z32,X32,V32,T32,R32,P32,N32,L32,J32,H32,F32,D32) -> 8521.2
C33: =SUM(C2:C32) -> 11.6 | E33: =SUM(E2:E32) -> 21.75 | G33: =SUM(G2:G32) -> 19 | I33: =SUM(I2:I32) -> 20.25 | K33: 3 | M33: =SUM(M2:M32) -> 20.5 | O33: =SUM(O2:O32) -> 22 | Q33: =SUM(Q2:Q32) -> 16.5 | S33: =SUM(S2:S32) -> 22.5 | U33: =SUM(U2:U32) -> 22.5 | W33: =SUM(W2:W32) -> 23 | Y33: =SUM(Y2:Y32) -> 23.45 | AA33: =SUM(AA2:AA32) -> 13 | AC33: =SUM(AC2:AC32) -> 23.5 | AF33: =SUM(AD33,AB33,Z33,X33,V33,T33,R33,P33,N33,L33,J33,H33,F33,D33) -> 0
C34: 1500 | E34: 1112 | G34: 1112 | I34: 1112 | K34: 1112 | M34: 1112 | O34: 1112 | Q34: 1200 | S34: 1112 | U34: 1112 | W34: 1200 | Y34: 1112 | AA34: 1100 | AC34: 1112 | AF34: =SUM(AD34,AB34,Z34,X34,V34,T34,R34,P34,N34,L34,J34,H34,F34,D34) -> 0
C35: =C34*C33 -> 17400 | E35: =E34*E33 -> 24186 | G35: =G34*G33 -> 21128 | I35: =I34*I33 -> 22518 | K35: =K34*K33 -> 3336 | M35: =M34*M33 -> 22796 | O35: =O34*O33 -> 24464 | Q35: =Q34*Q33 -> 19800 | S35: =S34*S33 -> 25020 | U35: =U34*U33 -> 25020 | W35: =W34*W33 -> 27600 | Y35: =Y34*Y33 -> 26076.4 | AA35: =AA33*AA34 -> 14300 | AC35: =AC34*AC33 -> 26132 | AF35: =SUM(AD35,AB35,Z35,X35,V35,T35,R35,P35,N35,L35,J35,H35,F35,D35) -> 0
D36: =C36*1500 -> 0 | E36: 30000 | F36: =E36*E65 -> 0 | G36: 30000 | I36: 30000 | K36: 30000 | M36: 30000 | O36: 30000 | S36: 30000 | U36: 30000 | X36: =W36*1200 -> 0 | Z36: =Y36*1112 -> 0 | AB36: =AA36*1100 -> 0 | AD36: =AC36*1100 -> 0 | AF36: =SUM(AD36,AB36,Z36,X36,V36,T36,R36,P36,N36,L36,J36,H36,F36,D36) -> 0

Sheet Les charges 
C2: Produit | D2: Quantité | E2: Prix unitaire | F2: Prix | G2: Date d'achat
C3: Semoule Moyenne 25kg | D3: 4 | E3: 1000 | F3: =D3*E3 -> 4000
C4: Semoule Fine 25kg | D4: 25 | E4: 1000 | F4: =D4*E4 -> 25000
C5: Semoule Fine Sosimie 10kg | D5: 2.5 | E5: 37 | F5: =D5*E5 -> 92.5
C6: Semoule Fine 5 kg | D6: 3 | E6: 380 | F6: =D6*E6 -> 1140
C7: semoule Fine Moula 10kg | D7: 2 | E7: 580 | F7: =D7*E7 -> 1160
C8: Levure boulangère | D8: 9 | E8: 390 | F8: =D8*E8 -> 3510
C9: levure chimique | D9: 60 | E9: 6.2 | F9: =D9*E9 -> 372
C10: margarine Fleuriel 500g | D10: 70 | E10: 189 | F10: =D10*E10 -> 13230
C11: Harrissa 1kg | D11: 4 | E11: 260 | F11: =D11*E11 -> 1040
C12: Tomate conserve 1kg | D12: 6 | E12: 325 | F12: =D12*E12 -> 1950
C13: huile 5 litre | D13: 21 | E13: 600 | F13: =D13*E13 -> 12600
C14: terida | D14: 1 | E14: 180 | F14: =D14*E14 -> 180
... C73: thym | D73: 3 | E73: 50 | F73: =D73*E73 -> 150
C74: carotte | D74: 1 | E74: 100 | F74: =D74*E74 -> 100 | G74: 45597
C75: concombre | D75: 1 | E75: 140 | F75: =D75*E75 -> 140
C76: poivre | D76: 0.5 | E76: 200 | F76: =D76*E76 -> 100
C77: Tomate fraiche | D77: 1 | E77: 200 | F77: =D77*E77 -> 200
C78: citron | D78: 1.5 | E78: 120 | F78: =D78*E78 -> 180
C79: salade | D79: 1.5 | E79: 200 | F79: =D79*E79 -> 300
C80: persil | D80: 3 | E80: 30 | F80: =D80*E80 -> 90
C81: coriandre | D81: 4 | E81: 30 | F81: =D81*E81 -> 120
C82: menth frais | D82: 1 | E82: 30 | F82: =D82*E82 -> 30
C83: rechta | D83: 10 | E83: 100 | F83: =D83*E83 -> 1000
C84: Blanc de poulet | D84: 1 | E84: 800 | F84: =D84*E84 -> 800
C85: oeufs | D85: 60 | E85: 16 | F85: =D85*E85 -> 960
C86: ferik | D86: 0.5 | E86: 400 | F86: =D86*E86 -> 200
... C109: metelou3 | D109: 11 | E109: 50 | F109: =D109*E109 -> 550
C110: poulet haché | D110: 1 | E110: 800 | F110: =D110*E110 -> 800 | G110: 45598
C111: Blanc de poulet | D111: 1 | E111: 800 | F111: =D111*E111 -> 800
C112: éscalope de poulet | D112: 1 | E112: 800 | F112: =D112*E112 -> 800
C113: Tomate fraiche | D113: 1 | E113: 200 | F113: =D113*E113 -> 200
C114: isis | D114: 1 | E114: 190 | F114: =D114*E114 -> 190
C115: sel | D115: 1 | E115: 40 | F115: =D115*E115 -> 40
C116: rechta | D116: 3 | E116: 120 | F116: =D116*E116 -> 360
C117: rechta | D117: 2 | E117: 120 | F117: =D117*E117 -> 240 | G117: 45599
C118: livraison idir | D118: 1 | E118: 300 | F118: =D118*E118 -> 300 | G118: 45600
C119: Tomate fraiche | D119: 1 | E119: 250 | F119: =D119*E119 -> 250
C120: Tomate fraiche | D120: 3 | E120: 140 | F120: =D120*E120 -> 420
C121: poulet haché | D121: 1 | E121: 800 | F121: =D121*E121 -> 800
...

Sheet Feuille 5

Sheet Salaires
E7: Nom | F7: Salaire | G7: Avance | H7: Salaire à payer
E8: Sofiane | F8: 30000 | G8: 30000 | H8: =F8-G8 -> 0 | I8: les repas
E9: Amel | F9: 30000 | G9: 30000 | H9: =F9-G9 -> 0
D10: 1 | E10: Nadjet | F10: =Pointage!C35 -> 17400 | G10: 17500 | H10: =F10-G10 -> -100
D11: 2 | E11: Yasmine | F11: =Pointage!E35+I11 -> 29186 | G11: 29500 | H11: =F11-G11 -> -314 | I11: 5000
D12: 3 | E12: Saida | F12: =Pointage!G35 -> 21128 | G12: 21500 | H12: =F12-G12 -> -372
D13: 5 | E13: Ahlem | F13: 22500 | G13: 22500 | H13: =F13-G13 -> 0
D14: 6 | E14: Nour ElHouda | F14: =Pointage!K35 -> 3336 | G14: 4000 | H14: =F14-G14 -> -664
D15: 9 | E15: Amina | F15: =Pointage!M35 -> 22796 | G15: 23000 | H15: =F15-G15 -> -204
D16: 10 | E16: Selma | F16: =Pointage!O35 -> 24464 | G16: 24500 | H16: =F16-G16 -> -36 | I16: 5000+2000
D17: 11 | E17: Zohra | F17: =Pointage!Q35 -> 19800 | G17: 20000 | H17: =F17-G17 -> -200 | I17: 9000
D18: 13 | E18: Rayan | F18: =Pointage!W35 -> 27600 | G18: 28000 | H18: =F18-G18 -> -400
D19: 14 | E19: Ikram | F19: 25000 | G19: 25000 | H19: =F19-G19 -> 0 | I19: 1000
D20: 15 | E20: Nora | F20: 25000 | G20: 25000 | H20: =F20-G20 -> 0 | I20: 1000
D21: 16 | E21: Sihem | F21: =Pointage!AA35 -> 14300 | G21: 14500 | H21: =F21-G21 -> -200 | I21: 5000 Da +4000 Da
D22: 17 | E22: Karima | F22: 26000 | G22: 26000 | H22: =F22-G22 -> 0
D23: 17 | E23: Fatiha | F23: =Pointage!AC35 -> 26132 | G23: 26500 | H23: =F23-G23 -> -368 | I23: 20000+2000+500
E24: TOTAL | F24: =SUM(F8:F23) -> 364642 | G24: =SUM(G8:G23) -> 367500 | H24: =F24-G24 -> -2858
H25: =F25-G25 -> 0

Sheet Compta du 23 au 29
C12: Produit | D12: Quantité | E12: PU | F12: Prix total
H13: Total Achat | K13: Ouverture Caisse
C14: dyoul taille normal | D14: 2 | E14: 100 | F14: 200 | H14: =SUM(F14:F81) -> 100716 | K14: Date | L14: Montant
C15: Rechta | D15: 12 kg | E15: 100 | F15: 1200 | K15: 45619 | L15: 20240
C16: Felfel hlou | D16: 2 kg | E16: 180 | F16: 720 | H16: Caisse de départ | K16: 45620 | L16: 12250
C17: Tomate | D17: 2 kg | E17: 100 | F17: 400 | H17: 100000 | K17: 45621 | L17: 13750
C18: Salade verte | D18: 1 kg | E18: 110 | F18: 110 | K18: 45622 | L18: 12765
C19: Thom (ail) | D19: 1 unité | E19: 50 | F19: 50 | H19: Recette du 23 au 29 | K19: 45623 | L19: 7975
C20: Poulet haché | D20: 3.2 kg | E20: 760 | F20: 2430 | H20: =SUM(RECAP!D24:D30) -> 330000 | K20: 45624 | L20: 5810
C21: Blanc de poulet | D21: 3.5 kg | E21: 760 | F21: 2660 | K21: 45625 | L21: 5225
C22: Escalope | D22: 2.5 kg | E22: 760 | F22: 1900 | H22: Reste caisse | K22: 45626 | L22: 6090
C23: Œufs | D23: 4 plateaux | E23: 500 | F23: 2000 | H23: =(H20+H17)-H14 -> 329284
C24: Olives vertes | D24: 2 kg | E24: 600 | F24: 1200
C25: Olives coupées | D25: 2 kg | E25: 600 | F25: 1200
C26: Carton d’olives noires | D26: 5kg | E26: 400 | F26: 2000
C27: Viande hachée | D27: 1 kg | E27: 1000 | F27: 1000
C28: Boîte Hmissa (Mechamkha) | D28: 1 boîte | E28: 200 | F28: 200
C29: Pommes de terre | D29: 2 kg | E29: 150 | F29: 300
C30: Cuisse entière de poulet | D30: 1 unité | E30: 200 | F30: 200
C31: Épinards | D31: 6 rabtat | E31: 30 | F31: 180
C32: Bidoune fromage (Topla) | D32: 3.8 kg | E32: 1450 | F32: 1450
C33: 9arfa poudre | D33: 1 unité | E33: 100 | F33: 100
C34: Rabta Kesber | D34: 1 unité | E34: 30 | F34: 30
C35: Rabta Ma3adnous | D35: 1 unité | E35: 30 | F35: 30
... C37: Microfibre | D37: 1 unité | E37: 150 | F37: 150
C38: Reparation verre | D38: 1 | E38: 5500 | F38: 5500
C39: Rechta | D39: 5 kg | E39: 100 | F39: 500
C40: Rabta persil | D40: 1 unité | E40: 30 | F40: 30
C41: Blanc de poulet | D41: 1 kg | E41: 750 | F41: 750
C42: Poulet haché | D42: 1.2 kg | E42: 750 | F42: 900
C43: Carotte | D43: 1 kg | E43: 70 | F43: 70
C44: Brocoli | D44: 1 unité | E44: 195 | F44: 195
C45: Épinards | D45: 2 rabtat | E45: 30 | F45: 60
C46: Rechta | D46: 10 kg | E46: 100 | F46: 1000
C47: Chehma | D47: 1 unité | E47: 300 | F47: 300
C48: Œufs | D48: 2 plateaux | E48: 500 | F48: 1000
C49: Tomate | D49: 2 kg | E49: 100 | F49: 200
C50: Rabta Ma3adnous | D50: 1 unité | E50: 30 | F50: 30
... C59: Fromage pizza Napoli | D59: 2 kg | E59: 420 | F59: 840
C60: Fromage bidoune | D60: 3.8 kg | E60: 381.58 | F60: 1450
...

Sheet Feuille 7
D21: Mois de Janvier | E21: Mois de Février | F21: Mois de Mars | G21: Mois d'Avril | H21: Mois de Mai | I21: Mois de Jiun | J21: Mois de Juillet | K21: Mois d'Aout | L21: Mois de Septembre | M21: Mois d'Octobre | N21: Mois de Novembre | Q21: Mois d'Novembre
C22: Recette | D22: 1756000 | E22: 2274000 | F22: 1984000 | G22: 1910000 | H22: 1342000 | I22: 1760000 | J22: 2260000 | K22: 1427000 | L22: 1740000 | M22: 1620000 | N22: 1328000 | P22: Recette | Q22: 1328000
C23: Charges | D23: 920000 | E23: 914000 | F23: 928000 | G23: 744000 | H23: 646000 | I23: 804000 | J23: 958000 | K23: 640000 | L23: 716000 | M23: 747000 | N23: 645000 | P23: Charges | Q23: 645000
C24: Salaires | D24: 349000 | E24: 410000 | F24: 406000 | G24: 344000 | H24: 436000 | I24: 396000 | J24: 432000 | K24: 307000 | L24: 514000 | M24: 438000 | N24: 365000 | P24: Salaires | Q24: 365000
C25: Loyer | D25: 140000 | E25: 140000 | F25: 140000 | G25: 140000 | H25: 140000 | I25: 140000 | J25: 150000 | K25: 150000 | L25: 150000 | M25: 150000 | N25: 150000 | P25: Che7i7a | Q25: 48000
C26: Profit Net | D26: =D22-D23-D24-D25 -> 347000 | E26: =E22-E23-E24-E25 -> 810000 | F26: =F22-F23-F24-F25 -> 510000 | G26: 680000 | H26: =H22-H23-H24-H25 -> 120000 | I26: 420000 | J26: =J22-J23-J24-J25 -> 720000 | K26: 330000 | L26: =L22-L23-L24-L25 -> 360000 | M26: =M22-M23-M24-M25 -> 285000 | N26: 120000 | P26: Loyer | Q26: 150000
P27: Profit Net | Q27: =Q22-Q23-Q24-Q25-Q26 -> 120000

Sheet Feuille 8
C1: Saida | G1: Selma | K1: Karima | O1: Sihem
A2: Dimanche | B2: 45597 | C2: 0 | E2: Dimanche | F2: 45597 | G2: 0 | I2: Dimanche | J2: 45597 | K2: 0 | M2: Dimanche | N2: 45597 | O2: 0
A3: Lundi | B3: 45598 | C3: 1 | E3: Lundi | F3: 45598 | G3: 1 | I3: Lundi | J3: 45598 | K3: 1 | M3: Lundi | N3: 45598 | O3: 0
A4: Mardi | B4: 45599 | C4: 1 | E4: Mardi | F4: 45599 | G4: 1 | I4: Mardi | J4: 45599 | K4: 1 | M4: Mardi | N4: 45599 | O4: 1
A5: Mercredi | B5: 45600 | C5: 1 | E5: Mercredi | F5: 45600 | G5: 1 | I5: Mercredi | J5: 45600 | K5: 1 | M5: Mercredi | N5: 45600 | O5: 0.5
A6: Jeudi | B6: 45601 | C6: 1 | E6: Jeudi | F6: 45601 | G6: 1 | I6: Jeudi | J6: 45601 | K6: 1 | M6: Jeudi | N6: 45601 | O6: 1
A7: Vendredi | B7: 45602 | C7: 1 | E7: Vendredi | F7: 45602 | G7: 1 | I7: Vendredi | J7: 45602 | K7: 1 | M7: Vendredi | N7: 45602 | O7: 1
A8: Samedi | B8: 45603 | C8: 1 | E8: Samedi | F8: 45603 | G8: 0 | I8: Samedi | J8: 45603 | K8: 1 | M8: Samedi | N8: 45603 | O8: 1
A9: Dimanche | B9: 45604 | C9: 0 | E9: Dimanche | F9: 45604 | G9: 0 | I9: Dimanche | J9: 45604 | K9: 0 | M9: Dimanche | N9: 45604 | O9: 0
A10: Lundi | B10: 45605 | C10: 1 | E10: Lundi | F10: 45605 | G10: 1 | I10: Lundi | J10: 45605 | K10: 1 | M10: Lundi | N10: 45605 | O10: 0
A11: Mardi | B11: 45606 | C11: 1 | E11: Mardi | F11: 45606 | G11: 1 | I11: Mardi | J11: 45606 | K11: 1 | M11: Mardi | N11: 45606 | O11: 1
A12: Mercredi | B12: 45607 | C12: 1 | E12: Mercredi | F12: 45607 | G12: 1 | I12: Mercredi | J12: 45607 | K12: 1 | M12: Mercredi | N12: 45607 | O12: 1
A13: Jeudi | B13: 45608 | C13: 1 | E13: Jeudi | F13: 45608 | G13: 1 | I13: Jeudi | J13: 45608 | K13: 1 | M13: Jeudi | N13: 45608 | O13: 1
... A31: samedi | B31: 45626 | C31: 1 | E31: samedi | F31: 45626 | G31: 0.5 | I31: samedi | J31: 45626 | K31: 1 | M31: samedi | N31: 45626 | O31: 0
A32: Over Time | E32: Over Time | G32: 1.5 | I32: Over Time | K32: 1.95 | M32: Over Time
C33: =SUM(C2:C32) -> 19 | G33: =SUM(G2:G32) -> 22 | K33: =SUM(K2:K32) -> 23.45 | O33: =SUM(O2:O32) -> 13
C34: 1112 | G34: 1112 | K34: 1112 | O34: 1100
C35: =C34*C33 -> 21128 | G35: =G34*G33 -> 24464 | K35: =K34*K33 -> 26076.4 | O35: =O33*O34 -> 14300
C36: 30000 | G36: 30000
