Workbook

Sheet RECAP
B1: Date | C1: Recette Féverier 2025 | D1: Recette | E1: Charges | F1: Salaire | G1: Che7i7a | H1: Loyer | I1: Net Profit | J1: Nb de jours | L1: Objectif | M1: Mois de Février 2025
A2: Samedi | B2: 45717 | C2: 53000 | D2: 78000 | F2: =Pointage!AF2 | G2: 2000 | J2: 1 | M2: 53000
A3: Dimanche | B3: 45718 | C3: 60000 | D3: 48000 | F3: =Pointage!AF3 | G3: 2000 | J3: 1 | M3: 60000 | N3: Bénéfice Moyen par jour | O3: Moyenne | P3: Moyenne salaire | Q3: pourcentage du salaire vis à vis la recettte
A4: Lundi | B4: 45719 | C4: 46000 | D4: 53000 | F4: =Pointage!AF4 | G4: 2000 | J4: 1 | M4: 46000 | N4: =I33/J33 -> 15109.719 | O4: =D33/J33 -> 69800 | Q4: =P4/O4 -> 0
A5: Mardi | B5: 45720 | C5: 28000 | D5: 40000 | F5: =Pointage!AF5 | G5: 2000 | J5: 1 | M5: 28000
A6: Mercredi | B6: 45721 | C6: 91000 | D6: 43000 | F6: =Pointage!AF6 | G6: 2000 | J6: 1 | M6: 91000 | N6: Moyenne des charges par jour | O6: Objectif
A7: Jeudi | B7: 45722 | C7: 120000 | D7: 45000 | F7: =Pointage!AF7 | G7: 2000 | J7: 1 | M7: 120000 | N7: =E33/J33 -> 31900.017 | O7: 100000
A8: Vendredi | B8: 45723 | C8: 69000 | D8: 63000 | F8: =Pointage!AF8 | G8: 2000 | J8: 1 | M8: 69000 | N8: ² | S8: "
A9: Samedi | B9: 45724 | C9: 58000 | D9: 54000 | F9: =Pointage!AF9 | G9: 2000 | J9: 1 | M9: 58000
A10: Dimanche | B10: 45725 | C10: 21000 | D10: 52000 | F10: =Pointage!AF10 | G10: 2000 | J10: 1 | M10: 21000 | N10: Cash restant | O10: Magasin | P10: Cash réel | Q10: Mes dettes pour le magasin
A11: Lundi | B11: 45726 | C11: 46000 | D11: 45000 | F11: =Pointage!AF11 | G11: 2000 | J11: 1 | M11: 46000 | N11: =N14+D33-E33-G33-'Les Salaires'!L24-O11 -> 271999.5 | O11: 718000 | P11: 340000 | Q11: =N11-P11 -> -68000.5
A12: Mardi | B12: 45727 | C12: 54000 | D12: 57000 | F12: =Pointage!AF12 | G12: 2000 | J12: 1 | M12: 54000
A13: Mercredi | B13: 45728 | C13: 67000 | D13: 58000 | F13: =Pointage!AF13 | G13: 2000 | J13: 1 | M13: 67000 | N13: Fond de Roulement
A14: Jeudi | B14: 45729 | C14: 130000 | D14: 55000 | F14: =Pointage!AF14 | G14: 2000 | J14: 1 | M14: 130000 | N14: 330000
A15: Vendredi | B15: 45730 | C15: 60000 | D15: 74000 | F15: =Pointage!AF15 | G15: 2000 | J15: 1 | M15: 60000 | Q15: La caisse :2000 Da
A16: Samedi | B16: 45731 | C16: 50000 | D16: 29000 | F16: =Pointage!AF16 | G16: 2000 | J16: 1 | K16: 1 | M16: 50000 | N16: Bénéfice Sept + loyer | Q16: Sofiane :20000Da+7000Da +30000Da +20000Da+11000=88000Da-50000Da Sifou =38000Da
A17: Dimanche | B17: 45732 | C17: 71000 | D17: 56000 | F17: =Pointage!AF17 | G17: 2000 | J17: 1 | K17: 1 | M17: 71000 | N17: 0 | Q17: 220000Da
A18: Lundi | B18: 45733 | C18: 39000 | D18: 37000 | F18: =Pointage!AF18 | G18: 2000 | J18: 1 | M18: 39000 | Q18: Nour : 10000 Da gateaux
A19: Mardi | B19: 45734 | C19: 60000 | D19: 36000 | F19: =Pointage!AF19 | G19: 2000 | J19: 1 | M19: 60000 | N19: Différence mois de Décembre | Q19: Sofiane : 24000Da
A20: Mercredi | B20: 45735 | C20: 41000 | D20: 49000 | F20: =Pointage!AF20 | G20: 2000 | J20: 1 | M20: 41000 | N20: =D33-C33 -> 305000 | Q20: les Charges Mois d'Avril: 424000Da
A21: Jeudi | B21: 45736 | C21: 110000 | D21: 61000 | F21: =Pointage!AF21 | G21: 2000 | J21: 1 | M21: 110000 | N21: Différence objectif | Q21: CCP:30000Da
A22: Vendredi | B22: 45737 | C22: 55000 | D22: 61000 | F22: =Pointage!AF22 | G22: 2000 | J22: 1 | M22: 55000 | N22: =L36-E36 -> 0
A23: Samedi | B23: 45738 | C23: 77000 | D23: 36000 | F23: =Pointage!AF23 | G23: 2000 | J23: 1 | M23: 77000 | N23: Différence du Totale
A24: Dimanche | B24: 45739 | C24: 44000 | D24: 39000 | F24: =Pointage!AF24 | G24: 2000 | J24: 1 | M24: 44000 | N24: =D33-C33 -> 305000
A25: Lundi | B25: 45740 | C25: 49000 | D25: 57000 | F25: =Pointage!AF25 | G25: 2000 | J25: 1 | M25: 49000 | N25: Les vendredis
A26: Mardi | B26: 45741 | C26: 137000 | D26: 74000 | F26: =Pointage!AF26 | G26: 2000 | J26: 1 | M26: 137000 | N26: =D9+D16+D23+D30 -> 489000
A27: Mercredi | B27: 45742 | C27: 60000 | D27: 68000 | F27: =Pointage!AF27 | G27: 2000 | J27: 1 | M27: 60000
A28: Jeudi | B28: 45743 | C28: 93000 | D28: 70000 | F28: =Pointage!AF28 | G28: 2000 | J28: 1 | M28: 93000 | N28: Cash réel
A29: Vendredi | B29: 45744 | C29: 0 | D29: 226000 | F29: =Pointage!AF29 | G29: 2000 | J29: 1 | M29: 70000 | N29: 51000
A30: Samedi | B30: 45745 | C30: 0 | D30: 370000 | F30: =Pointage!AF30 | G30: 2000 | J30: 1 | M30: 0 | N30: rest à payer
A31: Dimanche | B31: 45746 | C31: 0 | D31: 60000 | F31: =Pointage!AF31 | G31: 2000 | J31: 1 | M31: 0
A32: Lundi | B32: 45747 | C32: 0 | D32: 0 | F32: =Pointage!AF32 | M32: 0
C33: =SUM(C2:C32) -> 1789000 | D33: =SUM(D2:D32) -> 2094000 | E33: ='Les Charges'!H427 -> 957000.5 | F33: ='Les Salaires'!K24 -> 443707.93 | G33: =SUM(G2:G32) -> 60000 | H33: 180000 | I33: =D33-E33-F33-G33-H33 -> 453291.57 | J33: =SUM(J2:J32) -> 30 | M33: =SUM(M2:M32) -> 1859000
G34: Loyer Magasin | H34: 55000
G35: Loyer Locale | H35: 40000 | N35: =N11-N29-N34 -> 220999.5
D36: 200000 | G36: Sofiane Maison | H36: 45000
G37: Dette Papa | H37: 40000
D38: -
C49: 1

Sheet Les Charges
E2: Produit | F2: Quantité | G2: Prix unitaire | H2: Prix | I2: Date d'achat
E3: Semoule Fine 10kg | F3: 20 | G3: 380 | H3: =F3*G3 -> 7600
E4: Semoule Fine 25kg | F4: 5 | G4: 1000 | H4: =F4*G4 -> 5000
E5: Semoule Moyenne 25kg | F5: 5 | G5: 1000 | H5: =F5*G5 -> 5000
E6: Semoule Moula Gross 10 kg | F6: 3 | G6: 950 | H6: =F6*G6 -> 2850
E7: Semoule Grosse moula 2kg | F7: 1 | G7: 270 | H7: =F7*G7 -> 270
E8: Faine 10kg | F8: 5 | G8: 580 | H8: =F8*G8 -> 2900
E9: semoule blé complet | F9: 5 | G9: 100 | H9: =F9*G9 -> 500
E10: Levure boulangère | F10: 10 | G10: 415 | H10: =F10*G10 -> 4150
E11: Chocolat wedjedane au lait | F11: 2 | G11: 230 | H11: =F11*G11 -> 460
E12: Chocolat wedjedane noir | F12: 8 | G12: 230 | H12: =F12*G12 -> 1840
E13: chocolat wedjedane noisette | F13: 5 | G13: 270 | H13: =F13*G13 -> 1350
E14: chocolat wedjdane Blanc | F14: 10 | G14: 230 | H14: =F14*G14 -> 2300
... E75: plateaux oeufs | F75: 9 | G75: 450 | H75: =F75*G75 -> 4050
E76: plateaux oeufs | F76: 8 | G76: 450 | H76: =F76*G76 -> 3600 | I76: 45722
E77: poulet haché + blanc de poulet | F77: 6 | G77: 700 | H77: =F77*G77 -> 4200
E78: bessel | F78: 4 | G78: 70 | H78: =F78*G78 -> 280
E79: dettes légumes | F79: 1 | G79: 1090 | H79: =F79*G79 -> 1090
E80: poivron couleur | F80: 1 | G80: 220 | H80: =F80*G80 -> 220
E81: tomate fraiche | F81: 8 | G81: 100 | H81: =F81*G81 -> 800
E82: riz basmati | F82: 1 | G82: 480 | H82: =F82*G82 -> 480
E83: camembert | F83: 1 | G83: 420 | H83: =F83*G83 -> 420
E84: deyoul | F84: 15 | G84: 100 | H84: =F84*G84 -> 1500
E85: poulet haché + blanc de poulet | F85: 6 | G85: 700 | H85: =F85*G85 -> 4200
E86: lavemain | F86: 2 | G86: 120 | H86: =F86*G86 -> 240
E87: olive dényauté | F87: 2 | G87: 600 | H87: =F87*G87 -> 1200
E88: curdent | F88: 3 | G88: 150 | H88: =F88*G88 -> 450
... E101: Houda yassir | F101: 2 | G101: 800 | H101: =F101*G101 -> 1600
E102: deyoul | F102: 25 | G102: 100 | H102: =F102*G102 -> 2500 | I102: 45723
E103: sac croissant 23 | F103: 2 | G103: 850 | H103: =F103*G103 -> 1700
E104: livraison marchandise | F104: 1 | G104: 300 | H104: =F104*G104 -> 300
E105: Heech Amel | F105: 3 | G105: 500 | H105: =F105*G105 -> 1500
E106: Heech Employées | F106: 2 | G106: 500 | H106: =F106*G106 -> 1000
E107: poivre + poivron | F107: 4 | G107: 250 | H107: =F107*G107 -> 1000
E108: tomate fraiche | F108: 1 | G108: 100 | H108: =F108*G108 -> 100
E109: plateaux oeufs | F109: 4 | G109: 450 | H109: =F109*G109 -> 1800
E110: blanc de poulet + poulet haché | F110: 6 | G110: 750 | H110: =F110*G110 -> 4500
E111: viande hachée | F111: 1 | G111: 1200 | H111: =F111*G111 -> 1200
E112: motif temina Bé bé girl | F112: 6 | G112: 150 | H112: =F112*G112 -> 900 | I112: 45724
E113: Deyoul | F113: 4 | G113: 100 | H113: =F113*G113 -> 400
...

Sheet Pointage
B1: Date | C1: Saida | D1: Fatiha | E1: Assia | F1: Samira | G1: Nour ElHouda | H1: Yasmine | I1: Zohra | J1: Rayan | K1: Amina | L1: Khalida | M1: Amina Ain Beniane | N1: Ahlem | O1: Houda Oueld Fayet | P1: Selma | Q1: Merieioma | R1: Israa | S1: Wafa
A2: Samedi | B2: 45717 | C2: 1 | D2: 1 | E2: 1 | F2: 0 | G2: 0 | H2: 1 | I2: 0 | J2: 1 | K2: 0 | L2: 1 | M2: 1 | N2: 1 | O2: 0 | P2: 0 | Q2: 0 | R2: 7.4
A3: Dimanche | B3: 45718 | C3: 1 | D3: 1 | E3: 1 | F3: 0 | G3: 0 | H3: 1 | I3: 1 | J3: 1 | K3: 0 | L3: 1 | M3: 1 | N3: 1 | O3: 0 | P3: 0 | Q3: 0 | R3: 0
A4: Lundi | B4: 45719 | C4: 1 | D4: 1 | E4: 0.75 | F4: 0 | G4: 1 | H4: 1 | I4: 0 | J4: 1 | K4: 0 | L4: 1 | M4: 1 | N4: 1 | O4: 0 | P4: 0 | Q4: 0 | R4: 0 | U4: Retard: Yasmine + Assia
A5: Mardi | B5: 45720 | C5: 1 | D5: 1 | E5: 1 | F5: 0 | G5: 1 | H5: 0 | I5: 1 | J5: 1 | K5: 0 | L5: 1 | M5: 1 | N5: 1 | O5: 0 | P5: 0 | Q5: 0 | R5: 0 | U5: Retard: Houda
A6: Mercredi | B6: 45721 | C6: 1 | D6: 1 | E6: 1 | F6: 0 | G6: 1 | H6: 1 | I6: 0 | J6: 1 | K6: 0 | L6: 1 | M6: 1 | N6: 1 | O6: 0 | P6: 0 | Q6: 0 | U6: Retard : Yasmine
A7: Jeudi | B7: 45722 | C7: 1 | D7: 1 | E7: 1 | F7: 0 | G7: 1 | H7: 1 | I7: 1 | J7: 1 | K7: 0 | L7: 1 | M7: 1 | N7: 1 | O7: 0 | P7: 0 | Q7: 0 | R7: 0
A8: Vendredi | B8: 45723 | C8: 0 | D8: 1 | E8: 1 | F8: 0 | G8: 0 | H8: 1 | I8: 0 | J8: 0 | K8: 1 | L8: 0 | M8: 1 | N8: 0 | O8: 0 | P8: 0 | Q8: 0
A9: Samedi | B9: 45724 | C9: 1 | D9: 1 | E9: 0 | F9: 0 | G9: 0 | H9: 1 | I9: 1 | J9: 0 | K9: 0 | L9: 1 | M9: 1 | N9: 1 | O9: 0 | P9: 0 | Q9: 0 | R9: 0
A10: Dimanche | B10: 45725 | C10: 1 | D10: 1 | E10: 1 | F10: 0 | G10: 0 | H10: 1 | I10: 0 | J10: 1 | K10: 0 | L10: 0.5 | M10: 1 | N10: 1 | O10: 0 | P10: 1 | Q10: 0 | U10: Rayan djate directe men Batna au boulot
A11: Lundi | B11: 45726 | C11: 1 | D11: 1 | E11: 1 | F11: 0 | G11: 0 | H11: 1 | I11: 0 | J11: 1 | K11: 0 | L11: 0 | M11: 1 | N11: 1 | O11: 1 | P11: 0 | Q11: 0 | R11: 0
A12: Mardi | B12: 45727 | C12: 1 | D12: 1 | E12: 1 | F12: 1 | G12: 1 | H12: 0 | I12: 1 | J12: 1 | K12: 0 | L12: 1 | M12: 1 | N12: 1 | O12: 0 | P12: 1 | Q12: 0 | R12: 0
A13: Mercredi | B13: 45728 | C13: 1 | D13: 1 | E13: 1 | F13: 1 | G13: 1 | H13: 1 | I13: 0 | J13: 1 | K13: 0 | L13: 1 | M13: 1 | N13: 1 | O13: 1 | P13: 0 | Q13: 1 | R13: 0
A14: Jeudi | B14: 45729 | C14: 1 | D14: 1 | E14: 1 | F14: 1 | G14: 1 | H14: 1 | I14: 1 | J14: 1 | K14: 0 | L14: 1 | M14: 1 | N14: 1 | O14: 0 | P14: 0 | Q14: 0 | R14: 0
A15: Vendredi | B15: 45730 | C15: 0 | D15: 0 | E15: 1 | F15: 1 | G15: 0 | H15: 1 | I15: 1 | J15: 1 | K15: 1 | L15: 0 | M15: 1 | N15: 0 | O15: 0 | P15: 0 | Q15: 0 | R15: 0
A16: Samedi | B16: 45731 | C16: 1 | D16: 1 | E16: 0 | F16: 1 | G16: 0 | H16: 1 | I16: 0 | J16: 1 | K16: 0 | L16: 1 | M16: 1 | N16: 1 | O16: 0 | P16: 0 | Q16: 0 | R16: 0
A17: Dimanche | B17: 45732 | C17: 1 | D17: 1 | E17: 1 | F17: 1 | G17: 0 | H17: 1 | I17: 1 | J17: 1 | K17: 0 | L17: 1 | M17: 1 | N17: 1 | O17: 0 | P17: 0 | Q17: 0 | R17: 0
A18: Lundi | B18: 45733 | C18: 1 | D18: 1 | E18: 1 | F18: 1 | G18: 1 | H18: 1 | I18: 0 | J18: 1 | K18: 0 | L18: 1 | M18: 0 | N18: 1 | O18: 0 | P18: 0 | Q18: 0 | R18: 0
A19: Mardi | B19: 45734 | C19: 1 | D19: 1 | E19: 1 | F19: 1 | G19: 1 | H19: 0 | I19: 1 | J19: 1 | K19: 0 | L19: 1 | M19: 1 | N19: 1 | O19: 1 | P19: 1 | Q19: 0 | R19: 0
A20: Mercredi | B20: 45735 | C20: 1 | D20: 1 | E20: 1 | F20: 1 | G20: 1 | H20: 0 | I20: 0 | J20: 1 | K20: 0 | L20: 0.5 | M20: 1 | N20: 1 | O20: 0 | P20: 0 | Q20: 0 | R20: 0
A21: Jeudi | B21: 45736 | C21: 1 | D21: 1 | E21: 1 | F21: 1 | G21: 1 | H21: 1 | I21: 1 | J21: 1 | K21: 0 | L21: 1 | M21: 1 | N21: 1 | O21: 0 | P21: 1 | Q21: 0 | R21: 0
A22: Vendredi | B22: 45737 | C22: 0 | D22: 1 | E22: 1 | F22: 1 | G22: 0 | H22: 1 | I22: 0 | J22: 1 | K22: 1 | L22: 1 | M22: 1 | N22: 0 | O22: 0 | P22: 0 | Q22: 1 | R22: 0
A23: Samedi | B23: 45738 | C23: 1 | D23: 1 | E23: 0 | F23: 1 | G23: 0 | H23: 1 | I23: 1 | J23: 1 | K23: 1 | L23: 1 | M23: 1 | N23: 1 | O23: 1 | P23: 1 | Q23: 1 | R23: 0 | S23: 1
A24: Dimanche | B24: 45739 | C24: 0 | D24: 1 | E24: 1 | F24: 1 | G24: 0 | H24: 1 | I24: 0 | J24: 1 | K24: 1 | L24: 1 | M24: 1 | N24: 1 | O24: 1 | P24: 0 | Q24: 0 | R24: 0 | S24: 1
A25: Lundi | B25: 45740 | C25: 1 | D25: 1 | E25: 0 | F25: 1 | G25: 1 | H25: 1 | I25: 1 | J25: 1 | K25: 1 | L25: 1 | M25: 1 | N25: 1 | O25: 0 | P25: 1 | Q25: 1 | R25: 0 | S25: 1
A26: Mardi | B26: 45741 | C26: 1 | D26: 0 | E26: 1 | F26: 1 | G26: 1 | H26: 0 | I26: 0 | J26: 1 | K26: 1 | L26: 1 | M26: 1 | N26: 1 | O26: 0 | P26: 0 | Q26: 1 | R26: 0 | S26: 1
A27: Mercredi | B27: 45742 | C27: 1 | D27: 1 | E27: 1 | F27: 1 | G27: 1 | H27: 1 | I27: 0 | J27: 1 | K27: 1 | L27: 1 | M27: 2 | N27: 1 | O27: 0 | P27: 1 | Q27: 1 | R27: 0 | S27: 1
A28: Jeudi | B28: 45743 | C28: 1 | D28: 1 | E28: 1 | F28: 0 | G28: 2 | H28: 1 | I28: 0 | J28: 0.5 | K28: 1 | L28: 1 | M28: 1 | N28: 1 | O28: 1 | P28: 0 | Q28: 1 | R28: 0 | S28: 0 | U28: Houda + Douaa
A29: Vendredi | B29: 45744 | C29: 0 | D29: 1 | E29: 1 | F29: 0 | G29: 4 | H29: 1 | I29: 1 | J29: 0 | K29: 1 | L29: 1 | M29: 1 | N29: 0 | O29: 0 | P29: 1 | Q29: 1 | R29: 0 | S29: 0 | U29: Houda et Douaa double journée
A30: Samedi | B30: 45745 | C30: 1 | D30: 1 | E30: 1 | F30: 0 | G30: 0 | H30: 1 | I30: 0 | J30: 0 | K30: 0 | L30: 1 | M30: 1 | N30: 1 | O30: 0 | P30: 1 | Q30: 0 | R30: 0 | S30: 0
A31: Dimanche | B31: 45746 | C31: 0 | D31: 1 | E31: 1 | F31: 0 | G31: 0 | H31: 1 | I31: 1 | J31: 0 | K31: 0 | L31: 0 | M31: 0 | N31: 1 | O31: 0 | P31: 0 | Q31: 0
A32: Lundi | B32: 45747 | C32: 0 | D32: 0 | E32: 0 | F32: 0 | G32: 0 | H32: 0 | I32: 0 | J32: 0 | K32: 0 | L32: 1 | M32: 0 | N32: 0 | O32: 0 | P32: 0 | Q32: 0 | R32: 0 | S32: 0 | T32: 0
B33: Heures suplimentaires | D33: 3 | E33: 1 | F33: 0 | G33: 0 | H33: 0 | J33: 2 | K33: 0 | L33: 6 | M33: 4.5 | N33: 0 | O33: 1 | P33: 3
C34: =SUM(C2:C33) -> 24 | D34: =SUM(D2:D33) -> 31 | E34: =SUM(E2:E33) -> 26.75 | F34: =SUM(F2:F33) -> 16 | G34: =SUM(G2:G33) -> 20 | H34: =SUM(H2:H33) -> 25 | I34: =SUM(I2:I33) -> 14 | J34: =SUM(J2:J33) -> 26.5 | ... T34: =SUM(T2:T33) -> 0
C35: 1290 | D35: 1155 | E35: 1155 | F35: 1155 | G35: 1111 | H35: 1155 | I35: 1155 | J35: 1296.29 | K35: 1200 | L35: 1300 | M35: 1300 | N35: 1155 | O35: 1000 | P35: 1200 | Q35: 1200 | R35: 1000 | S35: 1000 | T35: 1000
C36: =C34*C35 -> 30960 | D36: =D34*D35 -> 35805 | E36: =E34*E35 -> 30896.25 | F36: =F34*F35 -> 18480 | G36: =G34*G35 -> 22220 | H36: =H34*H35 -> 28875 | I36: =I34*I35 -> 16170 | J36: =J34*J35 -> 34351.685 | ... T36: =T34*T35 -> 0
B51: Date | C51: Rayan
A52: Samedi | B52: 45717 | C52: 1
A53: Dimanche | B53: 45718 | C53: 1
A54: Lundi | B54: 45719 | C54: 1
...

Sheet Les Salaires
J5: Nom | K5: Salaire | L5: Avance | M5: Salaire à payer
J6: Sofiane | K6: 30000 | L6: 30000 | M6: =K6-L6 -> 0
J7: Amel | K7: 30000 | L7: 30000 | M7: =K7-L7 -> 0
I8: 1 | J8: Saida | K8: =Pointage!C36 -> 30960 | L8: 31000 | M8: =K8-L8 -> -40 | N8: 20000+11000
I9: 2 | J9: Fatiha | K9: =Pointage!D36 -> 35805 | L9: 36000 | M9: =K9-L9 -> -195 | N9: 500+15000+2000
I10: 3 | J10: Assia | K10: =Pointage!E36 -> 30896.25 | L10: 31000 | M10: =K10-L10 -> -103.75 | N10: 1000+5000+25000
I11: 4 | J11: Samira | K11: =Pointage!F36 -> 18480 | L11: 18500 | M11: =K11-L11 -> -20 | N11: 1000+1000+10000+6500
I12: 5 | J12: Nour ElHouda | K12: =Pointage!G36 -> 22220 | M12: =K12-L12 -> 22220
I13: 6 | J13: Yasmine | K13: =Pointage!H36+N13 -> 33875 | L13: 34000 | M13: =K13-L13 -> -125 | N13: 5000
I14: 7 | J14: Zohra | K14: =Pointage!I36 -> 16170 | L14: 16500 | M14: =K14-L14 -> -330
I15: 8 | J15: Rayan | K15: =Pointage!J36 -> 34351.685 | L15: 34500 | M15: =K15-L15 -> -148.315 | N15: 6000+28000
H16: 5000 | I16: 9 | J16: Amina | K16: =Pointage!K36 -> 12000 | L16: 12000 | M16: =K16-L16 -> 0 | N16: 5000+12000
I17: 10 | J17: Khalida | K17: =Pointage!L36 -> 41600 | L17: 42000 | M17: =K17-L17 -> -400 | O17: 45000
I18: 11 | J18: Amina Ain Beniane | K18: =Pointage!M36 -> 43550 | L18: 44000 | M18: =K18-L18 -> -450 | O18: 45000
I19: 12 | J19: Ahlem | K19: 30000 | L19: 30000 | M19: =K19-L19 -> 0
I20: 13 | J20: Houda Ouled Fayet | K20: =Pointage!O36 -> 7000 | M20: =K20-L20 -> 7000
I21: 14 | J21: Selma | K21: =Pointage!P36 -> 14400 | L21: 15000 | M21: =K21-L21 -> -600
I22: 15 | J22: wafa | K22: =Pointage!S36 -> 5000 | L22: 5000 | M22: =K22-L22 -> 0
I23: 16 | J23: Israa | K23: =Pointage!R36 -> 7400 | L23: 7500 | M23: =K23-L23 -> -100
J24: TOTAL | K24: =SUM(K6:K23) -> 443707.93 | L24: =SUM(L6:L23) -> 417000 | M24: =K24-L24 -> 26707.935
M25: =K25-L25 -> 0

Sheet Feuille 5
H16: Mois de Janvier 2025 | I16: Mois de Février 2025 | J16: Mois de Mars 2025
G17: Recette | H17: 2033000 | I17: 1859000 | J17: =RECAP!D33 -> 2094000
G18: Charges | H18: 854000 | I18: 884000 | J18: 962000
G19: Salaires | H19: 427000 | I19: 409000 | J19: 439000
G20: Che7i7a | H20: 62000 | I20: 56000 | J20: =RECAP!G33 -> 60000 | K20: =J20+I20+H20 -> 178000
G21: Loyer+Dettes | H21: 180000 | I21: 180000 | J21: 180000
G22: Profit Net | H22: =H17-H18-H19-H20-H21 -> 510000 | I22: =I17-I18-I19-I20-I21 -> 330000 | J22: =J17-J18-J19-J20-J21 -> 453000

Sheet Feuille 6
B7: Date | C7: Saida | D7: Fatiha | E7: Assia | F7: Samira | G7: Nour ElHouda | H7: Yasmine | I7: Zohra | J7: Rayan | K7: Amina | L7: Khalida | M7: Amina Ain Beniane | N7: Ahlem | O7: Houda Oueld Fayet | P7: Selma | Q7: Merieioma | R7: Israa | S7: Wafa
A8: Samedi | B8: 45717 | C8: 1 | D8: 1 | E8: 1 | F8: 0 | G8: 0 | H8: 1 | I8: 0 | J8: 1 | K8: 0 | L8: 1 | M8: 1 | N8: 1 | O8: 0 | P8: 0 | Q8: 0 | R8: 7.4
A9: Dimanche | B9: 45718 | C9: 1 | D9: 1 | E9: 1 | F9: 0 | G9: 0 | H9: 1 | I9: 1 | J9: 1 | K9: 0 | L9: 1 | M9: 1 | N9: 1 | O9: 0 | P9: 0 | Q9: 0 | R9: 0
A10: Lundi | B10: 45719 | C10: 1 | D10: 1 | E10: 0.75 | F10: 0 | G10: 1 | H10: 1 | I10: 0 | J10: 1 | K10: 0 | L10: 1 | M10: 1 | N10: 1 | O10: 0 | P10: 0 | Q10: 0 | R10: 0 | U10: Retard: Yasmine + Assia
A11: Mardi | B11: 45720 | C11: 1 | D11: 1 | E11: 1 | F11: 0 | G11: 1 | H11: 0 | I11: 1 | J11: 1 | K11: 0 | L11: 1 | M11: 1 | N11: 1 | O11: 0 | P11: 0 | Q11: 0 | R11: 0 | U11: Retard: Houda
A12: Mercredi | B12: 45721 | C12: 1 | D12: 1 | E12: 1 | F12: 0 | G12: 1 | H12: 1 | I12: 0 | J12: 1 | K12: 0 | L12: 1 | M12: 1 | N12: 1 | O12: 0 | P12: 0 | Q12: 0 | U12: Retard : Yasmine
A13: Jeudi | B13: 45722 | C13: 1 | D13: 1 | E13: 1 | F13: 0 | G13: 1 | H13: 1 | I13: 1 | J13: 1 | K13: 0 | L13: 1 | M13: 1 | N13: 1 | O13: 0 | P13: 0 | Q13: 0 | R13: 0
A14: Vendredi | B14: 45723 | C14: 0 | D14: 1 | E14: 1 | F14: 0 | G14: 0 | H14: 1 | I14: 0 | J14: 0 | K14: 1 | L14: 0 | M14: 1 | N14: 0 | O14: 0 | P14: 0 | Q14: 0
A15: Samedi | B15: 45724 | C15: 1 | D15: 1 | E15: 0 | F15: 0 | G15: 0 | H15: 1 | I15: 1 | J15: 0 | K15: 0 | L15: 1 | M15: 1 | N15: 1 | O15: 0 | P15: 0 | Q15: 0 | R15: 0
A16: Dimanche | B16: 45725 | C16: 1 | D16: 1 | E16: 1 | F16: 0 | G16: 0 | H16: 1 | I16: 0 | J16: 1 | K16: 0 | L16: 0.5 | M16: 1 | N16: 1 | O16: 0 | P16: 1 | Q16: 0 | U16: Rayan djate directe men Batna au boulot
A17: Lundi | B17: 45726 | C17: 1 | D17: 1 | E17: 1 | F17: 0 | G17: 0 | H17: 1 | I17: 0 | J17: 1 | K17: 0 | L17: 0 | M17: 1 | N17: 1 | O17: 1 | P17: 0 | Q17: 0 | R17: 0
A18: Mardi | B18: 45727 | C18: 1 | D18: 1 | E18: 1 | F18: 1 | G18: 1 | H18: 0 | I18: 1 | J18: 1 | K18: 0 | L18: 1 | M18: 1 | N18: 1 | O18: 0 | P18: 1 | Q18: 0 | R18: 0
A19: Mercredi | B19: 45728 | C19: 1 | D19: 1 | E19: 1 | F19: 1 | G19: 1 | H19: 1 | I19: 0 | J19: 1 | K19: 0 | L19: 1 | M19: 1 | N19: 1 | O19: 1 | P19: 0 | Q19: 1 | R19: 0
A20: Jeudi | B20: 45729 | C20: 1 | D20: 1 | E20: 1 | F20: 1 | G20: 1 | H20: 1 | I20: 1 | J20: 1 | K20: 0 | L20: 1 | M20: 1 | N20: 1 | O20: 0 | P20: 0 | Q20: 0 | R20: 0
A21: Vendredi | B21: 45730 | C21: 0 | D21: 0 | E21: 1 | F21: 1 | G21: 0 | H21: 1 | I21: 1 | J21: 1 | K21: 1 | L21: 0 | M21: 1 | N21: 0 | O21: 0 | P21: 0 | Q21: 0 | R21: 0
A22: Samedi | B22: 45731 | C22: 1 | D22: 1 | E22: 0 | F22: 1 | G22: 0 | H22: 1 | I22: 0 | J22: 1 | K22: 0 | L22: 1 | M22: 1 | N22: 1 | O22: 0 | P22: 0 | Q22: 0 | R22: 0
A23: Dimanche | B23: 45732 | C23: 1 | D23: 1 | E23: 1 | F23: 1 | G23: 0 | H23: 1 | I23: 1 | J23: 1 | K23: 0 | L23: 1 | M23: 1 | N23: 1 | O23: 0 | P23: 0 | Q23: 0 | R23: 0
A24: Lundi | B24: 45733 | C24: 1 | D24: 1 | E24: 1 | F24: 1 | G24: 1 | H24: 1 | I24: 0 | J24: 1 | K24: 0 | L24: 1 | M24: 0 | N24: 1 | O24: 0 | P24: 0 | Q24: 0 | R24: 0
A25: Mardi | B25: 45734 | C25: 1 | D25: 1 | E25: 1 | F25: 1 | G25: 1 | H25: 0 | I25: 1 | J25: 1 | K25: 0 | L25: 1 | M25: 1 | N25: 1 | O25: 1 | P25: 1 | Q25: 0 | R25: 0
A26: Mercredi | B26: 45735 | C26: 1 | D26: 1 | E26: 1 | F26: 1 | G26: 1 | H26: 0 | I26: 0 | J26: 1 | K26: 0 | L26: 0.5 | M26: 1 | N26: 1 | O26: 0 | P26: 0 | Q26: 0 | R26: 0
A27: Jeudi | B27: 45736 | C27: 1 | D27: 1 | E27: 1 | F27: 1 | G27: 1 | H27: 1 | I27: 1 | J27: 1 | K27: 0 | L27: 1 | M27: 1 | N27: 1 | O27: 0 | P27: 1 | Q27: 0 | R27: 0
A28: Vendredi | B28: 45737 | C28: 0 | D28: 1 | E28: 1 | F28: 1 | G28: 0 | H28: 1 | I28: 0 | J28: 1 | K28: 1 | L28: 1 | M28: 1 | N28: 0 | O28: 0 | P28: 0 | Q28: 1 | R28: 0
A29: Samedi | B29: 45738 | C29: 1 | D29: 1 | E29: 0 | F29: 1 | G29: 0 | H29: 1 | I29: 1 | J29: 1 | K29: 1 | L29: 1 | M29: 1 | N29: 1 | O29: 1 | P29: 1 | Q29: 1 | R29: 0 | S29: 1
A30: Dimanche | B30: 45739 | C30: 0 | D30: 1 | E30: 1 | F30: 1 | G30: 0 | H30: 1 | I30: 0 | J30: 1 | K30: 1 | L30: 1 | M30: 1 | N30: 1 | O30: 1 | P30: 0 | Q30: 0 | R30: 0 | S30: 1
A31: Lundi | B31: 45740 | C31: 1 | D31: 1 | E31: 0 | F31: 1 | G31: 1 | H31: 1 | I31: 1 | J31: 1 | K31: 1 | L31: 1 | M31: 1 | N31: 1 | O31: 0 | P31: 1 | Q31: 1 | R31: 0 | S31: 1
A32: Mardi | B32: 45741 | C32: 1 | D32: 0 | E32: 1 | F32: 1 | G32: 1 | H32: 0 | I32: 0 | J32: 1 | K32: 1 | L32: 1 | M32: 1 | N32: 1 | O32: 0 | P32: 0 | Q32: 1 | R32: 0 | S32: 1
A33: Mercredi | B33: 45742 | C33: 1 | D33: 1 | E33: 1 | F33: 1 | G33: 1 | H33: 1 | I33: 0 | J33: 1 | K33: 1 | L33: 1 | M33: 2 | N33: 1 | O33: 0 | P33: 1 | Q33: 1 | R33: 0 | S33: 1
A34: Jeudi | B34: 45743 | C34: 1 | D34: 1 | E34: 1 | F34: 0 | G34: 2 | H34: 1 | I34: 0 | J34: 0.5 | K34: 1 | L34: 1 | M34: 1 | N34: 1 | O34: 1 | P34: 0 | Q34: 1 | R34: 0 | S34: 0 | U34: Houda + Douaa
A35: Vendredi | B35: 45744 | C35: 0 | D35: 1 | E35: 1 | F35: 0 | G35: 4 | H35: 1 | I35: 1 | J35: 0 | K35: 1 | L35: 1 | M35: 1 | N35: 0 | O35: 0 | P35: 1 | Q35: 1 | R35: 0 | S35: 0 | U35: Houda et Douaa double journée
A36: Samedi | B36: 45745 | C36: 1 | D36: 1 | E36: 1 | F36: 0 | G36: 0 | H36: 1 | I36: 0 | J36: 0 | K36: 0 | L36: 1 | M36: 1 | N36: 1 | O36: 0 | P36: 1 | Q36: 0 | R36: 0 | S36: 0
A37: Dimanche | B37: 45746 | C37: 0 | D37: 1 | E37: 1 | F37: 0 | G37: 0 | H37: 1 | I37: 1 | J37: 0 | K37: 0 | L37: 0 | M37: 0 | N37: 1 | O37: 0 | P37: 0 | Q37: 0
A38: Lundi | B38: 45747 | C38: 0 | D38: 0 | E38: 0 | F38: 0 | G38: 0 | H38: 0 | I38: 0 | J38: 0 | K38: 0 | L38: 1 | M38: 0 | N38: 0 | O38: 0 | P38: 0 | Q38: 0 | R38: 0 | S38: 0 | T38: 0
B39: Heures suplimentaires | D39: 3 | E39: 1 | F39: 0 | G39: 0 | H39: 0 | J39: 2 | K39: 0 | L39: 6 | M39: 4.5 | N39: 0 | O39: 1 | P39: 3
C40: =SUM(C8:C39) -> 24 | D40: =SUM(D8:D39) -> 31 | E40: =SUM(E8:E39) -> 26.75 | F40: =SUM(F8:F39) -> 16 | G40: =SUM(G8:G39) -> 20 | H40: =SUM(H8:H39) -> 25 | I40: =SUM(I8:I39) -> 14 | J40: =SUM(J8:J39) -> 26.5 | ... T40: =SUM(T8:T39) -> 0
C41: 1290 | D41: 1111 | E41: 1111 | F41: 1111 | G41: 1111 | H41: 1111 | I41: 1111 | J41: 1296.29 | K41: 1200 | L41: 1300 | M41: 1300 | N41: 1111 | O41: 1000 | P41: 1200 | Q41: 1200 | R41: 1000 | S41: 1000 | T41: 1000
C42: =C40*C41 -> 30960 | D42: =D40*D41 -> 34441 | E42: =E40*E41 -> 29719.25 | F42: =F40*F41 -> 17776 | G42: =G40*G41 -> 22220 | H42: =H40*H41 -> 27775 | I42: =I40*I41 -> 15554 | J42: =J40*J41 -> 34351.685 | ... T42: =T40*T41 -> 0
D45: 35800 | E45: 30896 | F45: 18480 | G45: 23100 | H45: 28875 | I45: 16170 | N45: 30000
D48: =D45-D42 -> 1359 | E48: =E45-E42 -> 1176.75 | F48: =F45-F42 -> 704 | G48: =G45-G42 -> 880 | H48: =H45-H42 -> 1100 | I48: =I45-I42 -> 616 | N48: =N45-N42 -> 1114 | O48: =SUM(D48:N48) -> 6949.75
