Workbook

Sheet RECAP
B1: Date | C1: Recette Septembre 2023 | D1: Recette | E1: Charges | F1: Salaire | G1: Loyer | H1: Net Profit | I1: Nb de jours | K1: Objectif | L1: 45200
A2: Mercredi | B2: 45231 | C2: 34000 | D2: 48000 | I2: 1 | L2: 34000
A3: Jeudi | B3: 45232 | C3: 44000 | D3: 36000 | I3: 1 | L3: 44000 | M3: Bénéfice Moyen par jour | N3: Moyenne | O3: Moyenne salaire | P3: pourcentage du salaire vis à vis la recettte
A4: Vendredi | B4: 45233 | C4: 40000 | D4: 48000 | I4: 1 | L4: 40000 | M4: =H35/I35 -> #DIV/0! | N4: =D35/I35 -> #DIV/0! | P4: =O4/N4 -> #DIV/0!
A5: Samedi | B5: 45234 | C5: 50000 | D5: 25000 | I5: 1 | L5: 50000
A6: Dimanche | B6: 45235 | C6: 35000 | D6: 34000 | I6: 1 | L6: 35000 | M6: Moyenne des charges par jour | N6: Objectif
A7: Lundi | B7: 45236 | C7: 35000 | D7: 25000 | I7: 1 | L7: 35000 | M7: =E35/I35 -> #DIV/0! | N7: 100000
A8: Mardi | B8: 45237 | C8: 56000 | D8: 31000 | I8: 1 | L8: 56000 | M8: ²
A9: Mercredi | B9: 45238 | C9: 36000 | D9: 37000 | I9: 1 | L9: 36000
A10: Jeudi | B10: 45239 | C10: 34000 | D10: 40000 | I10: 1 | L10: 34000 | M10: Cash restant | N10: Magasin
A11: Vendredi | B11: 45240 | C11: 38000 | D11: 44000 | I11: 1 | L11: 38000 | M11: =O17+D33-O11-O18-O19-'Salaires '!K22-'Les charges '!H308-O16 -> 528270 | N11: =O11*1 -> 70000 | O11: 70000
A12: Samedi | B12: 45241 | C12: 45000 | D12: 37000 | I12: 1 | L12: 45000
A13: Dimanche | B13: 45242 | C13: 62000 | D13: 32000 | I13: 1 | L13: 62000 | M13: loyer
A14: Lundi | B14: 45243 | C14: 51000 | D14: 37000 | I14: 1 | L14: 51000 | O14: La caisse : 44000 | P14: 25000
A15: Mardi | B15: 45244 | C15: 32000 | D15: 37000 | I15: 1 | L15: 32000 | N15: Sofiane | O15: 32000+ 26000+12000 | P15: 70000-40000
A16: Mercredi | B16: 45245 | C16: 20000 | D16: 42000 | I16: 1 | L16: 20000 | N16: Sofiane complément | O16: 40000 | S16: recette | T16: =D33 -> 1254000
A17: Jeudi | B17: 45246 | C17: 37000 | D17: 59000 | I17: 1 | L17: 37000 | N17: Bénéfice Octobre+ loyer | O17: 320000 | S17: charges | T17: =E33 -> 508730
A18: Vendredi | B18: 45247 | C18: 32000 | D18: 58000 | I18: 1 | L18: 32000 | N18: Bloc moteur | O18: 50000 | S18: avances salaires | T18: ='Salaires '!K22 -> 307000
A19: Samedi | B19: 45248 | C19: 40000 | D19: 25000 | I19: 1 | L19: 40000 | M19: Différence mois de Juin | N19: fenetres | O19: 70000 | S19: la caisse | T19: 44000
A20: Dimanche | B20: 45249 | C20: 60000 | D20: 38000 | I20: 1 | L20: 60000 | M20: =D35-C35 -> 0 | N20: VMR Maghreb | O20: 9000+13000+11000 | S20: chèque | T20: 34000
A21: Lundi | B21: 45250 | C21: 36000 | D21: 16000 | I21: 1 | L21: 36000 | M21: Différence objectif | S21: cache qui doit etre rester | T21: =T16-T17-T18-T19-T20 -> 360270
A22: Mardi | B22: 45251 | C22: 60000 | D22: 50000 | I22: 1 | L22: 60000 | M22: =K36-E36 -> 0 | S22: cache réel | T22: 152000
A23: Mercredi | B23: 45252 | C23: 36000 | D23: 90000 | I23: 1 | L23: 36000 | M23: Différence du Totale | S23: mes dettes pour le magasin | T23: =T21-T22 -> 208270
A24: Jeudi | B24: 45253 | C24: 35000 | D24: 79000 | I24: 1 | L24: 35000 | M24: =D35-L35 -> 0
A25: Vendredi | B25: 45254 | C25: 27000 | D25: 33000 | I25: 1 | L25: 27000 | M25: Les vendredis
A26: Samedi | B26: 45255 | C26: 57000 | D26: 47000 | I26: 1 | L26: 57000 | M26: =E6+E13+E20+E27 -> 0
A27: Dimanche | B27: 45256 | C27: 62000 | D27: 35000 | I27: 1 | L27: 62000
A28: Lundi | B28: 45257 | C28: 43000 | D28: 36000 | I28: 1 | L28: 43000 | M28: Cash réel
A29: Mardi | B29: 45258 | C29: 34000 | D29: 35000 | I29: 1 | L29: 34000 | M29: 51000
A30: Mercredi | B30: 45259 | C30: 30000 | D30: 43000 | I30: 1 | L30: 30000 | M30: rest à payer
A31: Jeudi | B31: 45260 | C31: 15000 | D31: 57000 | I31: 1 | L31: 15000
C32: 48000 | D32: 0 | L32: 48000
C33: =SUM(C2:C32) -> 1264000 | D33: =SUM(D2:D32) -> 1254000 | E33: ='Les charges '!H308*1 -> 508730 | F33: ='Salaires '!J22*1 -> 304541.5 | G33: 110000 | H33: =D33-E33-F33-G33 -> 330728.5 | I33: =SUM(I2:I32) -> 30 | L33: =SUM(L2:L32) -> 1264000
M35: =M11-M29-M34 -> 477270
D38: -

Sheet Pointage
B1: Date | C1: Lynda | D1: Hafida | E1: Djamila | F1: Youssera | G1: Yasmine vendeuse | H1: Kenza | I1: Yasmine | J1: Amina | K1: Chaherazed | L1: Nadjet | M1: Samia | N1: Alia | O1: Samira | P1: NadiaFemme de ménage | Q1: Nadia | R1: Remarque
A2: Mercredi | B2: 45231 | C2: 1 | D2: 0 | E2: 0 | F2: 1 | G2: 1 | H2: 1 | I2: 1 | J2: 0 | K2: 1 | L2: 0 | M2: 1.5 | N2: 0 | O2: 1 | P2: 0 | Q2: 0
A3: Jeudi | B3: 45232 | C3: 2 | D3: 0 | E3: 0 | F3: 0 | G3: 1 | H3: 1 | I3: 1 | J3: 0 | K3: 1 | L3: 0.5 | M3: 1.5 | N3: 0 | O3: 1 | P3: 0 | Q3: 0
A4: Vendredi | B4: 45233 | C4: 2 | D4: 0 | E4: 0 | F4: 0 | G4: 1 | H4: 1.5 | I4: 1.5 | J4: 0 | K4: 0 | L4: 1 | M4: 0 | N4: 0 | O4: 0 | P4: 0 | Q4: 0
A5: Samedi | B5: 45234 | C5: 2 | D5: 0 | E5: 0 | F5: 1 | G5: 1 | H5: 0 | I5: 0 | J5: 0 | K5: 0 | L5: 0 | M5: 1.5 | N5: 0 | O5: 1 | P5: 1 | Q5: 0
A6: Dimanche | B6: 45235 | C6: 0 | D6: 1 | E6: 0 | F6: 0.25 | G6: 1 | H6: 0 | I6: 0 | J6: 0 | K6: 0 | L6: 1 | M6: 1 | N6: 0 | O6: 0 | P6: 1 | Q6: 0
A7: Lundi | B7: 45236 | C7: 0 | D7: 1 | E7: 0 | F7: 1 | G7: 0 | H7: 1 | I7: 0 | J7: 0 | K7: 0 | L7: 1 | M7: 1 | N7: 0 | O7: 0 | P7: 1 | Q7: 0
A8: Mardi | B8: 45237 | C8: 0 | D8: 1 | E8: 0 | F8: 0.5 | G8: 1 | H8: 0 | I8: 0 | J8: 0 | K8: 0 | L8: 1 | M8: 1 | N8: 0 | O8: 0 | P8: 1 | Q8: 0
A9: Mercredi | B9: 45238 | C9: 0.5 | D9: 1 | E9: 0 | F9: 0 | G9: 1 | H9: 0 | I9: 0 | K9: 0 | L9: 1 | M9: 1 | N9: 0 | O9: 0 | P9: 1 | Q9: 0
A10: Jeudi | B10: 45239 | C10: 0.5 | D10: 1 | E10: 0 | F10: 0 | G10: 1 | H10: 0 | I10: 0 | J10: 0.75 | K10: 0 | L10: 1 | M10: 1 | N10: 0 | O10: 0 | P10: 1 | Q10: 0
A11: Vendredi | B11: 45240 | C11: 1 | D11: 0 | E11: 0 | F11: 0 | G11: 1 | H11: 1 | I11: 1 | J11: 0 | K11: 0 | L11: 1 | M11: 0 | N11: 0 | O11: 0 | P11: 0 | Q11: 0
A12: Samedi | B12: 45241 | C12: 1 | D12: 0 | E12: 0 | F12: 1 | G12: 1 | H12: 0 | I12: 0 | J12: 1 | K12: 0 | L12: 1.5 | M12: 0 | N12: 0 | O12: 0 | P12: 1 | Q12: 0
A13: Dimanche | B13: 45242 | C13: 0 | D13: 1 | E13: 0 | F13: 0.5 | G13: 1 | H13: 0 | I13: 0 | J13: 1 | K13: 0 | L13: 0 | M13: 0 | N13: 0 | O13: 0 | P13: 1 | Q13: 1
A14: Lundi | B14: 45243 | C14: 0 | D14: 1 | E14: 0 | F14: 1 | G14: 0 | H14: 1 | I14: 1 | J14: 1 | K14: 0 | L14: 1 | M14: 1 | N14: 0 | O14: 0 | P14: 1 | Q14: 1
A15: Mardi | B15: 45244 | C15: 0 | D15: 1 | E15: 0 | F15: 0.5 | G15: 1 | H15: 0 | I15: 0 | J15: 1 | K15: 0 | L15: 1 | M15: 1 | N15: 0 | O15: 0 | P15: 1 | Q15: 1
A16: Mercredi | B16: 45245 | C16: 0.5 | D16: 1 | E16: 0 | F16: 1 | G16: 1 | H16: 0 | I16: 0 | J16: 0 | K16: 0 | L16: 0 | M16: 1 | N16: 0 | O16: 0 | P16: 1 | Q16: 1
A17: Jeudi | B17: 45246 | C17: 2 | D17: 1 | E17: 0 | F17: 0 | G17: 1 | H17: 0 | I17: 0 | J17: 1 | K17: 0 | L17: 0 | M17: 1 | N17: 0 | O17: 0 | P17: 1 | Q17: 1
A18: Vendredi | B18: 45247 | C18: 1.5 | D18: 0 | E18: 0 | F18: 0 | G18: 1 | H18: 1 | I18: 1 | J18: 1 | K18: 0 | L18: 0 | M18: 0 | N18: 0 | O18: 0 | P18: 0 | Q18: 0
A19: Samedi | B19: 45248 | C19: 1 | D19: 0 | E19: 0 | F19: 0 | G19: 1 | H19: 0 | I19: 0 | J19: 0 | K19: 0 | L19: 0 | M19: 0 | N19: 0 | O19: 0 | P19: 1 | Q19: 1
A20: Dimanche | B20: 45249 | C20: 0.5 | D20: 1 | E20: 0 | F20: 1 | G20: 1 | H20: 1 | I20: 0 | J20: 0 | K20: 0 | L20: 0 | M20: 1 | N20: 0 | O20: 0 | P20: 1 | Q20: 1
A21: Lundi | B21: 45250 | C21: 0 | D21: 1 | E21: 1 | F21: 0.5 | G21: 0 | H21: 0 | I21: 1 | J21: 0 | K21: 0 | L21: 0 | M21: 0 | N21: 1 | O21: 0 | P21: 1 | Q21: 1
... A23: Mercredi | B23: 45252 | C23: 1 | D23: 1 | E23: 1 | F23: 1 | G23: 1 | H23: 0 | I23: 0 | J23: 0 | K23: 0 | L23: 0 | M23: 1 | N23: 1 | O23: 0 | P23: 1 | Q23: 1
A24: Jeudi | B24: 45253 | C24: 0 | D24: 1 | E24: 1 | F24: 0 | G24: 1 | H24: 0 | I24: 0 | J24: 0 | K24: 0 | L24: 0 | M24: 0 | N24: 0 | O24: 0 | P24: 1 | Q24: 1 | R24: Hafida djate à 09h30 et djamila à 09h
A25: Vendredi | B25: 45254 | C25: 1 | D25: 0 | E25: 0 | F25: 0 | G25: 1 | H25: 0 | I25: 1 | J25: 0 | K25: 0 | L25: 0 | M25: 0 | N25: 1 | O25: 0 | P25: 0 | Q25: 0
A26: Samedi | B26: 45255 | C26: 1 | D26: 0 | E26: 0 | F26: 1 | G26: 1 | H26: 0 | I26: 0 | J26: 0 | K26: 0 | L26: 0 | M26: 1 | N26: 1 | O26: 0 | P26: 1 | Q26: 1
A27: Dimanche | B27: 45256 | C27: 0 | D27: 1 | E27: 1 | F27: 1 | G27: 1 | H27: 1 | I27: 0 | J27: 0 | K27: 0 | L27: 0 | M27: 1 | N27: 0 | O27: 0 | P27: 1 | Q27: 1
A28: Lundi | B28: 45257 | C28: 0.5 | D28: 1 | E28: 1 | F28: 1 | G28: 0 | H28: 0 | I28: 1 | J28: 0 | K28: 0 | L28: 0 | M28: 1 | N28: 1 | O28: 0 | P28: 1 | Q28: 1
A29: Mardi | B29: 45258 | C29: 0 | D29: 1 | E29: 0 | F29: 0 | G29: 1 | H29: 0 | I29: 0 | J29: 0 | K29: 0 | L29: 0 | M29: 1 | N29: 0 | O29: 0 | P29: 1 | Q29: 1
A30: Mercredi | B30: 45259 | C30: 0 | D30: 1 | E30: 1 | F30: 1 | G30: 1 | H30: 0 | I30: 0 | J30: 0 | K30: 0 | L30: 0 | M30: 1 | N30: 0 | O30: 0 | P30: 1 | Q30: 1
A31: Jeudi | B31: 45260 | C31: 0 | D31: 1 | E31: 1 | F31: 0 | G31: 1 | H31: 0 | I31: 1 | J31: 0 | K31: 0 | L31: 0 | M31: 1 | N31: 1 | O31: 0 | P31: 1 | Q31: 1
C32: =SUM(C2:C31) -> 19 | D32: =SUM(D2:D31) -> 20 | E32: =SUM(E2:E31) -> 8 | F32: =SUM(F2:F31) -> 14.75 | G32: =SUM(G2:G31) -> 26 | H32: =SUM(H2:H31) -> 9.5 | I32: =SUM(I2:I31) -> 10.5 | J32: =SUM(J2:J31) -> 6.75 | ... Q32: =SUM(Q2:Q31) -> 17
C33: 1300 | D33: 1400 | E33: 1270 | F33: 1270 | G33: 1154 | H33: 1154 | I33: 1154 | J33: 1500 | K33: 1000 | L33: 1400 | M33: 1270 | N33: 1200 | O33: 1080 | P33: 1100 | Q33: 1000
C34: =C32*C33 -> 24700 | D34: =D33*D32 -> 28000 | E34: =E33*E32 -> 10160 | F34: =F33*F32 -> 18732.5 | G34: =G33*G32 -> 30004 | H34: =H33*H32 -> 10963 | I34: =I33*I32 -> 12117 | J34: =J33*J32 -> 10125 | K34: =K32*K33 -> 2000 | L34: =L32*L33 -> 15400 | M34: =M32*M33 -> 28575 | N34: =N32*N33 -> 7200 | O34: =O33*O32 -> 3240 | P34: =P33*P32 -> 26400 | Q34: =Q32*Q33 -> 17000 | R34: =SUM(D34:I34) -> 109976.5
B35: Les salaires | C35: 33000 | D35: 36000 | E35: 33000 | F35: 33000 | G35: 30000 | H35: 28000 | I35: 28000 | J35: 40000 | K35: 26000 | L35: 36000 | M35: 33000 | O35: 28000 | P35: 28000 | Q35: 26000
D36: 31000

Sheet Les charges 
E3: Produit | F3: Quantité | G3: Prix unitaire | H3: Prix | I3: Date d'achat
E4: légumes | F4: 1 | G4: 250 | H4: =F4*G4 -> 250
E5: les épices | F5: 3 | G5: 200 | H5: =F5*G5 -> 600
E6: Nakkache | F6: 335 | G6: 60 | H6: =F6*G6 -> 20100
E7: Maa zehar | F7: 12 | G7: 75 | H7: =F7*G7 -> 900
E8: Farine SIM 1kg | F8: 27 | G8: 90 | H8: =F8*G8 -> 2430
E9: semoule moula moyenne 2kg | F9: 24 | G9: 260 | H9: =F9*G9 -> 6240
E10: djedjelan | F10: 1 | G10: 650 | H10: =F10*G10 -> 650
E11: 3akeri | F11: 2 | G11: 1100 | H11: =F11*G11 -> 2200
E12: sucre glace 1kg | F12: 16 | G12: 115 | H12: =F12*G12 -> 1840
E13: fromage slices | F13: 14 | G13: 200 | H13: =F13*G13 -> 2800
E14: cheddar+ gouda | F14: 4.3 | G14: 1800 | H14: =F14*G14 -> 7740
E15: Thon | F15: 8 | G15: 1880 | H15: =F15*G15 -> 15040
... E51: semoule Fine Agrodive 25kg | F51: 5 | G51: 1000 | H51: =F51*G51 -> 5000
E52: tomate conserve | F52: 17 | G52: 280 | H52: =G52*F52 -> 4760
E53: Harrissa | F53: 18 | G53: 240 | H53: =G53*F53 -> 4320
E54: semen 1,8kg | F54: 10 | G54: 830 | H54: =G54*F54 -> 8300
E55: Lait en poudre | F55: 11 | G55: 540 | H55: =G55*F55 -> 5940
E56: levure boulangère | F56: 5 | G56: 650 | H56: =G56*F56 -> 3250
E57: semoule Sim Moyenne 10kg | F57: 8 | G57: 500 | H57: =G57*F57 -> 4000
E58: Papier Aluminium | F58: 3 | G58: 2100 | H58: =G58*F58 -> 6300
E59: huile 5 litres | F59: 16 | G59: 600 | H59: =F59*G59 -> 9600
E60: 3assila Madina 5kg | F60: 6 | G60: 680 | H60: =F60*G60 -> 4080
E61: Transport semoule | F61: 1 | G61: 2000 | H61: =F61*G61 -> 2000
E62: nettoyage des vitres | F62: 1 | G62: 1000 | H62: =F62*G62 -> 1000
E63: Boites 48/10 | F63: 1 | G63: 1900 | H63: =F63*G63 -> 1900
E64: Boites 48/07 | F64: 1 | G64: 1600 | H64: =F64*G64 -> 1600
E65: Boites 36 | F65: 1 | G65: 1200 | H65: =F65*G65 -> 1200
E66: Boite 18 | F66: 1 | G66: 1550 | H66: =G66*F66 -> 1550
E67: Boite 12 | F67: 1 | G67: 1350 | H67: =G67*F67 -> 1350
E68: Boite 8 | F68: 2 | G68: 1150 | H68: =G68*F68 -> 2300
E69: Olive noir+ coupé+vert | F69: 3 | G69: 600 | H69: =G69*F69 -> 1800
E70: poulet haché + blanc de poulet | F70: 3 | G70: 800 | H70: =G70*F70 -> 2400
E71: rechta | F71: 5 | G71: 120 | H71: =G71*F71 -> 600
E72: javel+ isis | F72: 2 | G72: 150 | H72: =G72*F72 -> 300
D74: 10 | E74: Amandes blanc | G74: 1580
D75: 10 | E75: khel | G75: 82
D76: 2 | E76: Djouz | G76: 1550 | H76: =G76*F76 -> 0
E77: Maiis | F77: 14 | G77: 360 | H77: =G77*F77 -> 5040
E80: Maiizina | F80: 5 | G80: 400 | H80: =G80*F80 -> 2000
...

Sheet Salaires 
I4: Nom | J4: Salaire | K4: Avance | L4: Salaire à payer
H5: 1 | I5: Sofiane | J5: 30000 | K5: 30000 | L5: =J5-K5 -> 0
H6: 2 | I6: Amel | J6: 30000 | K6: 30000 | L6: =J6-K6 -> 0
H7: 3 | I7: Lynda | J7: =Pointage!C34*1 -> 24700 | K7: 25000 | L7: =J7-K7 -> -300
H8: 4 | I8: Hafida | J8: =Pointage!D34*1 -> 28000 | K8: 28000 | L8: =J8-K8 -> 0
H9: 5 | I9: Djamila | J9: =Pointage!E34*1 -> 10160 | K9: 10500 | L9: =J9-K9 -> -340
H10: 6 | I10: Youssera | J10: =Pointage!F34*1 -> 18732.5 | K10: 19000 | L10: =J10-K10 -> -267.5 | M10: 2000+4000
H11: 7 | I11: Yasmine Vendeuse | J11: =Pointage!G34*1 -> 30004 | K11: 30000 | L11: =J11-K11 -> 4
H12: 8 | I12: Kenza | J12: =Pointage!H34*1 -> 10963 | K12: 11000 | L12: =J12-K12 -> -37
H13: 9 | I13: Yasmine | J13: =Pointage!I34*1 -> 12117 | K13: 12500 | L13: =J13-K13 -> -383
H14: 10 | I14: Nadjet | J14: =Pointage!L34*1 -> 15400 | K14: 15500 | L14: =J14-K14 -> -100 | M14: 2500+10000+3000
H15: 11 | I15: Amina | J15: =Pointage!J34*1 -> 10125 | K15: 10500 | L15: =J15-K15 -> -375
H16: 12 | I16: Samira | J16: =Pointage!O34*1 -> 3240 | K16: 3500 | L16: =J16-K16 -> -260
H17: 13 | I17: Samia | J17: 28500 | K17: 28500 | L17: =J17-K17 -> 0
H18: 14 | I18: Nadia Femme de ménage | J18: =Pointage!P34*1 -> 26400 | K18: 26500 | L18: =J18-K18 -> -100
H19: 15 | I19: Alia | J19: =Pointage!N34*1 -> 7200 | K19: 7500 | L19: =J19-K19 -> -300
H20: 16 | I20: Nadia | J20: =Pointage!Q34 -> 17000 | K20: 17000 | L20: =J20-K20 -> 0
H21: 17 | I21: chahrazed | J21: =Pointage!K34*1 -> 2000 | K21: 2000 | L21: =J21-K21 -> 0
I22: TOTAL | J22: =SUM(J5:J21) -> 304541.5 | K22: =SUM(K5:K21) -> 307000 | L22: =SUM(L5:L21) -> -2458.5
I23: =J22-K22 -> -2458.5 | L23: =J23-K23 -> 0

Sheet Feuille 5
C14: Mois de Janvier | D14: Mois de Février | E14: Mois de Mars | F14: Mois d'Avril | G14: Mois de Mai | H14: Mois de Jiun | I14: Mois de Juillet | J14: Mois d'Aout | K14: Mois de Septembre | L14: Mois d'Octobre | M14: Mois de Novembre | N14: Mois de Décembre | O14: Totale
B15: Recette | C15: 1441000 | D15: 1400000 | E15: 1928000 | F15: 1488000 | G15: 1540000 | H15: 1577000 | I15: 1880000 | J15: 941000 | K15: 1629000 | L15: 1264000 | M15: 1254000 | O15: =SUM(C15:N15) -> 16342000
B16: Charges | C16: 749000 | D16: 597000 | E16: 938000 | F16: 670000 | G16: 753000 | H16: 716000 | I16: 834000 | J16: 492000 | K16: 692000 | L16: 580000 | M16: 509000 | O16: =SUM(C16:N16) -> 7530000
B17: Salaires | C17: 332000 | D17: 413000 | E17: 360000 | F17: 335000 | G17: 347000 | H17: 331000 | I17: 416000 | J17: 239000 | K17: 287000 | L17: 364000 | M17: 305000 | O17: =SUM(C17:N17) -> 3729000
B18: Loyer | C18: 110000 | D18: 110000 | E18: 110000 | F18: 110000 | G18: 110000 | H18: 110000 | I18: 110000 | J18: 110000 | K18: 110000 | L18: 110000 | M18: 110000 | O18: =SUM(C18:N18) -> 1210000
B19: Profit Net | C19: 250000 | D19: 280000 | E19: 520000 | F19: 370000 | G19: =G15-G16-G17-G18 -> 330000 | H19: =H15-H16-H17-H18 -> 420000 | I19: 520000 | J19: 100000 | K19: 540000 | L19: 210000 | M19: =M15-M16-M17-M18 -> 330000 | O19: =SUM(C19:N19) -> 3870000
G33: Mois de Novembre
F34: Recette | G34: 1254000
F35: Charges | G35: 509000
F36: Salaires | G36: 305000
F37: Loyer | G37: 110000
F38: Profit Net | G38: =G34-G35-G36-G37 -> 330000
