Workbook

Sheet RECAP
A1: 5 | B1: Date | C1: Recette mois d'Octobre | D1: Recette de Novembre | E1: Recette | F1: Charges | G1: Salaire | H1: Loyer | I1: Net Profit | J1: Nb de jours | L1: Novembre | M1: Octobre
A2: Mardi | B2: 44166 | C2: 53000 | D2: 23000 | E2: 26000 | J2: 1 | L2: 23000 | M2: 53000 | N2: Moyenne
A3: Mercredi | B3: 44167 | C3: 0 | D3: 20000 | E3: 29000 | J3: 1 | L3: 20000 | M3: 0 | N3: =E33/J33 -> 37225.806
A4: Jeudi | B4: 44168 | C4: 20000 | D4: 22000 | E4: 57000 | J4: 1 | L4: 22000 | M4: 20000
A5: Vendredi | B5: 44169 | C5: 20000 | D5: 27000 | E5: 40000 | J5: 1 | L5: 27000 | M5: 20000 | N5: 30000
A6: Samedi | B6: 44170 | C6: 21000 | D6: 37000 | E6: 30000 | J6: 1 | L6: 37000 | M6: 21000
A7: Dimanche | B7: 44171 | C7: 20000 | D7: 26000 | E7: 31000 | J7: 1 | L7: 26000 | M7: 20000
A8: Lundi | B8: 44172 | C8: 34000 | D8: 12000 | E8: 22000 | J8: 1 | L8: 12000 | M8: 34000
A9: Mardi | B9: 44173 | C9: 33000 | D9: 22000 | E9: 38000 | J9: 1 | L9: 22000 | M9: 33000
A10: Mercredi | B10: 44174 | C10: 0 | D10: 16000 | E10: 44000 | J10: 1 | L10: 16000 | M10: 0
A11: Jeudi | B11: 44175 | C11: 29000 | D11: 18000 | E11: 49000 | J11: 1 | L11: 18000 | M11: 29000
A12: Vendredi | B12: 44176 | C12: 26000 | D12: 24000 | E12: 60000 | J12: 1 | L12: 24000 | M12: 26000
A13: Samedi | B13: 44177 | C13: 27000 | D13: 34000 | E13: 31000 | J13: 1 | L13: 34000 | M13: 27000
A14: Dimanche | B14: 44178 | C14: 29000 | D14: 16000 | E14: 27000 | J14: 1 | L14: 16000 | M14: 29000 | N14: Cash restant | O14: Magasin | Q14: Différence mois de Novembre
A15: Lundi | B15: 44179 | C15: 32000 | D15: 19000 | E15: 27000 | J15: 1 | L15: 19000 | M15: 32000 | N15: =E33+Charges!G245-O15-F33-Salaires!J23 -> 589985 | O15: 0 | Q15: =E33-D33 -> 416000
A16: Mardi | B16: 44180 | C16: 40000 | D16: 17000 | E16: 20000 | J16: 1 | L16: 17000 | M16: 40000 | Q16: Différence mois d'Octobre
A17: Mercredi | B17: 44181 | C17: 35000 | D17: 22000 | E17: 36000 | J17: 1 | L17: 22000 | M17: 35000 | Q17: =E33-C33 -> 115000
A18: Jeudi | B18: 44182 | C18: 33000 | D18: 20000 | E18: 55000 | J18: 1 | L18: 20000 | M18: 33000
A19: Vendredi | B19: 44183 | C19: 43000 | D19: 24000 | E19: 36000 | J19: 1 | L19: 24000 | M19: 43000
A20: Samedi | B20: 44184 | C20: 32000 | D20: 52000 | E20: 33000 | J20: 1 | L20: 52000 | M20: 32000 | X20: 701900
A21: Dimanche | B21: 44185 | C21: 33000 | D21: 30000 | E21: 29000 | J21: 1 | L21: 30000 | M21: 33000 | X21: 509000
A22: Lundi | B22: 44186 | C22: 49000 | D22: 27000 | E22: 26000 | J22: 1 | L22: 27000 | M22: 49000 | N22: Sofiane | O22: 4000 | Q22: viande | W22: Sofiane | X22: 4000 | Z22: machine+viande
A23: Mardi | B23: 44187 | C23: 35000 | D23: 19000 | E23: 24000 | J23: 1 | L23: 19000 | M23: 35000 | O23: =N15-O22 -> 585985 | W23: / | X23: 15000
A24: Mercredi | B24: 44188 | C24: 30000 | D24: 30000 | E24: 60000 | J24: 1 | L24: 30000 | M24: 30000 | W24: Islem | X24: 15000
A25: Jeudi | B25: 44189 | C25: 48000 | D25: 29000 | E25: 45000 | J25: 1 | L25: 29000 | M25: 48000 | W25: charges janvier | X25: 220000
A26: Vendredi | B26: 44190 | C26: 52000 | D26: 26000 | E26: 42000 | J26: 1 | L26: 26000 | M26: 52000
A27: Samedi | B27: 44191 | C27: 55000 | D27: 30000 | E27: 32000 | J27: 1 | L27: 30000 | M27: 55000 | W27: Amel | X27: =X20-X21-X22-X23-X24-X25-X26 -> -61100
A28: Dimanche | B28: 44192 | C28: 66000 | D28: 20000 | E28: 29000 | J28: 1 | L28: 20000 | M28: 66000
A29: Lundi | B29: 44193 | C29: 80000 | D29: 28000 | E29: 35000 | J29: 1 | L29: 28000 | M29: 80000
A30: Mardi | B30: 44194 | C30: 40000 | D30: 24000 | E30: 44000 | J30: 1 | L30: 24000 | M30: 40000
A31: Mercredi | B31: 44195 | C31: 24000 | D31: 24000 | E31: 42000 | J31: 1 | L31: 24000 | M31: 24000
A32: Jeudi | B32: 44196 | C32: 0 | D32: 0 | E32: 55000 | J32: 1 | L32: =SUM(L2:L31) -> 738000 | M32: =SUM(M2:M31) -> 1039000
A33: TOTAL | C33: =SUM(C2:C32) -> 1039000 | D33: =SUM(D2:D32) -> 738000 | E33: =SUM(E2:E32) -> 1154000 | F33: =Charges!G244*1 -> 397815 | G33: =Salaires!I23*1 -> 206708 | H33: 77000 | I33: =E33+Charges!G245-F33-G33-H33 -> 512477 | J33: =SUM(J2:J32) -> 31
A34: TAUX | E34: 1 | F34: =F33/E33 -> 0.34472704 | G34: =G33/E33 -> 0.17912305 | H34: =H33/E33 -> 0.066724437 | I34: =I33/E33 -> 0.44408752
E36: 738000 | F36: 272000 | G36: 189000 | I36: 240000
E37: 1039000 | F37: 356000 | G37: 210000 | I37: 435000

Sheet Charges
E4: Produit | F4: Quantité | G4: Prix | H4: Date d'achat
E5: Gheress | F5: 20kg | G5: 3000 | H5: 44166
E6: vanille | F6: 1kg | G6: 400 | H6: 44166
E7: sacs en papier 23 | F7: 2 fardeaux | G7: 2400 | H7: 44166
E8: chocolat à tartiner | F8: 9kg | G8: 2900 | H8: 44166
E9: Farine Mama | F9: 4 fardeaux | G9: 2800 | H9: 44166
E10: Margarine Mani | F10: 1 carton de 24 boites | G10: 2760 | H10: 44166
E11: eau fleur d'oranger | F11: 1 carton de 12 | G11: 660 | H11: 44166
E12: na3ena3 yabess | F12: 1kg | G12: 700 | H12: 44166
E13: huile | F13: 20 bidons | G13: 10400 | H13: 44166
E14: semoule Sim fine et moyenne | F14: 6 | G14: 2700 | H14: 44166
E15: confiture | F15: 12kg | G15: 1650 | H15: 44166
E16: arachides éfilet | F16: 1kg | G16: 700 | H16: 44166
E17: djeldjelan | F17: 500g | G17: 400 | H17: 44166
E18: maizina | F18: 2kg | G18: 500 | H18: 44166
E19: amandes | F19: 2kg | G19: 3200 | H19: 44166
E20: sel | F20: 1 fardeau | G20: 330 | H20: 44166
E21: sucre glace | F21: 1 fardeau | G21: 1080 | H21: 44166
E22: Sucre cristalisé | F22: 1 fardeau | G22: 750 | H22: 44166
E23: semen | F23: 1 carton | G23: 1800 | H23: 44166
E24: Margarine Mani | F24: 1 carton de 24 boites | G24: 2760 | H24: 44166
E25: levure Nouara | F25: 1 boite | G25: 450 | H25: 44166
E26: chocolat glaçage | F26: 5 boites | G26: 900 | H26: 44166
E27: lave sol | F27: 1 | G27: 150 | H27: 44166
E28: Serpièrre | F28: 1 | G28: 100 | H28: 44166
E29: Boites 08/07 | F29: 2 cartons | G29: 1700 | H29: 44166
E30: Boites 36/07 | F30: 2 cartons | G30: 1720 | H30: 44166
E31: Boites 36/10 | F31: 2 cartons | G31: 2200 | H31: 44166
E32: Boites 48/10 | F32: 2 cartons | G32: 2900 | H32: 44166
E33: Semoule fine Moula 10kg | F33: 3 sachets | G33: 1650 | H33: 44166
E34: Semoule fine Moula 10kg | F34: 3 sachets | G34: 1800 | H34: 44166
E35: Semoule fine Mama 25kg | F35: 7 sachets | G35: 9800 | H35: 44166
E36: Semoule fine Mama 10KG | F36: 15 sachets | G36: 9450 | H36: 44166
E37: tomate fraiche | F37: 20kg | G37: 900 | H37: 44166
E38: transport semoule | F38: 1 | G38: 500 | H38: 44166
E39: Rechta | F39: 30kg | G39: 3000 | H39: 44166
E40: bessel | F40: 100kg | G40: 4200 | H40: 44166
E41: ka3ek nakach | F41: 90 pièces | G41: 4500 | H41: 44166
E42: yaourt | F42: 8 boites | G42: 120 | H42: 44166
E43: papier aluminium | F43: 50m | G43: 550 | H43: 44166
...

Sheet Pointage
B1: Date | C1: Zehor | D1: Zoubida | E1: Nadjet | F1: Nawel | G1: Hadjer | H1: Amel | I1: Soumia | J1: Karima | K1: Nouara | L1: Zahida | M1: Remarque
A2: Mardi | B2: 44166 | C2: 1 | D2: 1 | E2: 0 | F2: 0 | G2: 0 | H2: 1 | I2: 0 | J2: 1 | K2: 1 | L2: 1
A3: Mercredi | B3: 44167 | C3: 1 | D3: 0 | E3: 0 | F3: 0 | G3: 1 | H3: 1 | I3: 0 | J3: 1 | K3: 1 | L3: 1
A4: Jeudi | B4: 44168 | C4: 1 | D4: 0 | E4: 0 | F4: 0 | G4: 1 | H4: 1 | I4: 0 | J4: 1 | K4: 1 | L4: 1
A5: Vendredi | B5: 44169 | C5: 1 | D5: 0 | E5: 1 | F5: 0 | G5: 1 | H5: 0 | I5: 0 | J5: 1 | K5: 1 | L5: 1.5
A6: Samedi | B6: 44170 | C6: 0 | D6: 1 | E6: 1 | F6: 0 | G6: 0 | H6: 1 | I6: 0 | J6: 1 | K6: 0.5 | L6: 0
A7: Dimanche | B7: 44171 | C7: 1 | D7: 1 | E7: 0 | F7: 0 | G7: 0 | H7: 1 | I7: 0 | J7: 1 | K7: 1 | L7: 1
A8: Lundi | B8: 44172 | C8: 1 | D8: 1 | E8: 0 | F8: 0 | G8: 0 | H8: 1 | I8: 0 | J8: 1 | K8: 0.5 | L8: 1
A9: Mardi | B9: 44173 | C9: 1 | D9: 1 | E9: 0 | F9: 0 | G9: 0 | H9: 1 | I9: 0 | J9: 1 | K9: 1 | L9: 1.5
A10: Mercredi | B10: 44174 | C10: 1 | D10: 1 | E10: 0 | F10: 0 | G10: 0 | H10: 1 | I10: 0 | J10: 1 | K10: 1 | L10: 1
A11: Jeudi | B11: 44175 | C11: 1 | D11: 1 | E11: 0 | F11: 0 | G11: 1 | H11: 1 | I11: 0 | J11: 1 | K11: 1 | L11: 1.5
A12: Vendredi | B12: 44176 | C12: 1 | D12: 0 | E12: 0 | F12: 0 | G12: 1 | H12: 1 | I12: 0 | J12: 1 | K12: 1 | L12: 1.5
A13: Samedi | B13: 44177 | C13: 1 | D13: 0 | E13: 0 | F13: 0 | G13: 0 | H13: 1 | I13: 0 | J13: 1 | K13: 1 | L13: 1
... A32: Jeudi | B32: 44196 | C32: 1 | D32: 1 | E32: 0 | F32: 1 | G32: 0 | H32: 1 | I32: 1 | J32: 0 | K32: 1 | L32: 1
B33: Total | C33: =SUM(C2:C32) -> 27 | D33: =SUM(D2:D32) -> 24 | E33: =SUM(E2:E32) -> 3 | F33: =SUM(F2:F32) -> 2 | G33: =SUM(G2:G32) -> 10 | H33: =SUM(H2:H32) -> 28 | I33: =SUM(I2:I32) -> 16 | J33: =SUM(J2:J32) -> 29 | ... L33: =SUM(L2:L32) -> 32
B34: Salaire/jour | C34: 1852 | D34: 1111 | E34: 900 | F34: 926 | G34: 900 | H34: 1037 | I34: 800 | J34: 550 | K34: 926 | L34: 1111 | M34: =SUM(C34:L34) -> 10113
B35: SALAIRES | C35: =C34*C33 -> 50004 | D35: =D34*D33 -> 26664 | E35: =E34*E33 -> 2700 | F35: =F34*F33 -> 1852 | G35: =G34*G33 -> 9000 | H35: =H34*H33 -> 29036 | I35: =I34*I33 -> 12800 | J35: =J34*J33 -> 15950 | K35: =K34*K33 -> 25002 | L35: =L33*L34 -> 35552 | M35: =SUM(C35:L35) -> 208560

Sheet Salaires
H13: Nom | I13: Salaire | J13: Avance
G14: 1 | H14: Zehor | I14: =Pointage!C35*1 -> 50004 | J14: 50000
G15: 2 | H15: Amel | I15: =Pointage!H35*1 -> 29036 | J15: 29000
G16: 3 | H16: Nowara | I16: =Pointage!K35*1 -> 25002 | J16: 25000
G17: 4 | H17: karima | I17: =Pointage!J35*1 -> 15950 | J17: 16000
G18: 5 | H18: Nadjet | I18: =Pointage!E35*1 -> 2700 | J18: 2700
G19: 6 | H19: Hadjer | I19: =Pointage!G35*1 -> 9000 | J19: 9000
G20: 7 | H20: Zoubida | I20: =Pointage!D35*1 -> 26664 | J20: 26700
G21: 8 | H21: Soumia | I21: =Pointage!I35*1 -> 12800 | J21: 12800
G22: 9 | H22: Zahida | I22: =Pointage!L35*1 -> 35552 | J22: 35000
H23: TOTAL | I23: =SUM(I14:I22) -> 206708 | J23: =SUM(J14:J22) -> 206200
I24: =I23-J23 -> 508
