Workbook

Sheet RECAP
B1: Date | C1: Recette de juillet | D1: Recette | E1: Charges | F1: Salaire | G1: Loyer | H1: Net Profit | I1: Nb de jours | J1: Objectif | K1: Juillet | N1: Moyenne
A2: Dimanche | B2: 44409 | C2: 47000 | D2: 40000 | I2: 1 | J2: 60000 | K2: 47000 | N2: =D33/I33 -> 49947.368
A3: Lundi | B3: 44410 | C3: 50000 | D3: 47000 | I3: 1 | J3: 60000 | K3: 50000
A4: Mardi | B4: 44411 | C4: 24000 | D4: 40000 | I4: 1 | J4: 60000 | K4: 24000 | N4: 60000
A5: Mercredi | B5: 44412 | C5: 40000 | D5: 50000 | I5: 1 | J5: 60000 | K5: 40000
A6: Jeudi | B6: 44413 | C6: 31000 | D6: 70000 | I6: 1 | J6: 60000 | K6: 31000
A7: Vendredi | B7: 44414 | C7: 33000 | D7: 0 | J7: 0 | K7: 33000
A8: Samedi | B8: 44415 | C8: 44000 | D8: 56000 | I8: 1 | J8: 60000 | K8: 44000
A9: Dimanche | B9: 44416 | C9: 77000 | D9: 51000 | I9: 1 | J9: 60000 | K9: 77000 | Q9: Différence mois de juillet
A10: Lundi | B10: 44417 | C10: 52000 | D10: 87000 | I10: 1 | J10: 60000 | K10: 52000 | Q10: =D33-C33 -> 21000
A11: Mardi | B11: 44418 | C11: 87000 | D11: 73000 | I11: 1 | J11: 60000 | K11: 87000 | M11: Cash restant | N11: Magasin | Q11: Différence objectif
A12: Mercredi | B12: 44419 | C12: 36000 | D12: 57000 | I12: 1 | J12: 60000 | K12: 36000 | M12: =D33+'Les Charges'!H248-N12-E33-'Les Charges'!H259-'Salaires '!J23 -> 380417 | N12: 8000 | Q12: =D33-J33 -> -191000
A13: Jeudi | B13: 44420 | C13: 22000 | D13: 41000 | I13: 1 | J13: 60000 | K13: 22000
A14: Vendredi | B14: 44421 | C14: 40000 | D14: 20000 | I14: 1 | J14: 60000 | K14: 40000
A15: Samedi | B15: 44422 | C15: 33000 | D15: 30000 | I15: 1 | J15: 60000 | K15: 33000
A16: Dimanche | B16: 44423 | C16: 36000 | D16: 19000 | I16: 1 | J16: 60000 | K16: 36000 | P16: Loyer | Q16: 350000
A17: Lundi | B17: 44424 | C17: 45000 | D17: 40000 | I17: 1 | J17: 60000 | K17: 45000
A18: Mardi | B18: 44425 | C18: 47000 | D18: 66000 | I18: 1 | J18: 60000 | K18: 47000
A19: Mercredi | B19: 44426 | C19: 55000 | D19: 63000 | I19: 1 | J19: 60000 | K19: 55000
A20: Jeudi | B20: 44427 | C20: 129000 | D20: 74000 | I20: 1 | J20: 60000 | K20: 129000 | P20: L+Cash restant | Q20: =Q16+M12 -> 730417
A21: Vendredi | B21: 44428 | C21: 0 | D21: 25000 | I21: 1 | J21: 60000 | K21: 0 | P21: cash disponible | Q21: 473000
A22: Samedi | B22: 44429 | D22: 0 | J22: 0 | K22: 0 | P22: Sofiane cash | Q22: 30000
A23: Dimanche | B23: 44430 | D23: 0 | J23: 0 | K23: 27000 | P23: ccp | Q23: 52000
A24: Lundi | B24: 44431 | D24: 0 | J24: 0 | K24: 32000 | P24: Sofiane Paypal | Q24: 7000
A25: Mardi | B25: 44432 | D25: 0 | J25: 0 | K25: 26000
A26: Mercredi | B26: 44433 | D26: 0 | J26: 0 | K26: 21000 | Q26: =Q20-Q21-Q22-Q23-Q24 -> 168417
A27: Jeudi | B27: 44434 | D27: 0 | J27: 0 | K27: 42000
A28: Vendredi | B28: 44435 | D28: 0 | J28: 0 | K28: 40000
A29: Samedi | B29: 44436 | D29: 0 | J29: 0 | K29: 45000 | L29: .
A30: Dimanche | B30: 44437 | D30: 0 | J30: 0 | K30: 58000
A31: Lundi | B31: 44438 | D31: 0 | J31: 0 | K31: 34000
A32: Mardi | B32: 44439 | D32: 0 | J32: 0 | K32: 44000
C33: =SUM(C2:C32) -> 928000 | D33: =SUM(D2:D32) -> 949000 | E33: ='Les Charges'!H247*1 -> 414283 | F33: ='Salaires '!I23*1 -> 162700 | G33: 50000 | H33: =D33+'Les Charges'!H248-G33-F33-E33 -> 342017 | I33: =SUM(I2:I32) -> 19 | J33: =SUM(J2:J32) -> 1140000 | K33: =SUM(K2:K32) -> 1297000
C35: Objectif | D35: 1190000 | E35: 500000 | F35: 140000 | G35: 50000 | H35: 500000
C36: Mois de Juillet | D36: 1297000 | E36: 505000 | F36: 222000 | G36: 50000 | H36: 540000

Sheet Les Charges
E9: Produit | F9: Quantité | G9: Prix unitaire | H9: Prix | I9: Date d'achat
E10: Semoule Mama 25kg | F10: 4 | G10: 1300 | H10: 5200 | I10: 44409
E11: Semoule Amor Ben Amor | F11: 4 | G11: 670 | H11: 2680 | I11: 44409
E12: Farine Sim 1kg | F12: 10 fardeaux | G12: 550 | H12: 2750 | I12: 44409
E13: Farine Agrodive 5kg | F13: 10 | G13: 190 | H13: 1900 | I13: 44409
E14: amandes | F14: 13kg | G14: 1680 | H14: 21840 | I14: 44409
E15: Nutella 1kg | F15: 3 | G15: 1200 | H15: 3600 | I15: 44409
E16: Maa zehar | F16: 12 | G16: 55 | H16: 660 | I16: 44409
E17: Sucre glace 1kg | F17: 12 | G17: 95 | H17: 1140 | I17: 44409
E18: Tomate | F18: 12 | G18: 190 | H18: 2280 | I18: 44409
E19: cerise | F19: 1 | G19: 150 | H19: 150 | I19: 44409
E20: boites demie plateaux | F20: 20 | G20: 90 | H20: 1800 | I20: 44409
E21: lait en poudre | F21: 1kg | G21: 650 | H21: 650 | I21: 44409
E22: Boites36/07 | F22: 2 | G22: 1050 | H22: 2100 | I22: 44409
E23: Boites 36/10 | F23: 2 | G23: 1600 | H23: 3200 | I23: 44409
E24: Boites Aluminium 1165 | F24: 1 fardeau de 100 | G24: 3750 | H24: 3750 | I24: 44409
E25: pate d'arome citron | F25: 1 | G25: 750 | H25: 750 | I25: 44409
E26: Sachet 5kg | F26: 1 fardeau de 1000 | G26: 1200 | H26: 1200 | I26: 44409
E27: chocolat Boudjedir à tartiner 9kg | F27: 1 | G27: 3400 | H27: 3400 | I27: 44409
E28: Levure chimique | F28: 1 | G28: 400 | H28: 400 | I28: 44409
E29: Thon | F29: 5 | G29: 850 | H29: 4250 | I29: 44409
E30: Maizina | F30: 2kg | G30: 160 | H30: 320 | I30: 44409
E31: Fromage sandwich | F31: 5 | G31: 650 | H31: 3250 | I31: 44409
E32: chedar | F32: 1,5kg | G32: 1230 | H32: 1800 | I32: 44409
E33: Confiture | F33: 7 | G33: 175 | H33: 1225 | I33: 44409
E34: semoule Sim moyenne 2kg | F34: 1 | G34: 950 | H34: 950 | I34: 44409
E35: bessel | F35: 75kg | G35: 30 | H35: 2250 | I35: 44409
E36: oeufs | F36: 5 plateaux | G36: 360 | H36: 1800 | I36: 44409
E37: Semoule Mama 25kg | F37: 5 | G37: 1300 | H37: 6500 | I37: 44409
E38: transport marchandises | F38: 2 | G38: / | H38: 1500 | I38: 44409
E39: ka3ek enakach | F39: 800 | G39: 50 | H39: 40000 | I39: 44409
E40: huile elio la concorde | F40: 16 | G40: 590 | H40: 9440 | I40: /
E41: huile elio | F41: 2 | G41: 600 | H41: 1200 | I41: 44409
E42: viande hachée | F42: 1kg | G42: 1500 | H42: 1500 | I42: 44409
E43: poulet haché | F43: 1kg | G43: 800 | H43: 800 | I43: 44409
E44: fromage spéciale pizza | F44: 8kg | G44: 230 | H44: 1840 | I44: 44409
E45: Semoule moyenne Sim 10kg | F45: 7 | G45: 450 | H45: 3150 | I45: 44409
E46: rechta | F46: 30kg | G46: 100 | H46: 3000 | I46: 44409
E47: boite | F47: 1 | G47: 350 | H47: 350
E48: djefena | F48: 1 | G48: 850 | H48: 850 | I48: 44409
...

Sheet Pointage
B1: Date | C1: Zehor | D1: Yossera | E1: Soumia | F1: Nadjet | G1: Hadjer | H1: Souad | I1: Amel | J1: Hafida | K1: Safia | L1: Samira | M1: Linda | N1: Zahida | O1: Remarque
A2: Dimanche | B2: 44409 | C2: 0 | D2: 1 | E2: 0 | F2: 1 | G2: 0 | H2: 0 | I2: 1 | J2: 1 | K2: 1 | L2: 1 | M2: 0 | N2: 0
A3: Lundi | B3: 44410 | C3: 0 | D3: 1 | E3: 0 | F3: 1 | G3: 0 | H3: 0 | I3: 1 | J3: 1 | K3: 1 | L3: 1 | M3: 0 | N3: 0 | O3: Safia djagte à 09h30
A4: Mardi | B4: 44411 | C4: 0 | D4: 1 | E4: 0 | F4: 1 | G4: 0 | H4: 0 | I4: 1 | J4: 1 | K4: 1 | L4: 1 | M4: 0 | N4: 0 | O4: Safia djagte à 09h45
A5: Mercredi | B5: 44412 | C5: 0 | D5: 1 | E5: 0 | F5: 1 | G5: 0 | H5: 0 | I5: 1 | J5: 1 | K5: 1 | L5: 1 | M5: 0 | N5: 0
A6: Jeudi | B6: 44413 | C6: 0 | D6: 1 | E6: 0 | F6: 1 | G6: 0 | H6: 0 | I6: 1 | J6: 1 | K6: 1 | L6: 1 | M6: 0 | N6: 1
A7: Vendredi | B7: 44414 | C7: 0 | D7: 0 | E7: 0 | F7: 0 | G7: 0 | H7: 0 | I7: 0 | J7: 0 | K7: 0 | L7: 0 | M7: 0 | N7: 0
A8: Samedi | B8: 44415 | C8: 0 | D8: 1 | E8: 0 | F8: 1 | G8: 0 | H8: 0 | I8: 1 | J8: 1 | K8: 1 | L8: 1 | M8: 0 | N8: 1
A9: Dimanche | B9: 44416 | C9: 0 | D9: 0 | E9: 0 | F9: 1 | G9: 0 | H9: 0 | I9: 1 | J9: 1 | K9: 1 | L9: 1 | M9: 0 | N9: 1.5
A10: Lundi | B10: 44417 | C10: 0 | D10: 1 | E10: 0 | F10: 1 | G10: 0 | H10: 0 | I10: 1 | J10: 1 | K10: 1 | L10: 1 | M10: 0 | N10: 1
A11: Mardi | B11: 44418 | C11: 0 | D11: 2 | E11: 0 | F11: 2 | G11: 0 | H11: 0 | I11: 2 | J11: 2 | K11: 2 | L11: 1 | M11: 0 | N11: 2
A12: Mercredi | B12: 44419 | C12: 0 | D12: 1 | E12: 0 | F12: 1 | G12: 0 | H12: 0 | I12: 1 | J12: 1 | K12: 1 | M12: 0 | N12: 1
A13: Jeudi | B13: 44420 | C13: 0 | D13: 1 | E13: 0 | F13: 1 | G13: 0 | H13: 0 | I13: 1 | J13: 1 | K13: 1 | L13: 1 | M13: 0 | N13: 1
A14: Vendredi | B14: 44421 | C14: 0 | D14: 1 | E14: 0 | F14: 0 | G14: 0 | H14: 0 | I14: 0 | J14: 1 | K14: 0 | L14: 0 | M14: 0 | N14: 1
A15: Samedi | B15: 44422 | C15: 0 | D15: 0 | E15: 0 | F15: 1 | G15: 0 | H15: 0 | I15: 1 | J15: 0 | K15: 1 | L15: 1 | M15: 0 | N15: 1
A16: Dimanche | B16: 44423 | C16: 0 | D16: 1 | E16: 0 | F16: 1 | G16: 0 | H16: 0 | I16: 1 | J16: 1 | K16: 1 | L16: 1 | M16: 0 | N16: 1
A17: Lundi | B17: 44424 | C17: 1 | D17: 1 | E17: 0 | F17: 1 | G17: 0 | H17: 0 | I17: 1 | J17: 1 | K17: 1 | L17: 0 | M17: 0 | N17: 1
A18: Mardi | B18: 44425 | C18: 1 | D18: 1 | E18: 0 | F18: 1 | G18: 0 | H18: 0 | I18: 1 | J18: 1 | K18: 1 | L18: 0.5 | M18: 0 | N18: 1
A19: Mercredi | B19: 44426 | C19: 1 | D19: 1 | E19: 0 | F19: 1 | G19: 0 | H19: 1 | I19: 1 | J19: 1 | K19: 1 | L19: 0 | M19: 0 | N19: 1
A20: Jeudi | B20: 44427 | C20: 1.5 | D20: 1 | E20: 0 | F20: 2 | G20: 0 | H20: 1 | I20: 2 | J20: 2 | K20: 2 | L20: 0 | M20: 0 | N20: 2
A21: Vendredi | B21: 44428 | C21: 1 | D21: 1 | E21: 0 | F21: 1 | G21: 0 | H21: 0 | I21: 0 | J21: 1 | K21: 0 | L21: 0 | M21: 0 | N21: 1
A22: Samedi | B22: 44429 | C22: 7.5 | D22: 0 | E22: 0 | F22: 0 | G22: 0 | H22: 0 | I22: 0 | J22: 0 | K22: 0 | L22: 0 | M22: 0 | N22: 0
A23: Dimanche | B23: 44430 | C23: 0 | D23: 0 | E23: 0 | F23: 0 | G23: 0 | H23: 0 | I23: 0 | J23: 0 | K23: 0 | L23: 0 | M23: 0 | N23: 0
A24: Lundi | B24: 44431 | C24: 0 | D24: 0 | E24: 0 | F24: 0 | G24: 0 | H24: 0 | I24: 0 | J24: 0 | K24: 0 | L24: 0 | M24: 0 | N24: 0
... A32: Mardi | B32: 44439 | C32: 0 | D32: 0 | E32: 0 | F32: 0 | G32: 0 | H32: 0 | I32: 0 | J32: 0 | K32: 0 | L32: 0 | M32: 0 | N32: 0
C33: =SUM(C1:C32) -> 13 | D33: =SUM(D1:D32) -> 18 | E33: =SUM(E2:E32) -> 0 | F33: =SUM(F1:F32) -> 20 | G33: =SUM(G1:G32) -> 0 | H33: =SUM(H2:H32) -> 2 | I33: =SUM(I1:I32) -> 19 | J33: =SUM(J1:J32) -> 20 | K33: =SUM(K2:K32) -> 19 | L33: =SUM(L2:L32) -> 12.5 | M33: =SUM(M2:M32) -> 0 | N33: =SUM(N1:N32) -> 17.5
C34: 2000 | D34: 800 | E34: 1000 | F34: 1000 | G34: 1000 | H34: 1500 | I34: 1200 | J34: 1200 | K34: 1000 | L34: 1000 | M34: 1000 | N34: 1200 | O34: =SUM(C34:N34) -> 13900
C35: =C34*C33 -> 26000 | D35: =D33*D34 -> 14400 | E35: =E34*E33 -> 0 | F35: =F34*F33 -> 20000 | G35: =G34*G33 -> 0 | H35: =H34*H33 -> 3000 | I35: =I34*I33 -> 22800 | J35: =J34*J33 -> 24000 | K35: =K34*K33 -> 19000 | L35: =L34*L33 -> 12500 | M35: =M34*M33 -> 0 | N35: =N33*N34 -> 21000 | O35: =SUM(C35:N35) -> 162700

Sheet Salaires 
H10: Nom | I10: Salaire | J10: Avance
G11: 1 | H11: Zehor | I11: =Pointage!C35*1 -> 26000 | J11: 26000
G12: 2 | H12: Yossera | I12: =Pointage!D35*1 -> 14400 | J12: 15000
G13: 3 | H13: Soumia | I13: =Pointage!E35*1 -> 0 | J13: 0
G14: 4 | H14: Amel | I14: =Pointage!I35*1 -> 22800 | J14: 23000
G15: 5 | H15: Nadjet | I15: =Pointage!F35*1 -> 20000 | J15: 20000
G16: 6 | H16: Hadjer | I16: =Pointage!G35*1 -> 0 | J16: 0
G17: 7 | H17: Hafida | I17: =Pointage!J35*1 -> 24000 | J17: 24000 | K17: 5000+1000+1000+500+500+500+500
G18: 8 | H18: Linda | I18: =Pointage!M35*1 -> 0 | J18: 0
G19: 11 | H19: Safia | I19: =Pointage!K35*1 -> 19000 | J19: 19000 | K19: 2000
G20: 12 | H20: Souad | I20: =Pointage!H35*1 -> 3000 | J20: 3000
G21: 13 | H21: Samira | I21: =Pointage!L35*1 -> 12500 | J21: 12500 | K21: 1850 | L21: 1200+150+100+400
G22: 14 | H22: Zahida | I22: =Pointage!N35*1 -> 21000 | J22: 21000
H23: TOTAL | I23: =SUM(I11:I22) -> 162700 | J23: =SUM(J11:J22) -> 163500
I24: =I23-J23 -> -800
