Workbook

Sheet RECAP
B1: Date | C1: Recette d'Octobre 2022 | D1: Recette | E1: Charges | F1: Salaire | G1: Loyer | H1: Net Profit | I1: Nb de jours | K1: Objectif | L1: octobre | M1: Bénéfice Moyen par jour | N1: Moyenne | O1: Moyenne salaire | P1: pourcentage du salaire vis à vis la recettte
A2: Mardi | B2: 44866 | C2: 50000 | D2: 2000 | I2: 0 | K2: 0 | L2: 50000 | M2: =H32/I32 -> 18644.207 | N2: =D32/I32 -> 58827.586 | O2: =F32/I32 -> 11662.207 | P2: =O2/N2 -> 0.19824385
A3: Mercredi | B3: 44867 | C3: 51000 | D3: 52000 | I3: 1 | K3: 70000 | L3: 51000
A4: Jeudi | B4: 44868 | C4: 90000 | D4: 69000 | I4: 1 | K4: 70000 | L4: 90000 | M4: Moyenne des charges par jour | N4: Objectif
A5: Vendredi | B5: 44869 | C5: 120000 | D5: 60000 | I5: 1 | K5: 70000 | L5: 120000 | M5: =E32/I32 -> 24728.069 | N5: 70000
A6: Samedi | B6: 44870 | C6: 140000 | D6: 60000 | I6: 1 | K6: 70000 | L6: 140000 | M6: ²
A7: Dimanche | B7: 44871 | C7: 210000 | D7: 45000 | I7: 1 | K7: 70000 | L7: 210000
A8: Lundi | B8: 44872 | C8: 60000 | D8: 40000 | I8: 1 | K8: 70000 | L8: 60000 | M8: Cash restant | N8: Magasin | O8: caisse | P8: cash en attente pour le récupérer =Dettes éxterieurs
A9: Mardi | B9: 44873 | C9: 52000 | D9: 53000 | I9: 1 | K9: 70000 | L9: 52000 | M9: =D32+N11-E32-N9-'Les salaires '!J27 -> 525086 | N9: =P9+O9 -> 741000 | O9: 18000 | P9: 723000
A10: Mercredi | B10: 44874 | C10: 42000 | D10: 40000 | I10: 1 | K10: 70000 | L10: 42000 | P10: Sofiane: 120000+500000+16000+8000
A11: Jeudi | B11: 44875 | C11: 35000 | D11: 60000 | I11: 1 | K11: 70000 | L11: 35000 | M11: loyer | N11: 368000 | P11: CCP.: 12000+43000
A12: Vendredi | B12: 44876 | C12: 32000 | D12: 110000 | I12: 1 | K12: 70000 | L12: 32000 | P12: Abdou:4000
A13: Samedi | B13: 44877 | C13: 45000 | D13: 72000 | I13: 1 | K13: 70000 | L13: 45000 | P13: mokrani: 20000
A14: Dimanche | B14: 44878 | C14: 80000 | D14: 50000 | I14: 1 | K14: 70000 | L14: 80000
A15: Lundi | B15: 44879 | C15: 66000 | D15: 71000 | I15: 1 | K15: 70000 | L15: 66000
A16: Mardi | B16: 44880 | C16: 78000 | D16: 73000 | I16: 1 | K16: 70000 | L16: 78000 | O16: Sofiane Loyer Magasin | P16: 620000
A17: Mercredi | B17: 44881 | C17: 36000 | D17: 90000 | I17: 1 | K17: 70000 | L17: 36000 | M17: Différence mois d'Aout
A18: Jeudi | B18: 44882 | C18: 30000 | D18: 60000 | I18: 1 | K18: 70000 | L18: 30000 | M18: =D32-C32 -> -162000
A19: Vendredi | B19: 44883 | C19: 40000 | D19: 70000 | I19: 1 | K19: 70000 | L19: 40000 | M19: Différence objectif
A20: Samedi | B20: 44884 | C20: 54000 | D20: 70000 | I20: 1 | K20: 70000 | L20: 54000 | M20: =K32-D32 -> 324000
A21: Dimanche | B21: 44885 | C21: 30000 | D21: 40000 | I21: 1 | K21: 70000 | L21: 30000
A22: Lundi | B22: 44886 | C22: 45000 | D22: 24000 | I22: 1 | K22: 70000 | L22: 45000
A23: Mardi | B23: 44887 | C23: 60000 | D23: 40000 | I23: 1 | K23: 70000 | L23: 60000 | M23: Les vendredis
A24: Mercredi | B24: 44888 | C24: 100000 | D24: 90000 | I24: 1 | K24: 70000 | L24: 100000 | M24: =D5+D12+D19+D26 -> 340000
A25: Jeudi | B25: 44889 | C25: 33000 | D25: 60000 | I25: 1 | K25: 70000 | L25: 33000
A26: Vendredi | B26: 44890 | C26: 25000 | D26: 100000 | I26: 1 | K26: 70000 | L26: 25000 | M26: Cash réel
A27: Samedi | B27: 44891 | C27: 55000 | D27: 40000 | I27: 1 | K27: 70000 | L27: 55000 | M27: 230000
A28: Dimanche | B28: 44892 | C28: 50000 | D28: 30000 | I28: 1 | K28: 70000 | L28: 50000 | M28: rest à payer
A29: Lundi | B29: 44893 | C29: 70000 | D29: 65000 | I29: 1 | K29: 70000 | L29: 70000 | M29: =M9-M27 -> 295086
A30: Mardi | B30: 44894 | C30: 68000 | D30: 40000 | I30: 1 | K30: 70000 | L30: 68000
A31: Dimanche | B31: 44895 | C31: 21000 | D31: 30000 | I31: 1 | K31: 70000 | L31: 21000
C32: =SUM(C2:C31) -> 1868000 | D32: =SUM(D2:D31) -> 1706000 | E32: ='Les charges '!H311*1 -> 717114 | F32: ='Les salaires '!I27*1 -> 338204 | G32: 110000 | H32: =D32-G32-F32-E32 -> 540682 | I32: =SUM(I2:I31) -> 29 | K32: =SUM(K2:K31) -> 2030000 | L32: =SUM(L2:L31) -> 1868000
C34: Objectif | D34: 2030000 | E34: 700000 | F34: 310000 | G34: 110000 | H34: 910000
C35: Mois d'Octobre | D35: 1921000 | E35: 901000 | F35: 369000 | G35: 110000 | H35: 540000
C38: La différence | D38: =D32-D35 -> -215000 | E38: =E32-E35 -> -183886 | F38: =F32-F35 -> -30796 | G38: =G32-G35 -> 0 | H38: =H32-H35 -> 682
D41: NOV | E41: =E32/D32*100 -> 42.034818 | F41: =F32/D32*100 -> 19.824385 | G41: =G32/D32*100 -> 6.4478312 | H41: =H32/D32*100 -> 31.692966
D43: OBJ | E43: =E34/D34*100 -> 34.482759 | F43: =F34/D34*100 -> 15.270936 | G43: =G34/D34*100 -> 5.4187192 | H43: =H34/D34*100 -> 44.827586
D44: OCT | E44: =E35/D35*100 -> 46.902655 | F44: =F35/D35*100 -> 19.208745 | G44: =G35/D35*100 -> 5.7261843 | H44: =H35/D35*100 -> 28.110359

Sheet Pointage
B1: Date | C1: Nadjet | D1: Hafida | E1: Wahiba | F1: Rania/Fella | G1: djamila | H1: Farida | I1: Yousera | J1: Lynda | K1: Kenza | L1: Fouzia | M1: SAmira | N1: Karima/Alia | O1: Yasmine | P1: Extra | Q1: Remarque | V1: Date | W1: Farida
A2: Mardi | B2: 44866 | C2: 0 | D2: 0 | E2: 0 | F2: 0 | G2: 0 | H2: 0 | I2: 0 | J2: 0 | K2: 0 | L2: 0 | M2: 0 | N2: 0 | O2: 0 | P2: 0 | U2: Mardi | V2: 44866 | W2: 0
A3: Mercredi | B3: 44867 | C3: 1 | D3: 0 | E3: 1 | F3: 1 | G3: 0 | H3: 1 | I3: 1 | J3: 1 | K3: 1 | L3: 0 | M3: 1 | N3: 1 | O3: 0 | P3: 0 | U3: Mercredi | V3: 44867 | W3: 1
A4: Jeudi | B4: 44868 | C4: 0 | D4: 0 | E4: 1 | F4: 1 | G4: 1 | H4: 1 | I4: 1 | J4: 1 | K4: 0 | L4: 0 | M4: 1 | N4: 0 | O4: 1 | P4: 0 | U4: Jeudi | V4: 44868 | W4: 1
A5: Vendredi | B5: 44869 | C5: 0 | D5: 0 | E5: 0 | F5: 1 | G5: 1 | H5: 1 | I5: 1 | J5: 1 | K5: 0 | L5: 0 | M5: 1 | N5: 0 | O5: 1 | P5: 0 | U5: Vendredi | V5: 44869 | W5: 1
A6: Samedi | B6: 44870 | C6: 0 | D6: 0 | E6: 1 | F6: 1 | G6: 1 | H6: 1 | I6: 1 | J6: 1 | K6: 1 | L6: 0 | M6: 1 | N6: 0 | O6: 0 | P6: 0 | U6: Samedi | V6: 44870 | W6: 1
A7: Dimanche | B7: 44871 | C7: 0 | D7: 0 | E7: 1 | F7: 1 | G7: 1 | H7: 1 | I7: 1 | J7: 1 | K7: 0.5 | L7: 0 | M7: 0 | N7: 0 | O7: 0 | P7: 0 | U7: Dimanche | V7: 44871 | W7: 1
A8: Lundi | B8: 44872 | C8: 0 | D8: 1 | E8: 1 | F8: 1 | G8: 1 | H8: 1 | I8: 1 | J8: 1 | K8: 1 | L8: 0 | M8: 1 | N8: 0 | O8: 0 | P8: 0 | U8: Lundi | V8: 44872 | W8: 1
A9: Mardi | B9: 44873 | C9: 0 | D9: 1 | E9: 1 | F9: 0 | G9: 0 | H9: 1 | I9: 1 | J9: 0 | K9: 0 | L9: 1 | M9: 1 | N9: 1 | O9: 0 | P9: 0 | U9: Mardi | V9: 44873 | W9: 1
A10: Mercredi | B10: 44874 | C10: 0 | D10: 1 | E10: 1 | F10: 1 | G10: 0 | H10: 1 | I10: 1 | J10: 1 | K10: 0 | L10: 1 | M10: 1 | N10: 1 | O10: 1 | P10: 0 | U10: Mercredi | V10: 44874 | W10: 1
A11: Jeudi | B11: 44875 | C11: 0 | D11: 1 | E11: 1 | F11: 1 | G11: 0 | H11: 1 | I11: 1 | J11: 1 | K11: 0 | L11: 1 | M11: 1 | N11: 1 | O11: 0.5 | P11: 0 | U11: Jeudi | V11: 44875 | W11: 1
A12: Vendredi | B12: 44876 | C12: 2 | D12: 0 | E12: 1 | F12: 1 | G12: 0 | H12: 2 | I12: 1 | J12: 0 | K12: 0 | L12: 0 | M12: 1 | N12: 0 | O12: 2 | P12: 0 | U12: Vendredi | V12: 44876 | W12: 2
A13: Samedi | B13: 44877 | C13: 0 | D13: 1 | E13: 1 | F13: 1 | G13: 0 | H13: 1 | I13: 1 | J13: 0 | K13: 0 | L13: 1 | M13: 1 | N13: 1 | O13: 1 | P13: 0 | U13: Samedi | V13: 44877 | W13: 1
... A25: Jeudi | B25: 44889 | C25: 0 | D25: 1 | E25: 1 | F25: 0 | G25: 0 | H25: 1 | I25: 1 | J25: 1 | K25: 1.5 | L25: 1 | M25: 0 | N25: 1 | O25: 1.5 | P25: 0 | U25: Jeudi | V25: 44889 | W25: 1
A26: Vendredi | B26: 44890 | C26: 0 | D26: 0 | E26: 1.5 | F26: 1 | G26: 1 | H26: 1 | I26: 1 | J26: 1.5 | K26: 1.5 | L26: 0 | M26: 1 | N26: 1 | O26: 1.5 | U26: Vendredi | V26: 44890 | W26: 1
A27: Samedi | B27: 44891 | C27: 0 | D27: 1 | E27: 1 | F27: 1 | G27: 1 | H27: 0 | I27: 0 | J27: 1 | K27: 1 | L27: 1 | M27: 0 | N27: 1 | O27: 1 | P27: 0 | U27: Samedi | V27: 44891 | W27: 0
A28: Dimanche | B28: 44892 | C28: 0 | D28: 1 | E28: 1 | F28: 1 | G28: 1 | H28: 1 | I28: 1 | J28: 1 | K28: 0 | L28: 1 | M28: 1 | N28: 0 | O28: 0 | P28: 0 | U28: Dimanche | V28: 44892 | W28: 1
A29: Lundi | B29: 44893 | C29: 0 | D29: 1 | E29: 1 | F29: 1 | G29: 1 | H29: 1 | I29: 1 | J29: 1 | K29: 0 | L29: 0 | M29: 1 | N29: 1 | O29: 0 | P29: 0 | U29: Lundi | V29: 44893 | W29: 1
A30: Mardi | B30: 44894 | C30: 0 | D30: 1 | E30: 1 | F30: 0 | G30: 0 | H30: 1 | I30: 1 | J30: 1 | K30: 1 | L30: 0 | M30: 1 | N30: 1 | O30: 0.5 | P30: 0 | U30: Mardi | V30: 44894 | W30: 1
A31: Mercredi | B31: 44895 | C31: 0 | D31: 1 | E31: 1 | F31: 0 | G31: 0 | H31: 1 | I31: 1 | J31: 1 | K31: 1 | L31: 0 | M31: 1 | N31: 1 | O31: 1.5 | P31: 0 | U31: Mercredi | V31: 44895 | W31: 1
C32: =SUM(C2:C31) -> 4 | D32: =SUM(D2:D31) -> 21 | E32: =SUM(E2:E31) -> 25.5 | F32: =SUM(F2:F31) -> 20 | G32: =SUM(G2:G31) -> 16 | H32: =SUM(H2:H31) -> 27 | I32: =SUM(I2:I31) -> 26 | J32: =SUM(J2:J31) -> 25.5 | ... P32: =SUM(P2:P31) -> 0 | W32: =SUM(W2:W31) -> 27
C33: 1200 | D33: 1111 | E33: 1111 | F33: 1000 | G33: 1111 | H33: 1150 | I33: 1111 | J33: 1111 | K33: 1000 | L33: 1200 | M33: 1000 | N33: 800 | O33: 1000 | P33: 1000 | W33: 1150
C34: =C33*C32 -> 4800 | D34: =D33*D32 -> 23331 | E34: =E33*E32 -> 28330.5 | F34: =F33*F32 -> 20000 | G34: =G33*G32 -> 17776 | H34: =H33*H32 -> 31050 | I34: =I33*I32 -> 28886 | J34: =J33*J32 -> 28330.5 | ... P34: =P33*P32 -> 0 | Q34: =SUM(C34:P34) -> 278204 | W34: =W33*W32 -> 31050

Sheet Les charges 
E2: Produit | F2: Quantité | G2: Prix unitaire | H2: Prix | I2: Date d'achat
E3: oeuf | F3: 6 | G3: 500 | H3: =G3*F3 -> 3000 | I3: 44860
E4: Tomate conserve | F4: 12 | G4: 215 | H4: =G4*F4 -> 2580 | I4: 44859
E5: sel | F5: 2 | G5: 390 | H5: =G5*F5 -> 780 | I5: 44859
E6: amandes | F6: 10 | G6: 1580 | H6: =G6*F6 -> 15800 | I6: 44859
E7: miel 5kg | F7: 5 | G7: 760 | H7: =G7*F7 -> 3800 | I7: 44859
E8: sac croissant 24 | F8: 1 | G8: 1100 | H8: =G8*F8 -> 1100 | I8: 44859
E9: sac croissant 14 | F9: 1 | G9: 650 | H9: =G9*F9 -> 650 | I9: 44859
E10: sac croissant 6 | F10: 1 | G10: 4600 | H10: =G10*F10 -> 4600 | I10: 44859
E11: sucre glace Houda | F11: 16 | G11: 100 | H11: =G11*F11 -> 1600 | I11: 44859
E12: djeldjelane | F12: 1 | G12: 1000 | H12: =G12*F12 -> 1000 | I12: 44859
E13: poivre noir | F13: 1 | G13: 200 | H13: =G13*F13 -> 200 | I13: 44859
E14: kousseber moulu | F14: 1 | G14: 1000 | H14: =G14*F14 -> 1000 | I14: 44859
... E21: eau minéral lala khedidja 0.5litre | F21: 5 | G21: 200 | H21: =G21*F21 -> 1000 | I21: 44854
E22: Jus Tchina 33cl | H22: =G22*F22 -> 0
E23: sucre cristalisé 25kg | F23: 1 | G23: 4010 | H23: =G23*F23 -> 4010
E24: Maiis 850g | F24: 12 | G24: 370 | H24: =G24*F24 -> 4440 | I24: 44854
E25: thon le gou 2kg | F25: 6 | G25: 1850 | H25: =G25*F25 -> 11100 | I25: 44854
E26: gouda barre | F26: 3.9 | G26: 2200 | H26: =G26*F26 -> 8580 | I26: 44854
E27: cheddar | F27: 2.2 | G27: 2450 | H27: =G27*F27 -> 5390 | I27: 44854
E28: fromage blanc 1.8kg | F28: 2 | G28: 680 | H28: =G28*F28 -> 1360 | I28: 44854
E29: fromage rouge | F29: 1.6 | G29: 2100 | H29: =G29*F29 -> 3360 | I29: 44854
E30: fromage slices | F30: 14 | G30: 175 | H30: =G30*F30 -> 2450 | I30: 44854
E31: fromage bidon 3,8 | F31: 3 | G31: 1300 | H31: =G31*F31 -> 3900 | I31: 44854
E32: coca cannette | F32: 2 | G32: 1300 | H32: =F32*G32 -> 2600 | I32: 44854
E33: Fanta fraise et sprite | F33: 2 | G33: 1300 | H33: =F33*G33 -> 2600 | I33: 44854
E34: coca fanta sprit petit bouteille | F34: 3 | G34: 450 | H34: =F34*G34 -> 1350 | I34: 44854
E35: Amina Baghrir | F35: 1 | G35: 20660 | H35: =F35*G35 -> 20660 | I35: 44863
E36: huiles 2 litres | F36: 27 | G36: 1416 | H36: =G36*F36 -> 38232 | I36: 44854
E37: semoule Sim 10kg | F37: 3 | G37: 700 | H37: =G37*F37 -> 2100 | I37: 44850
E38: semoule moyenne Sim 2kg | F38: 4 | G38: 300 | H38: =G38*F38 -> 1200 | I38: 44849
E39: 3akeri | F39: 10 | G39: 750 | H39: =G39*F39 -> 7500 | I39: 44849
E40: papier aluminium | F40: 3 | G40: 1200 | H40: =G40*F40 -> 3600 | I40: 44849
E41: sachets blanc 5kg | F41: 2 | G41: 1450 | H41: =G41*F41 -> 2900 | I41: 44849
E42: cerise confis | F42: 2 | G42: 1650 | H42: =G42*F42 -> 3300 | I42: 44849
E43: sachet de congélation 3kg | F43: 1 | G43: 2000 | H43: =G43*F43 -> 2000 | I43: 44849
E44: Huile 5 litres | F44: 0 | G44: 600 | H44: =G44*F44 -> 0 | I44: 44847
E45: lait en poudre 500g | F45: 6 | G45: 540 | H45: =G45*F45 -> 3240 | I45: 44845
E46: Chocolat au Lait | F46: 7 | G46: 240 | H46: =G46*F46 -> 1680 | I46: 44805
E47: Chocolat noisette | F47: 4 | G47: 260 | H47: =G47*F47 -> 1040 | I47: 44805
...

Sheet Les salaires 
A1: 4
H10: Nom | I10: Salaire | J10: Avance | K10: Salaire à payer
G11: 1 | H11: Sofiane | I11: 30000 | J11: 30000 | K11: =I11-J11 -> 0 | L11: 20000+10000
G12: 2 | H12: Amel | I12: 30000 | J12: 30000 | K12: =I12-J12 -> 0
G13: 3 | H13: Nadjet | I13: =Pointage!C34*1 -> 4800 | J13: 4800 | K13: =I13-J13 -> 0 | L13: 3600+1200
G14: 4 | H14: Hafida | I14: =Pointage!D34*1 -> 23331 | K14: =I14-J14 -> 23331
G15: 5 | H15: Wahiba | I15: =Pointage!E34*1 -> 28330.5 | K15: =I15-J15 -> 28330.5
G16: 6 | H16: Rania | I16: =Pointage!F34*1 -> 20000 | J16: 16000 | K16: =I16-J16 -> 4000
G17: 7 | H17: Djamila | I17: =Pointage!G34*1 -> 17776 | K17: =I17-J17 -> 17776
G18: 8 | H18: Farida | I18: =Pointage!H34*1 -> 31050 | J18: 3000 | K18: =I18-J18 -> 28050
G19: 9 | H19: Yousera | I19: =Pointage!I34*1 -> 28886 | J19: 5000 | K19: =I19-J19 -> 23886 | L19: 4000+10000
G20: 10 | H20: lynda | I20: =Pointage!J34*1 -> 28330.5 | K20: =I20-J20 -> 28330.5
G21: 11 | H21: Karima | I21: =Pointage!N34*1 -> 16800 | K21: =I21-J21 -> 16800
G22: 12 | H22: Samira | I22: =Pointage!M34*1 -> 25000 | J22: 2000 | K22: =I22-J22 -> 23000
G23: 13 | H23: Fouzia | I23: =Pointage!L34*1 -> 20400 | K23: =I23-J23 -> 20400
G24: 14 | H24: Kenza | I24: =Pointage!K34*1 -> 13500 | K24: =I24-J24 -> 13500
G25: 15 | H25: Yasmine | I25: =Pointage!O34*1 -> 20000 | K25: =I25-J25 -> 20000
G26: 16 | H26: Extra | I26: =Pointage!P34*1 -> 0 | K26: =I26-J26 -> 0
H27: TOTAL | I27: =SUM(I11:I26) -> 338204 | J27: =SUM(J11:J26) -> 90800 | K27: =SUM(K11:K26) -> 247404
H28: =I27-J27 -> 247404 | K28: =I28-J28 -> 0

Sheet Feuille 5
I12: Mois de Juillet | J12: Mois d'Aout | K12: Mois de Septembre | L12: Mois d'Octobre | M12: Mois de Novembre
H13: Recette | I13: 2230000 | J13: 1332000 | K13: 1657000 | L13: 1921000 | M13: =RECAP!D32*1 -> 1706000
H14: Charges | I14: 990000 | J14: 594000 | K14: 702000 | L14: 901000 | M14: =RECAP!E32*1 -> 717114
H15: Salaires | I15: 330000 | J15: 188000 | K15: 305000 | L15: 369000 | M15: =RECAP!F32*1 -> 338204
H16: Loyer | I16: 110000 | J16: 110000 | K16: 110000 | L16: 110000 | M16: =RECAP!G32*1 -> 110000
H17: Profit Net | I17: 800000 | J17: 440000 | K17: 540000 | L17: 540000 | M17: =RECAP!H32*1 -> 540682
I24: Mois | J24: CA | K24: Charge % | L24: Salaire % | M24: Loyer % | N24: Bénef %
I25: SEP | J25: 1 657 000 | K25: 42.37 | L25: 18.39 | M25: 6.64 | N25: 32.6
I26: OCT | J26: 1 921 000 | K26: 46.9 | L26: 19.21 | M26: 5.73 | N26: 28.11
I27: NOV | J27: 1 706 000 | K27: 42.03 | L27: 19.82 | M27: 6.45 | N27: 31.69
I29: OBJ | J29: 2 030 000 | K29: 34.48 | L29: 15.27 | M29: 5.42 | N29: 44.83
