Workbook

Sheet RECAP
B1: Date | C1: Recette | D1: Charges | E1: Salaire | F1: Loyer | G1: Net Profit
A2: Mardi | B2: 43739 | C2: 24000
A3: Mercredi | B3: 43740 | C3: 22000
A4: Jeudi | B4: 43741 | C4: 30000
A5: Vendredi | B5: 43742 | C5: 0
A6: Samedi | B6: 43743 | C6: 15000
A7: Dimanche | B7: 43744 | C7: 22000
A8: Lundi | B8: 43745 | C8: 26000
A9: Mardi | B9: 43746 | C9: 19000
A10: Mercredi | B10: 43747 | C10: 21000
A11: Jeudi | B11: 43748 | C11: 21000
A12: Vendredi | B12: 43749 | C12: 0
A13: Samedi | B13: 43750 | C13: 18000
... A29: Lundi | B29: 43766 | C29: 18000
A30: Mardi | B30: 43767 | C30: 27000 | R30: =C33*1 -> 584500 | S30: =Pointage!C33*1 -> 27 | T30: =R30/S30 -> 21648.148
A31: Mercredi | B31: 43768 | C31: 22000
A32: Jeudi | B32: 43769 | C32: 23500
B33: TOTAL | C33: =SUM(C2:C32) -> 584500 | D33: ='Les Charges '!D58*1 -> 157460 | E33: =Pointage!L35*1 -> 166994 | F33: 40000 | G33: =C33-D33-E33-F33 -> 220046

Sheet Les Charges 
A1: 6
B2: Produit | C2: Quantité | D2: Prix | E2: Date d'achat
B3: Semoule Moyenne Extra Ben Hamadi 10kg | C3: 30 Sachets | D3: 17100 | E3: 43739
B4: Margarine Mani | C4: 5 cartons | D4: 13800 | E4: 43739
B5: Harissa | C5: 1 carton | D5: 2640 | E5: 43739
B6: Levure de bièrre | C6: 1 carton | D6: 4800 | E6: 43739
B7: Javel Oz | C7: 1 Bidon 5 litres | D7: 280 | E7: 43739
B8: Fromage spéciale Pizza | C8: 6 kg | D8: 1500 | E8: 43739
B9: Cheddar | C9: 1.6 kg | D9: 1850 | E9: 43739
B10: Lait en poudre | C10: 2 kg | D10: 1400 | E10: 43739
B11: savon liquide | C11: 2.5 litres | D11: 500 | E11: 43739
B12: Gruyère | C12: 400g | D12: 580 | E12: 43739
B13: Sanouj | C13: 1 kg | D13: 700 | E13: 43739
B14: huile de 10 litres | C14: 10 Bidons | D14: 10550 | E14: 43741
B15: Gruyère | C15: 1.6 kg | D15: 1900 | E15: 43743
B16: Bassines | C16: 2 | D16: 500 | E16: 43743
B17: 3akeri | C17: 1 kg | D17: 950 | E17: 43743
B18: Papier aluminium | C18: 1 boite | D18: 900 | E18: 43743
B19: sac poubelle +sachets de congelation | C19: 4 | D19: 500 | E19: 43743
B20: les gants | C20: 1 boite | D20: 780 | E20: 43744
B21: bessel | C21: 100kg | D21: 2500 | E21: 43744
B22: chedar | C22: 3 kg | D22: 3600 | E22: 43746
B23: Spécial pizza | C23: 12.8kg | D23: 3200 | E23: 43746
B24: boites 40/10 36/7 | C24: 4 cartons | D24: 4500 | E24: 43746
B25: Goblets | C25: 150 | D25: 2500 | E25: 43746
B26: vanille | C26: / | D26: 100 | E26: 43746
B27: Tomate fraiche | C27: 30kg | D27: 1800 | E27: 43746
B28: cartes visite | C28: 6 boites | D28: 7200 | E28: 43748
B29: baghrir | D29: 6000 | E29: 43750
B30: gherss | C30: 40kg | D30: 6800 | E30: 43750
B31: bessel | C31: 100kg | D31: 2500 | E31: 43751
B32: coca 1/2 litre | C32: 2 fardeaux | D32: 1300 | E32: 43755
B33: canette coca | C33: 1 fardeau | D33: 1500 | E33: 43755
B34: eau | C34: 6 fardeaux | D34: 1080 | E34: 43755
B35: IFRUIT | C35: 3 FARDEAUX | D35: 1650 | E35: 43755
B36: Aliminium | C36: 1 | D36: 850 | E36: 43755
B37: Gruyère | C37: 900g | D37: 1300 | E37: 43755
B38: Bessel | C38: 100kg | D38: 2500 | E38: 43758
B39: sel | C39: fardeau | D39: 350 | E39: 43759
B40: Yassir | C40: / | D40: 1000 | E40: 43759
...

Sheet Pointage
B1: Date | C1: Zehor | D1: Malika | E1: Souad | F1: Ghania | G1: Ibtissam | H1: Nabila | I1: Wahiba | J1: Loubna | K1: Zahida | L1: Remarque | M1: Reste à payer
A2: Mardi | B2: 43739 | C2: 1 | D2: 0 | E2: 1 | F2: 0 | G2: 1 | H2: 1 | I2: 0 | J2: 0 | K2: 1
A3: Mercredi | B3: 43740 | C3: 1 | D3: 0 | E3: 1 | F3: 1 | G3: 1 | H3: 1 | I3: 0 | J3: 0 | K3: 1
A4: Jeudi | B4: 43741 | C4: 1 | D4: 0 | E4: 1 | F4: 1 | G4: 1 | H4: 1 | I4: 0 | J4: 0 | K4: 1
A5: Vendredi | B5: 43742 | C5: 0 | D5: 0 | E5: 0 | F5: 0 | G5: 0 | H5: 0 | I5: 0 | J5: 0 | K5: 0
A6: Samedi | B6: 43743 | C6: 1 | D6: 0 | E6: 1 | F6: 1 | G6: 0 | H6: 1 | I6: 0 | J6: 0 | K6: 1
A7: Dimanche | B7: 43744 | C7: 1 | D7: 0 | E7: 1 | F7: 1 | G7: 0 | H7: 1 | I7: 0 | J7: 0 | K7: 1
A8: Lundi | B8: 43745 | C8: 1 | D8: 1 | E8: 1 | F8: 1 | G8: 0 | H8: 1 | I8: 0 | J8: 0 | K8: 1
A9: Mardi | B9: 43746 | C9: 1 | D9: 1 | E9: 1 | F9: 0 | G9: 0 | H9: 0 | I9: 0 | J9: 0 | K9: 0
A10: Mercredi | B10: 43747 | C10: 1 | D10: 1 | E10: 1 | F10: 1 | G10: 0 | H10: 1 | I10: 0 | J10: 0 | K10: 1
A11: Jeudi | B11: 43748 | C11: 1 | D11: 1 | E11: 1 | F11: 1 | G11: 0 | H11: 1 | I11: 0 | J11: 0 | K11: 1
A12: Vendredi | B12: 43749 | C12: 0 | D12: 0 | E12: 0 | F12: 0 | G12: 0 | H12: 0 | I12: 0 | J12: 0 | K12: 0
A13: Samedi | B13: 43750 | C13: 1 | D13: 1 | E13: 1 | F13: 0 | G13: 0 | H13: 1 | I13: 0 | J13: 0 | K13: 1
... A32: Jeudi | B32: 43769 | C32: 1 | D32: 0 | E32: 1 | F32: 0 | G32: 0 | H32: 1 | I32: 0 | J32: 0 | K32: 1
B33: TOTAL | C33: =SUM(C2:C32) -> 27 | D33: =SUM(D2:D32) -> 15 | E33: =SUM(E2:E32) -> 26 | F33: =SUM(F2:F32) -> 7 | G33: =SUM(G2:G32) -> 3 | H33: =SUM(H2:H32) -> 25 | I33: =SUM(I2:I32) -> 7 | J33: =SUM(J2:J32) -> 3 | K33: =SUM(K2:K32) -> 26
B34: Salaire/jour | C34: 1850 | D34: 1700 | E34: 1111 | F34: 740 | G34: 926 | H34: 926 | I34: 555 | J34: 555 | K34: 1000 | L34: =SUM(C34:K34) -> 9363
B35: SALAIRES | C35: =C33*C34 -> 49950 | D35: =D33*D34 -> 25500 | E35: =E33*E34 -> 28886 | F35: =F33*F34 -> 5180 | G35: =G33*G34 -> 2778 | H35: =H33*H34 -> 23150 | I35: =I34*I33 -> 3885 | J35: =J34*J33 -> 1665 | K35: =K33*K34 -> 26000 | L35: =SUM(C35:K35) -> 166994 | M35: =L35-I35-G35-F35-D35 -> 129651
C37: 50000 | D37: 24000 | E37: 27600 | F37: 5200 | G37: 2800 | H37: 24000 | I37: 4000 | J37: 1700 | K37: 27000 | L37: =SUM(C37:K37) -> 166300

Sheet Salaires 
F3: Nom | G3: Salaire | H3: La Date
E4: 1 | F4: Zehor | G4: =Pointage!C35*1 -> 49950
E5: 2 | F5: Malika | G5: =Pointage!D35*1 -> 25500 | H5: 43745
E6: 3 | F6: Souad | G6: =Pointage!E35*1 -> 28886
E7: 4 | F7: Ibtissam | G7: =Pointage!G35*1 -> 2778
E8: 5 | F8: Nabila | G8: =Pointage!H35*1 -> 23150
E9: 6 | F9: Ghania | G9: =Pointage!F35*1 -> 5180
E10: 7 | F10: wahiba | G10: =Pointage!I35*1 -> 3885 | H10: 43759
E11: 8 | F11: Zahida | G11: =Pointage!K35*1 -> 26000
F12: TOTAL | G12: =SUM(G4:G11) -> 165329

Sheet Feuille 5
I3: Bénifice mois d'Octobre 220000 Da
I4: Sofiane | J4: 55000
I5: Amel | J5: 55000
I6: Saida | J6: 55000
I7: Magasin | J7: 55000
